Workbook

Sheet Stock grad Doctors
A1: Country | B1: 2013 | C1: 2018 | D1: Doctors stock 2022 | E1: Doctors graduates
A2: Algeria | B2: 0 | C2: 73168 | D2: 48033.824 | E2: 0
A3: Angola | B3: 0 | C3: 6593 | D3: 8693 | E3: 611
A4: Benin | B4: 0 | C4: 908 | D4: 2608 | E4: 780
A5: Botswana | B5: 819 | C5: 925 | D5: 992 | E5: 60
A6: Burkina Faso | B6: 803 | C6: 1684 | D6: 3323 | E6: 1492
A7: Burundi | B7: 554 | C7: 1084 | D7: 1014.861 | E7: 325
A8: Cameroon | B8: 1842 | C8: 3259 | D8: 3759 | E8: 800
A9: Cabo Verde | B9: 308 | C9: 452 | D9: 2644 | E9: 0
A10: Central African Republic | B10: 324 | C10: 335 | D10: 146.38958 | E10: 18
A11: Chad | B11: 573 | C11: 803 | D11: 1507 | E11: 330
A12: Comoros | B12: 123 | C12: 220 | D12: 354 | E12: 0
A13: Congo | B13: 0 | C13: 544 | D13: 1042 | E13: 60
... A48: Zimbabwe | B48: 1114 | C48: 3026 | D48: 3131.5984 | E48: 265

Sheet Sheet2
A1: Country | B1: Generalist Medical Practitioners | C1: Specialist Medical Practitioners | D1: Dentists | E1: Other Dental practitioners | F1: Pharmacists | G1: Other Pharmacy practitioners | H1: Midwifery personnel | I1: Nursing Personnel | J1: Medical and Pathology Laboratory scientists | K1: Paramedical Practitioners | L1: Other Health Workers | M1: Total | N1: Data Sorce(s)
A2: Algeria | B2: 0 | M2: 0 | N2: NHWA dataset, 2023
A3: Angola | B3: 611 | D3: 145 | F3: 529 | I3: 2950 | M3: 4235 | N3: Dent-2018;
A4: Benin | B4: 780 | C4: 385 | F4: 143 | H4: 247 | I4: 257 | J4: 1113 | L4: 1194 | M4: 4119 | N4: Med-2021; Pharm-2021;Mid-2021; Nur-2021;Biom-2021; others-2021
A5: Botswana | B5: 60 | C5: 48 | D5: 7 | E5: 10 | F5: 95 | G5: 60 | H5: 40 | I5: 490 | J5: 189 | K5: 30 | L5: 597 | M5: 1626 | N5: 2022 for all
A6: Burkina Faso | B6: 1492 | C6: 385 | D6: 62 | F6: 594 | H6: 1170 | I6: 1170 | M6: 4873 | N6: NHWA dataset, 2023
A7: Burundi | B7: 325 | C7: 240 | F7: 39 | H7: 196 | I7: 1467 | J7: 322 | L7: 194 | M7: 2783 | N7: 2018 dataset
A8: Cameroon | B8: 800 | I8: 2660 | J8: 800 | M8: 4260 | N8: NHWA dataset, 2023
A9: Cabo Verde | E9: 7 | L9: 83 | M9: 90 | N9: NHWA dataset, 2023
A10: Central African Republic | B10: 18 | M10: 18 | N10: NHWA dataset, 2023
A11: Chad | B11: 330 | C11: 30 | F11: 80 | G11: 180 | H11: 2084 | I11: 2920 | J11: 220 | M11: 5844 | N11: NHWA dataset, 2023
A12: Comoros | H12: 29 | I12: 40 | M12: 69 | N12: 2021 for all
A13: Congo | B13: 60 | C13: 315 | E13: 10 | G13: 5 | H13: 120 | I13: 60 | K13: 50 | L13: 408 | M13: 1028 | N13: 2022 for all
A14: Cote d'Ivoire | B14: 254 | C14: 48 | G14: 151 | I14: 1007 | J14: 1106 | L14: 450 | M14: 3016 | N14: NHWA dataset, 2023
A15: Democratic Republic of the Congo | B15: 6020 | D15: 66 | F15: 178 | G15: 328 | H15: 3453 | I15: 24061 | J15: 2571 | L15: 3151 | M15: 39828 | N15: NHWA dataset, 2023
A16: Equatorial Guinea | B16: 767 | H16: 492 | I16: 962 | J16: 27 | L16: 1304 | M16: 3552 | N16: NHWA dataset, 2023
A17: Eritrea | I17: 400 | L17: 1023 | M17: 1423 | N17: Nurs-2022
A18: Eswatini | F18: 44 | G18: 30 | H18: 80 | I18: 160 | J18: 78 | L18: 58 | M18: 450 | N18: NHWA dataset, 2023
A19: Ethiopia | B19: 3114 | C19: 880 | D19: 189 | E19: 64 | F19: 699 | G19: 2878 | H19: 2440 | I19: 6298 | J19: 1220 | K19: 1613 | L19: 3672 | M19: 23067 | N19: pharmacist from 2018
A20: Gabon | B20: 46 | C20: 16 | F20: 2 | H20: 34 | I20: 95 | J20: 6 | M20: 199 | N20: NHWA dataset, 2023
A21: Gambia | B21: 23 | I21: 137 | J21: 6 | M21: 166 | N21: NHWA dataset, 2023
A22: Ghana | B22: 1566 | F22: 343 | H22: 4827 | I22: 21271 | J22: 396 | M22: 28403 | N22: HLMA 2023; Ismaila (2023)
A23: Guinea | B23: 767 | C23: 74 | F23: 113 | G23: 34 | H23: 492 | I23: 964 | J23: 27 | L23: 1304 | M23: 3775 | N23: NHWA dataset, 2023
A24: Guinea-Bissau | J24: 23 | L24: 489 | M24: 512 | N24: NHWA dataset, 2023
A25: Kenya | B25: 558 | D25: 36 | F25: 379 | G25: 20 | I25: 1070 | J25: 519 | L25: 366 | M25: 2948 | N25: HLMA data, Dentist-2018; CMHW-2022; Biom -2018;
A26: Lesotho | B26: 8 | C26: 22 | D26: 8 | F26: 33 | G26: 20 | H26: 69 | I26: 376 | J26: 20 | M26: 556 | N26: NHWA dataset, 2023
A27: Liberia | B27: 29 | C27: 50 | F27: 22 | I27: 63 | J27: 56 | L27: 50 | M27: 270 | N27: NHWA dataset, 2023
A28: Madagascar | B28: 316 | C28: 156 | H28: 2473 | I28: 2540 | J28: 116 | L28: 297 | M28: 5898 | N28: NHWA dataset, 2023
A29: Malawi | B29: 115 | C29: 167 | F29: 110 | G29: 189 | H29: 1171 | I29: 386 | J29: 175 | L29: 616 | M29: 2929 | N29: NHWA dataset, 2023
A30: Mali | M30: 0 | N30: NHWA dataset, 2023
A31: Mauritania | C31: 76 | I31: 113 | L31: 366 | M31: 555 | N31: NHWA dataset, 2023
A32: Mauritius | B32: 432 | H32: 40 | I32: 175 | L32: 39 | M32: 686 | N32: SADC dataset, 2022
A33: Mozambique | B33: 819 | C33: 146 | D33: 161 | G33: 112 | H33: 140 | I33: 580 | J33: 248 | K33: 20 | M33: 2226 | N33: capacity-HLMA data extracted
A34: Namibia | B34: 475 | C34: 3 | F34: 247 | G34: 31 | H34: 1414 | I34: 200 | J34: 121 | L34: 175 | M34: 2666 | N34: NHWA dataset, 2023; HLMA dataset, 2019; 2018 survey dataset
A35: Niger | B35: 370 | C35: 14 | H35: 124 | I35: 305 | J35: 45 | L35: 1891 | M35: 2749 | N35: Med-2021,2022; Nurs-2022; Midw-2022; Other-2021,2022, CHW-2021
A36: Nigeria | B36: 4340 | D36: 459 | H36: 375 | I36: 12835 | J36: 1774 | M36: 19783 | N36: NHWA dataset, 2023
A37: Rwanda | B37: 11 | F37: 95 | H37: 176 | I37: 355 | L37: 81 | M37: 718 | N37: NHWA dataset, 2023
A38: Sao Tome and Principe | M38: 0 | N38: NHWA dataset, 2023
A39: Senegal | B39: 434 | C39: 137 | D39: 67 | F39: 171 | H39: 104 | I39: 582 | J39: 36 | L39: 710 | M39: 2241 | N39: NHWA dataset, 2023
A40: Seychelles | B40: 10 | G40: 20 | H40: 10 | I40: 40 | L40: 80 | M40: 160 | N40: NHWA dataset, 2023
...

Sheet Sheet1
A1: Country | B1: Country Code
A2: Burkina Faso | B2: BFA
A3: Central African Republic | B3: CAF
A4: Sao Tome and Principe | B4: STP
A5: DRC | B5: COD
A6: Ethiopia | B6: ETH
A7: Nigeria | B7: NGA
A8: Gabon | B8: GAB
A9: Mauritania | B9: MRT
A10: Eswatini | B10: SWZ
A11: Lesotho | B11: LSO
A12: Algeria | B12: DZA
... A48: Tanzania | B48: TZA

Sheet Nurses
A1: Country | B1: 2013 | C1: 2018 | D1: Nurses Stock 2022 | E1: Nurses Graduates
A2: Algeria | B2: 0 | C2: 57705 | D2: 5043.8935 | E2: 0
A3: Angola | B3: 0 | C3: 46082 | D3: 66717.354 | E3: 2950
A4: Benin | B4: 4880 | C4: 3410 | D4: 5893 | E4: 257
A5: Botswana | B5: 5816 | C5: 7645 | D5: 8028 | E5: 490
A6: Burkina Faso | B6: 6196 | C6: 10325 | D6: 13961 | E6: 1170
A7: Burundi | B7: 6573 | C7: 9156 | D7: 9372 | E7: 1467
A8: Cameroon | B8: 18954 | C8: 9925 | D8: 16473 | E8: 2660
A9: Cabo Verde | B9: 403 | C9: 768 | D9: 941 | E9: 0
A10: Central African Republic | B10: 322 | C10: 1195 | D10: 648.48015 | E10: 0
A11: Chad | B11: 3606 | C11: 4799 | D11: 3387.1517 | E11: 2920
A12: Comoros | B12: 0 | C12: 747 | D12: 784.97097 | E12: 40
A13: Congo | B13: 3289 | C13: 5081 | D13: 5573 | E13: 60
... A48: Zimbabwe | B48: 18722 | C48: 27874 | D48: 46537 | E48: 1100

Sheet DoctNurses
A1: Country | B1: Country code | C1: Doctors stock 2022 | D1: Doctors graduates | E1: Nurses Stock 2022 | F1: Nurses Graduates | G1: Doctors and Nurses Stock 2022 | H1: Doctors and Nurses graduates | I1: Ratio | J1: Density | K1: % of health budget spent on HWF | L1: GGHE-D as % GGE | M1: Percentage of health budget spent on HWF | N1: GGHE-D as percentage GGE
A2: Algeria | B2: DZA | C2: 75512 | D2: 5134.816 | E2: 104776 | F2: 4679.8755 | G2: =C2+E2 -> 180288 | H2: =D2+F2 -> 9814.6915 | I2: =G2/H2 -> 18.369197 | J2: =VLOOKUP(B2,stockgranddensity!B$2:C$48,2,FALSE) -> 40.150346 | K2: =VLOOKUP(B2,Sheet4!A$2:B$48,2,FALSE) -> 0.55 | L2: =VLOOKUP(B2,Sheet4!A$2:C$48,3,FALSE) -> 0.10730769 | M2: =K2*100 -> 55 | N2: =L2*100 -> 10.730769
A3: Angola | B3: AGO | C3: 8693 | D3: 611 | E3: 66717.354 | F3: 2950 | G3: =C3+E3 -> 75410.354 | H3: =D3+F3 -> 3561 | I3: =G3/H3 -> 21.176735 | J3: =VLOOKUP(B3,stockgranddensity!B$2:C$48,2,FALSE) -> 21.189239 | K3: =VLOOKUP(B3,Sheet4!A$2:B$48,2,FALSE) -> 0.50045872 | L3: =VLOOKUP(B3,Sheet4!A$2:C$48,3,FALSE) -> 0.053643193 | M3: =K3*100 -> 50.045872 | N3: =L3*100 -> 5.3643193
A4: Benin | B4: BEN | C4: 2608 | D4: 780 | E4: 5893 | F4: 257 | G4: =C4+E4 -> 8501 | H4: =D4+F4 -> 1037 | I4: =G4/H4 -> 8.1976856 | J4: =VLOOKUP(B4,stockgranddensity!B$2:C$48,2,FALSE) -> 6.3664245 | K4: =VLOOKUP(B4,Sheet4!A$2:B$48,2,FALSE) -> 0.47302604 | L4: =VLOOKUP(B4,Sheet4!A$2:C$48,3,FALSE) -> 0.04554594 | M4: =K4*100 -> 47.302604 | N4: =L4*100 -> 4.554594
A5: Botswana | B5: BWA | C5: 992 | D5: 60 | E5: 8028 | F5: 490 | G5: =C5+E5 -> 9020 | H5: =D5+F5 -> 550 | I5: =G5/H5 -> 16.4 | J5: =VLOOKUP(B5,stockgranddensity!B$2:C$48,2,FALSE) -> 34.292718 | K5: =VLOOKUP(B5,Sheet4!A$2:B$48,2,FALSE) -> 0.521 | L5: =VLOOKUP(B5,Sheet4!A$2:C$48,3,FALSE) -> 0.12006065 | M5: =K5*100 -> 52.1 | N5: =L5*100 -> 12.006065
A6: Burkina Faso | B6: BFA | C6: 3323 | D6: 1492 | E6: 13961 | F6: 1170 | G6: =C6+E6 -> 17284 | H6: =D6+F6 -> 2662 | I6: =G6/H6 -> 6.4928625 | J6: =VLOOKUP(B6,stockgranddensity!B$2:C$48,2,FALSE) -> 7.6229079 | K6: =VLOOKUP(B6,Sheet4!A$2:B$48,2,FALSE) -> 0.32880543 | L6: =VLOOKUP(B6,Sheet4!A$2:C$48,3,FALSE) -> 0.11463944 | M6: =K6*100 -> 32.880543 | N6: =L6*100 -> 11.463944
A7: Burundi | B7: BDI | C7: 1014.861 | D7: 325 | E7: 9372 | F7: 1467 | G7: =C7+E7 -> 10386.861 | H7: =D7+F7 -> 1792 | I7: =G7/H7 -> 5.7962394 | J7: =VLOOKUP(B7,stockgranddensity!B$2:C$48,2,FALSE) -> 8.0583416 | K7: =VLOOKUP(B7,Sheet4!A$2:B$48,2,FALSE) -> 0.2677 | L7: =VLOOKUP(B7,Sheet4!A$2:C$48,3,FALSE) -> 0.08312808 | M7: =K7*100 -> 26.77 | N7: =L7*100 -> 8.312808
A8: Cameroon | B8: CMR | C8: 3759 | D8: 800 | E8: 16473 | F8: 2660 | G8: =C8+E8 -> 20232 | H8: =D8+F8 -> 3460 | I8: =G8/H8 -> 5.8473988 | J8: =VLOOKUP(B8,stockgranddensity!B$2:C$48,2,FALSE) -> 7.2478366 | K8: =VLOOKUP(B8,Sheet4!A$2:B$48,2,FALSE) -> 0.60169836 | L8: =VLOOKUP(B8,Sheet4!A$2:C$48,3,FALSE) -> 0.036992729 | M8: =K8*100 -> 60.169836 | N8: =L8*100 -> 3.6992729
A9: Cabo Verde | B9: CPV | C9: 2644 | D9: 179.792 | E9: 941 | F9: 76.3151 | G9: =C9+E9 -> 3585 | H9: =D9+F9 -> 256.1071 | I9: =G9/H9 -> 13.99805 | J9: =VLOOKUP(B9,stockgranddensity!B$2:C$48,2,FALSE) -> 60.440075 | K9: =VLOOKUP(B9,Sheet4!A$2:B$48,2,FALSE) -> 0.32863413 | L9: =VLOOKUP(B9,Sheet4!A$2:C$48,3,FALSE) -> 0.10392425 | M9: =K9*100 -> 32.863413 | N9: =L9*100 -> 10.392425
A10: Central African Republic | B10: CAF | C10: 146.38958 | D10: 18 | E10: 648.48015 | F10: 105.05378 | G10: =C10+E10 -> 794.86973 | H10: =D10+F10 -> 123.05378 | I10: =G10/H10 -> 6.459531 | J10: =VLOOKUP(B10,stockgranddensity!B$2:C$48,2,FALSE) -> 1.4247164 | K10: =VLOOKUP(B10,Sheet4!A$2:B$48,2,FALSE) -> 0.60169836 | L10: =VLOOKUP(B10,Sheet4!A$2:C$48,3,FALSE) -> 0.048423176 | M10: =K10*100 -> 60.169836 | N10: =L10*100 -> 4.8423176
A11: Chad | B11: TCD | C11: 1507 | D11: 330 | E11: 3387.1517 | F11: 2920 | G11: =C11+E11 -> 4894.1517 | H11: =D11+F11 -> 3250 | I11: =G11/H11 -> 1.5058928 | J11: =VLOOKUP(B11,stockgranddensity!B$2:C$48,2,FALSE) -> 2.7614201 | K11: =VLOOKUP(B11,Sheet4!A$2:B$48,2,FALSE) -> 0.35310312 | L11: =VLOOKUP(B11,Sheet4!A$2:C$48,3,FALSE) -> 0.048723002 | M11: =K11*100 -> 35.310312 | N11: =L11*100 -> 4.8723002
A12: Comoros | B12: COM | C12: 354 | D12: 24.072 | E12: 784.97097 | F12: 40 | G12: =C12+E12 -> 1138.971 | H12: =D12+F12 -> 64.072 | I12: =G12/H12 -> 17.776423 | J12: =VLOOKUP(B12,stockgranddensity!B$2:C$48,2,FALSE) -> 13.611461 | K12: =VLOOKUP(B12,Sheet4!A$2:B$48,2,FALSE) -> 0.65 | L12: =VLOOKUP(B12,Sheet4!A$2:C$48,3,FALSE) -> 0.041246686 | M12: =K12*100 -> 65 | N12: =L12*100 -> 4.1246686
A13: Congo | B13: COG | C13: 1042 | D13: 60 | E13: 5573 | F13: 60 | G13: =C13+E13 -> 6615 | H13: =D13+F13 -> 120 | I13: =G13/H13 -> 55.125 | J13: =VLOOKUP(B13,stockgranddensity!B$2:C$48,2,FALSE) -> 11.079615 | K13: =VLOOKUP(B13,Sheet4!A$2:B$48,2,FALSE) -> 0.43066372 | L13: =VLOOKUP(B13,Sheet4!A$2:C$48,3,FALSE) -> 0.082168407 | M13: =K13*100 -> 43.066372 | N13: =L13*100 -> 8.2168407
... A48: Zimbabwe | B48: ZWE | C48: 3131.5984 | D48: 265 | E48: 46537 | F48: 1100 | G48: =C48+E48 -> 49668.598 | H48: =D48+F48 -> 1365 | I48: =G48/H48 -> 36.387252 | J48: =VLOOKUP(B48,stockgranddensity!B$2:C$48,2,FALSE) -> 30.433189 | K48: =VLOOKUP(B48,Sheet4!A$2:B$48,2,FALSE) -> 0.35 | L48: =VLOOKUP(B48,Sheet4!A$2:C$48,3,FALSE) -> 0.051729364 | M48: =K48*100 -> 35 | N48: =L48*100 -> 5.1729364

Sheet Sheet4
A1: Country | B1: % of health budget spent on HWF | C1: GGHE-D as % GGE
A2: DZA | B2: 0.55 | C2: 0.10730769
A3: AGO | B3: 0.50045872 | C3: 0.053643193
A4: BEN | B4: 0.47302604 | C4: 0.04554594
A5: BWA | B5: 0.521 | C5: 0.12006065
A6: BFA | B6: 0.32880543 | C6: 0.11463944
A7: BDI | B7: 0.2677 | C7: 0.08312808
A8: CPV | B8: 0.32863413 | C8: 0.10392425
A9: CMR | B9: 0.60169836 | C9: 0.036992729
A10: CAF | B10: 0.60169836 | C10: 0.048423176
A11: TCD | B11: 0.35310312 | C11: 0.048723002
A12: COM | B12: 0.65 | C12: 0.041246686
A13: COG | B13: 0.43066372 | C13: 0.082168407
... A48: ZWE | B48: 0.35 | C48: 0.051729364

Sheet All workforce stock
C1: Core health workforce* | F1: Other workers | I1: Total
A2: S No | B2: Country | C2: 2013 | D2: 2018 | E2: Adjusted 2022 | F2: 2013 | G2: 2018 | H2: Adjusted 2022 | I2: 2013 | J2: 2018 | K2: Adjusted 2022
A3: 1 | B3: Algeria | C3: 11139 | D3: 175647 | E3: 74186.82 | F3: 200 | G3: 240105 | H3: 366963.78 | I3: 11339 | J3: 415752 | K3: 441150.6
A4: 2 | B4: Angola | C4: 30 | D4: 60468 | E4: 78869.769 | F4: 602 | G4: 50395 | H4: 58067.47 | I4: 632 | J4: 110863 | K4: 136937.24
A5: 3 | B5: Benin | C5: 7923 | D5: 5769 | E5: 11051.475 | F5: 15066 | G5: 11707 | H5: 13972.937 | I5: 22989 | J5: 17476 | K5: 25024.412
A6: 4 | B6: Botswana | C6: 8191 | D6: 9284 | E6: 9739.0852 | F6: 1000 | G6: 7514 | H6: 8210.398 | I6: 9191 | J6: 16798 | K6: 17949.483
A7: 5 | B7: Burkina Faso | C7: 8983 | D7: 19646 | E7: 27591.375 | F7: 4585 | G7: 7601 | H7: 10576.497 | I7: 13568 | J7: 27247 | K7: 38167.872
A8: 6 | B8: Burundi | C8: 7170 | D8: 10533 | E8: 10709.32 | F8: 44 | G8: 37621 | H8: 42120.333 | I8: 7214 | J8: 48154 | K8: 52829.653
A9: 7 | B9: Cameroon | C9: 22321 | D9: 14532 | E9: 23282 | F9: 0 | G9: 16843 | H9: 8354.2378 | I9: 22321 | J9: 31375 | K9: 31636.238
A10: 8 | B10: Cape-Verde | C10: 711 | D10: 1666 | E10: 3734.4936 | F10: 7662 | G10: 5297 | H10: 2475.7981 | I10: 8373 | J10: 6963 | K10: 6210.2918
A11: 9 | B11: Central African Republic | C11: 1180 | D11: 2027 | E11: 1344.0062 | F11: 384 | G11: 1029 | H11: 4353.7072 | I11: 1564 | J11: 3056 | K11: 5697.7134
A12: 10 | B12: Chad | C12: 4702 | D12: 6992 | E12: 6338.6323 | F12: 1664 | G12: 3800 | H12: 33923.737 | I12: 6366 | J12: 10792 | K12: 40262.37
A13: 11 | B13: Comoros | C13: 452 | D13: 1541 | E13: 1868.1964 | F13: 841 | G13: 1215 | H13: 753.73247 | I13: 1293 | J13: 2756 | K13: 2621.9289
A14: 12 | B14: Congo | C14: 4571 | D14: 6962 | E14: 7791.8818 | F14: 4923 | G14: 3307 | H14: 4346 | I14: 9494 | J14: 10269 | K14: 12137.882
... A50: 48 | B50: AFRO | C50: 841834 | D50: 1994699 | E50: 2460099.1 | F50: 724195 | G50: 2312731 | H50: 2488957.6 | I50: 1566029 | J50: 4307430 | K50: 4949056.7

Sheet All workforce density 
B1: Core health workforce* | E1: Other workers | H1: Total
A2: Country | B2: Density per 10,000 (2013) | C2: Density per 10,000 (2018) | D2: Density per 10,000 (2022) | E2: Density per 10,000 (2013) | F2: Density per 10,000 (2018) | G2: Density per 10,000 (2022) | H2: Density per 10,000 (2013) | I2: Density per 10,000 (2018) | J2: Density per 10,000 (2022)
A3: Algeria | B3: 2.9312675 | C3: 41.893522 | D3: 16.52149 | E3: 0.052630711 | F3: 57.06799 | G3: 81.537078 | H3: 2.9838982 | I3: 98.961512 | J3: 98.058569
A4: Angola | B4: 0.011473591 | C4: 19.3352 | D4: 22.161285 | E4: 0.23023672 | F4: 16.090283 | G4: 16.295061 | H4: 0.24171031 | I4: 35.425483 | J4: 38.456346
A5: Benin | B5: 7.6857184 | C5: 4.8313817 | D5: 8.2764832 | E5: 14.614797 | F5: 9.7917343 | G5: 10.453141 | H5: 22.300515 | I5: 14.623116 | J5: 18.729624
A6: Botswana | B6: 36.941692 | C6: 37.872105 | D6: 37.026575 | E6: 4.5100344 | F6: 30.541625 | G6: 31.089269 | H6: 41.451726 | I6: 68.41373 | J6: 68.115844
A7: Burkina Faso | B7: 5.0934409 | C7: 9.6338287 | D7: 12.168856 | E7: 2.5997358 | F7: 3.7258389 | G7: 4.658467 | H7: 7.6931767 | I7: 13.359668 | J7: 16.827323
A8: Burundi | B8: 7.0643335 | C8: 9.1643322 | D8: 8.3085116 | E8: 0.043351558 | F8: 32.732492 | G8: 32.677826 | H8: 7.107685 | I8: 41.896824 | J8: 40.986337
A9: Cameroon | B9: 10.318104 | C9: 5.7950101 | D9: 8.3404573 | E9: 0 | F9: 6.716581 | G9: 2.9859847 | H9: 10.318104 | I9: 12.511591 | J9: 11.326442
A10: Cape-Verde | B10: 13.16813 | C10: 29.16659 | D10: 62.960411 | E10: 141.90466 | F10: 92.384211 | G10: 41.402684 | H10: 155.07279 | I10: 121.5508 | J10: 104.3631
A11: Central African Republic | B11: 2.4570902 | C11: 3.978582 | D11: 2.408983 | E11: 0.79959545 | F11: 2.0177515 | G11: 7.8017481 | H11: 3.2566857 | I11: 5.9963335 | J11: 10.210731
A12: Chad | B12: 3.5576024 | C12: 4.480842 | D12: 3.5764373 | E12: 1.2590069 | F12: 2.4352402 | G12: 19.134535 | H12: 4.8166093 | I12: 6.9160823 | J12: 22.710972
A13: Comoros | B13: 6.4627516 | C13: 19.850228 | D13: 22.32619 | E13: 12.024721 | F13: 15.650894 | G13: 9.0076044 | H13: 18.487473 | I13: 35.501122 | J13: 31.333795
A14: Congo | B14: 9.4675581 | C14: 12.795296 | D14: 13.050801 | E14: 10.196628 | F14: 6.0778576 | G14: 7.279215 | H14: 19.664186 | I14: 18.873154 | J14: 20.330016
... A50: AFRO | B50: 11.136507 | C50: 23.57697 | D50: 26.089625 | E50: 8.3497581 | F50: 26.690657 | G50: 27.338421 | H50: 19.486265 | I50: 50.267627 | J50: 53.428046

Sheet Doctors education
A1: Country | B1: Country code | C1: income level | D1: 2013 | E1: 2018 | F1: Adjusted 2022 | G1: Medical Doctors Stock By Age Group < 25 yrs (prop) | H1: Medical Doctors Stock By Age Group 25-34 yrs (prop) | I1: Medical Doctors Stock By Age Group 35-44 yrs (prop) | J1: Medical Doctors Stock By Age Group 45-54 yrs (prop) | K1: Medical Doctors Stock By Age Group 55-64 yrs (prop) | L1: Medical Doctors Stock By Age Group ≥ 65 yrs (prop) | M1: Medical Doctors Stock By Age Group < 25 yrs (prop) | N1: Medical Doctors Stock By Age Group 25-34 yrs | O1: Medical Doctors Stock By Age Group 35-44 yrs | P1: Medical Doctors Stock By Age Group 45-54 yrs | Q1: Medical Doctors Stock By Age Group 55-64 yrs | R1: Medical Doctors Stock By Age Group ≥ 65 yrs | S1: Annual graduates (2017 survey) | T1: Updated annual graduate | U1: Projected 2023 | V1: Projected 2024 | W1: Projected 2025 | X1: Projected 2026 | Y1: Projected 2027 | Z1: Projected 2028 | AA1: Projected 2029 | AB1: Projected 2030 | AC1: Force of movement from 55-64 into Age 65+ | AD1: stock to graduates | AE1: Estimated graduates
A2: Algeria | B2: DZA | C2: Lower-Middle-Income Economies | D2: 0 | E2: 73168 | F2: 75512 | G2: 0.082034048 | H2: 0.29430885 | I2: 0.2086111 | J2: 0.13796761 | K2: 0.17288304 | L2: 0.10419536 | M2: 6194.555 | N2: 22223.85 | O2: 15752.641 | P2: 10418.21 | Q2: 13054.744 | R2: 7868.0001 | S2: 0 | T2: 0 | U2: 70913.671 | V2: 72957.365 | W2: 74965.727 | X2: 76939.368 | Y2: 78878.888 | Z2: 80784.877 | AA2: 82657.915 | AB2: 84498.571 | AC2: 0.1 | AD2: 0.068 | AE2: 5134.816
A3: Angola | B3: AGO | C3: Lower-Middle-Income Economies | D3: 0 | E3: 6593 | F3: 8693 | G3: 0.009627305 | H3: 0.3275993 | I3: 0.3862164 | J3: 0.1759096 | K3: 0.080800436 | L3: 0.019846966 | M3: 83.690162 | N3: 2847.8207 | O3: 3357.3792 | P3: 1529.1821 | Q3: 702.39819 | R3: 172.52967 | S3: 0 | T3: 611 | U3: 8932.0703 | V3: 9271.4988 | W3: 9608.1847 | X3: 9942.1501 | Y3: 10273.417 | Z3: 10602.007 | AA3: 10927.943 | AB3: 11251.245 | AC3: 0.1 | AD3: 0.070286437 | AE3: 611
A4: Benin | B4: BEN | C4: Lower-Middle-Income Economies | D4: 0 | E4: 908 | F4: 2608 | G4: 0.012341198 | H4: 0.40471869 | I4: 0.33248639 | J4: 0.16624319 | K4: 0.080217786 | L4: 0.0039927405 | M4: 32.185844 | N4: 1055.5064 | O4: 867.1245 | P4: 433.56225 | Q4: 209.20799 | R4: 10.413067 | S4: 291 | T4: 780 | U4: 3134.9369 | V4: 3647.1392 | W4: 4155.2326 | X4: 4659.2503 | Y4: 5159.2248 | Z4: 5655.1886 | AA4: 6147.174 | AB4: 6635.2127 | AC4: 0.1 | AD4: 0.29907975 | AE4: 780
A5: Botswana | B5: BWA | C5: High/Upper-Middle-Income Economies | D5: 819 | E5: 925 | F5: 992 | G5: 0 | H5: 0.48640483 | I5: 0.32527694 | J5: 0.12185297 | K5: 0.052366566 | L5: 0.014098691 | M5: 0 | N5: 482.5136 | O5: 322.67472 | P5: 120.87815 | Q5: 51.947633 | R5: 13.985901 | S5: 8 | T5: 60 | U5: 1019.0641 | V5: 1054.7776 | W5: 1090.3041 | X5: 1125.6446 | Y5: 1160.7999 | Z5: 1195.7712 | AA5: 1230.5594 | AB5: 1265.1654 | AC5: 0.1 | AD5: 0.060483871 | AE5: 60
A6: Burkina Faso | B6: BFA | C6: Low-Income Economies | D6: 803 | E6: 1684 | F6: 3323 | G6: 0 | H6: 0.47976391 | I6: 0.45868465 | J6: 0.047217538 | K6: 0.01391231 | L6: 0.00042158516 | M6: 0 | N6: 1594.2555 | O6: 1524.2091 | P6: 156.90388 | Q6: 46.230607 | R6: 1.4009275 | S6: 578 | T6: 1492 | U6: 4363.2491 | V6: 5398.8288 | W6: 6432.9678 | X6: 7465.668 | Y6: 8496.9316 | Z6: 9526.7604 | AA6: 10555.156 | AB6: 11582.122 | AC6: 0.1 | AD6: 0.44899187 | AE6: 1492
A7: Burundi | B7: BDI | C7: Low-Income Economies | D7: 554 | E7: 1084 | F7: 1014.861 | G7: 0 | H7: 0.23688394 | I7: 0.62957075 | J7: 0.096979332 | K7: 0.030206677 | L7: 0.0063593005 | M7: 0 | N7: 240.40428 | O7: 638.92682 | P7: 98.420546 | Q7: 30.65558 | R7: 6.4538063 | S7: 319 | T7: 325 | U7: 1229.3072 | V7: 1446.4939 | W7: 1663.0245 | X7: 1878.9011 | Y7: 2094.1255 | Z7: 2308.6999 | AA7: 2522.6261 | AB7: 2735.9061 | AC7: 0.1 | AD7: 0.32024089 | AE7: 325
A8: Cameroon | B8: CMR | C8: Lower-Middle-Income Economies | D8: 1842 | E8: 3259 | F8: 3759 | G8: 0.0039872408 | H8: 0.50212653 | I8: 0.32961191 | J8: 0.12068049 | K8: 0.041467305 | L8: 0.0021265284 | M8: 14.988038 | N8: 1887.4936 | O8: 1239.0112 | P8: 453.63796 | Q8: 155.8756 | R8: 7.9936204 | S8: 0 | T8: 800 | U8: 4289.0564 | V8: 4809.3208 | W8: 5327.4279 | X8: 5843.3865 | Y8: 6357.2055 | Z8: 6868.8939 | AA8: 7378.4604 | AB8: 7885.9139 | AC8: 0.1 | AD8: 0.21282256 | AE8: 800
A9: Cape-Verde | B9: CPV | C9: Lower-Middle-Income Economies | D9: 308 | E9: 452 | F9: 2644 | G9: 0.0041603631 | H9: 0.20385779 | I9: 0.30295008 | J9: 0.26966717 | K9: 0.1709531 | L9: 0.048411498 | M9: 11 | N9: 539 | O9: 801 | P9: 713 | Q9: 452 | R9: 128 | S9: 0 | T9: 0 | U9: 2638.8544 | V9: 2716.5968 | W9: 2793.0101 | X9: 2868.1171 | Y9: 2941.9402 | Z9: 3014.5012 | AA9: 3085.8218 | AB9: 3155.9231 | AC9: 0.1 | AD9: 0.068 | AE9: 179.792
A10: Central African Republic | B10: CAF | C10: Low-Income Economies | D10: 324 | E10: 335 | F10: 146.38958 | G10: 0.0084136314 | H10: 0.47834159 | I10: 0.34535536 | J10: 0.11474563 | K10: 0.041844842 | L10: 0.011298946 | M10: 1.231668 | N10: 70.024224 | O10: 50.556426 | P10: 16.797564 | Q10: 6.1256487 | R10: 1.654048 | S10: 0 | T10: 18 | U10: 156.28553 | V10: 167.18156 | W10: 178.03199 | X10: 188.83702 | Y10: 199.59683 | Z10: 210.31162 | AA10: 220.98157 | AB10: 231.60688 | AC10: 0.1 | AD10: 0.12295957 | AE10: 18
A11: Chad | B11: TCD | C11: Low-Income Economies | D11: 573 | E11: 803 | F11: 1507 | G11: 0.0019880716 | H11: 0.58316766 | I11: 0.28098078 | J11: 0.085487078 | K11: 0.048376408 | L11: 0 | M11: 2.9960239 | N11: 878.83366 | O11: 423.43804 | P11: 128.82903 | Q11: 72.903247 | R11: 0 | S11: 113 | T11: 330 | U11: 1737.3 | V11: 1959.1956 | W11: 2180.0177 | X11: 2399.7715 | Y11: 2618.4623 | Z11: 2836.0951 | AA11: 3052.6751 | AB11: 3268.2074 | AC11: 0.1 | AD11: 0.2189781 | AE11: 330
A12: Comoros | B12: COM | C12: Lower-Middle-Income Economies | D12: 123 | E12: 220 | F12: 354 | G12: 0.009627305 | H12: 0.3275993 | I12: 0.3862164 | J12: 0.1759096 | K12: 0.080800436 | L12: 0.019846966 | M12: 3.408066 | N12: 115.97015 | O12: 136.72061 | P12: 62.271998 | Q12: 28.603354 | R12: 7.0258259 | S12: 0 | T12: 0 | U12: 363.62457 | V12: 377.33687 | W12: 390.93837 | X12: 404.42997 | Y12: 417.81256 | Z12: 431.08702 | AA12: 444.25422 | AB12: 457.31502 | AC12: 0.1 | AD12: 0.068 | AE12: 24.072
A13: Congo | B13: COG | C13: Lower-Middle-Income Economies | D13: 0 | E13: 544 | F13: 1042 | G13: 0 | H13: 0.4452975 | I13: 0.29942418 | J13: 0.11612284 | K13: 0.13147793 | L13: 0.0076775432 | M13: 0 | N13: 464 | O13: 312 | P13: 121 | Q13: 137 | R13: 8 | S13: 39 | T13: 60 | U13: 1063.4 | V13: 1078.8186 | W13: 1094.0346 | X13: 1109.0504 | Y13: 1123.8688 | Z13: 1138.4925 | AA13: 1152.9238 | AB13: 1167.1654 | AC13: 0.1 | AD13: 0.057581574 | AE13: 60
... A48: Zimbabwe | B48: ZWE | C48: Lower-Middle-Income Economies | D48: 1114 | E48: 3026 | F48: 3131.5984 | G48: 0 | H48: 0.1598966 | I48: 0.4098966 | J48: 0.43020679 | K48: 0 | L48: 0 | M48: 0 | N48: 500.73194 | O48: 1283.6315 | P48: 1347.2349 | Q48: 0 | R48: 0 | S48: 212 | T48: 265 | U48: 3285.7984 | V48: 3439.9984 | W48: 3594.1984 | X48: 3748.3984 | Y48: 3902.5984 | Z48: 4056.7984 | AA48: 4210.9984 | AB48: 4365.1984 | AC48: 0.1 | AD48: 0.084621324 | AE48: 265

Sheet Nurses education
A1: Country | B1: Country code | C1: income level | D1: 2013 | E1: 2018 | F1: Adjusted 2022 | G1: Nursing Personnel Stock By Age Group < 25 yrs (prop) | H1: Nursing Personnel Stock By Age Group 25-34 yrs (prop) | I1: Nursing Personnel Stock By Age Group 35-44 yrs (prop) | J1: Nursing Personnel Stock By Age Group 45-54 yrs (prop) | K1: Nursing Personnel Stock By Age Group 55-64 yrs (prop) | L1: Nursing Personnel Stock By Age Group ≥ 65 yrs (prop) | M1: Nursing Personnel Stock By Age Group < 25 yrs | N1: Nursing Personnel Stock By Age Group 25-34 yrs | O1: Nursing Personnel Stock By Age Group 35-44 yrs | P1: Nursing Personnel Stock By Age Group 45-54 yrs | Q1: Nursing Personnel Stock By Age Group 55-64 yrs | R1: Nursing Personnel Stock By Age Group ≥ 65 yrs | S1: Updated Annual graduated | T1: Ratio of stock to graduates | U1: Estimated annual graduates | V1: Projected 2023 | W1: Projected 2024 | X1: Projected 2025 | Y1: Projected 2026 | Z1: Projected 2027 | AA1: Projected 2028 | AB1: Projected 2029 | AC1: Projected 2030
A2: Algeria | B2: DZA | C2: Lower-Middle-Income Economies | D2: 0 | E2: 57705 | F2: 104776 | G2: 0.093988761 | H2: 0.30100512 | I2: 0.16025243 | J2: 0.35528532 | K2: 0.0841148 | L2: 0.0053535658 | M2: 5423.6215 | N2: 17369.501 | O2: 9247.3666 | P2: 20501.739 | Q2: 4853.8446 | R2: 308.92751 | S2: 0 | T2: 0.0811 | U2: 4679.8755 | V2: 107436.99 | W2: 109755.2 | X2: 112053.91 | Y2: 114333.28 | Z2: 116593.48 | AA2: 118834.67 | AB2: 121057.01 | AC2: 123260.65
A3: Angola | B3: AGO | C3: Lower-Middle-Income Economies | D3: 0 | E3: 46082 | F3: 66717.354 | G3: 0.031079804 | H3: 0.33653963 | I3: 0.34941396 | J3: 0.20169963 | K3: 0.073507085 | L3: 0.0077599026 | M3: 2073.5623 | N3: 22453.033 | O3: 23311.975 | P3: 13456.865 | Q3: 4904.1982 | R3: 517.72017 | S3: 2950 | T3: 0.044216382 | U3: 2950 | V3: 68260.684 | W3: 69819.969 | X3: 71367.793 | Y3: 72904.239 | Z3: 74429.391 | AA3: 75943.333 | AB3: 77446.145 | AC3: 78937.911
A4: Benin | B4: BEN | C4: Lower-Middle-Income Economies | D4: 4880 | E4: 3410 | F4: 5893 | G4: 0.037563822 | H4: 0.15973742 | I4: 0.44164843 | J4: 0.30069292 | K4: 0.05269876 | L4: 0.0076586433 | M4: 2506.1588 | N4: 10657.258 | O4: 29465.615 | P4: 20061.436 | Q4: 3515.9218 | R4: 510.96442 | S4: 257 | T4: 0.043611064 | U4: 257 | V4: 6027.4676 | W4: 6175.3036 | X4: 6322.3605 | Y4: 6468.6425 | Z4: 6614.1535 | AA4: 6758.8978 | AB4: 6902.8792 | AC4: 7046.1019
A5: Botswana | B5: BWA | C5: High/Upper-Middle-Income Economies | D5: 5816 | E5: 7645 | F5: 8028 | G5: 0.028276034 | H5: 0.36858495 | I5: 0.33096662 | J5: 0.18709517 | K5: 0.080468361 | L5: 0.004608869 | M5: 1886.5022 | N5: 24591.013 | O5: 22081.217 | P5: 12482.494 | Q5: 5368.6361 | R5: 307.49154 | S5: 490 | T5: 0.061036373 | U5: 490 | V5: 8319.9 | W5: 8581.8511 | X5: 8841.6944 | Y5: 9099.4467 | Z5: 9355.125 | AA5: 9608.7458 | AB5: 9860.3258 | AC5: 10109.881
A6: Burkina Faso | B6: BFA | C6: Low-Income Economies | D6: 6196 | E6: 10325 | F6: 13961 | G6: 0.16765299 | H6: 0.35339731 | I6: 0.29951984 | J6: 0.13365552 | K6: 0.043048784 | L6: 0.0027255474 | M6: 11185.364 | N6: 23577.734 | O6: 19983.171 | P6: 8917.1429 | Q6: 2872.1009 | R6: 181.84131 | S6: 1170 | T6: 0.083804885 | U6: 1170 | V6: 14738.299 | W6: 15490.202 | X6: 16238.869 | Y6: 16984.312 | Z6: 17726.547 | AA6: 18465.586 | AB6: 19201.444 | AC6: 19934.134
A7: Burundi | B7: BDI | C7: Low-Income Economies | D7: 6573 | E7: 9156 | F7: 9372 | G7: 0.0022612397 | H7: 0.32016494 | I7: 0.46847566 | J7: 0.16440543 | K7: 0.038840117 | L7: 0.0058526204 | M7: 150.86393 | N7: 21360.557 | O7: 31255.456 | P7: 10968.695 | Q7: 2591.3098 | R7: 390.47134 | S7: 1467 | T7: 0.15653009 | U7: 1467 | V7: 10343.399 | W7: 11329.475 | X7: 12311.722 | Y7: 13290.153 | Z7: 14264.784 | AA7: 15235.629 | AB7: 16202.704 | AC7: 17166.022
A8: Cameroon | B8: CMR | C8: Lower-Middle-Income Economies | D8: 18954 | E8: 9925 | F8: 16473 | G8: 0.017974253 | H8: 0.39561574 | I8: 0.37776293 | J8: 0.17585621 | K8: 0.031637114 | L8: 0.0011537527 | M8: 1199.1946 | N8: 26394.435 | O8: 25203.343 | P8: 11732.661 | Q8: 2110.7446 | R8: 76.975329 | S8: 2660 | T8: 0.16147636 | U8: 2660 | V8: 17904.544 | W8: 19298.449 | X8: 20687.945 | Y8: 22073.044 | Z8: 23453.761 | AA8: 24830.11 | AB8: 26202.105 | AC8: 27569.759
A9: Cape-Verde | B9: CPV | C9: Lower-Middle-Income Economies | D9: 403 | E9: 768 | F9: 941 | G9: 0 | H9: 0.26886291 | I9: 0.26461211 | J9: 0.27842721 | K9: 0.1360255 | L9: 0.052072264 | M9: 0 | N9: 17937.822 | O9: 17654.22 | P9: 18575.926 | Q9: 9075.2617 | R9: 3474.1236 | S9: 0 | T9: 0.0811 | U9: 76.3151 | V9: 931.72057 | W9: 958.76736 | X9: 985.44625 | Y9: 1011.7622 | Z9: 1037.7203 | AA9: 1063.3252 | AB9: 1088.5818 | AC9: 1113.4949
A10: Central African Republic | B10: CAF | C10: Low-Income Economies | D10: 322 | E10: 1195 | F10: 648.48015 | G10: 0.16765299 | H10: 0.35339731 | I10: 0.29951984 | J10: 0.13365552 | K10: 0.043048784 | L10: 0.0027255474 | M10: 11185.364 | N10: 23577.734 | O10: 19983.171 | P10: 8917.1429 | Q10: 2872.1009 | R10: 181.84131 | S10: 0 | T10: 0.162 | U10: 105.05378 | V10: 720.20033 | W10: 790.58761 | X10: 860.67187 | Y10: 930.45443 | Z10: 999.93659 | AA10: 1069.1196 | AB10: 1138.0049 | AC10: 1206.5935
A11: Chad | B11: TCD | C11: Low-Income Economies | D11: 3606 | E11: 4799 | F11: 3387.1517 | G11: 0.036531037 | H11: 0.44371844 | I11: 0.31006831 | J11: 0.14582715 | K11: 0.063855064 | L11: 0 | M11: 2437.2541 | N11: 29603.72 | O11: 20686.937 | P11: 9729.2013 | Q11: 4260.2409 | R11: 0 | S11: 2920 | T11: 0.86208125 | U11: 2920 | V11: 5427.8017 | W11: 7433.7925 | X11: 9426.9739 | Y11: 11407.428 | Z11: 13375.236 | AA11: 15330.478 | AB11: 17273.235 | AC11: 19203.587
A12: Comoros | B12: COM | C12: Lower-Middle-Income Economies | D12: 0 | E12: 747 | F12: 784.97097 | G12: 0.031079804 | H12: 0.33653963 | I12: 0.34941396 | J12: 0.20169963 | K12: 0.073507085 | L12: 0.0077599026 | M12: 2073.5623 | N12: 22453.033 | O12: 23311.975 | P12: 13456.865 | Q12: 4904.1982 | R12: 517.72017 | S12: 40 | T12: 0.050957298 | U12: 40 | V12: 806.87968 | W12: 828.94854 | X12: 850.85518 | Y12: 872.60079 | Z12: 894.18656 | AA12: 915.61365 | AB12: 936.88324 | AC12: 957.99649
A13: Congo | B13: COG | C13: Lower-Middle-Income Economies | D13: 3289 | E13: 5081 | F13: 5573 | G13: 0.013457743 | H13: 0.12739996 | I13: 0.46438184 | J13: 0.27310246 | K13: 0.12111968 | L13: 0.00053830971 | M13: 897.86498 | N13: 8499.7885 | O13: 30982.328 | P13: 18220.673 | Q13: 8080.7848 | R13: 35.914599 | S13: 60 | T13: 0.010766194 | U13: 60 | V13: 5597.6 | W13: 5557.402 | X13: 5517.691 | Y13: 5478.4609 | Z13: 5439.7059 | AA13: 5401.4204 | AB13: 5363.5985 | AC13: 5326.2348
... A48: Zimbabwe | B48: ZWE | C48: Lower-Middle-Income Economies | D48: 18722 | E48: 27874 | F48: 46537 | G48: 0.031079804 | H48: 0.33653963 | I48: 0.34941396 | J48: 0.20169963 | K48: 0.073507085 | L48: 0.0077599026 | M48: 2073.5623 | N48: 22453.033 | O48: 23311.975 | P48: 13456.865 | Q48: 4904.1982 | R48: 517.72017 | S48: 1100 | T48: 0.023637106 | U48: 1100 | V48: 46568.527 | W48: 46618.866 | X48: 46668.834 | Y48: 46718.435 | Z48: 46767.671 | AA48: 46816.546 | AB48: 46865.061 | AC48: 46913.22
A49: AFRO | B49: AFRO | C49: AFRO | D49: 479279 | E49: 1248604 | F49: 1698828.4 | G49: 0.028094911 | H49: 0.42408199 | I49: 0.32237544 | J49: 0.14725788 | K49: 0.073303781 | L49: 0.0048859963 | M49: 1874.4181 | N49: 28293.628 | O49: 21508.036 | P49: 9824.6558 | Q49: 4890.6343 | R49: 325.98074 | T49: 0.0429 | U49: 72879.739 | V49: 1751813.5 | W49: 1816536.1 | X49: 1881091.6 | Y49: 1945479.7 | Z49: 2009700.3 | AA49: 2073753 | AB49: 2137637.7 | AC49: 2201354.2

Sheet stockgranddensity
A1: Country | B1: Country | C1: Doctors and Nurses Density per 10,000 (2022) | D1: Ratio stock to graduates | E1: Population | F1: Graduates Doctors and Nurses per 10,000
A2: Seychelles | B2: SYC | C2: 196.51134 | D2: 42.1 | E2: 107118.5 | F2: =C2/D2 -> 4.6677278
A3: South Africa | B3: ZAF | C3: 74.345193 | D3: 107.24524 | E3: 59893886 | F3: =C3/D3 -> 0.69322602
A4: Namibia | B4: NAM | C4: 66.829911 | D4: 25.415291 | E4: 2567012.5 | F4: =C4/D4 -> 2.6295158
A5: Cabo Verde | B5: CPV | C5: 60.440075 | D5: 13.99805 | E5: 593149.5 | F5: =C5/D5 -> 4.3177496
A6: Mauritius | B6: MUS | C6: 49.501252 | D6: 10.597256 | E6: 1299469 | F6: =C6/D6 -> 4.6711387
A7: Eswatini | B7: SWZ | C7: 49.339648 | D7: 28.681863 | E7: 1201670.5 | F7: =C7/D7 -> 1.7202386
A8: Ghana | B8: GHA | C8: 38.514391 | D8: 5.6456749 | E8: 33475871 | F8: =C8/D8 -> 6.8219286
A9: Algeria | B9: DZA | C9: 40.150346 | D9: 18.369197 | E9: 44903225 | F9: =C9/D9 -> 2.1857431
A10: Zimbabwe | B10: ZWE | C10: 30.433189 | D10: 36.387252 | E10: 16320537 | F10: =C10/D10 -> 0.83636954
A11: Botswana | B11: BWA | C11: 34.292718 | D11: 16.4 | E11: 2630296 | F11: =C11/D11 -> 2.0910194
A12: Zambia | B12: ZMB | C12: 28.228053 | D12: 10.489326 | E12: 20017675 | F12: =C12/D12 -> 2.6911217
A13: Gabon | B13: GAB | C13: 25.186306 | D13: 42.673686 | E13: 2388992.5 | F13: =C13/D13 -> 0.59020696
... A48: Niger | B48: NER | C48: 2.0110936 | D48: 7.8083991 | E48: 26207976 | F48: =C48/D48 -> 0.25755518
