Workbook

Sheet Sheet1
A1: Country | B1: 2013 | C1: 2018 | D1: Doctors stock 2022 | E1: Doctors graduates
A2: Algeria | B2: 0 | C2: 73168 | D2: 48033.824 | E2: =VLOOKUP(A2,Sheet2!A$2:B$48,2,FALSE) -> 0
A3: Angola | B3: 0 | C3: 6593 | D3: 8693 | E3: =VLOOKUP(A3,Sheet2!A$2:B$48,2,FALSE) -> 611
A4: Benin | B4: 0 | C4: 908 | D4: 2608 | E4: =VLOOKUP(A4,Sheet2!A$2:B$48,2,FALSE) -> 780
A5: Botswana | B5: 819 | C5: 925 | D5: 992 | E5: =VLOOKUP(A5,Sheet2!A$2:B$48,2,FALSE) -> 60
A6: Burkina Faso | B6: 803 | C6: 1684 | D6: 3323 | E6: =VLOOKUP(A6,Sheet2!A$2:B$48,2,FALSE) -> 1492
A7: Burundi | B7: 554 | C7: 1084 | D7: 1014.861 | E7: =VLOOKUP(A7,Sheet2!A$2:B$48,2,FALSE) -> 325
A8: Cameroon | B8: 1842 | C8: 3259 | D8: 3759 | E8: =VLOOKUP(A8,Sheet2!A$2:B$48,2,FALSE) -> 800
A9: Cabo Verde | B9: 308 | C9: 452 | D9: 2644 | E9: =VLOOKUP(A9,Sheet2!A$2:B$48,2,FALSE) -> 0
A10: Central African Republic | B10: 324 | C10: 335 | D10: 146.38958 | E10: =VLOOKUP(A10,Sheet2!A$2:B$48,2,FALSE) -> 18
A11: Chad | B11: 573 | C11: 803 | D11: 1507 | E11: =VLOOKUP(A11,Sheet2!A$2:B$48,2,FALSE) -> 330
A12: Comoros | B12: 123 | C12: 220 | D12: 354 | E12: =VLOOKUP(A12,Sheet2!A$2:B$48,2,FALSE) -> 0
A13: Congo | B13: 0 | C13: 544 | D13: 1042 | E13: =VLOOKUP(A13,Sheet2!A$2:B$48,2,FALSE) -> 60
... A48: Zimbabwe | B48: 1114 | C48: 3026 | D48: 3131.5984 | E48: =VLOOKUP(A48,Sheet2!A$2:B$48,2,FALSE) -> 265

Sheet Sheet2
A1: Country | B1: Generalist Medical Practitioners | C1: Specialist Medical Practitioners | D1: Dentists | E1: Other Dental practitioners | F1: Pharmacists | G1: Other Pharmacy practitioners | H1: Midwifery personnel | I1: Nursing Personnel | J1: Medical and Pathology Laboratory scientists | K1: Paramedical Practitioners | L1: Other Health Workers | M1: Total
A2: Algeria | B2: 0 | M2: 0
A3: Angola | B3: 611 | D3: 145 | F3: 529 | I3: 2950 | M3: 4235
A4: Benin | B4: 780 | C4: 385 | F4: 143 | H4: 247 | I4: 257 | J4: 1113 | L4: 1194 | M4: 4119
A5: Botswana | B5: 60 | C5: 48 | D5: 7 | E5: 10 | F5: 95 | G5: 60 | H5: 40 | I5: 490 | J5: 189 | K5: 30 | L5: 597 | M5: 1626
A6: Burkina Faso | B6: 1492 | C6: 385 | D6: 62 | F6: 594 | H6: 1170 | I6: 1170 | M6: 4873
A7: Burundi | B7: 325 | C7: 240 | F7: 39 | H7: 196 | I7: 1467 | J7: 322 | L7: 194 | M7: 2783
A8: Cameroon | B8: 800 | I8: 2660 | J8: 800 | M8: 4260
A9: Cabo Verde | E9: 7 | L9: 83 | M9: 90
A10: Central African Republic | B10: 18 | M10: 18
A11: Chad | B11: 330 | C11: 30 | F11: 80 | G11: 180 | H11: 2084 | I11: 2920 | J11: 220 | M11: 5844
A12: Comoros | H12: 29 | I12: 40 | M12: 69
A13: Congo | B13: 60 | C13: 315 | E13: 10 | G13: 5 | H13: 120 | I13: 60 | K13: 50 | L13: 408 | M13: 1028
A14: Cote d'Ivoire | B14: 254 | C14: 48 | G14: 151 | I14: 1007 | J14: 1106 | L14: 450 | M14: 3016
A15: DRC | B15: 6020 | D15: 66 | F15: 178 | G15: 328 | H15: 3453 | I15: 24061 | J15: 2571 | L15: 3151 | M15: 39828
A16: Equatorial Guinea | B16: 767 | H16: 492 | I16: 962 | J16: 27 | L16: 1304 | M16: 3552
A17: Eritrea | I17: 400 | L17: 1023 | M17: 1423
A18: Eswatini | F18: 44 | G18: 30 | H18: 80 | I18: 160 | J18: 78 | L18: 58 | M18: 450
A19: Ethiopia | B19: 3114 | C19: 880 | D19: 189 | E19: 64 | F19: 699 | G19: 2878 | H19: 2440 | I19: 6298 | J19: 1220 | K19: 1613 | L19: 3672 | M19: 23067
A20: Gabon | B20: 46 | C20: 16 | F20: 2 | H20: 34 | I20: 95 | J20: 6 | M20: 199
A21: Gambia | B21: 23 | I21: 137 | J21: 6 | M21: 166
A22: Ghana | B22: 1566 | F22: 343 | H22: 4827 | I22: 21271 | J22: 396 | M22: 28403
A23: Guinea | B23: 767 | C23: 74 | F23: 113 | G23: 34 | H23: 492 | I23: 964 | J23: 27 | L23: 1304 | M23: 3775
A24: Guinea-Bissau | J24: 23 | L24: 489 | M24: 512
A25: Kenya | B25: 558 | D25: 36 | F25: 379 | G25: 20 | I25: 1070 | J25: 519 | L25: 366 | M25: 2948
A26: Lesotho | B26: 8 | C26: 22 | D26: 8 | F26: 33 | G26: 20 | H26: 69 | I26: 376 | J26: 20 | M26: 556
A27: Liberia | B27: 29 | C27: 50 | F27: 22 | I27: 63 | J27: 56 | L27: 50 | M27: 270
A28: Madagascar | B28: 316 | C28: 156 | H28: 2473 | I28: 2540 | J28: 116 | L28: 297 | M28: 5898
A29: Malawi | B29: 115 | C29: 167 | F29: 110 | G29: 189 | H29: 1171 | I29: 386 | J29: 175 | L29: 616 | M29: 2929
A30: Mali | M30: 0
A31: Mauritania | C31: 76 | I31: 113 | L31: 366 | M31: 555
A32: Mauritius | B32: 432 | H32: 40 | I32: 175 | L32: 39 | M32: 686
A33: Mozambique | B33: 819 | C33: 146 | D33: 161 | G33: 112 | H33: 140 | I33: 580 | J33: 248 | K33: 20 | M33: 2226
A34: Namibia | B34: 475 | C34: 3 | F34: 247 | G34: 31 | H34: 1414 | I34: 200 | J34: 121 | L34: 175 | M34: 2666
A35: Niger | B35: 370 | C35: 14 | H35: 124 | I35: 305 | J35: 45 | L35: 1891 | M35: 2749
A36: Nigeria | B36: 4340 | D36: 459 | H36: 375 | I36: 12835 | J36: 1774 | M36: 19783
A37: Rwanda | B37: 11 | F37: 95 | H37: 176 | I37: 355 | L37: 81 | M37: 718
A38: Sao Tome and Principe | M38: 0
A39: Senegal | B39: 434 | C39: 137 | D39: 67 | F39: 171 | H39: 104 | I39: 582 | J39: 36 | L39: 710 | M39: 2241
A40: Seychelles | B40: 10 | G40: 20 | H40: 10 | I40: 40 | L40: 80 | M40: 160
...
