Workbook

Sheet Data
A1: country_short_name | B1: code | C1: year | D1: income | E1: hr_che | F1: sr_hr_gghed_gghed | G1: sr_hr_gghed_hr | H1: xrt | I1: pop | J1: xrt_2019 | K1: che_usd2019_pc | L1: m_doctors_density | M1: year_doctors_density | N1: hr_usd2019_pc | O1: sub_group_name_3 | P1: sub_income | Q1: gghed_gge | R1: sr_hr_pvtd_hr | S1: sr_hr_ext_hr | T1: HALE | U1: RMNCAH | V1: Infectious dieases | W1: NCD | X1: Service capacity and access
A2: Burundi | B2: BDI | C2: 2018 | D2: Low | E2: 15.763333 | F2: 39.396931 | G2: 69.388785 | H2: 1782.8768 | I2: 11175.374 | J2: 1845.6229 | K2: 21.505672 | L2: 1.0011998 | M2: 2019 | N2: 3.3900108 | O2: ECCAS | P2: Low-income | Q2: 8.4705248 | R2: 17.613289 | S2: 12.997926 | T2: =VLOOKUP(B2,HALE!A$2:J$48,10,FALSE) -> 55.6 | U2: =VLOOKUP(B2,RMNCAH!D$2:J$195,7,FALSE) -> 59 | V2: =VLOOKUP(B2, 'Infectious D'!A$2:G$195,7,FALSE) -> 60 | W2: =VLOOKUP(B2,NCDs!A$1:G$47,7,FALSE) -> 59 | X2: =VLOOKUP(B2,'Service capacity and access'!A$2:G$48,7,FALSE) -> 14
A3: Burkina Faso | B3: BFA | C3: 2019 | D3: Low | E3: 32.880543 | F3: 65.129503 | G3: 82.824007 | H3: 585.91101 | I3: 20321.378 | J3: 585.91101 | K3: 42.344528 | L3: 0.93989666 | M3: 2019 | N3: 13.923111 | O3: WAEMU | P3: Low-income | Q3: 9.5769281 | R3: 5.8908882 | S3: 11.285105 | T3: =VLOOKUP(B3,HALE!A$2:J$48,10,FALSE) -> 54.9 | U3: =VLOOKUP(B3,RMNCAH!D$2:J$195,7,FALSE) -> 60 | V3: =VLOOKUP(B3, 'Infectious D'!A$2:G$195,7,FALSE) -> 50 | W3: =VLOOKUP(B3,NCDs!A$1:G$47,7,FALSE) -> 55 | X3: =VLOOKUP(B3,'Service capacity and access'!A$2:G$48,7,FALSE) -> 15
A4: Botswana | B4: BWA | C4: 2017 | D4: Upper middle | E4: 36.852196 | F4: 44.39461 | G4: 91.1446 | H4: 10.347417 | I4: 2205.08 | J4: 10.755867 | K4: 474.01831 | L4: 2.8925493 | M4: 2018 | N4: 174.68613 | O4: SADC | P4: Middle-income | Q4: 14.315475 | R4: 3.1786098 | S4: 5.6767898 | T4: =VLOOKUP(B4,HALE!A$2:J$48,10,FALSE) -> 53.9 | U4: =VLOOKUP(B4,RMNCAH!D$2:J$195,7,FALSE) -> 54 | V4: =VLOOKUP(B4, 'Infectious D'!A$2:G$195,7,FALSE) -> 66 | W4: =VLOOKUP(B4,NCDs!A$1:G$47,7,FALSE) -> 60 | X4: =VLOOKUP(B4,'Service capacity and access'!A$2:G$48,7,FALSE) -> 43
A5: Central African Rep. | B5: CAF | C5: 2018 | D5: Low | E5: 19.953117 | F5: 33.738449 | G5: 10.588879 | H5: 555.44647 | I5: 4666.368 | J5: 585.91101 | K5: 52.09977 | L5: 0.7210943 | M5: 2015 | N5: 10.395529 | O5: ECCAS | P5: Low-income | Q5: 3.9108746 | R5: 25.707739 | S5: 63.703381 | T5: =VLOOKUP(B5,HALE!A$2:J$48,10,FALSE) -> 46.4 | U5: =VLOOKUP(B5,RMNCAH!D$2:J$195,7,FALSE) -> 38 | V5: =VLOOKUP(B5, 'Infectious D'!A$2:G$195,7,FALSE) -> 39 | W5: =VLOOKUP(B5,NCDs!A$1:G$47,7,FALSE) -> 44 | X5: =VLOOKUP(B5,'Service capacity and access'!A$2:G$48,7,FALSE) -> 17
A6: Côte d'Ivoire | B6: CIV | C6: 2018 | D6: Lower middle | E6: 19.252622 | F6: 59.380839 | G6: 89.648114 | H6: 555.44647 | I6: 25069.23 | J6: 585.91101 | K6: 68.557785 | L6: 1.6226902 | M6: 2019 | N6: 13.19917 | O6: WAEMU | P6: Middle-income | Q6: 5.1173263 | R6: 5.0805235 | S6: 5.2713628 | T6: =VLOOKUP(B6,HALE!A$2:J$48,10,FALSE) -> 54.8 | U6: =VLOOKUP(B6,RMNCAH!D$2:J$195,7,FALSE) -> 51 | V6: =VLOOKUP(B6, 'Infectious D'!A$2:G$195,7,FALSE) -> 58 | W6: =VLOOKUP(B6,NCDs!A$1:G$47,7,FALSE) -> 59 | X6: =VLOOKUP(B6,'Service capacity and access'!A$2:G$48,7,FALSE) -> 19
A7: DR Congo | B7: COD | C7: 2019 | D7: Low | E7: 31.463267 | F7: 85.237445 | G7: 42.852808 | H7: 1647.7601 | I7: 86790.567 | J7: 1647.7601 | K7: 20.570732 | L7: 0.89939848 | M7: 2016 | N7: 6.4722247 | O7: ECCAS | P7: Low-income | Q7: 4.4249554 | R7: 7.9805975 | S7: 49.166595 | T7: =VLOOKUP(B7,HALE!A$2:J$48,10,FALSE) -> 54.1 | U7: =VLOOKUP(B7,RMNCAH!D$2:J$195,7,FALSE) -> 43 | V7: =VLOOKUP(B7, 'Infectious D'!A$2:G$195,7,FALSE) -> 48 | W7: =VLOOKUP(B7,NCDs!A$1:G$47,7,FALSE) -> 60 | X7: =VLOOKUP(B7,'Service capacity and access'!A$2:G$48,7,FALSE) -> 24
A8: Congo | B8: COG | C8: 2019 | D8: Lower middle | E8: 43.066372 | F8: 58.222172 | G8: 50.823961 | H8: 585.91101 | I8: 5380.508 | J8: 585.91101 | K8: 48.558773 | L8: 1.0640442 | M8: 2016 | N8: 20.912502 | O8: ECCAS | P8: Middle-income | Q8: 3.4871681 | R8: 43.398785 | S8: 5.7772541 | T8: =VLOOKUP(B8,HALE!A$2:J$48,10,FALSE) -> 56.2 | U8: =VLOOKUP(B8,RMNCAH!D$2:J$195,7,FALSE) -> 52 | V8: =VLOOKUP(B8, 'Infectious D'!A$2:G$195,7,FALSE) -> 36 | W8: =VLOOKUP(B8,NCDs!A$1:G$47,7,FALSE) -> 52 | X8: =VLOOKUP(B8,'Service capacity and access'!A$2:G$48,7,FALSE) -> 29
A9: Comoros | B9: COM | C9: 2019 | D9: Lower middle | E9: 27.033524 | F9: 45.446592 | G9: 27.013975 | H9: 439.4631 | I9: 850.886 | J9: 439.4631 | K9: 72.323799 | L9: 1.6992119 | M9: 2016 | N9: 19.55167 | O9: SADC | P9: Middle-income | Q9: 4.1375494 | R9: 52.743824 | S9: 20.242197 | T9: =VLOOKUP(B9,HALE!A$2:J$48,10,FALSE) -> 58.9 | U9: =VLOOKUP(B9,RMNCAH!D$2:J$195,7,FALSE) -> 50 | V9: =VLOOKUP(B9, 'Infectious D'!A$2:G$195,7,FALSE) -> 51 | W9: =VLOOKUP(B9,NCDs!A$1:G$47,7,FALSE) -> 56 | X9: =VLOOKUP(B9,'Service capacity and access'!A$2:G$48,7,FALSE) -> 37
A10: Cabo Verde | B10: CPV | C10: 2016 | D10: Lower middle | E10: 32.863413 | F10: 35.787606 | G10: 71.087569 | H10: 99.68811 | I10: 531.146 | J10: 98.495178 | K10: 157.87758 | L10: 7.8133933 | M10: 2015 | N10: 50.515446 | O10: ECOWAS | P10: Middle-income | Q10: 10.392425 | R10: 20.909378 | S10: 8.0030527 | T10: =VLOOKUP(B10,HALE!A$2:J$48,10,FALSE) -> 64.8 | U10: =VLOOKUP(B10,RMNCAH!D$2:J$195,7,FALSE) -> 76 | V10: =VLOOKUP(B10, 'Infectious D'!A$2:G$195,7,FALSE) -> 90 | W10: =VLOOKUP(B10,NCDs!A$1:G$47,7,FALSE) -> 57 | X10: =VLOOKUP(B10,'Service capacity and access'!A$2:G$48,7,FALSE) -> 66
A11: Ethiopia | B11: ETH | C11: 2017 | D11: Low | E11: 18.662367 | F11: 67.27584 | G11: 89.90588 | H11: 23.866104 | I11: 106399.92 | J11: 29.06975 | K11: 25.581903 | L11: 0.76860108 | M11: 2018 | N11: 4.774189 | O11: Other | P11: Low-income | Q11: 4.7883601 | R11: 2.6990519 | S11: 7.3950682 | T11: =VLOOKUP(B11,HALE!A$2:J$48,10,FALSE) -> 59.9 | U11: =VLOOKUP(B11,RMNCAH!D$2:J$195,7,FALSE) -> 48 | V11: =VLOOKUP(B11, 'Infectious D'!A$2:G$195,7,FALSE) -> 29 | W11: =VLOOKUP(B11,NCDs!A$1:G$47,7,FALSE) -> 52 | X11: =VLOOKUP(B11,'Service capacity and access'!A$2:G$48,7,FALSE) -> 21
A12: Gabon | B12: GAB | C12: 2019 | D12: Upper middle | E12: 48.757774 | F12: 61.652774 | G12: 76.261402 | H12: 585.91101 | I12: 2172.579 | J12: 585.91101 | K12: 215.01915 | L12: 6.8190227 | M12: 2017 | N12: 104.83855 | O12: ECCAS | P12: Middle-income | Q12: 9.5915642 | R12: 23.562569 | S12: 0.17602925 | T12: =VLOOKUP(B12,HALE!A$2:J$48,10,FALSE) -> 57.6 | U12: =VLOOKUP(B12,RMNCAH!D$2:J$195,7,FALSE) -> 64 | V12: =VLOOKUP(B12, 'Infectious D'!A$2:G$195,7,FALSE) -> 34 | W12: =VLOOKUP(B12,NCDs!A$1:G$47,7,FALSE) -> 54 | X12: =VLOOKUP(B12,'Service capacity and access'!A$2:G$48,7,FALSE) -> 48
A13: Ghana | B13: GHA | C13: 2015 | D13: Lower middle | E13: 25.763836 | F13: 69.288706 | G13: 98.468279 | H13: 3.7146416 | I13: 27849.205 | J13: 5.2173667 | K13: 87.82003 | L13: 1.0638487 | M13: 2019 | N13: 21.679375 | O13: ECOWAS | P13: Middle-income | Q13: 8.5578575 | R13: 0.048568171 | S13: 1.4831527 | T13: =VLOOKUP(B13,HALE!A$2:J$48,10,FALSE) -> 58 | U13: =VLOOKUP(B13,RMNCAH!D$2:J$195,7,FALSE) -> 69 | V13: =VLOOKUP(B13, 'Infectious D'!A$2:G$195,7,FALSE) -> 41 | W13: =VLOOKUP(B13,NCDs!A$1:G$47,7,FALSE) -> 71 | X13: =VLOOKUP(B13,'Service capacity and access'!A$2:G$48,7,FALSE) -> 26
... A25: Sierra Leone | B25: SLE | C25: 2018 | D25: Low | E25: 33.232562 | F25: 56.54561 | G25: 15.777281 | H25: 7931.6318 | I25: 7650.15 | J25: 9010.2207 | K25: 42.332474 | L25: 0.73985487 | M25: 2018 | N25: 14.068165 | O25: ECOWAS | P25: Low-income | Q25: 3.5992196 | R25: 60.312431 | S25: 23.910286 | T25: =VLOOKUP(B25,HALE!A$2:J$48,10,FALSE) -> 52.9 | U25: =VLOOKUP(B25,RMNCAH!D$2:J$195,7,FALSE) -> 72 | V25: =VLOOKUP(B25, 'Infectious D'!A$2:G$195,7,FALSE) -> 51 | W25: =VLOOKUP(B25,NCDs!A$1:G$47,7,FALSE) -> 55 | X25: =VLOOKUP(B25,'Service capacity and access'!A$2:G$48,7,FALSE) -> 14
A26: South Sudan | B26: SSD | C26: 2017 | D26: Low | E26: 24.952584 | F26: 89.351192 | G26: 30.229429 | H26: 113.6475 | I26: 10910.763 | J26: 157.99916 | K26: 31.630802 | N26: 7.8927021 | O26: Other | P26: Low-income | Q26: 2.1062052 | R26: 2.5843747 | S26: 67.186195 | T26: =VLOOKUP(B26,HALE!A$2:J$48,10,FALSE) -> 53.7 | U26: =VLOOKUP(B26,RMNCAH!D$2:J$195,7,FALSE) -> 29 | V26: =VLOOKUP(B26, 'Infectious D'!A$2:G$195,7,FALSE) -> 36 | W26: =VLOOKUP(B26,NCDs!A$1:G$47,7,FALSE) -> 59 | X26: =VLOOKUP(B26,'Service capacity and access'!A$2:G$48,7,FALSE) -> 22
A27: Sao Tome and Principe | B27: STP | C27: 2017 | D27: Lower middle | E27: 47.74081 | F27: 76.735081 | G27: 73.980807 | H27: 21.741138 | I27: 207.089 | J27: 21.884743 | K27: 126.08411 | L27: 3.1588606 | M27: 2015 | N27: 60.193577 | O27: ECCAS | P27: Middle-income | Q27: 10.762632 | R27: 12.771232 | S27: 13.24796 | T27: =VLOOKUP(B27,HALE!A$2:J$48,10,FALSE) -> 61.6 | U27: =VLOOKUP(B27,RMNCAH!D$2:J$195,7,FALSE) -> 80 | V27: =VLOOKUP(B27, 'Infectious D'!A$2:G$195,7,FALSE) -> 53 | W27: =VLOOKUP(B27,NCDs!A$1:G$47,7,FALSE) -> 63 | X27: =VLOOKUP(B27,'Service capacity and access'!A$2:G$48,7,FALSE) -> 45
A28: Eswatini | B28: SWZ | C28: 2017 | D28: Lower middle | E28: 36.157225 | F28: 41.983744 | G28: 58.922618 | H28: 13.323801 | I28: 1124.805 | J28: 14.451789 | K28: 265.11392 | L28: 0.96050787 | M28: 2017 | N28: 95.857849 | O28: SADC | P28: Middle-income | Q28: 9.9682932 | R28: 18.110748 | S28: 22.966635 | T28: =VLOOKUP(B28,HALE!A$2:J$48,10,FALSE) -> 50.1 | U28: =VLOOKUP(B28,RMNCAH!D$2:J$195,7,FALSE) -> 73 | V28: =VLOOKUP(B28, 'Infectious D'!A$2:G$195,7,FALSE) -> 65 | W28: =VLOOKUP(B28,NCDs!A$1:G$47,7,FALSE) -> 62 | X28: =VLOOKUP(B28,'Service capacity and access'!A$2:G$48,7,FALSE) -> 33
A29: Chad | B29: TCD | C29: 2018 | D29: Low | E29: 35.310312 | F29: 66.205999 | G29: 31.398584 | H29: 555.44647 | I29: 15477.729 | J29: 585.91101 | K29: 28.590483 | L29: 0.54242579 | M29: 2019 | N29: 10.095389 | O29: ECCAS | P29: Low-income | Q29: 5.2271085 | R29: 54.274082 | S29: 14.327333 | T29: =VLOOKUP(B29,HALE!A$2:J$48,10,FALSE) -> 52 | U29: =VLOOKUP(B29,RMNCAH!D$2:J$195,7,FALSE) -> 29 | V29: =VLOOKUP(B29, 'Infectious D'!A$2:G$195,7,FALSE) -> 41 | W29: =VLOOKUP(B29,NCDs!A$1:G$47,7,FALSE) -> 59 | X29: =VLOOKUP(B29,'Service capacity and access'!A$2:G$48,7,FALSE) -> 11
A30: Togo | B30: TGO | C30: 2019 | D30: Low | E30: 25.08889 | F30: 53.264435 | G30: 32.009066 | H30: 585.91101 | I30: 8082.366 | J30: 585.91101 | K30: 51.155029 | L30: 0.77576361 | M30: 2019 | N30: 12.834229 | O30: WAEMU | P30: Low-income | Q30: 5.3817401 | R30: 54.735744 | S30: 13.255195 | T30: =VLOOKUP(B30,HALE!A$2:J$48,10,FALSE) -> 56.2 | U30: =VLOOKUP(B30,RMNCAH!D$2:J$195,7,FALSE) -> 52 | V30: =VLOOKUP(B30, 'Infectious D'!A$2:G$195,7,FALSE) -> 55 | W30: =VLOOKUP(B30,NCDs!A$1:G$47,7,FALSE) -> 57 | X30: =VLOOKUP(B30,'Service capacity and access'!A$2:G$48,7,FALSE) -> 23
A31: Uganda | B31: UGA | C31: 2019 | D31: Low | E31: 27.683328 | F31: 44.742015 | G31: 24.431809 | H31: 3704.0491 | I31: 44269.594 | J31: 3704.0491 | K31: 32.408443 | L31: 1.680489 | M31: 2017 | N31: 8.971735 | O31: Other | P31: Low-income | Q31: 3.1451955 | R31: 45.921585 | S31: 29.64661 | T31: =VLOOKUP(B31,HALE!A$2:J$48,10,FALSE) -> 58.2 | U31: =VLOOKUP(B31,RMNCAH!D$2:J$195,7,FALSE) -> 68 | V31: =VLOOKUP(B31, 'Infectious D'!A$2:G$195,7,FALSE) -> 55 | W31: =VLOOKUP(B31,NCDs!A$1:G$47,7,FALSE) -> 55 | X31: =VLOOKUP(B31,'Service capacity and access'!A$2:G$48,7,FALSE) -> 27
A32: South Africa | B32: ZAF | C32: 2016 | D32: Upper middle | E32: 54.793439 | F32: 62.031868 | G32: 64.079555 | H32: 14.709611 | I32: 56207.646 | J32: 14.448427 | K32: 538.78699 | L32: 7.9225364 | M32: 2019 | N32: 295.21991 | O32: SADC | P32: Middle-income | Q32: 15.289785 | R32: 35.104065 | S32: 0.81638187 | T32: =VLOOKUP(B32,HALE!A$2:J$48,10,FALSE) -> 56.2 | U32: =VLOOKUP(B32,RMNCAH!D$2:J$195,7,FALSE) -> 76 | V32: =VLOOKUP(B32, 'Infectious D'!A$2:G$195,7,FALSE) -> 69 | W32: =VLOOKUP(B32,NCDs!A$1:G$47,7,FALSE) -> 61 | X32: =VLOOKUP(B32,'Service capacity and access'!A$2:G$48,7,FALSE) -> 80
A33: Zambia | B33: ZMB | C33: 2016 | D33: Lower middle | E33: 26.773291 | F33: 69.446701 | G33: 99.318778 | H33: 10.3075 | I33: 16363.458 | J33: 12.89 | K33: 58.384441 | L33: 0.92523282 | M33: 2018 | N33: 15.631436 | O33: SADC | P33: Middle-income | Q33: 7.0453463 | R33: 0.21889035 | S33: 0.46233174 | T33: =VLOOKUP(B33,HALE!A$2:J$48,10,FALSE) -> 54.4 | U33: =VLOOKUP(B33,RMNCAH!D$2:J$195,7,FALSE) -> 74 | V33: =VLOOKUP(B33, 'Infectious D'!A$2:G$195,7,FALSE) -> 61 | W33: =VLOOKUP(B33,NCDs!A$1:G$47,7,FALSE) -> 57 | X33: =VLOOKUP(B33,'Service capacity and access'!A$2:G$48,7,FALSE) -> 38
A34: Zimbabwe | B34: ZWE | C34: 2018 | D34: Lower middle | E34: 28.012556 | F34: 62.455734 | G34: 71.482507 | H34: 1 | I34: 14438.802 | J34: 1 | K34: 135.66473 | L34: 2.0957403 | M34: 2018 | N34: 38.003155 | O34: SADC | P34: Middle-income | Q34: 8.72929 | R34: 16.67371 | S34: 11.843782 | T34: =VLOOKUP(B34,HALE!A$2:J$48,10,FALSE) -> 53.1 | U34: =VLOOKUP(B34,RMNCAH!D$2:J$195,7,FALSE) -> 71 | V34: =VLOOKUP(B34, 'Infectious D'!A$2:G$195,7,FALSE) -> 48 | W34: =VLOOKUP(B34,NCDs!A$1:G$47,7,FALSE) -> 67 | X34: =VLOOKUP(B34,'Service capacity and access'!A$2:G$48,7,FALSE) -> 40

Sheet Correlations
A1: Correlations
D2: hr_che | E2: sr_hr_gghed_gghed | F2: sr_hr_gghed_hr | G2: xrt | H2: pop | I2: xrt_2019 | J2: che_usd2019_pc | K2: m_doctors_density | L2: year_doctors_density | M2: hr_usd2019_pc | N2: gghed_gge | O2: sr_hr_pvtd_hr | P2: sr_hr_ext_hr | Q2: HALE | R2: RMNCAH | S2: Infectious dieases | T2: NCD
A3: Spearman's rho | B3: hr_che | C3: Correlation Coefficient | D3: 1 | E3: 0.178855 | F3: -0.20342667 | G3: -0.1425463 | H3: -0.30689512 | I3: -0.16867446 | J3: .419* | K3: .368* | L3: -0.27715965 | M3: .731** | N3: 0.31555184 | O3: .501** | P3: -0.27825142 | Q3: 0.053181706 | R3: 0.31445548 | S3: -0.031127116 | T3: -0.026066637
C4: Sig. (2-tailed) | E4: 0.31930493 | F4: 0.25618248 | G4: 0.42874235 | H4: 0.082351798 | I4: 0.34806636 | J4: 0.015176714 | K4: 0.038186833 | L4: 0.12460278 | M4: 1.3445447e-06 | N4: 0.073642093 | O4: 0.003004928 | P4: 0.11689378 | Q4: 0.76880844 | R4: 0.074703776 | S4: 0.86347021 | T4: 0.88550686
C5: N | D5: 33 | E5: 33 | F5: 33 | G5: 33 | H5: 33 | I5: 33 | J5: 33 | K5: 32 | L5: 32 | M5: 33 | N5: 33 | O5: 33 | P5: 33 | Q5: 33 | R5: 33 | S5: 33 | T5: 33
B6: sr_hr_gghed_gghed | C6: Correlation Coefficient | D6: 0.178855 | E6: 1 | F6: 0.22894385 | G6: -0.2546926 | H6: 0.22526738 | I6: -0.26557448 | J6: -0.039274672 | K6: 0.062282008 | L6: 0.096998261 | M6: 0.021225036 | N6: -0.2305442 | O6: -0.27081245 | P6: -0.23648366 | Q6: -0.046480527 | R6: -0.098687003 | S6: -.431* | T6: 0.14094242
C7: Sig. (2-tailed) | D7: 0.31930493 | F7: 0.19999255 | G7: 0.15260329 | H7: 0.20751023 | I7: 0.13523925 | J7: 0.82820836 | K7: 0.73488708 | L7: 0.59741439 | M7: 0.90666971 | N7: 0.19677995 | O7: 0.12741874 | P7: 0.18517139 | Q7: 0.79729184 | R7: 0.58479708 | S7: 0.012355527 | T7: 0.43400836
C8: N | D8: 33 | E8: 33 | F8: 33 | G8: 33 | H8: 33 | I8: 33 | J8: 33 | K8: 32 | L8: 32 | M8: 33 | N8: 33 | O8: 33 | P8: 33 | Q8: 33 | R8: 33 | S8: 33 | T8: 33
B9: sr_hr_gghed_hr | C9: Correlation Coefficient | D9: -0.20342667 | E9: 0.22894385 | F9: 1 | G9: -.510** | H9: 0.16377005 | I9: -.531** | J9: 0.33492103 | K9: 0.31067515 | L9: 0.30452499 | M9: 0.14523272 | N9: .526** | O9: -.781** | P9: -.583** | Q9: 0.18809566 | R9: 0.31061316 | S9: 0.17232737 | T9: 0.31875444
C10: Sig. (2-tailed) | D10: 0.25618248 | E10: 0.19999255 | G10: 0.0024359122 | H10: 0.36246299 | I10: 0.0014644125 | J10: 0.056750699 | K10: 0.083515925 | L10: 0.090144984 | M10: 0.42000171 | N10: 0.0016484193 | O10: 8.2025527e-08 | P10: 0.00036730794 | Q10: 0.29452027 | R10: 0.078518594 | S10: 0.33757145 | T10: 0.070607875
C11: N | D11: 33 | E11: 33 | F11: 33 | G11: 33 | H11: 33 | I11: 33 | J11: 33 | K11: 32 | L11: 32 | M11: 33 | N11: 33 | O11: 33 | P11: 33 | Q11: 33 | R11: 33 | S11: 33 | T11: 33
B12: xrt | C12: Correlation Coefficient | D12: -0.1425463 | E12: -0.2546926 | F12: -.510** | G12: 1 | H12: 0.17878751 | I12: .987** | J12: -.597** | K12: -.447* | L12: -0.05026657 | M12: -.505** | N12: -.437* | O12: .447** | P12: 0.294094 | Q12: -0.069153559 | R12: -0.32092293 | S12: -0.090924445 | T12: -.442**
C13: Sig. (2-tailed) | D13: 0.42874235 | E13: 0.15260329 | F13: 0.0024359122 | H13: 0.31949059 | I13: 1.9466512e-26 | J13: 0.0002481018 | K13: 0.010368927 | L13: 0.78469168 | M13: 0.0027137888 | N13: 0.01097438 | O13: 0.0091309297 | P13: 0.096659529 | Q13: 0.70216638 | R13: 0.068609356 | S13: 0.61480552 | T13: 0.0099295822
C14: N | D14: 33 | E14: 33 | F14: 33 | G14: 33 | H14: 33 | I14: 33 | J14: 33 | K14: 32 | L14: 32 | M14: 33 | N14: 33 | O14: 33 | P14: 33 | Q14: 33 | R14: 33 | S14: 33 | T14: 33
B15: pop | C15: Correlation Coefficient | D15: -0.30689512 | E15: 0.22526738 | F15: 0.16377005 | G15: 0.17878751 | H15: 1 | I15: 0.18320741 | J15: -0.3270661 | K15: -0.19437865 | L15: .450** | M15: -.417* | N15: -0.2014545 | O15: -0.23804749 | P15: -0.1017799 | Q15: -0.07105836 | R15: -0.19570135 | S15: -0.0205789 | T15: 0.0015083017
C16: Sig. (2-tailed) | D16: 0.082351798 | E16: 0.20751023 | F16: 0.36246299 | G16: 0.31949059 | I16: 0.3074741 | J16: 0.063187006 | K16: 0.28640847 | L16: 0.0098432884 | M16: 0.015773199 | N16: 0.26091998 | O16: 0.18219676 | P16: 0.57302392 | Q16: 0.69435117 | R16: 0.2750674 | S16: 0.90949909 | T16: 0.99335335
C17: N | D17: 33 | E17: 33 | F17: 33 | G17: 33 | H17: 33 | I17: 33 | J17: 33 | K17: 32 | L17: 32 | M17: 33 | N17: 33 | O17: 33 | P17: 33 | Q17: 33 | R17: 33 | S17: 33 | T17: 33
B18: xrt_2019 | C18: Correlation Coefficient | D18: -0.16867446 | E18: -0.26557448 | F18: -.531** | G18: .987** | H18: 0.18320741 | I18: 1 | J18: -.622** | K18: -.470** | L18: -0.073155555 | M18: -.544** | N18: -.461** | O18: .437* | P18: .349* | Q18: -0.14387556 | R18: -.367* | S18: -0.10044948 | T18: -.411*
C19: Sig. (2-tailed) | D19: 0.34806636 | E19: 0.13523925 | F19: 0.0014644125 | G19: 1.9466512e-26 | H19: 0.3074741 | J19: 0.00011157889 | K19: 0.006666218 | L19: 0.6907042 | M19: 0.0010620653 | N19: 0.0068732349 | O19: 0.010912256 | P19: 0.046585921 | Q19: 0.42440492 | R19: 0.035876081 | S19: 0.57807507 | T19: 0.017380253
C20: N | D20: 33 | E20: 33 | F20: 33 | G20: 33 | H20: 33 | I20: 33 | J20: 33 | K20: 32 | L20: 32 | M20: 33 | N20: 33 | O20: 33 | P20: 33 | Q20: 33 | R20: 33 | S20: 33 | T20: 33
B21: che_usd2019_pc | C21: Correlation Coefficient | D21: .419* | E21: -0.039274672 | F21: 0.33492103 | G21: -.597** | H21: -0.3270661 | I21: -.622** | J21: 1 | K21: .676** | L21: -0.1293111 | M21: .898** | N21: .549** | O21: -0.035609798 | P21: -.483** | Q21: 0.13017307 | R21: .539** | S21: .370* | T21: 0.29783069
C22: Sig. (2-tailed) | D22: 0.015176714 | E22: 0.82820836 | F22: 0.056750699 | G22: 0.0002481018 | H22: 0.063187006 | I22: 0.00011157889 | K22: 2.1447569e-05 | L22: 0.48058561 | M22: 1.4157249e-12 | N22: 0.00093808132 | O22: 0.84403312 | P22: 0.004455213 | Q22: 0.470273 | R22: 0.0012033465 | S22: 0.033995939 | T22: 0.092300908
C23: N | D23: 33 | E23: 33 | F23: 33 | G23: 33 | H23: 33 | I23: 33 | J23: 33 | K23: 32 | L23: 32 | M23: 33 | N23: 33 | O23: 33 | P23: 33 | Q23: 33 | R23: 33 | S23: 33 | T23: 33
B24: m_doctors_density | C24: Correlation Coefficient | D24: .368* | E24: 0.062282008 | F24: 0.31067515 | G24: -.447* | H24: -0.19437865 | I24: -.470** | J24: .676** | K24: 1 | L24: -0.019961801 | M24: .626** | N24: .383* | O24: -0.074618789 | P24: -.455** | Q24: 0.34614029 | R24: 0.33946341 | S24: 0.307643 | T24: .438*
C25: Sig. (2-tailed) | D25: 0.038186833 | E25: 0.73488708 | F25: 0.083515925 | G25: 0.010368927 | H25: 0.28640847 | I25: 0.006666218 | J25: 2.1447569e-05 | L25: 0.91364751 | M25: 0.00012518072 | N25: 0.030596501 | O25: 0.68483052 | P25: 0.0089245457 | Q25: 0.052303379 | R25: 0.057331837 | S25: 0.086735715 | T25: 0.012259955
C26: N | D26: 32 | E26: 32 | F26: 32 | G26: 32 | H26: 32 | I26: 32 | J26: 32 | K26: 32 | L26: 32 | M26: 32 | N26: 32 | O26: 32 | P26: 32 | Q26: 32 | R26: 32 | S26: 32 | T26: 32
B27: year_doctors_density | C27: Correlation Coefficient | D27: -0.27715965 | E27: 0.096998261 | F27: 0.30452499 | G27: -0.05026657 | H27: .450** | I27: -0.073155555 | J27: -0.1293111 | K27: -0.019961801 | L27: 1 | M27: -0.21135743 | N27: 0.088082013 | O27: -0.16280333 | P27: -.390* | Q27: -0.039564274 | R27: -0.07257703 | S27: 0.18258963 | T27: 0.27540304
C28: Sig. (2-tailed) | D28: 0.12460278 | E28: 0.59741439 | F28: 0.090144984 | G28: 0.78469168 | H28: 0.0098432884 | I28: 0.6907042 | J28: 0.48058561 | K28: 0.91364751 | M28: 0.24555009 | N28: 0.63167069 | O28: 0.37331873 | P28: 0.027369772 | Q28: 0.82977602 | R28: 0.69303142 | S28: 0.31719938 | T28: 0.12710766
C29: N | D29: 32 | E29: 32 | F29: 32 | G29: 32 | H29: 32 | I29: 32 | J29: 32 | K29: 32 | L29: 32 | M29: 32 | N29: 32 | O29: 32 | P29: 32 | Q29: 32 | R29: 32 | S29: 32 | T29: 32
B30: hr_usd2019_pc | C30: Correlation Coefficient | D30: .731** | E30: 0.021225036 | F30: 0.14523272 | G30: -.505** | H30: -.417* | I30: -.544** | J30: .898** | K30: .626** | L30: -0.21135743 | M30: 1 | N30: .541** | O30: 0.18406755 | P30: -.461** | Q30: 0.11094391 | R30: .528** | S30: 0.22872932 | T30: 0.20766023
C31: Sig. (2-tailed) | D31: 1.3445447e-06 | E31: 0.90666971 | F31: 0.42000171 | G31: 0.0027137888 | H31: 0.015773199 | I31: 0.0010620653 | J31: 1.4157249e-12 | K31: 0.00012518072 | L31: 0.24555009 | N31: 0.0011421587 | O31: 0.30516916 | P31: 0.0068673895 | Q31: 0.53878437 | R31: 0.0016033654 | S31: 0.20042594 | T31: 0.24620558
C32: N | D32: 33 | E32: 33 | F32: 33 | G32: 33 | H32: 33 | I32: 33 | J32: 33 | K32: 32 | L32: 32 | M32: 33 | N32: 33 | O32: 33 | P32: 33 | Q32: 33 | R32: 33 | S32: 33 | T32: 33
B33: gghed_gge | C33: Correlation Coefficient | D33: 0.31555184 | E33: -0.2305442 | F33: .526** | G33: -.437* | H33: -0.2014545 | I33: -.461** | J33: .549** | K33: .383* | L33: 0.088082013 | M33: .541** | N33: 1 | O33: -0.21891463 | P33: -0.33581343 | Q33: 0.15338296 | R33: .586** | S33: .449** | T33: .363*
C34: Sig. (2-tailed) | D34: 0.073642093 | E34: 0.19677995 | F34: 0.0016484193 | G34: 0.01097438 | H34: 0.26091998 | I34: 0.0068732349 | J34: 0.00093808132 | K34: 0.030596501 | L34: 0.63167069 | M34: 0.0011421587 | O34: 0.22095518 | P34: 0.056053555 | Q34: 0.39410152 | R34: 0.00033677379 | S34: 0.0088091913 | T34: 0.03778213
C35: N | D35: 33 | E35: 33 | F35: 33 | G35: 33 | H35: 33 | I35: 33 | J35: 33 | K35: 32 | L35: 32 | M35: 33 | N35: 33 | O35: 33 | P35: 33 | Q35: 33 | R35: 33 | S35: 33 | T35: 33
B36: sr_hr_pvtd_hr | C36: Correlation Coefficient | D36: .501** | E36: -0.27081245 | F36: -.781** | G36: .447** | H36: -0.23804749 | I36: .437* | J36: -0.035609798 | K36: -0.074618789 | L36: -0.16280333 | M36: 0.18406755 | N36: -0.21891463 | O36: 1 | P36: 0.064699492 | Q36: 0.036460947 | R36: -0.062578443 | S36: 0.010711301 | T36: -0.33394909
C37: Sig. (2-tailed) | D37: 0.003004928 | E37: 0.12741874 | F37: 8.2025527e-08 | G37: 0.0091309297 | H37: 0.18219676 | I37: 0.010912256 | J37: 0.84403312 | K37: 0.68483052 | L37: 0.37331873 | M37: 0.30516916 | N37: 0.22095518 | P37: 0.72055702 | Q37: 0.84035232 | R37: 0.72936979 | S37: 0.95282406 | T37: 0.057517774
C38: N | D38: 33 | E38: 33 | F38: 33 | G38: 33 | H38: 33 | I38: 33 | J38: 33 | K38: 32 | L38: 32 | M38: 33 | N38: 33 | O38: 33 | P38: 33 | Q38: 33 | R38: 33 | S38: 33 | T38: 33
B39: sr_hr_ext_hr | C39: Correlation Coefficient | D39: -0.27825142 | E39: -0.23648366 | F39: -.583** | G39: 0.294094 | H39: -0.1017799 | I39: .349* | J39: -.483** | K39: -.455** | L39: -.390* | M39: -.461** | N39: -0.33581343 | O39: 0.064699492 | P39: 1 | Q39: -0.27489343 | R39: -0.18911014 | S39: -0.14690881 | T39: -0.15151319
C40: Sig. (2-tailed) | D40: 0.11689378 | E40: 0.18517139 | F40: 0.00036730794 | G40: 0.096659529 | H40: 0.57302392 | I40: 0.046585921 | J40: 0.004455213 | K40: 0.0089245457 | L40: 0.027369772 | M40: 0.0068673895 | N40: 0.056053555 | O40: 0.72055702 | Q40: 0.12156139 | R40: 0.29187616 | S40: 0.41459917 | T40: 0.39996056
...

Sheet Glossary
A1: Series | B1: Name
A2: code | B2: Country code
A3: year | B3: Year
A4: income | B4: Income WB classification
A5: hr_che | B5: Health workforce (HWF) remuneration expenditure
A6: sr_hr_gghed_gghed | B6: Government remunerations on health workforce (HWF) as a share of general government expenditure
A7: sr_hr_gghed_hr | B7: Government remunerations on health workforce (HWF) as a share of health workforce expenditure
A8: xrt | B8: Exchange rate
A9: pop | B9: Population (thousand)
A10: xrt_2019 | B10: Exchange rate in 2019
A11: che_usd2019_pc | B11: Per capita health expenditure in USD (2019)
A12: m_doctors_density | B12: Medical doctors density per 10,000 population
... A20: sr_hr_ext_hr | B20: Remunerations on health workforce (HWF) from external sources as a share of health workforce expenditure

Sheet Service capacity and access
A1: SpatialDimValueCode | B1: Location | C1: Period type | D1: Period | E1: IsLatestYear | F1: FactValueNumeric | G1: Value
A2: TCD | B2: Chad | C2: Year | D2: 2021 | E2: TRUE | F2: 10.76 | G2: 11
A3: NER | B3: Niger | C3: Year | D3: 2021 | E3: TRUE | F3: 11.68 | G3: 12
A4: BDI | B4: Burundi | C4: Year | D4: 2021 | E4: TRUE | F4: 13.85 | G4: 14
A5: NGA | B5: Nigeria | C5: Year | D5: 2021 | E5: TRUE | F5: 14.08 | G5: 14
A6: SLE | B6: Sierra Leone | C6: Year | D6: 2021 | E6: TRUE | F6: 14.19 | G6: 14
A7: BFA | B7: Burkina Faso | C7: Year | D7: 2021 | E7: TRUE | F7: 14.92 | G7: 15
A8: MLI | B8: Mali | C8: Year | D8: 2021 | E8: TRUE | F8: 15.25 | G8: 15
A9: BEN | B9: Benin | C9: Year | D9: 2021 | E9: TRUE | F9: 16.86 | G9: 17
A10: CAF | B10: Central African Republic | C10: Year | D10: 2021 | E10: TRUE | F10: 16.76 | G10: 17
A11: GNB | B11: Guinea-Bissau | C11: Year | D11: 2021 | E11: TRUE | F11: 17.33 | G11: 17
A12: GIN | B12: Guinea | C12: Year | D12: 2021 | E12: TRUE | F12: 18.03 | G12: 18
A13: CIV | B13: CÃ´te dâ€™Ivoire | C13: Year | D13: 2021 | E13: TRUE | F13: 19.16 | G13: 19
... A48: DZA | B48: Algeria | C48: Year | D48: 2021 | E48: TRUE | F48: 88.72 | G48: 89

Sheet NCDs
A1: CAF | B1: Central African Republic | C1: Year | D1: 2021 | E1: TRUE | F1: 43.77 | G1: 44
A2: RWA | B2: Rwanda | C2: Year | D2: 2021 | E2: TRUE | F2: 44.01 | G2: 44
A3: MDG | B3: Madagascar | C3: Year | D3: 2021 | E3: TRUE | F3: 45.77 | G3: 46
A4: CMR | B4: Cameroon | C4: Year | D4: 2021 | E4: TRUE | F4: 49.14 | G4: 49
A5: NER | B5: Niger | C5: Year | D5: 2021 | E5: TRUE | F5: 49.3 | G5: 49
A6: GNQ | B6: Equatorial Guinea | C6: Year | D6: 2021 | E6: TRUE | F6: 50.27 | G6: 50
A7: MOZ | B7: Mozambique | C7: Year | D7: 2021 | E7: TRUE | F7: 49.78 | G7: 50
A8: KEN | B8: Kenya | C8: Year | D8: 2021 | E8: TRUE | F8: 50.91 | G8: 51
A9: TZA | B9: United Republic of Tanzania | C9: Year | D9: 2021 | E9: TRUE | F9: 50.72 | G9: 51
A10: COG | B10: Congo | C10: Year | D10: 2021 | E10: TRUE | F10: 52.47 | G10: 52
A11: ETH | B11: Ethiopia | C11: Year | D11: 2021 | E11: TRUE | F11: 52.49 | G11: 52
A12: LBR | B12: Liberia | C12: Year | D12: 2021 | E12: TRUE | F12: 53.05 | G12: 53
... A47: GHA | B47: Ghana | C47: Year | D47: 2021 | E47: TRUE | F47: 70.51 | G47: 71

Sheet Infectious D
A1: SpatialDimValueCode | B1: Location | C1: Period type | D1: Period | E1: IsLatestYear | F1: FactValueNumeric | G1: Value
A2: COK | B2: Cook Islands | C2: Year | D2: 2021 | E2: TRUE | F2: 16.75 | G2: 17
A3: DMA | B3: Dominica | C3: Year | D3: 2021 | E3: TRUE | F3: 17.08 | G3: 17
A4: NIU | B4: Niue | C4: Year | D4: 2021 | E4: TRUE | F4: 17.5 | G4: 17
A5: ETH | B5: Ethiopia | C5: Year | D5: 2021 | E5: TRUE | F5: 29.04 | G5: 29
A6: MDG | B6: Madagascar | C6: Year | D6: 2021 | E6: TRUE | F6: 29.47 | G6: 29
A7: GNB | B7: Guinea-Bissau | C7: Year | D7: 2021 | E7: TRUE | F7: 29.95 | G7: 30
A8: AFG | B8: Afghanistan | C8: Year | D8: 2021 | E8: TRUE | F8: 32.97 | G8: 33
A9: GAB | B9: Gabon | C9: Year | D9: 2021 | E9: TRUE | F9: 34.37 | G9: 34
A10: DJI | B10: Djibouti | C10: Year | D10: 2021 | E10: TRUE | F10: 34.77 | G10: 35
A11: SOM | B11: Somalia | C11: Year | D11: 2021 | E11: TRUE | F11: 34.99 | G11: 35
A12: AGO | B12: Angola | C12: Year | D12: 2021 | E12: TRUE | F12: 36.07 | G12: 36
A13: COG | B13: Congo | C13: Year | D13: 2021 | E13: TRUE | F13: 36.21 | G13: 36
... A195: GBR | B195: United Kingdom of Great Britain and Northern Ireland | C195: Year | D195: 2021 | E195: TRUE | F195: 97.67 | G195: 98

Sheet RMNCAH
A1: ParentLocationCode | B1: ParentLocation | C1: Location type | D1: SpatialDimValueCode | E1: Location | F1: Period type | G1: Period | H1: IsLatestYear | I1: FactValueNumeric | J1: Value
A2: EMR | B2: Eastern Mediterranean | C2: Country | D2: SOM | E2: Somalia | F2: Year | G2: 2021 | H2: TRUE | I2: 17.39 | J2: 17
A3: AFR | B3: Africa | C3: Country | D3: TCD | E3: Chad | F3: Year | G3: 2021 | H3: TRUE | I3: 28.87 | J3: 29
A4: AFR | B4: Africa | C4: Country | D4: SSD | E4: South Sudan | F4: Year | G4: 2021 | H4: TRUE | I4: 29.42 | J4: 29
A5: AFR | B5: Africa | C5: Country | D5: CAF | E5: Central African Republic | F5: Year | G5: 2021 | H5: TRUE | I5: 38.17 | J5: 38
A6: AFR | B6: Africa | C6: Country | D6: MRT | E6: Mauritania | F6: Year | G6: 2021 | H6: TRUE | I6: 41.31 | J6: 41
A7: EMR | B7: Eastern Mediterranean | C7: Country | D7: YEM | E7: Yemen | F7: Year | G7: 2021 | H7: TRUE | I7: 41.33 | J7: 41
A8: AFR | B8: Africa | C8: Country | D8: BEN | E8: Benin | F8: Year | G8: 2021 | H8: TRUE | I8: 42.82 | J8: 43
A9: AFR | B9: Africa | C9: Country | D9: COD | E9: Democratic Republic of the Congo | F9: Year | G9: 2021 | H9: TRUE | I9: 43.22 | J9: 43
A10: AFR | B10: Africa | C10: Country | D10: AGO | E10: Angola | F10: Year | G10: 2021 | H10: TRUE | I10: 44.51 | J10: 45
A11: AFR | B11: Africa | C11: Country | D11: NGA | E11: Nigeria | F11: Year | G11: 2021 | H11: TRUE | I11: 46.44 | J11: 46
A12: EMR | B12: Eastern Mediterranean | C12: Country | D12: AFG | E12: Afghanistan | F12: Year | G12: 2021 | H12: TRUE | I12: 47.21 | J12: 47
A13: AFR | B13: Africa | C13: Country | D13: MLI | E13: Mali | F13: Year | G13: 2021 | H13: TRUE | I13: 47.33 | J13: 47
... A195: EUR | B195: Europe | C195: Country | D195: NOR | E195: Norway | F195: Year | G195: 2021 | H195: TRUE | I195: 94.91 | J195: 95

Sheet HALE
A1: SpatialDimValueCode | B1: Location | C1: Period type | D1: Period | E1: IsLatestYear | F1: Dim1 type | G1: Dim1 | H1: Dim1ValueCode | I1: FactValueNumeric | J1: Value
A2: DZA | B2: Algeria | C2: Year | D2: 2019 | E2: TRUE | F2: Sex | G2: Both sexes | H2: SEX_BTSX | I2: 66.39 | J2: 66.4
A3: AGO | B3: Angola | C3: Year | D3: 2019 | E3: TRUE | F3: Sex | G3: Both sexes | H3: SEX_BTSX | I3: 54.84 | J3: 54.8
A4: BEN | B4: Benin | C4: Year | D4: 2019 | E4: TRUE | F4: Sex | G4: Both sexes | H4: SEX_BTSX | I4: 55.52 | J4: 55.5
A5: BWA | B5: Botswana | C5: Year | D5: 2019 | E5: TRUE | F5: Sex | G5: Both sexes | H5: SEX_BTSX | I5: 53.89 | J5: 53.9
A6: BFA | B6: Burkina Faso | C6: Year | D6: 2019 | E6: TRUE | F6: Sex | G6: Both sexes | H6: SEX_BTSX | I6: 54.86 | J6: 54.9
A7: BDI | B7: Burundi | C7: Year | D7: 2019 | E7: TRUE | F7: Sex | G7: Both sexes | H7: SEX_BTSX | I7: 55.58 | J7: 55.6
A8: CIV | B8: CÃ´te dâ€™Ivoire | C8: Year | D8: 2019 | E8: TRUE | F8: Sex | G8: Both sexes | H8: SEX_BTSX | I8: 54.81 | J8: 54.8
A9: CPV | B9: Cabo Verde | C9: Year | D9: 2019 | E9: TRUE | F9: Sex | G9: Both sexes | H9: SEX_BTSX | I9: 64.8 | J9: 64.8
A10: CMR | B10: Cameroon | C10: Year | D10: 2019 | E10: TRUE | F10: Sex | G10: Both sexes | H10: SEX_BTSX | I10: 54.52 | J10: 54.5
A11: CAF | B11: Central African Republic | C11: Year | D11: 2019 | E11: TRUE | F11: Sex | G11: Both sexes | H11: SEX_BTSX | I11: 46.37 | J11: 46.4
A12: TCD | B12: Chad | C12: Year | D12: 2019 | E12: TRUE | F12: Sex | G12: Both sexes | H12: SEX_BTSX | I12: 52.02 | J12: 52
A13: COM | B13: Comoros | C13: Year | D13: 2019 | E13: TRUE | F13: Sex | G13: Both sexes | H13: SEX_BTSX | I13: 58.95 | J13: 58.9
... A48: ZWE | B48: Zimbabwe | C48: Year | D48: 2019 | E48: TRUE | F48: Sex | G48: Both sexes | H48: SEX_BTSX | I48: 53.07 | J48: 53.1

Sheet Metadata
A1: Metadata | B1: Description
A2: Method: | B2: Calculations are based on country-produced disaggregated health accounts data from 33 low- and middle-income African countries, disaggregated wherever possible by income and subregional economic group.
A3: Sources: | B3: The baseline information was calculated in July 2022 for 2019, the year before the COVID-19 pandemic. Country health accounts reports, broken down by factor of provision (FP), can be retrieved from the Documentation Center of WHO’s Global Health Expenditure Database (GHED). The latest available data before 2019 were used when no data were available for 2019. Population size and income group data were extracted from GHED Data Explorer in July 2022 (2021 update).

Sheet Data (2)
A1: country_short_name | B1: code | C1: year | D1: income | E1: hr_che | F1: sr_hr_gghed_gghed | G1: sr_hr_gghed_hr | H1: xrt | I1: pop | J1: xrt_2019 | K1: che_usd2019_pc | L1: m_doctors_density | M1: year_doctors_density | N1: hr_usd2019_pc | O1: sub_group_name_3 | P1: sub_income | Q1: gghed_gge | R1: sr_hr_pvtd_hr | S1: sr_hr_ext_hr
A2: Burundi | B2: BDI | C2: 2018 | D2: Low | E2: 15.763333 | F2: 39.396931 | G2: 69.388785 | H2: 1782.8768 | I2: 11175.374 | J2: 1845.6229 | K2: 21.505672 | L2: 1.0011998 | M2: 2019 | N2: 3.3900108 | O2: ECCAS | P2: Low-income | Q2: 8.4705248 | R2: 17.613289 | S2: 12.997926
A3: Burkina Faso | B3: BFA | C3: 2019 | D3: Low | E3: 32.880543 | F3: 65.129503 | G3: 82.824007 | H3: 585.91101 | I3: 20321.378 | J3: 585.91101 | K3: 42.344528 | L3: 0.93989666 | M3: 2019 | N3: 13.923111 | O3: WAEMU | P3: Low-income | Q3: 9.5769281 | R3: 5.8908882 | S3: 11.285105
A4: Botswana | B4: BWA | C4: 2017 | D4: Upper middle | E4: 36.852196 | F4: 44.39461 | G4: 91.1446 | H4: 10.347417 | I4: 2205.08 | J4: 10.755867 | K4: 474.01831 | L4: 2.8925493 | M4: 2018 | N4: 174.68613 | O4: SADC | P4: Middle-income | Q4: 14.315475 | R4: 3.1786098 | S4: 5.6767898
A5: Central African Rep. | B5: CAF | C5: 2018 | D5: Low | E5: 19.953117 | F5: 33.738449 | G5: 10.588879 | H5: 555.44647 | I5: 4666.368 | J5: 585.91101 | K5: 52.09977 | L5: 0.7210943 | M5: 2015 | N5: 10.395529 | O5: ECCAS | P5: Low-income | Q5: 3.9108746 | R5: 25.707739 | S5: 63.703381
A6: Cote d Ivoire | B6: CIV | C6: 2018 | D6: Lower middle | E6: 19.252622 | F6: 59.380839 | G6: 89.648114 | H6: 555.44647 | I6: 25069.23 | J6: 585.91101 | K6: 68.557785 | L6: 1.6226902 | M6: 2019 | N6: 13.19917 | O6: WAEMU | P6: Middle-income | Q6: 5.1173263 | R6: 5.0805235 | S6: 5.2713628
A7: DR Congo | B7: COD | C7: 2019 | D7: Low | E7: 31.463267 | F7: 85.237445 | G7: 42.852808 | H7: 1647.7601 | I7: 86790.567 | J7: 1647.7601 | K7: 20.570732 | L7: 0.89939848 | M7: 2016 | N7: 6.4722247 | O7: ECCAS | P7: Low-income | Q7: 4.4249554 | R7: 7.9805975 | S7: 49.166595
A8: Congo | B8: COG | C8: 2019 | D8: Lower middle | E8: 43.066372 | F8: 58.222172 | G8: 50.823961 | H8: 585.91101 | I8: 5380.508 | J8: 585.91101 | K8: 48.558773 | L8: 1.0640442 | M8: 2016 | N8: 20.912502 | O8: ECCAS | P8: Middle-income | Q8: 3.4871681 | R8: 43.398785 | S8: 5.7772541
A9: Comoros | B9: COM | C9: 2019 | D9: Lower middle | E9: 27.033524 | F9: 45.446592 | G9: 27.013975 | H9: 439.4631 | I9: 850.886 | J9: 439.4631 | K9: 72.323799 | L9: 1.6992119 | M9: 2016 | N9: 19.55167 | O9: SADC | P9: Middle-income | Q9: 4.1375494 | R9: 52.743824 | S9: 20.242197
A10: Cabo Verde | B10: CPV | C10: 2016 | D10: Lower middle | E10: 32.863413 | F10: 35.787606 | G10: 71.087569 | H10: 99.68811 | I10: 531.146 | J10: 98.495178 | K10: 157.87758 | L10: 7.8133933 | M10: 2015 | N10: 50.515446 | O10: ECOWAS | P10: Middle-income | Q10: 10.392425 | R10: 20.909378 | S10: 8.0030527
A11: Ethiopia | B11: ETH | C11: 2017 | D11: Low | E11: 18.662367 | F11: 67.27584 | G11: 89.90588 | H11: 23.866104 | I11: 106399.92 | J11: 29.06975 | K11: 25.581903 | L11: 0.76860108 | M11: 2018 | N11: 4.774189 | O11: Other | P11: Low-income | Q11: 4.7883601 | R11: 2.6990519 | S11: 7.3950682
A12: Gabon | B12: GAB | C12: 2019 | D12: Upper middle | E12: 48.757774 | F12: 61.652774 | G12: 76.261402 | H12: 585.91101 | I12: 2172.579 | J12: 585.91101 | K12: 215.01915 | L12: 6.8190227 | M12: 2017 | N12: 104.83855 | O12: ECCAS | P12: Middle-income | Q12: 9.5915642 | R12: 23.562569 | S12: 0.17602925
A13: Ghana | B13: GHA | C13: 2015 | D13: Lower middle | E13: 25.763836 | F13: 69.288706 | G13: 98.468279 | H13: 3.7146416 | I13: 27849.205 | J13: 5.2173667 | K13: 87.82003 | L13: 1.0638487 | M13: 2019 | N13: 21.679375 | O13: ECOWAS | P13: Middle-income | Q13: 8.5578575 | R13: 0.048568171 | S13: 1.4831527
... A25: Sierra Leone | B25: SLE | C25: 2018 | D25: Low | E25: 33.232562 | F25: 56.54561 | G25: 15.777281 | H25: 7931.6318 | I25: 7650.15 | J25: 9010.2207 | K25: 42.332474 | L25: 0.73985487 | M25: 2018 | N25: 14.068165 | O25: ECOWAS | P25: Low-income | Q25: 3.5992196 | R25: 60.312431 | S25: 23.910286
A26: South Sudan | B26: SSD | C26: 2017 | D26: Low | E26: 24.952584 | F26: 89.351192 | G26: 30.229429 | H26: 113.6475 | I26: 10910.763 | J26: 157.99916 | K26: 31.630802 | N26: 7.8927021 | O26: Other | P26: Low-income | Q26: 2.1062052 | R26: 2.5843747 | S26: 67.186195
A27: Sao Tome and Principe | B27: STP | C27: 2017 | D27: Lower middle | E27: 47.74081 | F27: 76.735081 | G27: 73.980807 | H27: 21.741138 | I27: 207.089 | J27: 21.884743 | K27: 126.08411 | L27: 3.1588606 | M27: 2015 | N27: 60.193577 | O27: ECCAS | P27: Middle-income | Q27: 10.762632 | R27: 12.771232 | S27: 13.24796
A28: Eswatini | B28: SWZ | C28: 2017 | D28: Lower middle | E28: 36.157225 | F28: 41.983744 | G28: 58.922618 | H28: 13.323801 | I28: 1124.805 | J28: 14.451789 | K28: 265.11392 | L28: 0.96050787 | M28: 2017 | N28: 95.857849 | O28: SADC | P28: Middle-income | Q28: 9.9682932 | R28: 18.110748 | S28: 22.966635
A29: Chad | B29: TCD | C29: 2018 | D29: Low | E29: 35.310312 | F29: 66.205999 | G29: 31.398584 | H29: 555.44647 | I29: 15477.729 | J29: 585.91101 | K29: 28.590483 | L29: 0.54242579 | M29: 2019 | N29: 10.095389 | O29: ECCAS | P29: Low-income | Q29: 5.2271085 | R29: 54.274082 | S29: 14.327333
A30: Togo | B30: TGO | C30: 2019 | D30: Low | E30: 25.08889 | F30: 53.264435 | G30: 32.009066 | H30: 585.91101 | I30: 8082.366 | J30: 585.91101 | K30: 51.155029 | L30: 0.77576361 | M30: 2019 | N30: 12.834229 | O30: WAEMU | P30: Low-income | Q30: 5.3817401 | R30: 54.735744 | S30: 13.255195
A31: Uganda | B31: UGA | C31: 2019 | D31: Low | E31: 27.683328 | F31: 44.742015 | G31: 24.431809 | H31: 3704.0491 | I31: 44269.594 | J31: 3704.0491 | K31: 32.408443 | L31: 1.680489 | M31: 2017 | N31: 8.971735 | O31: Other | P31: Low-income | Q31: 3.1451955 | R31: 45.921585 | S31: 29.64661
A32: South Africa | B32: ZAF | C32: 2016 | D32: Upper middle | E32: 54.793439 | F32: 62.031868 | G32: 64.079555 | H32: 14.709611 | I32: 56207.646 | J32: 14.448427 | K32: 538.78699 | L32: 7.9225364 | M32: 2019 | N32: 295.21991 | O32: SADC | P32: Middle-income | Q32: 15.289785 | R32: 35.104065 | S32: 0.81638187
A33: Zambia | B33: ZMB | C33: 2016 | D33: Lower middle | E33: 26.773291 | F33: 69.446701 | G33: 99.318778 | H33: 10.3075 | I33: 16363.458 | J33: 12.89 | K33: 58.384441 | L33: 0.92523282 | M33: 2018 | N33: 15.631436 | O33: SADC | P33: Middle-income | Q33: 7.0453463 | R33: 0.21889035 | S33: 0.46233174
A34: Zimbabwe | B34: ZWE | C34: 2018 | D34: Lower middle | E34: 28.012556 | F34: 62.455734 | G34: 71.482507 | H34: 1 | I34: 14438.802 | J34: 1 | K34: 135.66473 | L34: 2.0957403 | M34: 2018 | N34: 38.003155 | O34: SADC | P34: Middle-income | Q34: 8.72929 | R34: 16.67371 | S34: 11.843782

Sheet GGHE D
A1: Country | B1: Domestic general government health expenditure (GGHE-D) as percentage of general government expenditure (GGE) (%) | C1: Domestic general government health expenditure (GGHE-D) as percentage of general government expenditure (GGE) (%) | D1: Domestic general government health expenditure (GGHE-D) as percentage of general government expenditure (GGE) (%) | E1: Domestic general government health expenditure (GGHE-D) as percentage of general government expenditure (GGE) (%) | F1: Domestic general government health expenditure (GGHE-D) as percentage of general government expenditure (GGE) (%) | G1: Domestic general government health expenditure (GGHE-D) as percentage of general government expenditure (GGE) (%) | H1: Domestic general government health expenditure (GGHE-D) as percentage of general government expenditure (GGE) (%) | I1: Domestic general government health expenditure (GGHE-D) as percentage of general government expenditure (GGE) (%) | J1: Domestic general government health expenditure (GGHE-D) as percentage of general government expenditure (GGE) (%) | K1: Domestic general government health expenditure (GGHE-D) as percentage of general government expenditure (GGE) (%) | L1: Domestic general government health expenditure (GGHE-D) as percentage of general government expenditure (GGE) (%) | M1: Domestic general government health expenditure (GGHE-D) as percentage of general government expenditure (GGE) (%) | N1: Domestic general government health expenditure (GGHE-D) as percentage of general government expenditure (GGE) (%) | O1: Domestic general government health expenditure (GGHE-D) as percentage of general government expenditure (GGE) (%) | P1: Domestic general government health expenditure (GGHE-D) as percentage of general government expenditure (GGE) (%) | Q1: Domestic general government health expenditure (GGHE-D) as percentage of general government expenditure (GGE) (%) | R1: Domestic general government health expenditure (GGHE-D) as percentage of general government expenditure (GGE) (%) | S1: Domestic general government health expenditure (GGHE-D) as percentage of general government expenditure (GGE) (%) | T1: Domestic general government health expenditure (GGHE-D) as percentage of general government expenditure (GGE) (%) | U1: Domestic general government health expenditure (GGHE-D) as percentage of general government expenditure (GGE) (%) | V1: Domestic general government health expenditure (GGHE-D) as percentage of general government expenditure (GGE) (%) | W1: Domestic general government health expenditure (GGHE-D) as percentage of general government expenditure (GGE) (%)
A2: Countries, territories and areas | B2: 2021 | C2: 2020 | D2: 2019 | E2: 2018 | F2: 2017 | G2: 2016 | H2: 2015 | I2: 2014 | J2: 2013 | K2: 2012 | L2: 2011 | M2: 2010 | N2: 2009 | O2: 2008 | P2: 2007 | Q2: 2006 | R2: 2005 | S2: 2004 | T2: 2003 | U2: 2002 | V2: 2001 | W2: 2000
A3: Afghanistan | B3: 4.05 | C3: 4.25 | D3: 1.78 | E3: 1.91 | F3: 2.32 | G3: 2.14 | H3: 2.01 | I3: 1.86 | J3: 1.78 | K3: 1.37 | L3: 2.19 | M3: 2.26 | N3: 2.51 | O3: 3 | P3: 2.61 | Q3: 2.72 | R3: 3.37 | S3: 3.6 | T3: 5.46 | U3: 1.21
A4: Albania | B4: 9.14 | C4: 9.19 | D4: 10.07 | E4: 9.89 | F4: 9.51 | G4: 9.89 | H4: 8.8 | I4: 8.17 | J4: 8.83 | K4: 8.7 | L4: 8.29 | M4: 8.09 | N4: 7.22 | O4: 7.25 | P4: 9.38 | Q4: 9.03 | R4: 9.3 | S4: 9.35 | T4: 9 | U4: 8.21 | V4: 8.42 | W4: 8.17
A5: Algeria | B5: 8.82 | C5: 8.83 | D5: 8.83 | E5: 10.61 | F5: 10.61 | G5: 10.61 | H5: 10.6 | I5: 11.42 | J5: 11.7 | K5: 10.06 | L5: 9.03 | M5: 9.19 | N5: 8.64 | O5: 7.69 | P5: 7.63 | Q5: 7.85 | R5: 7.76 | S5: 8.67 | T5: 9.44 | U5: 7.97 | V5: 9.27 | W5: 8.78
A6: Andorra | B6: 15.73 | C6: 14.68 | D6: 14.59 | E6: 14.54 | F6: 14.12 | G6: 11.51 | H6: 15.76 | I6: 21.67 | J6: 11.19 | K6: 15.34 | L6: 23.77 | M6: 24.47 | N6: 16.82 | O6: 24.75 | P6: 21.77 | Q6: 23.4 | R6: 18.84 | S6: 27.78 | T6: 30.26 | U6: 30.31 | V6: 18.4 | W6: 30.57
A7: Angola | B7: 8.78 | C7: 7.31 | D7: 5.51 | E7: 5.36 | F7: 5.36 | G7: 5.43 | H7: 4.56 | I7: 3.62 | J7: 4.58 | K7: 4.2 | L7: 4.58 | M7: 4.25 | N7: 5.78 | O7: 4.06 | P7: 4.52 | Q7: 4.72 | R7: 4.82 | S7: 5.66 | T7: 4.26 | U7: 4.19 | V7: 5.97 | W7: 2.74
A8: Antigua and Barbuda | B8: 15.54 | C8: 13.78 | D8: 11.3 | E8: 13.07 | F8: 11.61 | G8: 11.61 | H8: 11.82 | I8: 15.11 | J8: 13.3 | K8: 14.63 | L8: 12.99 | M8: 13.9 | N8: 6.33 | O8: 8.08 | P8: 8.45 | Q8: 8.37 | R8: 11.53 | S8: 12.13 | T8: 12.45 | U8: 10.65 | V8: 12.12 | W8: 11.86
A9: Argentina | B9: 16.22 | C9: 15.74 | D9: 16.13 | E9: 15.48 | F9: 16.04 | G9: 15.52 | H9: 16.5 | I9: 16.29 | J9: 16.54 | K9: 16.66 | L9: 16.28 | M9: 16.69 | N9: 16.42 | O9: 14.66 | P9: 14.4 | Q9: 15.1 | R9: 16.02 | S9: 16.26 | T9: 17.13 | U9: 18.46 | V9: 17.37 | W9: 17.82
A10: Armenia | B10: 7.63 | C10: 7.69 | D10: 5.67 | E10: 5.13 | F10: 5.27 | G10: 6.05 | H10: 6.12 | I10: 6.28 | J10: 5.78 | K10: 7.04 | L10: 6.7 | M10: 6.44 | N10: 6.34 | O10: 6.69 | P10: 7.2 | Q10: 7.93 | R10: 7.44 | S10: 6.28 | T10: 5.38 | U10: 5.33 | V10: 5.66 | W10: 3.87
A11: Australia | B11: 19.32 | C11: 17.06 | D11: 17.11 | E11: 18.49 | F11: 18.54 | G11: 18.48 | H11: 18.31 | I11: 17.64 | J11: 15.4 | K11: 16.19 | L11: 16.32 | M11: 16.11 | N11: 15.88 | O11: 15.61 | P11: 16.49 | Q11: 15.94 | R11: 15.9 | S11: 15.95 | T11: 15.48 | U11: 15.51 | V11: 14.71 | W11: 14.6
A12: Austria | B12: 16.89 | C12: 15.39 | D12: 16.13 | E12: 15.81 | F12: 15.55 | G12: 14.96 | H12: 14.69 | I12: 14.34 | J12: 14.37 | K12: 14.51 | L12: 14.32 | M12: 14 | N12: 13.76 | O12: 14.39 | P12: 14.09 | Q12: 13.78 | R12: 13.67 | S12: 13.03 | T12: 13.62 | U12: 13.51 | V12: 13.29 | W12: 13.38
A13: Azerbaijan | B13: 4.59 | C13: 5.77 | D13: 3.29 | E13: 2.68 | F13: 2.82 | G13: 3.29 | H13: 3.37 | I13: 3.11 | J13: 2.82 | K13: 3.05 | L13: 2.82 | M13: 3.17 | N13: 3.28 | O13: 2.75 | P13: 3.49 | Q13: 3.43 | R13: 3.96 | S13: 3.56 | T13: 3.57 | U13: 3.19 | V13: 4.8 | W13: 4.75
A14: Bahamas | B14: 13.75 | C14: 15.4 | D14: 15.03 | E14: 15.41 | F14: 15.98 | G14: 14.19 | H14: 12.84 | I14: 14.21 | J14: 14.02 | K14: 14.06 | L14: 13.9 | M14: 15.44 | N14: 15.01 | O14: 14.47 | P14: 13.5 | Q14: 12.73 | R14: 12.86 | S14: 13.04 | T14: 13.16 | U14: 12.95 | V14: 13.24 | W14: 12.66
A15: Bahrain | B15: 8.69 | C15: 8.67 | D15: 7.06 | E15: 7.23 | F15: 7.98 | G15: 8.53 | H15: 8.87 | I15: 10.09 | J15: 8.46 | K15: 8.3 | L15: 8.05 | M15: 8.23 | N15: 11.17 | O15: 8.83 | P15: 9.07 | Q15: 8.94 | R15: 9.14 | S15: 9.04 | T15: 8.76 | U15: 8.22 | V15: 9.03 | W15: 10.27
... A82: Iran (Islamic Republic of) | B82: 26.11 | C82: 21.36 | D82: 19.73 | E82: 22.54 | F82: 21.07 | G82: 21.08 | H82: 22.6 | I82: 22.6 | J82: 16.05 | K82: 15.96 | L82: 12.04 | M82: 12.52 | N82: 12.38 | O82: 9.48 | P82: 11.53 | Q82: 9.61 | R82: 9.01 | S82: 10.16 | T82: 10.21 | U82: 9.57 | V82: 11.87 | W82: 10.95
A83: Iraq | B83: 6.99 | C83: 6.15 | D83: 5.99 | E83: 6.43 | F83: 4.79 | G83: 5.98 | H83: 1.68 | I83: 2.37 | J83: 2.38 | K83: 2.35 | L83: 4.8 | M83: 4.8 | N83: 4.91 | O83: 4.14 | P83: 4.42 | Q83: 3.05 | R83: 3.2 | S83: 2.98 | T83: 3.13
A84: Ireland | B84: 20.96 | C84: 20.29 | D84: 20.54 | E84: 18.71 | F84: 19.88 | G84: 19.27 | H84: 18.12 | I84: 18.02 | J84: 17.92 | K84: 17.93 | L84: 16.18 | M84: 12.35 | N84: 17.3 | O84: 17.42 | P84: 17.36 | Q84: 17.43 | R84: 18.25 | S84: 17.36 | T84: 16.9 | U84: 16.03 | V84: 15.59 | W84: 14.96
A85: Israel | B85: 13.19 | C85: 11.75 | D85: 11.88 | E85: 11.76 | F85: 11.76 | G85: 11.69 | H85: 11.68 | I85: 11.42 | J85: 10.92 | K85: 10.83 | L85: 10.67 | M85: 10.67 | N85: 10.02 | O85: 9.95 | P85: 9.92 | Q85: 9.87 | R85: 9.59 | S85: 9.6 | T85: 9.26 | U85: 8.7 | V85: 9.35 | W85: 9.43
A86: Italy | B86: 12.36 | C86: 12.87 | D86: 13.17 | E86: 13.25 | F86: 13.12 | G86: 13.23 | H86: 13.1 | I86: 13.15 | J86: 13.05 | K86: 13.17 | L86: 13.74 | M86: 14.01 | N86: 13.71 | O86: 13.86 | P86: 13.48 | Q86: 13.72 | R86: 13.68 | S86: 13.28 | T86: 12.51 | U86: 12.63 | V86: 12.2 | W86: 11.81
A87: Jamaica | B87: 16.18 | C87: 13.99 | D87: 13.32 | E87: 13.04 | F87: 13.95 | G87: 12.68 | H87: 12.82 | I87: 11.25 | J87: 10.77 | K87: 9.16 | L87: 9.53 | M87: 9.03 | N87: 7.45 | O87: 8.36 | P87: 8.23 | Q87: 6.26 | R87: 7.43 | S87: 7.65 | T87: 6.14 | U87: 8.67 | V87: 8.2 | W87: 11.84
A88: Japan | B88: 21.45 | C88: 20.96 | D88: 24.7 | E88: 24.49 | F88: 24.46 | G88: 23.18 | H88: 23.15 | I88: 22.57 | J88: 22.22 | K88: 22.22 | L88: 21.69 | M88: 18.93 | N88: 18.06 | O88: 18.1 | P88: 18.23 | Q88: 17.87 | R88: 17.75 | S88: 17.2 | T88: 16.36 | U88: 16.06 | V88: 15.95 | W88: 15.07
A89: Jordan | B89: 7.91 | C89: 8.89 | D89: 10.11 | E89: 9.98 | F89: 11.1 | G89: 11.24 | H89: 12.22 | I89: 13.06 | J89: 13.13 | K89: 13.67 | L89: 15.42 | M89: 17.02 | N89: 17.92 | O89: 15.13 | P89: 12.52 | Q89: 11.36 | R89: 11.79 | S89: 9.4 | T89: 11.37 | U89: 13.38 | V89: 13.61 | W89: 12.69
A90: Kazakhstan | B90: 11.62 | C90: 10.06 | D90: 8.25 | E90: 9.1 | F90: 7.86 | G90: 9.48 | H90: 8.39 | I90: 10.03 | J90: 9.32 | K90: 9.45 | L90: 8.68 | M90: 8.21 | N90: 11.32 | O90: 8.37 | P90: 7.56 | Q90: 11.69 | R90: 11.51 | S90: 10.91 | T90: 9.56 | U90: 9.42 | V90: 8.41 | W90: 9.25
A91: Kenya | B91: 9.29 | C91: 8.91 | D91: 8.23 | E91: 7.23 | F91: 6.8 | G91: 8.03 | H91: 8.07 | I91: 7.85 | J91: 7.15 | K91: 7.36 | L91: 7.98 | M91: 7.24 | N91: 7.2 | O91: 7.17 | P91: 7.04 | Q91: 6.81 | R91: 6.89 | S91: 6.99 | T91: 7.02 | U91: 7.09 | V91: 7.09 | W91: 7.09
A92: Kiribati | B92: 9.97 | C92: 9.3 | D92: 8.52 | E92: 8.09 | F92: 9.03 | G92: 7.78 | H92: 6.69 | I92: 7.28 | J92: 9.16 | K92: 8.36 | L92: 9.29 | M92: 10.45 | N92: 10.9 | O92: 12.69 | P92: 11.38 | Q92: 11.41 | R92: 11.41 | S92: 11.41 | T92: 11.41 | U92: 11.41 | V92: 11.41 | W92: 11.41
A93: Kuwait | B93: 9.92 | C93: 8.52 | D93: 8.91 | E93: 8.84 | F93: 7.67 | G93: 7.47 | H93: 6.57 | I93: 5.57 | J93: 5.48 | K93: 5.02 | L93: 5.05 | M93: 5.04 | N93: 5.23 | O93: 3.72 | P93: 4.9 | Q93: 4.37 | R93: 5.46 | S93: 5.26 | T93: 5.73 | U93: 5.73 | V93: 5.86 | W93: 4.37
A94: Kyrgyzstan | B94: 8.56 | C94: 6.92 | D94: 7.09 | E94: 7.33 | F94: 6.34 | G94: 6.42 | H94: 7.12 | I94: 7.14 | J94: 10.35 | K94: 10.4 | L94: 9.88 | M94: 9.2 | N94: 10.7 | O94: 10.39 | P94: 10.43 | Q94: 14.46 | R94: 13.07 | S94: 8.21 | T94: 8.07 | U94: 7.56 | V94: 7.13 | W94: 7.06
A95: Lao People's Democratic Republic | B95: 4.41 | C95: 4.26 | D95: 5.12 | E95: 4.16 | F95: 4.08 | G95: 3.66 | H95: 3.35 | I95: 2.74 | J95: 2.94 | K95: 1.77 | L95: 1.82 | M95: 2.69 | N95: 5.7 | O95: 3.2 | P95: 3.78 | Q95: 4.36 | R95: 5.91 | S95: 5.85 | T95: 6.83 | U95: 6.13 | V95: 7.06 | W95: 6.2
... A99: Liberia | B99: 3.66 | C99: 2.65 | D99: 4.2 | E99: 5.17 | F99: 3.96 | G99: 3.9 | H99: 3.24 | I99: 2.46 | J99: 1.25 | K99: 5.05 | L99: 5.05 | M99: 5.05 | N99: 5.05 | O99: 4.25 | P99: 4.25 | Q99: 4.25 | R99: 4.25 | S99: 4.25 | T99: 4.25 | U99: 4.25 | V99: 4.25 | W99: 4.25
A100: Libya | L100: 6.42 | M100: 4.33 | N100: 4.09 | O100: 3.7 | P100: 4.81 | Q100: 5.28 | R100: 5.78 | S100: 5.42 | T100: 6.31 | U100: 7.76 | V100: 5.78 | W100: 6.04
A101: Lithuania | B101: 14.01 | C101: 12.06 | D101: 13.1 | E101: 12.67 | F101: 12.7 | G101: 12.75 | H101: 12.2 | I101: 11.87 | J101: 11.3 | K101: 11.55 | L101: 10.73 | M101: 11.43 | N101: 11.78 | O101: 11.67 | P101: 10.75 | Q101: 10.62 | R101: 10.05 | S101: 10.13 | T101: 13.68 | U101: 12.71 | V101: 11.37 | W101: 10.57
A102: Luxembourg | B102: 11.48 | C102: 10.72 | D102: 10.89 | E102: 10.6 | F102: 10.55 | G102: 10.69 | H102: 10.63 | I102: 10.85 | J102: 10.65 | K102: 10.59 | L102: 11.96 | M102: 13.62 | N102: 14.12 | O102: 14.4 | P102: 14.06 | Q102: 14.12 | R102: 13.8 | S102: 14.09 | T102: 13.47 | U102: 13.59 | V102: 14.06 | W102: 12.99
A103: Madagascar | B103: 5.27 | C103: 4.22 | D103: 4.44 | E103: 10.48 | F103: 15.03 | G103: 17.51 | H103: 15.27 | I103: 13.92 | J103: 10.27 | K103: 12.94 | L103: 13.94 | M103: 15.21 | N103: 10.45 | O103: 8.98 | P103: 11.84 | Q103: 10.25 | R103: 10.54 | S103: 10.03 | T103: 13.1 | U103: 14.02 | V103: 12.02 | W103: 12.04
A104: Malawi | B104: 5.76 | C104: 6.87 | D104: 8.67 | E104: 8.67 | F104: 8.19 | G104: 9.68 | H104: 9.73 | I104: 8.58 | J104: 7.16 | K104: 5.1 | L104: 6.78 | M104: 5.77 | N104: 5.23 | O104: 6.62 | P104: 3.54 | Q104: 5.29 | R104: 6.04 | S104: 5 | T104: 7.63 | U104: 7.04 | V104: 7.04 | W104: 7.04
A105: Malaysia | B105: 10.11 | C105: 8.69 | D105: 8.52 | E105: 8.45 | F105: 8.72 | G105: 8.26 | H105: 8.23 | I105: 7.82 | J105: 6.82 | K105: 6.54 | L105: 6.52 | M105: 6.31 | N105: 5.87 | O105: 5.93 | P105: 6.28 | Q105: 6.55 | R105: 5.55 | S105: 5.63 | T105: 5.41 | U105: 5.04 | V105: 4.79 | W105: 4.58
A106: Maldives | B106: 18.17 | C106: 18.17 | D106: 17.85 | E106: 17.68 | F106: 21.47 | G106: 19.75 | H106: 18.45 | I106: 16.86 | J106: 15.93 | K106: 14.14 | L106: 11.76 | M106: 13.54 | N106: 15.74 | O106: 17.99 | P106: 11.25 | Q106: 8.45 | R106: 7.65 | S106: 9.6 | T106: 8.14 | U106: 8.62 | V106: 9.03 | W106: 8.83
A107: Mali | B107: 4.96 | C107: 5.37 | D107: 4.84 | E107: 5.67 | F107: 5.14 | G107: 5.43 | H107: 4.39 | I107: 4.45 | J107: 4.13 | K107: 2.66 | L107: 2.94 | M107: 3.3 | N107: 2.93 | O107: 3.79 | P107: 4.64 | Q107: 5.55 | R107: 6.46 | S107: 7.3 | T107: 6.79 | U107: 5.57 | V107: 5.75 | W107: 6.67
A108: Malta | B108: 16.23 | C108: 15.63 | D108: 15.91 | E108: 15.01 | F108: 15.94 | G108: 15.54 | H108: 14.05 | I108: 13.9 | J108: 14.06 | K108: 13.05 | L108: 12.98 | M108: 12.79 | N108: 12.5 | O108: 12.07 | P108: 13.33 | Q108: 14.3 | R108: 14.12 | S108: 13.37 | T108: 12.28 | U108: 13.11 | V108: 11.58 | W108: 11.78
A109: Marshall Islands | B109: 7.95 | C109: 8.8 | D109: 10.51 | E109: 12.26 | F109: 9.67 | G109: 12.15 | H109: 11.57 | I109: 11.64 | J109: 11.92 | K109: 11.4 | L109: 10.53 | M109: 7.67 | N109: 8.69 | O109: 8.98 | P109: 10.59 | Q109: 6.82 | R109: 6.55 | S109: 12.14 | T109: 11.41 | U109: 11.45 | V109: 13.46 | W109: 17.09
...

Sheet CHE
B1: Current health expenditure (CHE) as percentage of gross domestic product (GDP) (%) | C1: Current health expenditure (CHE) as percentage of gross domestic product (GDP) (%) | D1: Current health expenditure (CHE) as percentage of gross domestic product (GDP) (%) | E1: Current health expenditure (CHE) as percentage of gross domestic product (GDP) (%) | F1: Current health expenditure (CHE) as percentage of gross domestic product (GDP) (%) | G1: Current health expenditure (CHE) as percentage of gross domestic product (GDP) (%) | H1: Current health expenditure (CHE) as percentage of gross domestic product (GDP) (%) | I1: Current health expenditure (CHE) as percentage of gross domestic product (GDP) (%) | J1: Current health expenditure (CHE) as percentage of gross domestic product (GDP) (%) | K1: Current health expenditure (CHE) as percentage of gross domestic product (GDP) (%) | L1: Current health expenditure (CHE) as percentage of gross domestic product (GDP) (%) | M1: Current health expenditure (CHE) as percentage of gross domestic product (GDP) (%) | N1: Current health expenditure (CHE) as percentage of gross domestic product (GDP) (%) | O1: Current health expenditure (CHE) as percentage of gross domestic product (GDP) (%) | P1: Current health expenditure (CHE) as percentage of gross domestic product (GDP) (%) | Q1: Current health expenditure (CHE) as percentage of gross domestic product (GDP) (%) | R1: Current health expenditure (CHE) as percentage of gross domestic product (GDP) (%) | S1: Current health expenditure (CHE) as percentage of gross domestic product (GDP) (%) | T1: Current health expenditure (CHE) as percentage of gross domestic product (GDP) (%) | U1: Current health expenditure (CHE) as percentage of gross domestic product (GDP) (%) | V1: Current health expenditure (CHE) as percentage of gross domestic product (GDP) (%) | W1: Current health expenditure (CHE) as percentage of gross domestic product (GDP) (%)
A2: Countries, territories and areas | B2: 2021 | C2: 2020 | D2: 2019 | E2: 2018 | F2: 2017 | G2: 2016 | H2: 2015 | I2: 2014 | J2: 2013 | K2: 2012 | L2: 2011 | M2: 2010 | N2: 2009 | O2: 2008 | P2: 2007 | Q2: 2006 | R2: 2005 | S2: 2004 | T2: 2003 | U2: 2002 | V2: 2001 | W2: 2000
A3: Afghanistan | B3: 21.83 | C3: 15.53 | D3: 14.83 | E3: 14.21 | F3: 12.62 | G3: 11.82 | H3: 10.11 | I3: 9.53 | J3: 8.81 | K3: 7.9 | L3: 8.56 | M3: 8.57 | N3: 9.82 | O3: 10.26 | P3: 9.9 | Q3: 10.62 | R3: 9.95 | S3: 9.81 | T3: 8.94 | U3: 9.44
A4: Albania | B4: 7.27 | C4: 7.52 | D4: 6.86 | E4: 6.67 | F4: 6.58 | G4: 6.73 | H4: 6.46 | I4: 6.43 | J4: 6.28 | K4: 6.16 | L4: 6.18 | M4: 6.24 | N4: 5.83 | O4: 5.51 | P4: 5.93 | Q4: 5.63 | R4: 5.73 | S4: 5.89 | T4: 5.91 | U4: 5.66 | V4: 5.93 | W4: 5.94
A5: Algeria | B5: 5.53 | C5: 6.14 | D5: 5.87 | E5: 6.39 | F5: 6.53 | G5: 6.59 | H5: 6.96 | I5: 6.55 | J5: 6.04 | K5: 6 | L5: 5.27 | M5: 5.12 | N5: 5.36 | O5: 4.2 | P5: 3.82 | Q5: 3.36 | R5: 3.24 | S5: 3.54 | T5: 3.6 | U5: 3.73 | V5: 3.84 | W5: 3.49
A6: Andorra | B6: 8.33 | C6: 8.79 | D6: 7.32 | E6: 7.38 | F6: 7.07 | G6: 6.91 | H6: 6.92 | I6: 6.77 | J6: 6.8 | K6: 6.71 | L6: 7.62 | M6: 7.68 | N6: 6.08 | O6: 5.67 | P6: 4.92 | Q6: 4.97 | R6: 5.59 | S6: 5.29 | T6: 5.55 | U6: 6 | V6: 5.86 | W6: 5.95
A7: Angola | B7: 2.96 | C7: 3.22 | D7: 2.48 | E7: 2.59 | F7: 2.79 | G7: 2.71 | H7: 2.61 | I7: 2.43 | J7: 2.73 | K7: 2.4 | L7: 2.65 | M7: 2.7 | N7: 3.84 | O7: 3.32 | P7: 2.97 | Q7: 2.69 | R7: 2.85 | S7: 3.97 | T7: 3.55 | U7: 3.33 | V7: 4.48 | W7: 1.91
A8: Antigua and Barbuda | B8: 5.85 | C8: 5.92 | D8: 4.38 | E8: 4.85 | F8: 4.87 | G8: 5.12 | H8: 5.28 | I8: 5.87 | J8: 5.51 | K8: 5.48 | L8: 5.44 | M8: 5.38 | N8: 4.18 | O8: 4.2 | P8: 4.45 | Q8: 4.63 | R8: 4.99 | S8: 5.12 | T8: 5.58 | U8: 5.29 | V8: 5.44 | W8: 4.72
A9: Argentina | B9: 9.71 | C9: 10.35 | D9: 10.04 | E9: 10.29 | F9: 10.23 | G9: 9.86 | H9: 10.23 | I9: 9.67 | J9: 9.78 | K9: 9.83 | L9: 9.42 | M9: 9.45 | N9: 9.46 | O9: 8.18 | P9: 7.83 | Q9: 7.64 | R9: 7.61 | S9: 7.23 | T9: 6.89 | U9: 7.39 | V9: 8.37 | W9: 8.22
A10: Armenia | B10: 12.34 | C10: 12.24 | D10: 11.38 | E10: 10.01 | F10: 10.36 | G10: 9.95 | H10: 10.12 | I10: 10.18 | J10: 10.32 | K10: 9.13 | L10: 9.38 | M10: 9.24 | N10: 8.44 | O10: 6.64 | P10: 5.5 | Q10: 5.85 | R10: 5.86 | S10: 6.06 | T10: 7.18 | U10: 7.61 | V10: 4.65 | W10: 4.2
A11: Australia | B11: 10.54 | C11: 10.68 | D11: 10.22 | E11: 10.06 | F11: 10.12 | G11: 10.09 | H11: 10.18 | I11: 9.83 | J11: 8.75 | K11: 8.67 | L11: 8.54 | M11: 8.42 | N11: 8.54 | O11: 8.25 | P11: 8.05 | Q11: 7.98 | R11: 7.97 | S11: 8.09 | T11: 7.88 | U11: 7.88 | V11: 7.68 | W11: 7.59
A12: Austria | B12: 12.1 | C12: 11.39 | D12: 10.49 | E12: 10.35 | F12: 10.38 | G12: 10.35 | H12: 10.37 | I12: 10.37 | J12: 10.29 | K12: 10.2 | L12: 10.03 | M12: 10.22 | N12: 10.23 | O12: 9.73 | P12: 9.53 | Q12: 9.53 | R12: 9.63 | S12: 9.71 | T12: 9.55 | U12: 9.39 | V12: 9.27 | W12: 9.2
A13: Azerbaijan | B13: 4.7 | C13: 5.85 | D13: 4.18 | E13: 3.84 | F13: 4.07 | G13: 4.42 | H13: 4.34 | I13: 3.59 | J13: 3.23 | K13: 3.16 | L13: 2.6 | M13: 2.65 | N13: 2.77 | O13: 2.05 | P13: 1.99 | Q13: 2.07 | R13: 2.23 | S13: 2.66 | T13: 2.73 | U13: 2.73 | V13: 2.77 | W13: 2.95
A14: Bahamas | B14: 7.14 | C14: 7.65 | D14: 5.82 | E14: 5.98 | F14: 6.7 | G14: 5.68 | H14: 5.16 | I14: 5.54 | J14: 5.59 | K14: 5.32 | L14: 5.32 | M14: 5.26 | N14: 5.15 | O14: 4.86 | P14: 4.5 | Q14: 4.31 | R14: 4.03 | S14: 4.05 | T14: 4.02 | U14: 3.81 | V14: 3.92 | W14: 3.8
A15: Bahrain | B15: 4.27 | C15: 4.72 | D15: 3.96 | E15: 4.13 | F15: 4.51 | G15: 4.86 | H15: 4.98 | I15: 4.41 | J15: 4.31 | K15: 4.11 | L15: 3.87 | M15: 4.09 | N15: 4.33 | O15: 3.2 | P15: 3.3 | Q15: 3.11 | R15: 3.26 | S15: 3.5 | T15: 3.89 | U15: 3.68 | V15: 3.49 | W15: 3.34
... A82: Iran (Islamic Republic of) | B82: 5.77 | C82: 5.4 | D82: 6.27 | E82: 7.74 | F82: 7.83 | G82: 7.99 | H82: 7.53 | I82: 6.35 | J82: 5.55 | K82: 6.12 | L82: 6.1 | M82: 6.29 | N82: 6.11 | O82: 5.04 | P82: 4.91 | Q82: 5.16 | R82: 5.3 | S82: 5.13 | T82: 4.96 | U82: 4.65 | V82: 5.16 | W82: 4.72
A83: Iraq | B83: 5.25 | C83: 6.17 | D83: 4.26 | E83: 4.13 | F83: 4.04 | G83: 4.59 | H83: 3.16 | I83: 2.79 | J83: 2.81 | K83: 2.69 | L83: 2.8 | M83: 3.24 | N83: 3.77 | O83: 3.07 | P83: 3.21 | Q83: 2.49 | R83: 3.02 | S83: 3.9 | T83: 3
A84: Ireland | B84: 6.72 | C84: 7.11 | D84: 6.71 | E84: 6.5 | F84: 7.13 | G84: 7.47 | H84: 7.34 | I84: 9.51 | J84: 10.28 | K84: 10.6 | L84: 10.61 | M84: 10.52 | N84: 10.52 | O84: 9.13 | P84: 7.81 | Q84: 7.52 | R84: 7.64 | S84: 7.22 | T84: 7.01 | U84: 6.67 | V84: 6.39 | W84: 5.9
