Workbook

Sheet densities
A1: Country | B1: Doctors, Nurses and midwives density 2012 | C1: Data available year | D1: Doctors, Nurses and midwives density 2017 | E1: Data available year | F1: Doctors, Nurses and midwives density 2022 | G1: latest year
A2: Lesotho | B2: 6.0717945 | C2: 2013 | D2: 7.25 | E2: 2013 | F2: 3.2439575 | G2: 2022
A3: Niger | B3: 2.0563197 | C3: 2012 | D3: 0.43702429 | E3: 2017 | F3: 4.571509 | G3: 2022
A4: Central African Republic | B4: 2.1405837 | C4: 2013 | D4: 5.1915898 | E4: 2015 | F4: 4.8468483 | G4: 2021
A5: Madagascar | B5: 7.0068065 | C5: 2012 | D5: 2.2400086 | E5: 2017 | F5: 4.87 | G5: 2021
A6: United Republic of Tanzania | B6: 9.3252986 | C6: 2012 | D6: 11.353007 | E6: 2017 | F6: 6 | G6: 2021
A7: Chad | B7: 6.4053784 | C7: 2012 | D7: 5.4859231 | E7: 2017 | F7: 6.0615073 | G7: 2022
A8: Guinea | B8: 14.352312 | C8: 2014 | D8: 15.9 | E8: 2018 | F8: 8.0407866 | G8: 2022
A9: Mali | B9: 9.4334213 | C9: 2012 | D9: 2.3695904 | E9: 2017 | F9: 11.025251 | G9: 2022
A10: Malawi | B10: 4.7339197 | C10: 2013 | D10: 6.54 | E10: 2016 | F10: 11.044671 | G10: 2022
A11: Senegal | B11: 5.8357264 | C11: 2013 | D11: 7.768941 | E11: 2017 | F11: 11.524303 | G11: 2022
A12: Togo | B12: 2.3120561 | C12: 2013 | D12: 10.133971 | E12: 2017 | F12: 12.011936 | G12: 2022
A13: Mozambique | B13: 9.347584 | C13: 2012 | D13: 11.392243 | E13: 2017 | F13: 12.111187 | G13: 2022
... A15: Sao Tome and Principe | B15: 24.67 | C15: 2013 | D15: 26.42 | E15: 2018 | F15: 14.34 | G15: 2021
A16: South Sudan | B16: 0.028813174 | C16: 2013 | E16: 2017 | F16: 15.18 | G16: 2020
A17: Kenya | B17: 31.954128 | C17: 2012 | D17: 21.724218 | E17: 2017 | F17: 15.34071 | G17: 2022
A18: Gambia | B18: 23.153652 | C18: 2012 | D18: 16.613601 | E18: 2017 | F18: 15.973996 | G18: 2021
A19: Benin | B19: 13.243355 | C19: 2012 | D19: 15.596686 | E19: 2016 | F19: 16.073705 | G19: 2022
A20: Cameroon | B20: 17.43 | C20: 2013 | D20: 9.9 | E20: 2018 | F20: 16.177593 | G20: 2022
A21: Burundi | B21: 14.292308 | C21: 2012 | D21: 16.549546 | E21: 2017 | F21: 16.608753 | G21: 2021
A22: South Africa | B22: 22.098773 | C22: 2012 | D22: 15.766966 | E22: 2017 | F22: 16.684499 | G22: 2022
A23: Ethiopia | B23: 3.35 | C23: 2013 | D23: 16.296797 | E23: 2017 | F23: 17.849906 | G23: 2022
A24: Comoros | B24: 23.080772 | C24: 2012 | D24: 19.3 | E24: 2017 | F24: 18.73 | G24: 2021
A25: Côte d'Ivoire | B25: 11.242912 | C25: 2013 | D25: 16.29 | E25: 2018 | F25: 19.412978 | G25: 2022
A26: Equatorial Guinea | B26: 5.13 | C26: 2013 | D26: 15.730402 | E26: 2017 | F26: 19.547342 | G26: 2022
A27: Liberia | B27: 3.6410351 | C27: 2013 | D27: 15.78 | E27: 2018 | F27: 19.693811 | G27: 2022
A28: Cabo Verde | B28: 30.38227 | C28: 2012 | D28: 24.355965 | E28: 2017 | F28: 20.27 | G28: 2021
... A49: Seychelles | B49: 107.44001 | C49: 2012 | D49: 89.12 | E49: 2018 | F49: 115.52 | G49: 2021

Sheet anual growth
A1: Country | B1: Doctors, Nurses and midwives density 2012 | C1: Data available year | D1: Doctors, Nurses and midwives density 2017 | E1: Data available year | F1: Doctors, Nurses and midwives density 2022 | G1: latest year | H1: Annual growth 2012 - 2017 | I1: Annual growth 2017 - 2022
A2: Lesotho | B2: 6.0717945 | C2: 2013 | D2: 7.25 | E2: 2013 | F2: 3.2439575 | G2: 2022 | H2: =((D2/B2))^(1/5)-1 -> 0.036106001 | I2: =((F2/D2))^(1/5)-1 -> -0.14857298
A3: Guinea | B3: 14.352312 | C3: 2014 | D3: 15.9 | E3: 2018 | F3: 8.0407866 | G3: 2022 | H3: =((D3/B3))^(1/5)-1 -> 0.020692798 | I3: =((F3/D3))^(1/5)-1 -> -0.12747017
A4: United Republic of Tanzania | B4: 9.3252986 | C4: 2012 | D4: 11.353007 | E4: 2017 | F4: 6 | G4: 2021 | H4: =((D4/B4))^(1/5)-1 -> 0.040134809 | I4: =((F4/D4))^(1/5)-1 -> -0.11974587
A5: Sao Tome and Principe | B5: 24.67 | C5: 2013 | D5: 26.42 | E5: 2018 | F5: 14.34 | G5: 2021 | H5: =((D5/B5))^(1/5)-1 -> 0.013801041 | I5: =((F5/D5))^(1/5)-1 -> -0.11504076
A6: Kenya | B6: 31.954128 | C6: 2012 | D6: 21.724218 | E6: 2017 | F6: 15.34071 | G6: 2022 | H6: =((D6/B6))^(1/5)-1 -> -0.07427192 | I6: =((F6/D6))^(1/5)-1 -> -0.067217778
A7: Algeria | B7: 34.11 | C7: 2013 | D7: 44.729083 | E7: 2017 | F7: 32.9 | G7: 2021 | H7: =((D7/B7))^(1/5)-1 -> 0.055702758 | I7: =((F7/D7))^(1/5)-1 -> -0.059581466
A8: Mauritius | B8: 84.718111 | C8: 2012 | D8: 113.8761 | E8: 2017 | F8: 84.834652 | G8: 2022 | H8: =((D8/B8))^(1/5)-1 -> 0.060941078 | I8: =((F8/D8))^(1/5)-1 -> -0.057181407
A9: Gabon | B9: 50.62 | C9: 2013 | D9: 73.399151 | E9: 2017 | F9: 55.36225 | G9: 2022 | H9: =((D9/B9))^(1/5)-1 -> 0.07714403 | I9: =((F9/D9))^(1/5)-1 -> -0.054841728
A10: Zimbabwe | B10: 25.020107 | C10: 2012 | D10: 56.477818 | E10: 2017 | F10: 46.621628 | G10: 2022 | H10: =((D10/B10))^(1/5)-1 -> 0.17684089 | I10: =((F10/D10))^(1/5)-1 -> -0.037630381
A11: Cabo Verde | B11: 30.38227 | C11: 2012 | D11: 24.355965 | E11: 2017 | F11: 20.27 | G11: 2021 | H11: =((D11/B11))^(1/5)-1 -> -0.043253182 | I11: =((F11/D11))^(1/5)-1 -> -0.036060714
A12: Central African Republic | B12: 2.1405837 | C12: 2013 | D12: 5.1915898 | E12: 2015 | F12: 4.8468483 | G12: 2021 | H12: =((D12/B12))^(1/5)-1 -> 0.19386064 | I12: =((F12/D12))^(1/5)-1 -> -0.013648268
A13: Gambia | B13: 23.153652 | C13: 2012 | D13: 16.613601 | E13: 2017 | F13: 15.973996 | G13: 2021 | H13: =((D13/B13))^(1/5)-1 -> -0.06423056 | I13: =((F13/D13))^(1/5)-1 -> -0.0078211653
... A48: Niger | B48: 2.0563197 | C48: 2012 | D48: 0.43702429 | E48: 2017 | F48: 4.571509 | G48: 2022 | H48: =((D48/B48))^(1/5)-1 -> -0.26636002 | I48: =((F48/D48))^(1/5)-1 -> 0.59922953
A49: South Sudan | B49: 0.028813174 | C49: 2013 | E49: 2017 | F49: 15.18 | G49: 2020

Sheet Sheet4
A3: Row Labels | B3: Sum of Generalist medical practitioners | C3: Sum of Specialist medical practitioners | D3: Sum of Nursing professionals | E3: Sum of Nursing associate professionals | F3: Sum of Midwifery professionals | G3: Sum of Midwifery associate professionals | H3: Sum of Pharmacists1 | I3: Sum of Pharmaceutical technicians and assistants | J3: Sum of Dentists1 | K3: Sum of Dental assistants and therapists | L3: Sum of Community health workers
A4: AGO | B4: 3043 | C4: 3550 | D4: 7221 | E4: 38861 | F4: 769 | G4: 669 | H4: 697 | I4: 1605 | J4: 856 | K4: 796 | L4: 1680
A5: BDI | B5: 889 | C5: 195 | D5: 654 | E5: 8342 | F5: 41 | G5: 119 | H5: 119 | I5: 0 | J5: 14 | K5: 0 | L5: 11845
A6: BEN | B6: 391 | C6: 319 | D6: 1938 | E6: 1322 | F6: 807 | G6: 6 | H6: 14 | I6: 0 | J6: 0 | K6: 0 | L6: 0
A7: BFA | B7: 888 | C7: 738 | D7: 8208 | E7: 2117 | F7: 3583 | G7: 2986 | H7: 636 | I7: 156 | J7: 80 | K7: 0 | L7: 2749
A8: BWA | B8: 815 | C8: 38 | D8: 6935 | E8: 0 | F8: 0 | G8: 0 | H8: 149 | I8: 338 | J8: 94 | K8: 0 | L8: 0
A9: CAF | B9: 263 | C9: 72 | D9: 426 | E9: 325 | F9: 276 | G9: 168 | H9: 36 | I9: 0 | J9: 3 | K9: 7 | L9: 115
A10: CIV | B10: 4246 | C10: 1356 | D10: 11667 | E10: 63 | F10: 5456 | G10: 4 | H10: 2278 | I10: 217 | J10: 506 | K10: 0 | L10: 14556
A11: CMR | B11: 2400 | C11: 859 | D11: 9925 | E11: 0 | F11: 690 | G11: 0 | H11: 350 | I11: 0 | J11: 308 | K11: 0 | L11: 0
A12: COD | B12: 30768 | C12: 778 | D12: 51019 | E12: 52766 | F12: 1990 | G12: 1652 | H12: 1461 | I12: 226 | J12: 404 | K12: 0 | L12: 0
A13: COG | B13: 269 | C13: 275 | D13: 2707 | E13: 1305 | F13: 921 | G13: 148 | H13: 73 | I13: 84 | J13: 27 | K13: 0 | L13: 0
A14: COM | B14: 130 | C14: 90 | D14: 676 | E14: 71 | F14: 487 | G14: 0 | H14: 36 | I14: 19 | J14: 32 | K14: 0 | L14: 0
A15: CPV | B15: 165 | C15: 287 | D15: 243 | E15: 525 | F15: 7 | G15: 20 | H15: 80 | I15: 92 | J15: 81 | K15: 0 | L15: 117
... A51: Grand Total | B51: 243254 | C51: 90913 | D51: 715052 | E51: 378905 | F51: 200707 | G51: 16844 | H51: 69869 | I51: 24229 | J51: 31584 | K51: 26444 | L51: 486186

Sheet 2018 rep summaries
A1: Row Labels | B1: AGO | C1: BDI | D1: BEN | E1: BFA | F1: BWA | G1: CAF | H1: CIV | I1: CMR | J1: COD | K1: COG | L1: COM | M1: CPV | N1: DZA | O1: ERI | P1: ETH | Q1: GAB | R1: GHA | S1: GIN | T1: GMB | U1: GNB | V1: GNQ | W1: KEN | X1: LBR | Y1: LSO | Z1: MDG | AA1: MLI | AB1: MOZ | AC1: MRT | AD1: MUS | AE1: MWI | AF1: NAM | AG1: NER | AH1: NGA | AI1: RWA | AJ1: SEN | AK1: SLE | AL1: SSD | AM1: STP | AN1: SWZ | AO1: SYC | AP1: TCD | AQ1: TGO | AR1: TZA | AS1: UGA | AT1: ZAF | AU1: ZMB | AV1: ZWE
A2: Medical doctors | B2: 6593 | C2: 1084 | D2: 710 | E2: 1626 | F2: 853 | G2: 335 | H2: 5602 | I2: 3259 | J2: 31546 | K2: 544 | L2: 220 | M2: 452 | N2: 73168 | O2: 280 | P2: 11263 | Q2: 1368 | R2: 4406 | S2: 2787 | T2: 298 | U2: 318 | V2: 246 | W2: 8042 | X2: 246 | Y2: 998 | Z2: 5230 | AA2: 2866 | AB2: 2180 | AC2: 1626 | AD2: 2395 | AE2: 2760 | AF2: 1445 | AG2: 1065 | AH2: 83907 | AI2: 1350 | AJ2: 2883 | AK2: 281 | AL2: 411 | AM2: 60 | AN2: 278 | AO2: 240 | AP2: 803 | AQ2: 584 | AR2: 2885 | AS2: 17186 | AT2: 43503 | AU2: 2026 | AV2: 1959 | AW2: 334167
A3: Nursing Personnel | B3: 46082 | C3: 8996 | D3: 3260 | E3: 10325 | F3: 6935 | G3: 751 | H3: 11730 | I3: 9925 | J3: 103785 | K3: 4012 | L3: 747 | M3: 768 | N3: 57705 | O3: 3939 | P3: 61772 | Q3: 5352 | R3: 42827 | S3: 6329 | T3: 1178 | U3: 1264 | V3: 355 | W3: 59901 | X3: 8488 | Y3: 967 | Z3: 4560 | AA3: 5225 | AB3: 7961 | AC3: 4017 | AD3: 4419 | AE3: 6025 | AF3: 12956 | AG3: 3581 | AH3: 180709 | AI3: 9551 | AJ3: 4577 | AK3: 5302 | AL3: 2014 | AM3: 206 | AN3: 2204 | AO3: 1272 | AP3: 3863 | AQ3: 1966 | AR3: 31940 | AS3: 16407 | AT3: 287458 | AU3: 14516 | AV3: 25835 | AW3: 1093957
A4: Midwifery personnel | B4: 1438 | C4: 160 | D4: 813 | E4: 6569 | F4: 0 | G4: 444 | H4: 5460 | I4: 690 | J4: 3642 | K4: 1069 | L4: 487 | M4: 27 | N4: 8620 | O4: 45 | P4: 16161 | Q4: 733 | R4: 10625 | S4: 866 | T4: 320 | U4: 157 | V4: 51 | W4: 0 | X4: 927 | Y4: 2779 | Z4: 3164 | AA4: 3169 | AB4: 5820 | AC4: 855 | AD4: 567 | AE4: 0 | AF4: 0 | AG4: 902 | AH4: 120870 | AI4: 1207 | AJ4: 3015 | AK4: 391 | AL4: 1712 | AM4: 50 | AN4: 14 | AO4: 5 | AP4: 936 | AQ4: 1268 | AR4: 0 | AS4: 7237 | AT4: 0 | AU4: 3432 | AV4: 854 | AW4: 217551
A5: Pharmacists | B5: 2302 | C5: 119 | D5: 14 | E5: 792 | F5: 487 | G5: 36 | H5: 2495 | I5: 350 | J5: 1687 | K5: 157 | L5: 55 | M5: 172 | N5: 14106 | O5: 451 | P5: 10752 | Q5: 227 | R5: 2127 | S5: 255 | T5: 79 | U5: 82 | V5: 10 | W5: 2295 | X5: 1071 | Y5: 398 | Z5: 329 | AA5: 1424 | AB5: 2310 | AC5: 100 | AD5: 748 | AE5: 387 | AF5: 907 | AG5: 60 | AH5: 24668 | AI5: 167 | AJ5: 215 | AK5: 156 | AL5: 360 | AM5: 0 | AN5: 281 | AO5: 124 | AP5: 269 | AQ5: 226 | AR5: 1845 | AS5: 324 | AT5: 16195 | AU5: 1708 | AV5: 776 | AW5: 94098
A6: Dentists | B6: 1652 | C6: 14 | D6: 0 | E6: 80 | F6: 94 | G6: 10 | H6: 506 | I6: 308 | J6: 404 | K6: 27 | L6: 32 | M6: 81 | N6: 12781 | O6: 186 | P6: 1889 | Q6: 40 | R6: 713 | S6: 73 | T6: 3 | U6: 16 | V6: 0 | W6: 1764 | X6: 24 | Y6: 159 | Z6: 556 | AA6: 30 | AB6: 545 | AC6: 151 | AD6: 466 | AE6: 112 | AF6: 289 | AG6: 30 | AH6: 25487 | AI6: 228 | AJ6: 236 | AK6: 423 | AL6: 32 | AM6: 0 | AN6: 74 | AO6: 163 | AP6: 3 | AQ6: 21 | AR6: 682 | AS6: 26 | AT6: 6816 | AU6: 455 | AV6: 347 | AW6: 58028
A7: Community health workers | B7: 1680 | C7: 11845 | D7: 0 | E7: 2749 | F7: 0 | G7: 115 | H7: 14556 | I7: 0 | J7: 0 | K7: 0 | L7: 0 | M7: 117 | N7: 0 | O7: 243 | P7: 37259 | Q7: 0 | R7: 15820 | S7: 16567 | T7: 1553 | U7: 4057 | V7: 0 | W7: 58079 | X7: 3391 | Y7: 14508 | Z7: 35000 | AA7: 1152 | AB7: 2205 | AC7: 500 | AD7: 180 | AE7: 10016 | AF7: 2292 | AG7: 55 | AH7: 116454 | AI7: 45000 | AJ7: 17417 | AK7: 505 | AL7: 1455 | AM7: 0 | AN7: 6324 | AO7: 0 | AP7: 7 | AQ7: 7500 | AR7: 0 | AS7: 0 | AT7: 54180 | AU7: 1262 | AV7: 2143 | AW7: 486186
A8: Dieticians and nutritionists | B8: 0 | C8: 10 | D8: 0 | E8: 19 | F8: 0 | G8: 0 | H8: 25 | I8: 38 | J8: 535 | K8: 0 | L8: 0 | M8: 18 | N8: 381 | O8: 0 | P8: 147 | Q8: 6 | R8: 0 | S8: 0 | T8: 0 | U8: 0 | V8: 0 | W8: 1147 | X8: 0 | Y8: 29 | Z8: 414 | AA8: 7 | AB8: 0 | AC8: 20 | AD8: 0 | AE8: 25 | AF8: 33 | AG8: 42 | AH8: 0 | AI8: 0 | AJ8: 4 | AK8: 103 | AL8: 22 | AM8: 0 | AN8: 0 | AO8: 5 | AP8: 58 | AQ8: 12 | AR8: 148 | AS8: 3 | AT8: 0 | AU8: 404 | AV8: 0 | AW8: 3655
A9: Environmental and occupational health & hygiene workers | B9: 657 | C9: 372 | D9: 619 | E9: 160 | F9: 99 | G9: 105 | H9: 1425 | I9: 238 | J9: 167 | K9: 374 | L9: 389 | M9: 1 | N9: 1249 | O9: 243 | P9: 2662 | Q9: 312 | R9: 47 | S9: 0 | T9: 316 | U9: 3 | V9: 0 | W9: 5310 | X9: 285 | Y9: 144 | Z9: 15 | AA9: 78 | AB9: 0 | AC9: 5 | AD9: 48 | AE9: 35 | AF9: 218 | AG9: 101 | AH9: 14645 | AI9: 0 | AJ9: 573 | AK9: 406 | AL9: 250 | AM9: 0 | AN9: 187 | AO9: 50 | AP9: 76 | AQ9: 340 | AR9: 578 | AS9: 16 | AT9: 3585 | AU9: 2016 | AV9: 1644 | AW9: 40043
A10: Health care assistants and other personal care workers in health services | B10: 0 | C10: 8664 | D10: 2623 | E10: 1224 | F10: 1622 | G10: 79 | H10: 3640 | I10: 10717 | J10: 0 | K10: 850 | L10: 0 | M10: 149 | N10: 41461 | O10: 0 | P10: 0 | Q10: 86 | R10: 4059 | S10: 1 | T10: 0 | U10: 0 | V10: 1847 | W10: 0 | X10: 148 | Y10: 849 | Z10: 311 | AA10: 2153 | AB10: 0 | AC10: 38 | AD10: 1153 | AE10: 178 | AF10: 0 | AG10: 152 | AH10: 0 | AI10: 0 | AJ10: 1670 | AK10: 0 | AL10: 0 | AM10: 0 | AN10: 927 | AO10: 258 | AP10: 738 | AQ10: 3413 | AR10: 25803 | AS10: 527 | AT10: 0 | AU10: 0 | AV10: 2115 | AW10: 117455
A11: Health service managers | B11: 328 | C11: 1383 | D11: 0 | E11: 653 | F11: 0 | G11: 22 | H11: 91 | I11: 250 | J11: 2651 | K11: 790 | L11: 0 | M11: 61 | N11: 10838 | O11: 0 | P11: 4365 | Q11: 318 | R11: 1033 | S11: 189 | T11: 0 | U11: 130 | V11: 0 | W11: 0 | X11: 1404 | Y11: 110 | Z11: 411 | AA11: 25 | AB11: 2466 | AC11: 20 | AD11: 315 | AE11: 178 | AF11: 313 | AG11: 226 | AH11: 0 | AI11: 0 | AJ11: 135 | AK11: 0 | AL11: 20 | AM11: 79 | AN11: 195 | AO11: 0 | AP11: 732 | AQ11: 63 | AR11: 633 | AS11: 0 | AT11: 0 | AU11: 0 | AV11: 327 | AW11: 30754
A12: Medical and dental prosthetic technicians | B12: 75 | C12: 0 | D12: 0 | E12: 3 | F12: 0 | G12: 0 | H12: 0 | I12: 0 | J12: 0 | K12: 0 | L12: 0 | M12: 20 | N12: 663 | O12: 0 | P12: 52 | Q12: 46 | R12: 0 | S12: 0 | T12: 0 | U12: 5 | V12: 5 | W12: 468 | X12: 0 | Y12: 10 | Z12: 52 | AA12: 0 | AB12: 29 | AC12: 9 | AD12: 12 | AE12: 0 | AF12: 470 | AG12: 11 | AH12: 0 | AI12: 0 | AJ12: 100 | AK12: 128 | AL12: 21 | AM12: 0 | AN12: 0 | AO12: 2 | AP12: 0 | AQ12: 2 | AR12: 73 | AS12: 0 | AT12: 0 | AU12: 0 | AV12: 10 | AW12: 2266
A13: Other science professionals and technicians | B13: 468 | C13: 155 | D13: 0 | E13: 2 | F13: 0 | G13: 3 | H13: 497 | I13: 0 | J13: 0 | K13: 216 | L13: 161 | M13: 11 | N13: 0 | O13: 0 | P13: 672 | Q13: 83 | R13: 398 | S13: 0 | T13: 0 | U13: 0 | V13: 134 | W13: 0 | X13: 115 | Y13: 416 | Z13: 0 | AA13: 1496 | AB13: 5726 | AC13: 326 | AD13: 274 | AE13: 0 | AF13: 1739 | AG13: 191 | AH13: 0 | AI13: 321 | AJ13: 1045 | AK13: 0 | AL13: 16 | AM13: 146 | AN13: 84 | AO13: 70 | AP13: 814 | AQ13: 857 | AR13: 3028 | AS13: 526 | AT13: 8415 | AU13: 0 | AV13: 368 | AW13: 370104
... A25: Traditional and complementary medicine practitioners | B25: 16380 | C25: 1000 | D25: 0 | E25: 336 | F25: 0 | G25: 0 | H25: 4437 | I25: 0 | J25: 0 | K25: 0 | L25: 0 | M25: 1 | N25: 1 | O25: 0 | P25: 0 | Q25: 99 | R25: 3468 | S25: 0 | T25: 0 | U25: 1063 | V25: 0 | W25: 0 | X25: 0 | Y25: 6097 | Z25: 602 | AA25: 4 | AB25: 0 | AC25: 42 | AD25: 5 | AE25: 0 | AF25: 8 | AG25: 0 | AH25: 0 | AI25: 0 | AJ25: 0 | AK25: 0 | AL25: 0 | AM25: 0 | AN25: 7 | AO25: 0 | AP25: 0 | AQ25: 987 | AR25: 15200 | AS25: 0 | AT25: 0 | AU25: 0 | AV25: 5 | AW25: 2
AW26: 49742
B27: Country | C27: Pop 2018 | D27: Cadre | E27: 2018 report
B28: Country | C28: Pop 2018 | D28: Cadre | E28: 2018 report
B29: =#REF! -> #REF! | C29: =B1 -> AGO | D29: =A2 -> Medical doctors | E29: =B2 -> 6593
D30: =A3 -> Nursing Personnel | E30: =B3 -> 46082
D31: =A4 -> Midwifery personnel | E31: =B4 -> 1438
D32: =A5 -> Pharmacists | E32: =B5 -> 2302
D33: =A6 -> Dentists | E33: =B6 -> 1652
D34: =A7 -> Community health workers | E34: =B7 -> 1680
D35: =A8 -> Dieticians and nutritionists | E35: =B8 -> 0
D36: =A9 -> Environmental and occupational health & hygiene workers | E36: =B9 -> 657
D37: =A10 -> Health care assistants and other personal care workers in health services | E37: =B10 -> 0
D38: =A11 -> Health service managers | E38: =B11 -> 328
D39: =A12 -> Medical and dental prosthetic technicians | E39: =B12 -> 75
D40: =A13 -> Other science professionals and technicians | E40: =B13 -> 468
D41: =A14 -> Medical assistants – clinical officers | E41: =B14 -> 134
... D52: =A25 -> Traditional and complementary medicine practitioners | E52: =B25 -> 16380
B53: =#REF! -> #REF! | C53: =C1 -> BDI | D53: =D29 -> Medical doctors | E53: =C2 -> 1084
D54: =D30 -> Nursing Personnel | E54: =C3 -> 8996
D55: =D31 -> Midwifery personnel | E55: =C4 -> 160
D56: =D32 -> Pharmacists | E56: =C5 -> 119
D57: =D33 -> Dentists | E57: =C6 -> 14
D58: =D34 -> Community health workers | E58: =C7 -> 11845
D59: =D35 -> Dieticians and nutritionists | E59: =C8 -> 10
D60: =D36 -> Environmental and occupational health & hygiene workers | E60: =C9 -> 372
D61: =D37 -> Health care assistants and other personal care workers in health services | E61: =C10 -> 8664
...

Sheet 2018 report
A1: Country Name | B1: Country code | C1: Community health workers | D1: Dental assistants and therapists | E1: Dentists1 | F1: Dieticians and nutritionists | G1: Environmental and occupational health & hygiene workers | H1: Generalist medical practitioners | I1: Health care assistants and other personal care workers in health services | J1: Health service managers | K1: Medical and dental prosthetic technicians | L1: Medical and pathology laboratory technicians | M1: Medical assistants – clinical officers | N1: Medical imaging and therapeutic equipment operators | O1: Medical records and health information technicians | P1: Medical technicians and equipment operators | Q1: Midwifery associate professionals | R1: Midwifery professionals | S1: Nursing associate professionals | T1: Nursing professionals | U1: Optometrists and opticians | V1: Other health management and support workers | W1: Other health service providers | X1: Other science professionals and technicians | Y1: Paramedical practitioners (specify) | Z1: Pharmaceutical technicians and assistants | AA1: Pharmacists1 | AB1: Pharmacists | AC1: Physiotherapists and physiotherapy assistants | AD1: Social workers | AE1: Specialist medical practitioners | AF1: Speech Therapist | AG1: Traditional and complementary medicine practitioners | AH1: Dentists | AI1: Nursing Personnel | AJ1: Midwifery personnel | AK1: Medical doctors
A2: Algeria | B2: DZA | C2: 0 | D2: 7 | E2: 12774 | F2: 381 | G2: 1249 | H2: 34077 | I2: 41461 | J2: 10838 | K2: 663 | L2: 14548 | M2: 2227 | N2: 6176 | O2: 610 | P2: 0 | Q2: 38 | R2: 8582 | S2: 10029 | T2: 47676 | U2: 1218 | V2: 76532 | W2: 5104 | X2: 0 | Y2: 279 | Z2: 1536 | AA2: 12570 | AB2: =Z2+AA2 -> 14106 | AC2: 1827 | AD2: 0 | AE2: 39091 | AF2: 0 | AG2: 1 | AH2: =E2+D2 -> 12781 | AI2: =S2+T2 -> 57705 | AJ2: =Q2+R2 -> 8620 | AK2: =AE2+H2 -> 73168
A3: Angola | B3: AGO | C3: 1680 | D3: 796 | E3: 856 | F3: 0 | G3: 657 | H3: 3043 | I3: 0 | J3: 328 | K3: 75 | L3: 98 | M3: 134 | N3: 789 | O3: 190 | P3: 0 | Q3: 669 | R3: 769 | S3: 38861 | T3: 7221 | U3: 56 | V3: 28324 | W3: 0 | X3: 468 | Y3: 56 | Z3: 1605 | AA3: 697 | AB3: =Z3+AA3 -> 2302 | AC3: 1156 | AD3: 0 | AE3: 3550 | AF3: 0 | AG3: 16380 | AH3: =E3+D3 -> 1652 | AI3: =S3+T3 -> 46082 | AJ3: =Q3+R3 -> 1438 | AK3: =AE3+H3 -> 6593
A4: Benin | B4: BEN | C4: 0 | D4: 0 | E4: 0 | F4: 0 | G4: 619 | H4: 391 | I4: 2623 | J4: 0 | K4: 0 | L4: 241 | M4: 0 | N4: 54 | O4: 0 | P4: 0 | Q4: 6 | R4: 807 | S4: 1322 | T4: 1938 | U4: 0 | V4: 156 | W4: 1994 | X4: 0 | Y4: 146 | Z4: 0 | AA4: 14 | AB4: =Z4+AA4 -> 14 | AC4: 0 | AD4: 0 | AE4: 319 | AF4: 0 | AG4: 0 | AH4: =E4+D4 -> 0 | AI4: =S4+T4 -> 3260 | AJ4: =Q4+R4 -> 813 | AK4: =AE4+H4 -> 710
A5: Botswana | B5: BWA | C5: 0 | D5: 0 | E5: 94 | F5: 0 | G5: 99 | H5: 815 | I5: 1622 | J5: 0 | K5: 0 | L5: 460 | M5: 0 | N5: 78 | O5: 62 | P5: 0 | Q5: 0 | R5: 0 | S5: 0 | T5: 6935 | U5: 1 | V5: 0 | W5: 20 | X5: 0 | Y5: 58 | Z5: 338 | AA5: 149 | AB5: =Z5+AA5 -> 487 | AC5: 38 | AD5: 0 | AE5: 38 | AF5: 0 | AG5: 0 | AH5: =E5+D5 -> 94 | AI5: =S5+T5 -> 6935 | AJ5: =Q5+R5 -> 0 | AK5: =AE5+H5 -> 853
A6: Burkina Faso | B6: BFA | C6: 2749 | D6: 0 | E6: 80 | F6: 19 | G6: 160 | H6: 888 | I6: 1224 | J6: 653 | K6: 3 | L6: 699 | M6: 0 | N6: 128 | O6: 4 | P6: 0 | Q6: 2986 | R6: 3583 | S6: 2117 | T6: 8208 | U6: 3 | V6: 871 | W6: 44 | X6: 2 | Y6: 0 | Z6: 156 | AA6: 636 | AB6: =Z6+AA6 -> 792 | AC6: 18 | AD6: 0 | AE6: 738 | AF6: 0 | AG6: 336 | AH6: =E6+D6 -> 80 | AI6: =S6+T6 -> 10325 | AJ6: =Q6+R6 -> 6569 | AK6: =AE6+H6 -> 1626
A7: Burundi | B7: BDI | C7: 11845 | D7: 0 | E7: 14 | F7: 10 | G7: 372 | H7: 889 | I7: 8664 | J7: 1383 | K7: 0 | L7: 1071 | M7: 0 | N7: 86 | O7: 108 | P7: 0 | Q7: 119 | R7: 41 | S7: 8342 | T7: 654 | U7: 0 | V7: 2906 | W7: 0 | X7: 155 | Y7: 0 | Z7: 0 | AA7: 119 | AB7: =Z7+AA7 -> 119 | AC7: 9 | AD7: 0 | AE7: 195 | AF7: 0 | AG7: 1000 | AH7: =E7+D7 -> 14 | AI7: =S7+T7 -> 8996 | AJ7: =Q7+R7 -> 160 | AK7: =AE7+H7 -> 1084
A8: Cameroon | B8: CMR | C8: 0 | D8: 0 | E8: 308 | F8: 38 | G8: 238 | H8: 2400 | I8: 10717 | J8: 250 | K8: 0 | L8: 5235 | M8: 0 | N8: 124 | O8: 0 | P8: 0 | Q8: 0 | R8: 690 | S8: 0 | T8: 9925 | U8: 0 | V8: 0 | W8: 0 | X8: 0 | Y8: 0 | Z8: 0 | AA8: 350 | AB8: =Z8+AA8 -> 350 | AC8: 0 | AD8: 0 | AE8: 859 | AF8: 0 | AG8: 0 | AH8: =E8+D8 -> 308 | AI8: =S8+T8 -> 9925 | AJ8: =Q8+R8 -> 690 | AK8: =AE8+H8 -> 3259
A9: Cape-Verde | B9: CPV | C9: 117 | D9: 0 | E9: 81 | F9: 18 | G9: 1 | H9: 165 | I9: 149 | J9: 61 | K9: 20 | L9: 65 | M9: 3 | N9: 27 | O9: 14 | P9: 0 | Q9: 20 | R9: 7 | S9: 525 | T9: 243 | U9: 40 | V9: 1357 | W9: 95 | X9: 11 | Y9: 0 | Z9: 92 | AA9: 80 | AB9: =Z9+AA9 -> 172 | AC9: 58 | AD9: 0 | AE9: 287 | AF9: 0 | AG9: 1 | AH9: =E9+D9 -> 81 | AI9: =S9+T9 -> 768 | AJ9: =Q9+R9 -> 27 | AK9: =AE9+H9 -> 452
A10: Central African Republic | B10: CAF | C10: 115 | D10: 7 | E10: 3 | F10: 0 | G10: 105 | H10: 263 | I10: 79 | J10: 22 | K10: 0 | L10: 112 | M10: 104 | N10: 3 | O10: 20 | P10: 0 | Q10: 168 | R10: 276 | S10: 325 | T10: 426 | U10: 0 | V10: 65 | W10: 14 | X10: 3 | Y10: 200 | Z10: 0 | AA10: 36 | AB10: =Z10+AA10 -> 36 | AC10: 0 | AD10: 0 | AE10: 72 | AF10: 0 | AG10: 0 | AH10: =E10+D10 -> 10 | AI10: =S10+T10 -> 751 | AJ10: =Q10+R10 -> 444 | AK10: =AE10+H10 -> 335
A11: Chad | B11: TCD | C11: 7 | D11: 0 | E11: 3 | F11: 58 | G11: 76 | H11: 646 | I11: 738 | J11: 732 | K11: 0 | L11: 749 | M11: 42 | N11: 25 | O11: 6 | P11: 0 | Q11: 192 | R11: 744 | S11: 2076 | T11: 1787 | U11: 6 | V11: 436 | W11: 90 | X11: 814 | Y11: 0 | Z11: 171 | AA11: 98 | AB11: =Z11+AA11 -> 269 | AC11: 2 | AD11: 0 | AE11: 157 | AF11: 0 | AG11: 0 | AH11: =E11+D11 -> 3 | AI11: =S11+T11 -> 3863 | AJ11: =Q11+R11 -> 936 | AK11: =AE11+H11 -> 803
A12: Comoros | B12: COM | C12: 0 | D12: 0 | E12: 32 | F12: 0 | G12: 389 | H12: 130 | I12: 0 | J12: 0 | K12: 0 | L12: 8 | M12: 0 | N12: 498 | O12: 0 | P12: 0 | Q12: 0 | R12: 487 | S12: 71 | T12: 676 | U12: 0 | V12: 44 | W12: 115 | X12: 161 | Y12: 0 | Z12: 19 | AA12: 36 | AB12: =Z12+AA12 -> 55 | AC12: 0 | AD12: 0 | AE12: 90 | AF12: 0 | AG12: 0 | AH12: =E12+D12 -> 32 | AI12: =S12+T12 -> 747 | AJ12: =Q12+R12 -> 487 | AK12: =AE12+H12 -> 220
A13: Congo | B13: COG | C13: 0 | D13: 0 | E13: 27 | F13: 0 | G13: 374 | H13: 269 | I13: 850 | J13: 790 | K13: 0 | L13: 320 | M13: 0 | N13: 97 | O13: 0 | P13: 0 | Q13: 148 | R13: 921 | S13: 1305 | T13: 2707 | U13: 0 | V13: 111 | W13: 445 | X13: 216 | Y13: 0 | Z13: 84 | AA13: 73 | AB13: =Z13+AA13 -> 157 | AC13: 0 | AD13: 0 | AE13: 275 | AF13: 0 | AG13: 0 | AH13: =E13+D13 -> 27 | AI13: =S13+T13 -> 4012 | AJ13: =Q13+R13 -> 1069 | AK13: =AE13+H13 -> 544
... A48: Zimbabwe | B48: ZWE | C48: 2143 | D48: 205 | E48: 142 | F48: 0 | G48: 1644 | H48: 1715 | I48: 2115 | J48: 327 | K48: 10 | L48: 648 | M48: 76 | N48: 412 | O48: 718 | P48: 0 | Q48: 9 | R48: 845 | S48: 6664 | T48: 19171 | U48: 0 | V48: 9502 | W48: 1122 | X48: 368 | Y48: 1094 | Z48: 553 | AA48: 223 | AB48: =Z48+AA48 -> 776 | AC48: 459 | AD48: 0 | AE48: 244 | AF48: 0 | AG48: 5 | AH48: =E48+D48 -> 347 | AI48: =S48+T48 -> 25835 | AJ48: =Q48+R48 -> 854 | AK48: =AE48+H48 -> 1959

Sheet Sheet3
A1: 1 | B1: Audiologists and Speech Therapists | C1: 2 | D1: Community health workers
A2: 2 | B2: Community Health Workers | C2: 3 | D2: Dental assistants and therapists
A3: 3 | B3: Dental Assistants and Therapists | C3: 5 | D3: Dentists
A4: 4 | B4: Dental Prosthetic Technicians | C4: 12 | D4: Dieticians and nutritionists
A5: 5 | B5: Dentists | C5: 6 | D5: Environmental and occupational health & hygiene workers
A6: 6 | B6: Environmental and Occupational Health and Hygiene Professionals | C6: 8 | D6: Generalist medical practitioners
A7: 6 | B7: Environmental and Occupational Health Inspectors and Associates | D7: Health care assistants and other personal care workers in health services
B8: Medical and Pathology Laboratory scientists | D8: Health service managers
A9: 7 | B9: Medical and Pathology Laboratory Technicians | C9: 4 | D9: Medical and dental prosthetic technicians
A10: 8 | B10: Medical Doctors | C10: 7 | D10: Medical and pathology laboratory technicians
A11: 9 | B11: Medical Imaging and Therapeutic Equipment Technicians | D11: Medical assistants – clinical officers
A12: 4 | B12: Medical Prosthetic Technicians | C12: 9 | D12: Medical imaging and therapeutic equipment operators
A13: 10 | B13: Midwifery personnel | D13: Medical records and health information technicians
A14: 11 | B14: Nursing Personnel | D14: Medical technicians and equipment operators
A15: 12 | B15: Nutritionists | C15: 10 | D15: Midwifery associate professionals
A16: 13 | B16: Optometrists and Ophthalmic Opticians | C16: 10 | D16: Midwifery professionals
B17: Paramedical Practitioners | C17: 11 | D17: Nursing associate professionals
B18: Pharmaceutical Technicians and Assistants | C18: 11 | D18: Nursing professionals
B19: Pharmacists | C19: 13 | D19: Optometrists and opticians
B20: Physiotherapists | D20: Other health management and support workers
B21: Psychologists | D21: Other health service providers
B22: Social work and counselling professionals | D22: Other science professionals and technicians
D23: Paramedical practitioners (specify)
D24: Pharmaceutical technicians and assistants
D25: Pharmacists
D26: Physiotherapists and physiotherapy assistants
D27: Social workers
D28: Specialist medical practitioners
C29: 1 | D29: Speech Therapist
D30: Traditional and complementary medicine practitioners

Sheet Aggregate
A1: Country | B1: Pop 2012 | C1: Cadre | D1: 2012 | E1: Country | F1: Pop 2013 | G1: Cadre | H1: 2013 | I1: Country | J1: Pop 2014 | K1: Cadre | L1: 2014 | M1: Country | N1: Pop 2015 | O1: Cadre | P1: 2015 | Q1: Country | R1: Pop 2016 | S1: Cadre | T1: 2016 | U1: Country | V1: Pop 2017 | W1: Cadre | X1: 2017 | Y1: Country | Z1: Pop 2018 | AA1: Cadre | AB1: 2018 | AC1: Country | AD1: Pop 2019 | AE1: Cadre | AF1: 2019 | AG1: Country | AH1: Pop 2020 | AI1: Cadre | AJ1: 2020 | AK1: Country | AL1: Pop 2021 | AM1: Cadre | AN1: 2021 | AO1: Country | AP1: Pop 2022 | AQ1: Cadre | AR1: 2022 | AS1: Pop 2018 | AT1: Cadre | AU1: 2018 report
A2: AGO | B2: 25188292 | C2: Medical Doctors | D2: 0 | E2: AGO | F2: 26147002 | G2: Medical Doctors | H2: 0 | I2: AGO | J2: 27128336 | K2: Medical Doctors | L2: 0 | M2: AGO | N2: 28127721 | O2: Medical Doctors | P2: 0 | Q2: AGO | R2: 29154746 | S2: Medical Doctors | T2: 0 | U2: AGO | V2: 30208628 | W2: Medical Doctors | X2: 12800 | Y2: AGO | Z2: 31273533 | AA2: Medical Doctors | AB2: 13186 | AC2: AGO | AD2: 32353588 | AE2: Medical Doctors | AF2: 0 | AG2: AGO | AH2: 33428486 | AI2: Medical Doctors | AJ2: 0 | AK2: AGO | AL2: 34503773 | AM2: Medical Doctors | AN2: 0 | AO2: AGO | AP2: 35588987 | AQ2: Medical Doctors | AR2: 21301 | AS2: AGO | AT2: Medical doctors | AU2: 6593
C3: Nursing Personnel | D3: 0 | G3: Nursing Personnel | H3: 0 | K3: Nursing Personnel | L3: 0 | O3: Nursing Personnel | P3: 0 | S3: Nursing Personnel | T3: 0 | W3: Nursing Personnel | X3: 0 | AA3: Nursing Personnel | AB3: 25108 | AE3: Nursing Personnel | AF3: 0 | AI3: Nursing Personnel | AJ3: 0 | AM3: Nursing Personnel | AN3: 0 | AQ3: Nursing Personnel | AR3: 89978 | AT3: Nursing Personnel | AU3: 46082
C4: Midwifery personnel | D4: 0 | G4: Midwifery personnel | H4: 60 | K4: Midwifery personnel | L4: 0 | O4: Midwifery personnel | P4: 0 | S4: Midwifery personnel | T4: 0 | W4: Midwifery personnel | X4: 0 | AA4: Midwifery personnel | AB4: 0 | AE4: Midwifery personnel | AF4: 0 | AI4: Midwifery personnel | AJ4: 0 | AM4: Midwifery personnel | AN4: 0 | AQ4: Midwifery personnel | AR4: 44 | AT4: Midwifery personnel | AU4: 1438
C5: Pharmacists | D5: 751 | G5: Pharmacists | H5: 0 | K5: Pharmacists | L5: 0 | O5: Pharmacists | P5: 2781 | S5: Pharmacists | T5: 884 | W5: Pharmacists | X5: 0 | AA5: Pharmacists | AB5: 260 | AE5: Pharmacists | AF5: 0 | AI5: Pharmacists | AJ5: 525 | AM5: Pharmacists | AN5: 0 | AQ5: Pharmacists | AR5: 430 | AT5: Pharmacists | AU5: 2302
C6: Dentists | D6: 353 | G6: Dentists | H6: 0 | K6: Dentists | L6: 0 | O6: Dentists | P6: 595 | S6: Dentists | T6: 181 | W6: Dentists | X6: 0 | AA6: Dentists | AB6: 134 | AE6: Dentists | AF6: 0 | AI6: Dentists | AJ6: 81 | AM6: Dentists | AN6: 0 | AQ6: Dentists | AR6: 156 | AT6: Dentists | AU6: 1652
C7: Community Health Workers | D7: 0 | G7: Community Health Workers | H7: 0 | K7: Community Health Workers | L7: 0 | O7: Community Health Workers | P7: 0 | S7: Community Health Workers | T7: 0 | W7: Community Health Workers | X7: 0 | AA7: Community Health Workers | AB7: 1680 | AE7: Community Health Workers | AF7: 0 | AI7: Community Health Workers | AJ7: 2652 | AM7: Community Health Workers | AN7: 0 | AQ7: Community Health Workers | AR7: 5 | AT7: Community health workers | AU7: 1680
C8: Dieticians and nutritionists | D8: 85 | G8: Dieticians and nutritionists | H8: 0 | K8: Dieticians and nutritionists | L8: 0 | O8: Dieticians and nutritionists | P8: 870 | S8: Dieticians and nutritionists | T8: 32 | W8: Dieticians and nutritionists | X8: 0 | AA8: Dieticians and nutritionists | AB8: 4 | AE8: Dieticians and nutritionists | AF8: 0 | AI8: Dieticians and nutritionists | AJ8: 57 | AM8: Dieticians and nutritionists | AN8: 0 | AQ8: Dieticians and nutritionists | AR8: 197 | AT8: Dieticians and nutritionists | AU8: 0
C9: Environmental and occupational health & hygiene workers | D9: 517 | G9: Environmental and occupational health & hygiene workers | H9: 0 | K9: Environmental and occupational health & hygiene workers | L9: 0 | O9: Environmental and occupational health & hygiene workers | P9: 0 | S9: Environmental and occupational health & hygiene workers | T9: 177 | W9: Environmental and occupational health & hygiene workers | X9: 0 | AA9: Environmental and occupational health & hygiene workers | AB9: 411 | AE9: Environmental and occupational health & hygiene workers | AF9: 0 | AI9: Environmental and occupational health & hygiene workers | AJ9: 236 | AM9: Environmental and occupational health & hygiene workers | AN9: 0 | AQ9: Environmental and occupational health & hygiene workers | AR9: 10 | AT9: Environmental and occupational health & hygiene workers | AU9: 657
C10: Personal care workers in health service | D10: 0 | G10: Personal care workers in health service | H10: 0 | K10: Personal care workers in health service | L10: 0 | O10: Personal care workers in health service | P10: 0 | S10: Personal care workers in health service | T10: 0 | W10: Personal care workers in health service | X10: 0 | AA10: Personal care workers in health service | AB10: 0 | AE10: Personal care workers in health service | AF10: 0 | AI10: Personal care workers in health service | AJ10: 0 | AM10: Personal care workers in health service | AN10: 0 | AQ10: Personal care workers in health service | AR10: 0 | AT10: Health care assistants and other personal care workers in health services | AU10: 0
C11: Managerial staff | D11: 0 | G11: Managerial staff | H11: 0 | K11: Managerial staff | L11: 0 | O11: Managerial staff | P11: 0 | S11: Managerial staff | T11: 0 | W11: Managerial staff | X11: 0 | AA11: Managerial staff | AB11: 0 | AE11: Managerial staff | AF11: 0 | AI11: Managerial staff | AJ11: 0 | AM11: Managerial staff | AN11: 0 | AQ11: Managerial staff | AR11: 2072 | AT11: Health service managers | AU11: 328
C12: Medical and dental Prosthetic Technicians | D12: 0 | G12: Medical and dental Prosthetic Technicians | H12: 0 | K12: Medical and dental Prosthetic Technicians | L12: 0 | O12: Medical and dental Prosthetic Technicians | P12: 0 | S12: Medical and dental Prosthetic Technicians | T12: 0 | W12: Medical and dental Prosthetic Technicians | X12: 0 | AA12: Medical and dental Prosthetic Technicians | AB12: 0 | AE12: Medical and dental Prosthetic Technicians | AF12: 0 | AI12: Medical and dental Prosthetic Technicians | AJ12: 0 | AM12: Medical and dental Prosthetic Technicians | AN12: 0 | AQ12: Medical and dental Prosthetic Technicians | AR12: 0 | AT12: Medical and dental prosthetic technicians | AU12: 75
C13: Medical and Pathology Laboratory scientists | D13: 0 | G13: Medical and Pathology Laboratory scientists | H13: 0 | K13: Medical and Pathology Laboratory scientists | L13: 0 | O13: Medical and Pathology Laboratory scientists | P13: 0 | S13: Medical and Pathology Laboratory scientists | T13: 0 | W13: Medical and Pathology Laboratory scientists | X13: 0 | AA13: Medical and Pathology Laboratory scientists | AB13: 98 | AE13: Medical and Pathology Laboratory scientists | AF13: 0 | AI13: Medical and Pathology Laboratory scientists | AJ13: 0 | AM13: Medical and Pathology Laboratory scientists | AN13: 0 | AQ13: Medical and Pathology Laboratory scientists | AR13: 9 | AT13: Other science professionals and technicians | AU13: 468
C14: Medical Assistants | D14: 0 | G14: Medical Assistants | H14: 0 | K14: Medical Assistants | L14: 0 | O14: Medical Assistants | P14: 0 | S14: Medical Assistants | T14: 0 | W14: Medical Assistants | X14: 0 | AA14: Medical Assistants | AB14: 0 | AE14: Medical Assistants | AF14: 0 | AI14: Medical Assistants | AJ14: 0 | AM14: Medical Assistants | AN14: 0 | AQ14: Medical Assistants | AR14: 0 | AT14: Medical assistants – clinical officers | AU14: 134
... C25: Traditional and complementary medicine practitioners | D25: 0 | G25: Traditional and complementary medicine practitioners | H25: 0 | K25: Traditional and complementary medicine practitioners | L25: 0 | O25: Traditional and complementary medicine practitioners | P25: 0 | S25: Traditional and complementary medicine practitioners | T25: 0 | W25: Traditional and complementary medicine practitioners | X25: 0 | AA25: Traditional and complementary medicine practitioners | AB25: 0 | AE25: Traditional and complementary medicine practitioners | AF25: 0 | AI25: Traditional and complementary medicine practitioners | AJ25: 0 | AM25: Traditional and complementary medicine practitioners | AN25: 0 | AQ25: Traditional and complementary medicine practitioners | AR25: 0 | AT25: Traditional and complementary medicine practitioners | AU25: 16380
A26: BDI | B26: 9795479 | C26: Medical Doctors | D26: 996 | E26: BDI | F26: 10149578 | G26: Medical Doctors | H26: 1108 | I26: BDI | J26: 10494912 | K26: Medical Doctors | L26: 1218 | M26: BDI | N26: 10727148 | O26: Medical Doctors | P26: 1016 | Q26: BDI | R26: 10903328 | S26: Medical Doctors | T26: 0 | U26: BDI | V26: 11155593 | W26: Medical Doctors | X26: 0 | Y26: BDI | Z26: 11493472 | AA26: Medical Doctors | AB26: 45 | AC26: BDI | AD26: 11874838 | AE26: Medical Doctors | AF26: 0 | AG26: BDI | AH26: 12220227 | AI26: Medical Doctors | AJ26: 1704 | AK26: BDI | AL26: 12551213 | AM26: Medical Doctors | AN26: 1816 | AO26: BDI | AP26: 12889576 | AQ26: Medical Doctors | AR26: 0 | AS26: BDI | AT26: Medical doctors | AU26: 1084
C27: Nursing Personnel | D27: 12972 | G27: Nursing Personnel | H27: 13146 | K27: Nursing Personnel | L27: 13638 | O27: Nursing Personnel | P27: 13376 | S27: Nursing Personnel | T27: 0 | W27: Nursing Personnel | X27: 18142 | AA27: Nursing Personnel | AB27: 18312 | AE27: Nursing Personnel | AF27: 15036 | AI27: Nursing Personnel | AJ27: 15426 | AM27: Nursing Personnel | AN27: 18744 | AQ27: Nursing Personnel | AR27: 0 | AT27: Nursing Personnel | AU27: 8996
C28: Midwifery personnel | D28: 32 | G28: Midwifery personnel | H28: 70 | K28: Midwifery personnel | L28: 48 | O28: Midwifery personnel | P28: 158 | S28: Midwifery personnel | T28: 0 | W28: Midwifery personnel | X28: 320 | AA28: Midwifery personnel | AB28: 0 | AE28: Midwifery personnel | AF28: 248 | AI28: Midwifery personnel | AJ28: 0 | AM28: Midwifery personnel | AN28: 286 | AQ28: Midwifery personnel | AR28: 0 | AT28: Midwifery personnel | AU28: 160
C29: Pharmacists | D29: 546 | G29: Pharmacists | H29: 0 | K29: Pharmacists | L29: 0 | O29: Pharmacists | P29: 0 | S29: Pharmacists | T29: 188 | W29: Pharmacists | X29: 944 | AA29: Pharmacists | AB29: 0 | AE29: Pharmacists | AF29: 83 | AI29: Pharmacists | AJ29: 1138 | AM29: Pharmacists | AN29: 0 | AQ29: Pharmacists | AR29: 0 | AT29: Pharmacists | AU29: 119
C30: Dentists | D30: 115 | G30: Dentists | H30: 0 | K30: Dentists | L30: 194 | O30: Dentists | P30: 300 | S30: Dentists | T30: 11 | W30: Dentists | X30: 373 | AA30: Dentists | AB30: 0 | AE30: Dentists | AF30: 18 | AI30: Dentists | AJ30: 0 | AM30: Dentists | AN30: 0 | AQ30: Dentists | AR30: 0 | AT30: Dentists | AU30: 14
C31: Community Health Workers | D31: 0 | G31: Community Health Workers | H31: 0 | K31: Community Health Workers | L31: 0 | O31: Community Health Workers | P31: 0 | S31: Community Health Workers | T31: 0 | W31: Community Health Workers | X31: 0 | AA31: Community Health Workers | AB31: 11845 | AE31: Community Health Workers | AF31: 0 | AI31: Community Health Workers | AJ31: 11845 | AM31: Community Health Workers | AN31: 0 | AQ31: Community Health Workers | AR31: 0 | AT31: Community health workers | AU31: 11845
C32: Dieticians and nutritionists | D32: 44 | G32: Dieticians and nutritionists | H32: 0 | K32: Dieticians and nutritionists | L32: 0 | O32: Dieticians and nutritionists | P32: 0 | S32: Dieticians and nutritionists | T32: 42 | W32: Dieticians and nutritionists | X32: 0 | AA32: Dieticians and nutritionists | AB32: 0 | AE32: Dieticians and nutritionists | AF32: 0 | AI32: Dieticians and nutritionists | AJ32: 0 | AM32: Dieticians and nutritionists | AN32: 0 | AQ32: Dieticians and nutritionists | AR32: 0 | AT32: Dieticians and nutritionists | AU32: 10
C33: Environmental and occupational health & hygiene workers | D33: 0 | G33: Environmental and occupational health & hygiene workers | H33: 0 | K33: Environmental and occupational health & hygiene workers | L33: 0 | O33: Environmental and occupational health & hygiene workers | P33: 0 | S33: Environmental and occupational health & hygiene workers | T33: 96 | W33: Environmental and occupational health & hygiene workers | X33: 0 | AA33: Environmental and occupational health & hygiene workers | AB33: 0 | AE33: Environmental and occupational health & hygiene workers | AF33: 149 | AI33: Environmental and occupational health & hygiene workers | AJ33: 0 | AM33: Environmental and occupational health & hygiene workers | AN33: 0 | AQ33: Environmental and occupational health & hygiene workers | AR33: 0 | AT33: Environmental and occupational health & hygiene workers | AU33: 372
C34: Personal care workers in health service | D34: 0 | G34: Personal care workers in health service | H34: 0 | K34: Personal care workers in health service | L34: 0 | O34: Personal care workers in health service | P34: 0 | S34: Personal care workers in health service | T34: 0 | W34: Personal care workers in health service | X34: 0 | AA34: Personal care workers in health service | AB34: 0 | AE34: Personal care workers in health service | AF34: 0 | AI34: Personal care workers in health service | AJ34: 0 | AM34: Personal care workers in health service | AN34: 0 | AQ34: Personal care workers in health service | AR34: 0 | AT34: Health care assistants and other personal care workers in health services | AU34: 8664
C35: Managerial staff | D35: 0 | G35: Managerial staff | H35: 0 | K35: Managerial staff | L35: 0 | O35: Managerial staff | P35: 0 | S35: Managerial staff | T35: 0 | W35: Managerial staff | X35: 0 | AA35: Managerial staff | AB35: 0 | AE35: Managerial staff | AF35: 0 | AI35: Managerial staff | AJ35: 0 | AM35: Managerial staff | AN35: 0 | AQ35: Managerial staff | AR35: 0 | AT35: Health service managers | AU35: 1383
C36: Medical and dental Prosthetic Technicians | D36: 0 | G36: Medical and dental Prosthetic Technicians | H36: 0 | K36: Medical and dental Prosthetic Technicians | L36: 0 | O36: Medical and dental Prosthetic Technicians | P36: 0 | S36: Medical and dental Prosthetic Technicians | T36: 0 | W36: Medical and dental Prosthetic Technicians | X36: 0 | AA36: Medical and dental Prosthetic Technicians | AB36: 0 | AE36: Medical and dental Prosthetic Technicians | AF36: 0 | AI36: Medical and dental Prosthetic Technicians | AJ36: 0 | AM36: Medical and dental Prosthetic Technicians | AN36: 0 | AQ36: Medical and dental Prosthetic Technicians | AR36: 0 | AT36: Medical and dental prosthetic technicians | AU36: 0
C37: Medical and Pathology Laboratory scientists | D37: 0 | G37: Medical and Pathology Laboratory scientists | H37: 0 | K37: Medical and Pathology Laboratory scientists | L37: 0 | O37: Medical and Pathology Laboratory scientists | P37: 0 | S37: Medical and Pathology Laboratory scientists | T37: 0 | W37: Medical and Pathology Laboratory scientists | X37: 1073 | AA37: Medical and Pathology Laboratory scientists | AB37: 1071 | AE37: Medical and Pathology Laboratory scientists | AF37: 0 | AI37: Medical and Pathology Laboratory scientists | AJ37: 0 | AM37: Medical and Pathology Laboratory scientists | AN37: 0 | AQ37: Medical and Pathology Laboratory scientists | AR37: 0 | AT37: Other science professionals and technicians | AU37: 155
C38: Medical Assistants | D38: 0 | G38: Medical Assistants | H38: 0 | K38: Medical Assistants | L38: 0 | O38: Medical Assistants | P38: 0 | S38: Medical Assistants | T38: 0 | W38: Medical Assistants | X38: 0 | AA38: Medical Assistants | AB38: 0 | AE38: Medical Assistants | AF38: 0 | AI38: Medical Assistants | AJ38: 0 | AM38: Medical Assistants | AN38: 0 | AQ38: Medical Assistants | AR38: 0 | AT38: Medical assistants – clinical officers | AU38: 0
... C49: Traditional and complementary medicine practitioners | D49: 0 | G49: Traditional and complementary medicine practitioners | H49: 0 | K49: Traditional and complementary medicine practitioners | L49: 0 | O49: Traditional and complementary medicine practitioners | P49: 0 | S49: Traditional and complementary medicine practitioners | T49: 0 | W49: Traditional and complementary medicine practitioners | X49: 0 | AA49: Traditional and complementary medicine practitioners | AB49: 0 | AE49: Traditional and complementary medicine practitioners | AF49: 0 | AI49: Traditional and complementary medicine practitioners | AJ49: 0 | AM49: Traditional and complementary medicine practitioners | AN49: 0 | AQ49: Traditional and complementary medicine practitioners | AR49: 0 | AT49: Traditional and complementary medicine practitioners | AU49: 1000
A50: BEN | B50: 10014078 | C50: Medical Doctors | D50: 26 | E50: BEN | F50: 10308730 | G50: Medical Doctors | H50: 0 | I50: BEN | J50: 10614844 | K50: Medical Doctors | L50: 191 | M50: BEN | N50: 10932783 | O50: Medical Doctors | P50: 0 | Q50: BEN | R50: 11260084 | S50: Medical Doctors | T50: 1046 | U50: BEN | V50: 11596778 | W50: Medical Doctors | X50: 0 | Y50: BEN | Z50: 11940683 | AA50: Medical Doctors | AB50: 2300 | AC50: BEN | AD50: 12290444 | AE50: Medical Doctors | AF50: 1842 | AG50: BEN | AH50: 12643123 | AI50: Medical Doctors | AJ50: 0 | AK50: BEN | AL50: 12996895 | AM50: Medical Doctors | AN50: 5861 | AO50: BEN | AP50: 13352864 | AQ50: Medical Doctors | AR50: 5567 | AS50: BEN | AT50: Medical doctors | AU50: 710
C51: Nursing Personnel | D51: 10276 | G51: Nursing Personnel | H51: 9760 | K51: Nursing Personnel | L51: 0 | O51: Nursing Personnel | P51: 0 | S51: Nursing Personnel | T51: 14448 | W51: Nursing Personnel | X51: 0 | AA51: Nursing Personnel | AB51: 6820 | AE51: Nursing Personnel | AF51: 5340 | AI51: Nursing Personnel | AJ51: 0 | AM51: Nursing Personnel | AN51: 10968 | AQ51: Nursing Personnel | AR51: 11786 | AT51: Nursing Personnel | AU51: 3260
C52: Midwifery personnel | D52: 2960 | G52: Midwifery personnel | H52: 1886 | K52: Midwifery personnel | L52: 0 | O52: Midwifery personnel | P52: 0 | S52: Midwifery personnel | T52: 2068 | W52: Midwifery personnel | X52: 0 | AA52: Midwifery personnel | AB52: 2110 | AE52: Midwifery personnel | AF52: 1810 | AI52: Midwifery personnel | AJ52: 0 | AM52: Midwifery personnel | AN52: 4172 | AQ52: Midwifery personnel | AR52: 4110 | AT52: Midwifery personnel | AU52: 813
C53: Pharmacists | D53: 0 | G53: Pharmacists | H53: 0 | K53: Pharmacists | L53: 1717 | O53: Pharmacists | P53: 2626 | S53: Pharmacists | T53: 1600 | W53: Pharmacists | X53: 0 | AA53: Pharmacists | AB53: 281 | AE53: Pharmacists | AF53: 106 | AI53: Pharmacists | AJ53: 0 | AM53: Pharmacists | AN53: 505 | AQ53: Pharmacists | AR53: 0 | AT53: Pharmacists | AU53: 14
C54: Dentists | D54: 0 | G54: Dentists | H54: 0 | K54: Dentists | L54: 255 | O54: Dentists | P54: 658 | S54: Dentists | T54: 234 | W54: Dentists | X54: 0 | AA54: Dentists | AB54: 0 | AE54: Dentists | AF54: 32 | AI54: Dentists | AJ54: 0 | AM54: Dentists | AN54: 195 | AQ54: Dentists | AR54: 0 | AT54: Dentists | AU54: 0
C55: Community Health Workers | D55: 0 | G55: Community Health Workers | H55: 0 | K55: Community Health Workers | L55: 0 | O55: Community Health Workers | P55: 0 | S55: Community Health Workers | T55: 0 | W55: Community Health Workers | X55: 0 | AA55: Community Health Workers | AB55: 0 | AE55: Community Health Workers | AF55: 0 | AI55: Community Health Workers | AJ55: 0 | AM55: Community Health Workers | AN55: 21 | AQ55: Community Health Workers | AR55: 21 | AT55: Community health workers | AU55: 0
C56: Dieticians and nutritionists | D56: 0 | G56: Dieticians and nutritionists | H56: 0 | K56: Dieticians and nutritionists | L56: 0 | O56: Dieticians and nutritionists | P56: 0 | S56: Dieticians and nutritionists | T56: 0 | W56: Dieticians and nutritionists | X56: 0 | AA56: Dieticians and nutritionists | AB56: 8 | AE56: Dieticians and nutritionists | AF56: 0 | AI56: Dieticians and nutritionists | AJ56: 0 | AM56: Dieticians and nutritionists | AN56: 21 | AQ56: Dieticians and nutritionists | AR56: 0 | AT56: Dieticians and nutritionists | AU56: 0
C57: Environmental and occupational health & hygiene workers | D57: 0 | G57: Environmental and occupational health & hygiene workers | H57: 0 | K57: Environmental and occupational health & hygiene workers | L57: 0 | O57: Environmental and occupational health & hygiene workers | P57: 3830 | S57: Environmental and occupational health & hygiene workers | T57: 0 | W57: Environmental and occupational health & hygiene workers | X57: 0 | AA57: Environmental and occupational health & hygiene workers | AB57: 429 | AE57: Environmental and occupational health & hygiene workers | AF57: 0 | AI57: Environmental and occupational health & hygiene workers | AJ57: 0 | AM57: Environmental and occupational health & hygiene workers | AN57: 1570 | AQ57: Environmental and occupational health & hygiene workers | AR57: 0 | AT57: Environmental and occupational health & hygiene workers | AU57: 619
C58: Personal care workers in health service | D58: 0 | G58: Personal care workers in health service | H58: 0 | K58: Personal care workers in health service | L58: 0 | O58: Personal care workers in health service | P58: 0 | S58: Personal care workers in health service | T58: 0 | W58: Personal care workers in health service | X58: 0 | AA58: Personal care workers in health service | AB58: 0 | AE58: Personal care workers in health service | AF58: 0 | AI58: Personal care workers in health service | AJ58: 0 | AM58: Personal care workers in health service | AN58: 6809 | AQ58: Personal care workers in health service | AR58: 0 | AT58: Health care assistants and other personal care workers in health services | AU58: 2623
C59: Managerial staff | D59: 0 | G59: Managerial staff | H59: 0 | K59: Managerial staff | L59: 0 | O59: Managerial staff | P59: 0 | S59: Managerial staff | T59: 0 | W59: Managerial staff | X59: 0 | AA59: Managerial staff | AB59: 0 | AE59: Managerial staff | AF59: 0 | AI59: Managerial staff | AJ59: 0 | AM59: Managerial staff | AN59: 0 | AQ59: Managerial staff | AR59: 0 | AT59: Health service managers | AU59: 0
C60: Medical and dental Prosthetic Technicians | D60: 0 | G60: Medical and dental Prosthetic Technicians | H60: 0 | K60: Medical and dental Prosthetic Technicians | L60: 0 | O60: Medical and dental Prosthetic Technicians | P60: 0 | S60: Medical and dental Prosthetic Technicians | T60: 0 | W60: Medical and dental Prosthetic Technicians | X60: 15 | AA60: Medical and dental Prosthetic Technicians | AB60: 0 | AE60: Medical and dental Prosthetic Technicians | AF60: 0 | AI60: Medical and dental Prosthetic Technicians | AJ60: 0 | AM60: Medical and dental Prosthetic Technicians | AN60: 0 | AQ60: Medical and dental Prosthetic Technicians | AR60: 0 | AT60: Medical and dental prosthetic technicians | AU60: 0
...

Sheet 2012
A1: Row Labels | B1: AGO | C1: BDI | D1: BEN | E1: BFA | F1: BWA | G1: CAF | H1: CIV | I1: CMR | J1: COD | K1: COG | L1: COM | M1: CPV | N1: DZA | O1: ERI | P1: ETH | Q1: GAB | R1: GHA | S1: GIN | T1: GMB | U1: GNB | V1: GNQ | W1: KEN | X1: LBR | Y1: LSO | Z1: MDG | AA1: MLI | AB1: MOZ | AC1: MRT | AD1: MUS | AE1: MWI | AF1: NAM | AG1: NER | AH1: NGA | AI1: RWA | AJ1: SEN | AK1: SLE | AL1: SSD | AM1: STP | AN1: SWZ | AO1: SYC | AP1: TCD | AQ1: TGO | AR1: TZA | AS1: UGA | AT1: ZAF | AU1: ZMB | AV1: ZWE | AW1: Grand Total
A2: Population UN 1 | B2: 25188292 | C2: 9795479 | D2: 10014078 | E2: 17113732 | F2: 2175425.5 | G2: 4773305.5 | H2: 22010711 | I2: 21032684 | J2: 70997870 | K2: 4713256.5 | L2: 684552.5 | M2: 533864 | N2: 37260563 | O2: 3252596 | P2: 94451280 | Q2: 1836705 | R2: 26858762 | S2: 10788692 | T2: 2061014 | U2: 1652717.5 | V2: 1193635.5 | W2: 43725807 | X2: 4331740.5 | Y2: 2054718 | Z2: 22966240 | AA2: 16514687 | AB2: 24487611 | AC2: 3636113.5 | AD2: 1288744.5 | AE2: 15581250 | AF2: 2167470 | AG2: 17954407 | AH2: 1.7007593e+08 | AI2: 10840334 | AJ2: 13231833 | AK2: 6788587.5 | AL2: 10701605 | AM2: 189924.5 | AN2: 1111444 | AO2: 95309 | AP2: 12754906 | AQ2: 6926634.5 | AR2: 47786137 | AS2: 34273295 | AT2: 53145033 | AU2: 14744658 | AV2: 13265331 | AW2: 9.1902897e+08
A3: Medical Doctors | B3: 0 | C3: 996 | D3: 26 | E3: 1574 | F3: 1638 | G3: 0 | H3: 0 | I3: 0 | J3: 0 | K3: 0 | L3: 246 | M3: 520 | N3: 0 | O3: 389 | P3: 0 | Q3: 0 | R3: 4972 | S3: 0 | T3: 0 | U3: 0 | V3: 0 | W3: 16184 | X3: 0 | Y3: 0 | Z3: 6376 | AA3: 3525 | AB3: 2716 | AC3: 0 | AD3: 3444 | AE3: 0 | AF3: 0 | AG3: 1904 | AH3: 144 | AI3: 0 | AJ3: 0 | AK3: 8 | AL3: 0 | AM3: 0 | AN3: 0 | AO3: 186 | AP3: 1056 | AQ3: 49 | AR3: 2962 | AS3: 6740 | AT3: 0 | AU3: 156 | AV3: 2118 | AW3: 57929
A4: Nursing Personnel | B4: 0 | C4: 12972 | D4: 10276 | E4: 12016 | F4: 11632 | G4: 0 | H4: 0 | I4: 0 | J4: 0 | K4: 0 | L4: 0 | M4: 1102 | N4: 0 | O4: 0 | P4: 0 | Q4: 0 | R4: 0 | S4: 0 | T4: 4772 | U4: 0 | V4: 0 | W4: 123538 | X4: 0 | Y4: 0 | Z4: 6766 | AA4: 8514 | AB4: 11652 | AC4: 0 | AD4: 7474 | AE4: 0 | AF4: 0 | AG4: 0 | AH4: 0 | AI4: 0 | AJ4: 0 | AK4: 0 | AL4: 0 | AM4: 0 | AN4: 0 | AO4: 838 | AP4: 6282 | AQ4: 0 | AR4: 41600 | AS4: 81632 | AT4: 117444 | AU4: 0 | AV4: 31072 | AW4: 489582
A5: Midwifery personnel | B5: 0 | C5: 32 | D5: 2960 | E5: 8902 | F5: 0 | G5: 0 | H5: 0 | I5: 0 | J5: 0 | K5: 0 | L5: 1334 | M5: 0 | N5: 0 | O5: 0 | P5: 0 | Q5: 0 | R5: 0 | S5: 0 | T5: 0 | U5: 0 | V5: 0 | W5: 0 | X5: 0 | Y5: 0 | Z5: 2950 | AA5: 3540 | AB5: 8522 | AC5: 0 | AD5: 0 | AE5: 0 | AF5: 0 | AG5: 1788 | AH5: 0 | AI5: 0 | AJ5: 0 | AK5: 0 | AL5: 0 | AM5: 0 | AN5: 0 | AO5: 0 | AP5: 832 | AQ5: 0 | AR5: 0 | AS5: 0 | AT5: 0 | AU5: 0 | AV5: 0 | AW5: 30860
A6: Pharmacists | B6: 751 | C6: 546 | D6: 0 | E6: 785 | F6: 37 | G6: 1603 | H6: 0 | I6: 0 | J6: 409 | K6: 704 | L6: 0 | M6: 377 | N6: 391 | O6: 0 | P6: 328 | Q6: 0 | R6: 451 | S6: 0 | T6: 886 | U6: 0 | V6: 918 | W6: 531 | X6: 0 | Y6: 0 | Z6: 0 | AA6: 4 | AB6: 20 | AC6: 3445 | AD6: 0 | AE6: 4 | AF6: 0 | AG6: 0 | AH6: 0 | AI6: 0 | AJ6: 0 | AK6: 0 | AL6: 0 | AM6: 0 | AN6: 3320 | AO6: 0 | AP6: 19687 | AQ6: 4 | AR6: 20962 | AS6: 72 | AT6: 0 | AU6: 0 | AV6: 51 | AW6: 56286
A7: Dentists | B7: 353 | C7: 115 | D7: 0 | E7: 39 | F7: 6 | G7: 171 | H7: 1764 | I7: 0 | J7: 287 | K7: 278 | L7: 0 | M7: 147 | N7: 224 | O7: 0 | P7: 19 | Q7: 0 | R7: 186 | S7: 0 | T7: 228 | U7: 0 | V7: 713 | W7: 401 | X7: 0 | Y7: 0 | Z7: 0 | AA7: 0 | AB7: 0 | AC7: 695 | AD7: 0 | AE7: 4 | AF7: 0 | AG7: 0 | AH7: 0 | AI7: 0 | AJ7: 0 | AK7: 0 | AL7: 68 | AM7: 84 | AN7: 768 | AO7: 0 | AP7: 15483 | AQ7: 0 | AR7: 9658 | AS7: 0 | AT7: 0 | AU7: 0 | AV7: 30 | AW7: 31721
A8: Community Health Workers | E8: 2099 | F8: 166 | AB8: 1213 | AW8: 3478
A9: Dieticians and nutritionists | B9: 85 | C9: 44 | D9: 0 | E9: 128 | F9: 0 | G9: 15 | H9: 0 | I9: 0 | J9: 19 | K9: 819 | L9: 0 | M9: 130 | N9: 20 | O9: 0 | P9: 50 | Q9: 0 | R9: 0 | S9: 0 | T9: 0 | U9: 0 | V9: 0 | W9: 0 | X9: 0 | Y9: 0 | Z9: 0 | AA9: 0 | AB9: 0 | AC9: 1172 | AD9: 0 | AE9: 0 | AF9: 0 | AG9: 0 | AH9: 0 | AI9: 0 | AJ9: 0 | AK9: 0 | AL9: 0 | AM9: 0 | AN9: 0 | AO9: 0 | AP9: 406 | AQ9: 0 | AR9: 0 | AS9: 0 | AT9: 0 | AU9: 0 | AV9: 0 | AW9: 2888
A10: Environmental and occupational health & hygiene workers | B10: 517 | C10: 0 | D10: 0 | E10: 1791 | F10: 0 | G10: 11 | H10: 0 | I10: 0 | J10: 634 | K10: 4104 | L10: 0 | M10: 121 | N10: 199 | O10: 0 | P10: 461 | Q10: 0 | R10: 0 | S10: 0 | T10: 0 | U10: 0 | V10: 0 | W10: 0 | X10: 0 | Y10: 0 | Z10: 0 | AA10: 0 | AB10: 85 | AC10: 0 | AD10: 0 | AE10: 0 | AF10: 0 | AG10: 0 | AH10: 0 | AI10: 0 | AJ10: 0 | AK10: 0 | AL10: 0 | AM10: 0 | AN10: 4646 | AO10: 0 | AP10: 1258 | AQ10: 0 | AR10: 3255 | AS10: 0 | AT10: 0 | AU10: 0 | AV10: 0 | AW10: 17082
A11: Personal care workers in health service | B11: 0 | C11: 0 | D11: 0 | E11: 0 | F11: 0 | G11: 0 | H11: 0 | I11: 0 | J11: 0 | K11: 0 | L11: 0 | M11: 0 | N11: 0 | O11: 0 | P11: 0 | Q11: 0 | R11: 0 | S11: 0 | T11: 0 | U11: 0 | V11: 0 | W11: 0 | X11: 0 | Y11: 0 | Z11: 0 | AA11: 0 | AB11: 0 | AC11: 0 | AD11: 0 | AE11: 0 | AF11: 0 | AG11: 0 | AH11: 0 | AI11: 0 | AJ11: 0 | AK11: 0 | AL11: 0 | AM11: 0 | AN11: 0 | AO11: 0 | AP11: 0 | AQ11: 0 | AR11: 0 | AS11: 0 | AT11: 0 | AU11: 0 | AV11: 0 | AW11: 0
A12: Managerial staff
A13: Medical and dental Prosthetic Technicians | B13: 0 | C13: 0 | D13: 0 | E13: 0 | F13: 0 | G13: 0 | H13: 0 | I13: 0 | J13: 0 | K13: 0 | L13: 0 | M13: 0 | N13: 0 | O13: 0 | P13: 0 | Q13: 0 | R13: 0 | S13: 0 | T13: 0 | U13: 0 | V13: 0 | W13: 0 | X13: 0 | Y13: 0 | Z13: 0 | AA13: 0 | AB13: 33 | AC13: 0 | AD13: 0 | AE13: 0 | AF13: 0 | AG13: 0 | AH13: 0 | AI13: 0 | AJ13: 0 | AK13: 0 | AL13: 0 | AM13: 0 | AN13: 0 | AO13: 0 | AP13: 0 | AQ13: 0 | AR13: 60 | AS13: 0 | AT13: 0 | AU13: 53 | AV13: 27 | AW13: 173
A14: Medical and Pathology Laboratory scientists | AR14: 89 | AT14: 133 | AU14: 184 | AV14: 352 | AW14: 758
A15: Medical Assistants
A16: Medical Imaging and Therapeutic Equipment Technicians | D16: 241 | E16: 109 | AB16: 267 | AR16: 223 | AT16: 8095 | AU16: 500 | AV16: 233 | AW16: 9668
A17: Medical Records and Health Information Technicians | AR17: 470 | AW17: 470
A18: Optometrists and Ophthalmic Opticians | AB18: 76 | AR18: 82 | AT18: 3453 | AU18: 18 | AW18: 3629
A19: Other non-medical professional staff
A20: Other non-medical support staff
A21: Medical and Pathology Laboratory Technicians | D21: 845 | E21: 458 | L21: 86 | AB21: 1425 | AR21: 1997 | AT21: 171 | AU21: 1126 | AW21: 6108
A22: Paramedical Practitioners | AR22: 8787 | AT22: 90 | AU22: 3141 | AW22: 12018
A23: Physiotherapists and physiotherapy assistants | B23: 0 | C23: 0 | D23: 0 | E23: 0 | F23: 0 | G23: 0 | H23: 0 | I23: 0 | J23: 0 | K23: 0 | L23: 0 | M23: 0 | N23: 0 | O23: 0 | P23: 0 | Q23: 0 | R23: 0 | S23: 0 | T23: 0 | U23: 0 | V23: 0 | W23: 0 | X23: 0 | Y23: 0 | Z23: 0 | AA23: 0 | AB23: 281 | AC23: 0 | AD23: 0 | AE23: 0 | AF23: 0 | AG23: 0 | AH23: 0 | AI23: 0 | AJ23: 0 | AK23: 0 | AL23: 0 | AM23: 0 | AN23: 0 | AO23: 0 | AP23: 0 | AQ23: 0 | AR23: 130 | AS23: 0 | AT23: 7791 | AU23: 485 | AV23: 377 | AW23: 9064
A24: Social workers | B24: 0 | C24: 0 | D24: 0 | E24: 0 | F24: 0 | G24: 0 | H24: 0 | I24: 0 | J24: 0 | K24: 0 | L24: 0 | M24: 0 | N24: 0 | O24: 0 | P24: 0 | Q24: 0 | R24: 0 | S24: 0 | T24: 127 | U24: 0 | V24: 0 | W24: 0 | X24: 0 | Y24: 0 | Z24: 0 | AA24: 0 | AB24: 0 | AC24: 0 | AD24: 0 | AE24: 0 | AF24: 0 | AG24: 0 | AH24: 0 | AI24: 0 | AJ24: 0 | AK24: 0 | AL24: 0 | AM24: 0 | AN24: 0 | AO24: 0 | AP24: 0 | AQ24: 0 | AR24: 0 | AS24: 6046 | AT24: 0 | AU24: 0 | AV24: 0 | AW24: 6173
A25: Audiologists and Speech Therapists | AT25: 2285 | AW25: 2285
A26: Traditional and complementary medicine practitioners | B26: 0 | C26: 0 | D26: 0 | E26: 0 | F26: 0 | G26: 0 | H26: 0 | I26: 0 | J26: 0 | K26: 0 | L26: 0 | M26: 0 | N26: 0 | O26: 0 | P26: 0 | Q26: 0 | R26: 0 | S26: 0 | T26: 656 | U26: 0 | V26: 0 | W26: 0 | X26: 0 | Y26: 0 | Z26: 0 | AA26: 0 | AB26: 0 | AC26: 0 | AD26: 0 | AE26: 0 | AF26: 0 | AG26: 0 | AH26: 0 | AI26: 0 | AJ26: 0 | AK26: 0 | AL26: 0 | AM26: 0 | AN26: 0 | AO26: 0 | AP26: 0 | AQ26: 0 | AR26: 0 | AS26: 19791 | AT26: 0 | AU26: 0 | AV26: 0 | AW26: 20447
B29: Country | C29: Pop 2012 | D29: Cadre | E29: 2012
B30: =B1 -> AGO | C30: =B2 -> 25188292 | D30: =A3 -> Medical Doctors | E30: =B3 -> 0
D31: =A4 -> Nursing Personnel | E31: =B4 -> 0
D32: =A5 -> Midwifery personnel | E32: =B5 -> 0
D33: =A6 -> Pharmacists | E33: =B6 -> 751
D34: =A7 -> Dentists | E34: =B7 -> 353
D35: =A8 -> Community Health Workers | E35: =B8 -> 0
D36: =A9 -> Dieticians and nutritionists | E36: =B9 -> 85
D37: =A10 -> Environmental and occupational health & hygiene workers | E37: =B10 -> 517
D38: =A11 -> Personal care workers in health service | E38: =B11 -> 0
D39: =A12 -> Managerial staff | E39: =B12 -> 0
D40: =A13 -> Medical and dental Prosthetic Technicians | E40: =B13 -> 0
D41: =A14 -> Medical and Pathology Laboratory scientists | E41: =B14 -> 0
D42: =A15 -> Medical Assistants | E42: =B15 -> 0
...

Sheet 2013
A1: Row Labels | B1: AGO | C1: BDI | D1: BEN | E1: BFA | F1: BWA | G1: CAF | H1: CIV | I1: CMR | J1: COD | K1: COG | L1: COM | M1: CPV | N1: DZA | O1: ERI | P1: ETH | Q1: GAB | R1: GHA | S1: GIN | T1: GMB | U1: GNB | V1: GNQ | W1: KEN | X1: LBR | Y1: LSO | Z1: MDG | AA1: MLI | AB1: MOZ | AC1: MRT | AD1: MUS | AE1: MWI | AF1: NAM | AG1: NER | AH1: NGA | AI1: RWA | AJ1: SEN | AK1: SLE | AL1: SSD | AM1: STP | AN1: SWZ | AO1: SYC | AP1: TCD | AQ1: TGO | AR1: TZA | AS1: UGA | AT1: ZAF | AU1: ZMB | AV1: ZWE | AW1: Grand Total
A2: Population UN 1 | B2: 26147002 | C2: 10149578 | D2: 10308730 | E2: 17636408 | F2: 2217278 | G2: 4802428.5 | H2: 22469268 | I2: 21632850 | J2: 73460021 | K2: 4828066.5 | L2: 699392.5 | M2: 539940 | N2: 38000627 | O2: 3296367 | P2: 97084366 | Q2: 1902226.5 | R2: 27525597 | S2: 11055430 | T2: 2124869.5 | U2: 1697752.5 | V2: 1243941 | W2: 44792368 | X2: 4427312.5 | Y2: 2073938.5 | Z2: 23588074 | AA2: 17004032 | AB2: 25251731 | AC2: 3742959 | AD2: 1290691.5 | AE2: 16024775 | AF2: 2204510 | AG2: 18653199 | AH2: 1.7472612e+08 | AI2: 11101349 | AJ2: 13595565 | AK2: 6964858.5 | AL2: 11106031 | AM2: 193757 | AN2: 1118319 | AO2: 96714 | AP2: 13216766 | AQ2: 7106229 | AR2: 49253644 | AS2: 35273570 | AT2: 53873616 | AU2: 15234976 | AV2: 13555422 | AW2: 944292669
A3: Medical Doctors | B3: 0 | C3: 1108 | D3: 0 | E3: 1606 | F3: 0 | G3: 0 | H3: 0 | I3: 0 | J3: 12836 | K3: 0 | L3: 0 | M3: 616 | N3: 4628 | O3: 427 | P3: 0 | Q3: 0 | R3: 5460 | S3: 0 | T3: 0 | U3: 0 | V3: 0 | W3: 17493 | X3: 0 | Y3: 0 | Z3: 7046 | AA3: 4063 | AB3: 2904 | AC3: 0 | AD3: 4092 | AE3: 400 | AF3: 113 | AG3: 1892 | AH3: 131518 | AI3: 2208 | AJ3: 42 | AK3: 0 | AL3: 32 | AM3: 0 | AN3: 0 | AO3: 0 | AP3: 1146 | AQ3: 53 | AR3: 0 | AS3: 0 | AT3: 0 | AU3: 0 | AV3: 2228 | AW3: 201911
