Workbook

Sheet Midwives
A1: periodcode | B1: 2022
A3: Sum of NHWA_Midwifery personnel Stock By Sex Male | B3: Sum of NHWA_Midwifery personnel Stock By Sex Female
A4: 11846 | B4: 181387 | C4: =GETPIVOTDATA("Sum of NHWA_Midwifery personnel Stock By Sex Male",$A$3)+GETPIVOTDATA("Sum of NHWA_Midwifery personnel Stock By Sex Female",$A$3) -> 193233
A6: =GETPIVOTDATA("Sum of NHWA_Midwifery personnel Stock By Sex Male",$A$3)/C4 -> 0.061304229 | B6: =1-A6 -> 0.93869577

Sheet Doctors
A1: periodcode | B1: 2022
A3: Sum of NHWA_Medical Doctors Stock By Sex Female | B3: Sum of NHWA_Medical Doctors Stock By Sex Male
A4: 41610 | B4: 77154 | C4: =GETPIVOTDATA("Sum of NHWA_Medical Doctors Stock By Sex Female",$A$3)+GETPIVOTDATA("Sum of NHWA_Medical Doctors Stock By Sex Male",$A$3) -> 118764
A6: =GETPIVOTDATA("Sum of NHWA_Medical Doctors Stock By Sex Female",$A$3)/C4 -> 0.35035869 | B6: =1-A6 -> 0.64964131

Sheet Nurses
A1: periodcode | B1: 2019
A3: Sum of NHWA_Nursing Personnel Stock By Sex Female | B3: Sum of NHWA_Nursing Personnel Stock By Sex Male
A4: 75396 | B4: 39282 | C4: =GETPIVOTDATA("Sum of NHWA_Nursing Personnel Stock By Sex Female",$A$3)+GETPIVOTDATA("Sum of NHWA_Nursing Personnel Stock By Sex Male",$A$3) -> 114678
A6: =GETPIVOTDATA("Sum of NHWA_Nursing Personnel Stock By Sex Female",$A$3)/C4 -> 0.65745827 | B6: =1-A6 -> 0.34254173

Sheet Dentists
A1: periodcode | B1: 2022
A3: Sum of NHWA_Dentists Stock By Sex Female | B3: Sum of NHWA_Dentists Stock By Sex Male
A4: 3006 | B4: 5002 | C4: =GETPIVOTDATA("Sum of NHWA_Dentists Stock By Sex Female",$A$3)+GETPIVOTDATA("Sum of NHWA_Dentists Stock By Sex Male",$A$3) -> 8008
A7: =GETPIVOTDATA("Sum of NHWA_Dentists Stock By Sex Female",$A$3)/C4 -> 0.37537463 | B7: =1-A7 -> 0.62462537

Sheet Pharmacists
A1: periodcode | B1: 2022
A3: Sum of NHWA_Pharmacists Stock By Sex Female | B3: Sum of NHWA_Pharmacists Stock By Sex Male
A4: 11189 | B4: 15922 | C4: =GETPIVOTDATA("Sum of NHWA_Pharmacists Stock By Sex Female",$A$3)+GETPIVOTDATA("Sum of NHWA_Pharmacists Stock By Sex Male",$A$3) -> 27111
A6: =GETPIVOTDATA("Sum of NHWA_Pharmacists Stock By Sex Female",$A$3)/C4 -> 0.41271071 | B6: =1-A6 -> 0.58728929

Sheet Community workers
A1: periodcode | B1: 2022
A3: Sum of NHWA_Community Health Workers Stock By Sex Female | B3: Sum of NHWA_Community Health Workers Stock By Sex Male
A4: 93844 | B4: 25351 | C4: =GETPIVOTDATA("Sum of NHWA_Community Health Workers Stock By Sex Female",$A$3)+GETPIVOTDATA("Sum of NHWA_Community Health Workers Stock By Sex Male",$A$3) -> 119195
A7: =GETPIVOTDATA("Sum of NHWA_Community Health Workers Stock By Sex Female",$A$3)/C4 -> 0.7873149 | B7: =1-A7 -> 0.2126851

Sheet Sheet7
A1: periodcode | B1: (All)
A3: Row Labels | B3: Sum of NHWA_Medical Doctors Stock By Sex Male | C3: Sum of NHWA_Community Health Workers Stock By Sex Female | D3: Sum of NHWA_Community Health Workers Stock By Sex Male | E3: Sum of NHWA_Medical Doctors Stock By Sex Female | F3: Sum of NHWA_Nursing Personnel Stock By Sex Female | G3: Sum of NHWA_Nursing Personnel Stock By Sex Male | H3: Sum of NHWA_Generalist Medical Practitioners (incl. Family medical practitioners) Stock By Sex Female | I3: Sum of NHWA_Generalist Medical Practitioners (incl. Family medical practitioners) Stock By Sex Male | J3: Sum of NHWA_Medical group of Specialists Practitioners Stock By Sex Female | K3: Sum of NHWA_Medical group of Specialists Practitioners Stock By Sex Male | L3: Sum of NHWA_Medical doctors not further defined Stock By Sex Female | M3: Sum of NHWA_Medical doctors not further defined Stock By Sex Male | N3: Sum of NHWA_Nursing Professionals Stock By Sex Female | O3: Sum of NHWA_Nursing Professionals Stock By Sex Male | P3: Sum of NHWA_Nursing Associate Professionals Stock By Sex Female | Q3: Sum of NHWA_Nursing Associate Professionals Stock By Sex Male | R3: Sum of NHWA_Nurses not further defined Stock By Sex Female | S3: Sum of NHWA_Nurses not further defined Stock By Sex Male | T3: Sum of NHWA_Midwifery personnel Stock By Sex Female | U3: Sum of NHWA_Midwifery personnel Stock By Sex Male | V3: Sum of NHWA_Midwifery Professionals Stock By Sex Female | W3: Sum of NHWA_Midwifery Professionals Stock By Sex Male | X3: Sum of NHWA_Midwifery Associate Professionals Stock By Sex Female | Y3: Sum of NHWA_Midwifery Associate Professionals Stock By Sex Male | Z3: Sum of NHWA_Midwives not further defined Stock By Sex Female | AA3: Sum of NHWA_Midwives not further defined Stock By Sex Male | AB3: Sum of NHWA_Dentists Stock By Sex Female | AC3: Sum of NHWA_Dentists Stock By Sex Male | AD3: Sum of NHWA_Pharmacists Stock By Sex Female | AE3: Sum of NHWA_Pharmacists Stock By Sex Male | AF3: Sum of NHWA_Nursing Professionals Stock with additional midwifery training By Sex Female | AG3: Sum of NHWA_Nursing Professionals Stock with additional midwifery training By Sex Male | AH3: Sum of NHWA_Nursing Associate Professionals Stock with additional midwifery training By Sex Female
A4: BDI | B4: 472 | C4: 5923 | D4: 5922 | E4: 157 | F4: 4498 | G4: 3020 | H4: 157 | I4: 472 | N4: 4498 | O4: 3020 | T4: 55 | U4: 69 | V4: 55 | W4: 69
A5: BEN | B5: 2429 | C5: 14 | D5: 7 | E5: 1234 | F5: 4357 | G5: 4537 | H5: 619 | I5: 1524 | J5: 4 | K5: 9 | N5: 4357 | O5: 4537 | T5: 3141 | U5: 0 | V5: 3141 | W5: 0 | AB5: 35 | AC5: 27 | AD5: 355 | AE5: 354
A6: BFA | B6: 5651 | C6: 6130 | D6: 5864 | E6: 2923 | F6: 11302 | G6: 18001 | H6: 2076 | I6: 3630 | J6: 180 | K6: 513 | N6: 8849 | O6: 15429 | P6: 2453 | Q6: 2572 | T6: 22196 | U6: 4124 | V6: 15796 | W6: 4124 | X6: 6400 | Y6: 0 | AB6: 86 | AC6: 215 | AD6: 484 | AE6: 729 | AF6: 0 | AG6: 0 | AH6: 0
A7: BWA | B7: 2998 | E7: 1878 | F7: 27168 | G7: 11925 | H7: 1725 | I7: 2596 | N7: 27168 | O7: 11925 | AB7: 246 | AC7: 202 | AD7: 412 | AE7: 310
A8: CIV | B8: 3453 | E8: 1477 | F8: 12486 | G8: 17656 | H8: 1322 | I8: 3090 | N8: 9429 | O8: 17073 | P8: 3037 | Q8: 558 | R8: 20 | S8: 25 | T8: 7425 | U8: 0 | V8: 7421 | W8: 0 | X8: 4 | Y8: 0 | AB8: 146 | AC8: 272 | AD8: 469 | AE8: 693
A9: CMR | B9: 6587 | C9: 312 | D9: 152 | E9: 5678 | F9: 21239 | G9: 11255 | H9: 3165 | I9: 3422 | J9: 512 | K9: 629 | L9: 1167 | M9: 1403 | N9: 15496 | O9: 8349 | P9: 4332 | Q9: 1838 | R9: 1411 | S9: 1068 | T9: 3166 | U9: 470 | V9: 2902 | W9: 378 | X9: 226 | Y9: 90 | Z9: 38 | AA9: 2 | AB9: 371 | AC9: 270 | AD9: 675 | AE9: 528 | AF9: 284 | AG9: 137 | AH9: 183
A10: COD | F10: 17062 | G10: 34316 | N10: 12553 | O10: 24427 | P10: 4509 | Q10: 9889
A11: COG | B11: 405 | E11: 637 | F11: 1278 | G11: 4295 | H11: 470 | I11: 317 | J11: 116 | K11: 53 | N11: 1278 | O11: 4295 | T11: 895 | U11: 12 | V11: 895 | W11: 12 | AB11: 7 | AC11: 2 | AD11: 17 | AE11: 11
A12: CPV | B12: 827 | C12: 62 | D12: 93 | E12: 1815 | F12: 1258 | G12: 330 | H12: 132 | I12: 55 | J12: 58 | K12: 42 | L12: 1622 | M12: 725 | N12: 679 | O12: 167 | P12: 73 | Q12: 22 | R12: 506 | S12: 141 | AB12: 6 | AC12: 4 | AD12: 16 | AE12: 7
A13: DZA | B13: 28634 | E13: 43970 | F13: 34643 | G13: 21768 | H13: 20406 | I13: 12368 | J13: 12843 | K13: 6972 | N13: 29831 | O13: 15342 | P13: 4812 | Q13: 6426 | T13: 8903 | U13: 45 | V13: 8701 | W13: 38 | X13: 202 | Y13: 7 | AB13: 9405 | AC13: 6032 | AD13: 10953 | AE13: 7854
A14: ERI | B14: 190 | C14: 1915 | D14: 711 | E14: 70 | F14: 5885 | G14: 4063 | H14: 70 | I14: 190 | J14: 0 | K14: 19 | N14: 1638 | O14: 1836 | P14: 4188 | Q14: 2098 | R14: 59 | S14: 129 | T14: 20 | U14: 47 | V14: 20 | W14: 47 | AB14: 23 | AC14: 35 | AD14: 78 | AE14: 121
A15: ETH | B15: 19931 | C15: 121188 | D15: 2418 | E15: 5360 | F15: 65093 | G15: 74977 | H15: 4059 | I15: 13952 | N15: 65093 | O15: 74977 | T15: 27493 | U15: 14855 | V15: 27493 | W15: 14855 | AB15: 114 | AC15: 267 | AD15: 12760 | AE15: 19829
A16: GAB | B16: 2038 | C16: 169 | D16: 58 | E16: 1831 | F16: 9936 | G16: 4479 | H16: 821 | I16: 833 | J16: 187 | K16: 177 | L16: 2 | M16: 0 | N16: 6264 | O16: 2819 | P16: 3630 | Q16: 1614 | R16: 42 | S16: 46 | T16: 2178 | U16: 11 | V16: 2136 | W16: 0 | X16: 32 | Y16: 11 | Z16: 10 | AA16: 0 | AB16: 38 | AC16: 74 | AD16: 245 | AE16: 202 | AF16: 440 | AG16: 496 | AH16: 9
A17: GHA | B17: 7427 | E17: 4336 | F17: 243968 | G17: 89726 | H17: 3166 | I17: 5059 | N17: 97038 | O17: 48056 | P17: 146930 | Q17: 41670 | T17: 54319 | U17: 811 | V17: 54319 | W17: 811 | AD17: 911 | AE17: 1261
A18: GNB | B18: 824 | C18: 1049 | D18: 6039 | E18: 427 | F18: 4168 | G18: 2056 | H18: 423 | I18: 799 | J18: 0 | K18: 0 | L18: 0 | M18: 0 | N18: 2201 | O18: 1138 | P18: 1957 | Q18: 910 | R18: 10 | S18: 8 | T18: 595 | U18: 0 | V18: 257 | W18: 0 | X18: 338 | Y18: 0 | Z18: 0 | AA18: 0 | AB18: 11 | AC18: 15 | AD18: 8 | AE18: 9 | AF18: 25 | AG18: 15 | AH18: 0
A19: KEN | B19: 8837 | C19: 1572 | D19: 1299 | E19: 6414 | F19: 145085 | G19: 56588 | H19: 4426 | I19: 5795 | J19: 405 | K19: 642 | L19: 0 | M19: 0 | N19: 117323 | O19: 48300 | P19: 27762 | Q19: 8288 | T19: 94 | U19: 43 | V19: 94 | W19: 43 | AB19: 465 | AC19: 534 | AD19: 817 | AE19: 1129 | AF19: 0 | AG19: 0
A20: LBR | C20: 5547 | D20: 6811 | F20: 1734 | G20: 830 | R20: 1734 | S20: 830
A21: MDG | C21: 29131 | D21: 12485 | F21: 1423 | G21: 2037 | N21: 1423 | O21: 2037 | T21: 3994 | U21: 0 | V21: 3994 | W21: 0
A22: MLI | B22: 2234 | C22: 991 | D22: 2312 | E22: 283 | F22: 2233 | G22: 2941 | H22: 165 | I22: 1162 | N22: 2233 | O22: 2941 | T22: 1666 | U22: 0 | V22: 1666 | W22: 0 | AD22: 617 | AE22: 664 | AF22: 1638
A23: MOZ | B23: 5381 | C23: 2290 | D23: 4342 | E23: 4938 | F23: 24337 | G23: 17813 | H23: 3523 | I23: 3418 | J23: 245 | K23: 236 | N23: 9666 | O23: 8559 | P23: 14671 | Q23: 9254 | T23: 19780 | U23: 0 | V23: 10980 | W23: 0 | X23: 8800 | Y23: 0 | AB23: 575 | AC23: 357 | AD23: 591 | AE23: 678
A24: MWI | B24: 1133 | C24: 4767 | D24: 5980 | E24: 860 | F24: 23035 | G24: 9161 | H24: 631 | I24: 851 | J24: 11 | K24: 21 | L24: 4 | M24: 8 | N24: 10195 | O24: 3000 | P24: 12610 | Q24: 6087 | R24: 230 | S24: 74 | T24: 580 | U24: 36 | V24: 0 | W24: 0 | X24: 0 | Y24: 0 | Z24: 580 | AA24: 36 | AB24: 85 | AC24: 152 | AD24: 82 | AE24: 180 | AF24: 1168 | AG24: 311 | AH24: 2638
A25: NAM | AB25: 75 | AC25: 103 | AD25: 276 | AE25: 322
A26: NER | C26: 8786 | D26: 12643
A27: NGA | B27: 50528 | C27: 13577 | D27: 58 | E27: 48191 | F27: 358618 | G27: 60017 | H27: 48191 | I27: 50528 | N27: 358618 | O27: 60017 | AB27: 1300 | AC27: 1797
A28: RWA | C28: 36882 | D28: 21685
A29: SEN | B29: 3490 | C29: 12687 | D29: 7194 | E29: 2143 | F29: 12226 | G29: 6881 | H29: 584 | I29: 1268 | J29: 312 | K29: 498 | N29: 6190 | O29: 4360 | P29: 4685 | Q29: 2091 | R29: 1351 | S29: 430 | T29: 10126 | U29: 27 | V29: 9652 | W29: 18 | X29: 474 | Y29: 9 | AB29: 167 | AC29: 231 | AD29: 286 | AE29: 359 | AH29: 1056
A30: SLE | B30: 532 | C30: 12380 | D30: 1586 | E30: 44 | F30: 6066 | G30: 736 | H30: 28 | I30: 487 | N30: 1665 | O30: 245 | P30: 2291 | Q30: 256 | R30: 2110 | S30: 235 | T30: 611 | U30: 28 | V30: 522 | W30: 8 | X30: 89 | Y30: 20 | AB30: 5 | AC30: 10 | AD30: 41 | AE30: 152
A31: SSD | C31: 1828 | D31: 4680
A32: STP | F32: 296 | G32: 110 | R32: 296 | S32: 110
A33: SWZ | C33: 8519 | D33: 67 | F33: 7444 | G33: 2785 | N33: 5136 | O33: 2101 | P33: 1382 | Q33: 316 | R33: 926 | S33: 368 | T33: 1820 | U33: 645 | V33: 1820 | W33: 645 | AB33: 7 | AC33: 1
A34: SYC | B34: 185 | E34: 112 | F34: 1426 | G34: 148 | H34: 77 | I34: 105 | N34: 1426 | O34: 148 | P34: 0 | Q34: 0 | R34: 0 | S34: 0 | T34: 147 | U34: 3 | V34: 147 | W34: 3 | AB34: 19 | AC34: 25 | AF34: 314 | AG34: 2
A35: TCD | B35: 2821 | C35: 119 | D35: 485 | E35: 603 | F35: 2305 | G35: 4762 | H35: 603 | I35: 2821 | J35: 4 | K35: 170 | N35: 1833 | O35: 4139 | P35: 309 | Q35: 518 | R35: 163 | S35: 105 | T35: 2517 | U35: 160 | V35: 1863 | W35: 121 | X35: 98 | Y35: 6 | Z35: 556 | AA35: 33 | AB35: 11 | AC35: 29 | AD35: 62 | AE35: 222
A36: TGO | B36: 594 | C36: 1419 | D36: 5967 | E36: 136 | F36: 951 | G36: 3211 | H36: 59 | I36: 272 | N36: 367 | O36: 1332 | P36: 256 | Q36: 675 | R36: 328 | S36: 1204 | T36: 1864 | U36: 0 | V36: 1043 | W36: 0 | X36: 821 | Y36: 0 | AB36: 5 | AC36: 13 | AD36: 126 | AE36: 129
A37: UGA | B37: 5696 | E37: 2271 | F37: 104972 | G37: 38590 | H37: 1811 | I37: 4557 | J37: 115 | K37: 223 | P37: 15148 | Q37: 6277 | R37: 89824 | S37: 32313 | T37: 110270 | U37: 87 | X37: 86011 | Y37: 87 | Z37: 24259 | AA37: 0 | AD37: 526 | AE37: 1186
A38: ZMB | B38: 7217 | C38: 1129 | D38: 1292 | E38: 18616 | F38: 33830 | G38: 8086 | H38: 1695 | I38: 3013 | J38: 14 | K38: 87 | L38: 16792 | M38: 3799 | N38: 32952 | O38: 7926 | P38: 878 | Q38: 160 | R38: 0 | S38: 0 | T38: 7881 | U38: 1327 | V38: 7881 | W38: 1327 | AB38: 109 | AC38: 152 | AD38: 331 | AE38: 308 | AF38: 1807 | AG38: 327 | AH38: 925
A39: ZWE | B39: 4217 | C39: 24522 | D39: 11088 | E39: 1514 | F39: 45688 | G39: 14428 | H39: 988 | I39: 2906 | J39: 62 | K39: 147 | L39: 152 | M39: 392 | N39: 35768 | O39: 11296 | P39: 9920 | Q39: 3132 | T39: 2600 | U39: 196 | V39: 2600 | W39: 196 | AB39: 818 | AC39: 1989 | AD39: 1452 | AE39: 1847 | AF39: 5737 | AG39: 437 | AH39: 4780
A40: Grand Total | B40: 174731 | C40: 302908 | D40: 121238 | E40: 157918 | F40: 1236010 | G40: 531528 | H40: 101392 | I40: 125490 | J40: 15068 | K40: 10438 | L40: 19739 | M40: 6327 | N40: 871167 | O40: 389791 | P40: 265833 | Q40: 104651 | R40: 99010 | S40: 37086 | T40: 294336 | U40: 22996 | V40: 165398 | W40: 22695 | X40: 103495 | Y40: 230 | Z40: 25443 | AA40: 71 | AB40: 14129 | AC40: 12808 | AD40: 32590 | AE40: 39084 | AF40: 11413 | AG40: 1725 | AH40: 9591

Sheet Sheet9
A1: Row Labels | B1: Sum of NHWA_Medical Doctors Stock By Sex Male | C1: Sum of NHWA_Medical Doctors Stock By Sex Female | D1: Sum of NHWA_Community Health Workers Stock By Sex Female | E1: Sum of NHWA_Community Health Workers Stock By Sex Male | F1: Doctors | G1: Community health workers | H1: Sum of NHWA_Nursing Personnel Stock By Sex Female | I1: Sum of NHWA_Nursing Personnel Stock By Sex Male | J1: Nurses | K1: Doctors to Nurses
A2: 2018 | B2: 53363 | C2: 91466 | D2: 9533 | E2: 6355 | F2: =B2+C2 -> 144829 | G2: =D2+E2 -> 15888 | H2: 419219 | I2: 163955 | J2: =H2+I2 -> 583174
A3: 2019 | B3: 7332 | C3: 4296 | D3: 4367 | E3: 6498 | F3: =B3+C3 -> 11628 | G3: =D3+E3 -> 10865 | H3: 75396 | I3: 39282 | J3: =H3+I3 -> 114678
A4: 2020 | B4: 12433 | C4: 8400 | D4: 151949 | E4: 80651 | F4: =B4+C4 -> 20833 | G4: =D4+E4 -> 232600 | H4: 64278 | I4: 34718 | J4: =H4+I4 -> 98996
A5: 2021 | B5: 24449 | C5: 12146 | D5: 43215 | E5: 2383 | F5: =B5+C5 -> 36595 | G5: =D5+E5 -> 45598 | H5: 150573 | I5: 98003 | J5: =H5+I5 -> 248576
A6: 2022 | B6: 77154 | C6: 41610 | D6: 93844 | E6: 25351 | F6: =B6+C6 -> 118764 | G6: =D6+E6 -> 119195 | H6: 526544 | I6: 195570 | J6: =H6+I6 -> 722114
A7: Grand Total | B7: 174731 | C7: 157918 | D7: 302908 | E7: 121238 | F7: =B7+C7 -> 332649 | G7: =D7+E7 -> 424146 | H7: 1236010 | I7: 531528 | J7: =H7+I7 -> 1767538

Sheet aggregate
A1: Row Labels | B1: Sum of NHWA_Medical Doctors Stock By Sex Female | C1: Sum of NHWA_Medical Doctors Stock By Sex Male | D1: Sum of NHWA_Nursing Personnel Stock By Sex Female | E1: Sum of NHWA_Nursing Personnel Stock By Sex Male | F1: Sum of NHWA_Midwifery personnel Stock By Sex Female | G1: Sum of NHWA_Midwifery personnel Stock By Sex Male | H1: Sum of NHWA_Dentists Stock By Sex Female | I1: Sum of NHWA_Dentists Stock By Sex Male | J1: Sum of NHWA_Pharmacists Stock By Sex Female | K1: Sum of NHWA_Pharmacists Stock By Sex Male | L1: Sum of NHWA_Obstetricians and Gynaecologists Practitioners Stock By Sex Female | M1: Sum of NHWA_Obstetricians and Gynaecologists Practitioners Stock By Sex Male | N1: Sum of NHWA_General Paediatricians Practitioners Stock By Sex Female | O1: Sum of NHWA_General Paediatricians Practitioners Stock By Sex Male | P1: Sum of NHWA_Community Health Workers Stock By Sex Female | Q1: Sum of NHWA_Community Health Workers Stock By Sex Male | R1: Total Females | S1: Total Males | T1: total | U1: Female proportion | V1: Males proportions | W1: Year
A2: 2018 | B2: 91466 | C2: 53363 | D2: 419219 | E2: 163955 | F2: 15623 | G2: 45 | H2: 9575 | I2: 6252 | J2: 12745 | K2: 9800 | L2: 2445 | M2: 954 | N2: 2087 | O2: 1039 | P2: 9533 | Q2: 6355 | R2: =B2+D2+F2+H2+J2+L2+N2+P2 -> 562693 | S2: =C2+E2+G2+I2+K2+M2+O2+Q2 -> 241763 | T2: =R2+S2 -> 804456 | U2: =R2/T2 -> 0.6994702 | V2: =1-U2 -> 0.3005298 | W2: 2018
A3: 2019 | B3: 4296 | C3: 7332 | D3: 75396 | E3: 39282 | F3: 28930 | G3: 1357 | H3: 260 | I3: 202 | J3: 460 | K3: 516 | L3: 138 | M3: 239 | N3: 200 | O3: 153 | P3: 4367 | Q3: 6498 | R3: =B3+D3+F3+H3+J3+L3+N3+P3 -> 114047 | S3: =C3+E3+G3+I3+K3+M3+O3+Q3 -> 55579 | T3: =R3+S3 -> 169626 | U3: =R3/T3 -> 0.67234386 | V3: =1-U3 -> 0.32765614 | W3: 2019
A4: 2020 | B4: 8400 | C4: 12433 | D4: 64278 | E4: 34718 | F4: 18261 | G4: 1291 | H4: 626 | I4: 636 | J4: 1087 | K4: 1374 | L4: 322 | M4: 460 | N4: 358 | O4: 204 | P4: 151949 | Q4: 80651 | R4: =B4+D4+F4+H4+J4+L4+N4+P4 -> 245281 | S4: =C4+E4+G4+I4+K4+M4+O4+Q4 -> 131767 | T4: =R4+S4 -> 377048 | U4: =R4/T4 -> 0.65052991 | V4: =1-U4 -> 0.34947009 | W4: 2020
A5: 2021 | B5: 12146 | C5: 24449 | D5: 150573 | E5: 98003 | F5: 50135 | G5: 8457 | H5: 662 | I5: 716 | J5: 7109 | K5: 11472 | L5: 352 | M5: 554 | N5: 357 | O5: 296 | P5: 43215 | Q5: 2383 | R5: =B5+D5+F5+H5+J5+L5+N5+P5 -> 264549 | S5: =C5+E5+G5+I5+K5+M5+O5+Q5 -> 146330 | T5: =R5+S5 -> 410879 | U5: =R5/T5 -> 0.64386109 | V5: =1-U5 -> 0.35613891 | W5: 2021
A6: 2022 | B6: 41610 | C6: 77154 | D6: 526544 | E6: 195570 | F6: 181387 | G6: 11846 | H6: 3006 | I6: 5002 | J6: 11189 | K6: 15922 | L6: 619 | M6: 1326 | N6: 596 | O6: 914 | P6: 93844 | Q6: 25351 | R6: =B6+D6+F6+H6+J6+L6+N6+P6 -> 858795 | S6: =C6+E6+G6+I6+K6+M6+O6+Q6 -> 333085 | T6: =R6+S6 -> 1191880 | U6: =R6/T6 -> 0.72053814 | V6: =1-U6 -> 0.27946186 | W6: 2022
A7: Grand Total | B7: 157918 | C7: 174731 | D7: 1236010 | E7: 531528 | F7: 294336 | G7: 22996 | H7: 14129 | I7: 12808 | J7: 32590 | K7: 39084 | L7: 3876 | M7: 3533 | N7: 3598 | O7: 2606 | P7: 302908 | Q7: 121238 | R7: =B7+D7+F7+H7+J7+L7+N7+P7 -> 2045365 | S7: =C7+E7+G7+I7+K7+M7+O7+Q7 -> 908524 | T7: =R7+S7 -> 2953889 | U7: =R7/T7 -> 0.69243123 | V7: =1-U7 -> 0.30756877 | W7: Aggregate
A8: Female | B8: =(B6/(B6+C6)) -> 0.35035869 | D8: =(D6/(D6+E6)) -> 0.72917019 | F8: =(F6/(F6+G6)) -> 0.93869577 | H8: =(H6/(H6+I6)) -> 0.37537463 | J8: =(J6/(J6+K6)) -> 0.41271071 | L8: =(L6/(L6+M6)) -> 0.31825193 | N8: =(N6/(N6+O6)) -> 0.39470199 | P8: =(P6/(P6+Q6)) -> 0.7873149 | R8: =(R6/(R6+S6)) -> 0.72053814

Sheet Sheet3
A1: periodcode | B1: 2022
A3: Row Labels | B3: Sum of NHWA_Medical Doctors Stock By Sex Female | C3: Sum of NHWA_Medical Doctors Stock By Sex Male | D3: Sum of NHWA_Nursing Personnel Stock By Sex Female | E3: Sum of NHWA_Nursing Personnel Stock By Sex Male | F3: Sum of NHWA_Midwifery personnel Stock By Sex Female | G3: Sum of NHWA_Midwifery personnel Stock By Sex Male | H3: Sum of NHWA_Dentists Stock By Sex Female | I3: Sum of NHWA_Dentists Stock By Sex Male | J3: Sum of NHWA_Pharmacists Stock By Sex Female | K3: Sum of NHWA_Pharmacists Stock By Sex Male | L3: Sum of NHWA_Obstetricians and Gynaecologists Practitioners Stock By Sex Female | M3: Sum of NHWA_Obstetricians and Gynaecologists Practitioners Stock By Sex Male | N3: Sum of NHWA_General Paediatricians Practitioners Stock By Sex Female | O3: Sum of NHWA_General Paediatricians Practitioners Stock By Sex Male | P3: Sum of NHWA_Community Health Workers Stock By Sex Female | Q3: Sum of NHWA_Community Health Workers Stock By Sex Male
A4: High/Upper-Middle-Income Economies | B4: 1129 | C4: 1060 | D4: 9055 | E4: 3873 | F4: 1051 | G4: 14 | H4: 76 | I4: 98 | J4: 169 | K4: 124 | L4: 65 | M4: 85 | N4: 60 | O4: 106
A5: Lower-Middle-Income Economies | B5: 32523 | C5: 54574 | D5: 422784 | E5: 121208 | F5: 48005 | G5: 2726 | H5: 2778 | I5: 4540 | J5: 2998 | K5: 3733 | L5: 365 | M5: 526 | N5: 366 | O5: 234 | P5: 45368 | Q5: 12831
A6: Low-Income Economies | B6: 7958 | C6: 21520 | D6: 94705 | E6: 70489 | F6: 132331 | G6: 9106 | H6: 152 | I6: 364 | J6: 8022 | K6: 12065 | L6: 189 | M6: 715 | N6: 170 | O6: 574 | P6: 48476 | Q6: 12520
A7: Grand Total | B7: 41610 | C7: 77154 | D7: 526544 | E7: 195570 | F7: 181387 | G7: 11846 | H7: 3006 | I7: 5002 | J7: 11189 | K7: 15922 | L7: 619 | M7: 1326 | N7: 596 | O7: 914 | P7: 93844 | Q7: 25351

Sheet Countries
A1: Row Labels
A2: Burkina Faso
A3: Sao Tome and Principe
A4: Congo
A5: Ethiopia
A6: Nigeria
A7: Gabon
A8: Eswatini
A9: Algeria
A10: Benin
A11: Botswana
A12: Burundi
... A37: Togo

Sheet Sheet2
A3: Row Labels
A4: Burkina Faso
A5: Democratic Republic of Sao Tome and Principe
A6: Democratic Republic of the Congo
A7: Federal Democratic Republic of Ethiopia
A8: Federal Republic of Nigeria
A9: Gabonese Republic
A10: Kingdom of Eswatini
A11: People's Democratic Republic of Algeria
A12: Republic of Benin
A13: Republic of Botswana
A14: Republic of Burundi
... A40: Grand Total

Sheet Sheet 1 - AFRO Sex 20240123
A1: AFRO Sex 20240123
A2: periodid | B2: periodname | C2: periodcode | D2: perioddescription | E2: organisationunitid | F2: organisationunitname | G2: organisationunitcode | H2: organisationunitdescription | I2: NHWA_Medical Doctors Stock By Sex Female | J2: NHWA_Medical Doctors Stock By Sex Male | K2: NHWA_Generalist Medical Practitioners (incl. Family medical practitioners) Stock By Sex Female | L2: NHWA_Generalist Medical Practitioners (incl. Family medical practitioners) Stock By Sex Male | M2: NHWA_Medical group of Specialists Practitioners Stock By Sex Female | N2: NHWA_Medical group of Specialists Practitioners Stock By Sex Male | O2: NHWA_Medical doctors not further defined Stock By Sex Female | P2: NHWA_Medical doctors not further defined Stock By Sex Male | Q2: NHWA_Nursing Personnel Stock By Sex Female | R2: NHWA_Nursing Personnel Stock By Sex Male | S2: NHWA_Nursing Professionals Stock By Sex Female | T2: NHWA_Nursing Professionals Stock By Sex Male | U2: NHWA_Nursing Associate Professionals Stock By Sex Female | V2: NHWA_Nursing Associate Professionals Stock By Sex Male | W2: NHWA_Nurses not further defined Stock By Sex Female | X2: NHWA_Nurses not further defined Stock By Sex Male | Y2: NHWA_Midwifery personnel Stock By Sex Female | Z2: NHWA_Midwifery personnel Stock By Sex Male | AA2: NHWA_Midwifery Professionals Stock By Sex Female | AB2: NHWA_Midwifery Professionals Stock By Sex Male | AC2: NHWA_Midwifery Associate Professionals Stock By Sex Female | AD2: NHWA_Midwifery Associate Professionals Stock By Sex Male | AE2: NHWA_Midwives not further defined Stock By Sex Female | AF2: NHWA_Midwives not further defined Stock By Sex Male | AG2: NHWA_Dentists Stock By Sex Female | AH2: NHWA_Dentists Stock By Sex Male | AI2: NHWA_Pharmacists Stock By Sex Female | AJ2: NHWA_Pharmacists Stock By Sex Male | AK2: NHWA_Nursing Professionals Stock with additional midwifery training By Sex Female | AL2: NHWA_Nursing Professionals Stock with additional midwifery training By Sex Male | AM2: NHWA_Nursing Associate Professionals Stock with additional midwifery training By Sex Female | AN2: NHWA_Nursing Associate Professionals Stock with additional midwifery training By Sex Male | AO2: NHWA_Obstetricians and Gynaecologists Practitioners Stock By Sex Female | AP2: NHWA_Obstetricians and Gynaecologists Practitioners Stock By Sex Male | AQ2: NHWA_General Paediatricians Practitioners Stock By Sex Female | AR2: NHWA_General Paediatricians Practitioners Stock By Sex Male | AS2: NHWA_Community Health Workers Stock By Sex Female | AT2: NHWA_Community Health Workers Stock By Sex Male | AU2: Income level
A3: 2022 | B3: 2022 | C3: 2022 | E3: hmZE3mVAZFf | F3: Burkina Faso | G3: BFA | I3: 779 | J3: 1593 | K3: 779 | L3: 1593 | Y3: 4626 | Z3: 1060 | AA3: 4626 | AB3: 1060 | AG3: 9 | AH3: 30 | AI3: 223 | AJ3: 352 | AS3: 1600 | AT3: 1545 | AU3: =VLOOKUP(G3,'Country codes'!A$2:C$48,3,FALSE) -> Low-Income Economies
A4: 2022 | B4: 2022 | C4: 2022 | E4: zEYrsiNUGIo | F4: Federal Democratic Republic of Ethiopia | G4: ETH | I4: 2758 | J4: 10359 | K4: 1992 | L4: 6658 | Q4: 33050 | R4: 37196 | S4: 33050 | T4: 37196 | Y4: 14156 | Z4: 7837 | AA4: 14156 | AB4: 7837 | AG4: 73 | AH4: 198 | AI4: 6993 | AJ4: 10098 | AO4: 45 | AP4: 409 | AQ4: 42 | AR4: 310 | AS4: 39645 | AT4: 1456 | AU4: =VLOOKUP(G4,'Country codes'!A$2:C$48,3,FALSE) -> Low-Income Economies
A5: 2022 | B5: 2022 | C5: 2022 | E5: I3NxIqG7bD4 | F5: Federal Republic of Nigeria | G5: NGA | I5: 19401 | J5: 35297 | K5: 19401 | L5: 35297 | Q5: 249963 | R5: 44111 | S5: 249963 | T5: 44111 | AG5: 1300 | AH5: 1797 | AS5: 13577 | AT5: 58 | AU5: =VLOOKUP(G5,'Country codes'!A$2:C$48,3,FALSE) -> Lower-Middle-Income Economies
A6: 2022 | B6: 2022 | C6: 2022 | E6: EGLpIMSAWhx | F6: Gabonese Republic | G6: GAB | I6: 667 | J6: 472 | K6: 353 | L6: 259 | M6: 89 | N6: 48 | O6: 0 | P6: 0 | Q6: 2961 | R6: 1316 | S6: 658 | T6: 334 | U6: 2265 | V6: 936 | W6: 38 | X6: 46 | Y6: 909 | Z6: 11 | AA6: 867 | AB6: 0 | AC6: 32 | AD6: 11 | AE6: 10 | AF6: 0 | AG6: 8 | AH6: 36 | AI6: 95 | AJ6: 73 | AO6: 58 | AP6: 76 | AQ6: 56 | AR6: 98 | AU6: =VLOOKUP(G6,'Country codes'!A$2:C$48,3,FALSE) -> High/Upper-Middle-Income Economies
A7: 2022 | B7: 2022 | C7: 2022 | E7: G3thRWUQAX9 | F7: Kingdom of Eswatini | G7: SWZ | Q7: 3844 | R7: 1679 | S7: 2398 | T7: 1162 | U7: 520 | V7: 149 | W7: 926 | X7: 368 | Y7: 1820 | Z7: 645 | AA7: 1820 | AB7: 645 | AG7: 7 | AH7: 1 | AS7: 3200 | AT7: 0 | AU7: =VLOOKUP(G7,'Country codes'!A$2:C$48,3,FALSE) -> Lower-Middle-Income Economies
A8: 2022 | B8: 2022 | C8: 2022 | E8: c82mDnhUQly | F8: Republic of Botswana | G8: BWA | I8: 440 | J8: 553 | K8: 407 | L8: 492 | Q8: 5539 | R8: 2489 | S8: 5539 | T8: 2489 | AG8: 49 | AH8: 37 | AI8: 74 | AJ8: 51 | AU8: =VLOOKUP(G8,'Country codes'!A$2:C$48,3,FALSE) -> High/Upper-Middle-Income Economies
A9: 2022 | B9: 2022 | C9: 2022 | E9: bGWaeVBrOcc | F9: Republic of Cabo Verde | G9: CPV | I9: 1815 | J9: 827 | K9: 132 | L9: 55 | M9: 58 | N9: 42 | O9: 1622 | P9: 725 | Q9: 752 | R9: 189 | S9: 679 | T9: 167 | U9: 73 | V9: 22 | W9: 0 | X9: 0 | AG9: 6 | AH9: 4 | AI9: 16 | AJ9: 7 | AO9: 25 | AP9: 8 | AQ9: 15 | AR9: 8 | AS9: 62 | AT9: 93 | AU9: =VLOOKUP(G9,'Country codes'!A$2:C$48,3,FALSE) -> Lower-Middle-Income Economies
A10: 2022 | B10: 2022 | C10: 2022 | E10: VPesUmegQpP | F10: Republic of Cameroon | G10: CMR | I10: 1756 | J10: 2006 | K10: 1234 | L10: 1233 | M10: 279 | N10: 360 | O10: 2 | P10: 1 | Q10: 11079 | R10: 5394 | S10: 7416 | T10: 4069 | U10: 3614 | V10: 1311 | W10: 49 | X10: 14 | Y10: 1481 | Z10: 193 | AA10: 1397 | AB10: 181 | AC10: 65 | AD10: 12 | AE10: 19 | AF10: 0 | AG10: 186 | AH10: 131 | AI10: 328 | AJ10: 274 | AO10: 66 | AP10: 86 | AQ10: 63 | AR10: 24 | AS10: 210 | AT10: 100 | AU10: =VLOOKUP(G10,'Country codes'!A$2:C$48,3,FALSE) -> Lower-Middle-Income Economies
A11: 2022 | B11: 2022 | C11: 2022 | E11: tV0rWhHr9cj | F11: Republic of Chad | G11: TCD | I11: 236 | J11: 977 | K11: 236 | L11: 977 | Q11: 571 | R11: 1097 | S11: 571 | T11: 1097 | Y11: 618 | Z11: 39 | AA11: 618 | AB11: 39 | AG11: 6 | AH11: 15 | AI11: 31 | AJ11: 111 | AO11: 22 | AP11: 35 | AQ11: 8 | AR11: 20 | AU11: =VLOOKUP(G11,'Country codes'!A$2:C$48,3,FALSE) -> Low-Income Economies
A12: 2022 | B12: 2022 | C12: 2022 | E12: WXGcnQWJ0Qd | F12: Republic of Côte d'Ivoire | G12: CIV | I12: 1477 | J12: 3453 | K12: 1322 | L12: 3090 | Q12: 5530 | R12: 9449 | S12: 5510 | T12: 9424 | W12: 20 | X12: 25 | Y12: 7425 | Z12: 0 | AA12: 7421 | AB12: 0 | AC12: 4 | AD12: 0 | AG12: 146 | AH12: 272 | AI12: 469 | AJ12: 693 | AU12: =VLOOKUP(G12,'Country codes'!A$2:C$48,3,FALSE) -> Lower-Middle-Income Economies
A13: 2022 | B13: 2022 | C13: 2022 | E13: WC5rU5fLMzY | F13: Republic of Ghana | G13: GHA | I13: 1627 | J13: 2731 | K13: 1158 | L13: 1852 | Q13: 71253 | R13: 28420 | S13: 29537 | T13: 16426 | U13: 41716 | V13: 11994 | Y13: 23006 | Z13: 310 | AA13: 23006 | AB13: 310 | AI13: 476 | AJ13: 661 | AU13: =VLOOKUP(G13,'Country codes'!A$2:C$48,3,FALSE) -> Lower-Middle-Income Economies
A14: 2022 | B14: 2022 | C14: 2022 | E14: G9o5ad4oJJX | F14: Republic of Guinea-Bissau | G14: GNB | I14: 159 | J14: 279 | K14: 157 | L14: 271 | M14: 0 | N14: 0 | O14: 0 | P14: 0 | Q14: 1270 | R14: 608 | S14: 635 | T14: 350 | U14: 632 | V14: 257 | W14: 3 | X14: 1 | Y14: 197 | Z14: 0 | AA14: 26 | AB14: 0 | AC14: 171 | AD14: 0 | AE14: 0 | AF14: 0 | AG14: 7 | AH14: 14 | AI14: 1 | AJ14: 1 | AO14: 0 | AP14: 4 | AQ14: 2 | AR14: 4 | AS14: 549 | AT14: 2828 | AU14: =VLOOKUP(G14,'Country codes'!A$2:C$48,3,FALSE) -> Low-Income Economies
A15: 2022 | B15: 2022 | C15: 2022 | E15: HfVjCurKxh2 | F15: Republic of Kenya | G15: KEN | I15: 2323 | J15: 3194 | K15: 1535 | L15: 2009 | M15: 138 | N15: 195 | Q15: 24460 | R15: 11598 | S15: 24460 | T15: 11598 | Y15: 94 | Z15: 43 | AA15: 94 | AB15: 43 | AG15: 138 | AH15: 135 | AI15: 369 | AJ15: 517 | AO15: 106 | AP15: 179 | AQ15: 152 | AR15: 54 | AU15: =VLOOKUP(G15,'Country codes'!A$2:C$48,3,FALSE) -> Lower-Middle-Income Economies
A16: 2022 | B16: 2022 | C16: 2022 | E16: G037PAPU5dO | F16: Republic of Malawi | G16: MWI | I16: 419 | J16: 616 | K16: 324 | L16: 519 | M16: 11 | N16: 21 | O16: 4 | P16: 8 | Q16: 6162 | R16: 3430 | S16: 2260 | T16: 631 | U16: 3749 | V16: 2725 | W16: 153 | X16: 74 | Y16: 580 | Z16: 36 | AE16: 580 | AF16: 36 | AG16: 29 | AH16: 59 | AI16: 44 | AJ16: 67 | AO16: 18 | AP16: 3 | AQ16: 21 | AR16: 12 | AS16: 4767 | AT16: 5980 | AU16: =VLOOKUP(G16,'Country codes'!A$2:C$48,3,FALSE) -> Low-Income Economies
A17: 2022 | B17: 2022 | C17: 2022 | E17: Gan3VYicAWe | F17: Republic of Mozambique | G17: MOZ | I17: 1130 | J17: 1216 | K17: 820 | L17: 770 | AU17: =VLOOKUP(G17,'Country codes'!A$2:C$48,3,FALSE) -> Low-Income Economies
A18: 2022 | B18: 2022 | C18: 2022 | E18: wj7iV08dvFq | F18: Republic of Senegal | G18: SEN | I18: 1000 | J18: 1198 | K18: 250 | L18: 463 | Q18: 3029 | R18: 1708 | S18: 1669 | T18: 1100 | U18: 1360 | V18: 608 | Y18: 2803 | Z18: 0 | AA18: 2803 | AB18: 0 | AG18: 95 | AH18: 127 | AI18: 155 | AJ18: 197 | AO18: 77 | AP18: 87 | AQ18: 83 | AR18: 61 | AS18: 12201 | AT18: 6555 | AU18: =VLOOKUP(G18,'Country codes'!A$2:C$48,3,FALSE) -> Lower-Middle-Income Economies
A19: 2022 | B19: 2022 | C19: 2022 | E19: wimH12ukPK5 | F19: Republic of Seychelles | G19: SYC | I19: 22 | J19: 35 | K19: 22 | L19: 35 | Q19: 555 | R19: 68 | S19: 555 | T19: 68 | U19: 0 | V19: 0 | W19: 0 | X19: 0 | Y19: 142 | Z19: 3 | AA19: 142 | AB19: 3 | AG19: 19 | AH19: 25 | AO19: 7 | AP19: 9 | AQ19: 4 | AR19: 8 | AU19: =VLOOKUP(G19,'Country codes'!A$2:C$48,3,FALSE) -> High/Upper-Middle-Income Economies
A20: 2022 | B20: 2022 | C20: 2022 | E20: shRXArPWh8H | F20: Republic of the Congo | G20: COG | I20: 637 | J20: 405 | K20: 470 | L20: 317 | M20: 116 | N20: 53 | Q20: 1278 | R20: 4295 | S20: 1278 | T20: 4295 | Y20: 895 | Z20: 12 | AA20: 895 | AB20: 12 | AG20: 7 | AH20: 2 | AI20: 17 | AJ20: 11 | AO20: 19 | AP20: 12 | AQ20: 12 | AR20: 12 | AU20: =VLOOKUP(G20,'Country codes'!A$2:C$48,3,FALSE) -> Lower-Middle-Income Economies
A21: 2022 | B21: 2022 | C21: 2022 | E21: SnYHrnchKjL | F21: Republic of Uganda | G21: UGA | I21: 2271 | J21: 5696 | K21: 1811 | L21: 4557 | M21: 115 | N21: 223 | Q21: 49976 | R21: 24226 | U21: 15148 | V21: 6277 | W21: 34828 | X21: 17949 | Y21: 110270 | Z21: 87 | AC21: 86011 | AD21: 87 | AE21: 24259 | AF21: 0 | AI21: 526 | AJ21: 1186 | AO21: 92 | AP21: 223 | AQ21: 80 | AR21: 198 | AU21: =VLOOKUP(G21,'Country codes'!A$2:C$48,3,FALSE) -> Low-Income Economies
A22: 2022 | B22: 2022 | C22: 2022 | E22: gb7vWtO7Wjp | F22: Republic of Zambia | G22: ZMB | I22: 1824 | J22: 3418 | K22: 1695 | L22: 3013 | M22: 14 | N22: 87 | O22: 0 | P22: 0 | Q22: 27138 | R22: 6641 | S22: 27138 | T22: 6641 | U22: 0 | V22: 0 | W22: 0 | X22: 0 | Y22: 7881 | Z22: 1327 | AA22: 7881 | AB22: 1327 | AG22: 109 | AH22: 152 | AI22: 331 | AJ22: 308 | AO22: 31 | AP22: 54 | AQ22: 25 | AR22: 36 | AS22: 1129 | AT22: 1292 | AU22: =VLOOKUP(G22,'Country codes'!A$2:C$48,3,FALSE) -> Lower-Middle-Income Economies
A23: 2022 | B23: 2022 | C23: 2022 | E23: buSEeeViTo3 | F23: Republic of Zimbabwe | G23: ZWE | I23: 663 | J23: 2045 | K23: 467 | L23: 1565 | M23: 28 | N23: 65 | Q23: 24458 | R23: 7724 | S23: 24458 | T23: 7724 | Y23: 2600 | Z23: 196 | AA23: 2600 | AB23: 196 | AG23: 784 | AH23: 1919 | AI23: 837 | AJ23: 1065 | AO23: 41 | AP23: 100 | AQ23: 16 | AR23: 39 | AS23: 14989 | AT23: 4733 | AU23: =VLOOKUP(G23,'Country codes'!A$2:C$48,3,FALSE) -> Lower-Middle-Income Economies
A24: 2022 | B24: 2022 | C24: 2022 | E24: vnbnnSZXGTv | F24: State of Eritrea | G24: ERI | I24: 70 | J24: 190 | K24: 70 | L24: 190 | M24: 0 | N24: 19 | Q24: 3053 | R24: 1925 | S24: 721 | T24: 697 | U24: 2273 | V24: 1099 | W24: 59 | X24: 129 | Y24: 20 | Z24: 47 | AA24: 20 | AB24: 47 | AG24: 23 | AH24: 35 | AI24: 78 | AJ24: 121 | AO24: 2 | AP24: 8 | AQ24: 2 | AR24: 8 | AS24: 1915 | AT24: 711 | AU24: =VLOOKUP(G24,'Country codes'!A$2:C$48,3,FALSE) -> Low-Income Economies
A25: 2022 | B25: 2022 | C25: 2022 | E25: WtcZBCTspgM | F25: Togolese Republic | G25: TGO | I25: 136 | J25: 594 | K25: 59 | L25: 272 | Q25: 623 | R25: 2007 | S25: 367 | T25: 1332 | U25: 256 | V25: 675 | Y25: 1864 | Z25: 0 | AA25: 1043 | AB25: 0 | AC25: 821 | AD25: 0 | AG25: 5 | AH25: 13 | AI25: 126 | AJ25: 129 | AO25: 10 | AP25: 33 | AQ25: 15 | AR25: 22 | AU25: =VLOOKUP(G25,'Country codes'!A$2:C$48,3,FALSE) -> Low-Income Economies
A26: 2021 | B26: 2021 | C26: 2021 | E26: hmZE3mVAZFf | F26: Burkina Faso | G26: BFA | I26: 781 | J26: 1440 | K26: 481 | L26: 739 | Q26: 4719 | R26: 7470 | S26: 3988 | T26: 6715 | U26: 731 | V26: 755 | Y26: 4313 | Z26: 1039 | AA26: 3947 | AB26: 1039 | AC26: 366 | AD26: 0 | AG26: 32 | AH26: 75 | AI26: 134 | AJ26: 191 | AO26: 40 | AP26: 86 | AQ26: 54 | AR26: 51 | AS26: 1533 | AT26: 1414 | AU26: =VLOOKUP(G26,'Country codes'!A$2:C$48,3,FALSE) -> Low-Income Economies
A27: 2021 | B27: 2021 | C27: 2021 | E27: zEYrsiNUGIo | F27: Federal Democratic Republic of Ethiopia | G27: ETH | I27: 2602 | J27: 9572 | K27: 2067 | L27: 7294 | Q27: 32043 | R27: 37781 | S27: 32043 | T27: 37781 | Y27: 13337 | Z27: 7018 | AA27: 13337 | AB27: 7018 | AG27: 41 | AH27: 69 | AI27: 5767 | AJ27: 9731 | AS27: 41668 | AT27: 962 | AU27: =VLOOKUP(G27,'Country codes'!A$2:C$48,3,FALSE) -> Low-Income Economies
A28: 2021 | B28: 2021 | C28: 2021 | E28: DzAOqCf0ots | F28: Republic of Benin | G28: BEN | I28: 856 | J28: 1899 | K28: 521 | L28: 1276 | Q28: 3291 | R28: 2193 | S28: 3291 | T28: 2193 | Y28: 2086 | Z28: 0 | AA28: 2086 | AB28: 0 | AG28: 26 | AH28: 24 | AI28: 161 | AJ28: 242 | AO28: 62 | AP28: 95 | AQ28: 39 | AR28: 58 | AS28: 14 | AT28: 7 | AU28: =VLOOKUP(G28,'Country codes'!A$2:C$48,3,FALSE) -> Lower-Middle-Income Economies
A29: 2021 | B29: 2021 | C29: 2021 | E29: c82mDnhUQly | F29: Republic of Botswana | G29: BWA | I29: 411 | J29: 603 | K29: 374 | L29: 526 | Q29: 5466 | R29: 2420 | S29: 5466 | T29: 2420 | AG29: 49 | AH29: 40 | AI29: 90 | AJ29: 68 | AU29: =VLOOKUP(G29,'Country codes'!A$2:C$48,3,FALSE) -> High/Upper-Middle-Income Economies
A30: 2021 | B30: 2021 | C30: 2021 | E30: VPesUmegQpP | F30: Republic of Cameroon | G30: CMR | I30: 1594 | J30: 1784 | K30: 1180 | L30: 1297 | M30: 222 | N30: 264 | O30: 1 | P30: 3 | Q30: 2690 | R30: 1853 | S30: 2117 | T30: 1402 | U30: 32 | V30: 11 | W30: 541 | X30: 440 | Y30: 626 | Z30: 78 | AA30: 626 | AB30: 78 | AG30: 80 | AH30: 53 | AI30: 149 | AJ30: 115 | AK30: 77 | AL30: 54 | AM30: 25 | AN30: 12 | AO30: 57 | AP30: 68 | AQ30: 44 | AR30: 15 | AU30: =VLOOKUP(G30,'Country codes'!A$2:C$48,3,FALSE) -> Lower-Middle-Income Economies
A31: 2021 | B31: 2021 | C31: 2021 | E31: tV0rWhHr9cj | F31: Republic of Chad | G31: TCD | I31: 132 | J31: 653 | K31: 132 | L31: 653 | M31: 4 | N31: 170 | Q31: 540 | R31: 997 | S31: 540 | T31: 997 | Y31: 678 | Z31: 43 | AA31: 580 | AB31: 37 | AC31: 98 | AD31: 6 | AG31: 5 | AH31: 14 | AI31: 31 | AJ31: 111 | AO31: 16 | AP31: 40 | AQ31: 3 | AR31: 14 | AU31: =VLOOKUP(G31,'Country codes'!A$2:C$48,3,FALSE) -> Low-Income Economies
A32: 2021 | B32: 2021 | C32: 2021 | E32: WC5rU5fLMzY | F32: Republic of Ghana | G32: GHA | I32: 1552 | J32: 2617 | K32: 1181 | L32: 1853 | Q32: 66802 | R32: 26342 | S32: 26580 | T32: 14728 | U32: 40222 | V32: 11614 | Y32: 18862 | Z32: 279 | AA32: 18862 | AB32: 279 | AI32: 435 | AJ32: 600 | AU32: =VLOOKUP(G32,'Country codes'!A$2:C$48,3,FALSE) -> Lower-Middle-Income Economies
A33: 2021 | B33: 2021 | C33: 2021 | E33: G9o5ad4oJJX | F33: Republic of Guinea-Bissau | G33: GNB | I33: 157 | J33: 296 | K33: 156 | L33: 288 | M33: 0 | N33: 0 | O33: 0 | P33: 0 | Q33: 1281 | R33: 673 | S33: 635 | T33: 368 | U33: 646 | V33: 305 | W33: 0 | X33: 0 | Y33: 213 | Z33: 0 | AA33: 213 | AB33: 0 | AC33: 0 | AD33: 0 | AE33: 0 | AF33: 0 | AI33: 1 | AJ33: 1 | AK33: 0 | AL33: 0 | AM33: 0 | AN33: 0 | AO33: 4 | AP33: 0 | AQ33: 2 | AR33: 3 | AU33: =VLOOKUP(G33,'Country codes'!A$2:C$48,3,FALSE) -> Low-Income Economies
A34: 2021 | B34: 2021 | C34: 2021 | E34: HfVjCurKxh2 | F34: Republic of Kenya | G34: KEN | I34: 2140 | J34: 3063 | K34: 1372 | L34: 1880 | M34: 166 | N34: 281 | Q34: 23514 | R34: 11058 | S34: 23514 | T34: 11058 | AG34: 143 | AH34: 189 | AO34: 99 | AP34: 143 | AQ34: 134 | AR34: 65 | AU34: =VLOOKUP(G34,'Country codes'!A$2:C$48,3,FALSE) -> Lower-Middle-Income Economies
A35: 2021 | B35: 2021 | C35: 2021 | E35: Gan3VYicAWe | F35: Republic of Mozambique | G35: MOZ | I35: 1303 | J35: 1442 | K35: 945 | L35: 951 | M35: 245 | N35: 236 | Q35: 5844 | R35: 5122 | S35: 1252 | T35: 911 | U35: 4592 | V35: 4211 | Y35: 7281 | Z35: 0 | AA35: 42 | AB35: 0 | AC35: 7239 | AD35: 0 | AG35: 214 | AH35: 148 | AI35: 210 | AJ35: 251 | AO35: 15 | AP35: 48 | AQ35: 38 | AR35: 23 | AU35: =VLOOKUP(G35,'Country codes'!A$2:C$48,3,FALSE) -> Low-Income Economies
A36: 2021 | B36: 2021 | C36: 2021 | E36: wj7iV08dvFq | F36: Republic of Senegal | G36: SEN | I36: 618 | J36: 1080 | K36: 150 | L36: 328 | M36: 312 | N36: 498 | Q36: 4383 | R36: 2094 | S36: 1531 | T36: 992 | U36: 1501 | V36: 672 | W36: 1351 | X36: 430 | Y36: 2739 | Z36: 0 | AA36: 2710 | AB36: 0 | AC36: 29 | AD36: 0 | AG36: 72 | AH36: 104 | AI36: 131 | AJ36: 162 | AM36: 1056 | AN36: 532 | AO36: 59 | AP36: 74 | AQ36: 43 | AR36: 67 | AU36: =VLOOKUP(G36,'Country codes'!A$2:C$48,3,FALSE) -> Lower-Middle-Income Economies
A37: 2020 | B37: 2020 | C37: 2020 | E37: hmZE3mVAZFf | F37: Burkina Faso | G37: BFA | I37: 719 | J37: 1352 | K37: 426 | L37: 662 | Q37: 2307 | R37: 3443 | S37: 1522 | T37: 2582 | U37: 785 | V37: 861 | Y37: 6786 | Z37: 1019 | AA37: 3809 | AB37: 1019 | AC37: 2977 | AD37: 0 | AG37: 31 | AH37: 72 | AO37: 38 | AP37: 88 | AQ37: 53 | AR37: 48 | AS37: 1496 | AT37: 1427 | AU37: =VLOOKUP(G37,'Country codes'!A$2:C$48,3,FALSE) -> Low-Income Economies
A38: 2020 | B38: 2020 | C38: 2020 | E38: zEYrsiNUGIo | F38: Federal Democratic Republic of Ethiopia | G38: ETH | AS38: 39875 | AT38: 0 | AU38: =VLOOKUP(G38,'Country codes'!A$2:C$48,3,FALSE) -> Low-Income Economies
A39: 2020 | B39: 2020 | C39: 2020 | E39: EGLpIMSAWhx | F39: Gabonese Republic | G39: GAB | I39: 591 | J39: 771 | K39: 237 | L39: 289 | M39: 49 | N39: 65 | O39: 1 | P39: 0 | Q39: 3614 | R39: 1813 | S39: 3239 | T39: 1551 | U39: 373 | V39: 262 | W39: 2 | X39: 0 | Y39: 662 | Z39: 0 | AA39: 662 | AB39: 0 | AC39: 0 | AD39: 0 | AE39: 0 | AF39: 0 | AG39: 15 | AH39: 19 | AI39: 74 | AJ39: 65 | AK39: 117 | AL39: 73 | AM39: 1 | AN39: 0 | AO39: 24 | AP39: 58 | AQ39: 40 | AR39: 27 | AS39: 82 | AT39: 28 | AU39: =VLOOKUP(G39,'Country codes'!A$2:C$48,3,FALSE) -> High/Upper-Middle-Income Economies
A40: 2020 | B40: 2020 | C40: 2020 | E40: G3thRWUQAX9 | F40: Kingdom of Eswatini | G40: SWZ | AS40: 5319 | AT40: 67 | AU40: =VLOOKUP(G40,'Country codes'!A$2:C$48,3,FALSE) -> Lower-Middle-Income Economies
...

Sheet Females all
B1: Medical Doctors | C1: Nursing Personnel | D1: Midwifery personnel | E1: Dentists | F1: Pharmacists | G1: Obstetricians and Gynaecologists Practitioners | H1: General Paediatricians Practitioners | I1: Community Health Workers | J1: Total Females | N1: Occupation | O1: Female | P1: Male
A2: Female | B2: 0.35035869 | C2: 0.72917019 | D2: 0.93869577 | E2: 0.37537463 | F2: 0.41271071 | G2: 0.31825193 | H2: 0.39470199 | I2: 0.7873149 | J2: 0.72053814 | N2: Obstetricians and Gynaecologists Practitioners | O2: 0.31825193 | P2: =1-O2 -> 0.68174807
N3: Medical Doctors | O3: 0.35035869 | P3: =1-O3 -> 0.64964131
N4: Dentists | O4: 0.37537463 | P4: =1-O4 -> 0.62462537
N5: General Paediatricians Practitioners | O5: 0.39470199 | P5: =1-O5 -> 0.60529801
N6: Pharmacists | O6: 0.41271071 | P6: =1-O6 -> 0.58728929
N7: African Region | O7: 0.72053814 | P7: =1-O7 -> 0.27946186
N8: Nursing Personnel | O8: 0.72917019 | P8: =1-O8 -> 0.27082981
N9: Community Health Workers | O9: 0.7873149 | P9: =1-O9 -> 0.2126851
N10: Midwifery personnel | O10: 0.93869577 | P10: =1-O10 -> 0.061304229

Sheet Country codes
A1: country code | B1: Country | C1: Income
A2: DZA | B2: Algeria | C2: Lower-Middle-Income Economies
A3: AGO | B3: Angola | C3: Lower-Middle-Income Economies
A4: BEN | B4: Benin | C4: Lower-Middle-Income Economies
A5: BWA | B5: Botswana | C5: High/Upper-Middle-Income Economies
A6: BFA | B6: Burkina Faso | C6: Low-Income Economies
A7: BDI | B7: Burundi | C7: Low-Income Economies
A8: CMR | B8: Cameroon | C8: Lower-Middle-Income Economies
A9: CPV | B9: Cape-Verde | C9: Lower-Middle-Income Economies
A10: CAF | B10: Central African Republic | C10: Low-Income Economies
A11: TCD | B11: Chad | C11: Low-Income Economies
A12: COM | B12: Comoros | C12: Lower-Middle-Income Economies
... A48: ZWE | B48: Zimbabwe | C48: Lower-Middle-Income Economies
A49: AFRO | B49: AFRO

Sheet Females income levels
A1: Row Labels | B1: Sum of NHWA_Medical Doctors Stock By Sex Female | C1: Sum of NHWA_Medical Doctors Stock By Sex Male | D1: Sum of NHWA_Nursing Personnel Stock By Sex Female | E1: Sum of NHWA_Nursing Personnel Stock By Sex Male | F1: Sum of NHWA_Midwifery personnel Stock By Sex Female | G1: Sum of NHWA_Midwifery personnel Stock By Sex Male | H1: Sum of NHWA_Dentists Stock By Sex Female | I1: Sum of NHWA_Dentists Stock By Sex Male | J1: Sum of NHWA_Pharmacists Stock By Sex Female | K1: Sum of NHWA_Pharmacists Stock By Sex Male | L1: Sum of NHWA_Obstetricians and Gynaecologists Practitioners Stock By Sex Female | M1: Sum of NHWA_Obstetricians and Gynaecologists Practitioners Stock By Sex Male | N1: Sum of NHWA_General Paediatricians Practitioners Stock By Sex Female | O1: Sum of NHWA_General Paediatricians Practitioners Stock By Sex Male | P1: Sum of NHWA_Community Health Workers Stock By Sex Female | Q1: Sum of NHWA_Community Health Workers Stock By Sex Male
A2: High/Upper-Middle-Income Economies | B2: 3821 | C2: 5221 | D2: 38530 | E2: 16552 | F2: 2325 | G2: 14 | H2: 378 | I2: 404 | J2: 933 | K2: 834 | L2: 119 | M2: 203 | N2: 142 | O2: 167 | P2: 169 | Q2: 58
A3: Lower-Middle-Income Economies | B3: 136025 | C3: 124051 | D3: 922416 | E3: 298462 | F3: 100370 | G3: 3576 | H3: 12836 | I3: 11311 | J3: 16282 | K3: 14351 | L3: 3333 | M3: 2064 | N3: 2950 | O3: 1584 | P3: 62394 | Q3: 21250
A4: Low-Income Economies | B4: 18072 | C4: 45459 | D4: 275064 | E4: 216514 | F4: 191641 | G4: 19406 | H4: 915 | I4: 1093 | J4: 15375 | K4: 23899 | L4: 424 | M4: 1266 | N4: 506 | O4: 855 | P4: 240345 | Q4: 99930
A5: Grand Total | B5: 157918 | C5: 174731 | D5: 1236010 | E5: 531528 | F5: 294336 | G5: 22996 | H5: 14129 | I5: 12808 | J5: 32590 | K5: 39084 | L5: 3876 | M5: 3533 | N5: 3598 | O5: 2606 | P5: 302908 | Q5: 121238
A11: Row Labels | B11: Sum of NHWA_Medical Doctors Stock By Sex Female | C11: Sum of NHWA_Medical Doctors Stock By Sex Male | D11: Sum of NHWA_Nursing Personnel Stock By Sex Female | E11: Sum of NHWA_Nursing Personnel Stock By Sex Male | F11: Sum of NHWA_Midwifery personnel Stock By Sex Female | G11: Sum of NHWA_Midwifery personnel Stock By Sex Male | H11: Sum of NHWA_Dentists Stock By Sex Female | I11: Sum of NHWA_Dentists Stock By Sex Male | J11: Sum of NHWA_Pharmacists Stock By Sex Female | K11: Sum of NHWA_Pharmacists Stock By Sex Male | L11: Sum of NHWA_Obstetricians and Gynaecologists Practitioners Stock By Sex Female | M11: Sum of NHWA_Obstetricians and Gynaecologists Practitioners Stock By Sex Male | N11: Sum of NHWA_General Paediatricians Practitioners Stock By Sex Female | O11: Sum of NHWA_General Paediatricians Practitioners Stock By Sex Male | P11: Sum of NHWA_Community Health Workers Stock By Sex Female | Q11: Sum of NHWA_Community Health Workers Stock By Sex Male | R11: Total females | S11: Total males
A12: High/Upper-Middle-Income Economies | B12: 1129 | C12: 1060 | D12: 9055 | E12: 3873 | F12: 1051 | G12: 14 | H12: 76 | I12: 98 | J12: 169 | K12: 124 | L12: 65 | M12: 85 | N12: 60 | O12: 106 | P12: 169 | Q12: 58 | R12: =B12+D12+F12+H12+J12+L12+N12+P12 -> 11774 | S12: =C12+E12+G12+I12+K12+M12+O12+Q12 -> 5418
A13: Lower-Middle-Income Economies | B13: 32523 | C13: 54574 | D13: 422784 | E13: 121208 | F13: 48005 | G13: 2726 | H13: 2778 | I13: 4540 | J13: 2998 | K13: 3733 | L13: 365 | M13: 526 | N13: 366 | O13: 234 | P13: 45368 | Q13: 12831 | R13: =B13+D13+F13+H13+J13+L13+N13+P13 -> 555187 | S13: =C13+E13+G13+I13+K13+M13+O13+Q13 -> 200372
A14: Low-Income Economies | B14: 7958 | C14: 21520 | D14: 94705 | E14: 70489 | F14: 132331 | G14: 9106 | H14: 152 | I14: 364 | J14: 8022 | K14: 12065 | L14: 189 | M14: 715 | N14: 170 | O14: 574 | P14: 48476 | Q14: 12520 | R14: =B14+D14+F14+H14+J14+L14+N14+P14 -> 292003 | S14: =C14+E14+G14+I14+K14+M14+O14+Q14 -> 127353
A15: AFRO | B15: 41610 | C15: 77154 | D15: 526544 | E15: 195570 | F15: 181387 | G15: 11846 | H15: 3006 | I15: 5002 | J15: 11189 | K15: 15922 | L15: 619 | M15: 1326 | N15: 596 | O15: 914 | P15: 93844 | Q15: 25351 | R15: =B15+D15+F15+H15+J15+L15+N15+P15 -> 858795 | S15: =C15+E15+G15+I15+K15+M15+O15+Q15 -> 333085
A18: High/Upper-Middle-Income Economies | B18: =B12/(B12+C12) -> 0.51576062 | D18: =D12/(D12+E12) -> 0.7004177 | F18: =F12/(F12+G12) -> 0.98685446 | H18: =H12/(H12+I12) -> 0.43678161 | J18: =J12/(J12+K12) -> 0.57679181 | L18: =L12/(L12+M12) -> 0.43333333 | N18: =N12/(N12+O12) -> 0.36144578 | P18: =P12/(P12+Q12) -> 0.74449339 | R18: =R12/(R12+S12) -> 0.68485342
A19: Lower-Middle-Income Economies | B19: =B13/(B13+C13) -> 0.37341125 | D19: =D13/(D13+E13) -> 0.7771879 | F19: =F13/(F13+G13) -> 0.9462656 | H19: =H13/(H13+I13) -> 0.37961192 | J19: =J13/(J13+K13) -> 0.44540187 | L19: =L13/(L13+M13) -> 0.40965208 | N19: =N13/(N13+O13) -> 0.61 | P19: =P13/(P13+Q13) -> 0.77953229 | R19: =R13/(R13+S13) -> 0.73480297
A20: Low-Income Economies | B20: =B14/(B14+C14) -> 0.26996404 | D20: =D14/(D14+E14) -> 0.57329564 | F20: =F14/(F14+G14) -> 0.93561798 | H20: =H14/(H14+I14) -> 0.29457364 | J20: =J14/(J14+K14) -> 0.39936277 | L20: =L14/(L14+M14) -> 0.2090708 | N20: =N14/(N14+O14) -> 0.22849462 | P20: =P14/(P14+Q14) -> 0.79474064 | R20: =R14/(R14+S14) -> 0.69631292
A21: AFRO | B21: =B15/(B15+C15) -> 0.35035869 | D21: =D15/(D15+E15) -> 0.72917019 | F21: =F15/(F15+G15) -> 0.93869577 | H21: =H15/(H15+I15) -> 0.37537463 | J21: =J15/(J15+K15) -> 0.41271071 | L21: =L15/(L15+M15) -> 0.31825193 | N21: =N15/(N15+O15) -> 0.39470199 | P21: =P15/(P15+Q15) -> 0.7873149 | R21: =R15/(R15+S15) -> 0.72053814

Sheet Sheet1
A1: Row Labels | B1: Medical Doctors Female | C1: Medical Doctors Male | D1: Nursing Personnel Female | E1: Nursing Personnel Male | F1: Midwifery personnel Female | G1: Midwifery personnel Male | H1: Dentists Stock Female | I1: Dentists Male | J1: Pharmacists Female | K1: Pharmacists Male | M1: Female | N1: Male
A2: High/Upper-Middle-Income | B2: 1129 | C2: 1060 | D2: 9055 | E2: 3873 | F2: 1051 | G2: 14 | H2: 76 | I2: 98 | J2: 169 | K2: 124 | L2: =SUM(B2:K2) -> 16649 | M2: =B2+D2+F2+H2+J2 -> 11480 | N2: =C2+E2+G2+I2+K2 -> 5169
A3: Lower-Middle-Income Economies | B3: 32523 | C3: 54574 | D3: 422784 | E3: 121208 | F3: 48005 | G3: 2726 | H3: 2778 | I3: 4540 | J3: 2998 | K3: 3733 | L3: =SUM(B3:K3) -> 695869 | M3: =B3+D3+F3+H3+J3 -> 509088 | N3: =C3+E3+G3+I3+K3 -> 186781
A4: Low-Income Economies | B4: 7958 | C4: 21520 | D4: 94705 | E4: 70489 | F4: 132331 | G4: 9106 | H4: 152 | I4: 364 | J4: 8022 | K4: 12065 | L4: =SUM(B4:K4) -> 356712 | M4: =B4+D4+F4+H4+J4 -> 243168 | N4: =C4+E4+G4+I4+K4 -> 113544 | Q4: Female | R4: Male
A5: AFRO | B5: 41610 | C5: 77154 | D5: 526544 | E5: 195570 | F5: 181387 | G5: 11846 | H5: 3006 | I5: 5002 | J5: 11189 | K5: 15922 | L5: =SUM(B5:K5) -> 1069230 | M5: =B5+D5+F5+H5+J5 -> 763736 | N5: =C5+E5+G5+I5+K5 -> 305494 | Q5: =M5/L5 -> 0.71428598 | R5: =N5/L5 -> 0.28571402
A8: High/Upper-Middle-Income | B8: 0.51576062 | D8: 0.7004177 | F8: 0.98685446 | H8: 0.43678161 | J8: 0.57679181
A9: Lower-Middle-Income Economies | B9: 0.37341125 | D9: 0.7771879 | F9: 0.9462656 | H9: 0.37961192 | J9: 0.44540187
A10: Low-Income Economies | B10: 0.26996404 | D10: 0.57329564 | F10: 0.93561798 | H10: 0.29457364 | J10: 0.39936277
A11: AFRO | B11: 0.35035869 | D11: 0.72917019 | F11: 0.93869577 | H11: 0.37537463 | J11: 0.41271071
B17: Medical Doctors Female | C17: Medical Doctors Male | D17: Nursing Personnel Female | E17: Nursing Personnel Male | F17: Midwifery personnel Female | G17: Midwifery personnel Male | H17: Dentists Female | I17: Dentists Male | J17: Pharmacists Female | K17: Pharmacists Male
A18: High/Upper-Middle-Income | B18: 0.51576062 | C18: =1-B18 -> 0.48423938 | D18: 0.7004177 | E18: =1-D18 -> 0.2995823 | F18: 0.98685446 | G18: =1-F18 -> 0.01314554 | H18: 0.43678161 | I18: =1-H18 -> 0.56321839 | J18: 0.57679181 | K18: =1-J18 -> 0.42320819
A19: Lower-Middle-Income Economies | B19: 0.37341125 | C19: =1-B19 -> 0.62658875 | D19: 0.7771879 | E19: =1-D19 -> 0.2228121 | F19: 0.9462656 | G19: =1-F19 -> 0.053734403 | H19: 0.37961192 | I19: =1-H19 -> 0.62038808 | J19: 0.44540187 | K19: =1-J19 -> 0.55459813
A20: Low-Income Economies | B20: 0.26996404 | C20: =1-B20 -> 0.73003596 | D20: 0.57329564 | E20: =1-D20 -> 0.42670436 | F20: 0.93561798 | G20: =1-F20 -> 0.064382022 | H20: 0.29457364 | I20: =1-H20 -> 0.70542636 | J20: 0.39936277 | K20: =1-J20 -> 0.60063723
A21: AFRO | B21: 0.35035869 | C21: =1-B21 -> 0.64964131 | D21: 0.72917019 | E21: =1-D21 -> 0.27082981 | F21: 0.93869577 | G21: =1-F21 -> 0.061304229 | H21: 0.37537463 | I21: =1-H21 -> 0.62462537 | J21: 0.41271071 | K21: =1-J21 -> 0.58728929
B26: Females | C26: Males
A27: High/Upper-Middle-Income | B27: =M2/L2 -> 0.6895309 | C27: =1-B27 -> 0.3104691
A28: Lower-Middle-Income Economies | B28: =M3/L3 -> 0.73158597 | C28: =1-B28 -> 0.26841403
A29: Low-Income Economies | B29: =M4/L4 -> 0.68169279 | C29: =1-B29 -> 0.31830721
A30: African Region | B30: 0.72 | C30: =1-B30 -> 0.28
