Workbook

Sheet Sheet2
A3: Row Labels | B3: Count of 2018 | C3: Count of 2022 | D3: Count of 2021 | E3: Count of 2020 | F3: Count of 2019
A4: AGO
A5: BDI | F5: 1
A6: BEN | B6: 1 | D6: 1 | E6: 1
A7: BFA | B7: 1 | C7: 1 | D7: 1 | E7: 1 | F7: 1
A8: BWA | B8: 1 | C8: 1 | D8: 1 | E8: 1 | F8: 1
A9: CAF | B9: 1 | D9: 1 | E9: 1 | F9: 1
A10: CIV | B10: 1 | C10: 1 | D10: 1 | E10: 1 | F10: 1
A11: CMR | B11: 1 | C11: 1 | D11: 1 | E11: 1 | F11: 1
A12: COD | B12: 1 | D12: 1 | E12: 1 | F12: 1
A13: COG | B13: 1 | C13: 1 | D13: 1 | E13: 1 | F13: 1
A14: COM | B14: 1 | D14: 1 | E14: 1
A15: CPV | B15: 1 | C15: 1 | D15: 1 | E15: 1
A16: DZA | B16: 1 | E16: 1
A17: ERI | B17: 1 | C17: 1
A18: ETH | B18: 1
A19: GAB | B19: 1 | C19: 1
A20: GHA | B20: 1 | C20: 1
A21: GIN | B21: 1
A22: GMB | B22: 1
A23: GNB | B23: 1 | C23: 1
A24: GNQ | B24: 1
A25: KEN | C25: 1
A26: LBR | C26: 1
A27: LSO | C27: 1
A28: MDG | C28: 1
A29: MLI | C29: 1
A30: MOZ | C30: 1
A31: MRT | C31: 1
A32: MUS | C32: 1
A33: MWI | C33: 1
A34: NAM | C34: 1
A35: NER | C35: 1
A36: NGA
A37: RWA
A38: SEN
A39: SLE
A40: SSD
A41: STP
A42: SWZ
...

Sheet Sheet4
A1: Row Labels | B1: Sum of NHWA_Medical Doctors Stock By Age Group < 25 yrs | C1: Sum of NHWA_Medical Doctors Stock By Age Group 25-34 yrs | D1: Sum of NHWA_Medical Doctors Stock By Age Group 35-44 yrs | E1: Sum of NHWA_Medical Doctors Stock By Age Group 45-54 yrs | F1: Sum of NHWA_Medical Doctors Stock By Age Group 55-64 yrs | G1: Sum of NHWA_Medical Doctors Stock By Age Group ≥ 65 yrs
A2: AFR | B2: 989 | C2: 35839 | D2: 35402 | E2: 16936 | F2: 6573 | G2: 1720
A3: BFA | B3: 0 | C3: 1138 | D3: 1088 | E3: 112 | F3: 33 | G3: 1
A4: BWA | C4: 483 | D4: 323 | E4: 121 | F4: 52 | G4: 14
A5: CIV | B5: 0 | C5: 920 | D5: 1757 | E5: 1583 | F5: 640 | G5: 29
A6: CMR | B6: 15 | C6: 1889 | D6: 1240 | E6: 454 | F6: 156 | G6: 8
A7: COG | C7: 464 | D7: 312 | E7: 121 | F7: 137 | G7: 8
A8: CPV | B8: 11 | C8: 539 | D8: 801 | E8: 713 | F8: 452 | G8: 128
A9: ERI | C9: 175
A10: GAB | B10: 0 | C10: 248 | D10: 258 | E10: 379 | F10: 224 | G10: 28
A11: GHA | B11: 2 | C11: 1715 | D11: 1942 | E11: 512 | F11: 184 | G11: 3
A12: GNB | B12: 0 | C12: 229 | D12: 143 | E12: 41 | F12: 19 | G12: 5
A13: KEN | B13: 5 | C13: 1600 | D13: 2699 | E13: 941 | F13: 243 | G13: 6
A14: MOZ | B14: 6 | C14: 784 | D14: 897 | E14: 416 | F14: 193 | G14: 50
A15: MWI | B15: 61 | C15: 392 | D15: 331 | E15: 213 | F15: 30 | G15: 13
A16: NGA | B16: 860 | C16: 21366 | D16: 19365 | E16: 8834 | F16: 3461 | G16: 1088
A17: SEN | B17: 1 | C17: 338 | D17: 247 | E17: 64 | F17: 48 | G17: 5
A18: SWZ | C18: 116 | D18: 691
A19: SYC | C19: 9 | D19: 15 | E19: 17 | F19: 9 | G19: 7
A20: TCD | B20: 3 | C20: 880 | D20: 424 | E20: 129 | F20: 73 | G20: 0
A21: TGO | B21: 3 | C21: 213 | D21: 267 | E21: 155 | F21: 64 | G21: 28
A22: ZMB | B22: 22 | C22: 1908 | D22: 1492 | E22: 966 | F22: 555 | G22: 299
A23: ZWE | B23: 0 | C23: 433 | D23: 1110 | E23: 1165 | F23: 0 | G23: 0
A25: Grand Total | B25: 1978 | C25: 71678 | D25: 70804 | E25: 33872 | F25: 13146 | G25: 3440

Sheet Sheet3
A3: Count of 2020 | B3: Column Labels
A4: Row Labels | B4: BEN | C4: BWA | D4: CIV | E4: CPV | F4: DZA | G4: ERI | H4: GHA | I4: KEN | J4: MDG | K4: MOZ | L4: MWI | M4: SLE | N4: SWZ | O4: SYC | P4: TGO | Q4: UGA | R4: ZAF | S4: ZMB | T4: ZWE | U4: (blank) | V4: Grand Total
A5: BDI | B5: 1 | V5: 1
A6: BFA | C6: 1 | V6: 1
A7: BWA | D7: 1 | V7: 1
A8: GAB | E8: 1 | V8: 1
A9: GHA | F9: 1 | V9: 1
A10: MOZ | G10: 1 | V10: 1
A11: SEN | H11: 1 | V11: 1
A12: TCD | I12: 1 | V12: 1
A13: (blank) | J13: 1 | K13: 1 | L13: 1 | V13: 3
A14: Grand Total | B14: 1 | C14: 1 | D14: 1 | E14: 1 | F14: 1 | G14: 1 | H14: 1 | I14: 1 | J14: 1 | K14: 1 | L14: 1 | V14: 11

Sheet available
B1: Data on age group availability
A2: Country | B2: Data year
A3: AGO
A4: BDI | B4: 2019
A5: BEN | B5: 2021
A6: BFA | B6: 2022
A7: BWA | B7: 2022
A8: CAF
A9: CIV | B9: 2022
A10: CMR | B10: 2022
A11: COD
A12: COG | B12: 2022
A13: COM
A14: CPV | B14: 2022
A15: DZA | B15: 2018
A16: ERI | B16: 2022
A17: ETH
A18: GAB | B18: 2022
A19: GHA | B19: 2022
A20: GIN
A21: GMB
A22: GNB | B22: 2022
A23: GNQ
A24: KEN | B24: 2022
A25: LBR
A26: LSO
A27: MDG | B27: 2018
A28: MLI
A29: MOZ | B29: 2022
A30: MRT
A31: MUS
A32: MWI | B32: 2022
A33: NAM
A34: NER
A35: NGA | B35: 2022
A36: RWA
A37: SEN | B37: 2022
A38: SLE | B38: 2020
A39: SSD
A40: STP
...

Sheet Medical doctors
D1: Numbers | J1: Proportions
A2: Country | B2: Medical Doctors Stock By Age Group < 25 yrs | C2: Medical Doctors Stock By Age Group 25-34 yrs | D2: Medical Doctors Stock By Age Group 35-44 yrs | E2: Medical Doctors Stock By Age Group 45-54 yrs | F2: Medical Doctors Stock By Age Group 55-64 yrs | G2: Medical Doctors Stock By Age Group ≥ 65 yrs | H2: Total | I2: Medical Doctors Stock By Age Group < 25 yrs | J2: Medical Doctors Stock By Age Group 25-34 yrs | K2: Medical Doctors Stock By Age Group 35-44 yrs | L2: Medical Doctors Stock By Age Group 45-54 yrs | M2: Medical Doctors Stock By Age Group 55-64 yrs | N2: Medical Doctors Stock By Age Group ≥ 65 yrs
A3: AFR | B3: 989 | C3: 35839 | D3: 35402 | E3: 16936 | F3: 6573 | G3: 1720 | H3: =SUM(B3:G3) -> 97459 | I3: =B3/H3 -> 0.010147857 | J3: =C3/H3 -> 0.36773412 | K3: =D3/H3 -> 0.36325019 | L3: =E3/H3 -> 0.17377564 | M3: =F3/H3 -> 0.067443746 | N3: =G3/H3 -> 0.017648447
A4: BFA | B4: 0 | C4: 1138 | D4: 1088 | E4: 112 | F4: 33 | G4: 1 | H4: =SUM(B4:G4) -> 2372 | I4: =B4/H4 -> 0 | J4: =C4/H4 -> 0.47976391 | K4: =D4/H4 -> 0.45868465 | L4: =E4/H4 -> 0.047217538 | M4: =F4/H4 -> 0.01391231 | N4: =G4/H4 -> 0.00042158516
A5: BWA | C5: 483 | D5: 323 | E5: 121 | F5: 52 | G5: 14 | H5: =SUM(B5:G5) -> 993 | I5: =B5/H5 -> 0 | J5: =C5/H5 -> 0.48640483 | K5: =D5/H5 -> 0.32527694 | L5: =E5/H5 -> 0.12185297 | M5: =F5/H5 -> 0.052366566 | N5: =G5/H5 -> 0.014098691
A6: CIV | B6: 0 | C6: 920 | D6: 1757 | E6: 1583 | F6: 640 | G6: 29 | H6: =SUM(B6:G6) -> 4929 | I6: =B6/H6 -> 0 | J6: =C6/H6 -> 0.18665044 | K6: =D6/H6 -> 0.35646176 | L6: =E6/H6 -> 0.32116048 | M6: =F6/H6 -> 0.12984378 | N6: =G6/H6 -> 0.0058835464
A7: CMR | B7: 15 | C7: 1889 | D7: 1240 | E7: 454 | F7: 156 | G7: 8 | H7: =SUM(B7:G7) -> 3762 | I7: =B7/H7 -> 0.0039872408 | J7: =C7/H7 -> 0.50212653 | K7: =D7/H7 -> 0.32961191 | L7: =E7/H7 -> 0.12068049 | M7: =F7/H7 -> 0.041467305 | N7: =G7/H7 -> 0.0021265284
A8: COG | C8: 464 | D8: 312 | E8: 121 | F8: 137 | G8: 8 | H8: =SUM(B8:G8) -> 1042 | I8: =B8/H8 -> 0 | J8: =C8/H8 -> 0.4452975 | K8: =D8/H8 -> 0.29942418 | L8: =E8/H8 -> 0.11612284 | M8: =F8/H8 -> 0.13147793 | N8: =G8/H8 -> 0.0076775432
A9: CPV | B9: 11 | C9: 539 | D9: 801 | E9: 713 | F9: 452 | G9: 128 | H9: =SUM(B9:G9) -> 2644 | I9: =B9/H9 -> 0.0041603631 | J9: =C9/H9 -> 0.20385779 | K9: =D9/H9 -> 0.30295008 | L9: =E9/H9 -> 0.26966717 | M9: =F9/H9 -> 0.1709531 | N9: =G9/H9 -> 0.048411498
A10: ERI | C10: 175 | H10: =SUM(B10:G10) -> 175 | I10: =B10/H10 -> 0 | J10: =C10/H10 -> 1 | K10: =D10/H10 -> 0 | L10: =E10/H10 -> 0 | M10: =F10/H10 -> 0 | N10: =G10/H10 -> 0
A11: GAB | B11: 0 | C11: 248 | D11: 258 | E11: 379 | F11: 224 | G11: 28 | H11: =SUM(B11:G11) -> 1137 | I11: =B11/H11 -> 0 | J11: =C11/H11 -> 0.21811785 | K11: =D11/H11 -> 0.22691293 | L11: =E11/H11 -> 0.33333333 | M11: =F11/H11 -> 0.19700967 | N11: =G11/H11 -> 0.024626209
A12: GHA | B12: 2 | C12: 1715 | D12: 1942 | E12: 512 | F12: 184 | G12: 3 | H12: =SUM(B12:G12) -> 4358 | I12: =B12/H12 -> 0.00045892611 | J12: =C12/H12 -> 0.39352914 | K12: =D12/H12 -> 0.44561726 | L12: =E12/H12 -> 0.11748508 | M12: =F12/H12 -> 0.042221202 | N12: =G12/H12 -> 0.00068838917
A13: GNB | B13: 0 | C13: 229 | D13: 143 | E13: 41 | F13: 19 | G13: 5 | H13: =SUM(B13:G13) -> 437 | I13: =B13/H13 -> 0 | J13: =C13/H13 -> 0.52402746 | K13: =D13/H13 -> 0.32723112 | L13: =E13/H13 -> 0.09382151 | M13: =F13/H13 -> 0.043478261 | N13: =G13/H13 -> 0.011441648
A14: KEN | B14: 5 | C14: 1600 | D14: 2699 | E14: 941 | F14: 243 | G14: 6 | H14: =SUM(B14:G14) -> 5494 | I14: =B14/H14 -> 0.00091008373 | J14: =C14/H14 -> 0.29122679 | K14: =D14/H14 -> 0.4912632 | L14: =E14/H14 -> 0.17127776 | M14: =F14/H14 -> 0.044230069 | N14: =G14/H14 -> 0.0010921005
A15: MOZ | B15: 6 | C15: 784 | D15: 897 | E15: 416 | F15: 193 | G15: 50 | H15: =SUM(B15:G15) -> 2346 | I15: =B15/H15 -> 0.0025575448 | J15: =C15/H15 -> 0.33418585 | K15: =D15/H15 -> 0.38235294 | L15: =E15/H15 -> 0.1773231 | M15: =F15/H15 -> 0.08226769 | N15: =G15/H15 -> 0.021312873
A16: MWI | B16: 61 | C16: 392 | D16: 331 | E16: 213 | F16: 30 | G16: 13 | H16: =SUM(B16:G16) -> 1040 | I16: =B16/H16 -> 0.058653846 | J16: =C16/H16 -> 0.37692308 | K16: =D16/H16 -> 0.31826923 | L16: =E16/H16 -> 0.20480769 | M16: =F16/H16 -> 0.028846154 | N16: =G16/H16 -> 0.0125
A17: NGA | B17: 860 | C17: 21366 | D17: 19365 | E17: 8834 | F17: 3461 | G17: 1088 | H17: =SUM(B17:G17) -> 54974 | I17: =B17/H17 -> 0.015643759 | J17: =C17/H17 -> 0.38865646 | K17: =D17/H17 -> 0.35225743 | L17: =E17/H17 -> 0.16069415 | M17: =F17/H17 -> 0.062957034 | N17: =G17/H17 -> 0.019791174
A18: SEN | B18: 1 | C18: 338 | D18: 247 | E18: 64 | F18: 48 | G18: 5 | H18: =SUM(B18:G18) -> 703 | I18: =B18/H18 -> 0.0014224751 | J18: =C18/H18 -> 0.48079659 | K18: =D18/H18 -> 0.35135135 | L18: =E18/H18 -> 0.091038407 | M18: =F18/H18 -> 0.068278805 | N18: =G18/H18 -> 0.0071123755
A19: SWZ | C19: 116 | D19: 691 | H19: =SUM(B19:G19) -> 807 | I19: =B19/H19 -> 0 | J19: =C19/H19 -> 0.14374226 | K19: =D19/H19 -> 0.85625774 | L19: =E19/H19 -> 0 | M19: =F19/H19 -> 0 | N19: =G19/H19 -> 0
A20: SYC | C20: 9 | D20: 15 | E20: 17 | F20: 9 | G20: 7 | H20: =SUM(B20:G20) -> 57 | I20: =B20/H20 -> 0 | J20: =C20/H20 -> 0.15789474 | K20: =D20/H20 -> 0.26315789 | L20: =E20/H20 -> 0.29824561 | M20: =F20/H20 -> 0.15789474 | N20: =G20/H20 -> 0.12280702
A21: TCD | B21: 3 | C21: 880 | D21: 424 | E21: 129 | F21: 73 | G21: 0 | H21: =SUM(B21:G21) -> 1509 | I21: =B21/H21 -> 0.0019880716 | J21: =C21/H21 -> 0.58316766 | K21: =D21/H21 -> 0.28098078 | L21: =E21/H21 -> 0.085487078 | M21: =F21/H21 -> 0.048376408 | N21: =G21/H21 -> 0
A22: TGO | B22: 3 | C22: 213 | D22: 267 | E22: 155 | F22: 64 | G22: 28 | H22: =SUM(B22:G22) -> 730 | I22: =B22/H22 -> 0.004109589 | J22: =C22/H22 -> 0.29178082 | K22: =D22/H22 -> 0.36575342 | L22: =E22/H22 -> 0.21232877 | M22: =F22/H22 -> 0.087671233 | N22: =G22/H22 -> 0.038356164
A23: ZMB | B23: 22 | C23: 1908 | D23: 1492 | E23: 966 | F23: 555 | G23: 299 | H23: =SUM(B23:G23) -> 5242 | I23: =B23/H23 -> 0.0041968714 | J23: =C23/H23 -> 0.36398321 | K23: =D23/H23 -> 0.28462419 | L23: =E23/H23 -> 0.18428081 | M23: =F23/H23 -> 0.10587562 | N23: =G23/H23 -> 0.057039298
A24: ZWE | B24: 0 | C24: 433 | D24: 1110 | E24: 1165 | F24: 0 | G24: 0 | H24: =SUM(B24:G24) -> 2708 | I24: =B24/H24 -> 0 | J24: =C24/H24 -> 0.1598966 | K24: =D24/H24 -> 0.4098966 | L24: =E24/H24 -> 0.43020679 | M24: =F24/H24 -> 0 | N24: =G24/H24 -> 0
A25: BEN | B25: 34 | C25: 1115 | D25: 916 | E25: 458 | F25: 221 | G25: 11 | H25: =SUM(B25:G25) -> 2755 | I25: =B25/H25 -> 0.012341198 | J25: =C25/H25 -> 0.40471869 | K25: =D25/H25 -> 0.33248639 | L25: =E25/H25 -> 0.16624319 | M25: =F25/H25 -> 0.080217786 | N25: =G25/H25 -> 0.0039927405
A26: SLE | C26: 150 | H26: =SUM(B26:G26) -> 150 | I26: =B26/H26 -> 0 | J26: =C26/H26 -> 1 | K26: =D26/H26 -> 0 | L26: =E26/H26 -> 0 | M26: =F26/H26 -> 0 | N26: =G26/H26 -> 0
A27: BDI | B27: 0 | C27: 149 | D27: 396 | E27: 61 | F27: 19 | G27: 4 | H27: =SUM(B27:G27) -> 629 | I27: =B27/H27 -> 0 | J27: =C27/H27 -> 0.23688394 | K27: =D27/H27 -> 0.62957075 | L27: =E27/H27 -> 0.096979332 | M27: =F27/H27 -> 0.030206677 | N27: =G27/H27 -> 0.0063593005
A28: DZA | B28: 5956 | C28: 21368 | D28: 15146 | E28: 10017 | F28: 12552 | G28: 7565 | H28: =SUM(B28:G28) -> 72604 | I28: =B28/H28 -> 0.082034048 | J28: =C28/H28 -> 0.29430885 | K28: =D28/H28 -> 0.2086111 | L28: =E28/H28 -> 0.13796761 | M28: =F28/H28 -> 0.17288304 | N28: =G28/H28 -> 0.10419536

Sheet Doctors distribution
A1: Country | B1: Medical Doctors Stock By Age Group < 25 yrs | C1: Medical Doctors Stock By Age Group 25-34 yrs | D1: Medical Doctors Stock By Age Group 35-44 yrs | E1: Medical Doctors Stock By Age Group 45-54 yrs | F1: Medical Doctors Stock By Age Group 55-64 yrs | G1: Medical Doctors Stock By Age Group ≥ 65 yrs
A2: AFRO | B2: 0.010147857 | C2: 0.36773412 | D2: 0.36325019 | E2: 0.17377564 | F2: 0.067443746 | G2: 0.017648447
A3: BFA | B3: 0 | C3: 0.47976391 | D3: 0.45868465 | E3: 0.047217538 | F3: 0.01391231 | G3: 0.00042158516
A4: BWA | B4: 0 | C4: 0.48640483 | D4: 0.32527694 | E4: 0.12185297 | F4: 0.052366566 | G4: 0.014098691
A5: CIV | B5: 0 | C5: 0.18665044 | D5: 0.35646176 | E5: 0.32116048 | F5: 0.12984378 | G5: 0.0058835464
A6: CMR | B6: 0.0039872408 | C6: 0.50212653 | D6: 0.32961191 | E6: 0.12068049 | F6: 0.041467305 | G6: 0.0021265284
A7: COG | B7: 0 | C7: 0.4452975 | D7: 0.29942418 | E7: 0.11612284 | F7: 0.13147793 | G7: 0.0076775432
A8: CPV | B8: 0.0041603631 | C8: 0.20385779 | D8: 0.30295008 | E8: 0.26966717 | F8: 0.1709531 | G8: 0.048411498
A9: ERI | B9: 0 | C9: 1 | D9: 0 | E9: 0 | F9: 0 | G9: 0
A10: GAB | B10: 0 | C10: 0.21811785 | D10: 0.22691293 | E10: 0.33333333 | F10: 0.19700967 | G10: 0.024626209
A11: GHA | B11: 0.00045892611 | C11: 0.39352914 | D11: 0.44561726 | E11: 0.11748508 | F11: 0.042221202 | G11: 0.00068838917
A12: GNB | B12: 0 | C12: 0.52402746 | D12: 0.32723112 | E12: 0.09382151 | F12: 0.043478261 | G12: 0.011441648
A13: KEN | B13: 0.00091008373 | C13: 0.29122679 | D13: 0.4912632 | E13: 0.17127776 | F13: 0.044230069 | G13: 0.0010921005
... A27: DZA | B27: 0.082034048 | C27: 0.29430885 | D27: 0.2086111 | E27: 0.13796761 | F27: 0.17288304 | G27: 0.10419536
A215: Income level | B215: Medical Doctors Stock By Age Group < 25 yrs | C215: Medical Doctors Stock By Age Group 25-34 yrs | D215: Medical Doctors Stock By Age Group 35-44 yrs | E215: Medical Doctors Stock By Age Group 45-54 yrs | F215: Medical Doctors Stock By Age Group 55-64 yrs | G215: Medical Doctors Stock By Age Group ≥ 65 yrs
A216: High/Upper-Middle-Income Economies | B216: 0 | C216: 0.28747247 | D216: 0.27178259 | E216: 0.25114397 | F216: 0.13575699 | G216: 0.053843973
A217: Lower-Middle-Income Economies | B217: 0.009627305 | C217: 0.3275993 | D217: 0.3862164 | E217: 0.1759096 | F217: 0.080800436 | G217: 0.019846966
A218: Low-Income Economies | B218: 0.0084136314 | C218: 0.47834159 | D218: 0.34535536 | E218: 0.11474563 | F218: 0.041844842 | G218: 0.011298946
A219: AFRO | B219: 0.010147857 | C219: 0.36773412 | D219: 0.36325019 | E219: 0.17377564 | F219: 0.067443746 | G219: 0.017648447

Sheet Income
A1: Country | B1: country code | C1: Income
A2: Algeria | B2: DZA | C2: Lower-Middle-Income Economies
A3: Angola | B3: AGO | C3: Lower-Middle-Income Economies
A4: Benin | B4: BEN | C4: Lower-Middle-Income Economies
A5: Botswana | B5: BWA | C5: High/Upper-Middle-Income Economies
A6: Burkina Faso | B6: BFA | C6: Low-Income Economies
A7: Burundi | B7: BDI | C7: Low-Income Economies
A8: Cameroon | B8: CMR | C8: Lower-Middle-Income Economies
A9: Cape-Verde | B9: CPV | C9: Lower-Middle-Income Economies
A10: Central African Republic | B10: CAF | C10: Low-Income Economies
A11: Chad | B11: TCD | C11: Low-Income Economies
A12: Comoros | B12: COM | C12: Lower-Middle-Income Economies
... A48: Zimbabwe | B48: ZWE | C48: Lower-Middle-Income Economies
A49: AFRO | B49: AFRO

Sheet Sheet10
A3: Row Labels | B3: Average of Medical Doctors Stock By Age Group < 25 yrs | C3: Average of Medical Doctors Stock By Age Group 25-34 yrs | D3: Average of Medical Doctors Stock By Age Group 35-44 yrs | E3: Average of Medical Doctors Stock By Age Group 45-54 yrs | F3: Average of Medical Doctors Stock By Age Group 55-64 yrs | G3: Average of Medical Doctors Stock By Age Group ≥ 65 yrs
A4: High/Upper-Middle-Income Economies | B4: 0 | C4: 0.28747247 | D4: 0.27178259 | E4: 0.25114397 | F4: 0.13575699 | G4: 0.053843973
A5: Lower-Middle-Income Economies | B5: 0.009627305 | C5: 0.3275993 | D5: 0.3862164 | E5: 0.1759096 | F5: 0.080800436 | G5: 0.019846966
A6: Low-Income Economies | B6: 0.0084136314 | C6: 0.47834159 | D6: 0.34535536 | E6: 0.11474563 | F6: 0.041844842 | G6: 0.011298946
A7: (blank) | B7: 0.010147857 | C7: 0.36773412 | D7: 0.36325019 | E7: 0.17377564 | F7: 0.067443746 | G7: 0.017648447
A8: Grand Total | B8: 0.0081044749 | C8: 0.37262701 | D8: 0.35849016 | E8: 0.16527989 | F8: 0.074395165 | G8: 0.0211033

Sheet Med 1
A1: Country | B1: Medical Doctors Stock By Age Group < 25 yrs | C1: Medical Doctors Stock By Age Group 25-34 yrs | D1: Medical Doctors Stock By Age Group 35-44 yrs | E1: Medical Doctors Stock By Age Group 45-54 yrs | F1: Medical Doctors Stock By Age Group 55-64 yrs | G1: Medical Doctors Stock By Age Group ≥ 65 yrs | H1: Income
A2: AFRO | B2: 0.010147857 | C2: 0.36773412 | D2: 0.36325019 | E2: 0.17377564 | F2: 0.067443746 | G2: 0.017648447
A3: BFA | B3: 0 | C3: 0.47976391 | D3: 0.45868465 | E3: 0.047217538 | F3: 0.01391231 | G3: 0.00042158516 | H3: Low-Income Economies
A4: BWA | B4: 0 | C4: 0.48640483 | D4: 0.32527694 | E4: 0.12185297 | F4: 0.052366566 | G4: 0.014098691 | H4: High/Upper-Middle-Income Economies
A5: CIV | B5: 0 | C5: 0.18665044 | D5: 0.35646176 | E5: 0.32116048 | F5: 0.12984378 | G5: 0.0058835464 | H5: Lower-Middle-Income Economies
A6: CMR | B6: 0.0039872408 | C6: 0.50212653 | D6: 0.32961191 | E6: 0.12068049 | F6: 0.041467305 | G6: 0.0021265284 | H6: Lower-Middle-Income Economies
A7: COG | B7: 0 | C7: 0.4452975 | D7: 0.29942418 | E7: 0.11612284 | F7: 0.13147793 | G7: 0.0076775432 | H7: Lower-Middle-Income Economies
A8: CPV | B8: 0.0041603631 | C8: 0.20385779 | D8: 0.30295008 | E8: 0.26966717 | F8: 0.1709531 | G8: 0.048411498 | H8: Lower-Middle-Income Economies
A9: GAB | B9: 0 | C9: 0.21811785 | D9: 0.22691293 | E9: 0.33333333 | F9: 0.19700967 | G9: 0.024626209 | H9: High/Upper-Middle-Income Economies
A10: GHA | B10: 0.00045892611 | C10: 0.39352914 | D10: 0.44561726 | E10: 0.11748508 | F10: 0.042221202 | G10: 0.00068838917 | H10: Lower-Middle-Income Economies
A11: GNB | B11: 0 | C11: 0.52402746 | D11: 0.32723112 | E11: 0.09382151 | F11: 0.043478261 | G11: 0.011441648 | H11: Low-Income Economies
A12: KEN | B12: 0.00091008373 | C12: 0.29122679 | D12: 0.4912632 | E12: 0.17127776 | F12: 0.044230069 | G12: 0.0010921005 | H12: Lower-Middle-Income Economies
A13: MOZ | B13: 0.0025575448 | C13: 0.33418585 | D13: 0.38235294 | E13: 0.1773231 | F13: 0.08226769 | G13: 0.021312873 | H13: Low-Income Economies
A14: MWI | B14: 0.058653846 | C14: 0.37692308 | D14: 0.31826923 | E14: 0.20480769 | F14: 0.028846154 | G14: 0.0125 | H14: Low-Income Economies
... A26: DZA | B26: 0.082034048 | C26: 0.29430885 | D26: 0.2086111 | E26: 0.13796761 | F26: 0.17288304 | G26: 0.10419536 | H26: Lower-Middle-Income Economies

Sheet Total medical doctors
A1: Country | B1: Country code | C1: income level | D1: 2013 | E1: 2018 | F1: Adjusted 2022 | G1: Medical Doctors Stock By Age Group < 25 yrs (prop) | H1: Medical Doctors Stock By Age Group 25-34 yrs (prop) | I1: Medical Doctors Stock By Age Group 35-44 yrs (prop) | J1: Medical Doctors Stock By Age Group 45-54 yrs (prop) | K1: Medical Doctors Stock By Age Group 55-64 yrs (prop) | L1: Medical Doctors Stock By Age Group ≥ 65 yrs (prop) | M1: Medical Doctors Stock By Age Group < 25 yrs (prop) | N1: Medical Doctors Stock By Age Group 25-34 yrs | O1: Medical Doctors Stock By Age Group 35-44 yrs | P1: Medical Doctors Stock By Age Group 45-54 yrs | Q1: Medical Doctors Stock By Age Group 55-64 yrs | R1: Medical Doctors Stock By Age Group ≥ 65 yrs | S1: Annual graduates (2017 survey) | T1: 2023 | U1: 2024 | V1: 2025 | W1: 2026 | X1: 2027 | Y1: 2028 | Z1: 2029 | AA1: 2030
A2: Algeria | B2: DZA | C2: Lower-Middle-Income Economies | D2: 0 | E2: 73168 | F2: 48033.824 | G2: 0.082034048 | H2: 0.29430885 | I2: 0.2086111 | J2: 0.13796761 | K2: 0.17288304 | L2: 0.10419536 | M2: =F2*G2 -> 3940.409 | N2: =F2*H2 -> 14136.78 | O2: =F2*I2 -> 10020.389 | P2: =F2*J2 -> 6627.1117 | Q2: =F2*K2 -> 8304.2334 | R2: =F2*L2 -> 5004.9017 | S2: =VLOOKUP(A2,'Education graduates'!$A$2:$E$49,5,FALSE) -> 0
A3: Angola | B3: AGO | C3: Lower-Middle-Income Economies | D3: 0 | E3: 6593 | F3: 8693 | G3: 0.009627305 | H3: 0.3275993 | I3: 0.3862164 | J3: 0.1759096 | K3: 0.080800436 | L3: 0.019846966 | M3: =F3*G3 -> 83.690162 | N3: =F3*H3 -> 2847.8207 | O3: =F3*I3 -> 3357.3792 | P3: =F3*J3 -> 1529.1821 | Q3: =F3*K3 -> 702.39819 | R3: =F3*L3 -> 172.52967 | S3: =VLOOKUP(A3,'Education graduates'!$A$3:$E$49,5,FALSE) -> 0
A4: Benin | B4: BEN | C4: Lower-Middle-Income Economies | D4: 0 | E4: 908 | F4: 2608 | G4: 0.012341198 | H4: 0.40471869 | I4: 0.33248639 | J4: 0.16624319 | K4: 0.080217786 | L4: 0.0039927405 | M4: =F4*G4 -> 32.185844 | N4: =F4*H4 -> 1055.5064 | O4: =F4*I4 -> 867.1245 | P4: =F4*J4 -> 433.56225 | Q4: =F4*K4 -> 209.20799 | R4: =F4*L4 -> 10.413067 | S4: =VLOOKUP(A4,'Education graduates'!$A$3:$E$49,5,FALSE) -> 291
A5: Botswana | B5: BWA | C5: High/Upper-Middle-Income Economies | D5: 819 | E5: 925 | F5: 992 | G5: 0 | H5: 0.48640483 | I5: 0.32527694 | J5: 0.12185297 | K5: 0.052366566 | L5: 0.014098691 | M5: =F5*G5 -> 0 | N5: =F5*H5 -> 482.5136 | O5: =F5*I5 -> 322.67472 | P5: =F5*J5 -> 120.87815 | Q5: =F5*K5 -> 51.947633 | R5: =F5*L5 -> 13.985901 | S5: =VLOOKUP(A5,'Education graduates'!$A$3:$E$49,5,FALSE) -> 8
A6: Burkina Faso | B6: BFA | C6: Low-Income Economies | D6: 803 | E6: 1684 | F6: 3323 | G6: 0 | H6: 0.47976391 | I6: 0.45868465 | J6: 0.047217538 | K6: 0.01391231 | L6: 0.00042158516 | M6: =F6*G6 -> 0 | N6: =F6*H6 -> 1594.2555 | O6: =F6*I6 -> 1524.2091 | P6: =F6*J6 -> 156.90388 | Q6: =F6*K6 -> 46.230607 | R6: =F6*L6 -> 1.4009275 | S6: =VLOOKUP(A6,'Education graduates'!$A$3:$E$49,5,FALSE) -> 578
A7: Burundi | B7: BDI | C7: Low-Income Economies | D7: 554 | E7: 1084 | F7: 1014.861 | G7: 0 | H7: 0.23688394 | I7: 0.62957075 | J7: 0.096979332 | K7: 0.030206677 | L7: 0.0063593005 | M7: =F7*G7 -> 0 | N7: =F7*H7 -> 240.40428 | O7: =F7*I7 -> 638.92682 | P7: =F7*J7 -> 98.420546 | Q7: =F7*K7 -> 30.65558 | R7: =F7*L7 -> 6.4538063 | S7: =VLOOKUP(A7,'Education graduates'!$A$3:$E$49,5,FALSE) -> 319
A8: Cameroon | B8: CMR | C8: Lower-Middle-Income Economies | D8: 1842 | E8: 3259 | F8: 3759 | G8: 0.0039872408 | H8: 0.50212653 | I8: 0.32961191 | J8: 0.12068049 | K8: 0.041467305 | L8: 0.0021265284 | M8: =F8*G8 -> 14.988038 | N8: =F8*H8 -> 1887.4936 | O8: =F8*I8 -> 1239.0112 | P8: =F8*J8 -> 453.63796 | Q8: =F8*K8 -> 155.8756 | R8: =F8*L8 -> 7.9936204 | S8: =VLOOKUP(A8,'Education graduates'!$A$3:$E$49,5,FALSE) -> 0
A9: Cape-Verde | B9: CPV | C9: Lower-Middle-Income Economies | D9: 308 | E9: 452 | F9: 2644 | G9: 0.0041603631 | H9: 0.20385779 | I9: 0.30295008 | J9: 0.26966717 | K9: 0.1709531 | L9: 0.048411498 | M9: =F9*G9 -> 11 | N9: =F9*H9 -> 539 | O9: =F9*I9 -> 801 | P9: =F9*J9 -> 713 | Q9: =F9*K9 -> 452 | R9: =F9*L9 -> 128 | S9: =VLOOKUP(A9,'Education graduates'!$A$3:$E$49,5,FALSE) -> 0
A10: Central African Republic | B10: CAF | C10: Low-Income Economies | D10: 324 | E10: 335 | F10: 146.38958 | G10: 0.0084136314 | H10: 0.47834159 | I10: 0.34535536 | J10: 0.11474563 | K10: 0.041844842 | L10: 0.011298946 | M10: =F10*G10 -> 1.231668 | N10: =F10*H10 -> 70.024224 | O10: =F10*I10 -> 50.556426 | P10: =F10*J10 -> 16.797564 | Q10: =F10*K10 -> 6.1256487 | R10: =F10*L10 -> 1.654048 | S10: =VLOOKUP(A10,'Education graduates'!$A$3:$E$49,5,FALSE) -> 0
A11: Chad | B11: TCD | C11: Low-Income Economies | D11: 573 | E11: 803 | F11: 1507 | G11: 0.0019880716 | H11: 0.58316766 | I11: 0.28098078 | J11: 0.085487078 | K11: 0.048376408 | L11: 0 | M11: =F11*G11 -> 2.9960239 | N11: =F11*H11 -> 878.83366 | O11: =F11*I11 -> 423.43804 | P11: =F11*J11 -> 128.82903 | Q11: =F11*K11 -> 72.903247 | R11: =F11*L11 -> 0 | S11: =VLOOKUP(A11,'Education graduates'!$A$3:$E$49,5,FALSE) -> 113
A12: Comoros | B12: COM | C12: Lower-Middle-Income Economies | D12: 123 | E12: 220 | F12: 354 | G12: 0.009627305 | H12: 0.3275993 | I12: 0.3862164 | J12: 0.1759096 | K12: 0.080800436 | L12: 0.019846966 | M12: =F12*G12 -> 3.408066 | N12: =F12*H12 -> 115.97015 | O12: =F12*I12 -> 136.72061 | P12: =F12*J12 -> 62.271998 | Q12: =F12*K12 -> 28.603354 | R12: =F12*L12 -> 7.0258259 | S12: =VLOOKUP(A12,'Education graduates'!$A$3:$E$49,5,FALSE) -> 0
A13: Congo | B13: COG | C13: Lower-Middle-Income Economies | D13: 0 | E13: 544 | F13: 1042 | G13: 0 | H13: 0.4452975 | I13: 0.29942418 | J13: 0.11612284 | K13: 0.13147793 | L13: 0.0076775432 | M13: =F13*G13 -> 0 | N13: =F13*H13 -> 464 | O13: =F13*I13 -> 312 | P13: =F13*J13 -> 121 | Q13: =F13*K13 -> 137 | R13: =F13*L13 -> 8 | S13: =VLOOKUP(A13,'Education graduates'!$A$3:$E$49,5,FALSE) -> 39
A14: Cote d'Ivoire | B14: CIV | C14: Lower-Middle-Income Economies | D14: 5240 | E14: 5602 | F14: 6327.552 | G14: 0 | H14: 0.18665044 | I14: 0.35646176 | J14: 0.32116048 | K14: 0.12984378 | L14: 0.0058835464 | M14: =F14*G14 -> 0 | N14: =F14*H14 -> 1181.0403 | O14: =F14*I14 -> 2255.5303 | P14: =F14*J14 -> 2032.1596 | Q14: =F14*K14 -> 821.59328 | R14: =F14*L14 -> 37.228445 | S14: =VLOOKUP(A14,'Education graduates'!$A$3:$E$49,5,FALSE) -> 265
... A48: Zimbabwe | B48: ZWE | C48: Lower-Middle-Income Economies | D48: 1114 | E48: 3026 | F48: 3131.5984 | G48: 0 | H48: 0.1598966 | I48: 0.4098966 | J48: 0.43020679 | K48: 0 | L48: 0 | M48: =F48*G48 -> 0 | N48: =F48*H48 -> 500.73194 | O48: =F48*I48 -> 1283.6315 | P48: =F48*J48 -> 1347.2349 | Q48: =F48*K48 -> 0 | R48: =F48*L48 -> 0 | S48: =VLOOKUP(A48,'Education graduates'!$A$3:$E$49,5,FALSE) -> 51
A49: AFRO | B49: AFRO | D49: 115272 | E49: 339167 | F49: 339063.33 | G49: 0.010147857 | H49: 0.36773412 | I49: 0.36325019 | J49: 0.17377564 | K49: 0.067443746 | L49: 0.017648447 | M49: =F49*G49 -> 3440.7662 | N49: =F49*H49 -> 124685.16 | O49: =F49*I49 -> 123164.82 | P49: =F49*J49 -> 58920.947 | Q49: =F49*K49 -> 22867.701 | R49: =F49*L49 -> 5983.9413 | S49: =VLOOKUP(A49,'Education graduates'!$A$3:$E$49,5,FALSE) -> 12194

Sheet Education graduates
A1: Counry | B1: Country code | C1: Generalist Medical Practitioners | D1: Specialist Medical Practitioners | E1: Medical doctors
A2: Algeria | B2: DZA | E2: 0
A3: Angola | B3: AGO | E3: =C3+D3 -> 0
A4: Benin | B4: BEN | C4: 173 | D4: 118 | E4: =C4+D4 -> 291
A5: Botswana | B5: BWA | C5: 8 | E5: =C5+D5 -> 8
A6: Burkina Faso | B6: BFA | C6: 325 | D6: 253 | E6: =C6+D6 -> 578
A7: Burundi | B7: BDI | C7: 319 | E7: =C7+D7 -> 319
A8: Cameroon | B8: CMR | E8: =C8+D8 -> 0
A9: Cape-Verde | B9: CPV | E9: =C9+D9 -> 0
A10: Central African Republic | B10: CAF | E10: =C10+D10 -> 0
A11: Chad | B11: TCD | C11: 107 | D11: 6 | E11: =C11+D11 -> 113
A12: Comoros | B12: COM | E12: 0
A13: Congo | B13: COG | C13: 39 | D13: 0 | E13: =C13+D13 -> 39
A14: Cote d'Ivoire | B14: CIV | C14: 254 | D14: 11 | E14: =C14+D14 -> 265
A15: DRC | B15: COD | D15: 27 | E15: =C15+D15 -> 27
A16: Equatorial Guinea | B16: GNQ
A17: Eritrea | B17: ERI | C17: 44 | D17: 1 | E17: =C17+D17 -> 45
A18: Eswatini | B18: SWZ | E18: =C18+D18 -> 0
A19: Ethiopia | B19: ETH | C19: 2895 | D19: 41 | E19: =C19+D19 -> 2936
A20: Gabon | B20: GAB | C20: 46 | D20: 16 | E20: =C20+D20 -> 62
A21: Gambia | B21: GMB | E21: =C21+D21 -> 0
A22: Ghana | B22: GHA | E22: =C22+D22 -> 0
A23: Guinea | B23: GIN | C23: 767 | D23: 74 | E23: =C23+D23 -> 841
A24: Guinea-Bissau | B24: GNB | C24: 69 | E24: =C24+D24 -> 69
A25: Kenya | B25: KEN | E25: 538
A26: Lesotho | B26: LSO | E26: =C26+D26 -> 0
A27: Liberia | B27: LBR | C27: 47 | D27: 15 | E27: =C27+D27 -> 62
A28: Madagascar | B28: MDG | C28: 367 | D28: 37 | E28: =C28+D28 -> 404
A29: Malawi | B29: MWI | C29: 101 | E29: =C29+D29 -> 101
A30: Mali | B30: MLI | E30: =C30+D30 -> 0
A31: Mauritania | B31: MRT | C31: 74 | D31: 13 | E31: =C31+D31 -> 87
A32: Mauritius | B32: MUS | E32: =C32+D32 -> 0
A33: Mozambique | B33: MOZ | E33: =C33+D33 -> 0
A34: Namibia | B34: NAM | C34: 70 | D34: 3 | E34: =C34+D34 -> 73
A35: Niger | B35: NER | C35: 196 | E35: =C35+D35 -> 196
A36: Nigeria | B36: NGA | C36: 3766 | E36: =C36+D36 -> 3766
A37: Rwanda | B37: RWA | E37: =C37+D37 -> 0
A38: Sao Tome and Principe | B38: STP
A39: Senegal | B39: SEN | E39: =C39+D39 -> 0
A40: Seychelles | B40: SYC
...
