Workbook
Name _Hlk24031923: Sheet2!$C$10
Name Cost_drivers: '[1]2_Cost drivers & standard cost'!$C$5:$C$40
Name Cost_reference_table: '[1]2_Cost drivers & standard cost'!$C$4:$U$40
Name Country_Name: '[1]1_Stratgies and interventions'!$L$9:$L$25
Name CPI: [1]CPI!$A$4:$M$269
Name Exchange_rate: [2]Basic_Inputs!$D$23
Name Official_exchange_rate: '[1]Official Xch rate'!$A$1:$I$19
Name OLE_LINK1: AFRO!$C$8
Name OLE_LINK1: 'ESA_Int$ PPP'!$C$8
Name OLE_LINK1: ESA_USD!$C$8
Name PPP_conversion_factor: '[1]Price PPP Conversion'!$A$2:$N$18
Name Strategic_Direction: '[1]1_Stratgies and interventions'!$D$9:$D$13
Name Threshohod_Low_density: '[3]Need and Supply'!$D$44
Name Zero_reduction: '[1]3_Main_Costing the Plan'!$M$4

Sheet Population 7 Sept 2021
A1: Data Source | B1: World Development Indicators
A2: Last Updated Date | B2: 44407
A4: Country Name | B4: Country Code | C4: Indicator Name | D4: Indicator Code | E4: 1960 | F4: 1961 | G4: 1962 | H4: 1963 | I4: 1964 | J4: 1965 | K4: 1966 | L4: 1967 | M4: 1968 | N4: 1969 | O4: 1970 | P4: 1971 | Q4: 1972 | R4: 1973 | S4: 1974 | T4: 1975 | U4: 1976 | V4: 1977 | W4: 1978 | X4: 1979 | Y4: 1980 | Z4: 1981 | AA4: 1982 | AB4: 1983 | AC4: 1984 | AD4: 1985 | AE4: 1986 | AF4: 1987 | AG4: 1988 | AH4: 1989 | AI4: 1990 | AJ4: 1991 | AK4: 1992 | AL4: 1993 | AM4: 1994 | AN4: 1995 | AO4: 1996 | AP4: 1997 | AQ4: 1998 | AR4: 1999 | AS4: 2000 | AT4: 2001 | AU4: 2002 | AV4: 2003 | AW4: 2004 | AX4: 2005 | AY4: 2006 | AZ4: 2007 | BA4: 2008 | BB4: 2009 | BC4: 2010 | BD4: 2011 | BE4: 2012 | BF4: 2013 | BG4: 2014 | BH4: 2015 | BI4: 2016 | BJ4: 2017 | BK4: 2018 | BL4: 2019 | BM4: 2020
A5: Aruba | B5: ABW | C5: Population, total | D5: SP.POP.TOTL | E5: 54208 | F5: 55434 | G5: 56234 | H5: 56699 | I5: 57029 | J5: 57357 | K5: 57702 | L5: 58044 | M5: 58377 | N5: 58734 | O5: 59070 | P5: 59442 | Q5: 59849 | R5: 60236 | S5: 60527 | T5: 60653 | U5: 60586 | V5: 60366 | W5: 60102 | X5: 59972 | Y5: 60097 | Z5: 60561 | AA5: 61341 | AB5: 62213 | AC5: 62826 | AD5: 63024 | AE5: 62645 | AF5: 61838 | AG5: 61072 | AH5: 61033 | AI5: 62152 | AJ5: 64623 | AK5: 68240 | AL5: 72495 | AM5: 76705 | AN5: 80324 | AO5: 83211 | AP5: 85450 | AQ5: 87280 | AR5: 89009 | AS5: 90866 | AT5: 92892 | AU5: 94992 | AV5: 97016 | AW5: 98744 | AX5: 100028 | AY5: 100830 | AZ5: 101226 | BA5: 101362 | BB5: 101452 | BC5: 101665 | BD5: 102050 | BE5: 102565 | BF5: 103165 | BG5: 103776 | BH5: 104339 | BI5: 104865 | BJ5: 105361 | BK5: 105846 | BL5: 106310 | BM5: 106766
A6: Africa Eastern and Southern | B6: AFE | C6: Population, total | D6: SP.POP.TOTL | E6: 130836765 | F6: 134159786 | G6: 137614644 | H6: 141202036 | I6: 144920186 | J6: 148769974 | K6: 152752671 | L6: 156876454 | M6: 161156430 | N6: 165611760 | O6: 170257189 | P6: 175100167 | Q6: 180141148 | R6: 185376550 | S6: 190800796 | T6: 196409937 | U6: 202205766 | V6: 208193045 | W6: 214368393 | X6: 220740384 | Y6: 227305945 | Z6: 234058404 | AA6: 240999134 | AB6: 248146290 | AC6: 255530063 | AD6: 263161451 | AE6: 271050065 | AF6: 279184536 | AG6: 287524258 | AH6: 296024639 | AI6: 304648010 | AJ6: 313394693 | AK6: 322270073 | AL6: 331265579 | AM6: 340379934 | AN6: 349605660 | AO6: 358953595 | AP6: 368440591 | AQ6: 378098393 | AR6: 387977990 | AS6: 398113044 | AT6: 408522129 | AU6: 419223717 | AV6: 430246635 | AW6: 441630149 | AX6: 453404076 | AY6: 465581372 | AZ6: 478166911 | BA6: 491173160 | BB6: 504604672 | BC6: 518468229 | BD6: 532760424 | BE6: 547482863 | BF6: 562601578 | BG6: 578075373 | BH6: 593871847 | BI6: 609978946 | BJ6: 626392880 | BK6: 643090131 | BL6: 660046272 | BM6: 677243299
A7: Afghanistan | B7: AFG | C7: Population, total | D7: SP.POP.TOTL | E7: 8996967 | F7: 9169406 | G7: 9351442 | H7: 9543200 | I7: 9744772 | J7: 9956318 | K7: 10174840 | L7: 10399936 | M7: 10637064 | N7: 10893772 | O7: 11173654 | P7: 11475450 | Q7: 11791222 | R7: 12108963 | S7: 12412960 | T7: 12689164 | U7: 12943093 | V7: 13171294 | W7: 13341199 | X7: 13411060 | Y7: 13356500 | Z7: 13171679 | AA7: 12882518 | AB7: 12537732 | AC7: 12204306 | AD7: 11938204 | AE7: 11736177 | AF7: 11604538 | AG7: 11618008 | AH7: 11868873 | AI7: 12412311 | AJ7: 13299016 | AK7: 14485543 | AL7: 15816601 | AM7: 17075728 | AN7: 18110662 | AO7: 18853444 | AP7: 19357126 | AQ7: 19737770 | AR7: 20170847 | AS7: 20779957 | AT7: 21606992 | AU7: 22600774 | AV7: 23680871 | AW7: 24726689 | AX7: 25654274 | AY7: 26433058 | AZ7: 27100542 | BA7: 27722281 | BB7: 28394806 | BC7: 29185511 | BD7: 30117411 | BE7: 31161378 | BF7: 32269592 | BG7: 33370804 | BH7: 34413603 | BI7: 35383028 | BJ7: 36296111 | BK7: 37171922 | BL7: 38041757 | BM7: 38928341
A8: Africa Western and Central | B8: AFW | C8: Population, total | D8: SP.POP.TOTL | E8: 96396419 | F8: 98407221 | G8: 100506960 | H8: 102691339 | I8: 104953470 | J8: 107289875 | K8: 109701811 | L8: 112195950 | M8: 114781116 | N8: 117468741 | O8: 120269044 | P8: 123184308 | Q8: 126218502 | R8: 129384954 | S8: 132699537 | T8: 136173544 | U8: 139813171 | V8: 143615715 | W8: 147571063 | X8: 151663853 | Y8: 155882270 | Z8: 160223588 | AA8: 164689764 | AB8: 169279422 | AC8: 173991851 | AD8: 178826553 | AE8: 183785612 | AF8: 188868567 | AG8: 194070079 | AH8: 199382783 | AI8: 204803865 | AJ8: 210332267 | AK8: 215976366 | AL8: 221754806 | AM8: 227692136 | AN8: 233807627 | AO8: 240114179 | AP8: 246613750 | AQ8: 253302310 | AR8: 260170348 | AS8: 267214544 | AT8: 274433894 | AU8: 281842480 | AV8: 289469530 | AW8: 297353098 | AX8: 305520588 | AY8: 313985474 | AZ8: 322741656 | BA8: 331772330 | BB8: 341050537 | BC8: 350556886 | BD8: 360285439 | BE8: 370243017 | BF8: 380437896 | BG8: 390882979 | BH8: 401586651 | BI8: 412551299 | BJ8: 423769930 | BK8: 435229381 | BL8: 446911598 | BM8: 458803476
A9: Angola | B9: AGO | C9: Population, total | D9: SP.POP.TOTL | E9: 5454938 | F9: 5531451 | G9: 5608499 | H9: 5679409 | I9: 5734995 | J9: 5770573 | K9: 5781305 | L9: 5774440 | M9: 5771973 | N9: 5803677 | O9: 5890360 | P9: 6041239 | Q9: 6248965 | R9: 6497283 | S9: 6761623 | T9: 7023994 | U9: 7279630 | V9: 7533814 | W9: 7790774 | X9: 8058112 | Y9: 8341290 | Z9: 8640478 | AA9: 8952971 | AB9: 9278104 | AC9: 9614756 | AD9: 9961993 | AE9: 10320116 | AF9: 10689247 | AG9: 11068051 | AH9: 11454784 | AI9: 11848385 | AJ9: 12248901 | AK9: 12657361 | AL9: 13075044 | AM9: 13503753 | AN9: 13945205 | AO9: 14400722 | AP9: 14871572 | AQ9: 15359600 | AR9: 15866871 | AS9: 16395477 | AT9: 16945753 | AU9: 17519418 | AV9: 18121477 | AW9: 18758138 | AX9: 19433604 | AY9: 20149905 | AZ9: 20905360 | BA9: 21695636 | BB9: 22514275 | BC9: 23356247 | BD9: 24220660 | BE9: 25107925 | BF9: 26015786 | BG9: 26941773 | BH9: 27884380 | BI9: 28842482 | BJ9: 29816769 | BK9: 30809787 | BL9: 31825299 | BM9: 32866268
A10: Albania | B10: ALB | C10: Population, total | D10: SP.POP.TOTL | E10: 1608800 | F10: 1659800 | G10: 1711319 | H10: 1762621 | I10: 1814135 | J10: 1864791 | K10: 1914573 | L10: 1965598 | M10: 2022272 | N10: 2081695 | O10: 2135479 | P10: 2187853 | Q10: 2243126 | R10: 2296752 | S10: 2350124 | T10: 2404831 | U10: 2458526 | V10: 2513546 | W10: 2566266 | X10: 2617832 | Y10: 2671997 | Z10: 2726056 | AA10: 2784278 | AB10: 2843960 | AC10: 2904429 | AD10: 2964762 | AE10: 3022635 | AF10: 3083605 | AG10: 3142336 | AH10: 3227943 | AI10: 3286542 | AJ10: 3266790 | AK10: 3247039 | AL10: 3227287 | AM10: 3207536 | AN10: 3187784 | AO10: 3168033 | AP10: 3148281 | AQ10: 3128530 | AR10: 3108778 | AS10: 3089027 | AT10: 3060173 | AU10: 3051010 | AV10: 3039616 | AW10: 3026939 | AX10: 3011487 | AY10: 2992547 | AZ10: 2970017 | BA10: 2947314 | BB10: 2927519 | BC10: 2913021 | BD10: 2905195 | BE10: 2900401 | BF10: 2895092 | BG10: 2889104 | BH10: 2880703 | BI10: 2876101 | BJ10: 2873457 | BK10: 2866376 | BL10: 2854191 | BM10: 2837743
A11: Andorra | B11: AND | C11: Population, total | D11: SP.POP.TOTL | E11: 13410 | F11: 14378 | G11: 15379 | H11: 16407 | I11: 17466 | J11: 18542 | K11: 19646 | L11: 20760 | M11: 21886 | N11: 23053 | O11: 24275 | P11: 25571 | Q11: 26885 | R11: 28232 | S11: 29515 | T11: 30705 | U11: 31782 | V11: 32769 | W11: 33744 | X11: 34825 | Y11: 36063 | Z11: 37498 | AA11: 39115 | AB11: 40854 | AC11: 42706 | AD11: 44593 | AE11: 46520 | AF11: 48459 | AG11: 50433 | AH11: 52452 | AI11: 54508 | AJ11: 56666 | AK11: 58882 | AL11: 60974 | AM11: 62676 | AN11: 63860 | AO11: 64363 | AP11: 64318 | AQ11: 64140 | AR11: 64368 | AS11: 65390 | AT11: 67344 | AU11: 70048 | AV11: 73180 | AW11: 76250 | AX11: 78871 | AY11: 80995 | AZ11: 82682 | BA11: 83860 | BB11: 84461 | BC11: 84454 | BD11: 83748 | BE11: 82427 | BF11: 80770 | BG11: 79213 | BH11: 77993 | BI11: 77295 | BJ11: 76997 | BK11: 77008 | BL11: 77146 | BM11: 77265
A12: Arab World | B12: ARB | C12: Population, total | D12: SP.POP.TOTL | E12: 92197715 | F12: 94724540 | G12: 97334438 | H12: 100034191 | I12: 102832792 | J12: 105736428 | K12: 108758634 | L12: 111899335 | M12: 115136161 | N12: 118437193 | O12: 121785630 | P12: 125164720 | Q12: 128598743 | R12: 132161302 | S12: 135952270 | T12: 140040580 | U12: 144453278 | V12: 149161836 | W12: 154111160 | X12: 159218539 | Y12: 164420771 | Z12: 169698978 | AA12: 175061794 | AB12: 180505967 | AC12: 186035280 | AD12: 191650328 | AE12: 197338140 | AF12: 203084958 | AG12: 208889669 | AH12: 214753965 | AI12: 222653371 | AJ12: 228731671 | AK12: 232956364 | AL12: 239243294 | AM12: 245449429 | AN12: 253107302 | AO12: 259000937 | AP12: 264822167 | AQ12: 270575777 | AR12: 276393809 | AS12: 282344141 | AT12: 288432153 | AU12: 294665202 | AV12: 301113869 | AW12: 307862846 | AX12: 314965776 | AY12: 322452764 | AZ12: 330290752 | BA12: 338395936 | BB12: 346629179 | BC12: 354890097 | BD12: 363156846 | BE12: 371437642 | BF12: 379696477 | BG12: 387899835 | BH12: 396028301 | BI12: 404042892 | BJ12: 411942825 | BK12: 419851989 | BL12: 427870273 | BM12: 436080728
A13: United Arab Emirates | B13: ARE | C13: Population, total | D13: SP.POP.TOTL | E13: 92417 | F13: 100801 | G13: 112112 | H13: 125130 | I13: 138049 | J13: 149855 | K13: 159979 | L13: 169768 | M13: 182620 | N13: 203103 | O13: 234512 | P13: 277463 | Q13: 330968 | R13: 394625 | S13: 467457 | T13: 548295 | U13: 637926 | V13: 735347 | W13: 835498 | X13: 931752 | Y13: 1019507 | Z13: 1096602 | AA13: 1164816 | AB13: 1228457 | AC13: 1293970 | AD13: 1366165 | AE13: 1446386 | AF13: 1533526 | AG13: 1627068 | AH13: 1725676 | AI13: 1828437 | AJ13: 1937159 | AK13: 2052892 | AL13: 2173135 | AM13: 2294377 | AN13: 2415099 | AO13: 2539121 | AP13: 2671361 | AQ13: 2813214 | AR13: 2966029 | AS13: 3134067 | AT13: 3302722 | AU13: 3478769 | AV13: 3711931 | AW13: 4068577 | AX13: 4588222 | AY13: 5300172 | AZ13: 6168846 | BA13: 7089486 | BB13: 7917368 | BC13: 8549998 | BD13: 8946778 | BE13: 9141598 | BF13: 9197908 | BG13: 9214182 | BH13: 9262896 | BI13: 9360975 | BJ13: 9487206 | BK13: 9630966 | BL13: 9770526 | BM13: 9890400
A14: Argentina | B14: ARG | C14: Population, total | D14: SP.POP.TOTL | E14: 20481781 | F14: 20817270 | G14: 21153042 | H14: 21488916 | I14: 21824427 | J14: 22159644 | K14: 22494031 | L14: 22828872 | M14: 23168268 | N14: 23517613 | O14: 23880564 | P14: 24259564 | Q14: 24653172 | R14: 25056475 | S14: 25462305 | T14: 25865775 | U14: 26264681 | V14: 26661397 | W14: 27061041 | X14: 27471046 | Y14: 27896532 | Z14: 28338514 | AA14: 28794550 | AB14: 29262049 | AC14: 29737097 | AD14: 30216284 | AE14: 30698964 | AF14: 31184411 | AG14: 31668939 | AH14: 32148137 | AI14: 32618648 | AJ14: 33079002 | AK14: 33529320 | AL14: 33970103 | AM14: 34402669 | AN14: 34828168 | AO14: 35246376 | AP14: 35657438 | AQ14: 36063451 | AR14: 36467218 | AS14: 36870796 | AT14: 37275644 | AU14: 37681743 | AV14: 38087866 | AW14: 38491970 | AX14: 38892924 | AY14: 39289876 | AZ14: 39684303 | BA14: 40080159 | BB14: 40482786 | BC14: 40788453 | BD14: 41261490 | BE14: 41733271 | BF14: 42202935 | BG14: 42669500 | BH14: 43131966 | BI14: 43590368 | BJ14: 44044811 | BK14: 44494502 | BL14: 44938712 | BM14: 45376763
A15: Armenia | B15: ARM | C15: Population, total | D15: SP.POP.TOTL | E15: 1874119 | F15: 1941498 | G15: 2009524 | H15: 2077584 | I15: 2145004 | J15: 2211316 | K15: 2276038 | L15: 2339133 | M15: 2401142 | N15: 2462938 | O15: 2525067 | P15: 2587716 | Q15: 2650484 | R15: 2712780 | S15: 2773750 | T15: 2832752 | U15: 2889583 | V15: 2944375 | W15: 2997419 | X15: 3049107 | Y15: 3099759 | Z15: 3148096 | AA15: 3193696 | AB15: 3238592 | AC15: 3285593 | AD15: 3335935 | AE15: 3392264 | AF15: 3451947 | AG15: 3504667 | AH15: 3536473 | AI15: 3538164 | AJ15: 3505249 | AK15: 3442820 | AL15: 3363111 | AM15: 3283664 | AN15: 3217349 | AO15: 3168213 | AP15: 3133081 | AQ15: 3108691 | AR15: 3089020 | AS15: 3069597 | AT15: 3050686 | AU15: 3033976 | AV15: 3017938 | AW15: 3000715 | AX15: 2981262 | AY15: 2958301 | AZ15: 2932615 | BA15: 2907615 | BB15: 2888094 | BC15: 2877314 | BD15: 2876536 | BE15: 2884239 | BF15: 2897593 | BG15: 2912403 | BH15: 2925559 | BI15: 2936147 | BJ15: 2944789 | BK15: 2951741 | BL15: 2957728 | BM15: 2963234
A16: American Samoa | B16: ASM | C16: Population, total | D16: SP.POP.TOTL | E16: 20127 | F16: 20605 | G16: 21246 | H16: 22029 | I16: 22850 | J16: 23675 | K16: 24473 | L16: 25235 | M16: 25980 | N16: 26698 | O16: 27362 | P16: 27982 | Q16: 28564 | R16: 29103 | S16: 29595 | T16: 30045 | U16: 30455 | V16: 30834 | W16: 31262 | X16: 31842 | Y16: 32648 | Z16: 33697 | AA16: 34969 | AB16: 36413 | AC16: 37946 | AD16: 39521 | AE16: 41114 | AF16: 42741 | AG16: 44346 | AH16: 45894 | AI16: 47351 | AJ16: 48682 | AK16: 49900 | AL16: 51025 | AM16: 52099 | AN16: 53158 | AO16: 54209 | AP16: 55227 | AQ16: 56180 | AR16: 57049 | AS16: 57816 | AT16: 58496 | AU16: 59077 | AV16: 59495 | AW16: 59684 | AX16: 59557 | AY16: 59109 | AZ16: 58367 | BA16: 57490 | BB16: 56675 | BC16: 56084 | BD16: 55755 | BE16: 55669 | BF16: 55717 | BG16: 55791 | BH16: 55806 | BI16: 55739 | BJ16: 55617 | BK16: 55461 | BL16: 55312 | BM16: 55197
... A73: Euro area | B73: EMU | C73: Population, total | D73: SP.POP.TOTL | E73: 265203956 | F73: 267621091 | G73: 270110063 | H73: 272655396 | I73: 275163380 | J73: 277650954 | K73: 279969050 | L73: 281974870 | M73: 283866408 | N73: 285778639 | O73: 287338854 | P73: 288923399 | Q73: 290874612 | R73: 292728242 | S73: 294399217 | T73: 295923529 | U73: 297251532 | V73: 298441848 | W73: 299652841 | X73: 300886487 | Y73: 302184216 | Z73: 303343114 | AA73: 304174261 | AB73: 304787497 | AC73: 305299144 | AD73: 305877743 | AE73: 306640636 | AF73: 307488377 | AG73: 308516476 | AH73: 309837575 | AI73: 311262608 | AJ73: 312708132 | AK73: 314162056 | AL73: 315449093 | AM73: 316366781 | AN73: 317181461 | AO73: 318003013 | AP73: 318761752 | AQ73: 319433985 | AR73: 320258891 | AS73: 321310789 | AT73: 322547874 | AU73: 324125339 | AV73: 325885957 | AW73: 327682513 | AX73: 329380417 | AY73: 330922785 | AZ73: 332645162 | BA73: 334274725 | BB73: 335360891 | BC73: 336151482 | BD73: 335419656 | BE73: 336159199 | BF73: 337302111 | BG73: 338462234 | BH73: 339488382 | BI73: 340481755 | BJ73: 341217243 | BK73: 341979171 | BL73: 342282081 | BM73: 342949773
A74: Eritrea | B74: ERI | C74: Population, total | D74: SP.POP.TOTL | E74: 1007586 | F74: 1033320 | G74: 1060489 | H74: 1088859 | I74: 1118152 | J74: 1148188 | K74: 1178875 | L74: 1210304 | M74: 1242633 | N74: 1276122 | O74: 1310947 | P74: 1347180 | Q74: 1384789 | R74: 1423749 | S74: 1463986 | T74: 1505438 | U74: 1547978 | V74: 1591622 | W74: 1636771 | X74: 1683932 | Y74: 1733423 | Z74: 1784557 | AA74: 1836825 | AB74: 1890556 | AC74: 1946299 | AD74: 2003942 | AE74: 2064803 | AF74: 2127421 | AG74: 2185607 | AH74: 2231144 | AI74: 2258649 | AJ74: 2266356 | AK74: 2257593 | AL74: 2238631 | AM74: 2218436 | AN74: 2204227 | AO74: 2196467 | AP74: 2195192 | AQ74: 2206439 | AR74: 2237412 | AS74: 2292413 | AT74: 2374721 | AU74: 2481059 | AV74: 2600972 | AW74: 2719809 | AX74: 2826653 | AY74: 2918209 | AZ74: 2996540 | BA74: 3062782 | BB74: 3119920 | BC74: 3170437 | BD74: 3213969
A75: Spain | B75: ESP | C75: Population, total | D75: SP.POP.TOTL | E75: 30455000 | F75: 30739250 | G75: 31023366 | H75: 31296651 | I75: 31609195 | J75: 31954292 | K75: 32283194 | L75: 32682947 | M75: 33113134 | N75: 33441054 | O75: 33814531 | P75: 34224490 | Q75: 34604469 | R75: 34988947 | S75: 35373335 | T75: 35757900 | U75: 36137812 | V75: 36511638 | W75: 36864898 | X75: 37191330 | Y75: 37491165 | Z75: 37758631 | AA75: 37986012 | AB75: 38171525 | AC75: 38330364 | AD75: 38469512 | AE75: 38584624 | AF75: 38684815 | AG75: 38766939 | AH75: 38827764 | AI75: 38867322 | AJ75: 38966376 | AK75: 39157685 | AL75: 39361262 | AM75: 39549108 | AN75: 39724050 | AO75: 39889852 | AP75: 40057389 | AQ75: 40223509 | AR75: 40386875 | AS75: 40567864 | AT75: 40850412 | AU75: 41431558 | AV75: 42187645 | AW75: 42921895 | AX75: 43653155 | AY75: 44397319 | AZ75: 45226803 | BA75: 45954106 | BB75: 46362946 | BC75: 46576897 | BD75: 46742697 | BE75: 46773055 | BF75: 46620045 | BG75: 46480882 | BH75: 46444832 | BI75: 46484062 | BJ75: 46593236 | BK75: 46797754 | BL75: 47133521 | BM75: 47351567
A76: Estonia | B76: EST | C76: Population, total | D76: SP.POP.TOTL | E76: 1211537 | F76: 1225077 | G76: 1241623 | H76: 1258857 | I76: 1277086 | J76: 1294566 | K76: 1308597 | L76: 1318946 | M76: 1331214 | N76: 1345249 | O76: 1360076 | P76: 1376955 | Q76: 1392518 | R76: 1405951 | S76: 1418169 | T76: 1429352 | U76: 1439576 | V76: 1450211 | W76: 1460188 | X76: 1468333 | Y76: 1477219 | Z76: 1487666 | AA76: 1498414 | AB76: 1508745 | AC76: 1518617 | AD76: 1528781 | AE76: 1540190 | AF76: 1552221 | AG76: 1561900 | AH76: 1568131 | AI76: 1569174 | AJ76: 1561314 | AK76: 1533091 | AL76: 1494128 | AM76: 1462514 | AN76: 1436634 | AO76: 1415594 | AP76: 1399535 | AQ76: 1386156 | AR76: 1390244 | AS76: 1396985 | AT76: 1388115 | AU76: 1379350 | AV76: 1370720 | AW76: 1362550 | AX76: 1354775 | AY76: 1346810 | AZ76: 1340680 | BA76: 1337090 | BB76: 1334515 | BC76: 1331475 | BD76: 1327439 | BE76: 1322696 | BF76: 1317997 | BG76: 1314545 | BH76: 1315407 | BI76: 1315790 | BJ76: 1317384 | BK76: 1321977 | BL76: 1326898 | BM76: 1331057
A77: Ethiopia | B77: ETH | C77: Population, total | D77: SP.POP.TOTL | E77: 22151284 | F77: 22671193 | G77: 23221385 | H77: 23798418 | I77: 24397010 | J77: 25013634 | K77: 25641040 | L77: 26280135 | M77: 26944386 | N77: 27652715 | O77: 28415080 | P77: 29248650 | Q77: 30140799 | R77: 31036670 | S77: 31861353 | T77: 32566855 | U77: 33128151 | V77: 33577240 | W77: 33993301 | X77: 34487806 | Y77: 35141703 | Z77: 35984531 | AA77: 36995246 | AB77: 38142679 | AC77: 39374346 | AD77: 40652146 | AE77: 41965696 | AF77: 43329238 | AG77: 44757205 | AH77: 46272308 | AI77: 47887864 | AJ77: 49609976 | AK77: 51423591 | AL77: 53295556 | AM77: 55180993 | AN77: 57047906 | AO77: 58883531 | AP77: 60697443 | AQ77: 62507724 | AR77: 64343008 | AS77: 66224809 | AT77: 68159422 | AU77: 70142090 | AV77: 72170581 | AW77: 74239508 | AX77: 76346310 | AY77: 78489205 | AZ77: 80674343 | BA77: 82916236 | BB77: 85233923 | BC77: 87639962 | BD77: 90139928 | BE77: 92726982 | BF77: 95385793 | BG77: 98094264 | BH77: 100835453 | BI77: 103603461 | BJ77: 106399926 | BK77: 109224410 | BL77: 112078727 | BM77: 114963583
A78: European Union | B78: EUU | C78: Population, total | D78: SP.POP.TOTL | E78: 356906098 | F78: 359998408 | G78: 363200480 | H78: 366516509 | I78: 369850237 | J78: 373032729 | K78: 376039129 | L78: 378917964 | M78: 381605442 | N78: 384216977 | O78: 386322917 | P78: 388391948 | Q78: 390995000 | R78: 393524745 | S78: 395949381 | T78: 398316579 | U78: 400473497 | V78: 402425493 | W78: 404271789 | X78: 406051882 | Y78: 407875838 | Z78: 409551911 | AA78: 410895608 | AB78: 411974424 | AC78: 412931321 | AD78: 413924499 | AE78: 415076367 | AF78: 416301843 | AG78: 417653046 | AH78: 419073139 | AI78: 420477999 | AJ78: 421730520 | AK78: 422963890 | AL78: 424341124 | AM78: 425399126 | AN78: 426203356 | AO78: 426896861 | AP78: 427538048 | AQ78: 428109867 | AR78: 428815486 | AS78: 429328622 | AT78: 429895628 | AU78: 430881947 | AV78: 432415932 | AW78: 434040244 | AX78: 435581949 | AY78: 436998045 | AZ78: 438468397 | BA78: 439876674 | BB78: 440917801 | BC78: 441532415 | BD78: 440746989 | BE78: 441395937 | BF78: 442469469 | BG78: 443576675 | BH78: 444543761 | BI78: 445487730 | BJ78: 446186344 | BK78: 446915113 | BL78: 447196538 | BM78: 447794691
A79: Fragile and conflict affected situations | B79: FCS | C79: Population, total | D79: SP.POP.TOTL | E79: 208280083 | F79: 213082100 | G79: 218087139 | H79: 223284589 | I79: 228670583 | J79: 234243249 | K79: 240005133 | L79: 245962230 | M79: 252116419 | N79: 258473157 | O79: 265037231 | P79: 271800288 | Q79: 278767597 | R79: 285961194 | S79: 293417700 | T79: 301154406 | U79: 309196463 | V79: 317520801 | W79: 326050578 | X79: 334679714 | Y79: 343334222 | Z79: 352006783 | AA79: 360736356 | AB79: 369569548 | AC79: 378570396 | AD79: 387802210 | AE79: 397235010 | AF79: 406892515 | AG79: 416947257 | AH79: 427617018 | AI79: 440937023 | AJ79: 453319269 | AK79: 466482751 | AL79: 480128168 | AM79: 493815711 | AN79: 507247502 | AO79: 520303326 | AP79: 533112558 | AQ79: 545728172 | AR79: 558627550 | AS79: 572303917 | AT79: 586760366 | AU79: 601848734 | AV79: 617468591 | AW79: 633460044 | AX79: 649704454 | AY79: 666174377 | AZ79: 682901570 | BA79: 700030438 | BB79: 717553793 | BC79: 735448194 | BD79: 753858934 | BE79: 772742559 | BF79: 791943328 | BG79: 811249811 | BH79: 830536041 | BI79: 849739853 | BJ79: 868954263 | BK79: 888488369 | BL79: 908739462 | BM79: 930006546
A80: Finland | B80: FIN | C80: Population, total | D80: SP.POP.TOTL | E80: 4429634 | F80: 4461005 | G80: 4491443 | H80: 4523309 | I80: 4548543 | J80: 4563732 | K80: 4580869 | L80: 4605744 | M80: 4626469 | N80: 4623785 | O80: 4606307 | P80: 4612124 | Q80: 4639657 | R80: 4666081 | S80: 4690574 | T80: 4711440 | U80: 4725664 | V80: 4738902 | W80: 4752528 | X80: 4764690 | Y80: 4779535 | Z80: 4799964 | AA80: 4826933 | AB80: 4855787 | AC80: 4881803 | AD80: 4902206 | AE80: 4918154 | AF80: 4932123 | AG80: 4946481 | AH80: 4964371 | AI80: 4986431 | AJ80: 5013740 | AK80: 5041992 | AL80: 5066447 | AM80: 5088333 | AN80: 5107790 | AO80: 5124573 | AP80: 5139835 | AQ80: 5153498 | AR80: 5165474 | AS80: 5176209 | AT80: 5188008 | AU80: 5200598 | AV80: 5213014 | AW80: 5228172 | AX80: 5246096 | AY80: 5266268 | AZ80: 5288720 | BA80: 5313399 | BB80: 5338871 | BC80: 5363352 | BD80: 5388272 | BE80: 5413971 | BF80: 5438972 | BG80: 5461512 | BH80: 5479531 | BI80: 5495303 | BJ80: 5508214 | BK80: 5515525 | BL80: 5521606 | BM80: 5530719
A81: Fiji | B81: FJI | C81: Population, total | D81: SP.POP.TOTL | E81: 393480 | F81: 407244 | G81: 421673 | H81: 436303 | I81: 450538 | J81: 463960 | K81: 476399 | L81: 487973 | M81: 498944 | N81: 509708 | O81: 520561 | P81: 531622 | Q81: 542843 | R81: 554143 | S81: 565418 | T81: 576626 | U81: 587561 | V81: 598299 | W81: 609383 | X81: 621584 | Y81: 635312 | Z81: 651032 | AA81: 668281 | AB81: 685497 | AC81: 700478 | AD81: 711770 | AE81: 718642 | AF81: 721776 | AG81: 722924 | AH81: 724602 | AI81: 728575 | AJ81: 735398 | AK81: 744470 | AL81: 754962 | AM81: 765607 | AN81: 775428 | AO81: 784389 | AP81: 792736 | AQ81: 800148 | AR81: 806302 | AS81: 811011 | AT81: 813923 | AU81: 815257 | AV81: 816078 | AW81: 817864 | AX81: 821606 | AY81: 827869 | AZ81: 836185 | BA81: 845356 | BB81: 853636 | BC81: 859816 | BD81: 863451 | BE81: 865065 | BF81: 865602 | BG81: 866447 | BH81: 868632 | BI81: 872406 | BJ81: 877460 | BK81: 883490 | BL81: 889955 | BM81: 896444
A82: France | B82: FRA | C82: Population, total | D82: SP.POP.TOTL | E82: 46621688 | F82: 47240526 | G82: 47904879 | H82: 48582624 | I82: 49230585 | J82: 49818019 | K82: 50330268 | L82: 50775788 | M82: 51175507 | N82: 51561833 | O82: 51957747 | P82: 52371320 | Q82: 52793151 | R82: 53207744 | S82: 53592235 | T82: 53931390 | U82: 54220033 | V82: 54467709 | W82: 54691866 | X82: 54917110 | Y82: 55161510 | Z82: 55430278 | AA82: 55718940 | AB82: 56023775 | AC82: 56337675 | AD82: 56654703 | AE82: 56976126 | AF82: 57302642 | AG82: 57627106 | AH82: 57940199 | AI82: 58235716 | AJ82: 58559309 | AK82: 58851216 | AL82: 59106758 | AM82: 59327200 | AN82: 59541904 | AO82: 59753095 | AP82: 59964841 | AQ82: 60186284 | AR82: 60496708 | AS82: 60912500 | AT82: 61357432 | AU82: 61805266 | AV82: 62244880 | AW82: 62704901 | AX82: 63179356 | AY82: 63621376 | AZ82: 64016227 | BA82: 64374979 | BB82: 64707035 | BC82: 65027505 | BD82: 65342789 | BE82: 65659814 | BF82: 65998685 | BG82: 66312067 | BH82: 66548272 | BI82: 66724104 | BJ82: 66918020 | BK82: 67101930 | BL82: 67248926 | BM82: 67391582
A83: Faroe Islands | B83: FRO | C83: Population, total | D83: SP.POP.TOTL | E83: 34624 | F83: 35074 | G83: 35521 | H83: 35965 | I83: 36409 | J83: 36843 | K83: 37283 | L83: 37705 | M83: 38131 | N83: 38560 | O83: 39008 | P83: 39456 | Q83: 39915 | R83: 40395 | S83: 40847 | T83: 41292 | U83: 41724 | V83: 42133 | W83: 42539 | X83: 42941 | Y83: 43339 | Z83: 43725 | AA83: 44101 | AB83: 44483 | AC83: 44895 | AD83: 45328 | AE83: 45812 | AF83: 46340 | AG83: 46833 | AH83: 47159 | AI83: 47276 | AJ83: 47123 | AK83: 46746 | AL83: 46277 | AM83: 45848 | AN83: 45625 | AO83: 45624 | AP83: 45789 | AQ83: 46094 | AR83: 46428 | AS83: 46738 | AT83: 46999 | AU83: 47235 | AV83: 47439 | AW83: 47600 | AX83: 47731 | AY83: 47793 | AZ83: 47825 | BA83: 47822 | BB83: 47814 | BC83: 47803 | BD83: 47815 | BE83: 47843 | BF83: 47901 | BG83: 47965 | BH83: 48055 | BI83: 48173 | BJ83: 48326 | BK83: 48497 | BL83: 48677 | BM83: 48865
A84: Micronesia, Fed. Sts. | B84: FSM | C84: Population, total | D84: SP.POP.TOTL | E84: 44510 | F84: 45939 | G84: 47372 | H84: 48856 | I84: 50476 | J84: 52224 | K84: 54192 | L84: 56308 | M84: 58386 | N84: 60146 | O84: 61415 | P84: 62089 | Q84: 62275 | R84: 62268 | S84: 62456 | T84: 63122 | U84: 64360 | V84: 66079 | W84: 68196 | X84: 70515 | Y84: 72936 | Z84: 75422 | AA84: 78015 | AB84: 80630 | AC84: 83192 | AD84: 85641 | AE84: 87904 | AF84: 89985 | AG84: 91984 | AH84: 94062 | AI84: 96304 | AJ84: 98779 | AK84: 101386 | AL84: 103901 | AM84: 106030 | AN84: 107535 | AO84: 108311 | AP84: 108473 | AQ84: 108206 | AR84: 107769 | AS84: 107405 | AT84: 107170 | AU84: 107027 | AV84: 106902 | AW84: 106624 | AX84: 106135 | AY84: 105374 | AZ84: 104442 | BA84: 103549 | BB84: 102971 | BC84: 102916 | BD84: 103448 | BE84: 104506 | BF84: 105922 | BG84: 107444 | BH84: 108886 | BI84: 110215 | BJ84: 111461 | BK84: 112640 | BL84: 113811 | BM84: 115021
A85: Gabon | B85: GAB | C85: Population, total | D85: SP.POP.TOTL | E85: 500922 | F85: 505793 | G85: 511285 | H85: 517573 | I85: 524891 | J85: 533357 | K85: 543119 | L85: 554054 | M85: 565763 | N85: 577644 | O85: 589317 | P85: 600608 | Q85: 611705 | R85: 622914 | S85: 634739 | T85: 647538 | U85: 661398 | V85: 676264 | W85: 692078 | X85: 708788 | Y85: 726335 | Z85: 744695 | AA85: 763932 | AB85: 784056 | AC85: 805117 | AD85: 827107 | AE85: 850052 | AF85: 873871 | AG85: 898472 | AH85: 923714 | AI85: 949493 | AJ85: 975785 | AK85: 1002573 | AL85: 1029769 | AM85: 1057252 | AN85: 1084951 | AO85: 1112944 | AP85: 1141332 | AQ85: 1170061 | AR85: 1199058 | AS85: 1228359 | AT85: 1258008 | AU85: 1288310 | AV85: 1319946 | AW85: 1353788 | AX85: 1390550 | AY85: 1430144 | AZ85: 1472565 | BA85: 1518538 | BB85: 1568925 | BC85: 1624146 | BD85: 1684629 | BE85: 1749677 | BF85: 1817070 | BG85: 1883801 | BH85: 1947690 | BI85: 2007882 | BJ85: 2064812 | BK85: 2119275 | BL85: 2172578 | BM85: 2225728
A86: United Kingdom | B86: GBR | C86: Population, total | D86: SP.POP.TOTL | E86: 52400000 | F86: 52800000 | G86: 53250000 | H86: 53650000 | I86: 54000000 | J86: 54348050 | K86: 54648500 | L86: 54943600 | M86: 55211700 | N86: 55441750 | O86: 55663250 | P86: 55896223 | Q86: 56086065 | R86: 56194527 | S86: 56229974 | T86: 56225800 | U86: 56211968 | V86: 56193492 | W86: 56196504 | X86: 56246951 | Y86: 56314216 | Z86: 56333829 | AA86: 56313641 | AB86: 56332848 | AC86: 56422072 | AD86: 56550268 | AE86: 56681396 | AF86: 56802050 | AG86: 56928327 | AH86: 57076711 | AI86: 57247586 | AJ86: 57424897 | AK86: 57580402 | AL86: 57718614 | AM86: 57865745 | AN86: 58019030 | AO86: 58166950 | AP86: 58316954 | AQ86: 58487141 | AR86: 58682466 | AS86: 58892514 | AT86: 59119673 | AU86: 59370479 | AV86: 59647577 | AW86: 59987905 | AX86: 60401206 | AY86: 60846820 | AZ86: 61322463 | BA86: 61806995 | BB86: 62276270 | BC86: 62766365 | BD86: 63258810 | BE86: 63700215 | BF86: 64128273 | BG86: 64602298 | BH86: 65116219 | BI86: 65611593 | BJ86: 66058859 | BK86: 66460344 | BL86: 66836327 | BM86: 67215293
... A114: India | B114: IND | C114: Population, total | D114: SP.POP.TOTL | E114: 450547675 | F114: 459642166 | G114: 469077191 | H114: 478825602 | I114: 488848139 | J114: 499123328 | K114: 509631509 | L114: 520400577 | M114: 531513834 | N114: 543084333 | O114: 555189797 | P114: 567868021 | Q114: 581087255 | R114: 594770136 | S114: 608802595 | T114: 623102900 | U114: 637630085 | V114: 652408766 | W114: 667499815 | X114: 682995348 | Y114: 698952837 | Z114: 715384997 | AA114: 732239498 | AB114: 749428958 | AC114: 766833411 | AD114: 784360012 | AE114: 801975250 | AF114: 819682095 | AG114: 837468938 | AH114: 855334675 | AI114: 873277799 | AJ114: 891273202 | AK114: 909307018 | AL114: 927403866 | AM114: 945601828 | AN114: 963922586 | AO114: 982365248 | AP114: 1000900028 | AQ114: 1019483586 | AR114: 1038058154 | AS114: 1056575548 | AT114: 1075000094 | AU114: 1093317187 | AV114: 1111523146 | AW114: 1129623466 | AX114: 1147609924 | AY114: 1165486291 | AZ114: 1183209471 | BA114: 1200669762 | BB114: 1217726217 | BC114: 1234281163 | BD114: 1250287939 | BE114: 1265780243 | BF114: 1280842119 | BG114: 1295600768 | BH114: 1310152392 | BI114: 1324517250 | BJ114: 1338676779 | BK114: 1352642283 | BL114: 1366417756 | BM114: 1380004385
A115: Not classified | B115: INX | C115: Population, total | D115: SP.POP.TOTL
A116: Ireland | B116: IRL | C116: Population, total | D116: SP.POP.TOTL | E116: 2828600 | F116: 2824400 | G116: 2836050 | H116: 2852650 | I116: 2866550 | J116: 2877300 | K116: 2888800 | L116: 2902450 | M116: 2915550 | N116: 2932650 | O116: 2957250 | P116: 2992050 | Q116: 3036850 | R116: 3085950 | S116: 3137500 | T116: 3189550 | U116: 3238050 | V116: 3282200 | W116: 3329100 | X116: 3373750 | Y116: 3412800 | Z116: 3453000 | AA116: 3485800 | AB116: 3510600 | AC116: 3532423 | AD116: 3538082 | AE116: 3539690 | AF116: 3540057 | AG116: 3524949 | AH116: 3511009 | AI116: 3513974 | AJ116: 3534235 | AK116: 3558430 | AL116: 3576261 | AM116: 3590386 | AN116: 3608841 | AO116: 3637510 | AP116: 3674171 | AQ116: 3712696 | AR116: 3754786 | AS116: 3805174 | AT116: 3866243 | AU116: 3931947 | AV116: 3996521 | AW116: 4070262 | AX116: 4159914 | AY116: 4273591 | AZ116: 4398942 | BA116: 4489544 | BB116: 4535375 | BC116: 4560155 | BD116: 4580084 | BE116: 4599533 | BF116: 4623816 | BG116: 4657740 | BH116: 4701957 | BI116: 4755335 | BJ116: 4807388 | BK116: 4867316 | BL116: 4934340 | BM116: 4994724
A117: Iran, Islamic Rep. | B117: IRN | C117: Population, total | D117: SP.POP.TOTL | E117: 21906909 | F117: 22480371 | G117: 23071309 | H117: 23680246 | I117: 24307855 | J117: 24954865 | K117: 25624380 | L117: 26317776 | M117: 27032576 | N117: 27764928 | O117: 28513872 | P117: 29281583 | Q117: 30075295 | R117: 30905721 | S117: 31786481 | T117: 32729772 | U117: 33733975 | V117: 34803041 | W117: 35960811 | X117: 37237145 | Y117: 38650244 | Z117: 40199911 | AA117: 41869231 | AB117: 43636838 | AC117: 45472792 | AD117: 47347197 | AE117: 49260263 | AF117: 51193782 | AG117: 53077312 | AH117: 54822005 | AI117: 56366212 | AJ117: 57679025 | AK117: 58780376 | AL117: 59723761 | AM117: 60590608 | AN117: 61442658 | AO117: 62294919 | AP117: 63136309 | AQ117: 63971836 | AR117: 64800875 | AS117: 65623397 | AT117: 66449111 | AU117: 67284801 | AV117: 68122947 | AW117: 68951279 | AX117: 69762345 | AY117: 70554756 | AZ117: 71336476 | BA117: 72120608 | BB117: 72924833 | BC117: 73762519 | BD117: 74634959 | BE117: 75539881 | BF117: 76481963 | BG117: 77465769 | BH117: 78492208 | BI117: 79563991 | BJ117: 80673888 | BK117: 81800204 | BL117: 82913893 | BM117: 83992953
A118: Iraq | B118: IRQ | C118: Population, total | D118: SP.POP.TOTL | E118: 7289753 | F118: 7475349 | G118: 7674217 | H118: 7888910 | I118: 8122199 | J118: 8375795 | K118: 8651162 | L118: 8947397 | M118: 9260687 | N118: 9585585 | O118: 9917978 | P118: 10255853 | Q118: 10599661 | R118: 10950888 | S118: 11312062 | T118: 11684579 | U118: 12068675 | V118: 12462059 | W118: 12860678 | X118: 13259107 | Y118: 13653348 | Z118: 14044115 | AA118: 14432466 | AB118: 14815653 | AC118: 15190396 | AD118: 15555807 | AE118: 15909764 | AF118: 16257072 | AG118: 16612319 | AH118: 16994942 | AI118: 17419113 | AJ118: 17889457 | AK118: 18402740 | AL118: 18955087 | AM118: 19539348 | AN118: 20149342 | AO118: 20783073 | AP118: 21439579 | AQ118: 22114330 | AR118: 22802061 | AS118: 23497589 | AT118: 24208178 | AU118: 24931922 | AV118: 25644503 | AW118: 26313838 | AX118: 26922279 | AY118: 27448124 | AZ118: 27911242 | BA118: 28385739 | BB118: 28973157 | BC118: 29741977 | BD118: 30725305 | BE118: 31890012 | BF118: 33157061 | BG118: 34411949 | BH118: 35572269 | BI118: 36610632 | BJ118: 37552789 | BK118: 38433604 | BL118: 39309789 | BM118: 40222503
A119: Iceland | B119: ISL | C119: Population, total | D119: SP.POP.TOTL | E119: 175574 | F119: 179029 | G119: 182378 | H119: 185653 | I119: 188983 | J119: 192286 | K119: 195570 | L119: 198751 | M119: 201488 | N119: 203369 | O119: 204438 | P119: 206098 | Q119: 209137 | R119: 212317 | S119: 215209 | T119: 217979 | U119: 220154 | V119: 221799 | W119: 223537 | X119: 225735 | Y119: 228138 | Z119: 230755 | AA119: 233860 | AB119: 236977 | AC119: 239511 | AD119: 241405 | AE119: 243180 | AF119: 245859 | AG119: 249740 | AH119: 252852 | AI119: 254826 | AJ119: 257797 | AK119: 261057 | AL119: 263725 | AM119: 266021 | AN119: 267468 | AO119: 268916 | AP119: 271128 | AQ119: 274047 | AR119: 277381 | AS119: 281205 | AT119: 284968 | AU119: 287523 | AV119: 289521 | AW119: 292074 | AX119: 296734 | AY119: 303782 | AZ119: 311566 | BA119: 317414 | BB119: 318499 | BC119: 318041 | BD119: 319014 | BE119: 320716 | BF119: 323764 | BG119: 327386 | BH119: 330815 | BI119: 335439 | BJ119: 343400 | BK119: 352721 | BL119: 360563 | BM119: 366425
A120: Israel | B120: ISR | C120: Population, total | D120: SP.POP.TOTL | E120: 2114020 | F120: 2185000 | G120: 2293000 | H120: 2379000 | I120: 2475000 | J120: 2563000 | K120: 2629000 | L120: 2745000 | M120: 2803000 | N120: 2877000 | O120: 2974000 | P120: 3069000 | Q120: 3148000 | R120: 3278000 | S120: 3377000 | T120: 3455000 | U120: 3533000 | V120: 3613000 | W120: 3690000 | X120: 3786000 | Y120: 3878000 | Z120: 3956000 | AA120: 4031000 | AB120: 4105000 | AC120: 4159000 | AD120: 4233000 | AE120: 4299000 | AF120: 4369000 | AG120: 4442000 | AH120: 4518000 | AI120: 4660000 | AJ120: 4949000 | AK120: 5123000 | AL120: 5261000 | AM120: 5399000 | AN120: 5545000 | AO120: 5692000 | AP120: 5836000 | AQ120: 5971000 | AR120: 6125000 | AS120: 6289000 | AT120: 6439000 | AU120: 6570000 | AV120: 6689700 | AW120: 6809000 | AX120: 6930100 | AY120: 7053700 | AZ120: 7180100 | BA120: 7308800 | BB120: 7485600 | BC120: 7623600 | BD120: 7765800 | BE120: 7910500 | BF120: 8059500 | BG120: 8215700 | BH120: 8380100 | BI120: 8546000 | BJ120: 8713300 | BK120: 8882800 | BL120: 9054000 | BM120: 9216900
A121: Italy | B121: ITA | C121: Population, total | D121: SP.POP.TOTL | E121: 50199700 | F121: 50536350 | G121: 50879450 | H121: 51252000 | I121: 51675350 | J121: 52112350 | K121: 52519000 | L121: 52900500 | M121: 53235750 | N121: 53537950 | O121: 53821850 | P121: 54073490 | Q121: 54381345 | R121: 54751406 | S121: 55110868 | T121: 55441001 | U121: 55718260 | V121: 55955411 | W121: 56155143 | X121: 56317749 | Y121: 56433883 | Z121: 56501675 | AA121: 56543548 | AB121: 56564074 | AC121: 56576718 | AD121: 56593071 | AE121: 56596155 | AF121: 56601931 | AG121: 56629288 | AH121: 56671781 | AI121: 56719240 | AJ121: 56758521 | AK121: 56797087 | AL121: 56831821 | AM121: 56843400 | AN121: 56844303 | AO121: 56860281 | AP121: 56890372 | AQ121: 56906744 | AR121: 56916317 | AS121: 56942108 | AT121: 56974100 | AU121: 57059007 | AV121: 57313203 | AW121: 57685327 | AX121: 57969484 | AY121: 58143979 | AZ121: 58438310 | BA121: 58826731 | BB121: 59095365 | BC121: 59277417 | BD121: 59379449 | BE121: 59539717 | BF121: 60233948 | BG121: 60789140 | BH121: 60730582 | BI121: 60627498 | BJ121: 60536709 | BK121: 60421760 | BL121: 59729081 | BM121: 59554023
A122: Jamaica | B122: JAM | C122: Population, total | D122: SP.POP.TOTL | E122: 1628524 | F122: 1651067 | G122: 1676500 | H122: 1703660 | I122: 1730739 | J122: 1756508 | K122: 1780522 | L122: 1803324 | M122: 1825873 | N122: 1849658 | O122: 1875637 | P122: 1904281 | Q122: 1935089 | R122: 1966978 | S122: 1998313 | T122: 2028019 | U122: 2055371 | V122: 2080824 | W122: 2105903 | X122: 2132784 | Y122: 2162839 | Z122: 2196921 | AA122: 2234062 | AB122: 2271735 | AC122: 2306367 | AD122: 2335510 | AE122: 2358165 | AF122: 2375400 | AG122: 2389415 | AH122: 2403464 | AI122: 2419901 | AJ122: 2439329 | AK122: 2461047 | AL122: 2484583 | AM122: 2509042 | AN122: 2533705 | AO122: 2558631 | AP122: 2583914 | AQ122: 2608874 | AR122: 2632677 | AS122: 2654698 | AT122: 2674706 | AU122: 2692843 | AV122: 2709438 | AW122: 2725017 | AX122: 2740000 | AY122: 2754414 | AZ122: 2768229 | BA122: 2781869 | BB122: 2795839 | BC122: 2810464 | BD122: 2825932 | BE122: 2842128 | BF122: 2858710 | BG122: 2875137 | BH122: 2891024 | BI122: 2906242 | BJ122: 2920848 | BK122: 2934853 | BL122: 2948277 | BM122: 2961161
A123: Jordan | B123: JOR | C123: Population, total | D123: SP.POP.TOTL | E123: 933102 | F123: 973983 | G123: 1010647 | H123: 1050212 | I123: 1102404 | J123: 1173603 | K123: 1267063 | L123: 1378995 | M123: 1500168 | N123: 1617427 | O123: 1721315 | P123: 1809193 | Q123: 1883923 | R123: 1948443 | S123: 2007735 | T123: 2065916 | U123: 2123180 | V123: 2179361 | W123: 2237936 | X123: 2303116 | Y123: 2377997 | Z123: 2464870 | AA123: 2563525 | AB123: 2671413 | AC123: 2784457 | AD123: 2900055 | AE123: 3015294 | AF123: 3131800 | AG123: 3256552 | AH123: 3399333 | AI123: 3565888 | AJ123: 3760493 | AK123: 3977667 | AL123: 4201559 | AM123: 4410357 | AN123: 4588842 | AO123: 4732848 | AP123: 4848536 | AQ123: 4943975 | AR123: 5031754 | AS123: 5122495 | AT123: 5217328 | AU123: 5317514 | AV123: 5434036 | AW123: 5580241 | AX123: 5765639 | AY123: 5991547 | AZ123: 6255290 | BA123: 6556473 | BB123: 6893258 | BC123: 7261541 | BD123: 7662858 | BE123: 8089963 | BF123: 8518992 | BG123: 8918822 | BH123: 9266573 | BI123: 9554286 | BJ123: 9785840 | BK123: 9965322 | BL123: 10101697 | BM123: 10203140
A124: Japan | B124: JPN | C124: Population, total | D124: SP.POP.TOTL | E124: 93216000 | F124: 94055000 | G124: 94933000 | H124: 95900000 | I124: 96903000 | J124: 97952000 | K124: 98851000 | L124: 99879000 | M124: 101011000 | N124: 102219000 | O124: 103403000 | P124: 105697000 | Q124: 107188000 | R124: 108707000 | S124: 110162000 | T124: 111573000 | U124: 112775000 | V124: 113872000 | W124: 114913000 | X124: 115890000 | Y124: 116807000 | Z124: 117661000 | AA124: 118480000 | AB124: 119307000 | AC124: 120083000 | AD124: 120837000 | AE124: 121482000 | AF124: 122069000 | AG124: 122578000 | AH124: 123069000 | AI124: 123478000 | AJ124: 123964000 | AK124: 124425000 | AL124: 124829000 | AM124: 125178000 | AN124: 125472000 | AO124: 125757000 | AP124: 126057000 | AQ124: 126400000 | AR124: 126631000 | AS124: 126843000 | AT124: 127149000 | AU124: 127445000 | AV124: 127718000 | AW124: 127761000 | AX124: 127773000 | AY124: 127854000 | AZ124: 128001000 | BA124: 128063000 | BB124: 128047000 | BC124: 128070000 | BD124: 127833000 | BE124: 127629000 | BF124: 127445000 | BG124: 127276000 | BH124: 127141000 | BI124: 126994511 | BJ124: 126785797 | BK124: 126529100 | BL124: 126264931 | BM124: 125836021
...

Sheet GDP per capita 7 sept 2021
A1: Data Source | B1: World Development Indicators
A2: Last Updated Date | B2: 44407
A4: Country Name | B4: Country Code | C4: Indicator Name | D4: Indicator Code | E4: 1960 | F4: 1961 | G4: 1962 | H4: 1963 | I4: 1964 | J4: 1965 | K4: 1966 | L4: 1967 | M4: 1968 | N4: 1969 | O4: 1970 | P4: 1971 | Q4: 1972 | R4: 1973 | S4: 1974 | T4: 1975 | U4: 1976 | V4: 1977 | W4: 1978 | X4: 1979 | Y4: 1980 | Z4: 1981 | AA4: 1982 | AB4: 1983 | AC4: 1984 | AD4: 1985 | AE4: 1986 | AF4: 1987 | AG4: 1988 | AH4: 1989 | AI4: 1990 | AJ4: 1991 | AK4: 1992 | AL4: 1993 | AM4: 1994 | AN4: 1995 | AO4: 1996 | AP4: 1997 | AQ4: 1998 | AR4: 1999 | AS4: 2000 | AT4: 2001 | AU4: 2002 | AV4: 2003 | AW4: 2004 | AX4: 2005 | AY4: 2006 | AZ4: 2007 | BA4: 2008 | BB4: 2009 | BC4: 2010 | BD4: 2011 | BE4: 2012 | BF4: 2013 | BG4: 2014 | BH4: 2015 | BI4: 2016 | BJ4: 2017 | BK4: 2018 | BL4: 2019 | BM4: 2020
A5: Aruba | B5: ABW | C5: GDP per capita (current US$) | D5: NY.GDP.PCAP.CD | AE5: 6472.3987 | AF5: 7885.1589 | AG5: 9765.9092 | AH5: 11392.269 | AI5: 12306.718 | AJ5: 13495.794 | AK5: 14045.475 | AL5: 14938.682 | AM5: 16239.988 | AN5: 16439.356 | AO5: 16583.876 | AP5: 17927.959 | AQ5: 19077.687 | AR5: 19355.334 | AS5: 20617.75 | AT5: 20670.367 | AU5: 20436.887 | AV5: 20833.976 | AW5: 22568.375 | AX5: 23300.738 | AY5: 24046.226 | AZ5: 25834.112 | BA5: 27083.635 | BB5: 24631.182 | BC5: 23513.528 | BD5: 24985.014 | BE5: 24712.493 | BF5: 26441.62 | BG5: 26893.012 | BH5: 28396.908 | BI5: 28452.171 | BJ5: 29350.805 | BK5: 30253.279
A6: Africa Eastern and Southern | B6: AFE | C6: GDP per capita (current US$) | D6: NY.GDP.PCAP.CD | E6: 147.45037 | F6: 146.8537 | G6: 156.01793 | H6: 182.04409 | I6: 162.16958 | J6: 180.0173 | K6: 190.63622 | L6: 192.12627 | M6: 203.7834 | N6: 227.65871 | O6: 236.53378 | P6: 253.72845 | Q6: 267.83732 | R6: 339.38725 | S6: 409.66854 | T6: 424.33738 | U6: 411.06239 | V6: 455.7539 | W6: 495.54662 | X6: 563.38452 | Y6: 687.80039 | Z6: 684.45394 | AA6: 641.08015 | AB6: 643.09782 | AC6: 570.82052 | AD6: 495.12113 | AE6: 541.83335 | AF6: 643.09569 | AG6: 656.62646 | AH6: 656.46575 | AI6: 696.22389 | AJ6: 703.65468 | AK6: 682.58685 | AL6: 665.24293 | AM6: 659.5899 | AN6: 722.16972 | AO6: 701.7342 | AP6: 718.85428 | AQ6: 660.47197 | AR6: 635.14337 | AS6: 672.20547 | AT6: 591.08844 | AU6: 589.20682 | AV6: 757.44976 | AW6: 916.60337 | AX6: 1037.7271 | AY6: 1142.9559 | AZ6: 1278.9713 | BA6: 1356.5299 | BB6: 1326.2515 | BC6: 1550.1212 | BD6: 1682.2873 | BE6: 1667.9926 | BF6: 1648.8675 | BG6: 1654.3149 | BH6: 1503.8593 | BI6: 1401.2811 | BJ6: 1536.2068 | BK6: 1530.1619 | BL6: 1481.4253 | BM6: 1326.6637
A7: Afghanistan | B7: AFG | C7: GDP per capita (current US$) | D7: NY.GDP.PCAP.CD | E7: 59.773234 | F7: 59.8609 | G7: 58.458009 | H7: 78.706429 | I7: 82.095307 | J7: 101.10833 | K7: 137.5943 | L7: 160.89843 | M7: 129.10831 | N7: 129.32976 | O7: 156.51877 | P7: 159.56751 | Q7: 135.31723 | R7: 143.14465 | S7: 173.65362 | T7: 186.51084 | U7: 197.44551 | V7: 224.225 | W7: 247.35409 | X7: 275.73812 | Y7: 272.65551 | Z7: 264.1112 | AU7: 179.42658 | AV7: 190.68381 | AW7: 211.38207 | AX7: 242.03131 | AY7: 263.7336 | AZ7: 359.69316 | BA7: 364.66068 | BB7: 438.07614 | BC7: 543.30297 | BD7: 591.1628 | BE7: 641.87144 | BF7: 637.16546 | BG7: 613.85651 | BH7: 578.46635 | BI7: 509.2201 | BJ7: 519.88891 | BK7: 493.75658 | BL7: 507.10339 | BM7: 508.80841
A8: Africa Western and Central | B8: AFW | C8: GDP per capita (current US$) | D8: NY.GDP.PCAP.CD | E8: 107.96378 | F8: 113.1147 | G8: 118.86584 | H8: 123.47897 | I8: 131.89294 | J8: 138.56682 | K8: 144.36839 | L8: 128.62005 | M8: 129.679 | N8: 143.75764 | O8: 195.49068 | P8: 169.16853 | Q8: 200.22691 | R8: 241.78208 | S8: 333.28988 | T8: 377.89846 | U8: 444.5043 | V8: 454.92309 | W8: 482.6185 | X8: 584.54479 | Y8: 718.90192 | Z8: 1317.3165 | AA8: 1136.7947 | AB8: 816.13929 | AC8: 656.90478 | AD8: 651.70046 | AE8: 585.07829 | AF8: 584.29005 | AG8: 561.5256 | AH8: 510.56835 | AI8: 594.8996 | AJ8: 558.59904 | AK8: 547.82307 | AL8: 438.26231 | AM8: 376.35492 | AN8: 459.3649 | AO8: 495.77904 | AP8: 486.52302 | AQ8: 484.09074 | AR8: 500.43618 | AS8: 502.03166 | AT8: 516.92793 | AU8: 605.06101 | AV8: 681.88236 | AW8: 826.81654 | AX8: 988.83939 | AY8: 1224.0576 | AZ8: 1400.086 | BA8: 1666.8998 | BB8: 1444.2019 | BC8: 1655.1301 | BD8: 1827.5183 | BE8: 1936.391 | BF8: 2123.3924 | BG8: 2166.7433 | BH8: 1886.2482 | BI8: 1666.4224 | BJ8: 1606.9783 | BK8: 1695.9592 | BL8: 1772.3392 | BM8: 1714.4268
A9: Angola | B9: AGO | C9: GDP per capita (current US$) | D9: NY.GDP.PCAP.CD | Y9: 711.40958 | Z9: 642.7682 | AA9: 620.33312 | AB9: 623.81536 | AC9: 638.09901 | AD9: 758.74506 | AE9: 685.72813 | AF9: 756.76793 | AG9: 792.83302 | AH9: 891.14928 | AI9: 948.33818 | AM9: 251.07835 | AN9: 398.791 | AO9: 522.67962 | AP9: 514.38517 | AQ9: 423.61905 | AR9: 387.78512 | AS9: 556.83863 | AT9: 527.33353 | AU9: 872.49444 | AV9: 982.96101 | AW9: 1255.5645 | AX9: 1902.4221 | AY9: 2599.5659 | AZ9: 3121.9961 | BA9: 4080.941 | BB9: 3122.7816 | BC9: 3587.8836 | BD9: 4615.4682 | BE9: 5100.097 | BF9: 5254.8811 | BG9: 5408.4117 | BH9: 4166.9798 | BI9: 3506.0731 | BJ9: 4095.8101 | BK9: 3289.644 | BL9: 2809.6261 | BM9: 1895.7709
A10: Albania | B10: ALB | C10: GDP per capita (current US$) | D10: NY.GDP.PCAP.CD | AC10: 639.48474 | AD10: 639.86591 | AE10: 693.87347 | AF10: 674.79338 | AG10: 652.77432 | AH10: 697.9956 | AI10: 617.23044 | AJ10: 336.58699 | AK10: 200.85222 | AL10: 367.27923 | AM10: 586.41634 | AN10: 750.60445 | AO10: 1009.9777 | AP10: 717.38057 | AQ10: 813.79026 | AR10: 1033.2417 | AS10: 1126.6833 | AT10: 1281.6594 | AU10: 1425.1248 | AV10: 1846.1188 | AW10: 2373.5798 | AX10: 2673.7873 | AY10: 2972.7433 | AZ10: 3595.0372 | BA10: 4370.5401 | BB10: 4114.1401 | BC10: 4094.3503 | BD10: 4437.1429 | BE10: 4247.63 | BF10: 4413.0609 | BG10: 4578.632 | BH10: 3952.8012 | BI10: 4124.0557 | BJ10: 4531.0208 | BK10: 5284.3802 | BL10: 5355.8478 | BM10: 5215.2768
A11: Andorra | B11: AND | C11: GDP per capita (current US$) | D11: NY.GDP.PCAP.CD | O11: 3238.6903 | P11: 3496.532 | Q11: 4218.2716 | R11: 5342.1686 | S11: 6320.8096 | T11: 7169.101 | U11: 7151.2499 | V11: 7751.8433 | W11: 9127.8123 | X11: 11818.473 | Y11: 12378.785 | Z11: 10372.786 | AA11: 9610.0206 | AB11: 8025.2076 | AC11: 7728.9067 | AD11: 7775.6142 | AE11: 10361.148 | AF11: 12615.126 | AG11: 14304.641 | AH11: 15165.281 | AI11: 18878.852 | AJ11: 19534.264 | AK11: 20549.806 | AL11: 16515.658 | AM11: 16235.068 | AN11: 18458.174 | AO11: 19016.288 | AP11: 18355.628 | AQ11: 18895.111 | AR11: 19262.309 | AS11: 21854.247 | AT11: 22970.512 | AU11: 25067.24 | AV11: 32272.846 | AW11: 37966.187 | AX11: 40064.225 | AY11: 42674.759 | AZ11: 47804.85 | BA11: 48719.659 | BB11: 43504.216 | BC11: 40850.248 | BD11: 43334.811 | BE11: 38686.461 | BF11: 39540.725 | BG11: 41303.929 | BH11: 35770.777 | BI11: 37475.635 | BJ11: 38964.904 | BK11: 41791.97 | BL11: 40897.331
A12: Arab World | B12: ARB | C12: GDP per capita (current US$) | D12: NY.GDP.PCAP.CD | M12: 307.58698 | N12: 328.31931 | O12: 359.54699 | P12: 404.8275 | Q12: 469.97402 | R12: 578.69526 | S12: 1063.5455 | T12: 1143.7612 | U12: 1377.5607 | V12: 1536.2292 | W12: 1632.7983 | X12: 2138.8245 | Y12: 2802.4945 | Z12: 2801.1605 | AA12: 2549.4076 | AB12: 2324.8461 | AC12: 2288.0868 | AD12: 2198.4671 | AE12: 2038.4897 | AF12: 2112.0715 | AG12: 2019.8272 | AH12: 2060.1615 | AI12: 2750.9603 | AJ12: 1857.8212 | AK12: 1952.8882 | AL12: 1925.1132 | AM12: 1930.0025 | AN12: 2044.926 | AO12: 2191.2017 | AP12: 2309.3705 | AQ12: 2182.0079 | AR12: 2377.023 | AS12: 2678.3145 | AT12: 2536.7863 | AU12: 2484.8452 | AV12: 2696.0469 | AW12: 3134.8725 | AX12: 3765.9273 | AY12: 4360.0642 | AZ12: 4963.7 | BA12: 6149.7118 | BB12: 5180.5555 | BC12: 5948.6743 | BD12: 6870.0986 | BE12: 7455.0419 | BF12: 7505.1742 | BG12: 7436.5801 | BH12: 6346.0323 | BI12: 6093.331 | BJ12: 6095.6634 | BK12: 6568.9841 | BL12: 6570.1742 | BM12: 5802.1041
A13: United Arab Emirates | B13: ARE | C13: GDP per capita (current US$) | D13: NY.GDP.PCAP.CD | T13: 26848.088 | U13: 30117.949 | V13: 33823.182 | W13: 28457.078 | X13: 33512.633 | Y13: 42764.541 | Z13: 44987.538 | AA13: 40025.823 | AB13: 34843.16 | AC13: 32309.833 | AD13: 29720.898 | AE13: 23467.879 | AF13: 23726.307 | AG13: 22295.119 | AH13: 24028.262 | AI13: 27729.391 | AJ13: 26612.253 | AK13: 26420.86 | AL13: 25596.739 | AM13: 25848.016 | AN13: 27221.934 | AO13: 28975.08 | AP13: 29512.675 | AQ13: 26899.602 | AR13: 28470.886 | AS13: 33291.366 | AT13: 31280.756 | AU13: 31567.546 | AV13: 33499.103 | AW13: 36333.187 | AX13: 39365.46 | AY13: 41907.421 | AZ13: 41809.462 | BA13: 44498.941 | BB13: 32024.198 | BC13: 33893.264 | BD13: 39194.672 | BE13: 40976.491 | BF13: 42412.64 | BG13: 43751.806 | BH13: 38663.401 | BI13: 38141.867 | BJ13: 40644.791 | BK13: 43839.324 | BL13: 43103.336
A14: Argentina | B14: ARG | C14: GDP per capita (current US$) | D14: NY.GDP.PCAP.CD | G14: 1155.8907 | H14: 850.30458 | I14: 1173.2381 | J14: 1279.1138 | K14: 1272.8032 | L14: 1062.5434 | M14: 1141.0804 | N14: 1329.0585 | O14: 1322.5906 | P14: 1372.3742 | Q14: 1408.8654 | R14: 2097.0228 | S14: 2844.8633 | T14: 2027.3372 | U14: 1948.2247 | V14: 2129.7084 | W14: 2146.365 | X14: 2520.9207 | Y14: 2758.8348 | Z14: 2776.3221 | AA14: 2927.8974 | AB14: 3553.3775 | AC14: 2659.7082 | AD14: 2926.1265 | AE14: 3613.6217 | AF14: 3562.8761 | AG14: 3985.1925 | AH14: 2383.8675 | AI14: 4333.4834 | AJ14: 5735.36 | AK14: 6823.5388 | AL14: 6969.1197 | AM14: 7483.1403 | AN14: 7408.7087 | AO14: 7721.3541 | AP14: 8213.1251 | AQ14: 8289.5076 | AR14: 7774.7362 | AS14: 7708.0991 | AT14: 7208.3731 | AU14: 2593.4046 | AV14: 3349.8063 | AW14: 4277.7216 | AX14: 5109.8522 | AY14: 5919.0123 | AZ14: 7245.4469 | BA14: 9020.8733 | BB14: 8225.1376 | BC14: 10385.964 | BD14: 12848.864 | BE14: 13082.664 | BF14: 13080.255 | BG14: 12334.798 | BH14: 13789.06 | BI14: 12790.242 | BJ14: 14613.042 | BK14: 11633.498 | BL14: 9912.2818 | BM14: 8441.9194
A15: Armenia | B15: ARM | C15: GDP per capita (current US$) | D15: NY.GDP.PCAP.CD | AI15: 637.85592 | AJ15: 590.50588 | AK15: 369.70723 | AL15: 357.20285 | AM15: 400.51559 | AN15: 456.37493 | AO15: 504.05984 | AP15: 523.28441 | AQ15: 609.17165 | AR15: 597.4329 | AS15: 622.74092 | AT15: 694.42346 | AU15: 783.24121 | AV15: 930.12547 | AW15: 1191.921 | AX15: 1643.7569 | AY15: 2158.1481 | AZ15: 3139.2807 | BA15: 4010.8614 | BB15: 2994.3405 | BC15: 3218.3783 | BD15: 3525.8072 | BE15: 3681.8447 | BF15: 3838.1739 | BG15: 3986.2316 | BH15: 3607.2893 | BI15: 3591.8281 | BJ15: 3914.5279 | BK15: 4220.5403 | BL15: 4622.7382 | BM15: 4267.4521
A16: American Samoa | B16: ASM | C16: GDP per capita (current US$) | D16: NY.GDP.PCAP.CD | AU16: 8666.6554 | AV16: 8807.4628 | AW16: 8528.2488 | AX16: 8395.3188 | AY16: 8340.5234 | AZ16: 8874.8779 | BA16: 9740.8245 | BB16: 11910.013 | BC16: 10216.818 | BD16: 10223.298 | BE16: 11496.524 | BF16: 11450.724 | BG16: 11525.156 | BH16: 12059.635 | BI16: 12038.25 | BJ16: 11003.83 | BK16: 11557.671 | BL16: 11534.568
A17: Antigua and Barbuda | B17: ATG | C17: GDP per capita (current US$) | D17: NY.GDP.PCAP.CD | V17: 1246.6902 | W17: 1416.5405 | X17: 1760.8313 | Y17: 2124.6185 | Z17: 2392.687 | AA17: 2660.5581 | AB17: 2948.3173 | AC17: 3372.6021 | AD17: 3899.3918 | AE17: 4703.1794 | AF17: 5463.5954 | AG17: 6454.8355 | AH17: 7076.5363 | AI17: 7347.6464 | AJ17: 7602.3453 | AK17: 7745.7218 | AL17: 8136.1885 | AM17: 8771.1437 | AN17: 8406.3589 | AO17: 9030.575 | AP17: 9491.6608 | AQ17: 9940.8522 | AR17: 10260.599 | AS17: 10872.293 | AT17: 10367.32 | AU17: 10401.051 | AV17: 10797.951 | AW17: 11446.969 | AX17: 12557.548 | AY17: 13995.804 | AZ17: 15622.693 | BA17: 16044.106 | BB17: 14160.562 | BC17: 13048.961 | BD17: 12746.633 | BE17: 13272.735 | BF17: 12910.591 | BG17: 13501.581 | BH17: 14285.33 | BI17: 15198.743 | BJ17: 15383.576 | BK17: 16673.437 | BL17: 17113.35 | BM17: 14449.997
A18: Australia | B18: AUS | C18: GDP per capita (current US$) | D18: NY.GDP.PCAP.CD | E18: 1807.7857 | F18: 1874.7321 | G18: 1851.8419 | H18: 1964.1505 | I18: 2128.0684 | J18: 2277.5584 | K18: 2340.4387 | L18: 2576.2845 | M18: 2720.0826 | N18: 2986.9495 | O18: 3299.8432 | P18: 3489.9523 | Q18: 3943.7876 | R18: 4763.6284 | S18: 6473.1652 | T18: 6994.3082 | U18: 7476.7487 | V18: 7765.0705 | W18: 8241.9973 | X18: 9281.5234 | Y18: 10194.395 | Z18: 11833.743 | AA18: 12766.522 | AB18: 11518.669 | AC18: 12431.946 | AD18: 11437.713 | AE18: 11364.239 | AF18: 11624.621 | AG18: 14254.514 | AH18: 17798.556 | AI18: 18211.5 | AJ18: 18821.795 | AK18: 18570.12 | AL18: 17634.535 | AM18: 18046.136 | AN18: 20319.631 | AO18: 21861.326 | AP18: 23468.597 | AQ18: 21318.964 | AR18: 20533.035 | AS18: 21679.248 | AT18: 19490.861 | AU18: 20082.483 | AV18: 23447.031 | AW18: 30430.676 | AX18: 33999.243 | AY18: 36044.923 | AZ18: 40960.054 | BA18: 49601.657 | BB18: 42772.359 | BC18: 52022.126 | BD18: 62517.834 | BE18: 68012.148 | BF18: 68150.107 | BG18: 62510.791 | BH18: 56755.722 | BI18: 49971.131 | BJ18: 54027.967 | BK18: 57354.964 | BL18: 55057.205 | BM18: 51812.154
A19: Austria | B19: AUT | C19: GDP per capita (current US$) | D19: NY.GDP.PCAP.CD | E19: 935.46043 | F19: 1031.815 | G19: 1087.8342 | H19: 1167.0005 | I19: 1269.4126 | J19: 1374.5321 | K19: 1486.9686 | L19: 1569.6672 | M19: 1677.6735 | N19: 1825.3861 | O19: 2058.7691 | P19: 2380.9785 | Q19: 2924.0489 | R19: 3890.7224 | S19: 4630.7572 | T19: 5285.6207 | U19: 5678.3867 | V19: 6810.6277 | W19: 8205.469 | X19: 9793.7653 | Y19: 10869.546 | Z19: 9385.2491 | AA19: 9410.3473 | AB19: 9537.4074 | AC19: 8991.065 | AD19: 9172.0968 | AE19: 13083.073 | AF19: 16392.77 | AG19: 17578.619 | AH19: 17468.946 | AI19: 21680.99 | AJ19: 22410.912 | AK19: 24880.164 | AL19: 24081.528 | AM19: 25646.701 | AN19: 30325.85 | AO19: 29809.077 | AP19: 26705.479 | AQ19: 27361.875 | AR19: 27174.297 | AS19: 24564.458 | AT19: 24537.514 | AU19: 26401.745 | AV19: 32222.897 | AW19: 36821.521 | AX19: 38403.134 | AY19: 40635.282 | AZ19: 46855.772 | BA19: 51708.766 | BB19: 47963.179 | BC19: 46858.043 | BD19: 51374.958 | BE19: 48567.695 | BF19: 50716.709 | BG19: 51717.496 | BH19: 44178.047 | BI19: 45276.831 | BJ19: 47309.366 | BK19: 51453.147 | BL19: 50121.554 | BM19: 48105.365
A20: Azerbaijan | B20: AZE | C20: GDP per capita (current US$) | D20: NY.GDP.PCAP.CD | AK20: 60.458623 | AL20: 209.47298 | AM20: 157.07675 | AN20: 314.55509 | AO20: 409.16319 | AP20: 505.50035 | AQ20: 561.90681 | AR20: 573.91651 | AS20: 655.11995 | AT20: 703.68384 | AU20: 763.08064 | AV20: 883.73397 | AW20: 1045.0094 | AX20: 1578.4024 | AY20: 2473.0818 | AZ20: 3851.4379 | BA20: 5574.6038 | BB20: 4950.2948 | BC20: 5843.5338 | BD20: 7189.6912 | BE20: 7496.2946 | BF20: 7875.757 | BG20: 7891.3131 | BH20: 5500.3104 | BI20: 3880.7387 | BJ20: 4147.0897 | BK20: 4739.8417 | BL20: 4805.7537 | BM20: 4214.3113
A21: Burundi | B21: BDI | C21: GDP per capita (current US$) | D21: NY.GDP.PCAP.CD | E21: 70.05191 | F21: 71.167188 | G21: 73.435331 | H21: 78.514621 | I21: 86.16155 | J21: 51.381881 | K21: 52.182552 | L21: 54.806443 | M21: 54.900762 | N21: 55.714934 | O21: 69.769384 | P21: 71.62671 | Q21: 69.139615 | R21: 84.418782 | S21: 94.6854 | T21: 113.75316 | U21: 118.91493 | V21: 142.05298 | W21: 154.51627 | X21: 193.14996 | Y21: 221.23194 | Z21: 227.12812 | AA21: 231.34369 | AB21: 240.7817 | AC21: 213.61684 | AD21: 242.0585 | AE21: 245.91533 | AF21: 225.07148 | AG21: 209.41486 | AH21: 209.89441 | AI21: 208.14668 | AJ21: 209.77801 | AK21: 190.48888 | AL21: 161.88753 | AM21: 156.81238 | AN21: 167.09889 | AO21: 143.40232 | AP21: 158.91467 | AQ21: 144.49302 | AR21: 128.93892 | AS21: 136.46397 | AT21: 134.36343 | AU21: 123.11754 | AV21: 113.56725 | AW21: 128.3367 | AX21: 151.68157 | AY21: 167.37646 | AZ21: 172.4956 | BA21: 198.35285 | BB21: 212.13706 | BC21: 234.23553 | BD21: 249.57797 | BE21: 252.35887 | BF21: 256.97565 | BG21: 274.85784 | BH21: 305.54965 | BI21: 282.19303 | BJ21: 292.99801 | BK21: 271.7525 | BL21: 261.24529 | BM21: 274.00952
A22: Belgium | B22: BEL | C22: GDP per capita (current US$) | D22: NY.GDP.PCAP.CD | E22: 1273.6917 | F22: 1350.1977 | G22: 1438.5232 | H22: 1535.0237 | I22: 1701.8463 | J22: 1835.5948 | K22: 1957.6261 | L22: 2086.636 | M22: 2222.3615 | N22: 2458.0818 | O22: 2765.891 | P22: 3082.928 | Q22: 3831.6319 | R22: 4900.9622 | S22: 5733.7981 | T22: 6701.3774 | U22: 7243.0473 | V22: 8426.947 | W22: 10289.768 | X22: 11810.616 | Y22: 12864.003 | Z22: 10622.802 | AA22: 9343.8611 | AB22: 8846.2343 | AC22: 8457.2688 | AD22: 8750.8185 | AE22: 12170.041 | AF22: 15135.852 | AG22: 16391.094 | AH22: 16525.062 | AI22: 20600.375 | AJ22: 21041.661 | AK22: 23372.619 | AL22: 22283.936 | AM22: 24208.555 | AN22: 28413.826 | AO22: 27489.555 | AP22: 24820.938 | AQ22: 25338.443 | AR22: 25244.275 | AS22: 23041.535 | AT22: 22995.158 | AU22: 24887.561 | AV22: 30587.668 | AW22: 35364.375 | AX22: 36795.977 | AY22: 38672.706 | AZ22: 44262.896 | BA22: 48106.893 | BB22: 44583.545 | BC22: 44141.878 | BD22: 47348.525 | BE22: 44673.116 | BF22: 46744.663 | BG22: 47700.54 | BH22: 40991.808 | BI22: 41984.103 | BJ22: 44089.31 | BK22: 47554.746 | BL22: 46414.435 | BM22: 44594.378
A23: Benin | B23: BEN | C23: GDP per capita (current US$) | D23: NY.GDP.PCAP.CD | E23: 93.0227 | F23: 95.572232 | G23: 94.464497 | H23: 99.858918 | I23: 104.33993 | J23: 110.13258 | K23: 112.94084 | L23: 111.95156 | M23: 116.89515 | N23: 116.02526 | O23: 114.55668 | P23: 112.56998 | Q23: 134.81959 | R23: 161.98706 | S23: 174.01409 | T23: 207.30031 | U23: 208.6564 | V23: 218.45398 | W23: 263.58143 | X23: 327.82231 | Y23: 378.04431 | Z23: 337.97837 | AA23: 322.77745 | AB23: 271.12984 | AC23: 252.86979 | AD23: 244.41094 | AE23: 303.34904 | AF23: 344.50315 | AG23: 346.73663 | AH23: 311.67805 | AI23: 393.68677 | AJ23: 385.75384 | AK23: 317.96274 | AL23: 411.92618 | AM23: 279.66675 | AN23: 367.3877 | AO23: 387.43208 | AP23: 361.1 | AQ23: 379.44178 | AR23: 551.82139 | AS23: 512.67392 | AT23: 518.06748 | AU23: 574.92978 | AV23: 711.28492 | AW23: 798.74426 | AX23: 822.7852 | AY23: 856.05488 | AZ23: 966.20358 | BA23: 1125.426 | BB23: 1088.7579 | BC23: 1036.5346 | BD23: 1130.2732 | BE23: 1145.14 | BF23: 1251.2097 | BG23: 1291.4101 | BH23: 1076.7967 | BI23: 1087.2873 | BJ23: 1136.594 | BK23: 1240.831 | BL23: 1219.5155 | BM23: 1291.041
A24: Burkina Faso | B24: BFA | C24: GDP per capita (current US$) | D24: NY.GDP.PCAP.CD | E24: 68.424734 | F24: 71.55818 | G24: 76.520549 | H24: 78.372196 | I24: 80.472718 | J24: 81.725052 | K24: 82.545684 | L24: 84.36307 | M24: 84.732937 | N24: 86.520209 | O24: 81.500015 | P24: 84.287829 | Q24: 99.326747 | R24: 113.78034 | S24: 124.3589 | T24: 152.728 | U24: 155.64906 | V24: 176.78335 | W24: 225.94152 | X24: 262.07601 | Y24: 282.68585 | Z24: 254.23047 | AA24: 245.09449 | AB24: 217.9946 | AC24: 193.84327 | AD24: 200.89435 | AE24: 256.76248 | AF24: 291.13162 | AG24: 313.06159 | AH24: 304.85352 | AI24: 351.97923 | AJ24: 346.4106 | AK24: 361.04688 | AL24: 334.94324 | AM24: 193.07028 | AN24: 235.83215 | AO24: 249.36056 | AP24: 229.49295 | AQ24: 255.71824 | AR24: 300.42172 | AS24: 255.71869 | AT24: 267.0976 | AU24: 294.66539 | AV24: 374.62736 | AW24: 418.37666 | AX24: 457.93343 | AY24: 473.44987 | AZ24: 535.06228 | BA24: 643.40458 | BB24: 624.17516 | BC24: 647.8361 | BD24: 751.17277 | BE24: 758.00043 | BF24: 787.46944 | BG24: 792.84624 | BH24: 653.32727 | BI24: 688.2507 | BJ24: 734.99627 | BK24: 813.09969 | BL24: 786.89544 | BM24: 830.92514
