Workbook

Sheet Home
A1: Click on the following name of country for viewing data
A2: Data per country
A3: Algeria | L3: AFRO Stock 20240123
A4: Angola | L4: AFRO Stock 2012
A5: Benin | L5: AFRO Stock 2013
A6: Botswana | L6: AFRO Stock 2014
A7: BurkinaFaso | L7: AFRO Stock 2015
A8: Burundi | L8: AFRO Stock 2016
A9: Cabo Verde | L9: AFRO Stock 2017
A10: Cameroon | L10: AFRO Stock 2018
A11: CAR | L11: AFRO Stock 2019
A12: Chad | L12: AFRO Stock 2020
A13: Comoros | L13: AFRO Stock 2021
A14: Congo | L14: AFRO Stock 2022
A15: Cote d'Ivoire
A16: DRC
A17: Equatorial Guinea
A18: Eritrea
A19: Eswatini
A20: Ethiopia
A21: Gabon
A22: Gambia
A23: Ghana
A24: Guinea
A25: Guinea-Bissau
A26: Kenya
... A49: Zimbabwe

Sheet Algeria
A1: Algeria HRH Stock from 2012 to 2022 | M1: Home
A2: Occupation | B2: 2012 | C2: 2013 | D2: 2014 | E2: 2015 | F2: 2016 | G2: 2017 | H2: 2018 | I2: 2019 | J2: 2020 | K2: 2021 | L2: 2022
A3: Medical Doctors | B3: 0 | C3: 0 | D3: 0 | E3: 0 | F3: 74309 | G3: 0 | H3: 72604 | I3: 42140 | J3: 0 | K3: 0 | L3: 0
A4: Generalist Medical Practitioners (incl. Family medical practitioners) | B4: 0 | C4: 0 | D4: 0 | E4: 0 | F4: 0 | G4: 0 | H4: 32774 | I4: 27560 | J4: 0 | K4: 0 | L4: 0
A5: Medical group of Specialists Practitioners | B5: 0 | C5: 0 | D5: 0 | E5: 0 | F5: 0 | G5: 0 | H5: 19815 | I5: 0 | J5: 0 | K5: 0 | L5: 0
A6: Nursing Personnel | B6: 0 | C6: 0 | D6: 0 | E6: 0 | F6: 90958 | G6: 92000 | H6: 56411 | I6: 4425 | J6: 0 | K6: 0 | L6: 0
A7: Midwifery personnel | B7: 0 | C7: 0 | D7: 11139 | E7: 0 | F7: 0 | G7: 0 | H7: 8948 | I7: 9070 | J7: 0 | K7: 0 | L7: 0
A8: Dentists | B8: 0 | C8: 0 | D8: 0 | E8: 0 | F8: 0 | G8: 14263 | H8: 15437 | I8: 7018 | J8: 0 | K8: 0 | L8: 0
A9: Pharmacists | B9: 0 | C9: 0 | D9: 0 | E9: 0 | F9: 0 | G9: 0 | H9: 18807 | I9: 2156 | J9: 0 | K9: 0 | L9: 0
A10: Administrative staff | B10: 0 | C10: 0 | D10: 0 | E10: 0 | F10: 0 | G10: 0 | H10: 25611 | I10: 0 | J10: 0 | K10: 0 | L10: 0
A11: Ambulance Workers | B11: 0 | C11: 0 | D11: 0 | E11: 0 | F11: 0 | G11: 0 | H11: 0 | I11: 0 | J11: 0 | K11: 0 | L11: 0
A12: Audiologists and Speech Therapists | B12: 0 | C12: 0 | D12: 0 | E12: 0 | F12: 0 | G12: 0 | H12: 0 | I12: 0 | J12: 0 | K12: 0 | L12: 0
A13: Biomedical engineer | B13: 0 | C13: 0 | D13: 0 | E13: 0 | F13: 0 | G13: 0 | H13: 515 | I13: 0 | J13: 0 | K13: 0 | L13: 0
... A62: Traditional and Complementary Medicine Professionals | B62: 0 | C62: 0 | D62: 0 | E62: 0 | F62: 0 | G62: 0 | H62: 0 | I62: 0 | J62: 0 | K62: 0 | L62: 0
A63: Total | B63: =SUM(B3:B62) -> 0 | C63: =SUM(C3:C62) -> 4628 | D63: =SUM(D3:D62) -> 22890 | E63: =SUM(E3:E62) -> 0 | F63: =SUM(F3:F62) -> 330534 | G63: =SUM(G3:G62) -> 198784 | H63: =SUM(H3:H62) -> 537276 | I63: =SUM(I3:I62) -> 249267 | ... L63: =SUM(L3:L62) -> 0
A65: Population UN | B65: 944686.2 | C65: 971174.5 | D65: 991164.8 | E65: 1014537.2 | F65: 1030448.2 | G65: 1038181.5 | H65: 1036361.6 | I65: 1025953.1 | J65: 1010048.1 | K65: 989535.7 | L65: 966316.9

Sheet Angola
A1: Angola HRH Stock from 2012 to 2022 | N1: Home
A2: Occupation | B2: 2012 | C2: 2013 | D2: 2014 | E2: 2015 | F2: 2016 | G2: 2017 | H2: 2018 | I2: 2019 | J2: 2020 | K2: 2021 | L2: 2022
A3: Medical Doctors | B3: 0 | C3: 0 | D3: 0 | E3: 0 | F3: 0 | G3: 6400 | H3: 6593 | I3: 0 | J3: 0 | K3: 0 | L3: 8693
A4: Generalist Medical Practitioners (incl. Family medical practitioners) | B4: 0 | C4: 0 | D4: 0 | E4: 0 | F4: 0 | G4: 0 | H4: 3043 | I4: 0 | J4: 0 | K4: 0 | L4: 4778
A5: Medical group of Specialists Practitioners | B5: 0 | C5: 0 | D5: 0 | E5: 0 | F5: 0 | G5: 0 | H5: 0 | I5: 0 | J5: 0 | K5: 0 | L5: 2510
A6: Nursing Personnel | B6: 0 | C6: 0 | D6: 0 | E6: 0 | F6: 0 | G6: 0 | H6: 12554 | I6: 0 | J6: 0 | K6: 0 | L6: 44989
A7: Midwifery personnel | B7: 0 | C7: 30 | D7: 0 | E7: 0 | F7: 0 | G7: 0 | H7: 0 | I7: 0 | J7: 0 | K7: 0 | L7: 22
A8: Dentists | B8: 0 | C8: 0 | D8: 0 | E8: 0 | F8: 0 | G8: 0 | H8: 1652 | I8: 0 | J8: 0 | K8: 0 | L8: 171
A9: Pharmacists | B9: 0 | C9: 0 | D9: 0 | E9: 0 | F9: 0 | G9: 0 | H9: 2302 | I9: 0 | J9: 0 | K9: 0 | L9: 967
A10: Administrative staff | B10: 0 | C10: 0 | D10: 0 | E10: 0 | F10: 0 | G10: 0 | H10: 0 | I10: 0 | J10: 0 | K10: 0 | L10: 13442
A11: Ambulance Workers | B11: 0 | C11: 0 | D11: 0 | E11: 0 | F11: 0 | G11: 0 | H11: 0 | I11: 0 | J11: 0 | K11: 0 | L11: 1045
A12: Audiologists and Speech Therapists | B12: 0 | C12: 0 | D12: 0 | E12: 0 | F12: 0 | G12: 0 | H12: 0 | I12: 0 | J12: 0 | K12: 0 | L12: 1
A13: Biomedical engineer | B13: 0 | C13: 0 | D13: 0 | E13: 0 | F13: 0 | G13: 0 | H13: 0 | I13: 0 | J13: 0 | K13: 0 | L13: 16
... A62: Traditional and Complementary Medicine Professionals | B62: 0 | C62: 0 | D62: 0 | E62: 0 | F62: 0 | G62: 0 | H62: 0 | I62: 0 | J62: 0 | K62: 0 | L62: 0
A63: Total | B63: =SUM(B3:B62) -> 0 | C63: =SUM(C3:C62) -> 60 | D63: =SUM(D3:D62) -> 0 | E63: =SUM(E3:E62) -> 0 | F63: =SUM(F3:F62) -> 0 | G63: =SUM(G3:G62) -> 12800 | H63: =SUM(H3:H62) -> 44026 | I63: =SUM(I3:I62) -> 0 | ... L63: =SUM(L3:L62) -> 140499
A65: Population UN | B65: 1060133.3 | C65: 1089608.5 | D65: 1117632.7 | E65: 1144292.4 | F65: 1170060.7 | G65: 1196892.8 | H65: 1224269.3 | I65: 1251836.9 | J65: 1280498.2 | K65: 1308712.3 | L65: 1332678.6

Sheet Benin
A1: Benin HRH Stock from 2012 to 2022
A2: Occupation | B2: 2012 | C2: 2013 | D2: 2014 | E2: 2015 | F2: 2016 | G2: 2017 | H2: 2018 | I2: 2019 | J2: 2020 | K2: 2021 | L2: 2022 | M2: Home
A3: Medical Doctors | B3: 0 | C3: 0 | D3: 0 | E3: 0 | F3: 523 | G3: 0 | H3: 908 | I3: 763 | J3: 0 | K3: 2755 | L3: 2608
A4: Generalist Medical Practitioners (incl. Family medical practitioners) | B4: 0 | C4: 0 | D4: 0 | E4: 0 | F4: 0 | G4: 0 | H4: 346 | I4: 202 | J4: 0 | K4: 1797 | L4: 1753
A5: Medical group of Specialists Practitioners | B5: 0 | C5: 0 | D5: 0 | E5: 0 | F5: 0 | G5: 0 | H5: 13 | I5: 0 | J5: 0 | K5: 0 | L5: 0
A6: Nursing Personnel | B6: 5138 | C6: 4880 | D6: 0 | E6: 0 | F6: 7224 | G6: 0 | H6: 3410 | I6: 2670 | J6: 0 | K6: 5484 | L6: 5893
A7: Midwifery personnel | B7: 1480 | C7: 943 | D7: 0 | E7: 0 | F7: 1034 | G7: 0 | H7: 1055 | I7: 905 | J7: 0 | K7: 2086 | L7: 2055
A8: Dentists | B8: 0 | C8: 0 | D8: 0 | E8: 0 | F8: 9 | G8: 73 | H8: 12 | I8: 0 | J8: 0 | K8: 50 | L8: 50
A9: Pharmacists | B9: 0 | C9: 1330 | D9: 0 | E9: 0 | F9: 13 | G9: 0 | H9: 306 | I9: 0 | J9: 0 | K9: 403 | L9: 382
A10: Administrative staff | B10: 0 | C10: 0 | D10: 0 | E10: 0 | F10: 0 | G10: 0 | H10: 4463 | I10: 0 | J10: 0 | K10: 5903 | L10: 5106
A11: Ambulance Workers | B11: 0 | C11: 0 | D11: 0 | E11: 0 | F11: 0 | G11: 0 | H11: 0 | I11: 0 | J11: 0 | K11: 0 | L11: 0
A12: Audiologists and Speech Therapists | B12: 0 | C12: 0 | D12: 0 | E12: 0 | F12: 0 | G12: 0 | H12: 0 | I12: 0 | J12: 0 | K12: 0 | L12: 0
A13: Biomedical engineer | B13: 0 | C13: 0 | D13: 0 | E13: 0 | F13: 0 | G13: 0 | H13: 0 | I13: 0 | J13: 0 | K13: 0 | L13: 0
A14: Community Health Workers | B14: 0 | C14: 0 | D14: 0 | E14: 0 | F14: 0 | G14: 0 | H14: 0 | I14: 0 | J14: 0 | K14: 21 | L14: 21
... A62: Traditional and Complementary Medicine Professionals | B62: 0 | C62: 10200 | D62: 0 | E62: 0 | F62: 0 | G62: 0 | H62: 0 | I62: 0 | J62: 0 | K62: 0 | L62: 0
A63: Total | B63: =SUM(B3:B62) -> 14348 | C63: =SUM(C3:C62) -> 24982 | D63: =SUM(D3:D62) -> 191 | E63: =SUM(E3:E62) -> 0 | F63: =SUM(F3:F62) -> 19238 | G63: =SUM(G3:G62) -> 121 | H63: =SUM(H3:H62) -> 22362 | I63: =SUM(I3:I62) -> 9084 | ... L63: =SUM(L3:L62) -> 29498
A65: Population UN | B65: 376547.2 | C65: 387605.1 | D65: 399718.4 | E65: 411367.9 | F65: 422641.3 | G65: 433722.2 | H65: 442748.4 | I65: 450366.9 | J65: 457449.9 | K65: 464321.1 | L65: 470912.8

Sheet Botswana
A1: Botswana HRH Stock from 2012 to 2022 | M1: Home
A2: Occupation | B2: 2012 | C2: 2013 | D2: 2014 | E2: 2015 | F2: 2016 | G2: 2017 | H2: 2018 | I2: 2019 | J2: 2020 | K2: 2021 | L2: 2022
A3: Medical Doctors | B3: 819 | C3: 0 | D3: 0 | E3: 0 | F3: 830 | G3: 0 | H3: 925 | I3: 920 | J3: 1024 | K3: 1014 | L3: 992
A4: Generalist Medical Practitioners (incl. Family medical practitioners) | B4: 0 | C4: 0 | D4: 0 | E4: 0 | F4: 0 | G4: 0 | H4: 807 | I4: 813 | J4: 902 | K4: 900 | L4: 898
A5: Medical group of Specialists Practitioners | B5: 0 | C5: 0 | D5: 0 | E5: 0 | F5: 0 | G5: 0 | H5: 0 | I5: 0 | J5: 0 | K5: 0 | L5: 0
A6: Nursing Personnel | B6: 5816 | C6: 0 | D6: 0 | E6: 0 | F6: 7427 | G6: 0 | H6: 7645 | I6: 7763 | J6: 7771 | K6: 7886 | L6: 8028
A7: Midwifery personnel | B7: 0 | C7: 1501 | D7: 0 | E7: 0 | F7: 1461 | G7: 0 | H7: 0 | I7: 0 | J7: 0 | K7: 0 | L7: 0
A8: Dentists | B8: 55 | C8: 0 | D8: 0 | E8: 0 | F8: 91 | G8: 0 | H8: 96 | I8: 88 | J8: 89 | K8: 89 | L8: 86
A9: Pharmacists | B9: 0 | C9: 0 | D9: 0 | E9: 0 | F9: 0 | G9: 0 | H9: 156 | I9: 138 | J9: 145 | K9: 158 | L9: 125
A10: Administrative staff | B10: 0 | C10: 0 | D10: 0 | E10: 0 | F10: 0 | G10: 0 | H10: 534 | I10: 491 | J10: 463 | K10: 465 | L10: 449
A11: Ambulance Workers | B11: 0 | C11: 0 | D11: 0 | E11: 0 | F11: 0 | G11: 0 | H11: 927 | I11: 843 | J11: 842 | K11: 845 | L11: 848
A12: Audiologists and Speech Therapists | B12: 0 | C12: 0 | D12: 0 | E12: 0 | F12: 0 | G12: 0 | H12: 9 | I12: 8 | J12: 7 | K12: 8 | L12: 11
A13: Biomedical engineer | B13: 0 | C13: 0 | D13: 0 | E13: 0 | F13: 0 | G13: 0 | H13: 16 | I13: 11 | J13: 11 | K13: 12 | L13: 13
... A62: Traditional and Complementary Medicine Professionals | B62: 0 | C62: 0 | D62: 0 | E62: 0 | F62: 0 | G62: 0 | H62: 0 | I62: 0 | J62: 0 | K62: 0 | L62: 0
A63: Total | B63: =SUM(B3:B62) -> 13491 | C63: =SUM(C3:C62) -> 3002 | D63: =SUM(D3:D62) -> 76 | E63: =SUM(E3:E62) -> 0 | F63: =SUM(F3:F62) -> 19538 | G63: =SUM(G3:G62) -> 0 | H63: =SUM(H3:H62) -> 26600 | I63: =SUM(I3:I62) -> 27240 | ... L63: =SUM(L3:L62) -> 27631
A65: Population UN | B65: 59490.1 | C65: 60143.3 | D65: 60621.9 | E65: 61044.4 | F65: 61561.1 | G65: 62008.2 | H65: 62387.4 | I65: 62733.4 | J65: 62582.3 | K65: 62086.9 | L65: 61665.2

Sheet Burkina Faso
A1: Burkina Faso HRH Stock from 2012 to 2022 | N1: Home
A2: Occupation | B2: 2012 | C2: 2013 | D2: 2014 | E2: 2015 | F2: 2016 | G2: 2017 | H2: 2018 | I2: 2019 | J2: 2020 | K2: 2021 | L2: 2022
A3: Medical Doctors | B3: 787 | C3: 803 | D3: 857 | E3: 1189 | F3: 1202 | G3: 1626 | H3: 1684 | I3: 1910 | J3: 2061 | K3: 2221 | L3: 3323
A4: Generalist Medical Practitioners (incl. Family medical practitioners) | B4: 0 | C4: 0 | D4: 0 | E4: 0 | F4: 0 | G4: 888 | H4: 732 | I4: 1026 | J4: 1088 | K4: 1220 | L4: 2372
A5: Medical group of Specialists Practitioners | B5: 0 | C5: 0 | D5: 0 | E5: 0 | F5: 0 | G5: 0 | H5: 0 | I5: 693 | J5: 0 | K5: 0 | L5: 32
A6: Nursing Personnel | B6: 6008 | C6: 6196 | D6: 6358 | E6: 9748 | F6: 9701 | G6: 10376 | H6: 0 | I6: 11364 | J6: 11874 | K6: 12189 | L6: 13961
A7: Midwifery personnel | B7: 4451 | C7: 1591 | D7: 1744 | E7: 2383 | F7: 2580 | G7: 6569 | H7: 0 | I7: 7477 | J7: 7804 | K7: 8052 | L7: 9294
A8: Dentists | B8: 38 | C8: 0 | D8: 0 | E8: 0 | F8: 0 | G8: 80 | H8: 91 | I8: 52 | J8: 103 | K8: 107 | L8: 39
A9: Pharmacists | B9: 203 | C9: 207 | D9: 217 | E9: 258 | F9: 235 | G9: 284 | H9: 239 | I9: 313 | J9: 718 | K9: 691 | L9: 575
A10: Administrative staff | B10: 0 | C10: 0 | D10: 0 | E10: 0 | F10: 0 | G10: 0 | H10: 0 | I10: 811 | J10: 0 | K10: 0 | L10: 0
A11: Ambulance Workers | B11: 0 | C11: 0 | D11: 0 | E11: 0 | F11: 0 | G11: 0 | H11: 0 | I11: 200 | J11: 0 | K11: 0 | L11: 275
A12: Audiologists and Speech Therapists | B12: 0 | C12: 0 | D12: 0 | E12: 0 | F12: 0 | G12: 0 | H12: 0 | I12: 0 | J12: 0 | K12: 0 | L12: 0
A13: Biomedical engineer | B13: 0 | C13: 0 | D13: 0 | E13: 0 | F13: 0 | G13: 0 | H13: 0 | I13: 7 | J13: 8 | K13: 0 | L13: 18
... A62: Traditional and Complementary Medicine Professionals | B62: 0 | C62: 0 | D62: 0 | E62: 0 | F62: 0 | G62: 336 | H62: 0 | I62: 1 | J62: 0 | K62: 50 | L62: 0
A63: Total | B63: =SUM(B3:B62) -> 25638 | C63: =SUM(C3:C62) -> 17387 | D63: =SUM(D3:D62) -> 18239 | E63: =SUM(E3:E62) -> 26898 | F63: =SUM(F3:F62) -> 27201 | G63: =SUM(G3:G62) -> 42391 | H63: =SUM(H3:H62) -> 4533 | I63: =SUM(I3:I62) -> 53175 | ... L63: =SUM(L3:L62) -> 62972
A65: Population UN | B65: 699018.1 | C65: 712157.2 | D65: 722847.5 | E65: 731106.9 | F65: 735658.4 | G65: 737568.4 | H65: 743373 | I65: 752782.1 | J65: 761670.7 | K65: 770961.1 | L65: 780085.6

Sheet Burundi
A1: Burundi HRH Stock from 2012 to 2022
A2: Occupation | B2: 2012 | C2: 2013 | D2: 2014 | E2: 2015 | F2: 2016 | G2: 2017 | H2: 2018 | I2: 2019 | J2: 2020 | K2: 2021 | L2: 2022 | N2: HOME
A3: Medical Doctors | B3: 0 | C3: 0 | D3: 609 | E3: 508 | F3: 0 | G3: 0 | H3: 0 | I3: 0 | J3: 852 | K3: 812 | L3: 0
A4: Generalist Medical Practitioners (incl. Family medical practitioners) | B4: 0 | C4: 0 | D4: 556 | E4: 467 | F4: 0 | G4: 0 | H4: 0 | I4: 0 | J4: 0 | K4: 725 | L4: 0
A5: Medical group of Specialists Practitioners | B5: 0 | C5: 0 | D5: 0 | E5: 0 | F5: 0 | G5: 0 | H5: 0 | I5: 0 | J5: 0 | K5: 96 | L5: 0
A6: Nursing Personnel | B6: 5138 | C6: 4880 | D6: 6819 | E6: 6688 | F6: 0 | G6: 9071 | H6: 9156 | I6: 7518 | J6: 7713 | K6: 9372 | L6: 0
A7: Midwifery personnel | B7: 1480 | C7: 943 | D7: 24 | E7: 79 | F7: 0 | G7: 160 | H7: 0 | I7: 124 | J7: 0 | K7: 143 | L7: 0
A8: Dentists | B8: 0 | C8: 0 | D8: 0 | E8: 0 | F8: 0 | G8: 0 | H8: 14 | I8: 0 | J8: 0 | K8: 0 | L8: 0
A9: Pharmacists | B9: 0 | C9: 1330 | D9: 0 | E9: 0 | F9: 0 | G9: 0 | H9: 119 | I9: 0 | J9: 0 | K9: 99 | L9: 0
A10: Administrative staff | B10: 0 | C10: 0 | D10: 0 | E10: 0 | F10: 0 | G10: 0 | H10: 0 | I10: 0 | J10: 0 | K10: 1750 | L10: 0
A11: Ambulance Workers | B11: 0 | C11: 0 | D11: 0 | E11: 0 | F11: 0 | G11: 0 | H11: 0 | I11: 0 | J11: 0 | K11: 0 | L11: 0
A12: Audiologists and Speech Therapists | B12: 0 | C12: 0 | D12: 0 | E12: 0 | F12: 0 | G12: 0 | H12: 0 | I12: 0 | J12: 0 | K12: 5 | L12: 0
A13: Biomedical engineer | B13: 0 | C13: 0 | D13: 0 | E13: 0 | F13: 0 | G13: 0 | H13: 0 | I13: 0 | J13: 0 | K13: 0 | L13: 0
A14: Community Health Workers | B14: 0 | C14: 0 | D14: 0 | E14: 0 | F14: 0 | G14: 0 | H14: 11845 | I14: 0 | J14: 11845 | K14: 0 | L14: 0
... A65: Population UN | B65: 423678.2 | C65: 429312 | D65: 435003 | E65: 437619.8 | F65: 431656.2 | G65: 423373 | H65: 421562 | I65: 425247.1 | J65: 430785.2 | K65: 434393 | L65: 437298.7

Sheet Cabo Verde
A1: Cabo Verde HRH Stock from 2012 to 2022
A2: Occupation | B2: 2012 | C2: 2013 | D2: 2014 | E2: 2015 | F2: 2016 | G2: 2017 | H2: 2018 | I2: 2019 | J2: 2020 | K2: 2021 | L2: 2022 | N2: HOME
A3: Medical Doctors | B3: 260 | C3: 308 | D3: 0 | E3: 410 | F3: 408 | G3: 0 | H3: 452 | I3: 0 | J3: 0 | K3: 0 | L3: 2644
A4: Generalist Medical Practitioners (incl. Family medical practitioners) | B4: 0 | C4: 0 | D4: 0 | E4: 0 | F4: 0 | G4: 0 | H4: 165 | I4: 0 | J4: 0 | K4: 0 | L4: 187
A5: Medical group of Specialists Practitioners | B5: 0 | C5: 0 | D5: 0 | E5: 0 | F5: 0 | G5: 0 | H5: 0 | I5: 0 | J5: 0 | K5: 0 | L5: 100
A6: Nursing Personnel | B6: 551 | C6: 403 | D6: 476 | E6: 498 | F6: 612 | G6: 688 | H6: 706 | I6: 0 | J6: 0 | K6: 0 | L6: 941
A7: Midwifery personnel | B7: 0 | C7: 0 | D7: 0 | E7: 0 | F7: 0 | G7: 0 | H7: 0 | I7: 0 | J7: 0 | K7: 0 | L7: 0
A8: Dentists | B8: 0 | C8: 0 | D8: 0 | E8: 0 | F8: 4 | G8: 0 | H8: 81 | I8: 120 | J8: 0 | K8: 0 | L8: 10
A9: Pharmacists | B9: 0 | C9: 0 | D9: 0 | E9: 0 | F9: 4 | G9: 0 | H9: 172 | I9: 0 | J9: 0 | K9: 0 | L9: 23
A10: Administrative staff | B10: 0 | C10: 0 | D10: 0 | E10: 0 | F10: 0 | G10: 0 | H10: 0 | I10: 0 | J10: 0 | K10: 0 | L10: 0
A11: Ambulance Workers | B11: 0 | C11: 0 | D11: 0 | E11: 0 | F11: 0 | G11: 0 | H11: 0 | I11: 0 | J11: 0 | K11: 0 | L11: 0
A12: Audiologists and Speech Therapists | B12: 0 | C12: 0 | D12: 0 | E12: 0 | F12: 0 | G12: 0 | H12: 0 | I12: 0 | J12: 0 | K12: 0 | L12: 0
A13: Biomedical engineer | B13: 0 | C13: 0 | D13: 0 | E13: 0 | F13: 0 | G13: 0 | H13: 0 | I13: 0 | J13: 0 | K13: 0 | L13: 0
A14: Community Health Workers | B14: 0 | C14: 0 | D14: 0 | E14: 0 | F14: 0 | G14: 0 | H14: 117 | I14: 0 | J14: 0 | K14: 0 | L14: 155
... A62: Traditional and Complementary Medicine Professionals | B62: 0 | C62: 0 | D62: 0 | E62: 0 | F62: 0 | G62: 0 | H62: 0 | I62: 0 | J62: 0 | K62: 0 | L62: 0
A63: Total | B63: =SUM(B3:B62) -> 1622 | C63: =SUM(C3:C62) -> 1422 | D63: =SUM(D3:D62) -> 952 | E63: =SUM(E3:E62) -> 1816 | F63: =SUM(F3:F62) -> 2048 | G63: =SUM(G3:G62) -> 1376 | H63: =SUM(H3:H62) -> 2763 | I63: =SUM(I3:I62) -> 214 | ... L63: =SUM(L3:L62) -> 7633
A65: Population UN | B65: 11441.9 | C65: 11037.4 | D65: 10993.6 | E65: 11002.7 | F65: 11070.9 | G65: 11160.3 | H65: 10880.9 | I65: 10569 | J65: 10491.7 | K65: 10447 | L65: 10405.3

Sheet Cameroon
A1: Cameroon HRH Stock from 2012 to 2022
A2: Occupation | B2: 2012 | C2: 2013 | D2: 2014 | E2: 2015 | F2: 2016 | G2: 2017 | H2: 2018 | I2: 2019 | J2: 2020 | K2: 2021 | L2: 2022 | N2: HOME
A3: Medical Doctors | B3: 0 | C3: 0 | D3: 0 | E3: 0 | F3: 0 | G3: 0 | H3: 3259 | I3: 0 | J3: 2562 | K3: 3378 | L3: 3759
A4: Generalist Medical Practitioners (incl. Family medical practitioners) | B4: 0 | C4: 0 | D4: 0 | E4: 0 | F4: 0 | G4: 0 | H4: 2400 | I4: 0 | J4: 1643 | K4: 2477 | L4: 2467
A5: Medical group of Specialists Practitioners | B5: 0 | C5: 0 | D5: 0 | E5: 0 | F5: 0 | G5: 0 | H5: 0 | I5: 0 | J5: 16 | K5: 486 | L5: 639
A6: Nursing Personnel | B6: 0 | C6: 0 | D6: 0 | E6: 0 | F6: 0 | G6: 0 | H6: 9156 | I6: 0 | J6: 11478 | K6: 4543 | L6: 16473
A7: Midwifery personnel | B7: 0 | C7: 127 | D7: 0 | E7: 0 | F7: 0 | G7: 0 | H7: 0 | I7: 0 | J7: 1258 | K7: 704 | L7: 1674
A8: Dentists | B8: 0 | C8: 0 | D8: 0 | E8: 0 | F8: 88 | G8: 0 | H8: 0 | I8: 300 | J8: 179 | K8: 133 | L8: 317
A9: Pharmacists | B9: 0 | C9: 0 | D9: 0 | E9: 0 | F9: 199 | G9: 0 | H9: 14 | I9: 0 | J9: 337 | K9: 264 | L9: 602
A10: Administrative staff | B10: 0 | C10: 0 | D10: 0 | E10: 0 | F10: 0 | G10: 0 | H10: 0 | I10: 0 | J10: 2735 | K10: 3229 | L10: 3699
A11: Ambulance Workers | B11: 0 | C11: 0 | D11: 0 | E11: 0 | F11: 0 | G11: 0 | H11: 0 | I11: 0 | J11: 16 | K11: 37 | L11: 61
A12: Audiologists and Speech Therapists | B12: 0 | C12: 0 | D12: 0 | E12: 0 | F12: 0 | G12: 0 | H12: 0 | I12: 0 | J12: 2 | K12: 0 | L12: 0
A13: Biomedical engineer | B13: 0 | C13: 0 | D13: 0 | E13: 0 | F13: 0 | G13: 0 | H13: 0 | I13: 0 | J13: 15 | K13: 22 | L13: 85
A14: Community Health Workers | B14: 0 | C14: 0 | D14: 0 | E14: 0 | F14: 0 | G14: 0 | H14: 0 | I14: 0 | J14: 154 | K14: 0 | L14: 310
... A62: Traditional and Complementary Medicine Professionals | B62: 0 | C62: 0 | D62: 0 | E62: 0 | F62: 0 | G62: 0 | H62: 0 | I62: 0 | J62: 3 | K62: 0 | L62: 5
A63: Total | B63: =SUM(B3:B62) -> 0 | C63: =SUM(C3:C62) -> 254 | D63: =SUM(D3:D62) -> 0 | E63: =SUM(E3:E62) -> 0 | F63: =SUM(F3:F62) -> 287 | G63: =SUM(G3:G62) -> 0 | H63: =SUM(H3:H62) -> 25085 | I63: =SUM(I3:I62) -> 300 | ... L63: =SUM(L3:L62) -> 59456
A65: Population UN | B65: 791411.5 | C65: 803500.2 | D65: 818448.6 | E65: 840650.2 | F65: 867237.3 | G65: 889229.5 | H65: 903131.8 | I65: 914051.2 | J65: 925124.6 | K65: 935437.5 | L65: 946149.4

Sheet CAR
A1: CAR HRH Stock from 2012 to 2022
A2: Occupation | B2: 2012 | C2: 2013 | D2: 2014 | E2: 2015 | F2: 2016 | G2: 2017 | H2: 2018 | I2: 2019 | J2: 2020 | K2: 2021 | L2: 2022 | N2: HOME
A3: Medical Doctors | B3: 0 | C3: 0 | D3: 0 | E3: 324 | F3: 0 | G3: 0 | H3: 335 | I3: 0 | J3: 0 | K3: 114 | L3: 0
A4: Generalist Medical Practitioners (incl. Family medical practitioners) | B4: 0 | C4: 0 | D4: 0 | E4: 0 | F4: 0 | G4: 0 | H4: 263 | I4: 0 | J4: 0 | K4: 108 | L4: 0
A5: Medical group of Specialists Practitioners | B5: 0 | C5: 0 | D5: 0 | E5: 0 | F5: 0 | G5: 0 | H5: 0 | I5: 0 | J5: 0 | K5: 1 | L5: 0
A6: Nursing Personnel | B6: 0 | C6: 0 | D6: 0 | E6: 322 | F6: 0 | G6: 0 | H6: 1195 | I6: 0 | J6: 0 | K6: 505 | L6: 0
A7: Midwifery personnel | B7: 0 | C7: 514 | D7: 0 | E7: 605 | F7: 0 | G7: 0 | H7: 0 | I7: 0 | J7: 0 | K7: 537 | L7: 0
A8: Dentists | B8: 0 | C8: 0 | D8: 0 | E8: 0 | F8: 0 | G8: 0 | H8: 10 | I8: 0 | J8: 0 | K8: 2 | L8: 0
A9: Pharmacists | B9: 0 | C9: 0 | D9: 0 | E9: 20 | F9: 0 | G9: 0 | H9: 36 | I9: 0 | J9: 0 | K9: 2 | L9: 0
A10: Administrative staff | B10: 0 | C10: 0 | D10: 0 | E10: 734 | F10: 0 | G10: 0 | H10: 0 | I10: 0 | J10: 0 | K10: 12 | L10: 0
A11: Ambulance Workers | B11: 0 | C11: 0 | D11: 0 | E11: 0 | F11: 0 | G11: 0 | H11: 0 | I11: 0 | J11: 0 | K11: 0 | L11: 0
A12: Audiologists and Speech Therapists | B12: 0 | C12: 0 | D12: 0 | E12: 0 | F12: 0 | G12: 0 | H12: 0 | I12: 0 | J12: 0 | K12: 0 | L12: 0
A13: Biomedical engineer | B13: 0 | C13: 0 | D13: 0 | E13: 109 | F13: 0 | G13: 0 | H13: 0 | I13: 0 | J13: 0 | K13: 0 | L13: 0
A14: Community Health Workers | B14: 0 | C14: 0 | D14: 0 | E14: 0 | F14: 0 | G14: 0 | H14: 115 | I14: 0 | J14: 0 | K14: 1595 | L14: 0
... A62: Traditional and Complementary Medicine Professionals | B62: 0 | C62: 0 | D62: 0 | E62: 0 | F62: 0 | G62: 0 | H62: 0 | I62: 0 | J62: 0 | K62: 0 | L62: 0
A63: Total | B63: =SUM(B3:B62) -> 0 | C63: =SUM(C3:C62) -> 1028 | D63: =SUM(D3:D62) -> 17 | E63: =SUM(E3:E62) -> 3533 | F63: =SUM(F3:F62) -> 0 | G63: =SUM(G3:G62) -> 0 | H63: =SUM(H3:H62) -> 3334 | I63: =SUM(I3:I62) -> 0 | ... L63: =SUM(L3:L62) -> 0
A65: Population UN | B65: 196643.2 | C65: 196632.4 | D65: 194995.3 | E65: 192500.5 | F65: 193339.6 | G65: 198589 | H65: 204196.5 | I65: 209572.8 | J65: 215791.4 | K65: 223125.3 | L65: 228677.8

Sheet Chad
A1: Chad HRH Stock from 2012 to 2022
A2: Occupation | B2: 2012 | C2: 2013 | D2: 2014 | E2: 2015 | F2: 2016 | G2: 2017 | H2: 2018 | I2: 2019 | J2: 2020 | K2: 2021 | L2: 2022 | N2: HOME
A3: Medical Doctors | B3: 528 | C3: 573 | D3: 608 | E3: 696 | F3: 540 | G3: 651 | H3: 803 | I3: 859 | J3: 1003 | K3: 1000 | L3: 1507
A4: Generalist Medical Practitioners (incl. Family medical practitioners) | B4: 0 | C4: 0 | D4: 0 | E4: 0 | F4: 0 | G4: 0 | H4: 646 | I4: 642 | J4: 784 | K4: 740 | L4: 1197
A5: Medical group of Specialists Practitioners | B5: 0 | C5: 0 | D5: 0 | E5: 0 | F5: 0 | G5: 0 | H5: 0 | I5: 0 | J5: 0 | K5: 174 | L5: 0
A6: Nursing Personnel | B6: 3141 | C6: 3606 | D6: 3606 | E6: 3563 | F6: 3106 | G6: 3487 | H6: 4799 | I6: 0 | J6: 2623 | K6: 2677 | L6: 2933
A7: Midwifery personnel | B7: 416 | C7: 451 | D7: 0 | E7: 0 | F7: 0 | G7: 0 | H7: 0 | I7: 589 | J7: 710 | K7: 721 | L7: 783
A8: Dentists | B8: 0 | C8: 0 | D8: 0 | E8: 0 | F8: 0 | G8: 0 | H8: 3 | I8: 0 | J8: 0 | K8: 19 | L8: 21
A9: Pharmacists | B9: 68 | C9: 72 | D9: 78 | E9: 79 | F9: 0 | G9: 71 | H9: 269 | I9: 52 | J9: 54 | K9: 142 | L9: 163
A10: Administrative staff | B10: 0 | C10: 0 | D10: 0 | E10: 0 | F10: 0 | G10: 0 | H10: 0 | I10: 335 | J10: 0 | K10: 0 | L10: 431
A11: Ambulance Workers | B11: 0 | C11: 0 | D11: 0 | E11: 0 | F11: 0 | G11: 0 | H11: 0 | I11: 0 | J11: 0 | K11: 0 | L11: 0
A12: Audiologists and Speech Therapists | B12: 0 | C12: 0 | D12: 0 | E12: 0 | F12: 0 | G12: 0 | H12: 0 | I12: 0 | J12: 0 | K12: 0 | L12: 0
A13: Biomedical engineer | B13: 0 | C13: 0 | D13: 0 | E13: 0 | F13: 0 | G13: 0 | H13: 0 | I13: 560 | J13: 2 | K13: 0 | L13: 0
A14: Community Health Workers | B14: 0 | C14: 0 | D14: 0 | E14: 0 | F14: 0 | G14: 0 | H14: 0 | I14: 0 | J14: 592 | K14: 8077 | L14: 0
... A62: Traditional and Complementary Medicine Professionals | B62: 0 | C62: 0 | D62: 0 | E62: 0 | F62: 0 | G62: 0 | H62: 0 | I62: 0 | J62: 0 | K62: 0 | L62: 21983
A63: Total | B63: =SUM(B3:B62) -> 8238 | C63: =SUM(C3:C62) -> 9332 | D63: =SUM(D3:D62) -> 8506 | E63: =SUM(E3:E62) -> 8597 | F63: =SUM(F3:F62) -> 7292 | G63: =SUM(G3:G62) -> 8347 | H63: =SUM(H3:H62) -> 12225 | I63: =SUM(I3:I62) -> 5740 | ... L63: =SUM(L3:L62) -> 35957
A65: Population UN | B65: 579359.7 | C65: 595182.2 | D65: 610899.3 | E65: 625581.2 | F65: 635851.7 | G65: 646467.9 | H65: 661394.8 | I65: 680354 | J65: 699467.2 | K65: 715665.6 | L65: 734070.3

Sheet Comoros
A1: Comoros HRH Stock from 2012 to 2022
A2: Occupation | B2: 2012 | C2: 2013 | D2: 2014 | E2: 2015 | F2: 2016 | G2: 2017 | H2: 2018 | I2: 2019 | J2: 2020 | K2: 2021 | L2: 2022 | N2: HOME
A3: Medical Doctors | B3: 123 | C3: 0 | D3: 0 | E3: 0 | F3: 216 | G3: 0 | H3: 220 | I3: 0 | J3: 354 | K3: 0 | L3: 0
A4: Generalist Medical Practitioners (incl. Family medical practitioners) | B4: 0 | C4: 0 | D4: 0 | E4: 0 | F4: 216 | G4: 0 | H4: 130 | I4: 0 | J4: 241 | K4: 0 | L4: 0
A5: Medical group of Specialists Practitioners | B5: 0 | C5: 0 | D5: 0 | E5: 0 | F5: 0 | G5: 0 | H5: 0 | I5: 0 | J5: 0 | K5: 0 | L5: 0
A6: Nursing Personnel | B6: 0 | C6: 0 | D6: 0 | E6: 0 | F6: 0 | G6: 0 | H6: 679 | I6: 0 | J6: 683 | K6: 0 | L6: 0
A7: Midwifery personnel | B7: 667 | C7: 295 | D7: 0 | E7: 0 | F7: 500 | G7: 0 | H7: 484 | I7: 0 | J7: 586 | K7: 0 | L7: 0
A8: Dentists | B8: 18 | C8: 0 | D8: 0 | E8: 0 | F8: 0 | G8: 0 | H8: 32 | I8: 0 | J8: 32 | K8: 0 | L8: 0
A9: Pharmacists | B9: 16 | C9: 0 | D9: 0 | E9: 0 | F9: 0 | G9: 0 | H9: 36 | I9: 0 | J9: 35 | K9: 0 | L9: 0
A10: Administrative staff | B10: 0 | C10: 0 | D10: 0 | E10: 0 | F10: 0 | G10: 0 | H10: 0 | I10: 0 | J10: 0 | K10: 0 | L10: 0
A11: Ambulance Workers | B11: 0 | C11: 0 | D11: 0 | E11: 0 | F11: 0 | G11: 0 | H11: 0 | I11: 0 | J11: 0 | K11: 0 | L11: 0
A12: Audiologists and Speech Therapists | B12: 0 | C12: 0 | D12: 0 | E12: 0 | F12: 0 | G12: 0 | H12: 0 | I12: 0 | J12: 0 | K12: 0 | L12: 0
A13: Biomedical engineer | B13: 0 | C13: 0 | D13: 0 | E13: 0 | F13: 0 | G13: 0 | H13: 0 | I13: 0 | J13: 0 | K13: 0 | L13: 0
A14: Community Health Workers | B14: 0 | C14: 0 | D14: 0 | E14: 0 | F14: 0 | G14: 0 | H14: 0 | I14: 0 | J14: 0 | K14: 0 | L14: 0
... A62: Traditional and Complementary Medicine Professionals | B62: 0 | C62: 0 | D62: 0 | E62: 0 | F62: 0 | G62: 0 | H62: 0 | I62: 0 | J62: 0 | K62: 0 | L62: 0
A63: Total | B63: =SUM(B3:B62) -> 1700 | C63: =SUM(C3:C62) -> 590 | D63: =SUM(D3:D62) -> 0 | E63: =SUM(E3:E62) -> 0 | F63: =SUM(F3:F62) -> 1440 | G63: =SUM(G3:G62) -> 0 | H63: =SUM(H3:H62) -> 2861 | I63: =SUM(I3:I62) -> 0 | ... L63: =SUM(L3:L62) -> 0
A65: Population UN | B65: 22453.8 | C65: 22675.4 | D65: 22908.4 | E65: 23131.8 | F65: 23359.6 | G65: 23590.8 | H65: 23759.3 | I65: 23881.9 | J65: 23981 | K65: 24060.4 | L65: 24120.5

Sheet Congo
A1: Congo HRH Stock from 2012 to 2022
A2: Occupation | B2: 2012 | C2: 2013 | D2: 2014 | E2: 2015 | F2: 2016 | G2: 2017 | H2: 2018 | I2: 2019 | J2: 2020 | K2: 2021 | L2: 2022 | N2: HOME
A3: Medical Doctors | B3: 0 | C3: 0 | D3: 0 | E3: 0 | F3: 530 | G3: 0 | H3: 544 | I3: 0 | J3: 0 | K3: 0 | L3: 1042
A4: Generalist Medical Practitioners (incl. Family medical practitioners) | B4: 0 | C4: 0 | D4: 0 | E4: 0 | F4: 269 | G4: 0 | H4: 269 | I4: 0 | J4: 0 | K4: 0 | L4: 787
A5: Medical group of Specialists Practitioners | B5: 0 | C5: 0 | D5: 0 | E5: 0 | F5: 0 | G5: 0 | H5: 0 | I5: 0 | J5: 0 | K5: 0 | L5: 169
A6: Nursing Personnel | B6: 0 | C6: 3289 | D6: 3458 | E6: 3852 | F6: 3717 | G6: 0 | H6: 5081 | I6: 0 | J6: 0 | K6: 0 | L6: 5573
A7: Midwifery personnel | B7: 0 | C7: 1282 | D7: 0 | E7: 0 | F7: 921 | G7: 0 | H7: 0 | I7: 0 | J7: 0 | K7: 0 | L7: 907
A8: Dentists | B8: 0 | C8: 0 | D8: 0 | E8: 0 | F8: 27 | G8: 0 | H8: 27 | I8: 0 | J8: 0 | K8: 0 | L8: 9
A9: Pharmacists | B9: 0 | C9: 0 | D9: 0 | E9: 0 | F9: 73 | G9: 0 | H9: 157 | I9: 0 | J9: 0 | K9: 0 | L9: 28
A10: Administrative staff | B10: 0 | C10: 0 | D10: 0 | E10: 0 | F10: 0 | G10: 0 | H10: 0 | I10: 0 | J10: 0 | K10: 0 | L10: 2442
A11: Ambulance Workers | B11: 0 | C11: 0 | D11: 0 | E11: 0 | F11: 0 | G11: 0 | H11: 0 | I11: 0 | J11: 0 | K11: 0 | L11: 0
A12: Audiologists and Speech Therapists | B12: 0 | C12: 0 | D12: 0 | E12: 0 | F12: 0 | G12: 0 | H12: 0 | I12: 0 | J12: 0 | K12: 0 | L12: 0
A13: Biomedical engineer | B13: 0 | C13: 0 | D13: 0 | E13: 0 | F13: 0 | G13: 0 | H13: 0 | I13: 0 | J13: 0 | K13: 0 | L13: 0
A14: Community Health Workers | B14: 0 | C14: 0 | D14: 0 | E14: 0 | F14: 0 | G14: 0 | H14: 0 | I14: 0 | J14: 0 | K14: 0 | L14: 0
... A62: Traditional and Complementary Medicine Professionals | B62: 0 | C62: 0 | D62: 0 | E62: 0 | F62: 0 | G62: 0 | H62: 0 | I62: 0 | J62: 0 | K62: 0 | L62: 0
A63: Total | B63: =SUM(B3:B62) -> 0 | C63: =SUM(C3:C62) -> 9142 | D63: =SUM(D3:D62) -> 6916 | E63: =SUM(E3:E62) -> 7704 | F63: =SUM(F3:F62) -> 11068 | G63: =SUM(G3:G62) -> 0 | H63: =SUM(H3:H62) -> 11754 | I63: =SUM(I3:I62) -> 0 | ... L63: =SUM(L3:L62) -> 18635
A65: Population UN | B65: 174681.1 | C65: 175389.3 | D65: 175074.6 | E65: 174962.3 | F65: 174800 | G65: 175040.4 | H65: 175834.5 | I65: 176455.7 | J65: 177536.2 | K65: 179200.3 | L65: 180285.9

Sheet Cote d'Ivoire
A1: Cote d'Ivoire HRH Stock from 2012 to 2022 | N1: Home
A2: Occupation | B2: 2012 | C2: 2013 | D2: 2014 | E2: 2015 | F2: 2016 | G2: 2017 | H2: 2018 | I2: 2019 | J2: 2020 | K2: 2021 | L2: 2022
A3: Medical Doctors | B3: 0 | C3: 0 | D3: 5240 | E3: 0 | F3: 0 | G3: 0 | H3: 5602 | I3: 4173 | J3: 4435 | K3: 4951 | L3: 4930
A4: Generalist Medical Practitioners (incl. Family medical practitioners) | B4: 0 | C4: 0 | D4: 0 | E4: 0 | F4: 0 | G4: 0 | H4: 4246 | I4: 0 | J4: 4435 | K4: 4623 | L4: 4412
A5: Medical group of Specialists Practitioners | B5: 0 | C5: 0 | D5: 0 | E5: 0 | F5: 0 | G5: 0 | H5: 0 | I5: 0 | J5: 0 | K5: 0 | L5: 0
A6: Nursing Personnel | B6: 0 | C6: 8780 | D6: 8868 | E6: 10891 | F6: 12132 | G6: 13583 | H6: 15163 | I6: 11259 | J6: 13396 | K6: 12887 | L6: 14979
A7: Midwifery personnel | B7: 0 | C7: 3851 | D7: 5300 | E7: 0 | F7: 0 | G7: 0 | H7: 0 | I7: 5601 | J7: 6345 | K7: 7074 | L7: 7425
A8: Dentists | B8: 0 | C8: 0 | D8: 490 | E8: 0 | F8: 0 | G8: 0 | H8: 506 | I8: 373 | J8: 397 | K8: 416 | L8: 418
A9: Pharmacists | B9: 0 | C9: 0 | D9: 2430 | E9: 0 | F9: 0 | G9: 0 | H9: 2495 | I9: 944 | J9: 1029 | K9: 1117 | L9: 1162
A10: Administrative staff | B10: 0 | C10: 0 | D10: 0 | E10: 0 | F10: 0 | G10: 0 | H10: 0 | I10: 0 | J10: 0 | K10: 0 | L10: 0
A11: Ambulance Workers | B11: 0 | C11: 0 | D11: 0 | E11: 0 | F11: 0 | G11: 0 | H11: 0 | I11: 0 | J11: 0 | K11: 0 | L11: 0
A12: Audiologists and Speech Therapists | B12: 0 | C12: 0 | D12: 0 | E12: 0 | F12: 0 | G12: 0 | H12: 0 | I12: 0 | J12: 0 | K12: 0 | L12: 0
A13: Biomedical engineer | B13: 0 | C13: 0 | D13: 0 | E13: 0 | F13: 0 | G13: 0 | H13: 0 | I13: 0 | J13: 0 | K13: 0 | L13: 0
... A62: Traditional and Complementary Medicine Professionals | B62: 0 | C62: 0 | D62: 0 | E62: 0 | F62: 0 | G62: 0 | H62: 0 | I62: 0 | J62: 0 | K62: 0 | L62: 0
A63: Total | B63: =SUM(B3:B62) -> 0 | C63: =SUM(C3:C62) -> 25262 | D63: =SUM(D3:D62) -> 50752 | E63: =SUM(E3:E62) -> 21782 | F63: =SUM(F3:F62) -> 24264 | G63: =SUM(G3:G62) -> 27166 | H63: =SUM(H3:H62) -> 59087 | I63: =SUM(I3:I62) -> 51061 | ... L63: =SUM(L3:L62) -> 64755
A65: Population UN | B65: 808861.1 | C65: 812933 | D65: 819320.4 | E65: 830910.6 | F65: 846051 | G65: 863980 | H65: 875669 | I65: 883020.8 | J65: 896181.6 | K65: 911396.5 | L65: 924980.8

Sheet DRC
A1: DRC HRH Stock from 2012 to 2022
A2: Occupation | B2: 2012 | C2: 2013 | D2: 2014 | E2: 2015 | F2: 2016 | G2: 2017 | H2: 2018 | I2: 2019 | J2: 2020 | K2: 2021 | L2: 2022 | N2: HOME
A3: Medical Doctors | B3: 0 | C3: 6418 | D3: 0 | E3: 0 | F3: 0 | G3: 0 | H3: 0 | I3: 15016 | J3: 0 | K3: 16989 | L3: 18493
A4: Generalist Medical Practitioners (incl. Family medical practitioners) | B4: 0 | C4: 0 | D4: 0 | E4: 0 | F4: 0 | G4: 0 | H4: 0 | I4: 15016 | J4: 0 | K4: 16989 | L4: 18493
A5: Medical group of Specialists Practitioners | B5: 0 | C5: 0 | D5: 0 | E5: 0 | F5: 0 | G5: 0 | H5: 0 | I5: 0 | J5: 0 | K5: 0 | L5: 0
A6: Nursing Personnel | B6: 0 | C6: 59813 | D6: 0 | E6: 72270 | F6: 44897 | G6: 73046 | H6: 93326 | I6: 93964 | J6: 0 | K6: 101752 | L6: 115316
A7: Midwifery personnel | B7: 0 | C7: 1555 | D7: 0 | E7: 0 | F7: 1793 | G7: 0 | H7: 0 | I7: 3149 | J7: 0 | K7: 2093 | L7: 2640
A8: Dentists | B8: 0 | C8: 0 | D8: 0 | E8: 0 | F8: 147 | G8: 0 | H8: 404 | I8: 422 | J8: 0 | K8: 268 | L8: 392
A9: Pharmacists | B9: 0 | C9: 283 | D9: 0 | E9: 0 | F9: 404 | G9: 0 | H9: 1687 | I9: 584 | J9: 0 | K9: 682 | L9: 806
A10: Administrative staff | B10: 0 | C10: 0 | D10: 0 | E10: 0 | F10: 0 | G10: 0 | H10: 0 | I10: 75871 | J10: 0 | K10: 87086 | L10: 101117
A11: Ambulance Workers | B11: 0 | C11: 0 | D11: 0 | E11: 0 | F11: 0 | G11: 0 | H11: 0 | I11: 0 | J11: 0 | K11: 0 | L11: 0
A12: Audiologists and Speech Therapists | B12: 0 | C12: 0 | D12: 0 | E12: 0 | F12: 0 | G12: 0 | H12: 0 | I12: 0 | J12: 0 | K12: 0 | L12: 0
A13: Biomedical engineer | B13: 0 | C13: 0 | D13: 0 | E13: 0 | F13: 0 | G13: 0 | H13: 0 | I13: 0 | J13: 0 | K13: 0 | L13: 0
A14: Community Health Workers | B14: 0 | C14: 0 | D14: 0 | E14: 0 | F14: 0 | G14: 0 | H14: 0 | I14: 0 | J14: 0 | K14: 0 | L14: 0
... A62: Traditional and Complementary Medicine Professionals | B62: 0 | C62: 0 | D62: 0 | E62: 0 | F62: 0 | G62: 0 | H62: 0 | I62: 0 | J62: 0 | K62: 0 | L62: 0
A63: Total | B63: =SUM(B3:B62) -> 0 | C63: =SUM(C3:C62) -> 138850 | D63: =SUM(D3:D62) -> 0 | E63: =SUM(E3:E62) -> 144540 | F63: =SUM(F3:F62) -> 94131 | G63: =SUM(G3:G62) -> 146092 | H63: =SUM(H3:H62) -> 191677 | I63: =SUM(I3:I62) -> 307934 | ... L63: =SUM(L3:L62) -> 385816
A65: Population UN | B65: 3026941 | C65: 3118004.4 | D65: 3207143.3 | E65: 3300775.6 | F65: 3397335.8 | G65: 3505486.6 | H65: 3612384.5 | I65: 3709546.6 | J65: 3804138.2 | K65: 3905396.8 | L65: 4011145.2

Sheet Equatorial Guinea
A1: Equatorial Guinea HRH Stock from 2012 to 2022
A2: Occupation | B2: 2012 | C2: 2013 | D2: 2014 | E2: 2015 | F2: 2016 | G2: 2017 | H2: 2018 | I2: 2019 | J2: 2020 | K2: 2021 | L2: 2022 | N2: HOME
A3: Medical Doctors | B3: =+'AFRO Stock 2012'!U4 -> 0 | C3: =+'AFRO Stock 2013'!U4 -> 0 | D3: =+'AFRO Stock 2014'!U4 -> 0 | E3: =+'AFRO Stock 2015'!U4 -> 0 | F3: =+'AFRO Stock 2016'!U4 -> 0 | G3: =+'AFRO Stock 2017'!U4 -> 507 | H3: =+'AFRO Stock 2018'!U4 -> 0 | I3: =+'AFRO Stock 2019'!U4 -> 0 | J3: =+'AFRO Stock 2020'!U4 -> 0 | K3: =+'AFRO Stock 2021'!U4 -> 0 | L3: =+'AFRO Stock 2022'!U4 -> 239
A4: Generalist Medical Practitioners (incl. Family medical practitioners) | B4: =+'AFRO Stock 2012'!U5 -> 0 | C4: =+'AFRO Stock 2013'!U5 -> 0 | D4: =+'AFRO Stock 2014'!U5 -> 0 | E4: =+'AFRO Stock 2015'!U5 -> 0 | F4: =+'AFRO Stock 2016'!U5 -> 0 | G4: =+'AFRO Stock 2017'!U5 -> 0 | H4: =+'AFRO Stock 2018'!U5 -> 0 | I4: =+'AFRO Stock 2019'!U5 -> 0 | J4: =+'AFRO Stock 2020'!U5 -> 0 | K4: =+'AFRO Stock 2021'!U5 -> 0 | L4: =+'AFRO Stock 2022'!U5 -> 182
A5: Medical group of Specialists Practitioners | B5: =+'AFRO Stock 2012'!U6 -> 0 | C5: =+'AFRO Stock 2013'!U6 -> 0 | D5: =+'AFRO Stock 2014'!U6 -> 0 | E5: =+'AFRO Stock 2015'!U6 -> 0 | F5: =+'AFRO Stock 2016'!U6 -> 0 | G5: =+'AFRO Stock 2017'!U6 -> 0 | H5: =+'AFRO Stock 2018'!U6 -> 0 | I5: =+'AFRO Stock 2019'!U6 -> 0 | J5: =+'AFRO Stock 2020'!U6 -> 0 | K5: =+'AFRO Stock 2021'!U6 -> 0 | L5: =+'AFRO Stock 2022'!U6 -> 0
A6: Nursing Personnel | B6: =+'AFRO Stock 2012'!U7 -> 0 | C6: =+'AFRO Stock 2013'!U7 -> 0 | D6: =+'AFRO Stock 2014'!U7 -> 0 | E6: =+'AFRO Stock 2015'!U7 -> 0 | F6: =+'AFRO Stock 2016'!U7 -> 0 | G6: =+'AFRO Stock 2017'!U7 -> 634 | H6: =+'AFRO Stock 2018'!U7 -> 0 | I6: =+'AFRO Stock 2019'!U7 -> 0 | J6: =+'AFRO Stock 2020'!U7 -> 0 | K6: =+'AFRO Stock 2021'!U7 -> 0 | L6: =+'AFRO Stock 2022'!U7 -> 1375
A7: Midwifery personnel | B7: =+'AFRO Stock 2012'!U8 -> 0 | C7: =+'AFRO Stock 2013'!U8 -> 0 | D7: =+'AFRO Stock 2014'!U8 -> 0 | E7: =+'AFRO Stock 2015'!U8 -> 0 | F7: =+'AFRO Stock 2016'!U8 -> 0 | G7: =+'AFRO Stock 2017'!U8 -> 0 | H7: =+'AFRO Stock 2018'!U8 -> 0 | I7: =+'AFRO Stock 2019'!U8 -> 0 | J7: =+'AFRO Stock 2020'!U8 -> 0 | K7: =+'AFRO Stock 2021'!U8 -> 0 | L7: =+'AFRO Stock 2022'!U8 -> 23
A8: Dentists | B8: =+'AFRO Stock 2012'!U9 -> 0 | C8: =+'AFRO Stock 2013'!U9 -> 0 | D8: =+'AFRO Stock 2014'!U9 -> 0 | E8: =+'AFRO Stock 2015'!U9 -> 0 | F8: =+'AFRO Stock 2016'!U9 -> 0 | G8: =+'AFRO Stock 2017'!U9 -> 0 | H8: =+'AFRO Stock 2018'!U9 -> 0 | I8: =+'AFRO Stock 2019'!U9 -> 0 | J8: =+'AFRO Stock 2020'!U9 -> 0 | K8: =+'AFRO Stock 2021'!U9 -> 0 | L8: =+'AFRO Stock 2022'!U9 -> 0
A9: Pharmacists | B9: =+'AFRO Stock 2012'!U10 -> 0 | C9: =+'AFRO Stock 2013'!U10 -> 0 | D9: =+'AFRO Stock 2014'!U10 -> 0 | E9: =+'AFRO Stock 2015'!U10 -> 0 | F9: =+'AFRO Stock 2016'!U10 -> 0 | G9: =+'AFRO Stock 2017'!U10 -> 0 | H9: =+'AFRO Stock 2018'!U10 -> 10 | I9: =+'AFRO Stock 2019'!U10 -> 0 | J9: =+'AFRO Stock 2020'!U10 -> 0 | K9: =+'AFRO Stock 2021'!U10 -> 0 | L9: =+'AFRO Stock 2022'!U10 -> 14
A10: Administrative staff | B10: =+'AFRO Stock 2012'!U11 -> 0 | C10: =+'AFRO Stock 2013'!U11 -> 0 | D10: =+'AFRO Stock 2014'!U11 -> 0 | E10: =+'AFRO Stock 2015'!U11 -> 0 | F10: =+'AFRO Stock 2016'!U11 -> 0 | G10: =+'AFRO Stock 2017'!U11 -> 0 | H10: =+'AFRO Stock 2018'!U11 -> 0 | I10: =+'AFRO Stock 2019'!U11 -> 0 | J10: =+'AFRO Stock 2020'!U11 -> 0 | K10: =+'AFRO Stock 2021'!U11 -> 0 | L10: =+'AFRO Stock 2022'!U11 -> 0
A11: Ambulance Workers | B11: =+'AFRO Stock 2012'!U12 -> 0 | C11: =+'AFRO Stock 2013'!U12 -> 0 | D11: =+'AFRO Stock 2014'!U12 -> 0 | E11: =+'AFRO Stock 2015'!U12 -> 0 | F11: =+'AFRO Stock 2016'!U12 -> 0 | G11: =+'AFRO Stock 2017'!U12 -> 0 | H11: =+'AFRO Stock 2018'!U12 -> 0 | I11: =+'AFRO Stock 2019'!U12 -> 0 | J11: =+'AFRO Stock 2020'!U12 -> 0 | K11: =+'AFRO Stock 2021'!U12 -> 0 | L11: =+'AFRO Stock 2022'!U12 -> 0
A12: Audiologists and Speech Therapists | B12: =+'AFRO Stock 2012'!U13 -> 0 | C12: =+'AFRO Stock 2013'!U13 -> 0 | D12: =+'AFRO Stock 2014'!U13 -> 0 | E12: =+'AFRO Stock 2015'!U13 -> 0 | F12: =+'AFRO Stock 2016'!U13 -> 0 | G12: =+'AFRO Stock 2017'!U13 -> 0 | H12: =+'AFRO Stock 2018'!U13 -> 0 | I12: =+'AFRO Stock 2019'!U13 -> 0 | J12: =+'AFRO Stock 2020'!U13 -> 0 | K12: =+'AFRO Stock 2021'!U13 -> 0 | L12: =+'AFRO Stock 2022'!U13 -> 0
A13: Biomedical engineer | B13: =+'AFRO Stock 2012'!U14 -> 0 | C13: =+'AFRO Stock 2013'!U14 -> 0 | D13: =+'AFRO Stock 2014'!U14 -> 0 | E13: =+'AFRO Stock 2015'!U14 -> 0 | F13: =+'AFRO Stock 2016'!U14 -> 0 | G13: =+'AFRO Stock 2017'!U14 -> 0 | H13: =+'AFRO Stock 2018'!U14 -> 0 | I13: =+'AFRO Stock 2019'!U14 -> 0 | J13: =+'AFRO Stock 2020'!U14 -> 0 | K13: =+'AFRO Stock 2021'!U14 -> 0 | L13: =+'AFRO Stock 2022'!U14 -> 0
A14: Community Health Workers | B14: =+'AFRO Stock 2012'!U15 -> 0 | C14: =+'AFRO Stock 2013'!U15 -> 0 | D14: =+'AFRO Stock 2014'!U15 -> 0 | E14: =+'AFRO Stock 2015'!U15 -> 0 | F14: =+'AFRO Stock 2016'!U15 -> 0 | G14: =+'AFRO Stock 2017'!U15 -> 0 | H14: =+'AFRO Stock 2018'!U15 -> 0 | I14: =+'AFRO Stock 2019'!U15 -> 0 | J14: =+'AFRO Stock 2020'!U15 -> 0 | K14: =+'AFRO Stock 2021'!U15 -> 0 | L14: =+'AFRO Stock 2022'!U15 -> 146
... A62: Traditional and Complementary Medicine Professionals | B62: =+'AFRO Stock 2012'!U63 -> 0 | C62: =+'AFRO Stock 2013'!U63 -> 0 | D62: =+'AFRO Stock 2014'!U63 -> 0 | E62: =+'AFRO Stock 2015'!U63 -> 0 | F62: =+'AFRO Stock 2016'!U63 -> 0 | G62: =+'AFRO Stock 2017'!U63 -> 0 | H62: =+'AFRO Stock 2018'!U63 -> 0 | I62: =+'AFRO Stock 2019'!U63 -> 0 | J62: =+'AFRO Stock 2020'!U63 -> 0 | K62: =+'AFRO Stock 2021'!U63 -> 0 | L62: =+'AFRO Stock 2022'!U63 -> 0
A63: Total | B63: =SUM(B3:B62) -> 0 | C63: =SUM(C3:C62) -> 0 | D63: =SUM(D3:D62) -> 0 | E63: =SUM(E3:E62) -> 0 | F63: =SUM(F3:F62) -> 0 | G63: =SUM(G3:G62) -> 2282 | H63: =SUM(H3:H62) -> 12 | I63: =SUM(I3:I62) -> 0 | ... L63: =SUM(L3:L62) -> 4136
A65: Population UN | B65: 42828 | C65: 44010.1 | D65: 45062.4 | E65: 45967.3 | F65: 46750.5 | G65: 47406.7 | H65: 47969.6 | I65: 48504 | J65: 48954.6 | K65: 49221.8 | L65: 49447.1

Sheet Eritrea
A1: Eritrea HRH Stock from 2012 to 2022
A2: Occupation | B2: 2012 | C2: 2013 | D2: 2014 | E2: 2015 | F2: 2016 | G2: 2017 | H2: 2018 | I2: 2019 | J2: 2020 | K2: 2021 | L2: 2022 | N2: HOME
A3: Medical Doctors | B3: 153 | C3: 172 | D3: 204 | E3: 212 | F3: 226 | G3: 224 | H3: 280 | I3: 248 | J3: 291 | K3: 286 | L3: 260
A4: Generalist Medical Practitioners (incl. Family medical practitioners) | B4: 0 | C4: 0 | D4: 0 | E4: 0 | F4: 0 | G4: 0 | H4: 160 | I4: 0 | J4: 0 | K4: 276 | L4: 260
A5: Medical group of Specialists Practitioners | B5: 0 | C5: 0 | D5: 0 | E5: 0 | F5: 0 | G5: 0 | H5: 0 | I5: 0 | J5: 0 | K5: 19 | L5: 19
A6: Nursing Personnel | B6: 0 | C6: 4262 | D6: 4132 | E6: 3962 | F6: 4484 | G6: 4528 | H6: 4971 | I6: 0 | J6: 0 | K6: 4681 | L6: 5007
A7: Midwifery personnel | B7: 0 | C7: 0 | D7: 0 | E7: 0 | F7: 376 | G7: 0 | H7: 0 | I7: 0 | J7: 0 | K7: 67 | L7: 67
A8: Dentists | B8: 0 | C8: 0 | D8: 0 | E8: 0 | F8: 0 | G8: 0 | H8: 186 | I8: 0 | J8: 0 | K8: 60 | L8: 58
A9: Pharmacists | B9: 0 | C9: 0 | D9: 0 | E9: 0 | F9: 0 | G9: 0 | H9: 451 | I9: 0 | J9: 0 | K9: 208 | L9: 199
A10: Administrative staff | B10: 0 | C10: 0 | D10: 0 | E10: 0 | F10: 0 | G10: 0 | H10: 0 | I10: 0 | J10: 0 | K10: 0 | L10: 4713
A11: Ambulance Workers | B11: 0 | C11: 0 | D11: 0 | E11: 0 | F11: 0 | G11: 0 | H11: 0 | I11: 0 | J11: 0 | K11: 0 | L11: 0
A12: Audiologists and Speech Therapists | B12: 0 | C12: 0 | D12: 0 | E12: 0 | F12: 0 | G12: 0 | H12: 0 | I12: 0 | J12: 0 | K12: 0 | L12: 0
A13: Biomedical engineer | B13: 0 | C13: 0 | D13: 0 | E13: 0 | F13: 0 | G13: 0 | H13: 0 | I13: 0 | J13: 0 | K13: 11 | L13: 11
A14: Community Health Workers | B14: 0 | C14: 0 | D14: 0 | E14: 0 | F14: 0 | G14: 0 | H14: 243 | I14: 0 | J14: 6000 | K14: 2626 | L14: 2626
... A62: Traditional and Complementary Medicine Professionals | B62: 0 | C62: 0 | D62: 0 | E62: 0 | F62: 0 | G62: 0 | H62: 0 | I62: 0 | J62: 0 | K62: 0 | L62: 0
A63: Total | B63: =SUM(B3:B62) -> 389 | C63: =SUM(C3:C62) -> 8951 | D63: =SUM(D3:D62) -> 8748 | E63: =SUM(E3:E62) -> 8421 | F63: =SUM(F3:F62) -> 10257 | G63: =SUM(G3:G62) -> 9585 | H63: =SUM(H3:H62) -> 12010 | I63: =SUM(I3:I62) -> 576 | ... L63: =SUM(L3:L62) -> 20398
A65: Population UN | B65: 105648.1 | C65: 104956.6 | D65: 104202.4 | E65: 102828.4 | F65: 101415.1 | G65: 100718.5 | H65: 100677 | I65: 101446.8 | J65: 102444.9 | K65: 103744.1 | L65: 105140.5

Sheet Eswatini
A1: Eswatini HRH Stock from 2012 to 2022
A2: Occupation | B2: 2012 | C2: 2013 | D2: 2014 | E2: 2015 | F2: 2016 | G2: 2017 | H2: 2018 | I2: 2019 | J2: 2020 | K2: 2021 | L2: 2022 | N2: HOME
A3: Medical Doctors | B3: 0 | C3: 0 | D3: 0 | E3: 0 | F3: 107 | G3: 208 | H3: 278 | I3: 0 | J3: 165 | K3: 0 | L3: 1912
A4: Generalist Medical Practitioners (incl. Family medical practitioners) | B4: 0 | C4: 0 | D4: 0 | E4: 0 | F4: 0 | G4: 0 | H4: 211 | I4: 0 | J4: 136 | K4: 0 | L4: 623
A5: Medical group of Specialists Practitioners | B5: 0 | C5: 0 | D5: 0 | E5: 0 | F5: 0 | G5: 0 | H5: 0 | I5: 0 | J5: 0 | K5: 0 | L5: 0
A6: Nursing Personnel | B6: 0 | C6: 3735 | D6: 3847 | E6: 3976 | F6: 4200 | G6: 4431 | H6: 4706 | I6: 0 | J6: 2917 | K6: 0 | L6: 3824
A7: Midwifery personnel | B7: 0 | C7: 0 | D7: 0 | E7: 0 | F7: 0 | G7: 0 | H7: 0 | I7: 0 | J7: 0 | K7: 0 | L7: 0
A8: Dentists | B8: 0 | C8: 0 | D8: 0 | E8: 0 | F8: 0 | G8: 0 | H8: 74 | I8: 14 | J8: 22 | K8: 0 | L8: 0
A9: Pharmacists | B9: 0 | C9: 0 | D9: 0 | E9: 0 | F9: 0 | G9: 0 | H9: 281 | I9: 0 | J9: 48 | K9: 0 | L9: 0
A10: Administrative staff | B10: 0 | C10: 0 | D10: 0 | E10: 0 | F10: 0 | G10: 0 | H10: 0 | I10: 0 | J10: 2087 | K10: 0 | L10: 0
A11: Ambulance Workers | B11: 0 | C11: 0 | D11: 0 | E11: 0 | F11: 0 | G11: 0 | H11: 0 | I11: 0 | J11: 374 | K11: 0 | L11: 0
A12: Audiologists and Speech Therapists | B12: 0 | C12: 0 | D12: 0 | E12: 0 | F12: 0 | G12: 0 | H12: 0 | I12: 0 | J12: 7 | K12: 0 | L12: 0
A13: Biomedical engineer | B13: 0 | C13: 0 | D13: 0 | E13: 0 | F13: 0 | G13: 0 | H13: 0 | I13: 0 | J13: 75 | K13: 0 | L13: 0
A14: Community Health Workers | B14: 0 | C14: 0 | D14: 0 | E14: 0 | F14: 0 | G14: 0 | H14: 6324 | I14: 0 | J14: 5386 | K14: 0 | L14: 0
... A65: Population UN | B65: 32540 | C65: 32451 | D65: 32210.7 | E65: 31767.3 | F65: 31320.3 | G65: 30815.7 | H65: 30300.3 | I65: 29875.9 | J65: 29530.3 | K65: 29226.2 | L65: 28860

Sheet Ethiopia
A1: Ethiopia HRH Stock from 2012 to 2022
A2: Occupation | B2: 2012 | C2: 2013 | D2: 2014 | E2: 2015 | F2: 2016 | G2: 2017 | H2: 2018 | I2: 2019 | J2: 2020 | K2: 2021 | L2: 2022 | N2: HOME
A3: Medical Doctors | B3: 0 | C3: 0 | D3: 0 | E3: 0 | F3: 0 | G3: 0 | H3: 8395 | I3: 5867 | J3: 12174 | K3: 12174 | L3: 13327
A4: Generalist Medical Practitioners (incl. Family medical practitioners) | B4: 0 | C4: 0 | D4: 0 | E4: 0 | F4: 0 | G4: 0 | H4: 5867 | I4: 5867 | J4: 9361 | K4: 9361 | L4: 8860
A5: Medical group of Specialists Practitioners | B5: 0 | C5: 0 | D5: 0 | E5: 0 | F5: 0 | G5: 0 | H5: 0 | I5: 0 | J5: 847 | K5: 0 | L5: 540
A6: Nursing Personnel | B6: 0 | C6: 0 | D6: 0 | E6: 0 | F6: 0 | G6: 88164 | H6: 61772 | I6: 0 | J6: 69824 | K6: 69824 | L6: 70246
A7: Midwifery personnel | B7: 0 | C7: 6925 | D7: 0 | E7: 0 | F7: 12069 | G7: 0 | H7: 16159 | I7: 0 | J7: 20355 | K7: 20355 | L7: 21993
A8: Dentists | B8: 0 | C8: 0 | D8: 0 | E8: 0 | F8: 0 | G8: 0 | H8: 1889 | I8: 52 | J8: 228 | K8: 0 | L8: 271
A9: Pharmacists | B9: 0 | C9: 0 | D9: 0 | E9: 0 | F9: 0 | G9: 0 | H9: 10752 | I9: 0 | J9: 5394 | K9: 15498 | L9: 5871
A10: Administrative staff | B10: 0 | C10: 0 | D10: 0 | E10: 0 | F10: 0 | G10: 0 | H10: 0 | I10: 0 | J10: 113189 | K10: 113189 | L10: 121853
A11: Ambulance Workers | B11: 0 | C11: 0 | D11: 0 | E11: 0 | F11: 0 | G11: 0 | H11: 0 | I11: 0 | J11: 0 | K11: 0 | L11: 0
A12: Audiologists and Speech Therapists | B12: 0 | C12: 0 | D12: 0 | E12: 0 | F12: 0 | G12: 0 | H12: 0 | I12: 0 | J12: 4 | K12: 0 | L12: 0
A13: Biomedical engineer | B13: 0 | C13: 0 | D13: 0 | E13: 0 | F13: 0 | G13: 0 | H13: 0 | I13: 0 | J13: 423 | K13: 987 | L13: 1086
A14: Community Health Workers | B14: 0 | C14: 0 | D14: 0 | E14: 0 | F14: 0 | G14: 0 | H14: 37259 | I14: 0 | J14: 42630 | K14: 42630 | L14: 41101
... A62: Traditional and Complementary Medicine Professionals | B62: 0 | C62: 0 | D62: 0 | E62: 0 | F62: 0 | G62: 0 | H62: 0 | I62: 0 | J62: 0 | K62: 0 | L62: 0
A63: Total | B63: =SUM(B3:B62) -> 0 | C63: =SUM(C3:C62) -> 13850 | D63: =SUM(D3:D62) -> 0 | E63: =SUM(E3:E62) -> 0 | F63: =SUM(F3:F62) -> 24434 | G63: =SUM(G3:G62) -> 176328 | H63: =SUM(H3:H62) -> 233238 | I63: =SUM(I3:I62) -> 11786 | ... L63: =SUM(L3:L62) -> 427752
A65: Population UN | B65: 3248329.2 | C65: 3257516.8 | D65: 3292126.2 | E65: 3362812.3 | F65: 3447899.3 | G65: 3528311.4 | H65: 3612346.7 | I65: 3717724.4 | J65: 3808847.5 | K65: 3870531 | L65: 3920543

Sheet Gabon
A1: Gabon HRH Stock from 2012 to 2022
A2: Occupation | B2: 2012 | C2: 2013 | D2: 2014 | E2: 2015 | F2: 2016 | G2: 2017 | H2: 2018 | I2: 2019 | J2: 2020 | K2: 2021 | L2: 2022 | N2: HOME
A3: Medical Doctors | B3: 0 | C3: 0 | D3: 0 | E3: 0 | F3: 715 | G3: 1408 | H3: 1368 | I3: 1368 | J3: 1362 | K3: 0 | L3: 1139
A4: Generalist Medical Practitioners (incl. Family medical practitioners) | B4: 0 | C4: 0 | D4: 0 | E4: 0 | F4: 0 | G4: 570 | H4: 570 | I4: 516 | J4: 526 | K4: 0 | L4: 612
A5: Medical group of Specialists Practitioners | B5: 0 | C5: 0 | D5: 0 | E5: 0 | F5: 0 | G5: 0 | H5: 0 | I5: 113 | J5: 114 | K5: 0 | L5: 137
A6: Nursing Personnel | B6: 0 | C6: 0 | D6: 0 | E6: 0 | F6: 4596 | G6: 5350 | H6: 6085 | I6: 4711 | J6: 5481 | K6: 0 | L6: 4277
A7: Midwifery personnel | B7: 0 | C7: 437 | D7: 0 | E7: 0 | F7: 513 | G7: 733 | H7: 0 | I7: 607 | J7: 662 | K7: 0 | L7: 920
A8: Dentists | B8: 0 | C8: 0 | D8: 0 | E8: 0 | F8: 0 | G8: 37 | H8: 40 | I8: 34 | J8: 34 | K8: 0 | L8: 44
A9: Pharmacists | B9: 0 | C9: 0 | D9: 0 | E9: 0 | F9: 46 | G9: 121 | H9: 227 | I9: 140 | J9: 139 | K9: 0 | L9: 168
A10: Administrative staff | B10: 0 | C10: 0 | D10: 0 | E10: 0 | F10: 0 | G10: 1943 | H10: 0 | I10: 693 | J10: 693 | K10: 0 | L10: 0
A11: Ambulance Workers | B11: 0 | C11: 0 | D11: 0 | E11: 0 | F11: 0 | G11: 0 | H11: 0 | I11: 159 | J11: 132 | K11: 0 | L11: 0
A12: Audiologists and Speech Therapists | B12: 0 | C12: 0 | D12: 0 | E12: 0 | F12: 0 | G12: 2 | H12: 0 | I12: 1 | J12: 0 | K12: 0 | L12: 0
A13: Biomedical engineer | B13: 0 | C13: 0 | D13: 0 | E13: 0 | F13: 0 | G13: 8 | H13: 0 | I13: 65 | J13: 66 | K13: 0 | L13: 0
A14: Community Health Workers | B14: 0 | C14: 0 | D14: 0 | E14: 0 | F14: 0 | G14: 0 | H14: 0 | I14: 117 | J14: 110 | K14: 0 | L14: 98
... A62: Traditional and Complementary Medicine Professionals | B62: 0 | C62: 0 | D62: 0 | E62: 0 | F62: 0 | G62: 99 | H62: 0 | I62: 33 | J62: 33 | K62: 0 | L62: 0
A63: Total | B63: =SUM(B3:B62) -> 0 | C63: =SUM(C3:C62) -> 874 | D63: =SUM(D3:D62) -> 0 | E63: =SUM(E3:E62) -> 0 | F63: =SUM(F3:F62) -> 12326 | G63: =SUM(G3:G62) -> 19134 | H63: =SUM(H3:H62) -> 15612 | I63: =SUM(I3:I62) -> 22486 | ... L63: =SUM(L3:L62) -> 15278
A65: Population UN | B65: 59226.3 | C65: 60469.6 | D65: 61619.1 | E65: 62601.9 | F65: 63306.9 | G65: 63752.5 | H65: 63976.2 | I65: 64066.9 | J65: 64112.7 | K65: 64185.3 | L65: 64514.8

Sheet Gambia
A1: Gambia HRH Stock from 2012 to 2022
A2: Occupation | B2: 2012 | C2: 2013 | D2: 2014 | E2: 2015 | F2: 2016 | G2: 2017 | H2: 2018 | I2: 2019 | J2: 2020 | K2: 2021 | L2: 2022 | N2: HOME
A3: Medical Doctors | B3: 0 | C3: 0 | D3: 0 | E3: 213 | F3: 0 | G3: 232 | H3: 298 | I3: 188 | J3: 196 | K3: 269 | L3: 0
A4: Generalist Medical Practitioners (incl. Family medical practitioners) | B4: 0 | C4: 0 | D4: 0 | E4: 0 | F4: 0 | G4: 152 | H4: 181 | I4: 107 | J4: 122 | K4: 156 | L4: 0
A5: Medical group of Specialists Practitioners | B5: 0 | C5: 0 | D5: 0 | E5: 0 | F5: 0 | G5: 0 | H5: 0 | I5: 51 | J5: 47 | K5: 69 | L5: 0
A6: Nursing Personnel | B6: 2386 | C6: 0 | D6: 0 | E6: 2372 | F6: 0 | G6: 1127 | H6: 1498 | I6: 749 | J6: 1229 | K6: 1404 | L6: 0
A7: Midwifery personnel | B7: 0 | C7: 259 | D7: 0 | E7: 850 | F7: 0 | G7: 422 | H7: 0 | I7: 341 | J7: 540 | K7: 379 | L7: 0
A8: Dentists | B8: 0 | C8: 0 | D8: 0 | E8: 17 | F8: 0 | G8: 0 | H8: 4 | I8: 12 | J8: 8 | K8: 9 | L8: 0
A9: Pharmacists | B9: 0 | C9: 0 | D9: 0 | E9: 5 | F9: 0 | G9: 0 | H9: 2 | I9: 2 | J9: 0 | K9: 4 | L9: 0
A10: Administrative staff | B10: 0 | C10: 0 | D10: 0 | E10: 0 | F10: 0 | G10: 0 | H10: 0 | I10: 0 | J10: 0 | K10: 0 | L10: 0
A11: Ambulance Workers | B11: 0 | C11: 0 | D11: 0 | E11: 0 | F11: 0 | G11: 0 | H11: 0 | I11: 0 | J11: 0 | K11: 0 | L11: 0
A12: Audiologists and Speech Therapists | B12: 0 | C12: 0 | D12: 0 | E12: 0 | F12: 0 | G12: 0 | H12: 0 | I12: 0 | J12: 0 | K12: 0 | L12: 0
A13: Biomedical engineer | B13: 0 | C13: 0 | D13: 0 | E13: 0 | F13: 0 | G13: 0 | H13: 0 | I13: 10 | J13: 10 | K13: 3 | L13: 0
A14: Community Health Workers | B14: 0 | C14: 0 | D14: 0 | E14: 0 | F14: 0 | G14: 0 | H14: 1553 | I14: 0 | J14: 0 | K14: 0 | L14: 0
... A62: Traditional and Complementary Medicine Professionals | B62: 0 | C62: 0 | D62: 0 | E62: 0 | F62: 0 | G62: 0 | H62: 0 | I62: 0 | J62: 0 | K62: 0 | L62: 0
A63: Total | B63: =SUM(B3:B62) -> 5555 | C63: =SUM(C3:C62) -> 518 | D63: =SUM(D3:D62) -> 0 | E63: =SUM(E3:E62) -> 7387 | F63: =SUM(F3:F62) -> 1 | G63: =SUM(G3:G62) -> 4030 | H63: =SUM(H3:H62) -> 5382 | I63: =SUM(I3:I62) -> 3452 | ... L63: =SUM(L3:L62) -> 0
A65: Population UN | B65: 81185.8 | C65: 82489.4 | D65: 83366.8 | E65: 83965.3 | F65: 84366.1 | G65: 84719.8 | H65: 85148.1 | I65: 85715.6 | J65: 86528 | K65: 87525.9 | L65: 88529.1

Sheet Ghana
A1: Ghana HRH Stock from 2012 to 2022
A2: Occupation | B2: 2012 | C2: 2013 | D2: 2014 | E2: 2015 | F2: 2016 | G2: 2017 | H2: 2018 | I2: 2019 | J2: 2020 | K2: 2021 | L2: 2022 | N2: HOME
A3: Medical Doctors | B3: =+'AFRO Stock 2012'!W4 -> 2486 | C3: =+'AFRO Stock 2013'!W4 -> 2730 | D3: =+'AFRO Stock 2014'!W4 -> 3016 | E3: =+'AFRO Stock 2015'!W4 -> 3263 | F3: =+'AFRO Stock 2016'!W4 -> 3618 | G3: =+'AFRO Stock 2017'!W4 -> 2679 | H3: =+'AFRO Stock 2018'!W4 -> 4406 | I3: =+'AFRO Stock 2019'!W4 -> 3236 | J3: =+'AFRO Stock 2020'!W4 -> 5285 | K3: =+'AFRO Stock 2021'!W4 -> 4169 | L3: =+'AFRO Stock 2022'!W4 -> 4726
A4: Generalist Medical Practitioners (incl. Family medical practitioners) | B4: =+'AFRO Stock 2012'!W5 -> 0 | C4: =+'AFRO Stock 2013'!W5 -> 0 | D4: =+'AFRO Stock 2014'!W5 -> 0 | E4: =+'AFRO Stock 2015'!W5 -> 0 | F4: =+'AFRO Stock 2016'!W5 -> 0 | G4: =+'AFRO Stock 2017'!W5 -> 1757 | H4: =+'AFRO Stock 2018'!W5 -> 3316 | I4: =+'AFRO Stock 2019'!W5 -> 2181 | J4: =+'AFRO Stock 2020'!W5 -> 0 | K4: =+'AFRO Stock 2021'!W5 -> 3034 | L4: =+'AFRO Stock 2022'!W5 -> 3344
A5: Medical group of Specialists Practitioners | B5: =+'AFRO Stock 2012'!W6 -> 0 | C5: =+'AFRO Stock 2013'!W6 -> 0 | D5: =+'AFRO Stock 2014'!W6 -> 0 | E5: =+'AFRO Stock 2015'!W6 -> 0 | F5: =+'AFRO Stock 2016'!W6 -> 0 | G5: =+'AFRO Stock 2017'!W6 -> 0 | H5: =+'AFRO Stock 2018'!W6 -> 0 | I5: =+'AFRO Stock 2019'!W6 -> 0 | J5: =+'AFRO Stock 2020'!W6 -> 0 | K5: =+'AFRO Stock 2021'!W6 -> 0 | L5: =+'AFRO Stock 2022'!W6 -> 0
A6: Nursing Personnel | B6: =+'AFRO Stock 2012'!W7 -> 0 | C6: =+'AFRO Stock 2013'!W7 -> 0 | D6: =+'AFRO Stock 2014'!W7 -> 37404 | E6: =+'AFRO Stock 2015'!W7 -> 48939 | F6: =+'AFRO Stock 2016'!W7 -> 52605 | G6: =+'AFRO Stock 2017'!W7 -> 58608 | H6: =+'AFRO Stock 2018'!W7 -> 125024 | I6: =+'AFRO Stock 2019'!W7 -> 69789 | J6: =+'AFRO Stock 2020'!W7 -> 95789 | K6: =+'AFRO Stock 2021'!W7 -> 93144 | L6: =+'AFRO Stock 2022'!W7 -> 102943
A7: Midwifery personnel | B7: =+'AFRO Stock 2012'!W8 -> 0 | C7: =+'AFRO Stock 2013'!W8 -> 11287 | D7: =+'AFRO Stock 2014'!W8 -> 0 | E7: =+'AFRO Stock 2015'!W8 -> 6808 | F7: =+'AFRO Stock 2016'!W8 -> 7662 | G7: =+'AFRO Stock 2017'!W8 -> 9554 | H7: =+'AFRO Stock 2018'!W8 -> 10489 | I7: =+'AFRO Stock 2019'!W8 -> 12673 | J7: =+'AFRO Stock 2020'!W8 -> 16700 | K7: =+'AFRO Stock 2021'!W8 -> 19141 | L7: =+'AFRO Stock 2022'!W8 -> 23882
A8: Dentists | B8: =+'AFRO Stock 2012'!W9 -> 0 | C8: =+'AFRO Stock 2013'!W9 -> 0 | D8: =+'AFRO Stock 2014'!W9 -> 0 | E8: =+'AFRO Stock 2015'!W9 -> 0 | F8: =+'AFRO Stock 2016'!W9 -> 400 | G8: =+'AFRO Stock 2017'!W9 -> 0 | H8: =+'AFRO Stock 2018'!W9 -> 713 | I8: =+'AFRO Stock 2019'!W9 -> 0 | J8: =+'AFRO Stock 2020'!W9 -> 0 | K8: =+'AFRO Stock 2021'!W9 -> 0 | L8: =+'AFRO Stock 2022'!W9 -> 0
A9: Pharmacists | B9: =+'AFRO Stock 2012'!W10 -> 0 | C9: =+'AFRO Stock 2013'!W10 -> 0 | D9: =+'AFRO Stock 2014'!W10 -> 0 | E9: =+'AFRO Stock 2015'!W10 -> 0 | F9: =+'AFRO Stock 2016'!W10 -> 570 | G9: =+'AFRO Stock 2017'!W10 -> 718 | H9: =+'AFRO Stock 2018'!W10 -> 918 | I9: =+'AFRO Stock 2019'!W10 -> 1138 | J9: =+'AFRO Stock 2020'!W10 -> 1388 | K9: =+'AFRO Stock 2021'!W10 -> 1035 | L9: =+'AFRO Stock 2022'!W10 -> 1188
A10: Administrative staff | B10: =+'AFRO Stock 2012'!W11 -> 0 | C10: =+'AFRO Stock 2013'!W11 -> 0 | D10: =+'AFRO Stock 2014'!W11 -> 0 | E10: =+'AFRO Stock 2015'!W11 -> 0 | F10: =+'AFRO Stock 2016'!W11 -> 0 | G10: =+'AFRO Stock 2017'!W11 -> 0 | H10: =+'AFRO Stock 2018'!W11 -> 0 | I10: =+'AFRO Stock 2019'!W11 -> 0 | J10: =+'AFRO Stock 2020'!W11 -> 0 | K10: =+'AFRO Stock 2021'!W11 -> 4274 | L10: =+'AFRO Stock 2022'!W11 -> 4065
A11: Ambulance Workers | B11: =+'AFRO Stock 2012'!W12 -> 0 | C11: =+'AFRO Stock 2013'!W12 -> 0 | D11: =+'AFRO Stock 2014'!W12 -> 0 | E11: =+'AFRO Stock 2015'!W12 -> 0 | F11: =+'AFRO Stock 2016'!W12 -> 0 | G11: =+'AFRO Stock 2017'!W12 -> 0 | H11: =+'AFRO Stock 2018'!W12 -> 0 | I11: =+'AFRO Stock 2019'!W12 -> 0 | J11: =+'AFRO Stock 2020'!W12 -> 0 | K11: =+'AFRO Stock 2021'!W12 -> 2091 | L11: =+'AFRO Stock 2022'!W12 -> 3583
A12: Audiologists and Speech Therapists | B12: 0 | C12: 0 | D12: 0 | E12: 0 | F12: 0 | G12: 0 | H12: 0 | I12: 0 | J12: 0 | K12: 9 | L12: 30
A13: Biomedical engineer | B13: 0 | C13: 0 | D13: 0 | E13: 0 | F13: 0 | G13: 0 | H13: 0 | I13: 0 | J13: 0 | K13: 0 | L13: 0
A14: Community Health Workers | B14: 0 | C14: 5293 | D14: 0 | E14: 0 | F14: 0 | G14: 15456 | H14: 15820 | I14: 0 | J14: 0 | K14: 0 | L14: 0
A15: Dental Assistants and Therapists | B15: 0 | C15: 0 | D15: 0 | E15: 0 | F15: 516 | G15: 46 | H15: 0 | I15: 0 | J15: 0 | K15: 396 | L15: 488
A16: Dental Prosthetic Technicians | B16: 0 | C16: 0 | D16: 0 | E16: 0 | F16: 30 | G16: 167 | H16: 0 | I16: 0 | J16: 0 | K16: 0 | L16: 0
A17: Dieticians | B17: 0 | C17: 0 | D17: 0 | E17: 0 | F17: 0 | G17: 34 | H17: 0 | I17: 0 | J17: 0 | K17: 112 | L17: 153
A18: Dispensing Opticians | B18: 0 | C18: 0 | D18: 0 | E18: 0 | F18: 0 | G18: 0 | H18: 0 | I18: 0 | J18: 0 | K18: 0 | L18: 0
A19: Engineering and maintenance staff | B19: 0 | C19: 0 | D19: 0 | E19: 0 | F19: 0 | G19: 0 | H19: 0 | I19: 0 | J19: 0 | K19: 380 | L19: 436
A20: Environmental and Occupational Health Inspectors and Associates | B20: 0 | C20: 1473 | D20: 0 | E20: 0 | F20: 0 | G20: 0 | H20: 0 | I20: 0 | J20: 0 | K20: 0 | L20: 0
A21: Environmental and Occupational Health and Hygiene Professionals | B21: 0 | C21: 3639 | D21: 0 | E21: 0 | F21: 0 | G21: 0 | H21: 0 | I21: 0 | J21: 0 | K21: 6 | L21: 47
A22: General Paediatricians Practitioners | B22: 0 | C22: 0 | D22: 0 | E22: 0 | F22: 0 | G22: 0 | H22: 0 | I22: 0 | J22: 0 | K22: 0 | L22: 0
A23: Health Care Assistants | B23: 0 | C23: 0 | D23: 0 | E23: 0 | F23: 0 | G23: 0 | H23: 0 | I23: 0 | J23: 0 | K23: 0 | L23: 0
... A62: Traditional and Complementary Medicine Professionals | B62: 0 | C62: 4166 | D62: 0 | E62: 0 | F62: 0 | G62: 0 | H62: 0 | I62: 0 | J62: 0 | K62: 7 | L62: 0
A63: Total | B63: =SUM(B3:B62) -> 4972 | C63: =SUM(C3:C62) -> 57182 | D63: =SUM(D3:D62) -> 80840 | E63: =SUM(E3:E62) -> 118020 | F63: =SUM(F3:F62) -> 129286 | G63: =SUM(G3:G62) -> 160083 | H63: =SUM(H3:H62) -> 298852 | I63: =SUM(I3:I62) -> 172696 | ... L63: =SUM(L3:L62) -> 291782
A65: Population UN | B65: 867829 | C65: 884877.4 | D65: 893372.3 | E65: 904717.2 | F65: 908452.5 | G65: 890481.1 | H65: 889062.6 | I65: 902628.3 | J65: 906937.8 | K65: 910102.9 | L65: 913289.2

Sheet Guinea
A1: Guinea HRH Stock from 2012 to 2022
A2: Occupation | B2: 2012 | C2: 2013 | D2: 2014 | E2: 2015 | F2: 2016 | G2: 2017 | H2: 2018 | I2: 2019 | J2: 2020 | K2: 2021 | L2: 2022 | N2: HOME
A3: Medical Doctors | B3: 0 | C3: 0 | D3: 1844 | E3: 977 | F3: 977 | G3: 0 | H3: 2787 | I3: 0 | J3: 0 | K3: 0 | L3: 297
A4: Generalist Medical Practitioners (incl. Family medical practitioners) | B4: 0 | C4: 0 | D4: 0 | E4: 0 | F4: 0 | G4: 0 | H4: 2649 | I4: 0 | J4: 0 | K4: 0 | L4: 0
A5: Medical group of Specialists Practitioners | B5: 0 | C5: 0 | D5: 0 | E5: 0 | F5: 0 | G5: 0 | H5: 0 | I5: 0 | J5: 0 | K5: 0 | L5: 5
A6: Nursing Personnel | B6: 0 | C6: 0 | D6: 5789 | E6: 4389 | F6: 1010 | G6: 0 | H6: 7195 | I6: 0 | J6: 0 | K6: 0 | L6: 4367
A7: Midwifery personnel | B7: 0 | C7: 500 | D7: 500 | E7: 376 | F7: 443 | G7: 0 | H7: 0 | I7: 0 | J7: 0 | K7: 0 | L7: 777
A8: Dentists | B8: 0 | C8: 0 | D8: 0 | E8: 0 | F8: 50 | G8: 0 | H8: 73 | I8: 0 | J8: 0 | K8: 0 | L8: 34
A9: Pharmacists | B9: 0 | C9: 0 | D9: 0 | E9: 142 | F9: 107 | G9: 0 | H9: 255 | I9: 0 | J9: 0 | K9: 0 | L9: 0
A10: Administrative staff | B10: 0 | C10: 0 | D10: 0 | E10: 0 | F10: 0 | G10: 0 | H10: 0 | I10: 0 | J10: 0 | K10: 0 | L10: 0
A11: Ambulance Workers | B11: 0 | C11: 0 | D11: 0 | E11: 0 | F11: 0 | G11: 0 | H11: 0 | I11: 0 | J11: 0 | K11: 0 | L11: 0
A12: Audiologists and Speech Therapists | B12: 0 | C12: 0 | D12: 0 | E12: 0 | F12: 0 | G12: 0 | H12: 0 | I12: 0 | J12: 0 | K12: 0 | L12: 0
A13: Biomedical engineer | B13: 0 | C13: 0 | D13: 0 | E13: 0 | F13: 0 | G13: 0 | H13: 0 | I13: 0 | J13: 0 | K13: 0 | L13: 0
A14: Community Health Workers | B14: 0 | C14: 0 | D14: 0 | E14: 6700 | F14: 6700 | G14: 0 | H14: 16567 | I14: 0 | J14: 0 | K14: 0 | L14: 0
... A62: Traditional and Complementary Medicine Professionals | B62: 0 | C62: 0 | D62: 0 | E62: 0 | F62: 0 | G62: 0 | H62: 0 | I62: 0 | J62: 0 | K62: 0 | L62: 0
A63: Total | B63: =SUM(B3:B62) -> 0 | C63: =SUM(C3:C62) -> 1000 | D63: =SUM(D3:D62) -> 16266 | E63: =SUM(E3:E62) -> 18326 | F63: =SUM(F3:F62) -> 11934 | G63: =SUM(G3:G62) -> 0 | H63: =SUM(H3:H62) -> 37040 | I63: =SUM(I3:I62) -> 0 | ... L63: =SUM(L3:L62) -> 11228
A65: Population UN | B65: 399755.3 | C65: 405974.1 | D65: 413410.9 | E65: 422845.4 | F65: 431325.2 | G65: 435595 | H65: 438506.5 | I65: 442929.1 | J65: 448514.4 | K65: 453737.3 | L65: 458014.7

Sheet Guinea-Bissau
A1: Guinea-Bissau HRH Stock from 2012 to 2022
A2: Occupation | B2: 2012 | C2: 2013 | D2: 2014 | E2: 2015 | F2: 2016 | G2: 2017 | H2: 2018 | I2: 2019 | J2: 2020 | K2: 2021 | L2: 2022 | N2: HOME
A3: Medical Doctors | B3: 0 | C3: 0 | D3: 0 | E3: 354 | F3: 183 | G3: 0 | H3: 578 | I3: 0 | J3: 385 | K3: 453 | L3: 438
A4: Generalist Medical Practitioners (incl. Family medical practitioners) | B4: 0 | C4: 0 | D4: 0 | E4: 0 | F4: 169 | G4: 0 | H4: 544 | I4: 0 | J4: 375 | K4: 444 | L4: 428
A5: Medical group of Specialists Practitioners | B5: 0 | C5: 0 | D5: 0 | E5: 0 | F5: 0 | G5: 0 | H5: 21 | I5: 0 | J5: 0 | K5: 0 | L5: 0
A6: Nursing Personnel | B6: 0 | C6: 727 | D6: 885 | E6: 964 | F6: 918 | G6: 0 | H6: 744 | I6: 0 | J6: 1371 | K6: 1956 | L6: 1879
A7: Midwifery personnel | B7: 0 | C7: 153 | D7: 0 | E7: 0 | F7: 125 | G7: 0 | H7: 0 | I7: 0 | J7: 185 | K7: 213 | L7: 197
