Workbook
Name ActivitesASuivre: '[1]Activités à suivre'!$A$2:$A$31
Name Année: [2]MesCode!$C$2:$C$8
Name Cadres: Cadres!$A$2:$A$23
Name Entité: [1]Entités!$A$2:$A$34
Name Exercice: [1]MesCodes!$E$2:$E$10
Name Liste_des_Choristes: '[3]Liste des membres'!$A$2:$A$285
Name Liste_des_diacres: '[4]Liste des diacres'!$A$2:$A$294
Name Mois: [1]MesCodes!$A$2:$A$13
Name Nature_de_l_opération: [1]MesCodes!$C$2:$C$3
Name NomCaissier: [5]Caissier!$A$2:$A$5
Name Opération: [1]MesCodes!$FU$2:$FU$6
Name Pièce_N°: '[6]Journal de Caisse'!$B$3:$B$30072

Sheet Matching Cadres
A3: Row Labels
A4: Agent Technique de Santé (ATS) | B4: Nursing Associate Professionals
A5: Agent Technique de Santé/Accoucheuse (ATS/ACC) | B5: Nursing Associate Professionals
A6: Anaesthesiologists | B6: Specialist Medical Practitioners
A7: Anaesthestic officer | B7: Others
A8: Anaesthetician | B8: Specialist Medical Practitioners
A9: Anatomists | B9: Others
A10: Anesthésiste-Réanimateur | B10: Others
A11: Anesthéste | B11: Others
A12: ASDE | B12: Others
A13: Audiological Assistant | B13: Audiologists and Speech Therapists
A14: B. Biomedl Scs | B14: Medical and Pathology Laboratory scientists
A15: B. Cytotechnology | B15: Others
... A190: Neurosurgeons | B190: Specialist Medical Practitioners
A191: No data
A192: Nurse | B192: Nursing Professionals
A193: Nurses | B193: Nursing Professionals
A194: Nursing Anaesthesia | B194: Nursing Professionals
A195: Nursing and midwifery graduations | B195: Nursing Professionals
A196: Nutritionist | B196: Dieticians and nutritionists
A197: Obstetrical Gynecologist | B197: Specialist Medical Practitioners
A198: Obstetrics & Gyno | B198: Specialist Medical Practitioners
A199: Occupational Therapist | B199: Environmental and occupational health & hygiene workers
A200: Odontostomatologie | B200: Specialist Medical Practitioners
A201: Oncologist Physician | B201: Specialist Medical Practitioners
A202: Oncologists | B202: Specialist Medical Practitioners
A203: Ophtalmologist | B203: Specialist Medical Practitioners
... A283: X-Ray Tech and Assistants | B283: Medical Imaging and Therapeutic Equipment Technicians
A284: Grand Total

Sheet Cadres
A1: Cadres
A2: Audiologists and Speech Therapists
A3: Community Health Workers
A4: Dentists
A5: Dieticians and nutritionists
A6: Environmental and occupational health & hygiene workers
A7: Generalist Medical Practitioners
A8: Medical and dental Prosthetic Technicians
A9: Medical and Pathology Laboratory scientists
A10: Medical and Pathology Laboratory Technicians
A11: Medical Imaging and Therapeutic Equipment Technicians
A12: Midwifery personnel
... A23: Specialist Medical Practitioners

Sheet Pivot Countries
A3: Sum of Number of graduates per cadres in2017 | B3: Column Labels
A4: Row Labels | B4: Audiologists and Speech Therapists | C4: Community Health Workers | D4: Dentists | E4: Dieticians and nutritionists | F4: Environmental and occupational health & hygiene workers | G4: Generalist Medical Practitioners | H4: Medical and Pathology Laboratory scientists | I4: Medical and Pathology Laboratory Technicians | J4: Medical Imaging and Therapeutic Equipment Technicians | K4: Midwifery personnel | L4: No data | M4: Nursing Associate Professionals | N4: Nursing Professionals | O4: Optometrists and Ophthalmic Opticians | P4: Others | Q4: Pharmaceutical Technicians and Assistants | R4: Pharmacists | S4: Physiotherapists and physiotherapy assistants | T4: Specialist Medical Practitioners | U4: Grand Total
A5: Angola | L5: 4235 | U5: 4235
A6: Benin | G6: 173 | L6: 615 | R6: 22 | T6: 118 | U6: 928
A7: Botswana | D7: 0 | G7: 8 | L7: 543 | R7: 0 | U7: 551
A8: Burkina Faso | G8: 325 | H8: 32 | L8: 6340 | R8: 86 | T8: 253 | U8: 7036
A9: Burundi | G9: 319 | L9: 2419 | R9: 39 | U9: 2777
A10: Cameroon
A11: Cape-Verde | L11: 77 | N11: 6 | R11: 7 | U11: 90
A12: CAR | L12: 0 | U12: 0
A13: Chad | G13: 107 | I13: 22 | L13: 248 | M13: 208 | N13: 423 | P13: 45 | T13: 6 | U13: 1059
A14: Congo | G14: 39 | L14: 408 | N14: 5 | P14: 33 | T14: 0 | U14: 485
A15: Cote d'Ivoire | D15: 37 | G15: 254 | L15: 2647 | R15: 67 | T15: 11 | U15: 3016
A16: DRC | P16: 57 | T16: 27 | U16: 84
A17: Eritrea | D17: 30 | G17: 44 | I17: 78 | J17: 28 | K17: 6 | L17: 386 | N17: 43 | O17: 20 | P17: 275 | Q17: 39 | R17: 43 | S17: 30 | T17: 1 | U17: 1023
A18: Eswatini | L18: 500 | U18: 500
A19: Ethiopia | F19: 135 | G19: 2895 | I19: 258 | L19: 10939 | P19: 35 | R19: 350 | T19: 41 | U19: 14653
A20: Gabon | G20: 46 | H20: 0 | L20: 217 | P20: 0 | R20: 2 | T20: 16 | U20: 281
A21: Gambia | L21: 137 | U21: 137
A22: Ghana | D22: 51 | L22: 9280 | P22: 560 | U22: 9891
A23: Guinea | G23: 767 | L23: 2634 | R23: 113 | T23: 74 | U23: 3588
A24: Guinea-Bissau | G24: 69 | L24: 420 | U24: 489
A25: Lesotho | E25: 6 | F25: 6 | L25: 500 | N25: 1 | P25: 2 | R25: 33 | U25: 548
A26: Liberia | G26: 47 | L26: 191 | N26: 17 | T26: 15 | U26: 270
A27: Madagascar | D27: 48 | G27: 367 | L27: 5414 | P27: 32 | T27: 37 | U27: 5898
A28: Malawi | D28: 22 | G28: 101 | I28: 138 | L28: 2254 | P28: 189 | Q28: 75 | R28: 35 | U28: 2814
A29: Mali | L29: 0 | U29: 0
A30: Mauritania | G30: 74 | L30: 468 | T30: 13 | U30: 555
A31: Mauritius | L31: 17 | U31: 17
A32: Mozambique | L32: 6500 | U32: 6500
A33: Namibia | G33: 70 | L33: 569 | P33: 8 | R33: 76 | T33: 3 | U33: 726
A34: Niger | G34: 196 | L34: 2611 | R34: 0 | U34: 2807
A35: Nigeria | D35: 194 | G35: 3766 | L35: 29162.188 | U35: 33122.188
A36: Rwanda | L36: 0 | U36: 0
A37: Senegal | L37: 710 | U37: 710
A38: Sierra Leone | L38: 0 | U38: 0
A39: South Africa | L39: 16970 | U39: 16970
A40: South Sudan | L40: 1825 | U40: 1825
A41: Tanzania | D41: 38 | G41: 1076 | I41: 19 | L41: 10835 | P41: 22 | R41: 114 | T41: 304 | U41: 12408
A42: Togo | F42: 25 | G42: 40 | H42: 172 | J42: 6 | L42: 482 | P42: 37 | R42: 2 | T42: 51 | U42: 815
...

Sheet Pivot Cadres)
A3: Sum of Number of graduates per cadres in2017 | B3: Column Labels
A4: Row Labels | B4: Angola | C4: Benin | D4: Botswana | E4: Burkina Faso | F4: Burundi | G4: Cameroon | H4: Cape-Verde | I4: CAR | J4: Chad | K4: Congo | L4: Cote d'Ivoire | M4: DRC | N4: Eritrea | O4: Eswatini | P4: Ethiopia | Q4: Gabon | R4: Gambia | S4: Ghana | T4: Guinea | U4: Guinea-Bissau | V4: Lesotho | W4: Liberia | X4: Madagascar | Y4: Malawi | Z4: Mali | AA4: Mauritania | AB4: Mauritius | AC4: Mozambique | AD4: Namibia | AE4: Niger | AF4: Nigeria | AG4: Rwanda | AH4: Senegal | AI4: Sierra Leone | AJ4: South Africa | AK4: South Sudan | AL4: Tanzania | AM4: Togo | AN4: Uganda | AO4: Zambia | AP4: Zimbabwe | AQ4: Grand Total
A5: Audiologists and Speech Therapists | AN5: 8 | AQ5: 8
A6: Community Health Workers | AN6: 24 | AQ6: 24
A7: Dentists | D7: 0 | L7: 37 | N7: 30 | S7: 51 | X7: 48 | Y7: 22 | AF7: 194 | AL7: 38 | AN7: 61 | AP7: 31 | AQ7: 512
A8: Dieticians and nutritionists | V8: 6 | AN8: 24 | AQ8: 30
A9: Environmental and occupational health & hygiene workers | P9: 135 | V9: 6 | AM9: 25 | AN9: 181 | AQ9: 347
A10: Generalist Medical Practitioners | C10: 173 | D10: 8 | E10: 325 | F10: 319 | J10: 107 | K10: 39 | L10: 254 | N10: 44 | P10: 2895 | Q10: 46 | T10: 767 | U10: 69 | W10: 47 | X10: 367 | Y10: 101 | AA10: 74 | AD10: 70 | AE10: 196 | AF10: 3766 | AL10: 1076 | AM10: 40 | AN10: 62 | AQ10: 10845
A11: Medical and Pathology Laboratory scientists | E11: 32 | Q11: 0 | AM11: 172 | AN11: 799 | AP11: 1 | AQ11: 1004
A12: Medical and Pathology Laboratory Technicians | J12: 22 | N12: 78 | P12: 258 | Y12: 138 | AL12: 19 | AN12: 928 | AQ12: 1443
A13: Medical Imaging and Therapeutic Equipment Technicians | N13: 28 | AM13: 6 | AN13: 34 | AQ13: 68
A14: Midwifery personnel | N14: 6 | AN14: 27 | AQ14: 33
A15: No data | B15: 4235 | C15: 615 | D15: 543 | E15: 6340 | F15: 2419 | H15: 77 | I15: 0 | J15: 248 | K15: 408 | L15: 2647 | N15: 386 | O15: 500 | P15: 10939 | Q15: 217 | R15: 137 | S15: 9280 | T15: 2634 | U15: 420 | V15: 500 | W15: 191 | X15: 5414 | Y15: 2254 | Z15: 0 | AA15: 468 | AB15: 17 | AC15: 6500 | AD15: 569 | AE15: 2611 | AF15: 29162.188 | AG15: 0 | AH15: 710 | AI15: 0 | AJ15: 16970 | AK15: 1825 | AL15: 10835 | AM15: 482 | AN15: 811 | AO15: 645 | AP15: 1819 | AQ15: 123828.19
A16: Nursing Associate Professionals | J16: 208 | AQ16: 208
A17: Nursing Professionals | H17: 6 | J17: 423 | K17: 5 | N17: 43 | V17: 1 | W17: 17 | AN17: 155 | AQ17: 650
A18: Optometrists and Ophthalmic Opticians | N18: 20 | AN18: 18 | AQ18: 38
A19: Others | J19: 45 | K19: 33 | M19: 57 | N19: 275 | P19: 35 | Q19: 0 | S19: 560 | V19: 2 | X19: 32 | Y19: 189 | AD19: 8 | AL19: 22 | AM19: 37 | AN19: 904 | AP19: 177 | AQ19: 2376
A20: Pharmaceutical Technicians and Assistants | N20: 39 | Y20: 75 | AN20: 245 | AQ20: 359
A21: Pharmacists | C21: 22 | D21: 0 | E21: 86 | F21: 39 | H21: 7 | L21: 67 | N21: 43 | P21: 350 | Q21: 2 | T21: 113 | V21: 33 | Y21: 35 | AD21: 76 | AE21: 0 | AL21: 114 | AM21: 2 | AP21: 82 | AQ21: 1071
A22: Physiotherapists and physiotherapy assistants | N22: 30 | AQ22: 30
A23: Specialist Medical Practitioners | C23: 118 | E23: 253 | J23: 6 | K23: 0 | L23: 11 | M23: 27 | N23: 1 | P23: 41 | Q23: 16 | T23: 74 | W23: 15 | X23: 37 | AA23: 13 | AD23: 3 | AL23: 304 | AM23: 51 | AN23: 328 | AP23: 51 | AQ23: 1349
A24: Grand Total | B24: 4235 | C24: 928 | D24: 551 | E24: 7036 | F24: 2777 | H24: 90 | I24: 0 | J24: 1059 | K24: 485 | L24: 3016 | M24: 84 | N24: 1023 | O24: 500 | P24: 14653 | Q24: 281 | R24: 137 | S24: 9891 | T24: 3588 | U24: 489 | V24: 548 | W24: 270 | X24: 5898 | Y24: 2814 | Z24: 0 | AA24: 555 | AB24: 17 | AC24: 6500 | AD24: 726 | AE24: 2807 | AF24: 33122.188 | AG24: 0 | AH24: 710 | AI24: 0 | AJ24: 16970 | AK24: 1825 | AL24: 12408 | AM24: 815 | AN24: 4609 | AO24: 645 | AP24: 2161 | AQ24: 144223.19

Sheet Data of trainining institution
A1: List of medical training insitutions for medical practioners, dentists and pharmacists (Faculties, Colleges, Schools) & health sciences schools for other cadres in the country, 2018 HRH Survey.
A2: Country Name | B2: Name of the Training institution | C2: Type of institution | D2: Ownership | E2: Location/city | F2: Programs | G2: Cadre | H2: cadre2 | I2: Number of graduates per cadres in2017 | J2: Field of training in the Training institution
A3: Angola | B3: Universidade Agostinho Neto | C3: University | D3: Public | E3: Luanda | F3: Medicina | G3: No data | H3: =IFERROR(IF(G3="No data",G3,_xlfn.XLOOKUP(G3,'Matching Cadres'!A:A,'Matching Cadres'!B:B)),"") -> No data | I3: 75 | J3: Medical training insitutions for medical practioners, dentists and pharmacists
A4: Angola | B4: Universidade Agostinho Neto | C4: University | D4: Public | E4: Luanda | F4: Enfermagem | G4: No data | H4: =IFERROR(IF(G4="No data",G4,_xlfn.XLOOKUP(G4,'Matching Cadres'!A:A,'Matching Cadres'!B:B)),"") -> No data | I4: No data | J4: Medical training insitutions for medical practioners, dentists and pharmacists
A5: Angola | B5: Universidade Katyavala Bwila | C5: University | D5: Public | E5: Benguela | F5: Medicina | G5: No data | H5: =IFERROR(IF(G5="No data",G5,_xlfn.XLOOKUP(G5,'Matching Cadres'!A:A,'Matching Cadres'!B:B)),"") -> No data | I5: 68 | J5: Medical training insitutions for medical practioners, dentists and pharmacists
A6: Angola | B6: Universidade 11 de Novembro | C6: University | D6: Public | E6: Cabinda | F6: Medicina | G6: No data | H6: =IFERROR(IF(G6="No data",G6,_xlfn.XLOOKUP(G6,'Matching Cadres'!A:A,'Matching Cadres'!B:B)),"") -> No data | I6: 55 | J6: Medical training insitutions for medical practioners, dentists and pharmacists
A7: Angola | B7: Universidade 11 de Novembro | C7: University | D7: Public | E7: Huambo | F7: Medicina | G7: No data | H7: =IFERROR(IF(G7="No data",G7,_xlfn.XLOOKUP(G7,'Matching Cadres'!A:A,'Matching Cadres'!B:B)),"") -> No data | I7: 68 | J7: Medical training insitutions for medical practioners, dentists and pharmacists
A8: Angola | B8: Universidade Rei Mandume | C8: University | D8: Public | E8: Huila | F8: Medicina | G8: No data | H8: =IFERROR(IF(G8="No data",G8,_xlfn.XLOOKUP(G8,'Matching Cadres'!A:A,'Matching Cadres'!B:B)),"") -> No data | I8: 60 | J8: Medical training insitutions for medical practioners, dentists and pharmacists
A9: Angola | B9: Universidade Luije ya Konda | C9: University | D9: Public | E9: Malange | F9: Medicina | G9: No data | H9: =IFERROR(IF(G9="No data",G9,_xlfn.XLOOKUP(G9,'Matching Cadres'!A:A,'Matching Cadres'!B:B)),"") -> No data | I9: 45 | J9: Medical training insitutions for medical practioners, dentists and pharmacists
A10: Angola | B10: Universidade Catolica de Angola | C10: University | D10: Faith based Organization | E10: Luanda | F10: Medicina | G10: No data | H10: =IFERROR(IF(G10="No data",G10,_xlfn.XLOOKUP(G10,'Matching Cadres'!A:A,'Matching Cadres'!B:B)),"") -> No data | I10: 120 | J10: Health sciences schools for other cadres/categories
A11: Angola | B11: Universidade Jean Piagt | C11: University | D11: Private | E11: Luanda | F11: Enfermagem | G11: No data | H11: =IFERROR(IF(G11="No data",G11,_xlfn.XLOOKUP(G11,'Matching Cadres'!A:A,'Matching Cadres'!B:B)),"") -> No data | I11: 150 | J11: Health sciences schools for other cadres/categories
A12: Angola | B12: Universidade Jean Piagt | C12: University | D12: Private | E12: Luanda | F12: Med. Dentaria | G12: No data | H12: =IFERROR(IF(G12="No data",G12,_xlfn.XLOOKUP(G12,'Matching Cadres'!A:A,'Matching Cadres'!B:B)),"") -> No data | I12: 60 | J12: Health sciences schools for other cadres/categories
A13: Angola | B13: Universidade Jean Piagt | C13: University | D13: Private | E13: Luanda | F13: Farmacia | G13: No data | H13: =IFERROR(IF(G13="No data",G13,_xlfn.XLOOKUP(G13,'Matching Cadres'!A:A,'Matching Cadres'!B:B)),"") -> No data | I13: 30 | J13: Health sciences schools for other cadres/categories
A14: Angola | B14: Universidade Jean Piagt | C14: University | D14: Private | E14: Luanda | F14: Medicina | G14: No data | H14: =IFERROR(IF(G14="No data",G14,_xlfn.XLOOKUP(G14,'Matching Cadres'!A:A,'Matching Cadres'!B:B)),"") -> No data | I14: 120 | J14: Health sciences schools for other cadres/categories
A15: Angola | B15: Universidade de Belas | C15: University | D15: Private | E15: Luanda | F15: Enfermagem | G15: No data | H15: =IFERROR(IF(G15="No data",G15,_xlfn.XLOOKUP(G15,'Matching Cadres'!A:A,'Matching Cadres'!B:B)),"") -> No data | I15: 0 | J15: Health sciences schools for other cadres/categories
A16: Angola | B16: Instituto Superior Katangoji Politécnico | C16: Institute | D16: Private | E16: Luanda | F16: Enfermagem | G16: No data | H16: =IFERROR(IF(G16="No data",G16,_xlfn.XLOOKUP(G16,'Matching Cadres'!A:A,'Matching Cadres'!B:B)),"") -> No data | I16: 0 | J16: Health sciences schools for other cadres/categories
... A167: Botswana | B167: Gaborone Institute of Health Sciences | C167: Institute | D167: Public | E167: Gaborone | F167: Diploma in General Nursing | G167: No data | H167: =IFERROR(IF(G167="No data",G167,_xlfn.XLOOKUP(G167,'Matching Cadres'!A:A,'Matching Cadres'!B:B)),"") -> No data | I167: 50 | J167: Health sciences schools for other cadres/categories
A168: Botswana | B168: Gaborone Institute of Health Sciences | C168: Institute | D168: Public | E168: Gaborone | F168: Diploma in Midwifery | G168: No data | H168: =IFERROR(IF(G168="No data",G168,_xlfn.XLOOKUP(G168,'Matching Cadres'!A:A,'Matching Cadres'!B:B)),"") -> No data | I168: No data | J168: Health sciences schools for other cadres/categories
A169: Botswana | B169: Gaborone Institute of Health Sciences | C169: Institute | D169: Public | E169: Gaborone | F169: Higher Diploma in Medical Laboratory Technology | G169: No data | H169: =IFERROR(IF(G169="No data",G169,_xlfn.XLOOKUP(G169,'Matching Cadres'!A:A,'Matching Cadres'!B:B)),"") -> No data | I169: 26 | J169: Health sciences schools for other cadres/categories
A170: Botswana | B170: Gaborone Institute of Health Sciences | C170: Institute | D170: Public | E170: Gaborone | F170: Post Basic Diploma in Family Nurse Practitioner | G170: No data | H170: =IFERROR(IF(G170="No data",G170,_xlfn.XLOOKUP(G170,'Matching Cadres'!A:A,'Matching Cadres'!B:B)),"") -> No data | I170: 16 | J170: Health sciences schools for other cadres/categories
A171: Botswana | B171: Gaborone Institute of Health Sciences | C171: Institute | D171: Public | E171: Gaborone | F171: Diploma in Pharmacy Technology | G171: No data | H171: =IFERROR(IF(G171="No data",G171,_xlfn.XLOOKUP(G171,'Matching Cadres'!A:A,'Matching Cadres'!B:B)),"") -> No data | I171: 26 | J171: Health sciences schools for other cadres/categories
A172: Botswana | B172: Gaborone Institute of Health Sciences | C172: Institute | D172: Public | E172: Gaborone | F172: Diploma in Dental Therapy | G172: No data | H172: =IFERROR(IF(G172="No data",G172,_xlfn.XLOOKUP(G172,'Matching Cadres'!A:A,'Matching Cadres'!B:B)),"") -> No data | I172: 7 | J172: Health sciences schools for other cadres/categories
A173: Botswana | B173: Francistown Institute of Health Sciences | C173: Institute | D173: Public | E173: Francistown | F173: Diploma in General Nursing | G173: No data | H173: =IFERROR(IF(G173="No data",G173,_xlfn.XLOOKUP(G173,'Matching Cadres'!A:A,'Matching Cadres'!B:B)),"") -> No data | I173: 51 | J173: Health sciences schools for other cadres/categories
A174: Botswana | B174: Francistown Institute of Health Sciences | C174: Institute | D174: Public | E174: Francistown | F174: Diploma in Midwifery | G174: No data | H174: =IFERROR(IF(G174="No data",G174,_xlfn.XLOOKUP(G174,'Matching Cadres'!A:A,'Matching Cadres'!B:B)),"") -> No data | I174: 23 | J174: Health sciences schools for other cadres/categories
A175: Botswana | B175: Molepolole Institute of Health Sciences | C175: Institute | D175: Public | E175: Molepolole | F175: Diploma in General Nursing | G175: No data | H175: =IFERROR(IF(G175="No data",G175,_xlfn.XLOOKUP(G175,'Matching Cadres'!A:A,'Matching Cadres'!B:B)),"") -> No data | I175: 52 | J175: Health sciences schools for other cadres/categories
A176: Botswana | B176: Serowe Institute of Health Sciences | C176: Institute | D176: Public | E176: Serowe | F176: Diploma in Health Education | G176: No data | H176: =IFERROR(IF(G176="No data",G176,_xlfn.XLOOKUP(G176,'Matching Cadres'!A:A,'Matching Cadres'!B:B)),"") -> No data | I176: 21 | J176: Health sciences schools for other cadres/categories
A177: Botswana | B177: Serowe Institute of Health Sciences | C177: Institute | D177: Public | E177: Serowe | F177: Diploma in General Nursing | G177: No data | H177: =IFERROR(IF(G177="No data",G177,_xlfn.XLOOKUP(G177,'Matching Cadres'!A:A,'Matching Cadres'!B:B)),"") -> No data | I177: 77 | J177: Health sciences schools for other cadres/categories
A178: Botswana | B178: Lobatse Institute of Health Sciences | C178: Institute | D178: Public | E178: Lobatse | F178: Diploma in Environmental Health | G178: No data | H178: =IFERROR(IF(G178="No data",G178,_xlfn.XLOOKUP(G178,'Matching Cadres'!A:A,'Matching Cadres'!B:B)),"") -> No data | I178: 15 | J178: Health sciences schools for other cadres/categories
A179: Botswana | B179: Lobatse Institute of Health Sciences | C179: Institute | D179: Public | E179: Lobatse | F179: Diploma in General Nursing | G179: No data | H179: =IFERROR(IF(G179="No data",G179,_xlfn.XLOOKUP(G179,'Matching Cadres'!A:A,'Matching Cadres'!B:B)),"") -> No data | I179: 55 | J179: Health sciences schools for other cadres/categories
A180: Botswana | B180: Kanye Seventh Day Adventist College of Nursing | C180: School | D180: Faith based Organization | E180: Kanye | F180: Post Basic Diploma in Family Nurse Practitioner | G180: No data | H180: =IFERROR(IF(G180="No data",G180,_xlfn.XLOOKUP(G180,'Matching Cadres'!A:A,'Matching Cadres'!B:B)),"") -> No data | I180: 22 | J180: Health sciences schools for other cadres/categories
A181: Botswana | B181: Kanye Seventh Day Adventist College of Nursing | C181: School | D181: Faith based Organization | E181: Kanye | F181: Diploma in General Nursing | G181: No data | H181: =IFERROR(IF(G181="No data",G181,_xlfn.XLOOKUP(G181,'Matching Cadres'!A:A,'Matching Cadres'!B:B)),"") -> No data | I181: 66 | J181: Health sciences schools for other cadres/categories
A182: Botswana | B182: Kanye Seventh Day Adventist College of Nursing | C182: School | D182: Faith based Organization | E182: Kanye | F182: Diploma in Midwifery | G182: No data | H182: =IFERROR(IF(G182="No data",G182,_xlfn.XLOOKUP(G182,'Matching Cadres'!A:A,'Matching Cadres'!B:B)),"") -> No data | I182: No data | J182: Health sciences schools for other cadres/categories
A183: Botswana | B183: Bamalete Lutheran School of Nursing | C183: School | D183: Faith based Organization | E183: Ramotswa | F183: Diploma in Midwifery | G183: No data | H183: =IFERROR(IF(G183="No data",G183,_xlfn.XLOOKUP(G183,'Matching Cadres'!A:A,'Matching Cadres'!B:B)),"") -> No data | I183: 36 | J183: Health sciences schools for other cadres/categories
A184: Burkina Faso | B184: Université Ouaga I Pr Joseph KI-ZERBO | C184: University | D184: Public | E184: Ouagadougou | F184: Médecine | G184: Médecins généralistes | H184: =IFERROR(IF(G184="No data",G184,_xlfn.XLOOKUP(G184,'Matching Cadres'!A:A,'Matching Cadres'!B:B)),"") -> Generalist Medical Practitioners | I184: 225 | J184: Medical training insitutions for medical practioners, dentists and pharmacists
A185: Burkina Faso | B185: Université Ouaga I Pr Joseph KI-ZERBO | C185: University | D185: Public | E185: Ouagadougou | F185: Pharmacie | G185: Pharmaciens généralistes | H185: =IFERROR(IF(G185="No data",G185,_xlfn.XLOOKUP(G185,'Matching Cadres'!A:A,'Matching Cadres'!B:B)),"") -> Pharmacists | I185: 31 | J185: Medical training insitutions for medical practioners, dentists and pharmacists
A186: Burkina Faso | B186: Université Ouaga I Pr Joseph KI-ZERBO | C186: University | D186: Public | E186: Ouagadougou | F186: Chirurgie dentaire | G186: Chirurgiens-dentistes généralistes | H186: =IFERROR(IF(G186="No data",G186,_xlfn.XLOOKUP(G186,'Matching Cadres'!A:A,'Matching Cadres'!B:B)),"") -> Specialist Medical Practitioners | I186: 0 | J186: Medical training insitutions for medical practioners, dentists and pharmacists
A187: Burkina Faso | B187: Université Ouaga I Pr Joseph KI-ZERBO | C187: University | D187: Public | E187: Ouagadougou | F187: Techniciens supérieurs en santé | G187: Techniciens de Laboratoire médical et pathologique | H187: =IFERROR(IF(G187="No data",G187,_xlfn.XLOOKUP(G187,'Matching Cadres'!A:A,'Matching Cadres'!B:B)),"") -> Medical and Pathology Laboratory scientists | I187: 32 | J187: Medical training insitutions for medical practioners, dentists and pharmacists
A188: Burkina Faso | B188: Université Ouaga I Pr Joseph KI-ZERBO | C188: University | D188: Public | E188: Ouagadougou | F188: Urologie | G188: Médecin spécialiste | H188: =IFERROR(IF(G188="No data",G188,_xlfn.XLOOKUP(G188,'Matching Cadres'!A:A,'Matching Cadres'!B:B)),"") -> Specialist Medical Practitioners | I188: 32 | J188: Medical training insitutions for medical practioners, dentists and pharmacists
A189: Burkina Faso | B189: Université Ouaga I Pr Joseph KI-ZERBO | C189: University | D189: Public | E189: Ouagadougou | F189: Radio-diagnostic et imagérie médicale | G189: Médecin spécialiste | H189: =IFERROR(IF(G189="No data",G189,_xlfn.XLOOKUP(G189,'Matching Cadres'!A:A,'Matching Cadres'!B:B)),"") -> Specialist Medical Practitioners | I189: 76 | J189: Medical training insitutions for medical practioners, dentists and pharmacists
A190: Burkina Faso | B190: Université Ouaga I Pr Joseph KI-ZERBO | C190: University | D190: Public | E190: Ouagadougou | F190: Pédiatrie | G190: Médecin spécialiste | H190: =IFERROR(IF(G190="No data",G190,_xlfn.XLOOKUP(G190,'Matching Cadres'!A:A,'Matching Cadres'!B:B)),"") -> Specialist Medical Practitioners | I190: 49 | J190: Medical training insitutions for medical practioners, dentists and pharmacists
...
