Workbook

Sheet Sheet3
A3: Row Labels | B3: Average of Dentists Stock By Age Group < 25 yrs2 | C3: Average of Dentists Stock By Age Group 25-34 yrs2 | D3: Average of Dentists Stock By Age Group 35-44 yrs2 | E3: Average of Dentists Stock By Age Group 45-54 yrs2 | F3: Average of Dentists Stock By Age Group 55-64 yrs2 | G3: Average of Dentists Stock By Age Group ≥ 65 yrs2
A4: AFRO | B4: 0.075291181 | C4: 0.44647809 | D4: 0.28674432 | E4: 0.11175818 | F4: 0.066694398 | G4: 0.013033833
A5: High/Upper-Middle-Income Economies | B5: 0.010548523 | C5: 0.18459916 | D5: 0.21825853 | E5: 0.30705792 | F5: 0.24923283 | G5: 0.03030303
A6: Lower-Middle-Income Economies | B6: 0.03052838 | C6: 0.40571501 | D6: 0.28603213 | E6: 0.15979762 | F6: 0.10374001 | G6: 0.014186848
A7: Low-Income Economies | B7: 0.0081764545 | C7: 0.36686117 | D7: 0.32945884 | E7: 0.13608036 | F7: 0.13243992 | G7: 0.026983254
A8: Grand Total | B8: 0.023063964 | C8: 0.36292963 | D8: 0.28892971 | E8: 0.17236952 | F8: 0.13232163 | G8: 0.020385546

Sheet Sheet7
A3: Row Labels | B3: Average of Dentists Stock By Age Group < 25 yrs2 | C3: Average of Dentists Stock By Age Group 25-34 yrs2 | D3: Average of Dentists Stock By Age Group 35-44 yrs2 | E3: Average of Dentists Stock By Age Group 45-54 yrs2 | F3: Average of Dentists Stock By Age Group 55-64 yrs2 | G3: Average of Dentists Stock By Age Group ≥ 65 yrs2
A4: AFRO | B4: 0.075291181 | C4: 0.44647809 | D4: 0.28674432 | E4: 0.11175818 | F4: 0.066694398 | G4: 0.013033833
A5: High/Upper-Middle-Income Economies | B5: 0.010548523 | C5: 0.18459916 | D5: 0.21825853 | E5: 0.30705792 | F5: 0.24923283 | G5: 0.03030303
A6: Lower-Middle-Income Economies | B6: 0.03052838 | C6: 0.40571501 | D6: 0.28603213 | E6: 0.15979762 | F6: 0.10374001 | G6: 0.014186848
A7: Low-Income Economies | B7: 0.0081764545 | C7: 0.36686117 | D7: 0.32945884 | E7: 0.13608036 | F7: 0.13243992 | G7: 0.026983254
A8: Grand Total | B8: 0.023063964 | C8: 0.36292963 | D8: 0.28892971 | E8: 0.17236952 | F8: 0.13232163 | G8: 0.020385546

Sheet proportions
A1: Row Labels | B1: Dentists Stock By Age Group < 25 yrs | C1: Dentists Stock By Age Group 25-34 yrs | D1: Dentists Stock By Age Group 35-44 yrs | E1: Dentists Stock By Age Group 45-54 yrs | F1: Dentists Stock By Age Group 55-64 yrs | G1: Dentists Stock By Age Group ≥ 65 yrs | H1: Total | I1: Dentists Stock By Age Group < 25 yrs | J1: Dentists Stock By Age Group 25-34 yrs | K1: Dentists Stock By Age Group 35-44 yrs | L1: Dentists Stock By Age Group 45-54 yrs | M1: Dentists Stock By Age Group 55-64 yrs | N1: Dentists Stock By Age Group ≥ 65 yrs | O1: income
A2: AFRO | B2: 543 | C2: 3220 | D2: 2068 | E2: 806 | F2: 481 | G2: 94 | H2: =SUM(B2:G2) -> 7212 | I2: =B2/$H2 -> 0.075291181 | J2: =C2/$H2 -> 0.44647809 | K2: =D2/$H2 -> 0.28674432 | L2: =E2/$H2 -> 0.11175818 | M2: =F2/$H2 -> 0.066694398 | N2: =G2/$H2 -> 0.013033833 | O2: AFRO
A3: BFA | B3: 5 | C3: 22 | D3: 21 | E3: 29 | F3: 21 | G3: 10 | H3: =SUM(B3:G3) -> 108 | I3: =B3/$H3 -> 0.046296296 | J3: =C3/$H3 -> 0.2037037 | K3: =D3/$H3 -> 0.19444444 | L3: =E3/$H3 -> 0.26851852 | M3: =F3/$H3 -> 0.19444444 | N3: =G3/$H3 -> 0.092592593 | O3: =VLOOKUP(A3,Sheet2!A$3:D$50,4,FALSE) -> Low-Income Economies
A4: BWA | B4: 5 | C4: 48 | D4: 46 | E4: 45 | F4: 14 | H4: =SUM(B4:G4) -> 158 | I4: =B4/$H4 -> 0.03164557 | J4: =C4/$H4 -> 0.30379747 | K4: =D4/$H4 -> 0.29113924 | L4: =E4/$H4 -> 0.28481013 | M4: =F4/$H4 -> 0.088607595 | N4: =G4/$H4 -> 0 | O4: =VLOOKUP(A4,Sheet2!A$3:D$50,4,FALSE) -> High/Upper-Middle-Income Economies
A5: CIV | B5: 0 | C5: 67 | D5: 145 | E5: 103 | F5: 100 | G5: 3 | H5: =SUM(B5:G5) -> 418 | I5: =B5/$H5 -> 0 | J5: =C5/$H5 -> 0.16028708 | K5: =D5/$H5 -> 0.34688995 | L5: =E5/$H5 -> 0.24641148 | M5: =F5/$H5 -> 0.23923445 | N5: =G5/$H5 -> 0.0071770335 | O5: =VLOOKUP(A5,Sheet2!A$3:D$50,4,FALSE) -> Lower-Middle-Income Economies
A6: CMR | B6: 0 | C6: 230 | D6: 59 | E6: 18 | F6: 10 | G6: 0 | H6: =SUM(B6:G6) -> 317 | I6: =B6/$H6 -> 0 | J6: =C6/$H6 -> 0.72555205 | K6: =D6/$H6 -> 0.18611987 | L6: =E6/$H6 -> 0.056782334 | M6: =F6/$H6 -> 0.031545741 | N6: =G6/$H6 -> 0 | O6: =VLOOKUP(A6,Sheet2!A$3:D$50,4,FALSE) -> Lower-Middle-Income Economies
A7: ERI | C7: 49 | D7: 7 | E7: 2 | H7: =SUM(B7:G7) -> 58 | I7: =B7/$H7 -> 0 | J7: =C7/$H7 -> 0.84482759 | K7: =D7/$H7 -> 0.12068966 | L7: =E7/$H7 -> 0.034482759 | M7: =F7/$H7 -> 0 | N7: =G7/$H7 -> 0 | O7: =VLOOKUP(A7,Sheet2!A$3:D$50,4,FALSE) -> Low-Income Economies
A8: GAB | B8: 0 | C8: 2 | D8: 4 | E8: 17 | F8: 19 | G8: 2 | H8: =SUM(B8:G8) -> 44 | I8: =B8/$H8 -> 0 | J8: =C8/$H8 -> 0.045454545 | K8: =D8/$H8 -> 0.090909091 | L8: =E8/$H8 -> 0.38636364 | M8: =F8/$H8 -> 0.43181818 | N8: =G8/$H8 -> 0.045454545 | O8: =VLOOKUP(A8,Sheet2!A$3:D$50,4,FALSE) -> High/Upper-Middle-Income Economies
A9: GNB | B9: 0 | C9: 14 | D9: 7 | E9: 0 | F9: 0 | G9: 0 | H9: =SUM(B9:G9) -> 21 | I9: =B9/$H9 -> 0 | J9: =C9/$H9 -> 0.66666667 | K9: =D9/$H9 -> 0.33333333 | L9: =E9/$H9 -> 0 | M9: =F9/$H9 -> 0 | N9: =G9/$H9 -> 0 | O9: =VLOOKUP(A9,Sheet2!A$3:D$50,4,FALSE) -> Low-Income Economies
A10: KEN | B10: 22 | C10: 74 | D10: 142 | E10: 42 | F10: 14 | G10: 0 | H10: =SUM(B10:G10) -> 294 | I10: =B10/$H10 -> 0.074829932 | J10: =C10/$H10 -> 0.25170068 | K10: =D10/$H10 -> 0.4829932 | L10: =E10/$H10 -> 0.14285714 | M10: =F10/$H10 -> 0.047619048 | N10: =G10/$H10 -> 0 | O10: =VLOOKUP(A10,Sheet2!A$3:D$50,4,FALSE) -> Lower-Middle-Income Economies
A11: MWI | C11: 5 | D11: 41 | E11: 23 | F11: 25 | G11: 7 | H11: =SUM(B11:G11) -> 101 | I11: =B11/$H11 -> 0 | J11: =C11/$H11 -> 0.04950495 | K11: =D11/$H11 -> 0.40594059 | L11: =E11/$H11 -> 0.22772277 | M11: =F11/$H11 -> 0.24752475 | N11: =G11/$H11 -> 0.069306931 | O11: =VLOOKUP(A11,Sheet2!A$3:D$50,4,FALSE) -> Low-Income Economies
A12: NGA | B12: 62 | C12: 1146 | D12: 1086 | F12: 217 | G12: 62 | H12: =SUM(B12:G12) -> 2573 | I12: =B12/$H12 -> 0.024096386 | J12: =C12/$H12 -> 0.44539448 | K12: =D12/$H12 -> 0.4220754 | L12: =E12/$H12 -> 0 | M12: =F12/$H12 -> 0.084337349 | N12: =G12/$H12 -> 0.024096386 | O12: =VLOOKUP(A12,Sheet2!A$3:D$50,4,FALSE) -> Lower-Middle-Income Economies
A13: SEN | B13: 0 | C13: 31 | D13: 63 | E13: 80 | F13: 46 | G13: 2 | H13: =SUM(B13:G13) -> 222 | I13: =B13/$H13 -> 0 | J13: =C13/$H13 -> 0.13963964 | K13: =D13/$H13 -> 0.28378378 | L13: =E13/$H13 -> 0.36036036 | M13: =F13/$H13 -> 0.20720721 | N13: =G13/$H13 -> 0.009009009 | O13: =VLOOKUP(A13,Sheet2!A$3:D$50,4,FALSE) -> Lower-Middle-Income Economies
A14: SWZ | C14: 7 | E14: 1 | H14: =SUM(B14:G14) -> 8 | I14: =B14/$H14 -> 0 | J14: =C14/$H14 -> 0.875 | K14: =D14/$H14 -> 0 | L14: =E14/$H14 -> 0.125 | M14: =F14/$H14 -> 0 | N14: =G14/$H14 -> 0 | O14: =VLOOKUP(A14,Sheet2!A$3:D$50,4,FALSE) -> Lower-Middle-Income Economies
A15: SYC | C15: 9 | D15: 12 | E15: 11 | F15: 10 | G15: 2 | H15: =SUM(B15:G15) -> 44 | I15: =B15/$H15 -> 0 | J15: =C15/$H15 -> 0.20454545 | K15: =D15/$H15 -> 0.27272727 | L15: =E15/$H15 -> 0.25 | M15: =F15/$H15 -> 0.22727273 | N15: =G15/$H15 -> 0.045454545 | O15: =VLOOKUP(A15,Sheet2!A$3:D$50,4,FALSE) -> High/Upper-Middle-Income Economies
A16: TGO | B16: 0 | C16: 0 | D16: 8 | E16: 4 | F16: 6 | G16: 0 | H16: =SUM(B16:G16) -> 18 | I16: =B16/$H16 -> 0 | J16: =C16/$H16 -> 0 | K16: =D16/$H16 -> 0.44444444 | L16: =E16/$H16 -> 0.22222222 | M16: =F16/$H16 -> 0.33333333 | N16: =G16/$H16 -> 0 | O16: =VLOOKUP(A16,Sheet2!A$3:D$50,4,FALSE) -> Low-Income Economies
A17: ZMB | B17: 3 | C17: 103 | D17: 63 | E17: 55 | F17: 22 | G17: 15 | H17: =SUM(B17:G17) -> 261 | I17: =B17/$H17 -> 0.011494253 | J17: =C17/$H17 -> 0.39463602 | K17: =D17/$H17 -> 0.24137931 | L17: =E17/$H17 -> 0.21072797 | M17: =F17/$H17 -> 0.084291188 | N17: =G17/$H17 -> 0.057471264 | O17: =VLOOKUP(A17,Sheet2!A$3:D$50,4,FALSE) -> Lower-Middle-Income Economies
A18: ZWE | B18: 456 | C18: 1433 | D18: 378 | E18: 432 | F18: 0 | G18: 0 | H18: =SUM(B18:G18) -> 2699 | I18: =B18/$H18 -> 0.16895146 | J18: =C18/$H18 -> 0.53093738 | K18: =D18/$H18 -> 0.14005187 | L18: =E18/$H18 -> 0.16005928 | M18: =F18/$H18 -> 0 | N18: =G18/$H18 -> 0 | O18: =VLOOKUP(A18,Sheet2!A$3:D$50,4,FALSE) -> Lower-Middle-Income Economies
A19: BEN | B19: 0 | C19: 10 | D19: 26 | E19: 8 | F19: 6 | G19: 0 | H19: =SUM(B19:G19) -> 50 | I19: =B19/$H19 -> 0 | J19: =C19/$H19 -> 0.2 | K19: =D19/$H19 -> 0.52 | L19: =E19/$H19 -> 0.16 | M19: =F19/$H19 -> 0.12 | N19: =G19/$H19 -> 0 | O19: =VLOOKUP(A19,Sheet2!A$3:D$50,4,FALSE) -> Lower-Middle-Income Economies
A20: DZA | B20: 400 | C20: 5156 | D20: 3659 | E20: 2096 | F20: 3445 | G20: 681 | H20: =SUM(B20:G20) -> 15437 | I20: =B20/$H20 -> 0.02591177 | J20: =C20/$H20 -> 0.33400272 | K20: =D20/$H20 -> 0.23702792 | L20: =E20/$H20 -> 0.13577768 | M20: =F20/$H20 -> 0.22316512 | N20: =G20/$H20 -> 0.044114789 | O20: =VLOOKUP(A20,Sheet2!A$2:D$50,4,FALSE) -> Lower-Middle-Income Economies
A21: MOZ | B21: 1 | C21: 158 | D21: 173 | E21: 23 | F21: 7 | G21: 0 | H21: =SUM(B21:G21) -> 362 | I21: =B21/$H21 -> 0.0027624309 | J21: =C21/$H21 -> 0.43646409 | K21: =D21/$H21 -> 0.47790055 | L21: =E21/$H21 -> 0.063535912 | M21: =F21/$H21 -> 0.019337017 | N21: =G21/$H21 -> 0 | O21: =VLOOKUP(A21,Sheet2!A$3:D$50,4,FALSE) -> Low-Income Economies
A27: Income level | B27: Dentists Stock By Age Group < 25 yrs | C27: Dentists Stock By Age Group 25-34 yrs | D27: Dentists Stock By Age Group 35-44 yrs | E27: Dentists Stock By Age Group 45-54 yrs | F27: Dentists Stock By Age Group 55-64 yrs | G27: Dentists Stock By Age Group ≥ 65 yrs
A28: High/Upper-Middle-Income Economies | B28: 0.010548523 | C28: 0.18459916 | D28: 0.21825853 | E28: 0.30705792 | F28: 0.24923283 | G28: 0.03030303
A29: Lower-Middle-Income Economies | B29: 0.03052838 | C29: 0.40571501 | D29: 0.28603213 | E29: 0.15979762 | F29: 0.10374001 | G29: 0.014186848
A30: Low-Income Economies | B30: 0.0081764545 | C30: 0.36686117 | D30: 0.32945884 | E30: 0.13608036 | F30: 0.13243992 | G30: 0.026983254
A31: AFRO | B31: 0.075291181 | C31: 0.44647809 | D31: 0.28674432 | E31: 0.11175818 | F31: 0.066694398 | G31: 0.013033833

Sheet Sheet2
A1: country code | B1: Country | C1: country code | D1: Income
A2: DZA | B2: Algeria | C2: DZA | D2: Lower-Middle-Income Economies
A3: AGO | B3: Angola | C3: AGO | D3: Lower-Middle-Income Economies
A4: BEN | B4: Benin | C4: BEN | D4: Lower-Middle-Income Economies
A5: BWA | B5: Botswana | C5: BWA | D5: High/Upper-Middle-Income Economies
A6: BFA | B6: Burkina Faso | C6: BFA | D6: Low-Income Economies
A7: BDI | B7: Burundi | C7: BDI | D7: Low-Income Economies
A8: CMR | B8: Cameroon | C8: CMR | D8: Lower-Middle-Income Economies
A9: CPV | B9: Cape-Verde | C9: CPV | D9: Lower-Middle-Income Economies
A10: CAF | B10: Central African Republic | C10: CAF | D10: Low-Income Economies
A11: TCD | B11: Chad | C11: TCD | D11: Low-Income Economies
A12: COM | B12: Comoros | C12: COM | D12: Lower-Middle-Income Economies
... A48: ZWE | B48: Zimbabwe | C48: ZWE | D48: Lower-Middle-Income Economies
A49: AFRO | B49: AFRO | C49: AFRO

Sheet Sheet6
A3: Row Labels | B3: Average of graduate to stock ratio
A4: AFRO | B4: 0.08425629
A5: High/Upper-Middle-Income Economies | B5: #DIV/0!
A6: Lower-Middle-Income Economies | B6: 0.15145419
A7: Low-Income Economies | B7: 0.28504448
A8: Grand Total | B8: #DIV/0!

Sheet Total dentists
A2: Country | B2: Country code | C2: income level | D2: 2013 | E2: 2018 | F2: Adjusted 2022 | G2: Dentists Stock By Age Group < 25 yrs | H2: Dentists Stock By Age Group 25-34 yrs | I2: Dentists Stock By Age Group 35-44 yrs | J2: Dentists Stock By Age Group 45-54 yrs | K2: Dentists Stock By Age Group 55-64 yrs | L2: Dentists Stock By Age Group ≥ 65 yrs | M2: Annual graduates | N2: graduate to stock ratio | O2: Estimated numbe of graduates | P2: Cond | Q2: Projected 2023 | R2: Projected 2024 | S2: Projected 2025 | T2: Projected 2026 | U2: Projected 2027 | V2: Projected 2028 | W2: Projected 2029 | X2: Projected 2030
A3: Algeria | B3: DZA | C3: Lower-Middle-Income Economies | D3: 0 | E3: 15437 | F3: 16223 | G3: 0.02591177 | H3: 0.33400272 | I3: 0.23702792 | J3: 0.13577768 | K3: 0.22316512 | L3: 0.044114789 | N3: 0.068 | O3: =N3*F3 -> 1103.164 | P3: =F3<E3*0.7 -> FALSE | Q3: =E3*(1-L3)+0.7*O3 -> 15528.215 | R3: =Q3*(1-0.1*K3)+0.7*O3 -> 15953.894 | S3: =R3*(1-0.1*K3)+0.7*O3 -> 16370.074 | T3: =S3*(1-0.1*K3)+0.7*O3 -> 16776.965 | U3: =T3*(1-0.1*K3)+0.7*O3 -> 17174.777 | V3: =U3*(1-0.1*K3)+0.7*O3 -> 17563.711 | W3: =V3*(1-0.1*K3)+0.7*O3 -> 17943.965 | X3: =W3*(1-0.1*K3)+0.7*O3 -> 18315.733
A4: Angola | B4: AGO | C4: Lower-Middle-Income Economies | D4: 0 | E4: 1652 | F4: 253.58793 | G4: 0.03052838 | H4: 0.40571501 | I4: 0.28603213 | J4: 0.15979762 | K4: 0.10374001 | L4: 0.014186848 | M4: =VLOOKUP(B4,'Edu updated'!B$2:E$48,4,FALSE) -> 145 | N4: =M4/E4 -> 0.087772397 | O4: =N4*E4 -> 145 | P4: =F4<E4*0.7 -> TRUE | Q4: =E4*(1-L4)+0.7*O4 -> 1730.0633 | R4: =Q4*(1-0.1*K4)+0.7*O4 -> 1813.6156 | S4: =R4*(1-0.1*K4)+0.7*O4 -> 1896.3012 | T4: =S4*(1-0.1*K4)+0.7*O4 -> 1978.129 | U4: =T4*(1-0.1*K4)+0.7*O4 -> 2059.1079 | V4: =U4*(1-0.1*K4)+0.7*O4 -> 2139.2467 | W4: =V4*(1-0.1*K4)+0.7*O4 -> 2218.5541 | X4: =W4*(1-0.1*K4)+0.7*O4 -> 2297.0388
A5: Benin | B5: BEN | C5: Lower-Middle-Income Economies | D5: 0 | E5: 12 | F5: 50 | G5: 0 | H5: 0.2 | I5: 0.52 | J5: 0.16 | K5: 0.12 | L5: 0 | N5: 0.29907975 | O5: =N5*F5 -> 14.953988 | P5: =F5<E5*0.7 -> FALSE | Q5: =F5*(1-L5)+0.7*O5 -> 60.467791 | R5: =Q5*(1-0.1*K5)+0.7*O5 -> 70.209969 | S5: =R5*(1-0.1*K5)+0.7*O5 -> 79.835241 | T5: =S5*(1-0.1*K5)+0.7*O5 -> 89.34501 | U5: =T5*(1-0.1*K5)+0.7*O5 -> 98.740661 | V5: =U5*(1-0.1*K5)+0.7*O5 -> 108.02356 | W5: =V5*(1-0.1*K5)+0.7*O5 -> 117.19507 | X5: =W5*(1-0.1*K5)+0.7*O5 -> 126.25652
A6: Botswana | B6: BWA | C6: High/Upper-Middle-Income Economies | D6: 55 | E6: 96 | F6: 98.839683 | G6: 0.03164557 | H6: 0.30379747 | I6: 0.29113924 | J6: 0.28481013 | K6: 0.088607595 | L6: 0 | M6: =VLOOKUP(B6,'Edu updated'!B$2:E$48,4,FALSE) -> 7 | N6: =M6/F6 -> 0.070821757 | O6: =N6*F6 -> 7 | P6: =F6<E6*0.7 -> FALSE | Q6: =F6*(1-L6)+0.7*O6 -> 103.73968 | R6: =Q6*(1-0.1*K6)+0.7*O6 -> 107.72047 | S6: =R6*(1-0.1*K6)+0.7*O6 -> 111.66599 | T6: =S6*(1-0.1*K6)+0.7*O6 -> 115.57654 | U6: =T6*(1-0.1*K6)+0.7*O6 -> 119.45244 | V6: =U6*(1-0.1*K6)+0.7*O6 -> 123.29401 | W6: =V6*(1-0.1*K6)+0.7*O6 -> 127.10153 | X6: =W6*(1-0.1*K6)+0.7*O6 -> 130.87531
A7: Burkina Faso | B7: BFA | C7: Low-Income Economies | D7: 38 | E7: 91 | F7: 40.065995 | G7: 0.046296296 | H7: 0.2037037 | I7: 0.19444444 | J7: 0.26851852 | K7: 0.19444444 | L7: 0.092592593 | M7: =VLOOKUP(B7,'Edu updated'!B$2:E$48,4,FALSE) -> 62 | N7: 0.44899187 | O7: =N7*E7 -> 40.858261 | P7: =F7<E7*0.7 -> TRUE | Q7: =E7*(1-L7)+0.7*O7 -> 111.17486 | R7: =Q7*(1-0.1*K7)+0.7*O7 -> 137.61391 | S7: =R7*(1-0.1*K7)+0.7*O7 -> 163.53886 | T7: =S7*(1-0.1*K7)+0.7*O7 -> 188.95972 | U7: =T7*(1-0.1*K7)+0.7*O7 -> 213.88629 | V7: =U7*(1-0.1*K7)+0.7*O7 -> 238.32817 | W7: =V7*(1-0.1*K7)+0.7*O7 -> 262.29479 | X7: =W7*(1-0.1*K7)+0.7*O7 -> 285.7954
A8: Burundi | B8: BDI | C8: Low-Income Economies | D8: 4 | E8: 14 | F8: 14 | G8: 0.0081764545 | H8: 0.36686117 | I8: 0.32945884 | J8: 0.13608036 | K8: 0.13243992 | L8: 0.026983254 | N8: 0.32024089 | O8: =N8*F8 -> 4.4833724 | P8: =F8<E8*0.7 -> FALSE | Q8: =F8*(1-L8)+0.7*O8 -> 16.760595 | R8: =Q8*(1-0.1*K8)+0.7*O8 -> 19.676979 | S8: =R8*(1-0.1*K8)+0.7*O8 -> 22.554738 | T8: =S8*(1-0.1*K8)+0.7*O8 -> 25.394384 | U8: =T8*(1-0.1*K8)+0.7*O8 -> 28.196421 | V8: =U8*(1-0.1*K8)+0.7*O8 -> 30.961349 | W8: =V8*(1-0.1*K8)+0.7*O8 -> 33.689658 | X8: =W8*(1-0.1*K8)+0.7*O8 -> 36.381833
A9: Cameroon | B9: CMR | C9: Lower-Middle-Income Economies | D9: 58 | E9: 308 | F9: 317 | G9: 0 | H9: 0.72555205 | I9: 0.18611987 | J9: 0.056782334 | K9: 0.031545741 | L9: 0 | N9: 0.21282256 | O9: =N9*F9 -> 67.464751 | P9: =F9<E9*0.7 -> FALSE | Q9: =F9*(1-L9)+0.7*O9 -> 364.22533 | R9: =Q9*(1-0.1*K9)+0.7*O9 -> 410.30168 | S9: =R9*(1-0.1*K9)+0.7*O9 -> 456.23267 | T9: =S9*(1-0.1*K9)+0.7*O9 -> 502.01878 | U9: =T9*(1-0.1*K9)+0.7*O9 -> 547.66045 | V9: =U9*(1-0.1*K9)+0.7*O9 -> 593.15814 | W9: =V9*(1-0.1*K9)+0.7*O9 -> 638.51231 | X9: =W9*(1-0.1*K9)+0.7*O9 -> 683.7234
A10: Cape-Verde | B10: CPV | C10: Lower-Middle-Income Economies | D10: 0 | E10: 81 | F10: 12.434266 | G10: 0.03052838 | H10: 0.40571501 | I10: 0.28603213 | J10: 0.15979762 | K10: 0.10374001 | L10: 0.014186848 | N10: 0.068 | O10: =N10*E10 -> 5.508 | P10: =F10<E10*0.7 -> TRUE | Q10: =E10*(1-L10)+0.7*O10 -> 83.706465 | R10: =Q10*(1-0.1*K10)+0.7*O10 -> 86.693694 | S10: =R10*(1-0.1*K10)+0.7*O10 -> 89.649934 | T10: =S10*(1-0.1*K10)+0.7*O10 -> 92.575505 | U10: =T10*(1-0.1*K10)+0.7*O10 -> 95.470727 | V10: =U10*(1-0.1*K10)+0.7*O10 -> 98.335914 | W10: =V10*(1-0.1*K10)+0.7*O10 -> 101.17138 | X10: =W10*(1-0.1*K10)+0.7*O10 -> 103.97742
A11: Central African Republic | B11: CAF | C11: Low-Income Economies | D11: 0 | E11: 10 | F11: 2.5682382 | G11: 0.0081764545 | H11: 0.36686117 | I11: 0.32945884 | J11: 0.13608036 | K11: 0.13243992 | L11: 0.026983254 | N11: 0.12295957 | O11: =N11*E11 -> 1.2295957 | P11: =F11<E11*0.7 -> TRUE | Q11: =E11*(1-L11)+0.7*O11 -> 10.590884 | R11: =Q11*(1-0.1*K11)+0.7*O11 -> 11.311336 | S11: =R11*(1-0.1*K11)+0.7*O11 -> 12.022246 | T11: =S11*(1-0.1*K11)+0.7*O11 -> 12.72374 | U11: =T11*(1-0.1*K11)+0.7*O11 -> 13.415944 | V11: =U11*(1-0.1*K11)+0.7*O11 -> 14.09898 | W11: =V11*(1-0.1*K11)+0.7*O11 -> 14.772971 | X11: =W11*(1-0.1*K11)+0.7*O11 -> 15.438034
A12: Chad | B12: TCD | C12: Low-Income Economies | D12: 0 | E12: 3 | F12: 21 | G12: 0.0081764545 | H12: 0.36686117 | I12: 0.32945884 | J12: 0.13608036 | K12: 0.13243992 | L12: 0.026983254 | N12: 0.2189781 | O12: =N12*F12 -> 4.5985401 | P12: =F12<E12*0.7 -> FALSE | Q12: =F12*(1-L12)+0.7*O12 -> 23.65233 | R12: =Q12*(1-0.1*K12)+0.7*O12 -> 26.558057 | S12: =R12*(1-0.1*K12)+0.7*O12 -> 29.4253 | T12: =S12*(1-0.1*K12)+0.7*O12 -> 32.25457 | U12: =T12*(1-0.1*K12)+0.7*O12 -> 35.046368 | V12: =U12*(1-0.1*K12)+0.7*O12 -> 37.801193 | W12: =V12*(1-0.1*K12)+0.7*O12 -> 40.519532 | X12: =W12*(1-0.1*K12)+0.7*O12 -> 43.20187
A13: Comoros | B13: COM | C13: Lower-Middle-Income Economies | D13: 18 | E13: 32 | F13: 32 | G13: 0.03052838 | H13: 0.40571501 | I13: 0.28603213 | J13: 0.15979762 | K13: 0.10374001 | L13: 0.014186848 | N13: 0.068 | O13: =N13*F13 -> 2.176 | P13: =F13<E13*0.7 -> FALSE | Q13: =F13*(1-L13)+0.7*O13 -> 33.069221 | R13: =Q13*(1-0.1*K13)+0.7*O13 -> 34.249361 | S13: =R13*(1-0.1*K13)+0.7*O13 -> 35.417258 | T13: =S13*(1-0.1*K13)+0.7*O13 -> 36.573039 | U13: =T13*(1-0.1*K13)+0.7*O13 -> 37.71683 | V13: =U13*(1-0.1*K13)+0.7*O13 -> 38.848756 | W13: =V13*(1-0.1*K13)+0.7*O13 -> 39.968939 | X13: =W13*(1-0.1*K13)+0.7*O13 -> 41.077501
A14: Congo | B14: COG | C14: Lower-Middle-Income Economies | D14: 0 | E14: 27 | F14: 10.343688 | G14: 0.03052838 | H14: 0.40571501 | I14: 0.28603213 | J14: 0.15979762 | K14: 0.10374001 | L14: 0.014186848 | N14: 0.057581574 | O14: =N14*E14 -> 1.5547025 | P14: =F14<E14*0.7 -> TRUE | Q14: =E14*(1-L14)+0.7*O14 -> 27.705247 | R14: =Q14*(1-0.1*K14)+0.7*O14 -> 28.506124 | S14: =R14*(1-0.1*K14)+0.7*O14 -> 29.298694 | T14: =S14*(1-0.1*K14)+0.7*O14 -> 30.083041 | U14: =T14*(1-0.1*K14)+0.7*O14 -> 30.859251 | V14: =U14*(1-0.1*K14)+0.7*O14 -> 31.627409 | W14: =V14*(1-0.1*K14)+0.7*O14 -> 32.387598 | X14: =W14*(1-0.1*K14)+0.7*O14 -> 33.1399
A15: Cote d'Ivoire | B15: CIV | C15: Lower-Middle-Income Economies | D15: 490 | E15: 506 | F15: 536.49427 | G15: 0 | H15: 0.16028708 | I15: 0.34688995 | J15: 0.24641148 | K15: 0.23923445 | L15: 0.0071770335 | N15: 0.040141907 | O15: =N15*F15 -> 21.535903 | P15: =F15<E15*0.7 -> FALSE | Q15: =F15*(1-L15)+0.7*O15 -> 547.71896 | R15: =Q15*(1-0.1*K15)+0.7*O15 -> 549.69077 | S15: =R15*(1-0.1*K15)+0.7*O15 -> 551.6154 | T15: =S15*(1-0.1*K15)+0.7*O15 -> 553.49399 | U15: =T15*(1-0.1*K15)+0.7*O15 -> 555.32764 | V15: =U15*(1-0.1*K15)+0.7*O15 -> 557.11742 | W15: =V15*(1-0.1*K15)+0.7*O15 -> 558.86439 | X15: =W15*(1-0.1*K15)+0.7*O15 -> 560.56956
A16: DRC | B16: COD | C16: Low-Income Economies | D16: 0 | E16: 404 | F16: 451.28772 | G16: 0.0081764545 | H16: 0.36686117 | I16: 0.32945884 | J16: 0.13608036 | K16: 0.13243992 | L16: 0.026983254 | M16: =VLOOKUP(B16,'Edu updated'!B$2:E$48,4,FALSE) -> 66 | N16: =M16/F16 -> 0.14624816 | O16: =N16*F16 -> 66 | P16: =F16<E16*0.7 -> FALSE | Q16: =F16*(1-L16)+0.7*O16 -> 485.31051 | R16: =Q16*(1-0.1*K16)+0.7*O16 -> 525.08306 | S16: =R16*(1-0.1*K16)+0.7*O16 -> 564.32886 | T16: =S16*(1-0.1*K16)+0.7*O16 -> 603.0549 | U16: =T16*(1-0.1*K16)+0.7*O16 -> 641.26804 | V16: =U16*(1-0.1*K16)+0.7*O16 -> 678.97509 | W16: =V16*(1-0.1*K16)+0.7*O16 -> 716.18275 | X16: =W16*(1-0.1*K16)+0.7*O16 -> 752.89763
A17: Equatorial Guinea | B17: GNQ | C17: High/Upper-Middle-Income Economies | D17: 0 | E17: 0 | F17: 0 | G17: 0.010548523 | H17: 0.18459916 | I17: 0.21825853 | J17: 0.30705792 | K17: 0.24923283 | L17: 0.03030303 | N17: 2.792316 | O17: =N17*F17 -> 0 | P17: =F17<E17*0.7 -> FALSE | Q17: =F17*(1-L17)+0.7*O17 -> 0 | R17: =Q17*(1-0.1*K17)+0.7*O17 -> 0 | S17: =R17*(1-0.1*K17)+0.7*O17 -> 0 | T17: =S17*(1-0.1*K17)+0.7*O17 -> 0 | U17: =T17*(1-0.1*K17)+0.7*O17 -> 0 | V17: =U17*(1-0.1*K17)+0.7*O17 -> 0 | W17: =V17*(1-0.1*K17)+0.7*O17 -> 0 | X17: =W17*(1-0.1*K17)+0.7*O17 -> 0
A18: Eritrea | B18: ERI | C18: Low-Income Economies | D18: 0 | E18: 186 | F18: 66.659321 | G18: 0 | H18: 0.84482759 | I18: 0.12068966 | J18: 0.034482759 | K18: 0 | L18: 0 | N18: 0.206 | O18: =N18*E18 -> 38.316 | P18: =F18<E18*0.7 -> TRUE | Q18: =E18*(1-L18)+0.7*O18 -> 212.8212 | R18: =Q18*(1-0.1*K18)+0.7*O18 -> 239.6424 | S18: =R18*(1-0.1*K18)+0.7*O18 -> 266.4636 | T18: =S18*(1-0.1*K18)+0.7*O18 -> 293.2848 | U18: =T18*(1-0.1*K18)+0.7*O18 -> 320.106 | V18: =U18*(1-0.1*K18)+0.7*O18 -> 346.9272 | W18: =V18*(1-0.1*K18)+0.7*O18 -> 373.7484 | X18: =W18*(1-0.1*K18)+0.7*O18 -> 400.5696
A19: Eswatini | B19: SWZ | C19: Lower-Middle-Income Economies | D19: 0 | E19: 74 | F19: 50.164087 | G19: 0 | H19: 0.875 | I19: 0 | J19: 0.125 | K19: 0 | L19: 0 | N19: 0.068 | O19: =N19*F19 -> 3.4111579 | P19: =F19<E19*0.7 -> TRUE | Q19: =E19*(1-L19)+0.7*O19 -> 76.387811 | R19: =Q19*(1-0.1*K19)+0.7*O19 -> 78.775621 | S19: =R19*(1-0.1*K19)+0.7*O19 -> 81.163432 | T19: =S19*(1-0.1*K19)+0.7*O19 -> 83.551242 | U19: =T19*(1-0.1*K19)+0.7*O19 -> 85.939053 | V19: =U19*(1-0.1*K19)+0.7*O19 -> 88.326863 | W19: =V19*(1-0.1*K19)+0.7*O19 -> 90.714674 | X19: =W19*(1-0.1*K19)+0.7*O19 -> 93.102484
A20: Ethiopia | B20: ETH | C20: Low-Income Economies | D20: 0 | E20: 1889 | F20: 3522 | G20: 0.0081764545 | H20: 0.36686117 | I20: 0.32945884 | J20: 0.13608036 | K20: 0.13243992 | L20: 0.026983254 | M20: =VLOOKUP(B20,'Edu updated'!B$2:E$48,4,FALSE) -> 189 | N20: =M20/F20 -> 0.053662692 | O20: =N20*F20 -> 189 | P20: =F20<E20*0.7 -> FALSE | Q20: =F20*(1-L20)+0.7*O20 -> 3559.265 | R20: =Q20*(1-0.1*K20)+0.7*O20 -> 3644.4261 | S20: =R20*(1-0.1*K20)+0.7*O20 -> 3728.4593 | T20: =S20*(1-0.1*K20)+0.7*O20 -> 3811.3797 | U20: =T20*(1-0.1*K20)+0.7*O20 -> 3893.2018 | V20: =U20*(1-0.1*K20)+0.7*O20 -> 3973.9402 | W20: =V20*(1-0.1*K20)+0.7*O20 -> 4053.6094 | X20: =W20*(1-0.1*K20)+0.7*O20 -> 4132.2234
A21: Gabon | B21: GAB | C21: High/Upper-Middle-Income Economies | D21: 0 | E21: 40 | F21: 44 | G21: 0 | H21: 0.045454545 | I21: 0.090909091 | J21: 0.38636364 | K21: 0.43181818 | L21: 0.045454545 | N21: 0.036352434 | O21: =N21*F21 -> 1.5995071 | P21: =F21<E21*0.7 -> FALSE | Q21: =F21*(1-L21)+0.7*O21 -> 43.119655 | R21: =Q21*(1-0.1*K21)+0.7*O21 -> 42.377325 | S21: =R21*(1-0.1*K21)+0.7*O21 -> 41.66705 | T21: =S21*(1-0.1*K21)+0.7*O21 -> 40.987446 | U21: =T21*(1-0.1*K21)+0.7*O21 -> 40.337188 | V21: =U21*(1-0.1*K21)+0.7*O21 -> 39.71501 | W21: =V21*(1-0.1*K21)+0.7*O21 -> 39.119699 | X21: =W21*(1-0.1*K21)+0.7*O21 -> 38.550094
A22: Gambia | B22: GMB | C22: Low-Income Economies | D22: 17 | E22: 4 | F22: 9 | G22: 0.0081764545 | H22: 0.36686117 | I22: 0.32945884 | J22: 0.13608036 | K22: 0.13243992 | L22: 0.026983254 | N22: 0.083982301 | O22: =N22*F22 -> 0.75584071 | P22: =F22<E22*0.7 -> FALSE | Q22: =F22*(1-L22)+0.7*O22 -> 9.2862392 | R22: =Q22*(1-0.1*K22)+0.7*O22 -> 9.6923408 | S22: =R22*(1-0.1*K22)+0.7*O22 -> 10.093064 | T22: =S22*(1-0.1*K22)+0.7*O22 -> 10.48848 | U22: =T22*(1-0.1*K22)+0.7*O22 -> 10.878659 | V22: =U22*(1-0.1*K22)+0.7*O22 -> 11.263671 | W22: =V22*(1-0.1*K22)+0.7*O22 -> 11.643583 | X22: =W22*(1-0.1*K22)+0.7*O22 -> 12.018464
A23: Ghana | B23: GHA | C23: Lower-Middle-Income Economies | D23: 0 | E23: 713 | F23: 243.71996 | G23: 0.03052838 | H23: 0.40571501 | I23: 0.28603213 | J23: 0.15979762 | K23: 0.10374001 | L23: 0.014186848 | N23: 0.33135844 | O23: =N23*E23 -> 236.25857 | P23: =F23<E23*0.7 -> TRUE | Q23: =E23*(1-L23)+0.7*O23 -> 868.26578 | R23: =Q23*(1-0.1*K23)+0.7*O23 -> 1024.6394 | S23: =R23*(1-0.1*K23)+0.7*O23 -> 1179.3908 | T23: =S23*(1-0.1*K23)+0.7*O23 -> 1332.5368 | U23: =T23*(1-0.1*K23)+0.7*O23 -> 1484.094 | V23: =U23*(1-0.1*K23)+0.7*O23 -> 1634.079 | W23: =V23*(1-0.1*K23)+0.7*O23 -> 1782.5081 | X23: =W23*(1-0.1*K23)+0.7*O23 -> 1929.3974
A24: Guinea | B24: GIN | C24: Low-Income Economies | D24: 0 | E24: 73 | F24: 39.076154 | G24: 0.0081764545 | H24: 0.36686117 | I24: 0.32945884 | J24: 0.13608036 | K24: 0.13243992 | L24: 0.026983254 | N24: 2.2470153 | O24: =N24*F24 -> 87.804714 | P24: =F24<E24*0.7 -> TRUE | Q24: =E24*(1-L24)+0.7*O24 -> 132.49352 | R24: =Q24*(1-0.1*K24)+0.7*O24 -> 192.20208 | S24: =R24*(1-0.1*K24)+0.7*O24 -> 251.11986 | T24: =S24*(1-0.1*K24)+0.7*O24 -> 309.25733 | U24: =T24*(1-0.1*K24)+0.7*O24 -> 366.62482 | V24: =U24*(1-0.1*K24)+0.7*O24 -> 423.23255 | W24: =V24*(1-0.1*K24)+0.7*O24 -> 479.09056 | X24: =W24*(1-0.1*K24)+0.7*O24 -> 534.20879
A25: Guinea-Bissau | B25: GNB | C25: Low-Income Economies | D25: 0 | E25: 8 | F25: 20 | G25: 0 | H25: 0.66666667 | I25: 0.33333333 | J25: 0 | K25: 0 | L25: 0 | N25: 0.206 | O25: =N25*F25 -> 4.12 | P25: =F25<E25*0.7 -> FALSE | Q25: =F25*(1-L25)+0.7*O25 -> 22.884 | R25: =Q25*(1-0.1*K25)+0.7*O25 -> 25.768 | S25: =R25*(1-0.1*K25)+0.7*O25 -> 28.652 | T25: =S25*(1-0.1*K25)+0.7*O25 -> 31.536 | U25: =T25*(1-0.1*K25)+0.7*O25 -> 34.42 | V25: =U25*(1-0.1*K25)+0.7*O25 -> 37.304 | W25: =V25*(1-0.1*K25)+0.7*O25 -> 40.188 | X25: =W25*(1-0.1*K25)+0.7*O25 -> 43.072
A26: Kenya | B26: KEN | C26: Lower-Middle-Income Economies | D26: 1045 | E26: 1300 | F26: 1344 | G26: 0.074829932 | H26: 0.25170068 | I26: 0.4829932 | J26: 0.14285714 | K26: 0.047619048 | L26: 0 | M26: =VLOOKUP(B26,'Edu updated'!B$2:E$48,4,FALSE) -> 36 | N26: =M26/F26 -> 0.026785714 | O26: =N26*F26 -> 36 | P26: =F26<E26*0.7 -> FALSE | Q26: =F26*(1-L26)+0.7*O26 -> 1369.2 | R26: =Q26*(1-0.1*K26)+0.7*O26 -> 1387.88 | S26: =R26*(1-0.1*K26)+0.7*O26 -> 1406.471 | T26: =S26*(1-0.1*K26)+0.7*O26 -> 1424.9736 | U26: =T26*(1-0.1*K26)+0.7*O26 -> 1443.388 | V26: =U26*(1-0.1*K26)+0.7*O26 -> 1461.7147 | W26: =V26*(1-0.1*K26)+0.7*O26 -> 1479.9542 | X26: =W26*(1-0.1*K26)+0.7*O26 -> 1498.1068
A27: Lesotho | B27: LSO | C27: Lower-Middle-Income Economies | D27: 0 | E27: 159 | F27: 84.324394 | G27: 0.03052838 | H27: 0.40571501 | I27: 0.28603213 | J27: 0.15979762 | K27: 0.10374001 | L27: 0.014186848 | M27: =VLOOKUP(B27,'Edu updated'!B$2:E$48,4,FALSE) -> 8 | N27: =M27/E27 -> 0.050314465 | O27: =N27*F27 -> 4.2427368 | P27: =F27<E27*0.7 -> TRUE | Q27: =E27*(1-L27)+0.7*O27 -> 159.71421 | R27: =Q27*(1-0.1*K27)+0.7*O27 -> 161.02725 | S27: =R27*(1-0.1*K27)+0.7*O27 -> 162.32667 | T27: =S27*(1-0.1*K27)+0.7*O27 -> 163.6126 | U27: =T27*(1-0.1*K27)+0.7*O27 -> 164.8852 | V27: =U27*(1-0.1*K27)+0.7*O27 -> 166.1446 | W27: =V27*(1-0.1*K27)+0.7*O27 -> 167.39093 | X27: =W27*(1-0.1*K27)+0.7*O27 -> 168.62433
A28: Liberia | B28: LBR | C28: Low-Income Economies | D28: 0 | E28: 14 | F28: 7.715922 | G28: 0.0081764545 | H28: 0.36686117 | I28: 0.32945884 | J28: 0.13608036 | K28: 0.13243992 | L28: 0.026983254 | N28: 0.030398323 | O28: =N28*F28 -> 0.23455109 | P28: =F28<E28*0.7 -> TRUE | Q28: =E28*(1-L28)+0.7*O28 -> 13.78642 | R28: =Q28*(1-0.1*K28)+0.7*O28 -> 13.768019 | S28: =R28*(1-0.1*K28)+0.7*O28 -> 13.749861 | T28: =S28*(1-0.1*K28)+0.7*O28 -> 13.731944 | U28: =T28*(1-0.1*K28)+0.7*O28 -> 13.714264 | V28: =U28*(1-0.1*K28)+0.7*O28 -> 13.696818 | W28: =V28*(1-0.1*K28)+0.7*O28 -> 13.679603 | X28: =W28*(1-0.1*K28)+0.7*O28 -> 13.662616
A29: Madagascar | B29: MDG | C29: Low-Income Economies | D29: 111 | E29: 372 | F29: 250.78617 | G29: 0.0081764545 | H29: 0.36686117 | I29: 0.32945884 | J29: 0.13608036 | K29: 0.13243992 | L29: 0.026983254 | N29: 0.06042065 | O29: =N29*F29 -> 15.152663 | P29: =F29<E29*0.7 -> TRUE | Q29: =E29*(1-L29)+0.7*O29 -> 372.56909 | R29: =Q29*(1-0.1*K29)+0.7*O29 -> 378.24166 | S29: =R29*(1-0.1*K29)+0.7*O29 -> 383.83909 | T29: =S29*(1-0.1*K29)+0.7*O29 -> 389.36239 | U29: =T29*(1-0.1*K29)+0.7*O29 -> 394.81254 | V29: =U29*(1-0.1*K29)+0.7*O29 -> 400.19051 | W29: =V29*(1-0.1*K29)+0.7*O29 -> 405.49726 | X29: =W29*(1-0.1*K29)+0.7*O29 -> 410.73372
A30: Malawi | B30: MWI | C30: Low-Income Economies | D30: 0 | E30: 112 | F30: 100.82761 | G30: 0 | H30: 0.04950495 | I30: 0.40594059 | J30: 0.22772277 | K30: 0.24752475 | L30: 0.069306931 | N30: 0.10420784 | O30: =N30*F30 -> 10.507028 | P30: =F30<E30*0.7 -> FALSE | Q30: =F30*(1-L30)+0.7*O30 -> 101.19448 | R30: =Q30*(1-0.1*K30)+0.7*O30 -> 106.04459 | S30: =R30*(1-0.1*K30)+0.7*O30 -> 110.77464 | T30: =S30*(1-0.1*K30)+0.7*O30 -> 115.38761 | U30: =T30*(1-0.1*K30)+0.7*O30 -> 119.8864 | V30: =U30*(1-0.1*K30)+0.7*O30 -> 124.27384 | W30: =V30*(1-0.1*K30)+0.7*O30 -> 128.55267 | X30: =W30*(1-0.1*K30)+0.7*O30 -> 132.7256
A31: Mali | B31: MLI | C31: Low-Income Economies | D31: 0 | E31: 30 | F31: 30 | G31: 0.0081764545 | H31: 0.36686117 | I31: 0.32945884 | J31: 0.13608036 | K31: 0.13243992 | L31: 0.026983254 | N31: 0.206 | O31: =N31*F31 -> 6.18 | P31: =F31<E31*0.7 -> FALSE | Q31: =F31*(1-L31)+0.7*O31 -> 33.516502 | R31: =Q31*(1-0.1*K31)+0.7*O31 -> 37.39861 | S31: =R31*(1-0.1*K31)+0.7*O31 -> 41.229303 | T31: =S31*(1-0.1*K31)+0.7*O31 -> 45.009263 | U31: =T31*(1-0.1*K31)+0.7*O31 -> 48.73916 | V31: =U31*(1-0.1*K31)+0.7*O31 -> 52.419659 | W31: =V31*(1-0.1*K31)+0.7*O31 -> 56.051414 | X31: =W31*(1-0.1*K31)+0.7*O31 -> 59.635069
A32: Mauritania | B32: MRT | C32: Lower-Middle-Income Economies | D32: 0 | E32: 151 | F32: 149.16596 | G32: 0.03052838 | H32: 0.40571501 | I32: 0.28603213 | J32: 0.15979762 | K32: 0.10374001 | L32: 0.014186848 | N32: 0.068 | O32: =N32*F32 -> 10.143285 | P32: =F32<E32*0.7 -> FALSE | Q32: =F32*(1-L32)+0.7*O32 -> 154.15007 | R32: =Q32*(1-0.1*K32)+0.7*O32 -> 159.65121 | S32: =R32*(1-0.1*K32)+0.7*O32 -> 165.09529 | T32: =S32*(1-0.1*K32)+0.7*O32 -> 170.48289 | U32: =T32*(1-0.1*K32)+0.7*O32 -> 175.8146 | V32: =U32*(1-0.1*K32)+0.7*O32 -> 181.091 | W32: =V32*(1-0.1*K32)+0.7*O32 -> 186.31266 | X32: =W32*(1-0.1*K32)+0.7*O32 -> 191.48015
A33: Mauritius | B33: MUS | C33: High/Upper-Middle-Income Economies | D33: 351 | E33: 466 | F33: 413.89909 | G33: 0.010548523 | H33: 0.18459916 | I33: 0.21825853 | J33: 0.30705792 | K33: 0.24923283 | L33: 0.03030303 | N33: 0.23559496 | O33: =N33*F33 -> 97.51254 | P33: =F33<E33*0.7 -> FALSE | Q33: =F33*(1-L33)+0.7*O33 -> 469.61547 | R33: =Q33*(1-0.1*K33)+0.7*O33 -> 526.16989 | S33: =R33*(1-0.1*K33)+0.7*O33 -> 581.31478 | T33: =S33*(1-0.1*K33)+0.7*O33 -> 635.08529 | U33: =T33*(1-0.1*K33)+0.7*O33 -> 687.51566 | V33: =U33*(1-0.1*K33)+0.7*O33 -> 738.63929 | W33: =V33*(1-0.1*K33)+0.7*O33 -> 788.48875 | X33: =W33*(1-0.1*K33)+0.7*O33 -> 837.0958
A34: Mozambique | B34: MOZ | C34: Low-Income Economies | D34: 136 | E34: 255 | F34: 348 | G34: 0.0027624309 | H34: 0.43646409 | I34: 0.47790055 | J34: 0.063535912 | K34: 0.019337017 | L34: 0 | M34: =VLOOKUP(B34,'Edu updated'!B$2:E$48,4,FALSE) -> 161 | N34: =M34/F34 -> 0.46264368 | O34: =N34*F34 -> 161 | P34: =F34<E34*0.7 -> FALSE | Q34: =F34*(1-L34)+0.7*O34 -> 460.7 | R34: =Q34*(1-0.1*K34)+0.7*O34 -> 572.50914 | S34: =R34*(1-0.1*K34)+0.7*O34 -> 684.10208 | T34: =S34*(1-0.1*K34)+0.7*O34 -> 795.47923 | U34: =T34*(1-0.1*K34)+0.7*O34 -> 906.64101 | V34: =U34*(1-0.1*K34)+0.7*O34 -> 1017.5878 | W34: =V34*(1-0.1*K34)+0.7*O34 -> 1128.3201 | X34: =W34*(1-0.1*K34)+0.7*O34 -> 1238.8383
A35: Namibia | B35: NAM | C35: High/Upper-Middle-Income Economies | D35: 68 | E35: 181 | F35: 224 | G35: 0.010548523 | H35: 0.18459916 | I35: 0.21825853 | J35: 0.30705792 | K35: 0.24923283 | L35: 0.03030303 | N35: 0.29743269 | O35: =N35*F35 -> 66.624922 | P35: =F35<E35*0.7 -> FALSE | Q35: =F35*(1-L35)+0.7*O35 -> 263.84957 | R35: =Q35*(1-0.1*K35)+0.7*O35 -> 303.91101 | S35: =R35*(1-0.1*K35)+0.7*O35 -> 342.974 | T35: =S35*(1-0.1*K35)+0.7*O35 -> 381.06341 | U35: =T35*(1-0.1*K35)+0.7*O35 -> 418.2035 | V35: =U35*(1-0.1*K35)+0.7*O35 -> 454.41794 | W35: =V35*(1-0.1*K35)+0.7*O35 -> 489.7298 | X35: =W35*(1-0.1*K35)+0.7*O35 -> 524.16157
A36: Niger | B36: NER | C36: Low-Income Economies | D36: 30 | E36: 30 | F36: 27.583167 | G36: 0.0081764545 | H36: 0.36686117 | I36: 0.32945884 | J36: 0.13608036 | K36: 0.13243992 | L36: 0.026983254 | N36: 0.52432487 | O36: =N36*F36 -> 14.462541 | P36: =F36<E36*0.7 -> FALSE | Q36: =F36*(1-L36)+0.7*O36 -> 36.962662 | R36: =Q36*(1-0.1*K36)+0.7*O36 -> 46.596908 | S36: =R36*(1-0.1*K36)+0.7*O36 -> 56.103557 | T36: =S36*(1-0.1*K36)+0.7*O36 -> 65.4843 | U36: =T36*(1-0.1*K36)+0.7*O36 -> 74.740805 | V36: =U36*(1-0.1*K36)+0.7*O36 -> 83.874717 | W36: =V36*(1-0.1*K36)+0.7*O36 -> 92.88766 | X36: =W36*(1-0.1*K36)+0.7*O36 -> 101.78123
A37: Nigeria | B37: NGA | C37: Lower-Middle-Income Economies | D37: 0 | E37: 4358 | F37: 5048 | G37: 0.024096386 | H37: 0.44539448 | I37: 0.4220754 | J37: 0 | K37: 0.084337349 | L37: 0.024096386 | M37: =VLOOKUP(B37,'Edu updated'!B$2:E$48,4,FALSE) -> 459 | N37: =M37/F37 -> 0.0909271 | O37: =N37*F37 -> 459 | P37: =F37<E37*0.7 -> FALSE | Q37: =F37*(1-L37)+0.7*O37 -> 5247.6614 | R37: =Q37*(1-0.1*K37)+0.7*O37 -> 5524.7041 | S37: =R37*(1-0.1*K37)+0.7*O37 -> 5799.4102 | T37: =S37*(1-0.1*K37)+0.7*O37 -> 6071.7995 | U37: =T37*(1-0.1*K37)+0.7*O37 -> 6341.8915 | V37: =U37*(1-0.1*K37)+0.7*O37 -> 6609.7057 | W37: =V37*(1-0.1*K37)+0.7*O37 -> 6875.2612 | X37: =W37*(1-0.1*K37)+0.7*O37 -> 7138.5771
A38: Rwanda | B38: RWA | C38: Low-Income Economies | D38: 127 | E38: 228 | F38: 236 | G38: 0.0081764545 | H38: 0.36686117 | I38: 0.32945884 | J38: 0.13608036 | K38: 0.13243992 | L38: 0.026983254 | N38: 0.0066747573 | O38: =N38*F38 -> 1.5752427 | P38: =F38<E38*0.7 -> FALSE | Q38: =F38*(1-L38)+0.7*O38 -> 230.73462 | R38: =Q38*(1-0.1*K38)+0.7*O38 -> 228.78144 | S38: =R38*(1-0.1*K38)+0.7*O38 -> 226.85413 | T38: =S38*(1-0.1*K38)+0.7*O38 -> 224.95235 | U38: =T38*(1-0.1*K38)+0.7*O38 -> 223.07575 | V38: =U38*(1-0.1*K38)+0.7*O38 -> 221.22401 | W38: =V38*(1-0.1*K38)+0.7*O38 -> 219.39679 | X38: =W38*(1-0.1*K38)+0.7*O38 -> 217.59377
A39: Sao Tome and Principe | B39: STP | C39: Lower-Middle-Income Economies | D39: 0 | E39: 6 | F39: 6 | G39: 0.03052838 | H39: 0.40571501 | I39: 0.28603213 | J39: 0.15979762 | K39: 0.10374001 | L39: 0.014186848 | N39: 0.068 | O39: =N39*F39 -> 0.408 | P39: =F39<E39*0.7 -> FALSE | Q39: =F39*(1-L39)+0.7*O39 -> 6.2004789 | R39: =Q39*(1-0.1*K39)+0.7*O39 -> 6.4217551 | S39: =R39*(1-0.1*K39)+0.7*O39 -> 6.6407358 | T39: =S39*(1-0.1*K39)+0.7*O39 -> 6.8574448 | U39: =T39*(1-0.1*K39)+0.7*O39 -> 7.0719057 | V39: =U39*(1-0.1*K39)+0.7*O39 -> 7.2841417 | W39: =V39*(1-0.1*K39)+0.7*O39 -> 7.494176 | X39: =W39*(1-0.1*K39)+0.7*O39 -> 7.7020315
A40: Senegal | B40: SEN | C40: Lower-Middle-Income Economies | D40: 54 | E40: 136 | F40: 223 | G40: 0 | H40: 0.13963964 | I40: 0.28378378 | J40: 0.36036036 | K40: 0.20720721 | L40: 0.009009009 | M40: =VLOOKUP(B40,'Edu updated'!B$2:E$48,4,FALSE) -> 67 | N40: =M40/F40 -> 0.30044843 | O40: =N40*F40 -> 67 | P40: =F40<E40*0.7 -> FALSE | Q40: =F40*(1-L40)+0.7*O40 -> 267.89099 | R40: =Q40*(1-0.1*K40)+0.7*O40 -> 309.2401 | S40: =R40*(1-0.1*K40)+0.7*O40 -> 349.73242 | T40: =S40*(1-0.1*K40)+0.7*O40 -> 389.38571 | U40: =T40*(1-0.1*K40)+0.7*O40 -> 428.21736 | V40: =U40*(1-0.1*K40)+0.7*O40 -> 466.24439 | W40: =V40*(1-0.1*K40)+0.7*O40 -> 503.48347 | X40: =W40*(1-0.1*K40)+0.7*O40 -> 539.95093
A41: Seychelles | B41: SYC | C41: High/Upper-Middle-Income Economies | D41: 14 | E41: 38 | F41: 44 | G41: 0 | H41: 0.20454545 | I41: 0.27272727 | J41: 0.25 | K41: 0.22727273 | L41: 0.045454545 | N41: 0.012077295 | O41: =N41*F41 -> 0.53140097 | P41: =F41<E41*0.7 -> FALSE | Q41: =F41*(1-L41)+0.7*O41 -> 42.371981 | R41: =Q41*(1-0.1*K41)+0.7*O41 -> 41.780962 | S41: =R41*(1-0.1*K41)+0.7*O41 -> 41.203375 | T41: =S41*(1-0.1*K41)+0.7*O41 -> 40.638915 | U41: =T41*(1-0.1*K41)+0.7*O41 -> 40.087284 | V41: =U41*(1-0.1*K41)+0.7*O41 -> 39.54819 | W41: =V41*(1-0.1*K41)+0.7*O41 -> 39.021349 | X41: =W41*(1-0.1*K41)+0.7*O41 -> 38.50648
...

Sheet Education
A1: Row Labels | B1: Dentists
A2: Angola
A3: Benin
A4: Botswana
A5: Burkina Faso
A6: Burundi
A7: Cameroon
A8: Cape-Verde
A9: CAR
A10: Chad
A11: Congo
A12: Cote d'Ivoire | B12: 37
A13: DRC
A14: Eritrea | B14: 30
A15: Eswatini
A16: Ethiopia | B16: 185
A17: Gabon
A18: Gambia
A19: Ghana | B19: 51
A20: Guinea
A21: Guinea-Bissau
A22: Lesotho | B22: 8
A23: Kenya | B23: 36
A24: Liberia
A25: Madagascar | B25: 48
A26: Malawi | B26: 22
A27: Mali
A28: Mauritania
A29: Mauritius
A30: Mozambique
A31: Namibia
A32: Niger
A33: Nigeria | B33: 194
A34: Rwanda
A35: Senegal
A36: Sierra Leone
A37: South Africa
A38: South Sudan
A39: Tanzania | B39: 38
A40: Togo
...

Sheet Edu updated
A1: Country | B1: iso codes | C1: Generalist Medical Practitioners | D1: Specialist Medical Practitioners | E1: Dentists | F1: Other Dental practitioners | G1: Pharmacists | H1: Other Pharmacy practitioners | I1: Midwifery personnel | J1: Nursing Personnel | K1: Medical and Pathology Laboratory scientists | L1: Paramedical Practitioners | M1: Other Health Workers | N1: Total | O1: Data Sorce(s)
A2: Algeria | B2: DZA | C2: 0 | N2: 0 | O2: NHWA dataset, 2023
A3: Angola | B3: AGO | C3: 611 | E3: 145 | G3: 529 | J3: 2950 | N3: 4235 | O3: Dent-2018;
A4: Benin | B4: BEN | C4: 780 | D4: 385 | G4: 143 | I4: 247 | J4: 257 | K4: 1113 | M4: 1194 | N4: 4119 | O4: Med-2021; Pharm-2021;Mid-2021; Nur-2021;Biom-2021; others-2021
A5: Botswana | B5: BWA | C5: 60 | D5: 48 | E5: 7 | F5: 10 | G5: 95 | H5: 60 | I5: 40 | J5: 490 | K5: 189 | L5: 30 | M5: 597 | N5: 1626 | O5: 2022 for all
A6: Burkina Faso | B6: BFA | C6: 1492 | D6: 385 | E6: 62 | G6: 594 | I6: 1170 | J6: 1170 | N6: 4873 | O6: NHWA dataset, 2023
A7: Burundi | B7: BDI | C7: 325 | D7: 240 | G7: 39 | I7: 196 | J7: 1467 | K7: 322 | M7: 194 | N7: 2783 | O7: 2018 dataset
A8: Cameroon | B8: CMR | C8: 800 | J8: 2660 | K8: 800 | N8: 4260 | O8: NHWA dataset, 2023
A9: Cabo Verde | B9: CPV | F9: 7 | M9: 83 | N9: 90 | O9: NHWA dataset, 2023
A10: Central African Republic | B10: CAF | C10: 18 | N10: 18 | O10: NHWA dataset, 2023
A11: Chad | B11: TCD | C11: 330 | D11: 30 | G11: 80 | H11: 180 | I11: 2084 | J11: 2920 | K11: 220 | N11: 5844 | O11: NHWA dataset, 2023
A12: Comoros | B12: COM | I12: 29 | J12: 40 | N12: 69 | O12: 2021 for all
A13: Congo | B13: COG | C13: 60 | D13: 315 | F13: 10 | H13: 5 | I13: 120 | J13: 60 | L13: 50 | M13: 408 | N13: 1028 | O13: 2022 for all
A14: Cote d'Ivoire | B14: CIV | C14: 254 | D14: 48 | H14: 151 | J14: 1007 | K14: 1106 | M14: 450 | N14: 3016 | O14: NHWA dataset, 2023
A15: Democratic Republic of the Congo | B15: COD | C15: 6020 | E15: 66 | G15: 178 | H15: 328 | I15: 3453 | J15: 24061 | K15: 2571 | M15: 3151 | N15: 39828 | O15: NHWA dataset, 2023
A16: Equatorial Guinea | B16: GNQ | C16: 767 | I16: 492 | J16: 962 | K16: 27 | M16: 1304 | N16: 3552 | O16: NHWA dataset, 2023
A17: Eritrea | B17: ERI | J17: 400 | M17: 1023 | N17: 1423 | O17: Nurs-2022
A18: Eswatini | B18: SWZ | G18: 44 | H18: 30 | I18: 80 | J18: 160 | K18: 78 | M18: 58 | N18: 450 | O18: NHWA dataset, 2023
A19: Ethiopia | B19: ETH | C19: 3114 | D19: 880 | E19: 189 | F19: 64 | G19: 699 | H19: 2878 | I19: 2440 | J19: 6298 | K19: 1220 | L19: 1613 | M19: 3672 | N19: 23067 | O19: pharmacist from 2018
A20: Gabon | B20: GAB | C20: 46 | D20: 16 | G20: 2 | I20: 34 | J20: 95 | K20: 6 | N20: 199 | O20: NHWA dataset, 2023
A21: Gambia | B21: GMB | C21: 23 | J21: 137 | K21: 6 | N21: 166 | O21: NHWA dataset, 2023
A22: Ghana | B22: GHA | C22: 1566 | G22: 343 | I22: 4827 | J22: 21271 | K22: 396 | N22: 28403 | O22: HLMA 2023; Ismaila (2023)
A23: Guinea | B23: GIN | C23: 767 | D23: 74 | G23: 113 | H23: 34 | I23: 492 | J23: 964 | K23: 27 | M23: 1304 | N23: 3775 | O23: NHWA dataset, 2023
A24: Guinea-Bissau | B24: GNB | K24: 23 | M24: 489 | N24: 512 | O24: NHWA dataset, 2023
A25: Kenya | B25: KEN | C25: 558 | E25: 36 | G25: 379 | H25: 20 | J25: 1070 | K25: 519 | M25: 366 | N25: 2948 | O25: HLMA data, Dentist-2018; CMHW-2022; Biom -2018;
A26: Lesotho | B26: LSO | C26: 8 | D26: 22 | E26: 8 | G26: 33 | H26: 20 | I26: 69 | J26: 376 | K26: 20 | N26: 556 | O26: NHWA dataset, 2023
A27: Liberia | B27: LBR | C27: 29 | D27: 50 | G27: 22 | J27: 63 | K27: 56 | M27: 50 | N27: 270 | O27: NHWA dataset, 2023
A28: Madagascar | B28: MDG | C28: 316 | D28: 156 | I28: 2473 | J28: 2540 | K28: 116 | M28: 297 | N28: 5898 | O28: NHWA dataset, 2023
A29: Malawi | B29: MWI | C29: 115 | D29: 167 | G29: 110 | H29: 189 | I29: 1171 | J29: 386 | K29: 175 | M29: 616 | N29: 2929 | O29: NHWA dataset, 2023
A30: Mali | B30: MLI | N30: 0 | O30: NHWA dataset, 2023
A31: Mauritania | B31: MRT | D31: 76 | J31: 113 | M31: 366 | N31: 555 | O31: NHWA dataset, 2023
A32: Mauritius | B32: MUS | C32: 432 | I32: 40 | J32: 175 | M32: 39 | N32: 686 | O32: SADC dataset, 2022
A33: Mozambique | B33: MOZ | C33: 819 | D33: 146 | E33: 161 | H33: 112 | I33: 140 | J33: 580 | K33: 248 | L33: 20 | N33: 2226 | O33: capacity-HLMA data extracted
A34: Namibia | B34: NAM | C34: 475 | D34: 3 | G34: 247 | H34: 31 | I34: 1414 | J34: 200 | K34: 121 | M34: 175 | N34: 2666 | O34: NHWA dataset, 2023; HLMA dataset, 2019; 2018 survey dataset
A35: Niger | B35: NER | C35: 370 | D35: 14 | I35: 124 | J35: 305 | K35: 45 | M35: 1891 | N35: 2749 | O35: Med-2021,2022; Nurs-2022; Midw-2022; Other-2021,2022, CHW-2021
A36: Nigeria | B36: NGA | C36: 4340 | E36: 459 | I36: 375 | J36: 12835 | K36: 1774 | N36: 19783 | O36: NHWA dataset, 2023
A37: Rwanda | B37: RWA | C37: 11 | G37: 95 | I37: 176 | J37: 355 | M37: 81 | N37: 718 | O37: NHWA dataset, 2023
A38: Sao Tome and Principe | B38: STP | N38: 0 | O38: NHWA dataset, 2023
A39: Senegal | B39: SEN | C39: 434 | D39: 137 | E39: 67 | G39: 171 | I39: 104 | J39: 582 | K39: 36 | M39: 710 | N39: 2241 | O39: NHWA dataset, 2023
A40: Seychelles | B40: SYC | C40: 10 | H40: 20 | I40: 10 | J40: 40 | M40: 80 | N40: 160 | O40: NHWA dataset, 2023
...
