Workbook

Sheet Results
A1: Region | B1: ='Processed HWF'!A1 -> Country | C1: ='Processed HWF'!M1 -> Health workforce density per 10,000 population (includes medical doctors, nursing personnel, and midwifery personnel) in 2020 | D1: ='Processed HWF'!N1 -> UHC service coverage index 2019 | E1: Vulnerable | H1: Median density | K1: List of vulnerable countries | O1: Change since SSL 2020 list based on UHC 2017 and 2018 HWF | V1: Countries not in SSL but with major challenges | W1: ='Processed HWF'!I1 -> Shortage2020 | X1: Shortage as % of HWF (sdg3.c) | Y1: ='Processed HWF'!O1 -> % population vaccinated | Z1: ='Processed HWF'!P1 -> % redeployment required | AA1: UHC SCI 2019 | AB1: Potentially vulnerable | AE1: Criteria | AF1: Shortage minimum | AG1: 0 | AI1: Countries not in SSL but with major challenges | AJ1: UHC | AK1: HWF | AL1: Shortage in 2020 | AM1: Shortage as % of SDG 3.c | AN1: % population vaccinated (1st Jan 2022) | AO1: % of domestic resources required to achieve 70% Covid-19 vaccination by mid 2022
A2: =VLOOKUP(B2,'Reference table'!A$2:D$195,4,FALSE) -> EMR | B2: ='Processed HWF'!A2 -> Afghanistan | C2: ='Processed HWF'!M2 -> 6.9971038 | D2: ='Processed HWF'!N2 -> 37.33 | E2: =IF(AND(C2<H$4,Results!D2<50),1,0) -> 1 | F2: =IF(AND(A2="AFR",E2=1),1,0) -> 0 | G2: =SUM(E2:E195) -> 42 | H2: ='Processed HWF'!M$199 -> 52.977556 | K2: Afghanistan | O2: Out: | V2: ='Processed HWF'!A2 -> Afghanistan | W2: ='Processed HWF'!I2 -> 240155.88 | X2: ='Processed HWF'!K2 -> 7.7160229 | Y2: ='Processed HWF'!O2 -> 0.098226264 | Z2: ='Processed HWF'!P2 -> 0.29471777 | AA2: ='Processed HWF'!N2 -> 37.33 | AB2: =IF(AND(E2=0,W2>$AG$1,Y2<>0,Y2<$AG$2,Z2>$AG$3,AA2<$AG$5,X2>$AG$4),1,0) -> 0 | AD2: =SUM(AB2:AB195) -> 7 | AF2: % population vaccinated min | AG2: 0.25 | AI2: Kenya | AJ2: =VLOOKUP(AI2,$B$2:$D$195,3,FALSE) -> 55.95 | AK2: =VLOOKUP(AI2,$B$2:$D$195,2,FALSE) -> 13.218482 | AL2: =VLOOKUP(AI2,$V$2:$Z$195,2,FALSE) -> 262302.56 | AM2: =VLOOKUP(AI2,$V$2:$Z$195,3,FALSE) -> 3.5728785 | AN2: =VLOOKUP(AI2,$V$2:$Z$195,4,FALSE) -> 0.08524695 | AO2: =VLOOKUP(AI2,$V$2:$Z$195,5,FALSE) -> 0.15836786
A3: =VLOOKUP(B3,'Reference table'!A$2:D$195,4,FALSE) -> AFR | B3: ='Processed HWF'!A3 -> Angola | C3: ='Processed HWF'!M3 -> 6.2165585 | D3: ='Processed HWF'!N3 -> 38.69 | E3: =IF(AND(C3<H$4,Results!D3<50),1,0) -> 1 | F3: =IF(AND(A3="AFR",E3=1),1,0) -> 1 | G3: =SUM(F2:F195) -> 33 | H3: Median density reference | K3: Angola | O3: Bangladesh UHC was 48 now 51; HWF 10-> 12 | V3: ='Processed HWF'!A3 -> Angola | W3: ='Processed HWF'!I3 -> 189665.45 | X3: ='Processed HWF'!K3 -> 7.6940981 | Y3: ='Processed HWF'!O3 -> 0.1311034 | Z3: ='Processed HWF'!P3 -> 0.35992833 | AA3: ='Processed HWF'!N3 -> 38.69 | AB3: =IF(AND(E3=0,W3>$AG$1,Y3<>0,Y3<$AG$2,Z3>$AG$3,AA3<$AG$5,X3>$AG$4),1,0) -> 0 | AF3: % redployment max | AG3: 0.05 | AI3: Namibia | AJ3: =VLOOKUP(AI3,$B$2:$D$195,3,FALSE) -> 61.57 | AK3: =VLOOKUP(AI3,$B$2:$D$195,2,FALSE) -> 29.7409 | AL3: =VLOOKUP(AI3,$V$2:$Z$195,2,FALSE) -> 7075.5986 | AM3: =VLOOKUP(AI3,$V$2:$Z$195,3,FALSE) -> 0.84613759 | AN3: =VLOOKUP(AI3,$V$2:$Z$195,4,FALSE) -> 0.13538719 | AO3: =VLOOKUP(AI3,$V$2:$Z$195,5,FALSE) -> 0.059537573
A4: =VLOOKUP(B4,'Reference table'!A$2:D$195,4,FALSE) -> EUR | B4: ='Processed HWF'!A4 -> Albania | C4: ='Processed HWF'!M4 -> 79.213288 | D4: ='Processed HWF'!N4 -> 62.16 | E4: =IF(AND(C4<H$4,Results!D4<50),1,0) -> 0 | F4: =IF(AND(A4="AFR",E4=1),1,0) -> 0 | H4: 48.567162 | K4: Benin | O4: Kiribati UHC was 41 now 51; HWF 40 -> 40 | V4: ='Processed HWF'!A4 -> Albania | W4: ='Processed HWF'!I4 -> 0 | X4: ='Processed HWF'!K4 -> 0 | Y4: ='Processed HWF'!O4 -> 0.36799569 | Z4: ='Processed HWF'!P4 -> 0.012851644 | AA4: ='Processed HWF'!N4 -> 62.16 | AB4: =IF(AND(E4=0,W4>$AG$1,Y4<>0,Y4<$AG$2,Z4>$AG$3,AA4<$AG$5,X4>$AG$4),1,0) -> 0 | AF4: % shortage | AG4: 0.4 | AI4: Syrian Arab Republic | AJ4: =VLOOKUP(AI4,$B$2:$D$195,3,FALSE) -> 55.61 | AK4: =VLOOKUP(AI4,$B$2:$D$195,2,FALSE) -> 28.224572 | AL4: =VLOOKUP(AI4,$V$2:$Z$195,2,FALSE) -> 38845.852 | AM4: =VLOOKUP(AI4,$V$2:$Z$195,3,FALSE) -> 0.48230534 | AN4: =VLOOKUP(AI4,$V$2:$Z$195,4,FALSE) -> 0.050482559 | AO4: =VLOOKUP(AI4,$V$2:$Z$195,5,FALSE) -> 0.053786557
A5: =VLOOKUP(B5,'Reference table'!A$2:D$195,4,FALSE) -> EUR | B5: ='Processed HWF'!A5 -> Andorra | C5: ='Processed HWF'!M5 -> 73.468135 | D5: ='Processed HWF'!N5 -> 77.16 | E5: =IF(AND(C5<H$4,Results!D5<50),1,0) -> 0 | F5: =IF(AND(A5="AFR",E5=1),1,0) -> 0 | K5: Burkina Faso | O5: Nepal UHC was 48 now 53; HWF 41 -> 42 | V5: ='Processed HWF'!A5 -> Andorra | W5: ='Processed HWF'!I5 -> 15.1016 | X5: ='Processed HWF'!K5 -> 0.021290347 | Y5: ='Processed HWF'!O5 -> 0.66513946 | Z5: ='Processed HWF'!P5 -> 0 | AA5: ='Processed HWF'!N5 -> 77.16 | AB5: =IF(AND(E5=0,W5>$AG$1,Y5<>0,Y5<$AG$2,Z5>$AG$3,AA5<$AG$5,X5>$AG$4),1,0) -> 0 | AF5: UHC SCI max (90% median) | AG5: =0.9*69 -> 62.1 | AI5: Uganda | AJ5: =VLOOKUP(AI5,$B$2:$D$195,3,FALSE) -> 50.45 | AK5: =VLOOKUP(AI5,$B$2:$D$195,2,FALSE) -> 17.9221 | AL5: =VLOOKUP(AI5,$V$2:$Z$195,2,FALSE) -> 225795.94 | AM5: =VLOOKUP(AI5,$V$2:$Z$195,3,FALSE) -> 2.6896075 | AN5: =VLOOKUP(AI5,$V$2:$Z$195,4,FALSE) -> 0.039562465 | AO5: =VLOOKUP(AI5,$V$2:$Z$195,5,FALSE) -> 0.090918541
A6: =VLOOKUP(B6,'Reference table'!A$2:D$195,4,FALSE) -> EMR | B6: ='Processed HWF'!A6 -> United Arab Emirates | C6: ='Processed HWF'!M6 -> 88.652949 | D6: ='Processed HWF'!N6 -> 77.83 | E6: =IF(AND(C6<H$4,Results!D6<50),1,0) -> 0 | F6: =IF(AND(A6="AFR",E6=1),1,0) -> 0 | K6: Burundi | O6: Solomon islands UHC was 47 now 50; HWF 24 -> 24 | V6: ='Processed HWF'!A6 -> United Arab Emirates | W6: ='Processed HWF'!I6 -> 0 | X6: ='Processed HWF'!K6 -> 0 | Y6: ='Processed HWF'!O6 -> 0 | Z6: ='Processed HWF'!P6 -> 0 | AA6: ='Processed HWF'!N6 -> 77.83 | AB6: =IF(AND(E6=0,W6>$AG$1,Y6<>0,Y6<$AG$2,Z6>$AG$3,AA6<$AG$5,X6>$AG$4),1,0) -> 0 | AI6: Vanuatu | AJ6: =VLOOKUP(AI6,$B$2:$D$195,3,FALSE) -> 52.24 | AK6: =VLOOKUP(AI6,$B$2:$D$195,2,FALSE) -> 15.858326 | AL6: =VLOOKUP(AI6,$V$2:$Z$195,2,FALSE) -> 1323.2557 | AM6: =VLOOKUP(AI6,$V$2:$Z$195,3,FALSE) -> 2.4873321 | AN6: =VLOOKUP(AI6,$V$2:$Z$195,4,FALSE) -> 0.16410165 | AO6: =VLOOKUP(AI6,$V$2:$Z$195,5,FALSE) -> 0.087772989
A7: =VLOOKUP(B7,'Reference table'!A$2:D$195,4,FALSE) -> AMR | B7: ='Processed HWF'!A7 -> Argentina | C7: ='Processed HWF'!M7 -> 66.609812 | D7: ='Processed HWF'!N7 -> 73.41 | E7: =IF(AND(C7<H$4,Results!D7<50),1,0) -> 0 | F7: =IF(AND(A7="AFR",E7=1),1,0) -> 0 | K7: Cameroon | O7: Uganda UHC was 45 now 50; HWF 14 ->18 | V7: ='Processed HWF'!A7 -> Argentina | W7: ='Processed HWF'!I7 -> 28093.49 | X7: ='Processed HWF'!K7 -> 0.071439177 | Y7: ='Processed HWF'!O7 -> 0.73420592 | Z7: ='Processed HWF'!P7 -> 0 | AA7: ='Processed HWF'!N7 -> 73.41 | AB7: =IF(AND(E7=0,W7>$AG$1,Y7<>0,Y7<$AG$2,Z7>$AG$3,AA7<$AG$5,X7>$AG$4),1,0) -> 0 | AI7: Zambia | AJ7: =VLOOKUP(AI7,$B$2:$D$195,3,FALSE) -> 54.59 | AK7: =VLOOKUP(AI7,$B$2:$D$195,2,FALSE) -> 11.362644 | AL7: =VLOOKUP(AI7,$V$2:$Z$195,2,FALSE) -> 102644.66 | AM7: =VLOOKUP(AI7,$V$2:$Z$195,3,FALSE) -> 4.4292362 | AN7: =VLOOKUP(AI7,$V$2:$Z$195,4,FALSE) -> 0.035463805 | AO7: =VLOOKUP(AI7,$V$2:$Z$195,5,FALSE) -> 0.075162517
A8: =VLOOKUP(B8,'Reference table'!A$2:D$195,4,FALSE) -> EUR | B8: ='Processed HWF'!A8 -> Armenia | C8: ='Processed HWF'!M8 -> 93.389283 | D8: ='Processed HWF'!N8 -> 69.26 | E8: =IF(AND(C8<H$4,Results!D8<50),1,0) -> 0 | F8: =IF(AND(A8="AFR",E8=1),1,0) -> 0 | K8: Central African Republic | O8: Vanuatu UHC was 48 now 52; HWF 16 -> 16 | V8: ='Processed HWF'!A8 -> Armenia | W8: ='Processed HWF'!I8 -> 516.68658 | X8: ='Processed HWF'!K8 -> 0.01753464 | Y8: ='Processed HWF'!O8 -> 0.23971377 | Z8: ='Processed HWF'!P8 -> 0.019861468 | AA8: ='Processed HWF'!N8 -> 69.26 | AB8: =IF(AND(E8=0,W8>$AG$1,Y8<>0,Y8<$AG$2,Z8>$AG$3,AA8<$AG$5,X8>$AG$4),1,0) -> 0 | AI8: Zimbabwe | AJ8: =VLOOKUP(AI8,$B$2:$D$195,3,FALSE) -> 54.77 | AK8: =VLOOKUP(AI8,$B$2:$D$195,2,FALSE) -> 23.321477 | AL8: =VLOOKUP(AI8,$V$2:$Z$195,2,FALSE) -> 62603.586 | AM8: =VLOOKUP(AI8,$V$2:$Z$195,3,FALSE) -> 1.7155442 | AN8: =VLOOKUP(AI8,$V$2:$Z$195,4,FALSE) -> 0.21057922 | AO8: =VLOOKUP(AI8,$V$2:$Z$195,5,FALSE) -> 0.083665705
A9: =VLOOKUP(B9,'Reference table'!A$2:D$195,4,FALSE) -> AMR | B9: ='Processed HWF'!A9 -> Antigua and Barbuda | C9: ='Processed HWF'!M9 -> 118.48587 | D9: ='Processed HWF'!N9 -> 72.33 | E9: =IF(AND(C9<H$4,Results!D9<50),1,0) -> 0 | F9: =IF(AND(A9="AFR",E9=1),1,0) -> 0 | K9: Chad | V9: ='Processed HWF'!A9 -> Antigua and Barbuda | W9: ='Processed HWF'!I9 -> 17.632698 | X9: ='Processed HWF'!K9 -> 0.014917258 | Y9: ='Processed HWF'!O9 -> 0.60302872 | Z9: ='Processed HWF'!P9 -> 0.0065069573 | AA9: ='Processed HWF'!N9 -> 72.33 | AB9: =IF(AND(E9=0,W9>$AG$1,Y9<>0,Y9<$AG$2,Z9>$AG$3,AA9<$AG$5,X9>$AG$4),1,0) -> 0
A10: =VLOOKUP(B10,'Reference table'!A$2:D$195,4,FALSE) -> WPR | B10: ='Processed HWF'!A10 -> Australia | C10: ='Processed HWF'!M10 -> 172.69653 | D10: ='Processed HWF'!N10 -> 87.15 | E10: =IF(AND(C10<H$4,Results!D10<50),1,0) -> 0 | F10: =IF(AND(A10="AFR",E10=1),1,0) -> 0 | K10: Comoros | O10: In: | V10: ='Processed HWF'!A10 -> Australia | W10: ='Processed HWF'!I10 -> 0 | X10: ='Processed HWF'!K10 -> 0 | Y10: ='Processed HWF'!O10 -> 0.78025277 | Z10: ='Processed HWF'!P10 -> 0 | AA10: ='Processed HWF'!N10 -> 87.15 | AB10: =IF(AND(E10=0,W10>$AG$1,Y10<>0,Y10<$AG$2,Z10>$AG$3,AA10<$AG$5,X10>$AG$4),1,0) -> 0
A11: =VLOOKUP(B11,'Reference table'!A$2:D$195,4,FALSE) -> EUR | B11: ='Processed HWF'!A11 -> Austria | C11: ='Processed HWF'!M11 -> 158.57124 | D11: ='Processed HWF'!N11 -> 82.26 | E11: =IF(AND(C11<H$4,Results!D11<50),1,0) -> 0 | F11: =IF(AND(A11="AFR",E11=1),1,0) -> 0 | K11: Congo | O11: Comoros UHC was 52 now 44; HWF 23 -> 17 | V11: ='Processed HWF'!A11 -> Austria | W11: ='Processed HWF'!I11 -> 1120.1978 | X11: ='Processed HWF'!K11 -> 0.0072500218 | Y11: ='Processed HWF'!O11 -> 0.67008 | Z11: ='Processed HWF'!P11 -> 0 | AA11: ='Processed HWF'!N11 -> 82.26 | AB11: =IF(AND(E11=0,W11>$AG$1,Y11<>0,Y11<$AG$2,Z11>$AG$3,AA11<$AG$5,X11>$AG$4),1,0) -> 0
A12: =VLOOKUP(B12,'Reference table'!A$2:D$195,4,FALSE) -> EUR | B12: ='Processed HWF'!A12 -> Azerbaijan | C12: ='Processed HWF'!M12 -> 96.166758 | D12: ='Processed HWF'!N12 -> 65.28 | E12: =IF(AND(C12<H$4,Results!D12<50),1,0) -> 0 | F12: =IF(AND(A12="AFR",E12=1),1,0) -> 0 | K12: Cote d'Ivoire | V12: ='Processed HWF'!A12 -> Azerbaijan | W12: ='Processed HWF'!I12 -> 0 | X12: ='Processed HWF'!K12 -> 0 | Y12: ='Processed HWF'!O12 -> 0.44639865 | Z12: ='Processed HWF'!P12 -> 0.0083271478 | AA12: ='Processed HWF'!N12 -> 65.28 | AB12: =IF(AND(E12=0,W12>$AG$1,Y12<>0,Y12<$AG$2,Z12>$AG$3,AA12<$AG$5,X12>$AG$4),1,0) -> 0 | AI12: Countries not in SSL but with major challenges | AJ12: Potentially vulnerable
A13: =VLOOKUP(B13,'Reference table'!A$2:D$195,4,FALSE) -> AFR | B13: ='Processed HWF'!A13 -> Burundi | C13: ='Processed HWF'!M13 -> 7.197479 | D13: ='Processed HWF'!N13 -> 44.37 | E13: =IF(AND(C13<H$4,Results!D13<50),1,0) -> 1 | F13: =IF(AND(A13="AFR",E13=1),1,0) -> 1 | K13: Democratic Republic of the Congo | V13: ='Processed HWF'!A13 -> Burundi | W13: ='Processed HWF'!I13 -> 68919.078 | X13: ='Processed HWF'!K13 -> 7.9221248 | Y13: ='Processed HWF'!O13 -> 0.00050593804 | Z13: ='Processed HWF'!P13 -> 0.31022862 | AA13: ='Processed HWF'!N13 -> 44.37 | AB13: =IF(AND(E13=0,W13>$AG$1,Y13<>0,Y13<$AG$2,Z13>$AG$3,AA13<$AG$5,X13>$AG$4),1,0) -> 0 | AI13: Kenya | AJ13: 1
A14: =VLOOKUP(B14,'Reference table'!A$2:D$195,4,FALSE) -> EUR | B14: ='Processed HWF'!A14 -> Belgium | C14: ='Processed HWF'!M14 -> 261.39051 | D14: ='Processed HWF'!N14 -> 85.5 | E14: =IF(AND(C14<H$4,Results!D14<50),1,0) -> 0 | F14: =IF(AND(A14="AFR",E14=1),1,0) -> 0 | K14: Djibouti | V14: ='Processed HWF'!A14 -> Belgium | W14: ='Processed HWF'!I14 -> 0 | X14: ='Processed HWF'!K14 -> 0 | Y14: ='Processed HWF'!O14 -> 0.72816634 | Z14: ='Processed HWF'!P14 -> 0 | AA14: ='Processed HWF'!N14 -> 85.5 | AB14: =IF(AND(E14=0,W14>$AG$1,Y14<>0,Y14<$AG$2,Z14>$AG$3,AA14<$AG$5,X14>$AG$4),1,0) -> 0 | AI14: Namibia | AJ14: 1
A15: =VLOOKUP(B15,'Reference table'!A$2:D$195,4,FALSE) -> AFR | B15: ='Processed HWF'!A15 -> Benin | C15: ='Processed HWF'!M15 -> 3.6762711 | D15: ='Processed HWF'!N15 -> 38.2 | E15: =IF(AND(C15<H$4,Results!D15<50),1,0) -> 1 | F15: =IF(AND(A15="AFR",E15=1),1,0) -> 1 | K15: Equatorial Guinea | V15: ='Processed HWF'!A15 -> Benin | W15: ='Processed HWF'!I15 -> 82634.516 | X15: ='Processed HWF'!K15 -> 17.244085 | Y15: ='Processed HWF'!O15 -> 0.11724974 | Z15: ='Processed HWF'!P15 -> 0.58968532 | AA15: ='Processed HWF'!N15 -> 38.2 | AB15: =IF(AND(E15=0,W15>$AG$1,Y15<>0,Y15<$AG$2,Z15>$AG$3,AA15<$AG$5,X15>$AG$4),1,0) -> 0 | AI15: Uganda | AJ15: 1
A16: =VLOOKUP(B16,'Reference table'!A$2:D$195,4,FALSE) -> AFR | B16: ='Processed HWF'!A16 -> Burkina Faso | C16: ='Processed HWF'!M16 -> 9.8023334 | D16: ='Processed HWF'!N16 -> 43.19 | E16: =IF(AND(C16<H$4,Results!D16<50),1,0) -> 1 | F16: =IF(AND(A16="AFR",E16=1),1,0) -> 1 | K16: Eritrea | V16: ='Processed HWF'!A16 -> Burkina Faso | W16: ='Processed HWF'!I16 -> 124517.12 | X16: ='Processed HWF'!K16 -> 5.9674844 | Y16: ='Processed HWF'!O16 -> 0.036926992 | Z16: ='Processed HWF'!P16 -> 0.24684572 | AA16: ='Processed HWF'!N16 -> 43.19 | AB16: =IF(AND(E16=0,W16>$AG$1,Y16<>0,Y16<$AG$2,Z16>$AG$3,AA16<$AG$5,X16>$AG$4),1,0) -> 0 | AI16: Vanuatu | AJ16: 1
A17: =VLOOKUP(B17,'Reference table'!A$2:D$195,4,FALSE) -> SEAR | B17: ='Processed HWF'!A17 -> Bangladesh | C17: ='Processed HWF'!M17 -> 11.541212 | D17: ='Processed HWF'!N17 -> 50.74 | E17: =IF(AND(C17<H$4,Results!D17<50),1,0) -> 0 | F17: =IF(AND(A17="AFR",E17=1),1,0) -> 0 | K17: Ethiopia | V17: ='Processed HWF'!A17 -> Bangladesh | W17: ='Processed HWF'!I17 -> 912042.12 | X17: ='Processed HWF'!K17 -> 3.9456265 | Y17: ='Processed HWF'!O17 -> 0.32535576 | Z17: ='Processed HWF'!P17 -> 0.083567523 | AA17: ='Processed HWF'!N17 -> 50.74 | AB17: =IF(AND(E17=0,W17>$AG$1,Y17<>0,Y17<$AG$2,Z17>$AG$3,AA17<$AG$5,X17>$AG$4),1,0) -> 0 | AI17: Zambia | AJ17: 1
A18: =VLOOKUP(B18,'Reference table'!A$2:D$195,4,FALSE) -> EUR | B18: ='Processed HWF'!A18 -> Bulgaria | C18: ='Processed HWF'!M18 -> 89.924145 | D18: ='Processed HWF'!N18 -> 69.87 | E18: =IF(AND(C18<H$4,Results!D18<50),1,0) -> 0 | F18: =IF(AND(A18="AFR",E18=1),1,0) -> 0 | K18: Gabon | V18: ='Processed HWF'!A18 -> Bulgaria | W18: ='Processed HWF'!I18 -> 0 | X18: ='Processed HWF'!K18 -> 0 | Y18: ='Processed HWF'!O18 -> 0.21231444 | Z18: ='Processed HWF'!P18 -> 0.019478347 | AA18: ='Processed HWF'!N18 -> 69.87 | AB18: =IF(AND(E18=0,W18>$AG$1,Y18<>0,Y18<$AG$2,Z18>$AG$3,AA18<$AG$5,X18>$AG$4),1,0) -> 0 | AI18: Zimbabwe | AJ18: 1
A19: =VLOOKUP(B19,'Reference table'!A$2:D$195,4,FALSE) -> EMR | B19: ='Processed HWF'!A19 -> Bahrain | C19: ='Processed HWF'!M19 -> 39.38341 | D19: ='Processed HWF'!N19 -> 71.44 | E19: =IF(AND(C19<H$4,Results!D19<50),1,0) -> 0 | F19: =IF(AND(A19="AFR",E19=1),1,0) -> 0 | K19: Gambia | V19: ='Processed HWF'!A19 -> Bahrain | W19: ='Processed HWF'!I19 -> 2573.8413 | X19: ='Processed HWF'!K19 -> 0.36033328 | Y19: ='Processed HWF'!O19 -> 0.69681619 | Z19: ='Processed HWF'!P19 -> 0 | AA19: ='Processed HWF'!N19 -> 71.44 | AB19: =IF(AND(E19=0,W19>$AG$1,Y19<>0,Y19<$AG$2,Z19>$AG$3,AA19<$AG$5,X19>$AG$4),1,0) -> 0
A20: =VLOOKUP(B20,'Reference table'!A$2:D$195,4,FALSE) -> AMR | B20: ='Processed HWF'!A20 -> Bahamas | C20: ='Processed HWF'!M20 -> 70.230904 | D20: ='Processed HWF'!N20 -> 69.81 | E20: =IF(AND(C20<H$4,Results!D20<50),1,0) -> 0 | F20: =IF(AND(A20="AFR",E20=1),1,0) -> 0 | K20: Ghana | V20: ='Processed HWF'!A20 -> Bahamas | W20: ='Processed HWF'!I20 -> 0 | X20: ='Processed HWF'!K20 -> 0 | Y20: ='Processed HWF'!O20 -> 0.37989899 | Z20: ='Processed HWF'!P20 -> 0.017187225 | AA20: ='Processed HWF'!N20 -> 69.81 | AB20: =IF(AND(E20=0,W20>$AG$1,Y20<>0,Y20<$AG$2,Z20>$AG$3,AA20<$AG$5,X20>$AG$4),1,0) -> 0
A21: =VLOOKUP(B21,'Reference table'!A$2:D$195,4,FALSE) -> EUR | B21: ='Processed HWF'!A21 -> Bosnia and Herzegovina | C21: ='Processed HWF'!M21 -> 78.949018 | D21: ='Processed HWF'!N21 -> 64.61 | E21: =IF(AND(C21<H$4,Results!D21<50),1,0) -> 0 | F21: =IF(AND(A21="AFR",E21=1),1,0) -> 0 | K21: Guinea | V21: ='Processed HWF'!A21 -> Bosnia and Herzegovina | W21: ='Processed HWF'!I21 -> 257.37537 | X21: ='Processed HWF'!K21 -> 0.0094927248 | Y21: ='Processed HWF'!O21 -> 0.21965 | Z21: ='Processed HWF'!P21 -> 0.015805507 | AA21: ='Processed HWF'!N21 -> 64.61 | AB21: =IF(AND(E21=0,W21>$AG$1,Y21<>0,Y21<$AG$2,Z21>$AG$3,AA21<$AG$5,X21>$AG$4),1,0) -> 0
A22: =VLOOKUP(B22,'Reference table'!A$2:D$195,4,FALSE) -> EUR | B22: ='Processed HWF'!A22 -> Belarus | C22: ='Processed HWF'!M22 -> 155.40892 | D22: ='Processed HWF'!N22 -> 73.54 | E22: =IF(AND(C22<H$4,Results!D22<50),1,0) -> 0 | F22: =IF(AND(A22="AFR",E22=1),1,0) -> 0 | K22: Guinea-Bissau | V22: ='Processed HWF'!A22 -> Belarus | W22: ='Processed HWF'!I22 -> 0 | X22: ='Processed HWF'!K22 -> 0 | Y22: ='Processed HWF'!O22 -> 0.37786006 | Z22: ='Processed HWF'!P22 -> 0.0077025405 | AA22: ='Processed HWF'!N22 -> 73.54 | AB22: =IF(AND(E22=0,W22>$AG$1,Y22<>0,Y22<$AG$2,Z22>$AG$3,AA22<$AG$5,X22>$AG$4),1,0) -> 0
A23: =VLOOKUP(B23,'Reference table'!A$2:D$195,4,FALSE) -> AMR | B23: ='Processed HWF'!A23 -> Belize | C23: ='Processed HWF'!M23 -> 34.197316 | D23: ='Processed HWF'!N23 -> 67.17 | E23: =IF(AND(C23<H$4,Results!D23<50),1,0) -> 0 | F23: =IF(AND(A23="AFR",E23=1),1,0) -> 0 | K23: Haiti | V23: ='Processed HWF'!A23 -> Belize | W23: ='Processed HWF'!I23 -> 497.78339 | X23: ='Processed HWF'!K23 -> 0.29567327 | Y23: ='Processed HWF'!O23 -> 0.50362148 | Z23: ='Processed HWF'!P23 -> 0.0074955077 | AA23: ='Processed HWF'!N23 -> 67.17 | AB23: =IF(AND(E23=0,W23>$AG$1,Y23<>0,Y23<$AG$2,Z23>$AG$3,AA23<$AG$5,X23>$AG$4),1,0) -> 0
A24: =VLOOKUP(B24,'Reference table'!A$2:D$195,4,FALSE) -> AMR | B24: ='Processed HWF'!A24 -> Bolivia | C24: ='Processed HWF'!M24 -> 25.872321 | D24: ='Processed HWF'!N24 -> 66.75 | E24: =IF(AND(C24<H$4,Results!D24<50),1,0) -> 0 | F24: =IF(AND(A24="AFR",E24=1),1,0) -> 0 | K24: Lesotho | V24: ='Processed HWF'!A24 -> Bolivia | W24: ='Processed HWF'!I24 -> 26573.619 | X24: ='Processed HWF'!K24 -> 0.76080207 | Y24: ='Processed HWF'!O24 -> 0.40640268 | Z24: ='Processed HWF'!P24 -> 0.0061753037 | AA24: ='Processed HWF'!N24 -> 66.75 | AB24: =IF(AND(E24=0,W24>$AG$1,Y24<>0,Y24<$AG$2,Z24>$AG$3,AA24<$AG$5,X24>$AG$4),1,0) -> 0
A25: =VLOOKUP(B25,'Reference table'!A$2:D$195,4,FALSE) -> AMR | B25: ='Processed HWF'!A25 -> Brazil | C25: ='Processed HWF'!M25 -> 97.13739 | D25: ='Processed HWF'!N25 -> 75.03 | E25: =IF(AND(C25<H$4,Results!D25<50),1,0) -> 0 | F25: =IF(AND(A25="AFR",E25=1),1,0) -> 0 | K25: Liberia | V25: ='Processed HWF'!A25 -> Brazil | W25: ='Processed HWF'!I25 -> 0 | X25: ='Processed HWF'!K25 -> 0 | Y25: ='Processed HWF'!O25 -> 0.67275307 | Z25: ='Processed HWF'!P25 -> 0 | AA25: ='Processed HWF'!N25 -> 75.03 | AB25: =IF(AND(E25=0,W25>$AG$1,Y25<>0,Y25<$AG$2,Z25>$AG$3,AA25<$AG$5,X25>$AG$4),1,0) -> 0
A26: =VLOOKUP(B26,'Reference table'!A$2:D$195,4,FALSE) -> AMR | B26: ='Processed HWF'!A26 -> Barbados | C26: ='Processed HWF'!M26 -> 60.557792 | D26: ='Processed HWF'!N26 -> 74.46 | E26: =IF(AND(C26<H$4,Results!D26<50),1,0) -> 0 | F26: =IF(AND(A26="AFR",E26=1),1,0) -> 0 | K26: Madagascar | V26: ='Processed HWF'!A26 -> Barbados | W26: ='Processed HWF'!I26 -> 11.458291 | X26: ='Processed HWF'!K26 -> 0.0054832915 | Y26: ='Processed HWF'!O26 -> 0.50062462 | Z26: ='Processed HWF'!P26 -> 0.014246772 | AA26: ='Processed HWF'!N26 -> 74.46 | AB26: =IF(AND(E26=0,W26>$AG$1,Y26<>0,Y26<$AG$2,Z26>$AG$3,AA26<$AG$5,X26>$AG$4),1,0) -> 0
A27: =VLOOKUP(B27,'Reference table'!A$2:D$195,4,FALSE) -> WPR | B27: ='Processed HWF'!A27 -> Brunei Darussalam | C27: ='Processed HWF'!M27 -> 75.070095 | D27: ='Processed HWF'!N27 -> 76.81 | E27: =IF(AND(C27<H$4,Results!D27<50),1,0) -> 0 | F27: =IF(AND(A27="AFR",E27=1),1,0) -> 0 | K27: Malawi | V27: ='Processed HWF'!A27 -> Brunei Darussalam | W27: ='Processed HWF'!I27 -> 13.204123 | X27: ='Processed HWF'!K27 -> 0.0038051324 | Y27: ='Processed HWF'!O27 -> 0.91834579 | Z27: ='Processed HWF'!P27 -> 0 | AA27: ='Processed HWF'!N27 -> 76.81 | AB27: =IF(AND(E27=0,W27>$AG$1,Y27<>0,Y27<$AG$2,Z27>$AG$3,AA27<$AG$5,X27>$AG$4),1,0) -> 0
A28: =VLOOKUP(B28,'Reference table'!A$2:D$195,4,FALSE) -> SEAR | B28: ='Processed HWF'!A28 -> Bhutan | C28: ='Processed HWF'!M28 -> 25.764245 | D28: ='Processed HWF'!N28 -> 62.39 | E28: =IF(AND(C28<H$4,Results!D28<50),1,0) -> 0 | F28: =IF(AND(A28="AFR",E28=1),1,0) -> 0 | K28: Mali | V28: ='Processed HWF'!A28 -> Bhutan | W28: ='Processed HWF'!I28 -> 2299.6069 | X28: ='Processed HWF'!K28 -> 1.0898667 | Y28: ='Processed HWF'!O28 -> 0.73609527 | Z28: ='Processed HWF'!P28 -> 0 | AA28: ='Processed HWF'!N28 -> 62.39 | AB28: =IF(AND(E28=0,W28>$AG$1,Y28<>0,Y28<$AG$2,Z28>$AG$3,AA28<$AG$5,X28>$AG$4),1,0) -> 0
A29: =VLOOKUP(B29,'Reference table'!A$2:D$195,4,FALSE) -> AFR | B29: ='Processed HWF'!A29 -> Botswana | C29: ='Processed HWF'!M29 -> 58.3523 | D29: ='Processed HWF'!N29 -> 53.66 | E29: =IF(AND(C29<H$4,Results!D29<50),1,0) -> 0 | F29: =IF(AND(A29="AFR",E29=1),1,0) -> 0 | K29: Mauritania | V29: ='Processed HWF'!A29 -> Botswana | W29: ='Processed HWF'!I29 -> 3396.8843 | X29: ='Processed HWF'!K29 -> 0.23579746 | Y29: ='Processed HWF'!O29 -> 0.43968325 | Z29: ='Processed HWF'!P29 -> 0.019312148 | AA29: ='Processed HWF'!N29 -> 53.66 | AB29: =IF(AND(E29=0,W29>$AG$1,Y29<>0,Y29<$AG$2,Z29>$AG$3,AA29<$AG$5,X29>$AG$4),1,0) -> 0
A30: =VLOOKUP(B30,'Reference table'!A$2:D$195,4,FALSE) -> AFR | B30: ='Processed HWF'!A30 -> Central African Republic | C30: ='Processed HWF'!M30 -> 3.2787762 | D30: ='Processed HWF'!N30 -> 32.46 | E30: =IF(AND(C30<H$4,Results!D30<50),1,0) -> 1 | F30: =IF(AND(A30="AFR",E30=1),1,0) -> 1 | K30: Micronesia, Federated States of | V30: ='Processed HWF'!A30 -> Central African Republic | W30: ='Processed HWF'!I30 -> 30721.564 | X30: ='Processed HWF'!K30 -> 18.833914 | Y30: ='Processed HWF'!O30 -> 0.095804829 | Z30: ='Processed HWF'!P30 -> 1.1143202 | AA30: ='Processed HWF'!N30 -> 32.46 | AB30: =IF(AND(E30=0,W30>$AG$1,Y30<>0,Y30<$AG$2,Z30>$AG$3,AA30<$AG$5,X30>$AG$4),1,0) -> 0
... A43: =VLOOKUP(B43,'Reference table'!A$2:D$195,4,FALSE) -> AMR | B43: ='Processed HWF'!A43 -> Costa Rica | C43: ='Processed HWF'!M43 -> 71.021183 | D43: ='Processed HWF'!N43 -> 78.21 | E43: =IF(AND(C43<H$4,Results!D43<50),1,0) -> 0 | F43: =IF(AND(A43="AFR",E43=1),1,0) -> 0 | K43: Yemen | V43: ='Processed HWF'!A43 -> Costa Rica | W43: ='Processed HWF'!I43 -> 0 | X43: ='Processed HWF'!K43 -> 0 | Y43: ='Processed HWF'!O43 -> 0.69617155 | Z43: ='Processed HWF'!P43 -> 0 | AA43: ='Processed HWF'!N43 -> 78.21 | AB43: =IF(AND(E43=0,W43>$AG$1,Y43<>0,Y43<$AG$2,Z43>$AG$3,AA43<$AG$5,X43>$AG$4),1,0) -> 0
A44: =VLOOKUP(B44,'Reference table'!A$2:D$195,4,FALSE) -> AMR | B44: ='Processed HWF'!A44 -> Cuba | C44: ='Processed HWF'!M44 -> 164.65097 | D44: ='Processed HWF'!N44 -> 79.67 | E44: =IF(AND(C44<H$4,Results!D44<50),1,0) -> 0 | F44: =IF(AND(A44="AFR",E44=1),1,0) -> 0 | V44: ='Processed HWF'!A44 -> Cuba | W44: ='Processed HWF'!I44 -> 0 | X44: ='Processed HWF'!K44 -> 0 | Y44: ='Processed HWF'!O44 -> 0.85605595 | Z44: ='Processed HWF'!P44 -> 0 | AA44: ='Processed HWF'!N44 -> 79.67 | AB44: =IF(AND(E44=0,W44>$AG$1,Y44<>0,Y44<$AG$2,Z44>$AG$3,AA44<$AG$5,X44>$AG$4),1,0) -> 0
A45: =VLOOKUP(B45,'Reference table'!A$2:D$195,4,FALSE) -> EUR | B45: ='Processed HWF'!A45 -> Cyprus | C45: ='Processed HWF'!M45 -> 86.745233 | D45: ='Processed HWF'!N45 -> 78.74 | E45: =IF(AND(C45<H$4,Results!D45<50),1,0) -> 0 | F45: =IF(AND(A45="AFR",E45=1),1,0) -> 0 | V45: ='Processed HWF'!A45 -> Cyprus | W45: ='Processed HWF'!I45 -> 147.24223 | X45: ='Processed HWF'!K45 -> 0.012045569 | Y45: ='Processed HWF'!O45 -> 0.69261547 | Z45: ='Processed HWF'!P45 -> 0 | AA45: ='Processed HWF'!N45 -> 78.74 | AB45: =IF(AND(E45=0,W45>$AG$1,Y45<>0,Y45<$AG$2,Z45>$AG$3,AA45<$AG$5,X45>$AG$4),1,0) -> 0
A46: =VLOOKUP(B46,'Reference table'!A$2:D$195,4,FALSE) -> EUR | B46: ='Processed HWF'!A46 -> Czech Republic | C46: ='Processed HWF'!M46 -> 130.81963 | D46: ='Processed HWF'!N46 -> 78.37 | E46: =IF(AND(C46<H$4,Results!D46<50),1,0) -> 0 | F46: =IF(AND(A46="AFR",E46=1),1,0) -> 0 | V46: ='Processed HWF'!A46 -> Czech Republic | W46: ='Processed HWF'!I46 -> 0 | X46: ='Processed HWF'!K46 -> 0 | Y46: ='Processed HWF'!O46 -> 0.58860556 | Z46: ='Processed HWF'!P46 -> 0 | AA46: ='Processed HWF'!N46 -> 78.37 | AB46: =IF(AND(E46=0,W46>$AG$1,Y46<>0,Y46<$AG$2,Z46>$AG$3,AA46<$AG$5,X46>$AG$4),1,0) -> 0
A47: =VLOOKUP(B47,'Reference table'!A$2:D$195,4,FALSE) -> EUR | B47: ='Processed HWF'!A47 -> Germany | C47: ='Processed HWF'!M47 -> 186.2553 | D47: ='Processed HWF'!N47 -> 85.84 | E47: =IF(AND(C47<H$4,Results!D47<50),1,0) -> 0 | F47: =IF(AND(A47="AFR",E47=1),1,0) -> 0 | V47: ='Processed HWF'!A47 -> Germany | W47: ='Processed HWF'!I47 -> 8227.5166 | X47: ='Processed HWF'!K47 -> 0.0048758388 | Y47: ='Processed HWF'!O47 -> 0.67612699 | Z47: ='Processed HWF'!P47 -> 0 | AA47: ='Processed HWF'!N47 -> 85.84 | AB47: =IF(AND(E47=0,W47>$AG$1,Y47<>0,Y47<$AG$2,Z47>$AG$3,AA47<$AG$5,X47>$AG$4),1,0) -> 0
A48: =VLOOKUP(B48,'Reference table'!A$2:D$195,4,FALSE) -> EMR | B48: ='Processed HWF'!A48 -> Djibouti | C48: ='Processed HWF'!M48 -> 9.5247949 | D48: ='Processed HWF'!N48 -> 48.14 | E48: =IF(AND(C48<H$4,Results!D48<50),1,0) -> 1 | F48: =IF(AND(A48="AFR",E48=1),1,0) -> 0 | V48: ='Processed HWF'!A48 -> Djibouti | W48: ='Processed HWF'!I48 -> 5578.7021 | X48: ='Processed HWF'!K48 -> 4.6769704 | Y48: ='Processed HWF'!O48 -> 0.081762146 | Z48: ='Processed HWF'!P48 -> 0.22109117 | AA48: ='Processed HWF'!N48 -> 48.14 | AB48: =IF(AND(E48=0,W48>$AG$1,Y48<>0,Y48<$AG$2,Z48>$AG$3,AA48<$AG$5,X48>$AG$4),1,0) -> 0
A49: =VLOOKUP(B49,'Reference table'!A$2:D$195,4,FALSE) -> AMR | B49: ='Processed HWF'!A49 -> Dominica | C49: ='Processed HWF'!M49 -> 76.341424 | D49: ='Processed HWF'!N49 -> 66.68 | E49: =IF(AND(C49<H$4,Results!D49<50),1,0) -> 0 | F49: =IF(AND(A49="AFR",E49=1),1,0) -> 0 | V49: ='Processed HWF'!A49 -> Dominica | W49: ='Processed HWF'!I49 -> 21.746841 | X49: ='Processed HWF'!K49 -> 0.037739883 | Y49: ='Processed HWF'!O49 -> 0.39624397 | Z49: ='Processed HWF'!P49 -> 0.03530939 | AA49: ='Processed HWF'!N49 -> 66.68 | AB49: =IF(AND(E49=0,W49>$AG$1,Y49<>0,Y49<$AG$2,Z49>$AG$3,AA49<$AG$5,X49>$AG$4),1,0) -> 0
A50: =VLOOKUP(B50,'Reference table'!A$2:D$195,4,FALSE) -> EUR | B50: ='Processed HWF'!A50 -> Denmark | C50: ='Processed HWF'!M50 -> 147.60095 | D50: ='Processed HWF'!N50 -> 84.89 | E50: =IF(AND(C50<H$4,Results!D50<50),1,0) -> 0 | F50: =IF(AND(A50="AFR",E50=1),1,0) -> 0 | K50: Afghanistan | V50: ='Processed HWF'!A50 -> Denmark | W50: ='Processed HWF'!I50 -> 123.87114 | X50: ='Processed HWF'!K50 -> 0.0013342971 | Y50: ='Processed HWF'!O50 -> 0.86542987 | Z50: ='Processed HWF'!P50 -> 0 | AA50: ='Processed HWF'!N50 -> 84.89 | AB50: =IF(AND(E50=0,W50>$AG$1,Y50<>0,Y50<$AG$2,Z50>$AG$3,AA50<$AG$5,X50>$AG$4),1,0) -> 0
A51: =VLOOKUP(B51,'Reference table'!A$2:D$195,4,FALSE) -> AMR | B51: ='Processed HWF'!A51 -> Dominican Republic | C51: ='Processed HWF'!M51 -> 33.517448 | D51: ='Processed HWF'!N51 -> 65.72 | E51: =IF(AND(C51<H$4,Results!D51<50),1,0) -> 0 | F51: =IF(AND(A51="AFR",E51=1),1,0) -> 0 | K51: Angola | V51: ='Processed HWF'!A51 -> Dominican Republic | W51: ='Processed HWF'!I51 -> 23369.627 | X51: ='Processed HWF'!K51 -> 0.58198287 | Y51: ='Processed HWF'!O51 -> 0.52706014 | Z51: ='Processed HWF'!P51 -> 0.0057669407 | AA51: ='Processed HWF'!N51 -> 65.72 | AB51: =IF(AND(E51=0,W51>$AG$1,Y51<>0,Y51<$AG$2,Z51>$AG$3,AA51<$AG$5,X51>$AG$4),1,0) -> 0
A52: =VLOOKUP(B52,'Reference table'!A$2:D$195,4,FALSE) -> AFR | B52: ='Processed HWF'!A52 -> Algeria | C52: ='Processed HWF'!M52 -> 32.692653 | D52: ='Processed HWF'!N52 -> 74.99 | E52: =IF(AND(C52<H$4,Results!D52<50),1,0) -> 0 | F52: =IF(AND(A52="AFR",E52=1),1,0) -> 0 | K52: Burundi | V52: ='Processed HWF'!A52 -> Algeria | W52: ='Processed HWF'!I52 -> 122077.64 | X52: ='Processed HWF'!K52 -> 0.68220963 | Y52: ='Processed HWF'!O52 -> 0.1314246 | Z52: ='Processed HWF'!P52 -> 0.035642571 | AA52: ='Processed HWF'!N52 -> 74.99 | AB52: =IF(AND(E52=0,W52>$AG$1,Y52<>0,Y52<$AG$2,Z52>$AG$3,AA52<$AG$5,X52>$AG$4),1,0) -> 0
...

Sheet Indice
A1: iso_code | B1: Either doc or nurse dependency | C1: Health workforce density per 10,000 population (includes medical doctors, nursing personnel, and midwifery personnel) in 2020 | D1: UHC SCI | E1: Health workforce density per 10,000 population (includes medical doctors, nursing personnel, and midwifery personnel) in 2020 | F1: UHC SCI | K1: ART | Q1: => TOPLAY | R1: iso_code | S1: Either doc or nurse dependency | T1: Health workforce density per 10,000 population (includes medical doctors, nursing personnel, and midwifery personnel) in 2020 | U1: UHC SCI | V1: Health workforce density per 10,000 population (includes medical doctors, nursing personnel, and midwifery personnel) in 2020 | W1: UHC SCI | Z1: iso_code | AA1: Either doc or nurse dependency | AB1: Health workforce density per 10,000 population (includes medical doctors, nursing personnel, and midwifery personnel) in 2020 | AC1: UHC SCI | AD1: Share foreign med cat | AE1: Share foreign nur cat
A2: AFG | B2: 1 | E2: 6.9971038 | F2: 37.33 | G2: =IF(AND(E2<49,F2<60,F2>=50),A2,0) -> 0 | H2: GTM | I2: =VLOOKUP(H2,'Reference table'!$J$2:$K$195,2,FALSE) -> Guatemala | K2: SOM | L2: =TRIM(K2) -> SOM | M2: =VLOOKUP(Indice!L2,'Reference table'!J$2:K$195,2,FALSE) -> Somalia | N2: 1 | R2: AFG | S2: 1 | V2: 6.9971038 | W2: 37.33 | Z2: AFG | AA2: =IF(OR(AD2="Above 0.05",AE2="Above 0.05"),1,0) -> 0 | AB2: 6.9971038 | AC2: 37.33 | AD2: =VLOOKUP(Z2,Migration!$J$3:$R$196,8,FALSE) -> Less than 0.1 | AE2: =VLOOKUP(Z2,Migration!$J$3:$R$196,9,FALSE) -> Less than 0.1
A3: ALB | B3: 1 | E3: 79.213288 | F3: 62.16 | G3: =IF(AND(E3<49,F3<60,F3>=50),A3,0) -> 0 | H3: KEN | I3: =VLOOKUP(H3,'Reference table'!$J$2:$K$195,2,FALSE) -> Kenya | K3: TCD | L3: =TRIM(K3) -> TCD | M3: =VLOOKUP(Indice!L3,'Reference table'!J$2:K$195,2,FALSE) -> Chad | N3: 1 | R3: ALB | S3: 1 | V3: 79.213288 | W3: 62.16 | Z3: AGO | AA3: =IF(OR(AD3="Above 0.05",AE3="Above 0.05"),1,0) -> 0 | AB3: 6.2165585 | AC3: 38.69 | AD3: =VLOOKUP(Z3,Migration!$J$3:$R$196,8,FALSE) -> Less than 0.1 | AE3: =VLOOKUP(Z3,Migration!$J$3:$R$196,9,FALSE) -> Less than 0.1
A4: ARM | B4: 1 | E4: 93.389283 | F4: 69.26 | G4: =IF(AND(E4<49,F4<60,F4>=50),A4,0) -> 0 | H4: LAO | I4: =VLOOKUP(H4,'Reference table'!$J$2:$K$195,2,FALSE) -> Lao People's Democratic Republic | K4: CAF | L4: =TRIM(K4) -> CAF | M4: =VLOOKUP(Indice!L4,'Reference table'!J$2:K$195,2,FALSE) -> Central African Republic | N4: 1 | R4: ARM | S4: 1 | V4: 93.389283 | W4: 69.26 | Z4: ALB | AA4: =IF(OR(AD4="Above 0.05",AE4="Above 0.05"),1,0) -> 0 | AB4: 79.213288 | AC4: 62.16 | AD4: =VLOOKUP(Z4,Migration!$J$3:$R$196,8,FALSE) -> Above 0.1 | AE4: =VLOOKUP(Z4,Migration!$J$3:$R$196,9,FALSE) -> Above 0.1
A5: ATG | B5: 1 | E5: 118.48587 | F5: 72.33 | G5: =IF(AND(E5<49,F5<60,F5>=50),A5,0) -> 0 | H5: SYR | I5: =VLOOKUP(H5,'Reference table'!$J$2:$K$195,2,FALSE) -> Syrian Arab Republic | K5: BEN | L5: =TRIM(K5) -> BEN | M5: =VLOOKUP(Indice!L5,'Reference table'!J$2:K$195,2,FALSE) -> Benin | N5: 1 | R5: ATG | S5: 1 | V5: 118.48587 | W5: 72.33 | Z5: AND | AA5: =IF(OR(AD5="Above 0.05",AE5="Above 0.05"),1,0) -> 0 | AB5: 73.468135 | AC5: 77.16 | AD5: =VLOOKUP(Z5,Migration!$J$3:$R$196,8,FALSE) -> Less than 0.1 | AE5: =VLOOKUP(Z5,Migration!$J$3:$R$196,9,FALSE) -> No data
A6: BFA | B6: 1 | E6: 9.8023334 | F6: 43.19 | G6: =IF(AND(E6<49,F6<60,F6>=50),A6,0) -> 0 | H6: WSM | I6: =VLOOKUP(H6,'Reference table'!$J$2:$K$195,2,FALSE) -> Samoa | K6: PNG | L6: =TRIM(K6) -> PNG | M6: =VLOOKUP(Indice!L6,'Reference table'!J$2:K$195,2,FALSE) -> Papua New Guinea | N6: 1 | R6: BFA | S6: 1 | V6: 9.8023334 | W6: 43.19 | Z6: ARE | AA6: =IF(OR(AD6="Above 0.05",AE6="Above 0.05"),1,0) -> 0 | AB6: 88.652949 | AC6: 77.83 | AD6: =VLOOKUP(Z6,Migration!$J$3:$R$196,8,FALSE) -> Less than 0.1 | AE6: =VLOOKUP(Z6,Migration!$J$3:$R$196,9,FALSE) -> Less than 0.1
A7: BGR | B7: 1 | E7: 89.924145 | F7: 69.87 | G7: =IF(AND(E7<49,F7<60,F7>=50),A7,0) -> 0 | H7: ZMB | I7: =VLOOKUP(H7,'Reference table'!$J$2:$K$195,2,FALSE) -> Zambia | K7: TZA | L7: =TRIM(K7) -> TZA | M7: =VLOOKUP(Indice!L7,'Reference table'!J$2:K$195,2,FALSE) -> United Republic of Tanzania | N7: 1 | R7: BGR | S7: 1 | V7: 89.924145 | W7: 69.87 | Z7: ARG | AA7: =IF(OR(AD7="Above 0.05",AE7="Above 0.05"),1,0) -> 0 | AB7: 66.609812 | AC7: 73.41 | AD7: =VLOOKUP(Z7,Migration!$J$3:$R$196,8,FALSE) -> Less than 0.1 | AE7: =VLOOKUP(Z7,Migration!$J$3:$R$196,9,FALSE) -> Less than 0.1
A8: BHS | B8: 1 | E8: 70.230904 | F8: 69.81 | G8: =IF(AND(E8<49,F8<60,F8>=50),A8,0) -> 0 | H8: ZWE | I8: =VLOOKUP(H8,'Reference table'!$J$2:$K$195,2,FALSE) -> Zimbabwe | K8: AGO | L8: =TRIM(K8) -> AGO | M8: =VLOOKUP(Indice!L8,'Reference table'!J$2:K$195,2,FALSE) -> Angola | N8: 1 | R8: BHS | S8: 1 | V8: 70.230904 | W8: 69.81 | Z8: ARM | AA8: =IF(OR(AD8="Above 0.05",AE8="Above 0.05"),1,0) -> 0 | AB8: 93.389283 | AC8: 69.26 | AD8: =VLOOKUP(Z8,Migration!$J$3:$R$196,8,FALSE) -> Less than 0.1 | AE8: =VLOOKUP(Z8,Migration!$J$3:$R$196,9,FALSE) -> Above 0.1
A9: BIH | B9: 1 | E9: 78.949018 | F9: 64.61 | G9: =IF(AND(E9<49,F9<60,F9>=50),A9,0) -> 0 | K9: GNQ | L9: =TRIM(K9) -> GNQ | M9: =VLOOKUP(Indice!L9,'Reference table'!J$2:K$195,2,FALSE) -> Equatorial Guinea | N9: 1 | R9: BIH | S9: 1 | V9: 78.949018 | W9: 64.61 | Z9: ATG | AA9: =IF(OR(AD9="Above 0.05",AE9="Above 0.05"),1,0) -> 0 | AB9: 118.48587 | AC9: 72.33 | AD9: =VLOOKUP(Z9,Migration!$J$3:$R$196,8,FALSE) -> Less than 0.1 | AE9: =VLOOKUP(Z9,Migration!$J$3:$R$196,9,FALSE) -> Above 0.1
A10: BLZ | B10: 1 | E10: 34.197316 | F10: 67.17 | G10: =IF(AND(E10<49,F10<60,F10>=50),A10,0) -> 0 | K10: MWI | L10: =TRIM(K10) -> MWI | M10: =VLOOKUP(Indice!L10,'Reference table'!J$2:K$195,2,FALSE) -> Malawi | N10: 1 | R10: BLZ | S10: 1 | V10: 34.197316 | W10: 67.17 | Z10: AUS | AA10: =IF(OR(AD10="Above 0.05",AE10="Above 0.05"),1,0) -> 0 | AB10: 172.69653 | AC10: 87.15 | AD10: =VLOOKUP(Z10,Migration!$J$3:$R$196,8,FALSE) -> Less than 0.1 | AE10: =VLOOKUP(Z10,Migration!$J$3:$R$196,9,FALSE) -> Less than 0.1
A11: BOL | B11: 1 | E11: 25.872321 | F11: 66.75 | G11: =IF(AND(E11<49,F11<60,F11>=50),A11,0) -> 0 | K11: MRT | L11: =TRIM(K11) -> MRT | M11: =VLOOKUP(Indice!L11,'Reference table'!J$2:K$195,2,FALSE) -> Mauritania | N11: 1 | R11: BOL | S11: 1 | V11: 25.872321 | W11: 66.75 | Z11: AUT | AA11: =IF(OR(AD11="Above 0.05",AE11="Above 0.05"),1,0) -> 0 | AB11: 158.57124 | AC11: 82.26 | AD11: =VLOOKUP(Z11,Migration!$J$3:$R$196,8,FALSE) -> Less than 0.1 | AE11: =VLOOKUP(Z11,Migration!$J$3:$R$196,9,FALSE) -> Less than 0.1
A12: BRB | B12: 1 | E12: 60.557792 | F12: 74.46 | G12: =IF(AND(E12<49,F12<60,F12>=50),A12,0) -> 0 | K12: ZMB | L12: =TRIM(K12) -> ZMB | M12: =VLOOKUP(Indice!L12,'Reference table'!J$2:K$195,2,FALSE) -> Zambia | N12: 1 | R12: BRB | S12: 1 | V12: 60.557792 | W12: 74.46 | Z12: AZE | AA12: =IF(OR(AD12="Above 0.05",AE12="Above 0.05"),1,0) -> 0 | AB12: 96.166758 | AC12: 65.28 | AD12: =VLOOKUP(Z12,Migration!$J$3:$R$196,8,FALSE) -> Less than 0.1 | AE12: =VLOOKUP(Z12,Migration!$J$3:$R$196,9,FALSE) -> Less than 0.1
A13: CAN | B13: 1 | E13: 135.2862 | F13: 89.36 | G13: =IF(AND(E13<49,F13<60,F13>=50),A13,0) -> 0 | K13: YEM | L13: =TRIM(K13) -> YEM | M13: =VLOOKUP(Indice!L13,'Reference table'!J$2:K$195,2,FALSE) -> Yemen | N13: 1 | R13: CAN | S13: 1 | V13: 135.2862 | W13: 89.36 | Z13: BDI | AA13: =IF(OR(AD13="Above 0.05",AE13="Above 0.05"),1,0) -> 0 | AB13: 7.197479 | AC13: 44.37 | AD13: =VLOOKUP(Z13,Migration!$J$3:$R$196,8,FALSE) -> Less than 0.1 | AE13: =VLOOKUP(Z13,Migration!$J$3:$R$196,9,FALSE) -> Less than 0.1
A14: CMR | B14: 1 | E14: 5.7732076 | F14: 44.31 | G14: =IF(AND(E14<49,F14<60,F14>=50),A14,0) -> 0 | K14: SDN | L14: =TRIM(K14) -> SDN | M14: =VLOOKUP(Indice!L14,'Reference table'!J$2:K$195,2,FALSE) -> Sudan | N14: 1 | R14: CMR | S14: 1 | V14: 5.7732076 | W14: 44.31 | Z14: BEL | AA14: =IF(OR(AD14="Above 0.05",AE14="Above 0.05"),1,0) -> 0 | AB14: 261.39051 | AC14: 85.5 | AD14: =VLOOKUP(Z14,Migration!$J$3:$R$196,8,FALSE) -> Less than 0.1 | AE14: =VLOOKUP(Z14,Migration!$J$3:$R$196,9,FALSE) -> Less than 0.1
A15: COG | B15: 1 | E15: 10.725802 | F15: 40.49 | G15: =IF(AND(E15<49,F15<60,F15>=50),A15,0) -> 0 | K15: JAM | L15: =TRIM(K15) -> JAM | M15: =VLOOKUP(Indice!L15,'Reference table'!J$2:K$195,2,FALSE) -> Jamaica | N15: 1 | R15: COG | S15: 1 | V15: 10.725802 | W15: 40.49 | Z15: BEN | AA15: =IF(OR(AD15="Above 0.05",AE15="Above 0.05"),1,0) -> 0 | AB15: 3.6762711 | AC15: 38.2 | AD15: =VLOOKUP(Z15,Migration!$J$3:$R$196,8,FALSE) -> Less than 0.1 | AE15: =VLOOKUP(Z15,Migration!$J$3:$R$196,9,FALSE) -> Less than 0.1
A16: COL | B16: 1 | E16: 42.115654 | F16: 78.27 | G16: =IF(AND(E16<49,F16<60,F16>=50),A16,0) -> 0 | K16: COD | L16: =TRIM(K16) -> COD | M16: =VLOOKUP(Indice!L16,'Reference table'!J$2:K$195,2,FALSE) -> Democratic Republic of the Congo | N16: 1 | R16: COL | S16: 1 | V16: 42.115654 | W16: 78.27 | Z16: BFA | AA16: =IF(OR(AD16="Above 0.05",AE16="Above 0.05"),1,0) -> 0 | AB16: 9.8023334 | AC16: 43.19 | AD16: =VLOOKUP(Z16,Migration!$J$3:$R$196,8,FALSE) -> Less than 0.1 | AE16: =VLOOKUP(Z16,Migration!$J$3:$R$196,9,FALSE) -> Less than 0.1
A17: CPV | B17: 1 | E17: 25.59476 | F17: 69.41 | G17: =IF(AND(E17<49,F17<60,F17>=50),A17,0) -> 0 | K17: ERI | L17: =TRIM(K17) -> ERI | M17: =VLOOKUP(Indice!L17,'Reference table'!J$2:K$195,2,FALSE) -> Eritrea | N17: 1 | R17: CPV | S17: 1 | V17: 25.59476 | W17: 69.41 | Z17: BGD | AA17: =IF(OR(AD17="Above 0.05",AE17="Above 0.05"),1,0) -> 0 | AB17: 11.541212 | AC17: 50.74 | AD17: =VLOOKUP(Z17,Migration!$J$3:$R$196,8,FALSE) -> Less than 0.1 | AE17: =VLOOKUP(Z17,Migration!$J$3:$R$196,9,FALSE) -> Less than 0.1
A18: CRI | B18: 1 | E18: 71.021183 | F18: 78.21 | G18: =IF(AND(E18<49,F18<60,F18>=50),A18,0) -> 0 | K18: LAO | L18: =TRIM(K18) -> LAO | M18: =VLOOKUP(Indice!L18,'Reference table'!J$2:K$195,2,FALSE) -> Lao People's Democratic Republic | N18: 1 | R18: CRI | S18: 1 | V18: 71.021183 | W18: 78.21 | Z18: BGR | AA18: =IF(OR(AD18="Above 0.05",AE18="Above 0.05"),1,0) -> 0 | AB18: 89.924145 | AC18: 69.87 | AD18: =VLOOKUP(Z18,Migration!$J$3:$R$196,8,FALSE) -> Less than 0.1 | AE18: =VLOOKUP(Z18,Migration!$J$3:$R$196,9,FALSE) -> Less than 0.1
A19: CUB | B19: 1 | E19: 164.65097 | F19: 79.67 | G19: =IF(AND(E19<49,F19<60,F19>=50),A19,0) -> 0 | K19: VUT | L19: =TRIM(K19) -> VUT | M19: =VLOOKUP(Indice!L19,'Reference table'!J$2:K$195,2,FALSE) -> Vanuatu | N19: 1 | R19: CUB | S19: 1 | V19: 164.65097 | W19: 79.67 | Z19: BHR | AA19: =IF(OR(AD19="Above 0.05",AE19="Above 0.05"),1,0) -> 0 | AB19: 39.38341 | AC19: 71.44 | AD19: =VLOOKUP(Z19,Migration!$J$3:$R$196,8,FALSE) -> Less than 0.1 | AE19: =VLOOKUP(Z19,Migration!$J$3:$R$196,9,FALSE) -> Less than 0.1
A20: CYP | B20: 1 | E20: 86.745233 | F20: 78.74 | G20: =IF(AND(E20<49,F20<60,F20>=50),A20,0) -> 0 | K20: MMR | L20: =TRIM(K20) -> MMR | M20: =VLOOKUP(Indice!L20,'Reference table'!J$2:K$195,2,FALSE) -> Myanmar | N20: 1 | R20: CYP | S20: 1 | V20: 86.745233 | W20: 78.74 | Z20: BHS | AA20: =IF(OR(AD20="Above 0.05",AE20="Above 0.05"),1,0) -> 0 | AB20: 70.230904 | AC20: 69.81 | AD20: =VLOOKUP(Z20,Migration!$J$3:$R$196,8,FALSE) -> Above 0.1 | AE20: =VLOOKUP(Z20,Migration!$J$3:$R$196,9,FALSE) -> Above 0.1
... A23: DZA | B23: 1 | E23: 32.692653 | F23: 74.99 | G23: =IF(AND(E23<49,F23<60,F23>=50),A23,0) -> 0 | K23: SLB | L23: =TRIM(K23) -> SLB | M23: =VLOOKUP(Indice!L23,'Reference table'!J$2:K$195,2,FALSE) -> Solomon Islands | N23: 1 | R23: DZA | S23: 1 | V23: 32.692653 | W23: 74.99 | Z23: BLZ | AA23: =IF(OR(AD23="Above 0.05",AE23="Above 0.05"),1,0) -> 0 | AB23: 34.197316 | AC23: 67.17 | AD23: =VLOOKUP(Z23,Migration!$J$3:$R$196,8,FALSE) -> Less than 0.1 | AE23: =VLOOKUP(Z23,Migration!$J$3:$R$196,9,FALSE) -> Above 0.1
A24: ECU | B24: 1 | E24: 47.21603 | F24: 80.34 | G24: =IF(AND(E24<49,F24<60,F24>=50),A24,0) -> 0 | K24: IND | L24: =TRIM(K24) -> IND | M24: =VLOOKUP(Indice!L24,'Reference table'!J$2:K$195,2,FALSE) -> India | N24: 1 | R24: ECU | S24: 1 | V24: 47.21603 | W24: 80.34 | Z24: BMU | AA24: =IF(OR(AD24="Above 0.05",AE24="Above 0.05"),1,0) -> #N/A | AB24: #N/A | AC24: #N/A | AD24: =VLOOKUP(Z24,Migration!$J$3:$R$196,8,FALSE) -> #N/A | AE24: =VLOOKUP(Z24,Migration!$J$3:$R$196,9,FALSE) -> #N/A
A25: EGY | B25: 1 | E25: 26.758459 | F25: 69.8 | G25: =IF(AND(E25<49,F25<60,F25>=50),A25,0) -> 0 | K25: TLS | L25: =TRIM(K25) -> TLS | M25: =VLOOKUP(Indice!L25,'Reference table'!J$2:K$195,2,FALSE) -> Timor-Leste | N25: 1 | R25: EGY | S25: 1 | V25: 26.758459 | W25: 69.8 | Z25: BOL | AA25: =IF(OR(AD25="Above 0.05",AE25="Above 0.05"),1,0) -> 0 | AB25: 25.872321 | AC25: 66.75 | AD25: =VLOOKUP(Z25,Migration!$J$3:$R$196,8,FALSE) -> Above 0.1 | AE25: =VLOOKUP(Z25,Migration!$J$3:$R$196,9,FALSE) -> Less than 0.1
A26: ERI | B26: 1 | E26: 15.217567 | F26: 49.8 | G26: =IF(AND(E26<49,F26<60,F26>=50),A26,0) -> 0 | K26: CPV | L26: =TRIM(K26) -> CPV | M26: =VLOOKUP(Indice!L26,'Reference table'!J$2:K$195,2,FALSE) -> Cape Verde | N26: 1 | R26: ERI | S26: 1 | V26: 15.217567 | W26: 49.8 | Z26: BRA | AA26: =IF(OR(AD26="Above 0.05",AE26="Above 0.05"),1,0) -> 0 | AB26: 97.13739 | AC26: 75.03 | AD26: =VLOOKUP(Z26,Migration!$J$3:$R$196,8,FALSE) -> Less than 0.1 | AE26: =VLOOKUP(Z26,Migration!$J$3:$R$196,9,FALSE) -> Less than 0.1
A27: ETH | B27: 1 | E27: 8.9002606 | F27: 38.13 | G27: =IF(AND(E27<49,F27<60,F27>=50),A27,0) -> 0 | K27: BTN | L27: =TRIM(K27) -> BTN | M27: =VLOOKUP(Indice!L27,'Reference table'!J$2:K$195,2,FALSE) -> Bhutan | N27: 1 | R27: ETH | S27: 1 | V27: 8.9002606 | W27: 38.13 | Z27: BRB | AA27: =IF(OR(AD27="Above 0.05",AE27="Above 0.05"),1,0) -> 0 | AB27: 60.557792 | AC27: 74.46 | AD27: =VLOOKUP(Z27,Migration!$J$3:$R$196,8,FALSE) -> Less than 0.1 | AE27: =VLOOKUP(Z27,Migration!$J$3:$R$196,9,FALSE) -> Above 0.1
A28: FJI | B28: 1 | E28: 48.197238 | F28: 60.96 | G28: =IF(AND(E28<49,F28<60,F28>=50),A28,0) -> 0 | K28: SYR | L28: =TRIM(K28) -> SYR | M28: =VLOOKUP(Indice!L28,'Reference table'!J$2:K$195,2,FALSE) -> Syrian Arab Republic | N28: 1 | R28: FJI | S28: 1 | V28: 48.197238 | W28: 60.96 | Z28: BRN | AA28: =IF(OR(AD28="Above 0.05",AE28="Above 0.05"),1,0) -> 0 | AB28: 75.070095 | AC28: 76.81 | AD28: =VLOOKUP(Z28,Migration!$J$3:$R$196,8,FALSE) -> Less than 0.1 | AE28: =VLOOKUP(Z28,Migration!$J$3:$R$196,9,FALSE) -> Less than 0.1
A29: FSM | B29: 1 | E29: 30.916506 | F29: 47.9 | G29: =IF(AND(E29<49,F29<60,F29>=50),A29,0) -> 0 | K29: GAB | L29: =TRIM(K29) -> GAB | M29: =VLOOKUP(Indice!L29,'Reference table'!J$2:K$195,2,FALSE) -> Gabon | N29: 1 | R29: FSM | S29: 1 | V29: 30.916506 | W29: 47.9 | Z29: BTN | AA29: =IF(OR(AD29="Above 0.05",AE29="Above 0.05"),1,0) -> 0 | AB29: 25.764245 | AC29: 62.39 | AD29: =VLOOKUP(Z29,Migration!$J$3:$R$196,8,FALSE) -> Less than 0.1 | AE29: =VLOOKUP(Z29,Migration!$J$3:$R$196,9,FALSE) -> Less than 0.1
A30: GEO | B30: 1 | E30: 106.55085 | F30: 65.16 | G30: =IF(AND(E30<49,F30<60,F30>=50),A30,0) -> 0 | K30: FSM | L30: =TRIM(K30) -> FSM | M30: =VLOOKUP(Indice!L30,'Reference table'!J$2:K$195,2,FALSE) -> Micronesia, Federated States of | N30: 1 | R30: GEO | S30: 1 | V30: 106.55085 | W30: 65.16 | Z30: BWA | AA30: =IF(OR(AD30="Above 0.05",AE30="Above 0.05"),1,0) -> 0 | AB30: 58.3523 | AC30: 53.66 | AD30: =VLOOKUP(Z30,Migration!$J$3:$R$196,8,FALSE) -> Less than 0.1 | AE30: =VLOOKUP(Z30,Migration!$J$3:$R$196,9,FALSE) -> Less than 0.1
A31: GHA | B31: 1 | E31: 37.869453 | F31: 45.09 | G31: =IF(AND(E31<49,F31<60,F31>=50),A31,0) -> 0 | K31: PRY | L31: =TRIM(K31) -> PRY | M31: =VLOOKUP(Indice!L31,'Reference table'!J$2:K$195,2,FALSE) -> Paraguay | N31: 1 | R31: GHA | S31: 1 | V31: 37.869453 | W31: 45.09 | Z31: CAF | AA31: =IF(OR(AD31="Above 0.05",AE31="Above 0.05"),1,0) -> 0 | AB31: 3.2787762 | AC31: 32.46 | AD31: =VLOOKUP(Z31,Migration!$J$3:$R$196,8,FALSE) -> Less than 0.1 | AE31: =VLOOKUP(Z31,Migration!$J$3:$R$196,9,FALSE) -> Less than 0.1
A32: GMB | B32: 1 | E32: 10.28277 | F32: 47.78 | G32: =IF(AND(E32<49,F32<60,F32>=50),A32,0) -> 0 | K32: DOM | L32: =TRIM(K32) -> DOM | M32: =VLOOKUP(Indice!L32,'Reference table'!J$2:K$195,2,FALSE) -> Dominican Republic | N32: 1 | R32: GMB | S32: 1 | V32: 10.28277 | W32: 47.78 | Z32: CAN | AA32: =IF(OR(AD32="Above 0.05",AE32="Above 0.05"),1,0) -> 0 | AB32: 135.2862 | AC32: 89.36 | AD32: =VLOOKUP(Z32,Migration!$J$3:$R$196,8,FALSE) -> Less than 0.1 | AE32: =VLOOKUP(Z32,Migration!$J$3:$R$196,9,FALSE) -> Less than 0.1
A33: GRC | B33: 1 | E33: 100.15524 | F33: 77.63 | G33: =IF(AND(E33<49,F33<60,F33>=50),A33,0) -> 0 | K33: IRN | L33: =TRIM(K33) -> IRN | M33: =VLOOKUP(Indice!L33,'Reference table'!J$2:K$195,2,FALSE) -> Iran, Islamic Republic of | N33: 1 | R33: GRC | S33: 1 | V33: 100.15524 | W33: 77.63 | Z33: CHE | AA33: =IF(OR(AD33="Above 0.05",AE33="Above 0.05"),1,0) -> 0 | AB33: 226.40989 | AC33: 87.14 | AD33: =VLOOKUP(Z33,Migration!$J$3:$R$196,8,FALSE) -> Less than 0.1 | AE33: =VLOOKUP(Z33,Migration!$J$3:$R$196,9,FALSE) -> Less than 0.1
A34: GRD | B34: 1 | E34: 82.42415 | F34: 69.72 | G34: =IF(AND(E34<49,F34<60,F34>=50),A34,0) -> 0 | K34: LKA | L34: =TRIM(K34) -> LKA | M34: =VLOOKUP(Indice!L34,'Reference table'!J$2:K$195,2,FALSE) -> Sri Lanka | N34: 1 | R34: GRD | S34: 1 | V34: 82.42415 | W34: 69.72 | Z34: CHL | AA34: =IF(OR(AD34="Above 0.05",AE34="Above 0.05"),1,0) -> 0 | AB34: 71.889527 | AC34: 79.84 | AD34: =VLOOKUP(Z34,Migration!$J$3:$R$196,8,FALSE) -> Less than 0.1 | AE34: =VLOOKUP(Z34,Migration!$J$3:$R$196,9,FALSE) -> Less than 0.1
A35: GTM | B35: 1 | E35: 39.099315 | F35: 57.11 | G35: =IF(AND(E35<49,F35<60,F35>=50),A35,0) -> GTM | K35: GHA | L35: =TRIM(K35) -> GHA | M35: =VLOOKUP(Indice!L35,'Reference table'!J$2:K$195,2,FALSE) -> Ghana | N35: 1 | R35: GTM | S35: 1 | V35: 39.099315 | W35: 57.11 | Z35: CHN | AA35: =IF(OR(AD35="Above 0.05",AE35="Above 0.05"),1,0) -> 0 | AB35: 57.462381 | AC35: 82.17 | AD35: =VLOOKUP(Z35,Migration!$J$3:$R$196,8,FALSE) -> Less than 0.1 | AE35: =VLOOKUP(Z35,Migration!$J$3:$R$196,9,FALSE) -> Less than 0.1
A36: GUY | B36: 1 | E36: 49.544916 | F36: 74.28 | G36: =IF(AND(E36<49,F36<60,F36>=50),A36,0) -> 0 | K36: LCA | L36: =TRIM(K36) -> LCA | M36: =VLOOKUP(Indice!L36,'Reference table'!J$2:K$195,2,FALSE) -> Saint Lucia | N36: 1 | R36: GUY | S36: 1 | V36: 49.544916 | W36: 74.28 | Z36: CIV | AA36: =IF(OR(AD36="Above 0.05",AE36="Above 0.05"),1,0) -> 0 | AB36: 8.1840465 | AC36: 45.44 | AD36: =VLOOKUP(Z36,Migration!$J$3:$R$196,8,FALSE) -> Less than 0.1 | AE36: =VLOOKUP(Z36,Migration!$J$3:$R$196,9,FALSE) -> Less than 0.1
... A45: KHM | B45: 1 | E45: 11.991456 | F45: 61.18 | G45: =IF(AND(E45<49,F45<60,F45>=50),A45,0) -> 0 | K45: SUR | L45: =TRIM(K45) -> SUR | M45: =VLOOKUP(Indice!L45,'Reference table'!J$2:K$195,2,FALSE) -> Suriname | N45: 1 | R45: KHM | S45: 1 | V45: 11.991456 | W45: 61.18 | Z45: CUB | AA45: =IF(OR(AD45="Above 0.05",AE45="Above 0.05"),1,0) -> 0 | AB45: 164.65097 | AC45: 79.67 | AD45: =VLOOKUP(Z45,Migration!$J$3:$R$196,8,FALSE) -> Less than 0.1 | AE45: =VLOOKUP(Z45,Migration!$J$3:$R$196,9,FALSE) -> Above 0.1
A46: KNA | B46: 1 | E46: 74.134664 | F46: 71.75 | G46: =IF(AND(E46<49,F46<60,F46>=50),A46,0) -> 0 | K46: GUY | L46: =TRIM(K46) -> GUY | M46: =VLOOKUP(Indice!L46,'Reference table'!J$2:K$195,2,FALSE) -> Guyana | N46: 1 | R46: KNA | S46: 1 | V46: 74.134664 | W46: 71.75 | Z46: CYM | AA46: =IF(OR(AD46="Above 0.05",AE46="Above 0.05"),1,0) -> #N/A | AB46: #N/A | AC46: #N/A | AD46: =VLOOKUP(Z46,Migration!$J$3:$R$196,8,FALSE) -> #N/A | AE46: =VLOOKUP(Z46,Migration!$J$3:$R$196,9,FALSE) -> #N/A
A47: LAO | B47: 1 | E47: 15.442119 | F47: 50.21 | G47: =IF(AND(E47<49,F47<60,F47>=50),A47,0) -> LAO | K47: PAN | L47: =TRIM(K47) -> PAN | M47: =VLOOKUP(Indice!L47,'Reference table'!J$2:K$195,2,FALSE) -> Panama | N47: 1 | R47: LAO | S47: 1 | V47: 15.442119 | W47: 50.21 | Z47: CYP | AA47: =IF(OR(AD47="Above 0.05",AE47="Above 0.05"),1,0) -> 0 | AB47: 86.745233 | AC47: 78.74 | AD47: =VLOOKUP(Z47,Migration!$J$3:$R$196,8,FALSE) -> Above 0.1 | AE47: =VLOOKUP(Z47,Migration!$J$3:$R$196,9,FALSE) -> Less than 0.1
A48: LBN | B48: 1 | E48: 38.805336 | F48: 71.98 | G48: =IF(AND(E48<49,F48<60,F48>=50),A48,0) -> 0 | K48: TON | L48: =TRIM(K48) -> TON | M48: =VLOOKUP(Indice!L48,'Reference table'!J$2:K$195,2,FALSE) -> Tonga | N48: 1 | R48: LBN | S48: 1 | V48: 38.805336 | W48: 71.98 | Z48: CZE | AA48: =IF(OR(AD48="Above 0.05",AE48="Above 0.05"),1,0) -> 0 | AB48: 130.81963 | AC48: 78.37 | AD48: =VLOOKUP(Z48,Migration!$J$3:$R$196,8,FALSE) -> Less than 0.1 | AE48: =VLOOKUP(Z48,Migration!$J$3:$R$196,9,FALSE) -> Less than 0.1
A49: LBR | B49: 1 | E49: 20.047828 | F49: 41.87 | G49: =IF(AND(E49<49,F49<60,F49>=50),A49,0) -> 0 | K49: ZAF | L49: =TRIM(K49) -> ZAF | M49: =VLOOKUP(Indice!L49,'Reference table'!J$2:K$195,2,FALSE) -> South Africa | N49: 1 | R49: LBR | S49: 1 | V49: 20.047828 | W49: 41.87 | Z49: DEU | AA49: =IF(OR(AD49="Above 0.05",AE49="Above 0.05"),1,0) -> 0 | AB49: 186.2553 | AC49: 85.84 | AD49: =VLOOKUP(Z49,Migration!$J$3:$R$196,8,FALSE) -> Less than 0.1 | AE49: =VLOOKUP(Z49,Migration!$J$3:$R$196,9,FALSE) -> Less than 0.1
A50: LBY | B50: 1 | E50: 86.209371 | F50: 59.66 | G50: =IF(AND(E50<49,F50<60,F50>=50),A50,0) -> 0 | K50: MYS | L50: =TRIM(K50) -> MYS | M50: =VLOOKUP(Indice!L50,'Reference table'!J$2:K$195,2,FALSE) -> Malaysia | N50: 1 | R50: LBY | S50: 1 | V50: 86.209371 | W50: 59.66 | Z50: DJI | AA50: =IF(OR(AD50="Above 0.05",AE50="Above 0.05"),1,0) -> 0 | AB50: 9.5247949 | AC50: 48.14 | AD50: =VLOOKUP(Z50,Migration!$J$3:$R$196,8,FALSE) -> Less than 0.1 | AE50: =VLOOKUP(Z50,Migration!$J$3:$R$196,9,FALSE) -> No data
...

Sheet Migration
A1: Medical doctors | E1: Nursing personnel | J1: Stock | P1: Threshold | Q1: 0.1 | T1: 0-5% | U1: 5%+ | V1: No data
A2: ISO3 | B2: Foreign trained | E2: ISO3 | F2: Foreign trained | J2: ='Processed HWF'!B1 -> ISO3 | K2: Medical doctors | L2: Nursing personnel | M2: Medical doctors foreign | N2: Nursing personnel foreign | O2: Share foreign med | P2: Share foreign nurse | Q2: Share foreign med cat | R2: Share foreign nur cat | X2: ISO3 | Y2: Country | Z2: Share foreign med | AA2: Share foreign nurse | AC2: ISO3 | AD2: Country | AE2: Share foreign med | AF2: Share foreign nurse
A3: IND | B3: 17202 | E3: PHL | F3: 220984 | J3: ='Processed HWF'!B2 -> AFG | K3: =ROUND('Processed HWF'!D2/10000*'Processed HWF'!J2,0) -> 9887 | L3: =ROUND('Processed HWF'!E2/10000*'Processed HWF'!J2,0) -> 12017 | M3: =VLOOKUP(J3,A$3:B$184,2,FALSE) -> 261 | N3: =VLOOKUP(J3,E$3:F$171,2,FALSE) -> 767 | O3: =IF(_xlfn.IFNA(M3,0)=0,"No data",M3/K3) -> 0.026398301 | P3: =IF(_xlfn.IFNA(N3,0)=0,"No data",N3/L3) -> 0.063826246 | Q3: =IF(O3="No data","No data",IF(O3<$Q$1,"Less than "&$Q$1,"Above "&$Q$1)) -> Less than 0.1 | R3: =IF(P3="No data","No data",IF(P3<$Q$1,"Less than "&$Q$1,"Above "&$Q$1)) -> Less than 0.1 | X3: NIU | Y3: =VLOOKUP(X3,'Reference table'!$J$2:$K$195,2,FALSE) -> Niue | Z3: 44.333333 | AA3: No data | AC3: JAM | AD3: =VLOOKUP(AC3,'Reference table'!$J$2:$K$195,2,FALSE) -> Jamaica | AE3: 0.016025641 | AF3: 15.738384
A4: DZA | B4: 11000 | E4: IND | F4: 71230 | J4: ='Processed HWF'!B3 -> AGO | K4: =ROUND('Processed HWF'!D3/10000*'Processed HWF'!J3,0) -> 7035 | L4: =ROUND('Processed HWF'!E3/10000*'Processed HWF'!J3,0) -> 13396 | M4: =VLOOKUP(J4,A$3:B$184,2,FALSE) -> 114 | N4: =VLOOKUP(J4,E$3:F$171,2,FALSE) -> 16 | O4: =IF(_xlfn.IFNA(M4,0)=0,"No data",M4/K4) -> 0.016204691 | P4: =IF(_xlfn.IFNA(N4,0)=0,"No data",N4/L4) -> 0.0011943864 | Q4: =IF(O4="No data","No data",IF(O4<$Q$1,"Less than "&$Q$1,"Above "&$Q$1)) -> Less than 0.1 | R4: =IF(P4="No data","No data",IF(P4<$Q$1,"Less than "&$Q$1,"Above "&$Q$1)) -> Less than 0.1 | X4: FSM | Y4: =VLOOKUP(X4,'Reference table'!$J$2:$K$195,2,FALSE) -> Micronesia, Federated States of | Z4: 2.8703704 | AA4: 0.21982759 | AC4: HTI | AD4: =VLOOKUP(AC4,'Reference table'!$J$2:$K$195,2,FALSE) -> Haiti | AE4: 0.014942099 | AF4: 7.8843851
A5: RUS | B5: 9862 | E5: MEX | F5: 38969 | J5: ='Processed HWF'!B4 -> ALB | K5: =ROUND('Processed HWF'!D4/10000*'Processed HWF'!J4,0) -> 5397 | L5: =ROUND('Processed HWF'!E4/10000*'Processed HWF'!J4,0) -> 15692 | M5: =VLOOKUP(J5,A$3:B$184,2,FALSE) -> 1210 | N5: =VLOOKUP(J5,E$3:F$171,2,FALSE) -> 1613 | O5: =IF(_xlfn.IFNA(M5,0)=0,"No data",M5/K5) -> 0.22419863 | P5: =IF(_xlfn.IFNA(N5,0)=0,"No data",N5/L5) -> 0.10279123 | Q5: =IF(O5="No data","No data",IF(O5<$Q$1,"Less than "&$Q$1,"Above "&$Q$1)) -> Above 0.1 | R5: =IF(P5="No data","No data",IF(P5<$Q$1,"Less than "&$Q$1,"Above "&$Q$1)) -> Above 0.1 | X5: DMA | Y5: =VLOOKUP(X5,'Reference table'!$J$2:$K$195,2,FALSE) -> Dominica | Z5: 0.55696203 | AA5: 1.0660592 | AC5: GUY | AD5: =VLOOKUP(AC5,'Reference table'!$J$2:$K$195,2,FALSE) -> Guyana | AE5: 0.015178571 | AF5: 4.7513336
A6: ROU | B6: 9462 | E6: JAM | F6: 37599 | J6: ='Processed HWF'!B5 -> AND | K6: =ROUND('Processed HWF'!D5/10000*'Processed HWF'!J5,0) -> 258 | L6: =ROUND('Processed HWF'!E5/10000*'Processed HWF'!J5,0) -> 293 | M6: =VLOOKUP(J6,A$3:B$184,2,FALSE) -> 2 | N6: =VLOOKUP(J6,E$3:F$171,2,FALSE) -> #N/A | O6: =IF(_xlfn.IFNA(M6,0)=0,"No data",M6/K6) -> 0.007751938 | P6: =IF(_xlfn.IFNA(N6,0)=0,"No data",N6/L6) -> No data | Q6: =IF(O6="No data","No data",IF(O6<$Q$1,"Less than "&$Q$1,"Above "&$Q$1)) -> Less than 0.1 | R6: =IF(P6="No data","No data",IF(P6<$Q$1,"Less than "&$Q$1,"Above "&$Q$1)) -> No data | X6: GRD | Y6: =VLOOKUP(X6,'Reference table'!$J$2:$K$195,2,FALSE) -> Grenada | Z6: 0.48765432 | AA6: 2.0537482 | AC6: BRB | AD6: =VLOOKUP(AC6,'Reference table'!$J$2:$K$195,2,FALSE) -> Barbados | AE6: 0.0013986014 | AF6: 2.5517634
A7: UKR | B7: 7612 | E7: NGA | F7: 37461 | J7: ='Processed HWF'!B6 -> ARE | K7: =ROUND('Processed HWF'!D6/10000*'Processed HWF'!J6,0) -> 25726 | L7: =ROUND('Processed HWF'!E6/10000*'Processed HWF'!J6,0) -> 56831 | M7: =VLOOKUP(J7,A$3:B$184,2,FALSE) -> 130 | N7: =VLOOKUP(J7,E$3:F$171,2,FALSE) -> 287 | O7: =IF(_xlfn.IFNA(M7,0)=0,"No data",M7/K7) -> 0.0050532535 | P7: =IF(_xlfn.IFNA(N7,0)=0,"No data",N7/L7) -> 0.0050500607 | Q7: =IF(O7="No data","No data",IF(O7<$Q$1,"Less than "&$Q$1,"Above "&$Q$1)) -> Less than 0.1 | R7: =IF(P7="No data","No data",IF(P7<$Q$1,"Less than "&$Q$1,"Above "&$Q$1)) -> Less than 0.1 | X7: VCT | Y7: =VLOOKUP(X7,'Reference table'!$J$2:$K$195,2,FALSE) -> Saint Vincent and the Grenadines | Z7: 0.40384615 | AA7: 1.7866324 | AC7: SOM | AD7: =VLOOKUP(AC7,'Reference table'!$J$2:$K$195,2,FALSE) -> Somalia | AE7: 0.016393443 | AF7: 2.5301328
A8: PAK | B8: 6464 | E8: HTI | F8: 34234 | J8: ='Processed HWF'!B7 -> ARG | K8: =ROUND('Processed HWF'!D7/10000*'Processed HWF'!J7,0) -> 183458 | L8: =ROUND('Processed HWF'!E7/10000*'Processed HWF'!J7,0) -> 117590 | M8: =VLOOKUP(J8,A$3:B$184,2,FALSE) -> 1312 | N8: =VLOOKUP(J8,E$3:F$171,2,FALSE) -> 2768 | O8: =IF(_xlfn.IFNA(M8,0)=0,"No data",M8/K8) -> 0.0071515006 | P8: =IF(_xlfn.IFNA(N8,0)=0,"No data",N8/L8) -> 0.023539417 | Q8: =IF(O8="No data","No data",IF(O8<$Q$1,"Less than "&$Q$1,"Above "&$Q$1)) -> Less than 0.1 | R8: =IF(P8="No data","No data",IF(P8<$Q$1,"Less than "&$Q$1,"Above "&$Q$1)) -> Less than 0.1 | X8: CYP | Y8: =VLOOKUP(X8,'Reference table'!$J$2:$K$195,2,FALSE) -> Cyprus | Z8: 0.27660695 | AA8: 0.098107256 | AC8: GRD | AD8: =VLOOKUP(AC8,'Reference table'!$J$2:$K$195,2,FALSE) -> Grenada | AE8: 0.48765432 | AF8: 2.0537482
A9: MAR | B9: 5672 | E9: CAN | F9: 30106 | J9: ='Processed HWF'!B8 -> ARM | K9: =ROUND('Processed HWF'!D8/10000*'Processed HWF'!J8,0) -> 13045 | L9: =ROUND('Processed HWF'!E8/10000*'Processed HWF'!J8,0) -> 13433 | M9: =VLOOKUP(J9,A$3:B$184,2,FALSE) -> 819 | N9: =VLOOKUP(J9,E$3:F$171,2,FALSE) -> 1984 | O9: =IF(_xlfn.IFNA(M9,0)=0,"No data",M9/K9) -> 0.062782675 | P9: =IF(_xlfn.IFNA(N9,0)=0,"No data",N9/L9) -> 0.14769597 | Q9: =IF(O9="No data","No data",IF(O9<$Q$1,"Less than "&$Q$1,"Above "&$Q$1)) -> Less than 0.1 | R9: =IF(P9="No data","No data",IF(P9<$Q$1,"Less than "&$Q$1,"Above "&$Q$1)) -> Above 0.1 | X9: LUX | Y9: =VLOOKUP(X9,'Reference table'!$J$2:$K$195,2,FALSE) -> Luxembourg | Z9: 0.25345377 | AA9: 0.00013524479 | AC9: VCT | AD9: =VLOOKUP(AC9,'Reference table'!$J$2:$K$195,2,FALSE) -> Saint Vincent and the Grenadines | AE9: 0.40384615 | AF9: 1.7866324
A10: ITA | B10: 5434 | E10: POL | F10: 30040 | J10: ='Processed HWF'!B9 -> ATG | K10: =ROUND('Processed HWF'!D9/10000*'Processed HWF'!J9,0) -> 271 | L10: =ROUND('Processed HWF'!E9/10000*'Processed HWF'!J9,0) -> 615 | M10: =VLOOKUP(J10,A$3:B$184,2,FALSE) -> 8 | N10: =VLOOKUP(J10,E$3:F$171,2,FALSE) -> 906 | O10: =IF(_xlfn.IFNA(M10,0)=0,"No data",M10/K10) -> 0.029520295 | P10: =IF(_xlfn.IFNA(N10,0)=0,"No data",N10/L10) -> 1.4731707 | Q10: =IF(O10="No data","No data",IF(O10<$Q$1,"Less than "&$Q$1,"Above "&$Q$1)) -> Less than 0.1 | R10: =IF(P10="No data","No data",IF(P10<$Q$1,"Less than "&$Q$1,"Above "&$Q$1)) -> Above 0.1 | X10: TUN | Y10: =VLOOKUP(X10,'Reference table'!$J$2:$K$195,2,FALSE) -> Tunisia | Z10: 0.24153119 | AA10: 0.039907364 | AC10: TTO | AD10: =VLOOKUP(AC10,'Reference table'!$J$2:$K$195,2,FALSE) -> Trinidad and Tobago | AE10: 0.0001596424 | AF10: 1.6009904
A11: SYR | B11: 5400 | E11: DEU | F11: 28396 | J11: ='Processed HWF'!B10 -> AUS | K11: =ROUND('Processed HWF'!D10/10000*'Processed HWF'!J10,0) -> 105293 | L11: =ROUND('Processed HWF'!E10/10000*'Processed HWF'!J10,0) -> 313594 | M11: =VLOOKUP(J11,A$3:B$184,2,FALSE) -> 898 | N11: =VLOOKUP(J11,E$3:F$171,2,FALSE) -> 3735 | O11: =IF(_xlfn.IFNA(M11,0)=0,"No data",M11/K11) -> 0.0085285821 | P11: =IF(_xlfn.IFNA(N11,0)=0,"No data",N11/L11) -> 0.011910304 | Q11: =IF(O11="No data","No data",IF(O11<$Q$1,"Less than "&$Q$1,"Above "&$Q$1)) -> Less than 0.1 | R11: =IF(P11="No data","No data",IF(P11<$Q$1,"Less than "&$Q$1,"Above "&$Q$1)) -> Less than 0.1 | X11: SYR | Y11: =VLOOKUP(X11,'Reference table'!$J$2:$K$195,2,FALSE) -> Syrian Arab Republic | Z11: 0.24014943 | AA11: 0.027202795 | AC11: ATG | AD11: =VLOOKUP(AC11,'Reference table'!$J$2:$K$195,2,FALSE) -> Antigua and Barbuda | AE11: 0.029520295 | AF11: 1.4731707
A12: CUB | B12: 4577 | E12: GBR | F12: 23429 | J12: ='Processed HWF'!B11 -> AUT | K12: =ROUND('Processed HWF'!D11/10000*'Processed HWF'!J11,0) -> 47674 | L12: =ROUND('Processed HWF'!E11/10000*'Processed HWF'!J11,0) -> 92643 | M12: =VLOOKUP(J12,A$3:B$184,2,FALSE) -> 2336 | N12: =VLOOKUP(J12,E$3:F$171,2,FALSE) -> 869 | O12: =IF(_xlfn.IFNA(M12,0)=0,"No data",M12/K12) -> 0.048999455 | P12: =IF(_xlfn.IFNA(N12,0)=0,"No data",N12/L12) -> 0.0093800935 | Q12: =IF(O12="No data","No data",IF(O12<$Q$1,"Less than "&$Q$1,"Above "&$Q$1)) -> Less than 0.1 | R12: =IF(P12="No data","No data",IF(P12<$Q$1,"Less than "&$Q$1,"Above "&$Q$1)) -> Less than 0.1 | X12: MLT | Y12: =VLOOKUP(X12,'Reference table'!$J$2:$K$195,2,FALSE) -> Malta | Z12: 0.23357086 | AA12: 0.01714135 | AC12: LCA | AD12: =VLOOKUP(AC12,'Reference table'!$J$2:$K$195,2,FALSE) -> Saint Lucia | AE12: 0.076271186 | AF12: 1.2795031
A13: EGY | B13: 4228 | E13: RUS | F13: 21528 | J13: ='Processed HWF'!B12 -> AZE | K13: =ROUND('Processed HWF'!D12/10000*'Processed HWF'!J12,0) -> 32272 | L13: =ROUND('Processed HWF'!E12/10000*'Processed HWF'!J12,0) -> 59890 | M13: =VLOOKUP(J13,A$3:B$184,2,FALSE) -> 1450 | N13: =VLOOKUP(J13,E$3:F$171,2,FALSE) -> 1002 | O13: =IF(_xlfn.IFNA(M13,0)=0,"No data",M13/K13) -> 0.04493059 | P13: =IF(_xlfn.IFNA(N13,0)=0,"No data",N13/L13) -> 0.016730673 | Q13: =IF(O13="No data","No data",IF(O13<$Q$1,"Less than "&$Q$1,"Above "&$Q$1)) -> Less than 0.1 | R13: =IF(P13="No data","No data",IF(P13<$Q$1,"Less than "&$Q$1,"Above "&$Q$1)) -> Less than 0.1 | X13: ALB | Y13: =VLOOKUP(X13,'Reference table'!$J$2:$K$195,2,FALSE) -> Albania | Z13: 0.22419863 | AA13: 0.10279123 | AC13: BLZ | AD13: =VLOOKUP(AC13,'Reference table'!$J$2:$K$195,2,FALSE) -> Belize | AE13: 0.0046620047 | AF13: 1.1707841
