Workbook

Sheet Sheet2
A3: Row Labels | B3: Count of 2018 | C3: Count of 2022 | D3: Count of 2021 | E3: Count of 2020 | F3: Count of 2019
A4: AGO
A5: BDI | F5: 1
A6: BEN | B6: 1 | D6: 1 | E6: 1
A7: BFA | B7: 1 | C7: 1 | D7: 1 | E7: 1 | F7: 1
A8: BWA | B8: 1 | C8: 1 | D8: 1 | E8: 1 | F8: 1
A9: CAF | B9: 1 | D9: 1 | E9: 1 | F9: 1
A10: CIV | B10: 1 | C10: 1 | D10: 1 | E10: 1 | F10: 1
A11: CMR | B11: 1 | C11: 1 | D11: 1 | E11: 1 | F11: 1
A12: COD | B12: 1 | D12: 1 | E12: 1 | F12: 1
A13: COG | B13: 1 | C13: 1 | D13: 1 | E13: 1 | F13: 1
A14: COM | B14: 1 | D14: 1 | E14: 1
A15: CPV | B15: 1 | C15: 1 | D15: 1 | E15: 1
A16: DZA | B16: 1 | E16: 1
A17: ERI | B17: 1 | C17: 1
A18: ETH | B18: 1
A19: GAB | B19: 1 | C19: 1
A20: GHA | B20: 1 | C20: 1
A21: GIN | B21: 1
A22: GMB | B22: 1
A23: GNB | B23: 1 | C23: 1
A24: GNQ | B24: 1
A25: KEN | C25: 1
A26: LBR | C26: 1
A27: LSO | C27: 1
A28: MDG | C28: 1
A29: MLI | C29: 1
A30: MOZ | C30: 1
A31: MRT | C31: 1
A32: MUS | C32: 1
A33: MWI | C33: 1
A34: NAM | C34: 1
A35: NER | C35: 1
A36: NGA
A37: RWA
A38: SEN
A39: SLE
A40: SSD
A41: STP
A42: SWZ
...

Sheet Sheet4
A1: Row Labels | B1: Sum of NHWA_Medical Doctors Stock By Age Group < 25 yrs | C1: Sum of NHWA_Medical Doctors Stock By Age Group 25-34 yrs | D1: Sum of NHWA_Medical Doctors Stock By Age Group 35-44 yrs | E1: Sum of NHWA_Medical Doctors Stock By Age Group 45-54 yrs | F1: Sum of NHWA_Medical Doctors Stock By Age Group 55-64 yrs | G1: Sum of NHWA_Medical Doctors Stock By Age Group ≥ 65 yrs
A2: AFR | B2: 989 | C2: 35839 | D2: 35402 | E2: 16936 | F2: 6573 | G2: 1720
A3: BFA | B3: 0 | C3: 1138 | D3: 1088 | E3: 112 | F3: 33 | G3: 1
A4: BWA | C4: 483 | D4: 323 | E4: 121 | F4: 52 | G4: 14
A5: CIV | B5: 0 | C5: 920 | D5: 1757 | E5: 1583 | F5: 640 | G5: 29
A6: CMR | B6: 15 | C6: 1889 | D6: 1240 | E6: 454 | F6: 156 | G6: 8
A7: COG | C7: 464 | D7: 312 | E7: 121 | F7: 137 | G7: 8
A8: CPV | B8: 11 | C8: 539 | D8: 801 | E8: 713 | F8: 452 | G8: 128
A9: ERI | C9: 175
A10: GAB | B10: 0 | C10: 248 | D10: 258 | E10: 379 | F10: 224 | G10: 28
A11: GHA | B11: 2 | C11: 1715 | D11: 1942 | E11: 512 | F11: 184 | G11: 3
A12: GNB | B12: 0 | C12: 229 | D12: 143 | E12: 41 | F12: 19 | G12: 5
A13: KEN | B13: 5 | C13: 1600 | D13: 2699 | E13: 941 | F13: 243 | G13: 6
A14: MOZ | B14: 6 | C14: 784 | D14: 897 | E14: 416 | F14: 193 | G14: 50
A15: MWI | B15: 61 | C15: 392 | D15: 331 | E15: 213 | F15: 30 | G15: 13
A16: NGA | B16: 860 | C16: 21366 | D16: 19365 | E16: 8834 | F16: 3461 | G16: 1088
A17: SEN | B17: 1 | C17: 338 | D17: 247 | E17: 64 | F17: 48 | G17: 5
A18: SWZ | C18: 116 | D18: 691
A19: SYC | C19: 9 | D19: 15 | E19: 17 | F19: 9 | G19: 7
A20: TCD | B20: 3 | C20: 880 | D20: 424 | E20: 129 | F20: 73 | G20: 0
A21: TGO | B21: 3 | C21: 213 | D21: 267 | E21: 155 | F21: 64 | G21: 28
A22: ZMB | B22: 22 | C22: 1908 | D22: 1492 | E22: 966 | F22: 555 | G22: 299
A23: ZWE | B23: 0 | C23: 433 | D23: 1110 | E23: 1165 | F23: 0 | G23: 0
A25: Grand Total | B25: 1978 | C25: 71678 | D25: 70804 | E25: 33872 | F25: 13146 | G25: 3440

Sheet Sheet3
A3: Count of 2020 | B3: Column Labels
A4: Row Labels | B4: BEN | C4: BWA | D4: CIV | E4: CPV | F4: DZA | G4: ERI | H4: GHA | I4: KEN | J4: MDG | K4: MOZ | L4: MWI | M4: SLE | N4: SWZ | O4: SYC | P4: TGO | Q4: UGA | R4: ZAF | S4: ZMB | T4: ZWE | U4: (blank) | V4: Grand Total
A5: BDI | B5: 1 | V5: 1
A6: BFA | C6: 1 | V6: 1
A7: BWA | D7: 1 | V7: 1
A8: GAB | E8: 1 | V8: 1
A9: GHA | F9: 1 | V9: 1
A10: MOZ | G10: 1 | V10: 1
A11: SEN | H11: 1 | V11: 1
A12: TCD | I12: 1 | V12: 1
A13: (blank) | J13: 1 | K13: 1 | L13: 1 | V13: 3
A14: Grand Total | B14: 1 | C14: 1 | D14: 1 | E14: 1 | F14: 1 | G14: 1 | H14: 1 | I14: 1 | J14: 1 | K14: 1 | L14: 1 | V14: 11

Sheet available
B1: Data on age group availability
A2: Country | B2: Data year
A3: AGO
A4: BDI | B4: 2019
A5: BEN | B5: 2021
A6: BFA | B6: 2022
A7: BWA | B7: 2022
A8: CAF
A9: CIV | B9: 2022
A10: CMR | B10: 2022
A11: COD
A12: COG | B12: 2022
A13: COM
A14: CPV | B14: 2022
A15: DZA | B15: 2018
A16: ERI | B16: 2022
A17: ETH
A18: GAB | B18: 2022
A19: GHA | B19: 2022
A20: GIN
A21: GMB
A22: GNB | B22: 2022
A23: GNQ
A24: KEN | B24: 2022
A25: LBR
A26: LSO
A27: MDG | B27: 2018
A28: MLI
A29: MOZ | B29: 2022
A30: MRT
A31: MUS
A32: MWI | B32: 2022
A33: NAM
A34: NER
A35: NGA | B35: 2022
A36: RWA
A37: SEN | B37: 2022
A38: SLE | B38: 2020
A39: SSD
A40: STP
...

Sheet Medical doctors
D1: Numbers | J1: Proportions
A2: Country | B2: Medical Doctors Stock By Age Group < 25 yrs | C2: Medical Doctors Stock By Age Group 25-34 yrs | D2: Medical Doctors Stock By Age Group 35-44 yrs | E2: Medical Doctors Stock By Age Group 45-54 yrs | F2: Medical Doctors Stock By Age Group 55-64 yrs | G2: Medical Doctors Stock By Age Group ≥ 65 yrs | H2: Total | I2: Medical Doctors Stock By Age Group < 25 yrs | J2: Medical Doctors Stock By Age Group 25-34 yrs | K2: Medical Doctors Stock By Age Group 35-44 yrs | L2: Medical Doctors Stock By Age Group 45-54 yrs | M2: Medical Doctors Stock By Age Group 55-64 yrs | N2: Medical Doctors Stock By Age Group ≥ 65 yrs
A3: AFR | B3: 989 | C3: 35839 | D3: 35402 | E3: 16936 | F3: 6573 | G3: 1720 | H3: =SUM(B3:G3) -> 97459 | I3: =B3/H3 -> 0.010147857 | J3: =C3/H3 -> 0.36773412 | K3: =D3/H3 -> 0.36325019 | L3: =E3/H3 -> 0.17377564 | M3: =F3/H3 -> 0.067443746 | N3: =G3/H3 -> 0.017648447
A4: BFA | B4: 0 | C4: 1138 | D4: 1088 | E4: 112 | F4: 33 | G4: 1 | H4: =SUM(B4:G4) -> 2372 | I4: =B4/H4 -> 0 | J4: =C4/H4 -> 0.47976391 | K4: =D4/H4 -> 0.45868465 | L4: =E4/H4 -> 0.047217538 | M4: =F4/H4 -> 0.01391231 | N4: =G4/H4 -> 0.00042158516
A5: BWA | C5: 483 | D5: 323 | E5: 121 | F5: 52 | G5: 14 | H5: =SUM(B5:G5) -> 993 | I5: =B5/H5 -> 0 | J5: =C5/H5 -> 0.48640483 | K5: =D5/H5 -> 0.32527694 | L5: =E5/H5 -> 0.12185297 | M5: =F5/H5 -> 0.052366566 | N5: =G5/H5 -> 0.014098691
A6: CIV | B6: 0 | C6: 920 | D6: 1757 | E6: 1583 | F6: 640 | G6: 29 | H6: =SUM(B6:G6) -> 4929 | I6: =B6/H6 -> 0 | J6: =C6/H6 -> 0.18665044 | K6: =D6/H6 -> 0.35646176 | L6: =E6/H6 -> 0.32116048 | M6: =F6/H6 -> 0.12984378 | N6: =G6/H6 -> 0.0058835464
A7: CMR | B7: 15 | C7: 1889 | D7: 1240 | E7: 454 | F7: 156 | G7: 8 | H7: =SUM(B7:G7) -> 3762 | I7: =B7/H7 -> 0.0039872408 | J7: =C7/H7 -> 0.50212653 | K7: =D7/H7 -> 0.32961191 | L7: =E7/H7 -> 0.12068049 | M7: =F7/H7 -> 0.041467305 | N7: =G7/H7 -> 0.0021265284
A8: COG | C8: 464 | D8: 312 | E8: 121 | F8: 137 | G8: 8 | H8: =SUM(B8:G8) -> 1042 | I8: =B8/H8 -> 0 | J8: =C8/H8 -> 0.4452975 | K8: =D8/H8 -> 0.29942418 | L8: =E8/H8 -> 0.11612284 | M8: =F8/H8 -> 0.13147793 | N8: =G8/H8 -> 0.0076775432
A9: CPV | B9: 11 | C9: 539 | D9: 801 | E9: 713 | F9: 452 | G9: 128 | H9: =SUM(B9:G9) -> 2644 | I9: =B9/H9 -> 0.0041603631 | J9: =C9/H9 -> 0.20385779 | K9: =D9/H9 -> 0.30295008 | L9: =E9/H9 -> 0.26966717 | M9: =F9/H9 -> 0.1709531 | N9: =G9/H9 -> 0.048411498
A10: ERI | C10: 175 | H10: =SUM(B10:G10) -> 175 | I10: =B10/H10 -> 0 | J10: =C10/H10 -> 1 | K10: =D10/H10 -> 0 | L10: =E10/H10 -> 0 | M10: =F10/H10 -> 0 | N10: =G10/H10 -> 0
A11: GAB | B11: 0 | C11: 248 | D11: 258 | E11: 379 | F11: 224 | G11: 28 | H11: =SUM(B11:G11) -> 1137 | I11: =B11/H11 -> 0 | J11: =C11/H11 -> 0.21811785 | K11: =D11/H11 -> 0.22691293 | L11: =E11/H11 -> 0.33333333 | M11: =F11/H11 -> 0.19700967 | N11: =G11/H11 -> 0.024626209
A12: GHA | B12: 2 | C12: 1715 | D12: 1942 | E12: 512 | F12: 184 | G12: 3 | H12: =SUM(B12:G12) -> 4358 | I12: =B12/H12 -> 0.00045892611 | J12: =C12/H12 -> 0.39352914 | K12: =D12/H12 -> 0.44561726 | L12: =E12/H12 -> 0.11748508 | M12: =F12/H12 -> 0.042221202 | N12: =G12/H12 -> 0.00068838917
A13: GNB | B13: 0 | C13: 229 | D13: 143 | E13: 41 | F13: 19 | G13: 5 | H13: =SUM(B13:G13) -> 437 | I13: =B13/H13 -> 0 | J13: =C13/H13 -> 0.52402746 | K13: =D13/H13 -> 0.32723112 | L13: =E13/H13 -> 0.09382151 | M13: =F13/H13 -> 0.043478261 | N13: =G13/H13 -> 0.011441648
A14: KEN | B14: 5 | C14: 1600 | D14: 2699 | E14: 941 | F14: 243 | G14: 6 | H14: =SUM(B14:G14) -> 5494 | I14: =B14/H14 -> 0.00091008373 | J14: =C14/H14 -> 0.29122679 | K14: =D14/H14 -> 0.4912632 | L14: =E14/H14 -> 0.17127776 | M14: =F14/H14 -> 0.044230069 | N14: =G14/H14 -> 0.0010921005
A15: MOZ | B15: 6 | C15: 784 | D15: 897 | E15: 416 | F15: 193 | G15: 50 | H15: =SUM(B15:G15) -> 2346 | I15: =B15/H15 -> 0.0025575448 | J15: =C15/H15 -> 0.33418585 | K15: =D15/H15 -> 0.38235294 | L15: =E15/H15 -> 0.1773231 | M15: =F15/H15 -> 0.08226769 | N15: =G15/H15 -> 0.021312873
A16: MWI | B16: 61 | C16: 392 | D16: 331 | E16: 213 | F16: 30 | G16: 13 | H16: =SUM(B16:G16) -> 1040 | I16: =B16/H16 -> 0.058653846 | J16: =C16/H16 -> 0.37692308 | K16: =D16/H16 -> 0.31826923 | L16: =E16/H16 -> 0.20480769 | M16: =F16/H16 -> 0.028846154 | N16: =G16/H16 -> 0.0125
A17: NGA | B17: 860 | C17: 21366 | D17: 19365 | E17: 8834 | F17: 3461 | G17: 1088 | H17: =SUM(B17:G17) -> 54974 | I17: =B17/H17 -> 0.015643759 | J17: =C17/H17 -> 0.38865646 | K17: =D17/H17 -> 0.35225743 | L17: =E17/H17 -> 0.16069415 | M17: =F17/H17 -> 0.062957034 | N17: =G17/H17 -> 0.019791174
A18: SEN | B18: 1 | C18: 338 | D18: 247 | E18: 64 | F18: 48 | G18: 5 | H18: =SUM(B18:G18) -> 703 | I18: =B18/H18 -> 0.0014224751 | J18: =C18/H18 -> 0.48079659 | K18: =D18/H18 -> 0.35135135 | L18: =E18/H18 -> 0.091038407 | M18: =F18/H18 -> 0.068278805 | N18: =G18/H18 -> 0.0071123755
A19: SWZ | C19: 116 | D19: 691 | H19: =SUM(B19:G19) -> 807 | I19: =B19/H19 -> 0 | J19: =C19/H19 -> 0.14374226 | K19: =D19/H19 -> 0.85625774 | L19: =E19/H19 -> 0 | M19: =F19/H19 -> 0 | N19: =G19/H19 -> 0
A20: SYC | C20: 9 | D20: 15 | E20: 17 | F20: 9 | G20: 7 | H20: =SUM(B20:G20) -> 57 | I20: =B20/H20 -> 0 | J20: =C20/H20 -> 0.15789474 | K20: =D20/H20 -> 0.26315789 | L20: =E20/H20 -> 0.29824561 | M20: =F20/H20 -> 0.15789474 | N20: =G20/H20 -> 0.12280702
A21: TCD | B21: 3 | C21: 880 | D21: 424 | E21: 129 | F21: 73 | G21: 0 | H21: =SUM(B21:G21) -> 1509 | I21: =B21/H21 -> 0.0019880716 | J21: =C21/H21 -> 0.58316766 | K21: =D21/H21 -> 0.28098078 | L21: =E21/H21 -> 0.085487078 | M21: =F21/H21 -> 0.048376408 | N21: =G21/H21 -> 0
A22: TGO | B22: 3 | C22: 213 | D22: 267 | E22: 155 | F22: 64 | G22: 28 | H22: =SUM(B22:G22) -> 730 | I22: =B22/H22 -> 0.004109589 | J22: =C22/H22 -> 0.29178082 | K22: =D22/H22 -> 0.36575342 | L22: =E22/H22 -> 0.21232877 | M22: =F22/H22 -> 0.087671233 | N22: =G22/H22 -> 0.038356164
A23: ZMB | B23: 22 | C23: 1908 | D23: 1492 | E23: 966 | F23: 555 | G23: 299 | H23: =SUM(B23:G23) -> 5242 | I23: =B23/H23 -> 0.0041968714 | J23: =C23/H23 -> 0.36398321 | K23: =D23/H23 -> 0.28462419 | L23: =E23/H23 -> 0.18428081 | M23: =F23/H23 -> 0.10587562 | N23: =G23/H23 -> 0.057039298
A24: ZWE | B24: 0 | C24: 433 | D24: 1110 | E24: 1165 | F24: 0 | G24: 0 | H24: =SUM(B24:G24) -> 2708 | I24: =B24/H24 -> 0 | J24: =C24/H24 -> 0.1598966 | K24: =D24/H24 -> 0.4098966 | L24: =E24/H24 -> 0.43020679 | M24: =F24/H24 -> 0 | N24: =G24/H24 -> 0
A25: BEN | B25: 34 | C25: 1115 | D25: 916 | E25: 458 | F25: 221 | G25: 11 | H25: =SUM(B25:G25) -> 2755 | I25: =B25/H25 -> 0.012341198 | J25: =C25/H25 -> 0.40471869 | K25: =D25/H25 -> 0.33248639 | L25: =E25/H25 -> 0.16624319 | M25: =F25/H25 -> 0.080217786 | N25: =G25/H25 -> 0.0039927405
A26: SLE | C26: 150 | H26: =SUM(B26:G26) -> 150 | I26: =B26/H26 -> 0 | J26: =C26/H26 -> 1 | K26: =D26/H26 -> 0 | L26: =E26/H26 -> 0 | M26: =F26/H26 -> 0 | N26: =G26/H26 -> 0
A27: BDI | B27: 0 | C27: 149 | D27: 396 | E27: 61 | F27: 19 | G27: 4 | H27: =SUM(B27:G27) -> 629 | I27: =B27/H27 -> 0 | J27: =C27/H27 -> 0.23688394 | K27: =D27/H27 -> 0.62957075 | L27: =E27/H27 -> 0.096979332 | M27: =F27/H27 -> 0.030206677 | N27: =G27/H27 -> 0.0063593005
A28: DZA | B28: 5956 | C28: 21368 | D28: 15146 | E28: 10017 | F28: 12552 | G28: 7565 | H28: =SUM(B28:G28) -> 72604 | I28: =B28/H28 -> 0.082034048 | J28: =C28/H28 -> 0.29430885 | K28: =D28/H28 -> 0.2086111 | L28: =E28/H28 -> 0.13796761 | M28: =F28/H28 -> 0.17288304 | N28: =G28/H28 -> 0.10419536

Sheet Doctors distribution
A1: Country | B1: Medical Doctors Stock By Age Group < 25 yrs | C1: Medical Doctors Stock By Age Group 25-34 yrs | D1: Medical Doctors Stock By Age Group 35-44 yrs | E1: Medical Doctors Stock By Age Group 45-54 yrs | F1: Medical Doctors Stock By Age Group 55-64 yrs | G1: Medical Doctors Stock By Age Group ≥ 65 yrs
A2: AFRO | B2: 0.010147857 | C2: 0.36773412 | D2: 0.36325019 | E2: 0.17377564 | F2: 0.067443746 | G2: 0.017648447
A3: BFA | B3: 0 | C3: 0.47976391 | D3: 0.45868465 | E3: 0.047217538 | F3: 0.01391231 | G3: 0.00042158516
A4: BWA | B4: 0 | C4: 0.48640483 | D4: 0.32527694 | E4: 0.12185297 | F4: 0.052366566 | G4: 0.014098691
A5: CIV | B5: 0 | C5: 0.18665044 | D5: 0.35646176 | E5: 0.32116048 | F5: 0.12984378 | G5: 0.0058835464
A6: CMR | B6: 0.0039872408 | C6: 0.50212653 | D6: 0.32961191 | E6: 0.12068049 | F6: 0.041467305 | G6: 0.0021265284
A7: COG | B7: 0 | C7: 0.4452975 | D7: 0.29942418 | E7: 0.11612284 | F7: 0.13147793 | G7: 0.0076775432
A8: CPV | B8: 0.0041603631 | C8: 0.20385779 | D8: 0.30295008 | E8: 0.26966717 | F8: 0.1709531 | G8: 0.048411498
A9: ERI | B9: 0 | C9: 1 | D9: 0 | E9: 0 | F9: 0 | G9: 0
A10: GAB | B10: 0 | C10: 0.21811785 | D10: 0.22691293 | E10: 0.33333333 | F10: 0.19700967 | G10: 0.024626209
A11: GHA | B11: 0.00045892611 | C11: 0.39352914 | D11: 0.44561726 | E11: 0.11748508 | F11: 0.042221202 | G11: 0.00068838917
A12: GNB | B12: 0 | C12: 0.52402746 | D12: 0.32723112 | E12: 0.09382151 | F12: 0.043478261 | G12: 0.011441648
A13: KEN | B13: 0.00091008373 | C13: 0.29122679 | D13: 0.4912632 | E13: 0.17127776 | F13: 0.044230069 | G13: 0.0010921005
... A27: DZA | B27: 0.082034048 | C27: 0.29430885 | D27: 0.2086111 | E27: 0.13796761 | F27: 0.17288304 | G27: 0.10419536
A215: Income level | B215: Medical Doctors Stock By Age Group < 25 yrs | C215: Medical Doctors Stock By Age Group 25-34 yrs | D215: Medical Doctors Stock By Age Group 35-44 yrs | E215: Medical Doctors Stock By Age Group 45-54 yrs | F215: Medical Doctors Stock By Age Group 55-64 yrs | G215: Medical Doctors Stock By Age Group ≥ 65 yrs
A216: High/Upper-Middle-Income Economies | B216: 0 | C216: 0.28747247 | D216: 0.27178259 | E216: 0.25114397 | F216: 0.13575699 | G216: 0.053843973
A217: Lower-Middle-Income Economies | B217: 0.009627305 | C217: 0.3275993 | D217: 0.3862164 | E217: 0.1759096 | F217: 0.080800436 | G217: 0.019846966
A218: Low-Income Economies | B218: 0.0084136314 | C218: 0.47834159 | D218: 0.34535536 | E218: 0.11474563 | F218: 0.041844842 | G218: 0.011298946
A219: AFRO | B219: 0.010147857 | C219: 0.36773412 | D219: 0.36325019 | E219: 0.17377564 | F219: 0.067443746 | G219: 0.017648447

Sheet Sheet10
A3: Row Labels | B3: Average of Medical Doctors Stock By Age Group < 25 yrs | C3: Average of Medical Doctors Stock By Age Group 25-34 yrs | D3: Average of Medical Doctors Stock By Age Group 35-44 yrs | E3: Average of Medical Doctors Stock By Age Group 45-54 yrs | F3: Average of Medical Doctors Stock By Age Group 55-64 yrs | G3: Average of Medical Doctors Stock By Age Group ≥ 65 yrs
A4: High/Upper-Middle-Income Economies | B4: 0 | C4: 0.28747247 | D4: 0.27178259 | E4: 0.25114397 | F4: 0.13575699 | G4: 0.053843973
A5: Lower-Middle-Income Economies | B5: 0.009627305 | C5: 0.3275993 | D5: 0.3862164 | E5: 0.1759096 | F5: 0.080800436 | G5: 0.019846966
A6: Low-Income Economies | B6: 0.0084136314 | C6: 0.47834159 | D6: 0.34535536 | E6: 0.11474563 | F6: 0.041844842 | G6: 0.011298946
A7: (blank) | B7: 0.010147857 | C7: 0.36773412 | D7: 0.36325019 | E7: 0.17377564 | F7: 0.067443746 | G7: 0.017648447
A8: Grand Total | B8: 0.0081044749 | C8: 0.37262701 | D8: 0.35849016 | E8: 0.16527989 | F8: 0.074395165 | G8: 0.0211033

Sheet Med 1
A1: Country | B1: Medical Doctors Stock By Age Group < 25 yrs | C1: Medical Doctors Stock By Age Group 25-34 yrs | D1: Medical Doctors Stock By Age Group 35-44 yrs | E1: Medical Doctors Stock By Age Group 45-54 yrs | F1: Medical Doctors Stock By Age Group 55-64 yrs | G1: Medical Doctors Stock By Age Group ≥ 65 yrs | H1: Income
A2: AFRO | B2: 0.010147857 | C2: 0.36773412 | D2: 0.36325019 | E2: 0.17377564 | F2: 0.067443746 | G2: 0.017648447
A3: BFA | B3: 0 | C3: 0.47976391 | D3: 0.45868465 | E3: 0.047217538 | F3: 0.01391231 | G3: 0.00042158516 | H3: Low-Income Economies
A4: BWA | B4: 0 | C4: 0.48640483 | D4: 0.32527694 | E4: 0.12185297 | F4: 0.052366566 | G4: 0.014098691 | H4: High/Upper-Middle-Income Economies
A5: CIV | B5: 0 | C5: 0.18665044 | D5: 0.35646176 | E5: 0.32116048 | F5: 0.12984378 | G5: 0.0058835464 | H5: Lower-Middle-Income Economies
A6: CMR | B6: 0.0039872408 | C6: 0.50212653 | D6: 0.32961191 | E6: 0.12068049 | F6: 0.041467305 | G6: 0.0021265284 | H6: Lower-Middle-Income Economies
A7: COG | B7: 0 | C7: 0.4452975 | D7: 0.29942418 | E7: 0.11612284 | F7: 0.13147793 | G7: 0.0076775432 | H7: Lower-Middle-Income Economies
A8: CPV | B8: 0.0041603631 | C8: 0.20385779 | D8: 0.30295008 | E8: 0.26966717 | F8: 0.1709531 | G8: 0.048411498 | H8: Lower-Middle-Income Economies
A9: GAB | B9: 0 | C9: 0.21811785 | D9: 0.22691293 | E9: 0.33333333 | F9: 0.19700967 | G9: 0.024626209 | H9: High/Upper-Middle-Income Economies
A10: GHA | B10: 0.00045892611 | C10: 0.39352914 | D10: 0.44561726 | E10: 0.11748508 | F10: 0.042221202 | G10: 0.00068838917 | H10: Lower-Middle-Income Economies
A11: GNB | B11: 0 | C11: 0.52402746 | D11: 0.32723112 | E11: 0.09382151 | F11: 0.043478261 | G11: 0.011441648 | H11: Low-Income Economies
A12: KEN | B12: 0.00091008373 | C12: 0.29122679 | D12: 0.4912632 | E12: 0.17127776 | F12: 0.044230069 | G12: 0.0010921005 | H12: Lower-Middle-Income Economies
A13: MOZ | B13: 0.0025575448 | C13: 0.33418585 | D13: 0.38235294 | E13: 0.1773231 | F13: 0.08226769 | G13: 0.021312873 | H13: Low-Income Economies
A14: MWI | B14: 0.058653846 | C14: 0.37692308 | D14: 0.31826923 | E14: 0.20480769 | F14: 0.028846154 | G14: 0.0125 | H14: Low-Income Economies
... A26: DZA | B26: 0.082034048 | C26: 0.29430885 | D26: 0.2086111 | E26: 0.13796761 | F26: 0.17288304 | G26: 0.10419536 | H26: Lower-Middle-Income Economies

Sheet Sheet1
A3: Row Labels | B3: Average of stock to graduates
A4: High/Upper-Middle-Income Economies | B4: 0.023071261
A5: Lower-Middle-Income Economies | B5: 0.045458619
A6: Low-Income Economies | B6: 0.091657526
A7: (blank) | B7: 0.039001563
A8: Grand Total | B8: 0.061646057

Sheet Sheet5
A1: Updated annual graduate | B1: (Multiple Items)
A3: Row Labels | B3: Sum of Updated annual graduate | C3: Sum of Adjusted 2022
A4: High/Upper-Middle-Income Economies | B4: 2788 | C4: 54811.728 | D4: =B4/C4 -> 0.050865027
A5: Lower-Middle-Income Economies | B5: 10106 | C5: 147581.62 | D5: =B5/C5 -> 0.068477361
A6: Low-Income Economies | B6: 16040 | C6: 77885.433 | D6: =B6/C6 -> 0.20594352
A7: Grand Total | B7: 28934 | C7: 280278.78 | D7: =B7/C7 -> 0.10323293

Sheet Total medical doctors
A1: Country | B1: Country code | C1: income level | D1: 2013 | E1: 2018 | F1: Adjusted 2022 | G1: Medical Doctors Stock By Age Group < 25 yrs (prop) | H1: Medical Doctors Stock By Age Group 25-34 yrs (prop) | I1: Medical Doctors Stock By Age Group 35-44 yrs (prop) | J1: Medical Doctors Stock By Age Group 45-54 yrs (prop) | K1: Medical Doctors Stock By Age Group 55-64 yrs (prop) | L1: Medical Doctors Stock By Age Group ≥ 65 yrs (prop) | M1: Medical Doctors Stock By Age Group < 25 yrs (prop) | N1: Medical Doctors Stock By Age Group 25-34 yrs | O1: Medical Doctors Stock By Age Group 35-44 yrs | P1: Medical Doctors Stock By Age Group 45-54 yrs | Q1: Medical Doctors Stock By Age Group 55-64 yrs | R1: Medical Doctors Stock By Age Group ≥ 65 yrs | S1: Annual graduates (2017 survey) | T1: Updated annual graduate | U1: Projected 2023 | V1: Projected 2024 | W1: Projected 2025 | X1: Projected 2026 | Y1: Projected 2027 | Z1: Projected 2028 | AA1: Projected 2029 | AB1: Projected 2030 | AC1: Force of movement from 55-64 into Age 65+ | AD1: stock to graduates | AE1: Estimated graduates | AF1: Migration | AG1: Migration Factor | AH1: Trajectory | AI1: Doctors Migration to Stock | AJ1: Doctors Above 55 year of age
A2: Algeria | B2: DZA | C2: Lower-Middle-Income Economies | D2: 0 | E2: 73168 | F2: 75512 | G2: 0.082034048 | H2: 0.29430885 | I2: 0.2086111 | J2: 0.13796761 | K2: 0.17288304 | L2: 0.10419536 | M2: =F2*G2 -> 6194.555 | N2: =F2*H2 -> 22223.85 | O2: =F2*I2 -> 15752.641 | P2: =F2*J2 -> 10418.21 | Q2: =F2*K2 -> 13054.744 | R2: =F2*L2 -> 7868.0001 | S2: =VLOOKUP(A2,'Education graduates'!$A$2:$E$49,5,FALSE) -> 0 | T2: =VLOOKUP(B2,'Edu updated'!B$2:C$48,2,FALSE) -> 0 | U2: =F2*(1-L2)+1*0.7*AE2-AG2*AF2 -> 70913.671 | V2: =U2*(1-AC2*K2)+0.7*AE2-AG2*AF2 -> 72957.365 | W2: =V2*(1-AC2*K2)+0.7*AE2-AG2*AF2 -> 74965.727 | X2: =W2*(1-AC2*K2)+0.7*AE2-AG2*AF2 -> 76939.368 | Y2: =X2*(1-AC2*K2)+0.7*AE2-AG2*AF2 -> 78878.888 | Z2: =Y2*(1-AC2*K2)+0.7*AE2-AG2*AF2 -> 80784.877 | AA2: =Z2*(1-AC2*K2)+0.7*AE2-AG2*AF2 -> 82657.915 | AB2: =AA2*(1-AC2*K2)+0.7*AE2-AG2*AF2 -> 84498.571 | AC2: 0.1 | AD2: 0.068 | AE2: =F2*AD2 -> 5134.816 | AF2: =VLOOKUP(B2,Migration!A$2:B$189,2,FALSE) -> 6494 | AG2: =1/20 -> 0.05 | AH2: =IF(AB2<U2,"Decrease","Increase") -> Increase | AI2: =AF2/E2 -> 0.088754647 | AJ2: =K2+L2 -> 0.2770784
A3: Angola | B3: AGO | C3: Lower-Middle-Income Economies | D3: 0 | E3: 6593 | F3: 8693 | G3: 0.009627305 | H3: 0.3275993 | I3: 0.3862164 | J3: 0.1759096 | K3: 0.080800436 | L3: 0.019846966 | M3: =F3*G3 -> 83.690162 | N3: =F3*H3 -> 2847.8207 | O3: =F3*I3 -> 3357.3792 | P3: =F3*J3 -> 1529.1821 | Q3: =F3*K3 -> 702.39819 | R3: =F3*L3 -> 172.52967 | S3: =VLOOKUP(A3,'Education graduates'!$A$3:$E$49,5,FALSE) -> 0 | T3: =VLOOKUP(B3,'Edu updated'!B$2:C$48,2,FALSE) -> 611 | U3: =F3*(1-L3)+1*0.7*AE3-AG3*AF3 -> 8932.0703 | V3: =U3*(1-AC3*K3)+0.7*AE3-AG3*AF3 -> 9271.4988 | W3: =V3*(1-AC3*K3)+0.7*AE3-AG3*AF3 -> 9608.1847 | X3: =W3*(1-AC3*K3)+0.7*AE3-AG3*AF3 -> 9942.1501 | Y3: =X3*(1-AC3*K3)+0.7*AE3-AG3*AF3 -> 10273.417 | Z3: =Y3*(1-AC3*K3)+0.7*AE3-AG3*AF3 -> 10602.007 | AA3: =Z3*(1-AC3*K3)+0.7*AE3-AG3*AF3 -> 10927.943 | AB3: =AA3*(1-AC3*K3)+0.7*AE3-AG3*AF3 -> 11251.245 | AC3: 0.1 | AD3: =T3/F3 -> 0.070286437 | AE3: =F3*AD3 -> 611 | AF3: =VLOOKUP(B3,Migration!A$2:B$189,2,FALSE) -> 322 | AG3: =1/20 -> 0.05 | AH3: =IF(AB3<U3,"Decrease","Increase") -> Increase | AI3: =AF3/F3 -> 0.037041298 | AJ3: =K3+L3 -> 0.1006474
A4: Benin | B4: BEN | C4: Lower-Middle-Income Economies | D4: 0 | E4: 908 | F4: 2608 | G4: 0.012341198 | H4: 0.40471869 | I4: 0.33248639 | J4: 0.16624319 | K4: 0.080217786 | L4: 0.0039927405 | M4: =F4*G4 -> 32.185844 | N4: =F4*H4 -> 1055.5064 | O4: =F4*I4 -> 867.1245 | P4: =F4*J4 -> 433.56225 | Q4: =F4*K4 -> 209.20799 | R4: =F4*L4 -> 10.413067 | S4: =VLOOKUP(A4,'Education graduates'!$A$3:$E$49,5,FALSE) -> 291 | T4: =VLOOKUP(B4,'Edu updated'!B$2:C$48,2,FALSE) -> 780 | U4: =F4*(1-L4)+1*0.7*AE4-AG4*AF4 -> 3134.9369 | V4: =U4*(1-AC4*K4)+0.7*AE4-AG4*AF4 -> 3647.1392 | W4: =V4*(1-AC4*K4)+0.7*AE4-AG4*AF4 -> 4155.2326 | X4: =W4*(1-AC4*K4)+0.7*AE4-AG4*AF4 -> 4659.2503 | Y4: =X4*(1-AC4*K4)+0.7*AE4-AG4*AF4 -> 5159.2248 | Z4: =Y4*(1-AC4*K4)+0.7*AE4-AG4*AF4 -> 5655.1886 | AA4: =Z4*(1-AC4*K4)+0.7*AE4-AG4*AF4 -> 6147.174 | AB4: =AA4*(1-AC4*K4)+0.7*AE4-AG4*AF4 -> 6635.2127 | AC4: 0.1 | AD4: =T4/F4 -> 0.29907975 | AE4: =F4*AD4 -> 780 | AF4: =VLOOKUP(B4,Migration!A$2:B$189,2,FALSE) -> 173 | AG4: =1/20 -> 0.05 | AH4: =IF(AB4<U4,"Decrease","Increase") -> Increase | AI4: =AF4/F4 -> 0.066334356 | AJ4: =K4+L4 -> 0.084210526
A5: Botswana | B5: BWA | C5: High/Upper-Middle-Income Economies | D5: 819 | E5: 925 | F5: 992 | G5: 0 | H5: 0.48640483 | I5: 0.32527694 | J5: 0.12185297 | K5: 0.052366566 | L5: 0.014098691 | M5: =F5*G5 -> 0 | N5: =F5*H5 -> 482.5136 | O5: =F5*I5 -> 322.67472 | P5: =F5*J5 -> 120.87815 | Q5: =F5*K5 -> 51.947633 | R5: =F5*L5 -> 13.985901 | S5: =VLOOKUP(A5,'Education graduates'!$A$3:$E$49,5,FALSE) -> 8 | T5: =VLOOKUP(B5,'Edu updated'!B$2:C$48,2,FALSE) -> 60 | U5: =F5*(1-L5)+1*0.7*AE5-AG5*AF5 -> 1019.0641 | V5: =U5*(1-AC5*K5)+0.7*AE5-AG5*AF5 -> 1054.7776 | W5: =V5*(1-AC5*K5)+0.7*AE5-AG5*AF5 -> 1090.3041 | X5: =W5*(1-AC5*K5)+0.7*AE5-AG5*AF5 -> 1125.6446 | Y5: =X5*(1-AC5*K5)+0.7*AE5-AG5*AF5 -> 1160.7999 | Z5: =Y5*(1-AC5*K5)+0.7*AE5-AG5*AF5 -> 1195.7712 | AA5: =Z5*(1-AC5*K5)+0.7*AE5-AG5*AF5 -> 1230.5594 | AB5: =AA5*(1-AC5*K5)+0.7*AE5-AG5*AF5 -> 1265.1654 | AC5: 0.1 | AD5: =T5/F5 -> 0.060483871 | AE5: =F5*AD5 -> 60 | AF5: =VLOOKUP(B5,Migration!A$2:B$189,2,FALSE) -> 19 | AG5: =1/20 -> 0.05 | AH5: =IF(AB5<U5,"Decrease","Increase") -> Increase | AI5: =AF5/F5 -> 0.019153226 | AJ5: =K5+L5 -> 0.066465257
A6: Burkina Faso | B6: BFA | C6: Low-Income Economies | D6: 803 | E6: 1684 | F6: 3323 | G6: 0 | H6: 0.47976391 | I6: 0.45868465 | J6: 0.047217538 | K6: 0.01391231 | L6: 0.00042158516 | M6: =F6*G6 -> 0 | N6: =F6*H6 -> 1594.2555 | O6: =F6*I6 -> 1524.2091 | P6: =F6*J6 -> 156.90388 | Q6: =F6*K6 -> 46.230607 | R6: =F6*L6 -> 1.4009275 | S6: =VLOOKUP(A6,'Education graduates'!$A$3:$E$49,5,FALSE) -> 578 | T6: =VLOOKUP(B6,'Edu updated'!B$2:C$48,2,FALSE) -> 1492 | U6: =F6*(1-L6)+1*0.7*AE6-AG6*AF6 -> 4363.2491 | V6: =U6*(1-AC6*K6)+0.7*AE6-AG6*AF6 -> 5398.8288 | W6: =V6*(1-AC6*K6)+0.7*AE6-AG6*AF6 -> 6432.9678 | X6: =W6*(1-AC6*K6)+0.7*AE6-AG6*AF6 -> 7465.668 | Y6: =X6*(1-AC6*K6)+0.7*AE6-AG6*AF6 -> 8496.9316 | Z6: =Y6*(1-AC6*K6)+0.7*AE6-AG6*AF6 -> 9526.7604 | AA6: =Z6*(1-AC6*K6)+0.7*AE6-AG6*AF6 -> 10555.156 | AB6: =AA6*(1-AC6*K6)+0.7*AE6-AG6*AF6 -> 11582.122 | AC6: 0.1 | AD6: =T6/F6 -> 0.44899187 | AE6: =F6*AD6 -> 1492 | AF6: =VLOOKUP(B6,Migration!A$2:B$189,2,FALSE) -> 55 | AG6: =1/20 -> 0.05 | AH6: =IF(AB6<U6,"Decrease","Increase") -> Increase | AI6: =AF6/F6 -> 0.016551309 | AJ6: =K6+L6 -> 0.014333895
A7: Burundi | B7: BDI | C7: Low-Income Economies | D7: 554 | E7: 1084 | F7: 1014.861 | G7: 0 | H7: 0.23688394 | I7: 0.62957075 | J7: 0.096979332 | K7: 0.030206677 | L7: 0.0063593005 | M7: =F7*G7 -> 0 | N7: =F7*H7 -> 240.40428 | O7: =F7*I7 -> 638.92682 | P7: =F7*J7 -> 98.420546 | Q7: =F7*K7 -> 30.65558 | R7: =F7*L7 -> 6.4538063 | S7: =VLOOKUP(A7,'Education graduates'!$A$3:$E$49,5,FALSE) -> 319 | T7: =VLOOKUP(B7,'Edu updated'!B$2:C$48,2,FALSE) -> 325 | U7: =F7*(1-L7)+1*0.7*AE7-AG7*AF7 -> 1229.3072 | V7: =U7*(1-AC7*K7)+0.7*AE7-AG7*AF7 -> 1446.4939 | W7: =V7*(1-AC7*K7)+0.7*AE7-AG7*AF7 -> 1663.0245 | X7: =W7*(1-AC7*K7)+0.7*AE7-AG7*AF7 -> 1878.9011 | Y7: =X7*(1-AC7*K7)+0.7*AE7-AG7*AF7 -> 2094.1255 | Z7: =Y7*(1-AC7*K7)+0.7*AE7-AG7*AF7 -> 2308.6999 | AA7: =Z7*(1-AC7*K7)+0.7*AE7-AG7*AF7 -> 2522.6261 | AB7: =AA7*(1-AC7*K7)+0.7*AE7-AG7*AF7 -> 2735.9061 | AC7: 0.1 | AD7: =T7/F7 -> 0.32024089 | AE7: =F7*AD7 -> 325 | AF7: =VLOOKUP(B7,Migration!A$2:B$189,2,FALSE) -> 132 | AG7: =1/20 -> 0.05 | AH7: =IF(AB7<U7,"Decrease","Increase") -> Increase | AI7: =AF7/F7 -> 0.13006707 | AJ7: =K7+L7 -> 0.036565978
A8: Cameroon | B8: CMR | C8: Lower-Middle-Income Economies | D8: 1842 | E8: 3259 | F8: 3759 | G8: 0.0039872408 | H8: 0.50212653 | I8: 0.32961191 | J8: 0.12068049 | K8: 0.041467305 | L8: 0.0021265284 | M8: =F8*G8 -> 14.988038 | N8: =F8*H8 -> 1887.4936 | O8: =F8*I8 -> 1239.0112 | P8: =F8*J8 -> 453.63796 | Q8: =F8*K8 -> 155.8756 | R8: =F8*L8 -> 7.9936204 | S8: =VLOOKUP(A8,'Education graduates'!$A$3:$E$49,5,FALSE) -> 0 | T8: =VLOOKUP(B8,'Edu updated'!B$2:C$48,2,FALSE) -> 800 | U8: =F8*(1-L8)+1*0.7*AE8-AG8*AF8 -> 4289.0564 | V8: =U8*(1-AC8*K8)+0.7*AE8-AG8*AF8 -> 4809.3208 | W8: =V8*(1-AC8*K8)+0.7*AE8-AG8*AF8 -> 5327.4279 | X8: =W8*(1-AC8*K8)+0.7*AE8-AG8*AF8 -> 5843.3865 | Y8: =X8*(1-AC8*K8)+0.7*AE8-AG8*AF8 -> 6357.2055 | Z8: =Y8*(1-AC8*K8)+0.7*AE8-AG8*AF8 -> 6868.8939 | AA8: =Z8*(1-AC8*K8)+0.7*AE8-AG8*AF8 -> 7378.4604 | AB8: =AA8*(1-AC8*K8)+0.7*AE8-AG8*AF8 -> 7885.9139 | AC8: 0.1 | AD8: =T8/F8 -> 0.21282256 | AE8: =F8*AD8 -> 800 | AF8: =VLOOKUP(B8,Migration!A$2:B$189,2,FALSE) -> 439 | AG8: =1/20 -> 0.05 | AH8: =IF(AB8<U8,"Decrease","Increase") -> Increase | AI8: =AF8/F8 -> 0.11678638 | AJ8: =K8+L8 -> 0.043593833
A9: Cape-Verde | B9: CPV | C9: Lower-Middle-Income Economies | D9: 308 | E9: 452 | F9: 2644 | G9: 0.0041603631 | H9: 0.20385779 | I9: 0.30295008 | J9: 0.26966717 | K9: 0.1709531 | L9: 0.048411498 | M9: =F9*G9 -> 11 | N9: =F9*H9 -> 539 | O9: =F9*I9 -> 801 | P9: =F9*J9 -> 713 | Q9: =F9*K9 -> 452 | R9: =F9*L9 -> 128 | S9: =VLOOKUP(A9,'Education graduates'!$A$3:$E$49,5,FALSE) -> 0 | T9: =VLOOKUP(B9,'Edu updated'!B$2:C$48,2,FALSE) -> 0 | U9: =F9*(1-L9)+1*0.7*AE9-AG9*AF9 -> 2638.8544 | V9: =U9*(1-AC9*K9)+0.7*AE9-AG9*AF9 -> 2716.5968 | W9: =V9*(1-AC9*K9)+0.7*AE9-AG9*AF9 -> 2793.0101 | X9: =W9*(1-AC9*K9)+0.7*AE9-AG9*AF9 -> 2868.1171 | Y9: =X9*(1-AC9*K9)+0.7*AE9-AG9*AF9 -> 2941.9402 | Z9: =Y9*(1-AC9*K9)+0.7*AE9-AG9*AF9 -> 3014.5012 | AA9: =Z9*(1-AC9*K9)+0.7*AE9-AG9*AF9 -> 3085.8218 | AB9: =AA9*(1-AC9*K9)+0.7*AE9-AG9*AF9 -> 3155.9231 | AC9: 0.1 | AD9: 0.068 | AE9: =F9*AD9 -> 179.792 | AF9: =VLOOKUP(B9,Migration!A$2:B$189,2,FALSE) -> 60 | AG9: =1/20 -> 0.05 | AH9: =IF(AB9<U9,"Decrease","Increase") -> Increase | AI9: =AF9/F9 -> 0.02269289 | AJ9: =K9+L9 -> 0.2193646
A10: Central African Republic | B10: CAF | C10: Low-Income Economies | D10: 324 | E10: 335 | F10: 146.38958 | G10: 0.0084136314 | H10: 0.47834159 | I10: 0.34535536 | J10: 0.11474563 | K10: 0.041844842 | L10: 0.011298946 | M10: =F10*G10 -> 1.231668 | N10: =F10*H10 -> 70.024224 | O10: =F10*I10 -> 50.556426 | P10: =F10*J10 -> 16.797564 | Q10: =F10*K10 -> 6.1256487 | R10: =F10*L10 -> 1.654048 | S10: =VLOOKUP(A10,'Education graduates'!$A$3:$E$49,5,FALSE) -> 0 | T10: =VLOOKUP(B10,'Edu updated'!B$2:C$48,2,FALSE) -> 18 | U10: =F10*(1-L10)+1*0.7*AE10-AG10*AF10 -> 156.28553 | V10: =U10*(1-AC10*K10)+0.7*AE10-AG10*AF10 -> 167.18156 | W10: =V10*(1-AC10*K10)+0.7*AE10-AG10*AF10 -> 178.03199 | X10: =W10*(1-AC10*K10)+0.7*AE10-AG10*AF10 -> 188.83702 | Y10: =X10*(1-AC10*K10)+0.7*AE10-AG10*AF10 -> 199.59683 | Z10: =Y10*(1-AC10*K10)+0.7*AE10-AG10*AF10 -> 210.31162 | AA10: =Z10*(1-AC10*K10)+0.7*AE10-AG10*AF10 -> 220.98157 | AB10: =AA10*(1-AC10*K10)+0.7*AE10-AG10*AF10 -> 231.60688 | AC10: 0.1 | AD10: =T10/F10 -> 0.12295957 | AE10: =F10*AD10 -> 18 | AF10: =VLOOKUP(B10,Migration!A$2:B$189,2,FALSE) -> 21 | AG10: =1/20 -> 0.05 | AH10: =IF(AB10<U10,"Decrease","Increase") -> Increase | AI10: =AF10/F10 -> 0.14345283 | AJ10: =K10+L10 -> 0.053143788
A11: Chad | B11: TCD | C11: Low-Income Economies | D11: 573 | E11: 803 | F11: 1507 | G11: 0.0019880716 | H11: 0.58316766 | I11: 0.28098078 | J11: 0.085487078 | K11: 0.048376408 | L11: 0 | M11: =F11*G11 -> 2.9960239 | N11: =F11*H11 -> 878.83366 | O11: =F11*I11 -> 423.43804 | P11: =F11*J11 -> 128.82903 | Q11: =F11*K11 -> 72.903247 | R11: =F11*L11 -> 0 | S11: =VLOOKUP(A11,'Education graduates'!$A$3:$E$49,5,FALSE) -> 113 | T11: =VLOOKUP(B11,'Edu updated'!B$2:C$48,2,FALSE) -> 330 | U11: =F11*(1-L11)+1*0.7*AE11-AG11*AF11 -> 1737.3 | V11: =U11*(1-AC11*K11)+0.7*AE11-AG11*AF11 -> 1959.1956 | W11: =V11*(1-AC11*K11)+0.7*AE11-AG11*AF11 -> 2180.0177 | X11: =W11*(1-AC11*K11)+0.7*AE11-AG11*AF11 -> 2399.7715 | Y11: =X11*(1-AC11*K11)+0.7*AE11-AG11*AF11 -> 2618.4623 | Z11: =Y11*(1-AC11*K11)+0.7*AE11-AG11*AF11 -> 2836.0951 | AA11: =Z11*(1-AC11*K11)+0.7*AE11-AG11*AF11 -> 3052.6751 | AB11: =AA11*(1-AC11*K11)+0.7*AE11-AG11*AF11 -> 3268.2074 | AC11: 0.1 | AD11: =T11/F11 -> 0.2189781 | AE11: =F11*AD11 -> 330 | AF11: =VLOOKUP(B11,Migration!A$2:B$189,2,FALSE) -> 14 | AG11: =1/20 -> 0.05 | AH11: =IF(AB11<U11,"Decrease","Increase") -> Increase | AI11: =AF11/F11 -> 0.0092899801 | AJ11: =K11+L11 -> 0.048376408
A12: Comoros | B12: COM | C12: Lower-Middle-Income Economies | D12: 123 | E12: 220 | F12: 354 | G12: 0.009627305 | H12: 0.3275993 | I12: 0.3862164 | J12: 0.1759096 | K12: 0.080800436 | L12: 0.019846966 | M12: =F12*G12 -> 3.408066 | N12: =F12*H12 -> 115.97015 | O12: =F12*I12 -> 136.72061 | P12: =F12*J12 -> 62.271998 | Q12: =F12*K12 -> 28.603354 | R12: =F12*L12 -> 7.0258259 | S12: =VLOOKUP(A12,'Education graduates'!$A$3:$E$49,5,FALSE) -> 0 | T12: =VLOOKUP(B12,'Edu updated'!B$2:C$48,2,FALSE) -> 0 | U12: =F12*(1-L12)+1*0.7*AE12-AG12*AF12 -> 363.62457 | V12: =U12*(1-AC12*K12)+0.7*AE12-AG12*AF12 -> 377.33687 | W12: =V12*(1-AC12*K12)+0.7*AE12-AG12*AF12 -> 390.93837 | X12: =W12*(1-AC12*K12)+0.7*AE12-AG12*AF12 -> 404.42997 | Y12: =X12*(1-AC12*K12)+0.7*AE12-AG12*AF12 -> 417.81256 | Z12: =Y12*(1-AC12*K12)+0.7*AE12-AG12*AF12 -> 431.08702 | AA12: =Z12*(1-AC12*K12)+0.7*AE12-AG12*AF12 -> 444.25422 | AB12: =AA12*(1-AC12*K12)+0.7*AE12-AG12*AF12 -> 457.31502 | AC12: 0.1 | AD12: 0.068 | AE12: =F12*AD12 -> 24.072 | AF12: =VLOOKUP(B12,Migration!A$2:B$189,2,FALSE) -> 4 | AG12: =1/20 -> 0.05 | AH12: =IF(AB12<U12,"Decrease","Increase") -> Increase | AI12: =AF12/F12 -> 0.011299435 | AJ12: =K12+L12 -> 0.1006474
A13: Congo | B13: COG | C13: Lower-Middle-Income Economies | D13: 0 | E13: 544 | F13: 1042 | G13: 0 | H13: 0.4452975 | I13: 0.29942418 | J13: 0.11612284 | K13: 0.13147793 | L13: 0.0076775432 | M13: =F13*G13 -> 0 | N13: =F13*H13 -> 464 | O13: =F13*I13 -> 312 | P13: =F13*J13 -> 121 | Q13: =F13*K13 -> 137 | R13: =F13*L13 -> 8 | S13: =VLOOKUP(A13,'Education graduates'!$A$3:$E$49,5,FALSE) -> 39 | T13: =VLOOKUP(B13,'Edu updated'!B$2:C$48,2,FALSE) -> 60 | U13: =F13*(1-L13)+1*0.7*AE13-AG13*AF13 -> 1063.4 | V13: =U13*(1-AC13*K13)+0.7*AE13-AG13*AF13 -> 1078.8186 | W13: =V13*(1-AC13*K13)+0.7*AE13-AG13*AF13 -> 1094.0346 | X13: =W13*(1-AC13*K13)+0.7*AE13-AG13*AF13 -> 1109.0504 | Y13: =X13*(1-AC13*K13)+0.7*AE13-AG13*AF13 -> 1123.8688 | Z13: =Y13*(1-AC13*K13)+0.7*AE13-AG13*AF13 -> 1138.4925 | AA13: =Z13*(1-AC13*K13)+0.7*AE13-AG13*AF13 -> 1152.9238 | AB13: =AA13*(1-AC13*K13)+0.7*AE13-AG13*AF13 -> 1167.1654 | AC13: 0.1 | AD13: =T13/F13 -> 0.057581574 | AE13: =F13*AD13 -> 60 | AF13: =VLOOKUP(B13,Migration!A$2:B$189,2,FALSE) -> 252 | AG13: =1/20 -> 0.05 | AH13: =IF(AB13<U13,"Decrease","Increase") -> Increase | AI13: =AF13/F13 -> 0.24184261 | AJ13: =K13+L13 -> 0.13915547
A14: Cote d'Ivoire | B14: CIV | C14: Lower-Middle-Income Economies | D14: 5240 | E14: 5602 | F14: 6327.552 | G14: 0 | H14: 0.18665044 | I14: 0.35646176 | J14: 0.32116048 | K14: 0.12984378 | L14: 0.0058835464 | M14: =F14*G14 -> 0 | N14: =F14*H14 -> 1181.0403 | O14: =F14*I14 -> 2255.5303 | P14: =F14*J14 -> 2032.1596 | Q14: =F14*K14 -> 821.59328 | R14: =F14*L14 -> 37.228445 | S14: =VLOOKUP(A14,'Education graduates'!$A$3:$E$49,5,FALSE) -> 265 | T14: =VLOOKUP(B14,'Edu updated'!B$2:C$48,2,FALSE) -> 254 | U14: =F14*(1-L14)+1*0.7*AE14-AG14*AF14 -> 6457.0235 | V14: =U14*(1-AC14*K14)+0.7*AE14-AG14*AF14 -> 6539.8831 | W14: =V14*(1-AC14*K14)+0.7*AE14-AG14*AF14 -> 6621.6668 | X14: =W14*(1-AC14*K14)+0.7*AE14-AG14*AF14 -> 6702.3886 | Y14: =X14*(1-AC14*K14)+0.7*AE14-AG14*AF14 -> 6782.0622 | Z14: =Y14*(1-AC14*K14)+0.7*AE14-AG14*AF14 -> 6860.7013 | AA14: =Z14*(1-AC14*K14)+0.7*AE14-AG14*AF14 -> 6938.3194 | AB14: =AA14*(1-AC14*K14)+0.7*AE14-AG14*AF14 -> 7014.9296 | AC14: 0.1 | AD14: =T14/F14 -> 0.040141907 | AE14: =F14*AD14 -> 254 | AF14: =VLOOKUP(B14,Migration!A$2:B$189,2,FALSE) -> 222 | AG14: =1/20 -> 0.05 | AH14: =IF(AB14<U14,"Decrease","Increase") -> Increase | AI14: =AF14/F14 -> 0.035084658 | AJ14: =K14+L14 -> 0.13572733
A15: DRC | B15: COD | C15: Low-Income Economies | D15: 6418 | E15: 31546 | F15: 21289.959 | G15: 0.0084136314 | H15: 0.47834159 | I15: 0.34535536 | J15: 0.11474563 | K15: 0.041844842 | L15: 0.011298946 | M15: =F15*G15 -> 179.12587 | N15: =F15*H15 -> 10183.873 | O15: =F15*I15 -> 7352.6014 | P15: =F15*J15 -> 2442.9297 | Q15: =F15*K15 -> 890.87495 | R15: =F15*L15 -> 240.5541 | S15: =VLOOKUP(A15,'Education graduates'!$A$3:$E$49,5,FALSE) -> 27 | T15: =VLOOKUP(B15,'Edu updated'!B$2:C$48,2,FALSE) -> 6020 | U15: =F15*(1-L15)+1*0.7*AE15-AG15*AF15 -> 25247.955 | V15: =U15*(1-AC15*K15)+0.7*AE15-AG15*AF15 -> 29340.855 | W15: =V15*(1-AC15*K15)+0.7*AE15-AG15*AF15 -> 33416.629 | X15: =W15*(1-AC15*K15)+0.7*AE15-AG15*AF15 -> 37475.347 | Y15: =X15*(1-AC15*K15)+0.7*AE15-AG15*AF15 -> 41517.082 | Z15: =Y15*(1-AC15*K15)+0.7*AE15-AG15*AF15 -> 45541.905 | AA15: =Z15*(1-AC15*K15)+0.7*AE15-AG15*AF15 -> 49549.885 | AB15: =AA15*(1-AC15*K15)+0.7*AE15-AG15*AF15 -> 53541.095 | AC15: 0.1 | AD15: =T15/F15 -> 0.28276241 | AE15: =F15*AD15 -> 6020 | AF15: =VLOOKUP(B15,Migration!A$2:B$189,2,FALSE) -> 309 | AG15: =1/20 -> 0.05 | AH15: =IF(AB15<U15,"Decrease","Increase") -> Increase | AI15: =AF15/F15 -> 0.014513884 | AJ15: =K15+L15 -> 0.053143788
A16: Equatorial Guinea | B16: GNQ | C16: High/Upper-Middle-Income Economies | D16: 0 | E16: 246 | F16: 274.68238 | G16: 0 | H16: 0.28747247 | I16: 0.27178259 | J16: 0.25114397 | K16: 0.13575699 | L16: 0.053843973 | M16: =F16*G16 -> 0 | N16: =F16*H16 -> 78.963622 | O16: =F16*I16 -> 74.653887 | P16: =F16*J16 -> 68.984823 | Q16: =F16*K16 -> 37.290053 | R16: =F16*L16 -> 14.78999 | S16: =VLOOKUP(A16,'Education graduates'!$A$3:$E$49,5,FALSE) -> 0 | T16: =VLOOKUP(B16,'Edu updated'!B$2:C$48,2,FALSE) -> 767 | U16: =F16*(1-L16)+1*0.7*AE16-AG16*AF16 -> 796.74239 | V16: =U16*(1-AC16*K16)+0.7*AE16-AG16*AF16 -> 1322.7761 | W16: =V16*(1-AC16*K16)+0.7*AE16-AG16*AF16 -> 1841.6684 | X16: =W16*(1-AC16*K16)+0.7*AE16-AG16*AF16 -> 2353.5165 | Y16: =X16*(1-AC16*K16)+0.7*AE16-AG16*AF16 -> 2858.4159 | Z16: =Y16*(1-AC16*K16)+0.7*AE16-AG16*AF16 -> 3356.4609 | AA16: =Z16*(1-AC16*K16)+0.7*AE16-AG16*AF16 -> 3847.7446 | AB16: =AA16*(1-AC16*K16)+0.7*AE16-AG16*AF16 -> 4332.3588 | AC16: 0.1 | AD16: =T16/F16 -> 2.792316 | AE16: =F16*AD16 -> 767 | AF16: =VLOOKUP(B16,Migration!A$2:B$189,2,FALSE) -> 1 | AG16: =1/20 -> 0.05 | AH16: =IF(AB16<U16,"Decrease","Increase") -> Increase | AI16: =AF16/F16 -> 0.0036405685 | AJ16: =K16+L16 -> 0.18960097
A17: Eritrea | B17: ERI | C17: Low-Income Economies | D17: 172 | E17: 280 | F17: 298.81765 | G17: 0.0084136314 | H17: 0.47834159 | I17: 0.34535536 | J17: 0.11474563 | K17: 0.041844842 | L17: 0 | M17: =F17*G17 -> 2.5141416 | N17: =F17*H17 -> 142.93691 | O17: =F17*I17 -> 103.19828 | P17: =F17*J17 -> 34.288018 | Q17: =F17*K17 -> 12.503977 | R17: =F17*L17 -> 0 | S17: =VLOOKUP(A17,'Education graduates'!$A$3:$E$49,5,FALSE) -> 45 | T17: =VLOOKUP(B17,'Edu updated'!B$2:C$48,2,FALSE) -> 0 | U17: =F17*(1-L17)+1*0.7*AE17-AG17*AF17 -> 341.60715 | V17: =U17*(1-AC17*K17)+0.7*AE17-AG17*AF17 -> 382.96721 | W17: =V17*(1-AC17*K17)+0.7*AE17-AG17*AF17 -> 424.15419 | X17: =W17*(1-AC17*K17)+0.7*AE17-AG17*AF17 -> 465.16883 | Y17: =X17*(1-AC17*K17)+0.7*AE17-AG17*AF17 -> 506.01184 | Z17: =Y17*(1-AC17*K17)+0.7*AE17-AG17*AF17 -> 546.68395 | AA17: =Z17*(1-AC17*K17)+0.7*AE17-AG17*AF17 -> 587.18586 | AB17: =AA17*(1-AC17*K17)+0.7*AE17-AG17*AF17 -> 627.5183 | AC17: 0.1 | AD17: 0.206 | AE17: =F17*AD17 -> 61.556435 | AF17: =VLOOKUP(B17,Migration!A$2:B$189,2,FALSE) -> 6 | AG17: =1/20 -> 0.05 | AH17: =IF(AB17<U17,"Decrease","Increase") -> Increase | AI17: =AF17/F17 -> 0.020079135 | AJ17: =K17+L17 -> 0.041844842
A18: Eswatini | B18: SWZ | C18: Lower-Middle-Income Economies | D18: 0 | E18: 278 | F18: 687 | G18: 0 | H18: 0.14374226 | I18: 0.85625774 | J18: 0 | K18: 0 | L18: 0 | M18: =F18*G18 -> 0 | N18: =F18*H18 -> 98.750929 | O18: =F18*I18 -> 588.24907 | P18: =F18*J18 -> 0 | Q18: =F18*K18 -> 0 | R18: =F18*L18 -> 0 | S18: =VLOOKUP(A18,'Education graduates'!$A$3:$E$49,5,FALSE) -> 0 | T18: =VLOOKUP(B18,'Edu updated'!B$2:C$48,2,FALSE) -> 0 | U18: =F18*(1-L18)+1*0.7*AE18-AG18*AF18 -> 719.1012 | V18: =U18*(1-AC18*K18)+0.7*AE18-AG18*AF18 -> 751.2024 | W18: =V18*(1-AC18*K18)+0.7*AE18-AG18*AF18 -> 783.3036 | X18: =W18*(1-AC18*K18)+0.7*AE18-AG18*AF18 -> 815.4048 | Y18: =X18*(1-AC18*K18)+0.7*AE18-AG18*AF18 -> 847.506 | Z18: =Y18*(1-AC18*K18)+0.7*AE18-AG18*AF18 -> 879.6072 | AA18: =Z18*(1-AC18*K18)+0.7*AE18-AG18*AF18 -> 911.7084 | AB18: =AA18*(1-AC18*K18)+0.7*AE18-AG18*AF18 -> 943.8096 | AC18: 0.1 | AD18: 0.068 | AE18: =F18*AD18 -> 46.716 | AF18: =VLOOKUP(B18,Migration!A$2:B$189,2,FALSE) -> 12 | AG18: =1/20 -> 0.05 | AH18: =IF(AB18<U18,"Decrease","Increase") -> Increase | AI18: =AF18/F18 -> 0.017467249 | AJ18: =K18+L18 -> 0
A19: Ethiopia | B19: ETH | C19: Low-Income Economies | D19: 0 | E19: 11263 | F19: 23741 | G19: 0.0084136314 | H19: 0.47834159 | I19: 0.34535536 | J19: 0.11474563 | K19: 0.041844842 | L19: 0.011298946 | M19: =F19*G19 -> 199.74802 | N19: =F19*H19 -> 11356.308 | O19: =F19*I19 -> 8199.0817 | P19: =F19*J19 -> 2724.1759 | Q19: =F19*K19 -> 993.43839 | R19: =F19*L19 -> 268.24828 | S19: =VLOOKUP(A19,'Education graduates'!$A$3:$E$49,5,FALSE) -> 2936 | T19: =VLOOKUP(B19,'Edu updated'!B$2:C$48,2,FALSE) -> 3114 | U19: =F19*(1-L19)+1*0.7*AE19-AG19*AF19 -> 25611.302 | V19: =U19*(1-AC19*K19)+0.7*AE19-AG19*AF19 -> 27642.682 | W19: =V19*(1-AC19*K19)+0.7*AE19-AG19*AF19 -> 29665.561 | X19: =W19*(1-AC19*K19)+0.7*AE19-AG19*AF19 -> 31679.976 | Y19: =X19*(1-AC19*K19)+0.7*AE19-AG19*AF19 -> 33685.962 | Z19: =Y19*(1-AC19*K19)+0.7*AE19-AG19*AF19 -> 35683.553 | AA19: =Z19*(1-AC19*K19)+0.7*AE19-AG19*AF19 -> 37672.786 | AB19: =AA19*(1-AC19*K19)+0.7*AE19-AG19*AF19 -> 39653.695 | AC19: 0.1 | AD19: =T19/F19 -> 0.13116549 | AE19: =F19*AD19 -> 3114 | AF19: =VLOOKUP(B19,Migration!A$2:B$189,2,FALSE) -> 825 | AG19: =1/20 -> 0.05 | AH19: =IF(AB19<U19,"Decrease","Increase") -> Increase | AI19: =AF19/F19 -> 0.034750011 | AJ19: =K19+L19 -> 0.053143788
A20: Gabon | B20: GAB | C20: High/Upper-Middle-Income Economies | D20: 0 | E20: 1368 | F20: 1265.3898 | G20: 0 | H20: 0.21811785 | I20: 0.22691293 | J20: 0.33333333 | K20: 0.19700967 | L20: 0.024626209 | M20: =F20*G20 -> 0 | N20: =F20*H20 -> 276.00411 | O20: =F20*I20 -> 287.13331 | P20: =F20*J20 -> 421.79661 | Q20: =F20*K20 -> 249.29404 | R20: =F20*L20 -> 31.161755 | S20: =VLOOKUP(A20,'Education graduates'!$A$3:$E$49,5,FALSE) -> 62 | T20: =VLOOKUP(B20,'Edu updated'!B$2:C$48,2,FALSE) -> 46 | U20: =F20*(1-L20)+1*0.7*AE20-AG20*AF20 -> 1242.2781 | V20: =U20*(1-AC20*K20)+0.7*AE20-AG20*AF20 -> 1225.854 | W20: =V20*(1-AC20*K20)+0.7*AE20-AG20*AF20 -> 1209.7535 | X20: =W20*(1-AC20*K20)+0.7*AE20-AG20*AF20 -> 1193.9702 | Y20: =X20*(1-AC20*K20)+0.7*AE20-AG20*AF20 -> 1178.4978 | Z20: =Y20*(1-AC20*K20)+0.7*AE20-AG20*AF20 -> 1163.3302 | AA20: =Z20*(1-AC20*K20)+0.7*AE20-AG20*AF20 -> 1148.4615 | AB20: =AA20*(1-AC20*K20)+0.7*AE20-AG20*AF20 -> 1133.8857 | AC20: 0.1 | AD20: =T20/F20 -> 0.036352434 | AE20: =F20*AD20 -> 46 | AF20: =VLOOKUP(B20,Migration!A$2:B$189,2,FALSE) -> 483 | AG20: =1/20 -> 0.05 | AH20: =IF(AB20<U20,"Decrease","Increase") -> Decrease | AI20: =AF20/F20 -> 0.38170056 | AJ20: =K20+L20 -> 0.22163588
A21: Gambia | B21: GMB | C21: Low-Income Economies | D21: 213 | E21: 298 | F21: 273.86723 | G21: 0.0084136314 | H21: 0.47834159 | I21: 0.34535536 | J21: 0.11474563 | K21: 0.041844842 | L21: 0.011298946 | M21: =F21*G21 -> 2.3042179 | N21: =F21*H21 -> 131.00209 | O21: =F21*I21 -> 94.581516 | P21: =F21*J21 -> 31.425067 | Q21: =F21*K21 -> 11.459931 | R21: =F21*L21 -> 3.0944111 | S21: =VLOOKUP(A21,'Education graduates'!$A$3:$E$49,5,FALSE) -> 0 | T21: =VLOOKUP(B21,'Edu updated'!B$2:C$48,2,FALSE) -> 23 | U21: =F21*(1-L21)+1*0.7*AE21-AG21*AF21 -> 286.22282 | V21: =U21*(1-AC21*K21)+0.7*AE21-AG21*AF21 -> 300.47512 | W21: =V21*(1-AC21*K21)+0.7*AE21-AG21*AF21 -> 314.66779 | X21: =W21*(1-AC21*K21)+0.7*AE21-AG21*AF21 -> 328.80107 | Y21: =X21*(1-AC21*K21)+0.7*AE21-AG21*AF21 -> 342.8752 | Z21: =Y21*(1-AC21*K21)+0.7*AE21-AG21*AF21 -> 356.89045 | AA21: =Z21*(1-AC21*K21)+0.7*AE21-AG21*AF21 -> 370.84704 | AB21: =AA21*(1-AC21*K21)+0.7*AE21-AG21*AF21 -> 384.74524 | AC21: 0.1 | AD21: =T21/F21 -> 0.083982301 | AE21: =F21*AD21 -> 23 | AF21: =VLOOKUP(B21,Migration!A$2:B$189,2,FALSE) -> 13 | AG21: =1/20 -> 0.05 | AH21: =IF(AB21<U21,"Decrease","Increase") -> Increase | AI21: =AF21/F21 -> 0.047468257 | AJ21: =K21+L21 -> 0.053143788
A22: Ghana | B22: GHA | C22: Lower-Middle-Income Economies | D22: 2730 | E22: 4406 | F22: 4726 | G22: 0.00045892611 | H22: 0.39352914 | I22: 0.44561726 | J22: 0.11748508 | K22: 0.042221202 | L22: 0.00068838917 | M22: =F22*G22 -> 2.1688848 | N22: =F22*H22 -> 1859.8187 | O22: =F22*I22 -> 2105.9872 | P22: =F22*J22 -> 555.23451 | Q22: =F22*K22 -> 199.5374 | R22: =F22*L22 -> 3.2533272 | S22: =VLOOKUP(A22,'Education graduates'!$A$3:$E$49,5,FALSE) -> 0 | T22: =VLOOKUP(B22,'Edu updated'!B$2:C$48,2,FALSE) -> 1566 | U22: =F22*(1-L22)+1*0.7*AE22-AG22*AF22 -> 5728.2967 | V22: =U22*(1-AC22*K22)+0.7*AE22-AG22*AF22 -> 6709.6611 | W22: =V22*(1-AC22*K22)+0.7*AE22-AG22*AF22 -> 7686.8821 | X22: =W22*(1-AC22*K22)+0.7*AE22-AG22*AF22 -> 8659.9772 | Y22: =X22*(1-AC22*K22)+0.7*AE22-AG22*AF22 -> 9628.9637 | Z22: =Y22*(1-AC22*K22)+0.7*AE22-AG22*AF22 -> 10593.859 | AA22: =Z22*(1-AC22*K22)+0.7*AE22-AG22*AF22 -> 11554.681 | AB22: =AA22*(1-AC22*K22)+0.7*AE22-AG22*AF22 -> 12511.445 | AC22: 0.1 | AD22: =T22/F22 -> 0.33135844 | AE22: =F22*AD22 -> 1566 | AF22: =VLOOKUP(B22,Migration!A$2:B$189,2,FALSE) -> 1813 | AG22: =1/20 -> 0.05 | AH22: =IF(AB22<U22,"Decrease","Increase") -> Increase | AI22: =AF22/F22 -> 0.38362251 | AJ22: =K22+L22 -> 0.042909592
A23: Guinea | B23: GIN | C23: Low-Income Economies | D23: 1844 | E23: 2787 | F23: 2945 | G23: 0.0084136314 | H23: 0.47834159 | I23: 0.34535536 | J23: 0.11474563 | K23: 0.041844842 | L23: 0.011298946 | M23: =F23*G23 -> 24.778145 | N23: =F23*H23 -> 1408.716 | O23: =F23*I23 -> 1017.0715 | P23: =F23*J23 -> 337.92587 | Q23: =F23*K23 -> 123.23306 | R23: =F23*L23 -> 33.275397 | S23: =VLOOKUP(A23,'Education graduates'!$A$3:$E$49,5,FALSE) -> 841 | T23: =VLOOKUP(B23,'Edu updated'!B$2:C$48,2,FALSE) -> 767 | U23: =F23*(1-L23)+1*0.7*AE23-AG23*AF23 -> 3442.0246 | V23: =U23*(1-AC23*K23)+0.7*AE23-AG23*AF23 -> 3957.9215 | W23: =V23*(1-AC23*K23)+0.7*AE23-AG23*AF23 -> 4471.6596 | X23: =W23*(1-AC23*K23)+0.7*AE23-AG23*AF23 -> 4983.2481 | Y23: =X23*(1-AC23*K23)+0.7*AE23-AG23*AF23 -> 5492.6957 | Z23: =Y23*(1-AC23*K23)+0.7*AE23-AG23*AF23 -> 6000.0116 | AA23: =Z23*(1-AC23*K23)+0.7*AE23-AG23*AF23 -> 6505.2047 | AB23: =AA23*(1-AC23*K23)+0.7*AE23-AG23*AF23 -> 7008.2838 | AC23: 0.1 | AD23: =T23/F23 -> 0.26044143 | AE23: =F23*AD23 -> 767 | AF23: =VLOOKUP(B23,Migration!A$2:B$189,2,FALSE) -> 132 | AG23: =1/20 -> 0.05 | AH23: =IF(AB23<U23,"Decrease","Increase") -> Increase | AI23: =AF23/F23 -> 0.044821732 | AJ23: =K23+L23 -> 0.053143788
A24: Guinea-Bissau | B24: GNB | C24: Low-Income Economies | D24: 354 | E24: 578 | F24: 530.87376 | G24: 0 | H24: 0.52402746 | I24: 0.32723112 | J24: 0.09382151 | K24: 0.043478261 | L24: 0.011441648 | M24: =F24*G24 -> 0 | N24: =F24*H24 -> 278.19243 | O24: =F24*I24 -> 173.71842 | P24: =F24*J24 -> 49.807378 | Q24: =F24*K24 -> 23.081468 | R24: =F24*L24 -> 6.0740705 | S24: =VLOOKUP(A24,'Education graduates'!$A$3:$E$49,5,FALSE) -> 69 | T24: =VLOOKUP(B24,'Edu updated'!B$2:C$48,2,FALSE) -> 0 | U24: =F24*(1-L24)+1*0.7*AE24-AG24*AF24 -> 601.20169 | V24: =U24*(1-AC24*K24)+0.7*AE24-AG24*AF24 -> 674.98977 | W24: =V24*(1-AC24*K24)+0.7*AE24-AG24*AF24 -> 748.45703 | X24: =W24*(1-AC24*K24)+0.7*AE24-AG24*AF24 -> 821.60486 | Y24: =X24*(1-AC24*K24)+0.7*AE24-AG24*AF24 -> 894.43466 | Z24: =Y24*(1-AC24*K24)+0.7*AE24-AG24*AF24 -> 966.94781 | AA24: =Z24*(1-AC24*K24)+0.7*AE24-AG24*AF24 -> 1039.1457 | AB24: =AA24*(1-AC24*K24)+0.7*AE24-AG24*AF24 -> 1111.0297 | AC24: 0.1 | AD24: 0.206 | AE24: =F24*AD24 -> 109.36 | AF24: =VLOOKUP(B24,Migration!A$2:B$189,2,FALSE) -> 3 | AG24: =1/20 -> 0.05 | AH24: =IF(AB24<U24,"Decrease","Increase") -> Increase | AI24: =AF24/F24 -> 0.005651061 | AJ24: =K24+L24 -> 0.054919908
A25: Kenya | B25: KEN | C25: Lower-Middle-Income Economies | D25: 8682 | E25: 8042 | F25: 12792 | G25: 0.00091008373 | H25: 0.29122679 | I25: 0.4912632 | J25: 0.17127776 | K25: 0.044230069 | L25: 0.0010921005 | M25: =F25*G25 -> 11.641791 | N25: =F25*H25 -> 3725.3731 | O25: =F25*I25 -> 6284.2388 | P25: =F25*J25 -> 2190.9851 | Q25: =F25*K25 -> 565.79104 | R25: =F25*L25 -> 13.970149 | S25: =VLOOKUP(A25,'Education graduates'!$A$3:$E$49,5,FALSE) -> 0 | T25: =VLOOKUP(B25,'Edu updated'!B$2:C$48,2,FALSE) -> 558 | U25: =F25*(1-L25)+1*0.7*AE25-AG25*AF25 -> 13148.18 | V25: =U25*(1-AC25*K25)+0.7*AE25-AG25*AF25 -> 13460.175 | W25: =V25*(1-AC25*K25)+0.7*AE25-AG25*AF25 -> 13770.791 | X25: =W25*(1-AC25*K25)+0.7*AE25-AG25*AF25 -> 14080.033 | Y25: =X25*(1-AC25*K25)+0.7*AE25-AG25*AF25 -> 14387.907 | Z25: =Y25*(1-AC25*K25)+0.7*AE25-AG25*AF25 -> 14694.419 | AA25: =Z25*(1-AC25*K25)+0.7*AE25-AG25*AF25 -> 14999.575 | AB25: =AA25*(1-AC25*K25)+0.7*AE25-AG25*AF25 -> 15303.382 | AC25: 0.1 | AD25: =T25/F25 -> 0.043621013 | AE25: =F25*AD25 -> 558 | AF25: =VLOOKUP(B25,Migration!A$2:B$189,2,FALSE) -> 409 | AG25: =1/20 -> 0.05 | AH25: =IF(AB25<U25,"Decrease","Increase") -> Increase | AI25: =AF25/F25 -> 0.031973108 | AJ25: =K25+L25 -> 0.04532217
A26: Lesotho | B26: LSO | C26: Lower-Middle-Income Economies | D26: 0 | E26: 998 | F26: 536.60978 | G26: 0.009627305 | H26: 0.3275993 | I26: 0.3862164 | J26: 0.1759096 | K26: 0.080800436 | L26: 0.019846966 | M26: =F26*G26 -> 5.166106 | N26: =F26*H26 -> 175.79299 | O26: =F26*I26 -> 207.2475 | P26: =F26*J26 -> 94.394811 | Q26: =F26*K26 -> 43.358304 | R26: =F26*L26 -> 10.650076 | S26: =VLOOKUP(A26,'Education graduates'!$A$3:$E$49,5,FALSE) -> 0 | T26: =VLOOKUP(B26,'Edu updated'!B$2:C$48,2,FALSE) -> 8 | U26: =F26*(1-L26)+1*0.7*AE26-AG26*AF26 -> 531.4597 | V26: =U26*(1-AC26*K26)+0.7*AE26-AG26*AF26 -> 532.66549 | W26: =V26*(1-AC26*K26)+0.7*AE26-AG26*AF26 -> 533.86152 | X26: =W26*(1-AC26*K26)+0.7*AE26-AG26*AF26 -> 535.0479 | Y26: =X26*(1-AC26*K26)+0.7*AE26-AG26*AF26 -> 536.22469 | Z26: =Y26*(1-AC26*K26)+0.7*AE26-AG26*AF26 -> 537.39197 | AA26: =Z26*(1-AC26*K26)+0.7*AE26-AG26*AF26 -> 538.54982 | AB26: =AA26*(1-AC26*K26)+0.7*AE26-AG26*AF26 -> 539.69831 | AC26: 0.1 | AD26: =T26/F26 -> 0.014908413 | AE26: =F26*AD26 -> 8 | AF26: =VLOOKUP(B26,Migration!A$2:B$189,2,FALSE) -> 2 | AG26: =1/20 -> 0.05 | AH26: =IF(AB26<U26,"Decrease","Increase") -> Increase | AI26: =AF26/F26 -> 0.0037271032 | AJ26: =K26+L26 -> 0.1006474
A27: Liberia | B27: LBR | C27: Low-Income Economies | D27: 168 | E27: 693 | F27: 954 | G27: 0.0084136314 | H27: 0.47834159 | I27: 0.34535536 | J27: 0.11474563 | K27: 0.041844842 | L27: 0.011298946 | M27: =F27*G27 -> 8.0266044 | N27: =F27*H27 -> 456.33788 | O27: =F27*I27 -> 329.46902 | P27: =F27*J27 -> 109.46733 | Q27: =F27*K27 -> 39.919979 | R27: =F27*L27 -> 10.779195 | S27: =VLOOKUP(A27,'Education graduates'!$A$3:$E$49,5,FALSE) -> 62 | T27: =VLOOKUP(B27,'Edu updated'!B$2:C$48,2,FALSE) -> 29 | U27: =F27*(1-L27)+1*0.7*AE27-AG27*AF27 -> 960.47081 | V27: =U27*(1-AC27*K27)+0.7*AE27-AG27*AF27 -> 973.70173 | W27: =V27*(1-AC27*K27)+0.7*AE27-AG27*AF27 -> 986.87729 | X27: =W27*(1-AC27*K27)+0.7*AE27-AG27*AF27 -> 999.99772 | Y27: =X27*(1-AC27*K27)+0.7*AE27-AG27*AF27 -> 1013.0632 | Z27: =Y27*(1-AC27*K27)+0.7*AE27-AG27*AF27 -> 1026.0741 | AA27: =Z27*(1-AC27*K27)+0.7*AE27-AG27*AF27 -> 1039.0305 | AB27: =AA27*(1-AC27*K27)+0.7*AE27-AG27*AF27 -> 1051.9327 | AC27: 0.1 | AD27: =T27/F27 -> 0.030398323 | AE27: =F27*AD27 -> 29 | AF27: =VLOOKUP(B27,Migration!A$2:B$189,2,FALSE) -> 61 | AG27: =1/20 -> 0.05 | AH27: =IF(AB27<U27,"Decrease","Increase") -> Increase | AI27: =AF27/F27 -> 0.0639413 | AJ27: =K27+L27 -> 0.053143788
A28: Madagascar | B28: MDG | C28: Low-Income Economies | D28: 3523 | E28: 5230 | F28: 5230 | G28: 0.0084136314 | H28: 0.47834159 | I28: 0.34535536 | J28: 0.11474563 | K28: 0.041844842 | L28: 0.011298946 | M28: =F28*G28 -> 44.003292 | N28: =F28*H28 -> 2501.7265 | O28: =F28*I28 -> 1806.2085 | P28: =F28*J28 -> 600.11963 | Q28: =F28*K28 -> 218.84852 | R28: =F28*L28 -> 59.093489 | S28: =VLOOKUP(A28,'Education graduates'!$A$3:$E$49,5,FALSE) -> 404 | T28: =VLOOKUP(B28,'Edu updated'!B$2:C$48,2,FALSE) -> 316 | U28: =F28*(1-L28)+1*0.7*AE28-AG28*AF28 -> 5361.9065 | V28: =U28*(1-AC28*K28)+0.7*AE28-AG28*AF28 -> 5530.4697 | W28: =V28*(1-AC28*K28)+0.7*AE28-AG28*AF28 -> 5698.3275 | X28: =W28*(1-AC28*K28)+0.7*AE28-AG28*AF28 -> 5865.483 | Y28: =X28*(1-AC28*K28)+0.7*AE28-AG28*AF28 -> 6031.939 | Z28: =Y28*(1-AC28*K28)+0.7*AE28-AG28*AF28 -> 6197.6984 | AA28: =Z28*(1-AC28*K28)+0.7*AE28-AG28*AF28 -> 6362.7642 | AB28: =AA28*(1-AC28*K28)+0.7*AE28-AG28*AF28 -> 6527.1393 | AC28: 0.1 | AD28: =T28/F28 -> 0.06042065 | AE28: =F28*AD28 -> 316 | AF28: =VLOOKUP(B28,Migration!A$2:B$189,2,FALSE) -> 604 | AG28: =1/20 -> 0.05 | AH28: =IF(AB28<U28,"Decrease","Increase") -> Increase | AI28: =AF28/F28 -> 0.11548757 | AJ28: =K28+L28 -> 0.053143788
A29: Malawi | B29: MWI | C29: Low-Income Economies | D29: 200 | E29: 2760 | F29: 1103.5638 | G29: 0.058653846 | H29: 0.37692308 | I29: 0.31826923 | J29: 0.20480769 | K29: 0.028846154 | L29: 0.0125 | M29: =F29*G29 -> 64.72826 | N29: =F29*H29 -> 415.95865 | O29: =F29*I29 -> 351.23039 | P29: =F29*J29 -> 226.01835 | Q29: =F29*K29 -> 31.83357 | R29: =F29*L29 -> 13.794547 | S29: =VLOOKUP(A29,'Education graduates'!$A$3:$E$49,5,FALSE) -> 101 | T29: =VLOOKUP(B29,'Edu updated'!B$2:C$48,2,FALSE) -> 115 | U29: =F29*(1-L29)+1*0.7*AE29-AG29*AF29 -> 1167.8692 | V29: =U29*(1-AC29*K29)+0.7*AE29-AG29*AF29 -> 1242.6004 | W29: =V29*(1-AC29*K29)+0.7*AE29-AG29*AF29 -> 1317.116 | X29: =W29*(1-AC29*K29)+0.7*AE29-AG29*AF29 -> 1391.4166 | Y29: =X29*(1-AC29*K29)+0.7*AE29-AG29*AF29 -> 1465.5029 | Z29: =Y29*(1-AC29*K29)+0.7*AE29-AG29*AF29 -> 1539.3755 | AA29: =Z29*(1-AC29*K29)+0.7*AE29-AG29*AF29 -> 1613.035 | AB29: =AA29*(1-AC29*K29)+0.7*AE29-AG29*AF29 -> 1686.482 | AC29: 0.1 | AD29: =T29/F29 -> 0.10420784 | AE29: =F29*AD29 -> 115 | AF29: =VLOOKUP(B29,Migration!A$2:B$189,2,FALSE) -> 48 | AG29: =1/20 -> 0.05 | AH29: =IF(AB29<U29,"Decrease","Increase") -> Increase | AI29: =AF29/F29 -> 0.043495447 | AJ29: =K29+L29 -> 0.041346154
A30: Mali | B30: MLI | C30: Low-Income Economies | D30: 1971 | E30: 2866 | F30: 4402 | G30: 0.0084136314 | H30: 0.47834159 | I30: 0.34535536 | J30: 0.11474563 | K30: 0.041844842 | L30: 0.011298946 | M30: =F30*G30 -> 37.036806 | N30: =F30*H30 -> 2105.6597 | O30: =F30*I30 -> 1520.2543 | P30: =F30*J30 -> 505.11025 | Q30: =F30*K30 -> 184.20099 | R30: =F30*L30 -> 49.737962 | S30: =VLOOKUP(A30,'Education graduates'!$A$3:$E$49,5,FALSE) -> 0 | T30: =VLOOKUP(B30,'Edu updated'!B$2:C$48,2,FALSE) -> 0 | U30: =F30*(1-L30)+1*0.7*AE30-AG30*AF30 -> 4977.3804 | V30: =U30*(1-AC30*K30)+0.7*AE30-AG30*AF30 -> 5581.6711 | W30: =V30*(1-AC30*K30)+0.7*AE30-AG30*AF30 -> 6183.4331 | X30: =W30*(1-AC30*K30)+0.7*AE30-AG30*AF30 -> 6782.677 | Y30: =X30*(1-AC30*K30)+0.7*AE30-AG30*AF30 -> 7379.4134 | Z30: =Y30*(1-AC30*K30)+0.7*AE30-AG30*AF30 -> 7973.6527 | AA30: =Z30*(1-AC30*K30)+0.7*AE30-AG30*AF30 -> 8565.4055 | AB30: =AA30*(1-AC30*K30)+0.7*AE30-AG30*AF30 -> 9154.6821 | AC30: 0.1 | AD30: 0.206 | AE30: =F30*AD30 -> 906.812 | AF30: =VLOOKUP(B30,Migration!A$2:B$189,2,FALSE) -> 193 | AG30: =1/20 -> 0.05 | AH30: =IF(AB30<U30,"Decrease","Increase") -> Increase | AI30: =AF30/F30 -> 0.043843707 | AJ30: =K30+L30 -> 0.053143788
A31: Mauritania | B31: MRT | C31: Lower-Middle-Income Economies | D31: 622 | E31: 1626 | F31: 1273.0347 | G31: 0.009627305 | H31: 0.3275993 | I31: 0.3862164 | J31: 0.1759096 | K31: 0.080800436 | L31: 0.019846966 | M31: =F31*G31 -> 12.255893 | N31: =F31*H31 -> 417.04527 | O31: =F31*I31 -> 491.66687 | P31: =F31*J31 -> 223.93902 | Q31: =F31*K31 -> 102.86176 | R31: =F31*L31 -> 25.265876 | S31: =VLOOKUP(A31,'Education graduates'!$A$3:$E$49,5,FALSE) -> 87 | T31: =VLOOKUP(B31,'Edu updated'!B$2:C$48,2,FALSE) -> 0 | U31: =F31*(1-L31)+1*0.7*AE31-AG31*AF31 -> 1308.2653 | V31: =U31*(1-AC31*K31)+0.7*AE31-AG31*AF31 -> 1358.1909 | W31: =V31*(1-AC31*K31)+0.7*AE31-AG31*AF31 -> 1407.7131 | X31: =W31*(1-AC31*K31)+0.7*AE31-AG31*AF31 -> 1456.8352 | Y31: =X31*(1-AC31*K31)+0.7*AE31-AG31*AF31 -> 1505.5603 | Z31: =Y31*(1-AC31*K31)+0.7*AE31-AG31*AF31 -> 1553.8918 | AA31: =Z31*(1-AC31*K31)+0.7*AE31-AG31*AF31 -> 1601.8327 | AB31: =AA31*(1-AC31*K31)+0.7*AE31-AG31*AF31 -> 1649.3863 | AC31: 0.1 | AD31: 0.068 | AE31: =F31*AD31 -> 86.566359 | AF31: =VLOOKUP(B31,Migration!A$2:B$189,2,FALSE) -> 2 | AG31: =1/20 -> 0.05 | AH31: =IF(AB31<U31,"Decrease","Increase") -> Increase | AI31: =AF31/F31 -> 0.0015710491 | AJ31: =K31+L31 -> 0.1006474
A32: Mauritius | B32: MUS | C32: High/Upper-Middle-Income Economies | D32: 2046 | E32: 2395 | F32: 1833.6555 | G32: 0 | H32: 0.28747247 | I32: 0.27178259 | J32: 0.25114397 | K32: 0.13575699 | L32: 0.053843973 | M32: =F32*G32 -> 0 | N32: =F32*H32 -> 527.12548 | O32: =F32*I32 -> 498.35564 | P32: =F32*J32 -> 460.51153 | Q32: =F32*K32 -> 248.93156 | R32: =F32*L32 -> 98.731296 | S32: =VLOOKUP(A32,'Education graduates'!$A$3:$E$49,5,FALSE) -> 0 | T32: =VLOOKUP(B32,'Edu updated'!B$2:C$48,2,FALSE) -> 432 | U32: =F32*(1-L32)+1*0.7*AE32-AG32*AF32 -> 2030.9242 | V32: =U32*(1-AC32*K32)+0.7*AE32-AG32*AF32 -> 2299.353 | W32: =V32*(1-AC32*K32)+0.7*AE32-AG32*AF32 -> 2564.1377 | X32: =W32*(1-AC32*K32)+0.7*AE32-AG32*AF32 -> 2825.3277 | Y32: =X32*(1-AC32*K32)+0.7*AE32-AG32*AF32 -> 3082.9719 | Z32: =Y32*(1-AC32*K32)+0.7*AE32-AG32*AF32 -> 3337.1184 | AA32: =Z32*(1-AC32*K32)+0.7*AE32-AG32*AF32 -> 3587.8147 | AB32: =AA32*(1-AC32*K32)+0.7*AE32-AG32*AF32 -> 3835.1076 | AC32: 0.1 | AD32: =T32/F32 -> 0.23559496 | AE32: =F32*AD32 -> 432 | AF32: =VLOOKUP(B32,Migration!A$2:B$189,2,FALSE) -> 128 | AG32: =1/20 -> 0.05 | AH32: =IF(AB32<U32,"Decrease","Increase") -> Increase | AI32: =AF32/F32 -> 0.069805915 | AJ32: =K32+L32 -> 0.18960097
A33: Mozambique | B33: MOZ | C33: Low-Income Economies | D33: 1452 | E33: 2473 | F33: 5719 | G33: 0.0025575448 | H33: 0.33418585 | I33: 0.38235294 | J33: 0.1773231 | K33: 0.08226769 | L33: 0.021312873 | M33: =F33*G33 -> 14.626598 | N33: =F33*H33 -> 1911.2089 | O33: =F33*I33 -> 2186.6765 | P33: =F33*J33 -> 1014.1108 | Q33: =F33*K33 -> 470.48892 | R33: =F33*L33 -> 121.88832 | S33: =VLOOKUP(A33,'Education graduates'!$A$3:$E$49,5,FALSE) -> 819 | T33: =VLOOKUP(B33,'Edu updated'!B$2:C$48,2,FALSE) -> 819 | U33: =F33*(1-L33)+1*0.7*AE33-AG33*AF33 -> 6166.8117 | V33: =U33*(1-AC33*K33)+0.7*AE33-AG33*AF33 -> 6685.7787 | W33: =V33*(1-AC33*K33)+0.7*AE33-AG33*AF33 -> 7200.4764 | X33: =W33*(1-AC33*K33)+0.7*AE33-AG33*AF33 -> 7710.9397 | Y33: =X33*(1-AC33*K33)+0.7*AE33-AG33*AF33 -> 8217.2036 | Z33: =Y33*(1-AC33*K33)+0.7*AE33-AG33*AF33 -> 8719.3026 | AA33: =Z33*(1-AC33*K33)+0.7*AE33-AG33*AF33 -> 9217.2709 | AB33: =AA33*(1-AC33*K33)+0.7*AE33-AG33*AF33 -> 9711.1425 | AC33: 0.1 | AD33: =T33/F33 -> 0.14320685 | AE33: =F33*AD33 -> 819 | AF33: =VLOOKUP(B33,Migration!A$2:B$189,2,FALSE) -> 72 | AG33: =1/20 -> 0.05 | AH33: =IF(AB33<U33,"Decrease","Increase") -> Increase | AI33: =AF33/F33 -> 0.012589614 | AJ33: =K33+L33 -> 0.10358056
A34: Namibia | B34: NAM | C34: High/Upper-Middle-Income Economies | D34: 0 | E34: 1445 | F34: 1597 | G34: 0 | H34: 0.28747247 | I34: 0.27178259 | J34: 0.25114397 | K34: 0.13575699 | L34: 0.053843973 | M34: =F34*G34 -> 0 | N34: =F34*H34 -> 459.09354 | O34: =F34*I34 -> 434.03679 | P34: =F34*J34 -> 401.07692 | Q34: =F34*K34 -> 216.80392 | R34: =F34*L34 -> 85.988824 | S34: =VLOOKUP(A34,'Education graduates'!$A$3:$E$49,5,FALSE) -> 73 | T34: =VLOOKUP(B34,'Edu updated'!B$2:C$48,2,FALSE) -> 475 | U34: =F34*(1-L34)+1*0.7*AE34-AG34*AF34 -> 1843.1612 | V34: =U34*(1-AC34*K34)+0.7*AE34-AG34*AF34 -> 2150.289 | W34: =V34*(1-AC34*K34)+0.7*AE34-AG34*AF34 -> 2453.2473 | X34: =W34*(1-AC34*K34)+0.7*AE34-AG34*AF34 -> 2752.0928 | Y34: =X34*(1-AC34*K34)+0.7*AE34-AG34*AF34 -> 3046.8812 | Z34: =Y34*(1-AC34*K34)+0.7*AE34-AG34*AF34 -> 3337.6676 | AA34: =Z34*(1-AC34*K34)+0.7*AE34-AG34*AF34 -> 3624.5065 | AB34: =AA34*(1-AC34*K34)+0.7*AE34-AG34*AF34 -> 3907.4512 | AC34: 0.1 | AD34: =T34/F34 -> 0.29743269 | AE34: =F34*AD34 -> 475 | AF34: =VLOOKUP(B34,Migration!A$2:B$189,2,FALSE) -> 7 | AG34: =1/20 -> 0.05 | AH34: =IF(AB34<U34,"Decrease","Increase") -> Increase | AI34: =AF34/F34 -> 0.0043832185 | AJ34: =K34+L34 -> 0.18960097
