Workbook

Sheet Available
B1: Data on age group availability
A2: Country | B2: Data year
A3: AGO
A4: BDI | B4: 2019
A5: BEN | B5: 2021
A6: BFA | B6: 2022
A7: BWA | B7: 2022
A8: CAF
A9: CIV | B9: 2022
A10: CMR | B10: 2022
A11: COD
A12: COG | B12: 2022
A13: COM
A14: CPV | B14: 2022
A15: DZA | B15: 2018
A16: ERI | B16: 2022
A17: ETH
A18: GAB | B18: 2022
A19: GHA | B19: 2022
A20: GIN
A21: GMB
A22: GNB | B22: 2022
A23: GNQ
A24: KEN | B24: 2022
A25: LBR
A26: LSO
A27: MDG | B27: 2018
A28: MLI
A29: MOZ | B29: 2022
A30: MRT
A31: MUS
A32: MWI | B32: 2022
A33: NAM
A34: NER
A35: NGA | B35: 2022
A36: RWA
A37: SEN | B37: 2022
A38: SLE | B38: 2020
A39: SSD
A40: STP
...

Sheet Sheet4
A3: Row Labels | B3: Average of Nursing Personnel Stock By Age Group < 25 yrs2 | C3: Average of Nursing Personnel Stock By Age Group 25-34 yrs2 | D3: Average of Nursing Personnel Stock By Age Group 35-44 yrs2 | E3: Average of Nursing Personnel Stock By Age Group 45-54 yrs2 | F3: Average of Nursing Personnel Stock By Age Group 55-64 yrs2 | G3: Average of Nursing Personnel Stock By Age Group ≥ 65 yrs2
A4: High/Upper-Middle-Income Economies | B4: 0.018679111 | C4: 0.24613492 | D4: 0.31712616 | E4: 0.24329285 | F4: 0.13924057 | G4: 0.035526392
A5: Lower-Middle-Income Economies | B5: 0.031079804 | C5: 0.33653963 | D5: 0.34941396 | E5: 0.20169963 | F5: 0.073507085 | G5: 0.0077599026
A6: Low-Income Economies | B6: 0.16765299 | C6: 0.35339731 | D6: 0.29951984 | E6: 0.13365552 | F6: 0.043048784 | G6: 0.0027255474
A7: AFRO | B7: 0.028094911 | C7: 0.42408199 | D7: 0.32237544 | E7: 0.14725788 | F7: 0.073303781 | G7: 0.0048859963
A8: Grand Total | B8: 0.068722497 | C8: 0.3300366 | D8: 0.3283536 | E8: 0.18651723 | F8: 0.075570524 | G8: 0.010799551

Sheet proportions
A1: Country | B1: Nursing Personnel Stock By Age Group < 25 yrs | C1: Nursing Personnel Stock By Age Group 25-34 yrs | D1: Nursing Personnel Stock By Age Group 35-44 yrs | E1: Nursing Personnel Stock By Age Group 45-54 yrs | F1: Nursing Personnel Stock By Age Group 55-64 yrs | G1: Nursing Personnel Stock By Age Group ≥ 65 yrs | H1: Total | I1: Nursing Personnel Stock By Age Group < 25 yrs | J1: Nursing Personnel Stock By Age Group 25-34 yrs | K1: Nursing Personnel Stock By Age Group 35-44 yrs | L1: Nursing Personnel Stock By Age Group 45-54 yrs | M1: Nursing Personnel Stock By Age Group 55-64 yrs | N1: Nursing Personnel Stock By Age Group ≥ 65 yrs | O1: Income
A2: AFRO | B2: 16244 | C2: 245197 | D2: 186392 | E2: 85142 | F2: 42383 | G2: 2825 | H2: =SUM(B2:G2) -> 578183 | I2: =B2/H2 -> 0.028094911 | J2: =C2/H2 -> 0.42408199 | K2: =D2/H2 -> 0.32237544 | L2: =E2/H2 -> 0.14725788 | M2: =F2/H2 -> 0.073303781 | N2: =G2/H2 -> 0.0048859963 | O2: AFRO
A3: BWA | B3: 227 | C3: 2959 | D3: 2657 | E3: 1502 | F3: 646 | G3: 37 | H3: =SUM(B3:G3) -> 8028 | I3: =B3/H3 -> 0.028276034 | J3: =C3/H3 -> 0.36858495 | K3: =D3/H3 -> 0.33096662 | L3: =E3/H3 -> 0.18709517 | M3: =F3/H3 -> 0.080468361 | N3: =G3/H3 -> 0.004608869 | O3: =VLOOKUP(A3,Income!A$2:D$49,4,FALSE) -> High/Upper-Middle-Income Economies
A4: CIV | B4: 35 | C4: 3771 | D4: 6788 | E4: 3016 | F4: 1366 | G4: 3 | H4: =SUM(B4:G4) -> 14979 | I4: =B4/H4 -> 0.0023366046 | J4: =C4/H4 -> 0.25175245 | K4: =D4/H4 -> 0.45316777 | L4: =E4/H4 -> 0.20134855 | M4: =F4/H4 -> 0.091194339 | N4: =G4/H4 -> 0.00020028039 | O4: =VLOOKUP(A4,Income!A$2:D$49,4,FALSE) -> Lower-Middle-Income Economies
A5: CMR | B5: 296 | C5: 6515 | D5: 6221 | E5: 2896 | F5: 521 | G5: 19 | H5: =SUM(B5:G5) -> 16468 | I5: =B5/H5 -> 0.017974253 | J5: =C5/H5 -> 0.39561574 | K5: =D5/H5 -> 0.37776293 | L5: =E5/H5 -> 0.17585621 | M5: =F5/H5 -> 0.031637114 | N5: =G5/H5 -> 0.0011537527 | O5: =VLOOKUP(A5,Income!A$2:D$49,4,FALSE) -> Lower-Middle-Income Economies
A6: COG | B6: 75 | C6: 710 | D6: 2588 | E6: 1522 | F6: 675 | G6: 3 | H6: =SUM(B6:G6) -> 5573 | I6: =B6/H6 -> 0.013457743 | J6: =C6/H6 -> 0.12739996 | K6: =D6/H6 -> 0.46438184 | L6: =E6/H6 -> 0.27310246 | M6: =F6/H6 -> 0.12111968 | N6: =G6/H6 -> 0.00053830971 | O6: =VLOOKUP(A6,Income!A$2:D$49,4,FALSE) -> Lower-Middle-Income Economies
A7: CPV | B7: 0 | C7: 253 | D7: 249 | E7: 262 | F7: 128 | G7: 49 | H7: =SUM(B7:G7) -> 941 | I7: =B7/H7 -> 0 | J7: =C7/H7 -> 0.26886291 | K7: =D7/H7 -> 0.26461211 | L7: =E7/H7 -> 0.27842721 | M7: =F7/H7 -> 0.1360255 | N7: =G7/H7 -> 0.052072264 | O7: =VLOOKUP(A7,Income!A$2:D$49,4,FALSE) -> Lower-Middle-Income Economies
A8: ERI | B8: 859 | C8: 2083 | D8: 940 | E8: 916 | F8: 209 | H8: =SUM(B8:G8) -> 5007 | I8: =B8/H8 -> 0.17155982 | J8: =C8/H8 -> 0.41601758 | K8: =D8/H8 -> 0.18773717 | L8: =E8/H8 -> 0.18294388 | M8: =F8/H8 -> 0.041741562 | N8: =G8/H8 -> 0 | O8: =VLOOKUP(A8,Income!A$2:D$49,4,FALSE) -> Low-Income Economies
A9: GAB | B9: 0 | C9: 615 | D9: 1660 | E9: 1532 | F9: 470 | G9: 0 | H9: =SUM(B9:G9) -> 4277 | I9: =B9/H9 -> 0 | J9: =C9/H9 -> 0.14379238 | K9: =D9/H9 -> 0.38812252 | L9: =E9/H9 -> 0.358195 | M9: =F9/H9 -> 0.10989011 | N9: =G9/H9 -> 0 | O9: =VLOOKUP(A9,Income!A$2:D$49,4,FALSE) -> High/Upper-Middle-Income Economies
A10: GHA | B10: 39 | C10: 66582 | D10: 30701 | E10: 1561 | F10: 790 | G10: 0 | H10: =SUM(B10:G10) -> 99673 | I10: =B10/H10 -> 0.00039127948 | J10: =C10/H10 -> 0.66800437 | K10: =D10/H10 -> 0.30801722 | L10: =E10/H10 -> 0.015661212 | M10: =F10/H10 -> 0.0079259178 | N10: =G10/H10 -> 0 | O10: =VLOOKUP(A10,Income!A$2:D$49,4,FALSE) -> Lower-Middle-Income Economies
A11: GNB | B11: 0 | C11: 659 | D11: 863 | E11: 209 | F11: 134 | G11: 14 | H11: =SUM(B11:G11) -> 1879 | I11: =B11/H11 -> 0 | J11: =C11/H11 -> 0.35071847 | K11: =D11/H11 -> 0.45928685 | L11: =E11/H11 -> 0.11122938 | M11: =F11/H11 -> 0.071314529 | N11: =G11/H11 -> 0.0074507717 | O11: =VLOOKUP(A11,Income!A$2:D$49,4,FALSE) -> Low-Income Economies
A12: KEN | B12: 375 | C12: 11055 | D12: 12233 | E12: 8664 | F12: 3678 | G12: 57 | H12: =SUM(B12:G12) -> 36062 | I12: =B12/H12 -> 0.010398758 | J12: =C12/H12 -> 0.30655538 | K12: =D12/H12 -> 0.33922134 | L12: =E12/H12 -> 0.2402529 | M12: =F12/H12 -> 0.10199102 | N12: =G12/H12 -> 0.0015806112 | O12: =VLOOKUP(A12,Income!A$2:D$49,4,FALSE) -> Lower-Middle-Income Economies
A13: MWI | B13: 310 | C13: 4736 | D13: 2722 | E13: 1613 | F13: 211 | H13: =SUM(B13:G13) -> 9592 | I13: =B13/H13 -> 0.032318599 | J13: =C13/H13 -> 0.49374479 | K13: =D13/H13 -> 0.28377815 | L13: =E13/H13 -> 0.16816097 | M13: =F13/H13 -> 0.021997498 | N13: =G13/H13 -> 0 | O13: =VLOOKUP(A13,Income!A$2:D$49,4,FALSE) -> Low-Income Economies
A14: NGA | B14: 9026 | C14: 106455 | D14: 89987 | E14: 52923 | F14: 31760 | G14: 2353 | H14: =SUM(B14:G14) -> 292504 | I14: =B14/H14 -> 0.030857698 | J14: =C14/H14 -> 0.36394374 | K14: =D14/H14 -> 0.30764366 | L14: =E14/H14 -> 0.18093086 | M14: =F14/H14 -> 0.10857971 | N14: =G14/H14 -> 0.0080443344 | O14: =VLOOKUP(A14,Income!A$2:D$49,4,FALSE) -> Lower-Middle-Income Economies
A15: SEN | B15: 15 | C15: 1113 | D15: 2668 | E15: 709 | F15: 203 | G15: 29 | H15: =SUM(B15:G15) -> 4737 | I15: =B15/H15 -> 0.0031665611 | J15: =C15/H15 -> 0.23495883 | K15: =D15/H15 -> 0.56322567 | L15: =E15/H15 -> 0.14967279 | M15: =F15/H15 -> 0.042854127 | N15: =G15/H15 -> 0.0061220182 | O15: =VLOOKUP(A15,Income!A$2:D$49,4,FALSE) -> Lower-Middle-Income Economies
A16: SWZ | B16: 156 | C16: 2150 | D16: 1684 | E16: 1016 | F16: 478 | G16: 34 | H16: =SUM(B16:G16) -> 5518 | I16: =B16/H16 -> 0.028271113 | J16: =C16/H16 -> 0.38963393 | K16: =D16/H16 -> 0.30518304 | L16: =E16/H16 -> 0.18412468 | M16: =F16/H16 -> 0.086625589 | N16: =G16/H16 -> 0.0061616528 | O16: =VLOOKUP(A16,Income!A$2:D$49,4,FALSE) -> Lower-Middle-Income Economies
A17: SYC | B17: 42 | C17: 256 | D17: 239 | E17: 162 | F17: 168 | G17: 80 | H17: =SUM(B17:G17) -> 947 | I17: =B17/H17 -> 0.044350581 | J17: =C17/H17 -> 0.27032735 | K17: =D17/H17 -> 0.25237592 | L17: =E17/H17 -> 0.17106653 | M17: =F17/H17 -> 0.17740232 | N17: =G17/H17 -> 0.084477297 | O17: =VLOOKUP(A17,Income!A$2:D$49,4,FALSE) -> High/Upper-Middle-Income Economies
A18: TCD | B18: 123 | C18: 1494 | D18: 1044 | E18: 491 | F18: 215 | G18: 0 | H18: =SUM(B18:G18) -> 3367 | I18: =B18/H18 -> 0.036531037 | J18: =C18/H18 -> 0.44371844 | K18: =D18/H18 -> 0.31006831 | L18: =E18/H18 -> 0.14582715 | M18: =F18/H18 -> 0.063855064 | N18: =G18/H18 -> 0 | O18: =VLOOKUP(A18,Income!A$2:D$49,4,FALSE) -> Low-Income Economies
A19: TGO | B19: 121 | C19: 987 | D19: 1001 | E19: 411 | F19: 146 | G19: 4 | H19: =SUM(B19:G19) -> 2670 | I19: =B19/H19 -> 0.045318352 | J19: =C19/H19 -> 0.36966292 | K19: =D19/H19 -> 0.37490637 | L19: =E19/H19 -> 0.15393258 | M19: =F19/H19 -> 0.054681648 | N19: =G19/H19 -> 0.0014981273 | O19: =VLOOKUP(A19,Income!A$2:D$49,4,FALSE) -> Low-Income Economies
A20: ZMB | B20: 4545 | C20: 19288 | D20: 7021 | E20: 2197 | F20: 585 | G20: 143 | H20: =SUM(B20:G20) -> 33779 | I20: =B20/H20 -> 0.13455105 | J20: =C20/H20 -> 0.57100565 | K20: =D20/H20 -> 0.20785103 | L20: =E20/H20 -> 0.06504041 | M20: =F20/H20 -> 0.017318452 | N20: =G20/H20 -> 0.0042333994 | O20: =VLOOKUP(A20,Income!A$2:D$49,4,FALSE) -> Lower-Middle-Income Economies
A21: BEN | B21: 206 | C21: 876 | D21: 2422 | E21: 1649 | F21: 289 | G21: 42 | H21: =SUM(B21:G21) -> 5484 | I21: =B21/H21 -> 0.037563822 | J21: =C21/H21 -> 0.15973742 | K21: =D21/H21 -> 0.44164843 | L21: =E21/H21 -> 0.30069292 | M21: =F21/H21 -> 0.05269876 | N21: =G21/H21 -> 0.0076586433 | O21: =VLOOKUP(A21,Income!A$2:D$49,4,FALSE) -> Lower-Middle-Income Economies
A22: BDI | B22: 17 | C22: 2407 | D22: 3522 | E22: 1236 | F22: 292 | G22: 44 | H22: =SUM(B22:G22) -> 7518 | I22: =B22/H22 -> 0.0022612397 | J22: =C22/H22 -> 0.32016494 | K22: =D22/H22 -> 0.46847566 | L22: =E22/H22 -> 0.16440543 | M22: =F22/H22 -> 0.038840117 | N22: =G22/H22 -> 0.0058526204 | O22: =VLOOKUP(A22,Income!A$2:D$49,4,FALSE) -> Low-Income Economies
A23: DZA | B23: 5302 | C23: 16980 | D23: 9040 | E23: 20042 | F23: 4745 | G23: 302 | H23: =SUM(B23:G23) -> 56411 | I23: =B23/H23 -> 0.093988761 | J23: =C23/H23 -> 0.30100512 | K23: =D23/H23 -> 0.16025243 | L23: =E23/H23 -> 0.35528532 | M23: =F23/H23 -> 0.0841148 | N23: =G23/H23 -> 0.0053535658 | O23: =VLOOKUP(A23,Income!A$2:D$49,4,FALSE) -> Lower-Middle-Income Economies
A24: UGA | B24: 9938 | C24: 895 | D24: 139 | E24: 102 | F24: 100 | G24: 48 | H24: =SUM(B24:G24) -> 11222 | I24: =B24/H24 -> 0.88558189 | J24: =C24/H24 -> 0.079754055 | K24: =D24/H24 -> 0.012386384 | L24: =E24/H24 -> 0.0090892889 | M24: =F24/H24 -> 0.0089110675 | N24: =G24/H24 -> 0.0042773124 | O24: =VLOOKUP(A24,Income!A$2:D$49,4,FALSE) -> Low-Income Economies
A25: ZAF | B25: 597 | C25: 57658 | D25: 84855 | E25: 73364 | F25: 54049 | G25: 15146 | H25: =SUM(B25:G25) -> 285669 | I25: =B25/H25 -> 0.0020898312 | J25: =C25/H25 -> 0.20183499 | K25: =D25/H25 -> 0.29703958 | L25: =E25/H25 -> 0.25681471 | M25: =F25/H25 -> 0.18920149 | N25: =G25/H25 -> 0.053019404 | O25: =VLOOKUP(A25,Income!A$2:D$49,4,FALSE) -> High/Upper-Middle-Income Economies

Sheet Income
A1: country code | B1: Country | C1: country code | D1: Income
A2: DZA | B2: Algeria | C2: DZA | D2: Lower-Middle-Income Economies
A3: AGO | B3: Angola | C3: AGO | D3: Lower-Middle-Income Economies
A4: BEN | B4: Benin | C4: BEN | D4: Lower-Middle-Income Economies
A5: BWA | B5: Botswana | C5: BWA | D5: High/Upper-Middle-Income Economies
A6: BFA | B6: Burkina Faso | C6: BFA | D6: Low-Income Economies
A7: BDI | B7: Burundi | C7: BDI | D7: Low-Income Economies
A8: CMR | B8: Cameroon | C8: CMR | D8: Lower-Middle-Income Economies
A9: CPV | B9: Cape-Verde | C9: CPV | D9: Lower-Middle-Income Economies
A10: CAF | B10: Central African Republic | C10: CAF | D10: Low-Income Economies
A11: TCD | B11: Chad | C11: TCD | D11: Low-Income Economies
A12: COM | B12: Comoros | C12: COM | D12: Lower-Middle-Income Economies
... A48: ZWE | B48: Zimbabwe | C48: ZWE | D48: Lower-Middle-Income Economies
A49: AFRO | B49: AFRO | C49: AFRO
A63: Income | B63: Nursing Personnel Stock By Age Group < 25 years | C63: Nursing Personnel Stock By Age Group 25-34 years | D63: Nursing Personnel Stock By Age Group 35-44 years | E63: Nursing Personnel Stock By Age Group 45-54 years | F63: Nursing Personnel Stock By Age Group 55-64 years | G63: Nursing Personnel Stock By Age Group ≥ 65 years
A64: High/Upper-Middle-Income Economies | B64: 0.018679111 | C64: 0.24613492 | D64: 0.31712616 | E64: 0.24329285 | F64: 0.13924057 | G64: 0.035526392
A65: Lower-Middle-Income Economies | B65: 0.031079804 | C65: 0.33653963 | D65: 0.34941396 | E65: 0.20169963 | F65: 0.073507085 | G65: 0.0077599026
A66: Low-Income Economies | B66: 0.16765299 | C66: 0.35339731 | D66: 0.29951984 | E66: 0.13365552 | F66: 0.043048784 | G66: 0.0027255474
A67: AFRO | B67: 0.028094911 | C67: 0.42408199 | D67: 0.32237544 | E67: 0.14725788 | F67: 0.073303781 | G67: 0.0048859963

Sheet Sheet7
A3: Row Labels | B3: Average of Ratio of stock to graduates
A4: High/Upper-Middle-Income Economies | B4: 0.051036475
A5: Lower-Middle-Income Economies | B5: 0.027626283
A6: Low-Income Economies | B6: 0.054110868
A7: (blank)
A8: Grand Total | B8: 0.044941073

Sheet Sheet2
A3: Row Labels | B3: Average of Ratio of stock to graduates
A4: AFRO | B4: 0.0429
A5: High/Upper-Middle-Income Economies | B5: 0.1244052
A6: Lower-Middle-Income Economies | B6: 0.081139451
A7: Low-Income Economies | B7: 0.16169029
A8: Grand Total | B8: 0.12196174

Sheet Projections
A2: Country | B2: Country code | C2: income level | D2: 2013 | E2: 2018 | F2: Adjusted 2022 | G2: Nursing Personnel Stock By Age Group < 25 yrs (prop) | H2: Nursing Personnel Stock By Age Group 25-34 yrs (prop) | I2: Nursing Personnel Stock By Age Group 35-44 yrs (prop) | J2: Nursing Personnel Stock By Age Group 45-54 yrs (prop) | K2: Nursing Personnel Stock By Age Group 55-64 yrs (prop) | L2: Nursing Personnel Stock By Age Group ≥ 65 yrs (prop) | M2: Nursing Personnel Stock By Age Group < 25 yrs | N2: Nursing Personnel Stock By Age Group 25-34 yrs | O2: Nursing Personnel Stock By Age Group 35-44 yrs | P2: Nursing Personnel Stock By Age Group 45-54 yrs | Q2: Nursing Personnel Stock By Age Group 55-64 yrs | R2: Nursing Personnel Stock By Age Group ≥ 65 yrs | S2: Updated Annual graduated | T2: Ratio of stock to graduates | U2: Estimated annual graduates | V2: Projected 2023 | W2: Projected 2024 | X2: Projected 2025 | Y2: Projected 2026 | Z2: Projected 2027 | AA2: Projected 2028 | AB2: Projected 2029 | AC2: Projected 2030 | AD2: Migrated | AE2: Migration factor | AF2: Trajectory
A3: Algeria | B3: DZA | C3: Lower-Middle-Income Economies | D3: 0 | E3: 57705 | F3: 104776 | G3: 0.093988761 | H3: 0.30100512 | I3: 0.16025243 | J3: 0.35528532 | K3: 0.0841148 | L3: 0.0053535658 | M3: =$E$3*G3 -> 5423.6215 | N3: =$E$3*H3 -> 17369.501 | O3: =$E$3*I3 -> 9247.3666 | P3: =$E$3*J3 -> 20501.739 | Q3: =$E$3*K3 -> 4853.8446 | R3: =$E$3*L3 -> 308.92751 | S3: =VLOOKUP(B3,'Edu updated'!B$2:J$48,9,FALSE) -> 0 | T3: 0.0811 | U3: =E3*T3 -> 4679.8755 | V3: =F3*(1-L3)+0.7*U3-AD3*AE3 -> 107436.99 | W3: =V3*(1-0.1*K3)+0.7*U3-AD3*AE3 -> 109755.2 | X3: =W3*(1-0.1*K3)+0.7*U3-AD3*AE3 -> 112053.91 | Y3: =X3*(1-0.1*K3)+0.7*U3-AD3*AE3 -> 114333.28 | Z3: =Y3*(1-0.1*K3)+0.7*U3-AD3*AE3 -> 116593.48 | AA3: =Z3*(1-0.1*K3)+0.7*U3-AD3*AE3 -> 118834.67 | AB3: =AA3*(1-0.1*K3)+0.7*U3-AD3*AE3 -> 121057.01 | AC3: =AB3*(1-0.1*K3)+0.7*U3-AD3*AE3 -> 123260.65 | AD3: =VLOOKUP(B3,Migration!A$2:B$193,2,FALSE) -> 1080 | AE3: =1/20 -> 0.05 | AF3: =IF(AC3<V3,"Decreased","Increased") -> Increased | AG3: =AD3/F3 -> 0.010307704
A4: Angola | B4: AGO | C4: Lower-Middle-Income Economies | D4: 0 | E4: 46082 | F4: 66717.354 | G4: 0.031079804 | H4: 0.33653963 | I4: 0.34941396 | J4: 0.20169963 | K4: 0.073507085 | L4: 0.0077599026 | M4: =$F$4*G4 -> 2073.5623 | N4: =$F$4*H4 -> 22453.033 | O4: =$F$4*I4 -> 23311.975 | P4: =$F$4*J4 -> 13456.865 | Q4: =$F$4*K4 -> 4904.1982 | R4: =$F$4*L4 -> 517.72017 | S4: =VLOOKUP(B4,'Edu updated'!B$2:J$48,9,FALSE) -> 2950 | T4: =S4/F4 -> 0.044216382 | U4: =T4*F4 -> 2950 | V4: =F4*(1-L4)+0.7*U4-AD4*AE4 -> 68260.684 | W4: =V4*(1-0.1*K4)+0.7*U4-AD4*AE4 -> 69819.969 | X4: =W4*(1-0.1*K4)+0.7*U4-AD4*AE4 -> 71367.793 | Y4: =X4*(1-0.1*K4)+0.7*U4-AD4*AE4 -> 72904.239 | Z4: =Y4*(1-0.1*K4)+0.7*U4-AD4*AE4 -> 74429.391 | AA4: =Z4*(1-0.1*K4)+0.7*U4-AD4*AE4 -> 75943.333 | AB4: =AA4*(1-0.1*K4)+0.7*U4-AD4*AE4 -> 77446.145 | AC4: =AB4*(1-0.1*K4)+0.7*U4-AD4*AE4 -> 78937.911 | AD4: =VLOOKUP(B4,Migration!A$2:B$193,2,FALSE) -> 79 | AE4: =1/20 -> 0.05 | AF4: =IF(AC4<V4,"Decreased","Increased") -> Increased | AG4: =AD4/F4 -> 0.0011840997
A5: Benin | B5: BEN | C5: Lower-Middle-Income Economies | D5: 4880 | E5: 3410 | F5: 5893 | G5: 0.037563822 | H5: 0.15973742 | I5: 0.44164843 | J5: 0.30069292 | K5: 0.05269876 | L5: 0.0076586433 | M5: =$F$4*G5 -> 2506.1588 | N5: =$F$4*H5 -> 10657.258 | O5: =$F$4*I5 -> 29465.615 | P5: =$F$4*J5 -> 20061.436 | Q5: =$F$4*K5 -> 3515.9218 | R5: =$F$4*L5 -> 510.96442 | S5: =VLOOKUP(B5,'Edu updated'!B$2:J$48,9,FALSE) -> 257 | T5: =S5/F5 -> 0.043611064 | U5: =T5*F5 -> 257 | V5: =F5*(1-L5)+0.7*U5-AD5*AE5 -> 6027.4676 | W5: =V5*(1-0.1*K5)+0.7*U5-AD5*AE5 -> 6175.3036 | X5: =W5*(1-0.1*K5)+0.7*U5-AD5*AE5 -> 6322.3605 | Y5: =X5*(1-0.1*K5)+0.7*U5-AD5*AE5 -> 6468.6425 | Z5: =Y5*(1-0.1*K5)+0.7*U5-AD5*AE5 -> 6614.1535 | AA5: =Z5*(1-0.1*K5)+0.7*U5-AD5*AE5 -> 6758.8978 | AB5: =AA5*(1-0.1*K5)+0.7*U5-AD5*AE5 -> 6902.8792 | AC5: =AB5*(1-0.1*K5)+0.7*U5-AD5*AE5 -> 7046.1019 | AD5: =VLOOKUP(B5,Migration!A$2:B$193,2,FALSE) -> 6 | AE5: =1/20 -> 0.05 | AF5: =IF(AC5<V5,"Decreased","Increased") -> Increased | AG5: =AD5/F5 -> 0.0010181571
A6: Botswana | B6: BWA | C6: High/Upper-Middle-Income Economies | D6: 5816 | E6: 7645 | F6: 8028 | G6: 0.028276034 | H6: 0.36858495 | I6: 0.33096662 | J6: 0.18709517 | K6: 0.080468361 | L6: 0.004608869 | M6: =$F$4*G6 -> 1886.5022 | N6: =$F$4*H6 -> 24591.013 | O6: =$F$4*I6 -> 22081.217 | P6: =$F$4*J6 -> 12482.494 | Q6: =$F$4*K6 -> 5368.6361 | R6: =$F$4*L6 -> 307.49154 | S6: =VLOOKUP(B6,'Edu updated'!B$2:J$48,9,FALSE) -> 490 | T6: =S6/F6 -> 0.061036373 | U6: =T6*F6 -> 490 | V6: =F6*(1-L6)+0.7*U6-AD6*AE6 -> 8319.9 | W6: =V6*(1-0.1*K6)+0.7*U6-AD6*AE6 -> 8581.8511 | X6: =W6*(1-0.1*K6)+0.7*U6-AD6*AE6 -> 8841.6944 | Y6: =X6*(1-0.1*K6)+0.7*U6-AD6*AE6 -> 9099.4467 | Z6: =Y6*(1-0.1*K6)+0.7*U6-AD6*AE6 -> 9355.125 | AA6: =Z6*(1-0.1*K6)+0.7*U6-AD6*AE6 -> 9608.7458 | AB6: =AA6*(1-0.1*K6)+0.7*U6-AD6*AE6 -> 9860.3258 | AC6: =AB6*(1-0.1*K6)+0.7*U6-AD6*AE6 -> 10109.881 | AD6: =VLOOKUP(B6,Migration!A$2:B$193,2,FALSE) -> 282 | AE6: =1/20 -> 0.05 | AF6: =IF(AC6<V6,"Decreased","Increased") -> Increased | AG6: =AD6/F6 -> 0.035127055
A7: Burkina Faso | B7: BFA | C7: Low-Income Economies | D7: 6196 | E7: 10325 | F7: 13961 | G7: 0.16765299 | H7: 0.35339731 | I7: 0.29951984 | J7: 0.13365552 | K7: 0.043048784 | L7: 0.0027255474 | M7: =$F$4*G7 -> 11185.364 | N7: =$F$4*H7 -> 23577.734 | O7: =$F$4*I7 -> 19983.171 | P7: =$F$4*J7 -> 8917.1429 | Q7: =$F$4*K7 -> 2872.1009 | R7: =$F$4*L7 -> 181.84131 | S7: =VLOOKUP(B7,'Edu updated'!B$2:J$48,9,FALSE) -> 1170 | T7: =S7/F7 -> 0.083804885 | U7: =T7*F7 -> 1170 | V7: =F7*(1-L7)+0.7*U7-AD7*AE7 -> 14738.299 | W7: =V7*(1-0.1*K7)+0.7*U7-AD7*AE7 -> 15490.202 | X7: =W7*(1-0.1*K7)+0.7*U7-AD7*AE7 -> 16238.869 | Y7: =X7*(1-0.1*K7)+0.7*U7-AD7*AE7 -> 16984.312 | Z7: =Y7*(1-0.1*K7)+0.7*U7-AD7*AE7 -> 17726.547 | AA7: =Z7*(1-0.1*K7)+0.7*U7-AD7*AE7 -> 18465.586 | AB7: =AA7*(1-0.1*K7)+0.7*U7-AD7*AE7 -> 19201.444 | AC7: =AB7*(1-0.1*K7)+0.7*U7-AD7*AE7 -> 19934.134 | AD7: =VLOOKUP(B7,Migration!A$2:B$193,2,FALSE) -> 73 | AE7: =1/20 -> 0.05 | AF7: =IF(AC7<V7,"Decreased","Increased") -> Increased | AG7: =AD7/F7 -> 0.0052288518
A8: Burundi | B8: BDI | C8: Low-Income Economies | D8: 6573 | E8: 9156 | F8: 9372 | G8: 0.0022612397 | H8: 0.32016494 | I8: 0.46847566 | J8: 0.16440543 | K8: 0.038840117 | L8: 0.0058526204 | M8: =$F$4*G8 -> 150.86393 | N8: =$F$4*H8 -> 21360.557 | O8: =$F$4*I8 -> 31255.456 | P8: =$F$4*J8 -> 10968.695 | Q8: =$F$4*K8 -> 2591.3098 | R8: =$F$4*L8 -> 390.47134 | S8: =VLOOKUP(B8,'Edu updated'!B$2:J$48,9,FALSE) -> 1467 | T8: =S8/F8 -> 0.15653009 | U8: =T8*F8 -> 1467 | V8: =F8*(1-L8)+0.7*U8-AD8*AE8 -> 10343.399 | W8: =V8*(1-0.1*K8)+0.7*U8-AD8*AE8 -> 11329.475 | X8: =W8*(1-0.1*K8)+0.7*U8-AD8*AE8 -> 12311.722 | Y8: =X8*(1-0.1*K8)+0.7*U8-AD8*AE8 -> 13290.153 | Z8: =Y8*(1-0.1*K8)+0.7*U8-AD8*AE8 -> 14264.784 | AA8: =Z8*(1-0.1*K8)+0.7*U8-AD8*AE8 -> 15235.629 | AB8: =AA8*(1-0.1*K8)+0.7*U8-AD8*AE8 -> 16202.704 | AC8: =AB8*(1-0.1*K8)+0.7*U8-AD8*AE8 -> 17166.022 | AD8: =VLOOKUP(B8,Migration!A$2:B$193,2,FALSE) -> 13 | AE8: =1/20 -> 0.05 | AF8: =IF(AC8<V8,"Decreased","Increased") -> Increased | AG8: =AD8/F8 -> 0.0013871105
A9: Cameroon | B9: CMR | C9: Lower-Middle-Income Economies | D9: 18954 | E9: 9925 | F9: 16473 | G9: 0.017974253 | H9: 0.39561574 | I9: 0.37776293 | J9: 0.17585621 | K9: 0.031637114 | L9: 0.0011537527 | M9: =$F$4*G9 -> 1199.1946 | N9: =$F$4*H9 -> 26394.435 | O9: =$F$4*I9 -> 25203.343 | P9: =$F$4*J9 -> 11732.661 | Q9: =$F$4*K9 -> 2110.7446 | R9: =$F$4*L9 -> 76.975329 | S9: =VLOOKUP(B9,'Edu updated'!B$2:J$48,9,FALSE) -> 2660 | T9: =S9/F9 -> 0.16147636 | U9: =T9*F9 -> 2660 | V9: =F9*(1-L9)+0.7*U9-AD9*AE9 -> 17904.544 | W9: =V9*(1-0.1*K9)+0.7*U9-AD9*AE9 -> 19298.449 | X9: =W9*(1-0.1*K9)+0.7*U9-AD9*AE9 -> 20687.945 | Y9: =X9*(1-0.1*K9)+0.7*U9-AD9*AE9 -> 22073.044 | Z9: =Y9*(1-0.1*K9)+0.7*U9-AD9*AE9 -> 23453.761 | AA9: =Z9*(1-0.1*K9)+0.7*U9-AD9*AE9 -> 24830.11 | AB9: =AA9*(1-0.1*K9)+0.7*U9-AD9*AE9 -> 26202.105 | AC9: =AB9*(1-0.1*K9)+0.7*U9-AD9*AE9 -> 27569.759 | AD9: =VLOOKUP(B9,Migration!A$2:B$193,2,FALSE) -> 8229 | AE9: =1/20 -> 0.05 | AF9: =IF(AC9<V9,"Decreased","Increased") -> Increased | AG9: =AD9/F9 -> 0.49954471
A10: Cape-Verde | B10: CPV | C10: Lower-Middle-Income Economies | D10: 403 | E10: 768 | F10: 941 | G10: 0 | H10: 0.26886291 | I10: 0.26461211 | J10: 0.27842721 | K10: 0.1360255 | L10: 0.052072264 | M10: =$F$4*G10 -> 0 | N10: =$F$4*H10 -> 17937.822 | O10: =$F$4*I10 -> 17654.22 | P10: =$F$4*J10 -> 18575.926 | Q10: =$F$4*K10 -> 9075.2617 | R10: =$F$4*L10 -> 3474.1236 | S10: =VLOOKUP(B10,'Edu updated'!B$2:J$48,9,FALSE) -> 0 | T10: 0.0811 | U10: =T10*F10 -> 76.3151 | V10: =F10*(1-L10)+0.7*U10-AD10*AE10 -> 931.72057 | W10: =V10*(1-0.1*K10)+0.7*U10-AD10*AE10 -> 958.76736 | X10: =W10*(1-0.1*K10)+0.7*U10-AD10*AE10 -> 985.44625 | Y10: =X10*(1-0.1*K10)+0.7*U10-AD10*AE10 -> 1011.7622 | Z10: =Y10*(1-0.1*K10)+0.7*U10-AD10*AE10 -> 1037.7203 | AA10: =Z10*(1-0.1*K10)+0.7*U10-AD10*AE10 -> 1063.3252 | AB10: =AA10*(1-0.1*K10)+0.7*U10-AD10*AE10 -> 1088.5818 | AC10: =AB10*(1-0.1*K10)+0.7*U10-AD10*AE10 -> 1113.4949 | AD10: =VLOOKUP(B10,Migration!A$2:B$193,2,FALSE) -> 274 | AE10: =1/20 -> 0.05 | AF10: =IF(AC10<V10,"Decreased","Increased") -> Increased | AG10: =AD10/F10 -> 0.2911796
A11: Central African Republic | B11: CAF | C11: Low-Income Economies | D11: 322 | E11: 1195 | F11: 648.48015 | G11: 0.16765299 | H11: 0.35339731 | I11: 0.29951984 | J11: 0.13365552 | K11: 0.043048784 | L11: 0.0027255474 | M11: =$F$4*G11 -> 11185.364 | N11: =$F$4*H11 -> 23577.734 | O11: =$F$4*I11 -> 19983.171 | P11: =$F$4*J11 -> 8917.1429 | Q11: =$F$4*K11 -> 2872.1009 | R11: =$F$4*L11 -> 181.84131 | S11: =VLOOKUP(B11,'Edu updated'!B$2:J$48,9,FALSE) -> 0 | T11: 0.162 | U11: =T11*F11 -> 105.05378 | V11: =F11*(1-L11)+0.7*U11-AD11*AE11 -> 720.20033 | W11: =V11*(1-0.1*K11)+0.7*U11-AD11*AE11 -> 790.58761 | X11: =W11*(1-0.1*K11)+0.7*U11-AD11*AE11 -> 860.67187 | Y11: =X11*(1-0.1*K11)+0.7*U11-AD11*AE11 -> 930.45443 | Z11: =Y11*(1-0.1*K11)+0.7*U11-AD11*AE11 -> 999.93659 | AA11: =Z11*(1-0.1*K11)+0.7*U11-AD11*AE11 -> 1069.1196 | AB11: =AA11*(1-0.1*K11)+0.7*U11-AD11*AE11 -> 1138.0049 | AC11: =AB11*(1-0.1*K11)+0.7*U11-AD11*AE11 -> 1206.5935 | AD11: =VLOOKUP(B11,Migration!A$2:B$193,2,FALSE) -> 1 | AE11: =1/20 -> 0.05 | AF11: =IF(AC11<V11,"Decreased","Increased") -> Increased | AG11: =AD11/F11 -> 0.0015420673
A12: Chad | B12: TCD | C12: Low-Income Economies | D12: 3606 | E12: 4799 | F12: 3387.1517 | G12: 0.036531037 | H12: 0.44371844 | I12: 0.31006831 | J12: 0.14582715 | K12: 0.063855064 | L12: 0 | M12: =$F$4*G12 -> 2437.2541 | N12: =$F$4*H12 -> 29603.72 | O12: =$F$4*I12 -> 20686.937 | P12: =$F$4*J12 -> 9729.2013 | Q12: =$F$4*K12 -> 4260.2409 | R12: =$F$4*L12 -> 0 | S12: =VLOOKUP(B12,'Edu updated'!B$2:J$48,9,FALSE) -> 2920 | T12: =S12/F12 -> 0.86208125 | U12: =T12*F12 -> 2920 | V12: =F12*(1-L12)+0.7*U12-AD12*AE12 -> 5427.8017 | W12: =V12*(1-0.1*K12)+0.7*U12-AD12*AE12 -> 7433.7925 | X12: =W12*(1-0.1*K12)+0.7*U12-AD12*AE12 -> 9426.9739 | Y12: =X12*(1-0.1*K12)+0.7*U12-AD12*AE12 -> 11407.428 | Z12: =Y12*(1-0.1*K12)+0.7*U12-AD12*AE12 -> 13375.236 | AA12: =Z12*(1-0.1*K12)+0.7*U12-AD12*AE12 -> 15330.478 | AB12: =AA12*(1-0.1*K12)+0.7*U12-AD12*AE12 -> 17273.235 | AC12: =AB12*(1-0.1*K12)+0.7*U12-AD12*AE12 -> 19203.587 | AD12: =VLOOKUP(B12,Migration!A$2:B$193,2,FALSE) -> 67 | AE12: =1/20 -> 0.05 | AF12: =IF(AC12<V12,"Decreased","Increased") -> Increased | AG12: =AD12/F12 -> 0.019780631
A13: Comoros | B13: COM | C13: Lower-Middle-Income Economies | D13: 0 | E13: 747 | F13: 784.97097 | G13: 0.031079804 | H13: 0.33653963 | I13: 0.34941396 | J13: 0.20169963 | K13: 0.073507085 | L13: 0.0077599026 | M13: =$F$4*G13 -> 2073.5623 | N13: =$F$4*H13 -> 22453.033 | O13: =$F$4*I13 -> 23311.975 | P13: =$F$4*J13 -> 13456.865 | Q13: =$F$4*K13 -> 4904.1982 | R13: =$F$4*L13 -> 517.72017 | S13: =VLOOKUP(B13,'Edu updated'!B$2:J$48,9,FALSE) -> 40 | T13: =S13/F13 -> 0.050957298 | U13: =T13*F13 -> 40 | V13: =F13*(1-L13)+0.7*U13-AD13*AE13 -> 806.87968 | W13: =V13*(1-0.1*K13)+0.7*U13-AD13*AE13 -> 828.94854 | X13: =W13*(1-0.1*K13)+0.7*U13-AD13*AE13 -> 850.85518 | Y13: =X13*(1-0.1*K13)+0.7*U13-AD13*AE13 -> 872.60079 | Z13: =Y13*(1-0.1*K13)+0.7*U13-AD13*AE13 -> 894.18656 | AA13: =Z13*(1-0.1*K13)+0.7*U13-AD13*AE13 -> 915.61365 | AB13: =AA13*(1-0.1*K13)+0.7*U13-AD13*AE13 -> 936.88324 | AC13: =AB13*(1-0.1*K13)+0.7*U13-AD13*AE13 -> 957.99649 | AD13: 0 | AE13: =1/20 -> 0.05 | AF13: =IF(AC13<V13,"Decreased","Increased") -> Increased | AG13: =AD13/F13 -> 0
A14: Congo | B14: COG | C14: Lower-Middle-Income Economies | D14: 3289 | E14: 5081 | F14: 5573 | G14: 0.013457743 | H14: 0.12739996 | I14: 0.46438184 | J14: 0.27310246 | K14: 0.12111968 | L14: 0.00053830971 | M14: =$F$4*G14 -> 897.86498 | N14: =$F$4*H14 -> 8499.7885 | O14: =$F$4*I14 -> 30982.328 | P14: =$F$4*J14 -> 18220.673 | Q14: =$F$4*K14 -> 8080.7848 | R14: =$F$4*L14 -> 35.914599 | S14: =VLOOKUP(B14,'Edu updated'!B$2:J$48,9,FALSE) -> 60 | T14: =S14/F14 -> 0.010766194 | U14: =T14*F14 -> 60 | V14: =F14*(1-L14)+0.7*U14-AD14*AE14 -> 5597.6 | W14: =V14*(1-0.1*K14)+0.7*U14-AD14*AE14 -> 5557.402 | X14: =W14*(1-0.1*K14)+0.7*U14-AD14*AE14 -> 5517.691 | Y14: =X14*(1-0.1*K14)+0.7*U14-AD14*AE14 -> 5478.4609 | Z14: =Y14*(1-0.1*K14)+0.7*U14-AD14*AE14 -> 5439.7059 | AA14: =Z14*(1-0.1*K14)+0.7*U14-AD14*AE14 -> 5401.4204 | AB14: =AA14*(1-0.1*K14)+0.7*U14-AD14*AE14 -> 5363.5985 | AC14: =AB14*(1-0.1*K14)+0.7*U14-AD14*AE14 -> 5326.2348 | AD14: =VLOOKUP(B14,Migration!A$2:B$193,2,FALSE) -> 288 | AE14: =1/20 -> 0.05 | AF14: =IF(AC14<V14,"Decreased","Increased") -> Decreased | AG14: =AD14/F14 -> 0.051677732
A15: Cote d'Ivoire | B15: CIV | C15: Lower-Middle-Income Economies | D15: 8780 | E15: 15163 | F15: 19225.233 | G15: 0.0023366046 | H15: 0.25175245 | I15: 0.45316777 | J15: 0.20134855 | K15: 0.091194339 | L15: 0.00020028039 | M15: =$F$4*G15 -> 155.89207 | N15: =$F$4*H15 -> 16796.258 | O15: =$F$4*I15 -> 30234.154 | P15: =$F$4*J15 -> 13433.443 | Q15: =$F$4*K15 -> 6084.245 | R15: =$F$4*L15 -> 13.362178 | S15: =VLOOKUP(B15,'Edu updated'!B$2:J$48,9,FALSE) -> 1007 | T15: =S15/F15 -> 0.052379078 | U15: =T15*F15 -> 1007 | V15: =F15*(1-L15)+0.7*U15-AD15*AE15 -> 19907.283 | W15: =V15*(1-0.1*K15)+0.7*U15-AD15*AE15 -> 20411.64 | X15: =W15*(1-0.1*K15)+0.7*U15-AD15*AE15 -> 20911.397 | Y15: =X15*(1-0.1*K15)+0.7*U15-AD15*AE15 -> 21406.597 | Z15: =Y15*(1-0.1*K15)+0.7*U15-AD15*AE15 -> 21897.281 | AA15: =Z15*(1-0.1*K15)+0.7*U15-AD15*AE15 -> 22383.49 | AB15: =AA15*(1-0.1*K15)+0.7*U15-AD15*AE15 -> 22865.266 | AC15: =AB15*(1-0.1*K15)+0.7*U15-AD15*AE15 -> 23342.647 | AD15: =VLOOKUP(B15,Migration!A$2:B$193,2,FALSE) -> 380 | AE15: =1/20 -> 0.05 | AF15: =IF(AC15<V15,"Decreased","Increased") -> Increased | AG15: =AD15/F15 -> 0.01976569
A16: DRC | B16: COD | C16: Low-Income Economies | D16: 59813 | E16: 103785 | F16: 115316 | G16: 0.16765299 | H16: 0.35339731 | I16: 0.29951984 | J16: 0.13365552 | K16: 0.043048784 | L16: 0.0027255474 | M16: =$F$4*G16 -> 11185.364 | N16: =$F$4*H16 -> 23577.734 | O16: =$F$4*I16 -> 19983.171 | P16: =$F$4*J16 -> 8917.1429 | Q16: =$F$4*K16 -> 2872.1009 | R16: =$F$4*L16 -> 181.84131 | S16: =VLOOKUP(B16,'Edu updated'!B$2:J$48,9,FALSE) -> 24061 | T16: =S16/F16 -> 0.20865275 | U16: =T16*F16 -> 24061 | V16: =F16*(1-L16)+0.7*U16-AD16*AE16 -> 131840.9 | W16: =V16*(1-0.1*K16)+0.7*U16-AD16*AE16 -> 148112.54 | X16: =W16*(1-0.1*K16)+0.7*U16-AD16*AE16 -> 164314.14 | Y16: =X16*(1-0.1*K16)+0.7*U16-AD16*AE16 -> 180445.98 | Z16: =Y16*(1-0.1*K16)+0.7*U16-AD16*AE16 -> 196508.38 | AA16: =Z16*(1-0.1*K16)+0.7*U16-AD16*AE16 -> 212501.64 | AB16: =AA16*(1-0.1*K16)+0.7*U16-AD16*AE16 -> 228426.05 | AC16: =AB16*(1-0.1*K16)+0.7*U16-AD16*AE16 -> 244281.9 | AD16: =VLOOKUP(B16,Migration!A$2:B$193,2,FALSE) -> 70 | AE16: =1/20 -> 0.05 | AF16: =IF(AC16<V16,"Decreased","Increased") -> Increased | AG16: =AD16/F16 -> 0.00060702765
A17: Equatorial Guinea | B17: GNQ | C17: High/Upper-Middle-Income Economies | D17: 0 | E17: 355 | F17: 1375 | G17: 0.018679111 | H17: 0.24613492 | I17: 0.31712616 | J17: 0.24329285 | K17: 0.13924057 | L17: 0.035526392 | M17: =$F$4*G17 -> 1246.2209 | N17: =$F$4*H17 -> 16421.47 | O17: =$F$4*I17 -> 21157.818 | P17: =$F$4*J17 -> 16231.855 | Q17: =$F$4*K17 -> 9289.7624 | R17: =$F$4*L17 -> 2370.2269 | S17: =VLOOKUP(B17,'Edu updated'!B$2:J$48,9,FALSE) -> 962 | T17: =S17/F17 -> 0.69963636 | U17: =T17*F17 -> 962 | V17: =F17*(1-L17)+0.7*U17-AD17*AE17 -> 1999.0512 | W17: =V17*(1-0.1*K17)+0.7*U17-AD17*AE17 -> 2644.1163 | X17: =W17*(1-0.1*K17)+0.7*U17-AD17*AE17 -> 3280.1995 | Y17: =X17*(1-0.1*K17)+0.7*U17-AD17*AE17 -> 3907.4258 | Z17: =Y17*(1-0.1*K17)+0.7*U17-AD17*AE17 -> 4525.9186 | AA17: =Z17*(1-0.1*K17)+0.7*U17-AD17*AE17 -> 5135.7994 | AB17: =AA17*(1-0.1*K17)+0.7*U17-AD17*AE17 -> 5737.1883 | AC17: =AB17*(1-0.1*K17)+0.7*U17-AD17*AE17 -> 6330.2033 | AD17: =VLOOKUP(B17,Migration!A$2:B$193,2,FALSE) -> 10 | AE17: =1/20 -> 0.05 | AF17: =IF(AC17<V17,"Decreased","Increased") -> Increased | AG17: =AD17/F17 -> 0.0072727273
A18: Eritrea | B18: ERI | C18: Low-Income Economies | D18: 4262 | E18: 4971 | F18: 5007 | G18: 0.17155982 | H18: 0.41601758 | I18: 0.18773717 | J18: 0.18294388 | K18: 0.041741562 | L18: 0 | M18: =$F$4*G18 -> 11446.017 | N18: =$F$4*H18 -> 27755.592 | O18: =$F$4*I18 -> 12525.327 | P18: =$F$4*J18 -> 12205.531 | Q18: =$F$4*K18 -> 2784.8865 | R18: =$F$4*L18 -> 0 | S18: =VLOOKUP(B18,'Edu updated'!B$2:J$48,9,FALSE) -> 400 | T18: =S18/F18 -> 0.079888157 | U18: =T18*F18 -> 400 | V18: =F18*(1-L18)+0.7*U18-AD18*AE18 -> 5198.7 | W18: =V18*(1-0.1*K18)+0.7*U18-AD18*AE18 -> 5368.6998 | X18: =W18*(1-0.1*K18)+0.7*U18-AD18*AE18 -> 5537.99 | Y18: =X18*(1-0.1*K18)+0.7*U18-AD18*AE18 -> 5706.5736 | Z18: =Y18*(1-0.1*K18)+0.7*U18-AD18*AE18 -> 5874.4535 | AA18: =Z18*(1-0.1*K18)+0.7*U18-AD18*AE18 -> 6041.6326 | AB18: =AA18*(1-0.1*K18)+0.7*U18-AD18*AE18 -> 6208.1139 | AC18: =AB18*(1-0.1*K18)+0.7*U18-AD18*AE18 -> 6373.9002 | AD18: =VLOOKUP(B18,Migration!A$2:B$193,2,FALSE) -> 1766 | AE18: =1/20 -> 0.05 | AF18: =IF(AC18<V18,"Decreased","Increased") -> Increased | AG18: =AD18/F18 -> 0.35270621
A19: Eswatini | B19: SWZ | C19: Lower-Middle-Income Economies | D19: 3735 | E19: 4706 | F19: 5242 | G19: 0.028271113 | H19: 0.38963393 | I19: 0.30518304 | J19: 0.18412468 | K19: 0.086625589 | L19: 0.0061616528 | M19: =$F$4*G19 -> 1886.1738 | N19: =$F$4*H19 -> 25995.344 | O19: =$F$4*I19 -> 20361.005 | P19: =$F$4*J19 -> 12284.312 | Q19: =$F$4*K19 -> 5779.4301 | R19: =$F$4*L19 -> 411.08917 | S19: =VLOOKUP(B19,'Edu updated'!B$2:J$48,9,FALSE) -> 160 | T19: =S19/F19 -> 0.030522701 | U19: =T19*F19 -> 160 | V19: =F19*(1-L19)+0.7*U19-AD19*AE19 -> 5315.6006 | W19: =V19*(1-0.1*K19)+0.7*U19-AD19*AE19 -> 5375.4539 | X19: =W19*(1-0.1*K19)+0.7*U19-AD19*AE19 -> 5434.7887 | Y19: =X19*(1-0.1*K19)+0.7*U19-AD19*AE19 -> 5493.6095 | Z19: =Y19*(1-0.1*K19)+0.7*U19-AD19*AE19 -> 5551.9208 | AA19: =Z19*(1-0.1*K19)+0.7*U19-AD19*AE19 -> 5609.727 | AB19: =AA19*(1-0.1*K19)+0.7*U19-AD19*AE19 -> 5667.0324 | AC19: =AB19*(1-0.1*K19)+0.7*U19-AD19*AE19 -> 5723.8414 | AD19: =VLOOKUP(B19,Migration!A$2:B$193,2,FALSE) -> 122 | AE19: =1/20 -> 0.05 | AF19: =IF(AC19<V19,"Decreased","Increased") -> Increased | AG19: =AD19/F19 -> 0.02327356
A20: Ethiopia | B20: ETH | C20: Low-Income Economies | D20: 0 | E20: 61772 | F20: 131262 | G20: 0.16765299 | H20: 0.35339731 | I20: 0.29951984 | J20: 0.13365552 | K20: 0.043048784 | L20: 0.0027255474 | M20: =$F$4*G20 -> 11185.364 | N20: =$F$4*H20 -> 23577.734 | O20: =$F$4*I20 -> 19983.171 | P20: =$F$4*J20 -> 8917.1429 | Q20: =$F$4*K20 -> 2872.1009 | R20: =$F$4*L20 -> 181.84131 | S20: =VLOOKUP(B20,'Edu updated'!B$2:J$48,9,FALSE) -> 6298 | T20: =S20/F20 -> 0.047980375 | U20: =T20*F20 -> 6298 | V20: =F20*(1-L20)+0.7*U20-AD20*AE20 -> 134997.14 | W20: =V20*(1-0.1*K20)+0.7*U20-AD20*AE20 -> 138508.89 | X20: =W20*(1-0.1*K20)+0.7*U20-AD20*AE20 -> 142005.53 | Y20: =X20*(1-0.1*K20)+0.7*U20-AD20*AE20 -> 145487.11 | Z20: =Y20*(1-0.1*K20)+0.7*U20-AD20*AE20 -> 148953.71 | AA20: =Z20*(1-0.1*K20)+0.7*U20-AD20*AE20 -> 152405.38 | AB20: =AA20*(1-0.1*K20)+0.7*U20-AD20*AE20 -> 155842.19 | AC20: =AB20*(1-0.1*K20)+0.7*U20-AD20*AE20 -> 159264.21 | AD20: =VLOOKUP(B20,Migration!A$2:B$193,2,FALSE) -> 6314 | AE20: =1/20 -> 0.05 | AF20: =IF(AC20<V20,"Decreased","Increased") -> Increased | AG20: =AD20/F20 -> 0.048102269
A21: Gabon | B21: GAB | C21: High/Upper-Middle-Income Economies | D21: 0 | E21: 6085 | F21: 4751.5999 | G21: 0 | H21: 0.14379238 | I21: 0.38812252 | J21: 0.358195 | K21: 0.10989011 | L21: 0 | M21: =$F$4*G21 -> 0 | N21: =$F$4*H21 -> 9593.4469 | O21: =$F$4*I21 -> 25894.507 | P21: =$F$4*J21 -> 23897.822 | Q21: =$F$4*K21 -> 7331.5773 | R21: =$F$4*L21 -> 0 | S21: =VLOOKUP(B21,'Edu updated'!B$2:J$48,9,FALSE) -> 95 | T21: =S21/F21 -> 0.019993266 | U21: =T21*F21 -> 95 | V21: =F21*(1-L21)+0.7*U21-AD21*AE21 -> 4812.7999 | W21: =V21*(1-0.1*K21)+0.7*U21-AD21*AE21 -> 4821.112 | X21: =W21*(1-0.1*K21)+0.7*U21-AD21*AE21 -> 4829.3327 | Y21: =X21*(1-0.1*K21)+0.7*U21-AD21*AE21 -> 4837.4631 | Z21: =Y21*(1-0.1*K21)+0.7*U21-AD21*AE21 -> 4845.5042 | AA21: =Z21*(1-0.1*K21)+0.7*U21-AD21*AE21 -> 4853.4569 | AB21: =AA21*(1-0.1*K21)+0.7*U21-AD21*AE21 -> 4861.3222 | AC21: =AB21*(1-0.1*K21)+0.7*U21-AD21*AE21 -> 4869.1011 | AD21: =VLOOKUP(B21,Migration!A$2:B$193,2,FALSE) -> 106 | AE21: =1/20 -> 0.05 | AF21: =IF(AC21<V21,"Decreased","Increased") -> Increased | AG21: =AD21/F21 -> 0.022308276
A22: Gambia | B22: GMB | C22: Low-Income Economies | D22: 2386 | E22: 1498 | F22: 1429.4037 | G22: 0.16765299 | H22: 0.35339731 | I22: 0.29951984 | J22: 0.13365552 | K22: 0.043048784 | L22: 0.0027255474 | M22: =$F$4*G22 -> 11185.364 | N22: =$F$4*H22 -> 23577.734 | O22: =$F$4*I22 -> 19983.171 | P22: =$F$4*J22 -> 8917.1429 | Q22: =$F$4*K22 -> 2872.1009 | R22: =$F$4*L22 -> 181.84131 | S22: =VLOOKUP(B22,'Edu updated'!B$2:J$48,9,FALSE) -> 137 | T22: =S22/F22 -> 0.095844164 | U22: =T22*F22 -> 137 | V22: =F22*(1-L22)+0.7*U22-AD22*AE22 -> 1501.1578 | W22: =V22*(1-0.1*K22)+0.7*U22-AD22*AE22 -> 1570.3455 | X22: =W22*(1-0.1*K22)+0.7*U22-AD22*AE22 -> 1639.2353 | Y22: =X22*(1-0.1*K22)+0.7*U22-AD22*AE22 -> 1707.8286 | Z22: =Y22*(1-0.1*K22)+0.7*U22-AD22*AE22 -> 1776.1266 | AA22: =Z22*(1-0.1*K22)+0.7*U22-AD22*AE22 -> 1844.1306 | AB22: =AA22*(1-0.1*K22)+0.7*U22-AD22*AE22 -> 1911.8418 | AC22: =AB22*(1-0.1*K22)+0.7*U22-AD22*AE22 -> 1979.2616 | AD22: =VLOOKUP(B22,Migration!A$2:B$193,2,FALSE) -> 405 | AE22: =1/20 -> 0.05 | AF22: =IF(AC22<V22,"Decreased","Increased") -> Increased | AG22: =AD22/F22 -> 0.28333494
A23: Ghana | B23: GHA | C23: Lower-Middle-Income Economies | D23: 37404 | E23: 125024 | F23: 124204.28 | G23: 0.00039127948 | H23: 0.66800437 | I23: 0.30801722 | J23: 0.015661212 | K23: 0.0079259178 | L23: 0 | M23: =$F$4*G23 -> 26.105132 | N23: =$F$4*H23 -> 44567.484 | O23: =$F$4*I23 -> 20550.094 | P23: =$F$4*J23 -> 1044.8746 | Q23: =$F$4*K23 -> 528.79626 | R23: =$F$4*L23 -> 0 | S23: =VLOOKUP(B23,'Edu updated'!B$2:J$48,9,FALSE) -> 21271 | T23: =S23/F23 -> 0.17125819 | U23: =T23*F23 -> 21271 | V23: =F23*(1-L23)+0.7*U23-AD23*AE23 -> 138466.28 | W23: =V23*(1-0.1*K23)+0.7*U23-AD23*AE23 -> 152618.53 | X23: =W23*(1-0.1*K23)+0.7*U23-AD23*AE23 -> 166759.57 | Y23: =X23*(1-0.1*K23)+0.7*U23-AD23*AE23 -> 180889.39 | Z23: =Y23*(1-0.1*K23)+0.7*U23-AD23*AE23 -> 195008.02 | AA23: =Z23*(1-0.1*K23)+0.7*U23-AD23*AE23 -> 209115.46 | AB23: =AA23*(1-0.1*K23)+0.7*U23-AD23*AE23 -> 223211.72 | AC23: =AB23*(1-0.1*K23)+0.7*U23-AD23*AE23 -> 237296.8 | AD23: =VLOOKUP(B23,Migration!A$2:B$193,2,FALSE) -> 12554 | AE23: =1/20 -> 0.05 | AF23: =IF(AC23<V23,"Decreased","Increased") -> Increased | AG23: =AD23/F23 -> 0.10107542
A24: Guinea | B24: GIN | C24: Low-Income Economies | D24: 5789 | E24: 7195 | F24: 5018.9872 | G24: 0.16765299 | H24: 0.35339731 | I24: 0.29951984 | J24: 0.13365552 | K24: 0.043048784 | L24: 0.0027255474 | M24: =$F$4*G24 -> 11185.364 | N24: =$F$4*H24 -> 23577.734 | O24: =$F$4*I24 -> 19983.171 | P24: =$F$4*J24 -> 8917.1429 | Q24: =$F$4*K24 -> 2872.1009 | R24: =$F$4*L24 -> 181.84131 | S24: =VLOOKUP(B24,'Edu updated'!B$2:J$48,9,FALSE) -> 964 | T24: =S24/F24 -> 0.19207062 | U24: =T24*F24 -> 964 | V24: =F24*(1-L24)+0.7*U24-AD24*AE24 -> 5663.8577 | W24: =V24*(1-0.1*K24)+0.7*U24-AD24*AE24 -> 6298.0255 | X24: =W24*(1-0.1*K24)+0.7*U24-AD24*AE24 -> 6929.4632 | Y24: =X24*(1-0.1*K24)+0.7*U24-AD24*AE24 -> 7558.1827 | Z24: =Y24*(1-0.1*K24)+0.7*U24-AD24*AE24 -> 8184.1957 | AA24: =Z24*(1-0.1*K24)+0.7*U24-AD24*AE24 -> 8807.5137 | AB24: =AA24*(1-0.1*K24)+0.7*U24-AD24*AE24 -> 9428.1484 | AC24: =AB24*(1-0.1*K24)+0.7*U24-AD24*AE24 -> 10046.111 | AD24: =VLOOKUP(B24,Migration!A$2:B$193,2,FALSE) -> 325 | AE24: =1/20 -> 0.05 | AF24: =IF(AC24<V24,"Decreased","Increased") -> Increased | AG24: =AD24/F24 -> 0.0647541
A25: Guinea-Bissau | B25: GNB | C25: Low-Income Economies | D25: 727 | E25: 1264 | F25: 1879 | G25: 0 | H25: 0.35071847 | I25: 0.45928685 | J25: 0.11122938 | K25: 0.071314529 | L25: 0.0074507717 | M25: =$F$4*G25 -> 0 | N25: =$F$4*H25 -> 23399.008 | O25: =$F$4*I25 -> 30642.404 | P25: =$F$4*J25 -> 7420.9297 | Q25: =$F$4*K25 -> 4757.9167 | R25: =$F$4*L25 -> 497.09577 | S25: =VLOOKUP(B25,'Edu updated'!B$2:J$48,9,FALSE) -> 0 | T25: 0.162 | U25: =T25*F25 -> 304.398 | V25: =F25*(1-L25)+0.7*U25-AD25*AE25 -> 2075.4786 | W25: =V25*(1-0.1*K25)+0.7*U25-AD25*AE25 -> 2271.156 | X25: =W25*(1-0.1*K25)+0.7*U25-AD25*AE25 -> 2465.438 | Y25: =X25*(1-0.1*K25)+0.7*U25-AD25*AE25 -> 2658.3344 | Z25: =Y25*(1-0.1*K25)+0.7*U25-AD25*AE25 -> 2849.8552 | AA25: =Z25*(1-0.1*K25)+0.7*U25-AD25*AE25 -> 3040.0102 | AB25: =AA25*(1-0.1*K25)+0.7*U25-AD25*AE25 -> 3228.8091 | AC25: =AB25*(1-0.1*K25)+0.7*U25-AD25*AE25 -> 3416.2616 | AD25: =VLOOKUP(B25,Migration!A$2:B$193,2,FALSE) -> 52 | AE25: =1/20 -> 0.05 | AF25: =IF(AC25<V25,"Decreased","Increased") -> Increased | AG25: =AD25/F25 -> 0.027674295
A26: Kenya | B26: KEN | C26: Lower-Middle-Income Economies | D26: 40292 | E26: 59901 | F26: 109659 | G26: 0.010398758 | H26: 0.30655538 | I26: 0.33922134 | J26: 0.2402529 | K26: 0.10199102 | L26: 0.0015806112 | M26: =$F$4*G26 -> 693.7776 | N26: =$F$4*H26 -> 20452.564 | O26: =$F$4*I26 -> 22631.95 | P26: =$F$4*J26 -> 16029.038 | Q26: =$F$4*K26 -> 6804.5707 | R26: =$F$4*L26 -> 105.45419 | S26: =VLOOKUP(B26,'Edu updated'!B$2:J$48,9,FALSE) -> 1070 | T26: =S26/F26 -> 0.009757521 | U26: =T26*F26 -> 1070 | V26: =F26*(1-L26)+0.7*U26-AD26*AE26 -> 109501.27 | W26: =V26*(1-0.1*K26)+0.7*U26-AD26*AE26 -> 108400.06 | X26: =W26*(1-0.1*K26)+0.7*U26-AD26*AE26 -> 107310.07 | Y26: =X26*(1-0.1*K26)+0.7*U26-AD26*AE26 -> 106231.21 | Z26: =Y26*(1-0.1*K26)+0.7*U26-AD26*AE26 -> 105163.34 | AA26: =Z26*(1-0.1*K26)+0.7*U26-AD26*AE26 -> 104106.37 | AB26: =AA26*(1-0.1*K26)+0.7*U26-AD26*AE26 -> 103060.18 | AC26: =AB26*(1-0.1*K26)+0.7*U26-AD26*AE26 -> 102024.66 | AD26: =VLOOKUP(B26,Migration!A$2:B$193,2,FALSE) -> 14668 | AE26: =1/20 -> 0.05 | AF26: =IF(AC26<V26,"Decreased","Increased") -> Decreased | AG26: =AD26/F26 -> 0.13376011
A27: Lesotho | B27: LSO | C27: Lower-Middle-Income Economies | D27: 0 | E27: 6866 | F27: 1235.4801 | G27: 0.031079804 | H27: 0.33653963 | I27: 0.34941396 | J27: 0.20169963 | K27: 0.073507085 | L27: 0.0077599026 | M27: =$F$4*G27 -> 2073.5623 | N27: =$F$4*H27 -> 22453.033 | O27: =$F$4*I27 -> 23311.975 | P27: =$F$4*J27 -> 13456.865 | Q27: =$F$4*K27 -> 4904.1982 | R27: =$F$4*L27 -> 517.72017 | S27: =VLOOKUP(B27,'Edu updated'!B$2:J$48,9,FALSE) -> 376 | T27: =S27/F27 -> 0.30433512 | U27: =T27*F27 -> 376 | V27: =F27*(1-L27)+0.7*U27-AD27*AE27 -> 1484.5429 | W27: =V27*(1-0.1*K27)+0.7*U27-AD27*AE27 -> 1732.2805 | X27: =W27*(1-0.1*K27)+0.7*U27-AD27*AE27 -> 1978.197 | Y27: =X27*(1-0.1*K27)+0.7*U27-AD27*AE27 -> 2222.3058 | Z27: =Y27*(1-0.1*K27)+0.7*U27-AD27*AE27 -> 2464.6203 | AA27: =Z27*(1-0.1*K27)+0.7*U27-AD27*AE27 -> 2705.1536 | AB27: =AA27*(1-0.1*K27)+0.7*U27-AD27*AE27 -> 2943.9188 | AC27: =AB27*(1-0.1*K27)+0.7*U27-AD27*AE27 -> 3180.9289 | AD27: =VLOOKUP(B27,Migration!A$2:B$193,2,FALSE) -> 91 | AE27: =1/20 -> 0.05 | AF27: =IF(AC27<V27,"Decreased","Increased") -> Increased | AG27: =AD27/F27 -> 0.073655575
A28: Liberia | B28: LBR | C28: Low-Income Economies | D28: 0 | E28: 8488 | F28: 4423.7953 | G28: 0.16765299 | H28: 0.35339731 | I28: 0.29951984 | J28: 0.13365552 | K28: 0.043048784 | L28: 0.0027255474 | M28: =$F$4*G28 -> 11185.364 | N28: =$F$4*H28 -> 23577.734 | O28: =$F$4*I28 -> 19983.171 | P28: =$F$4*J28 -> 8917.1429 | Q28: =$F$4*K28 -> 2872.1009 | R28: =$F$4*L28 -> 181.84131 | S28: =VLOOKUP(B28,'Edu updated'!B$2:J$48,9,FALSE) -> 63 | T28: =S28/F28 -> 0.014241165 | U28: =T28*F28 -> 63 | V28: =F28*(1-L28)+0.7*U28-AD28*AE28 -> 4171.138 | W28: =V28*(1-0.1*K28)+0.7*U28-AD28*AE28 -> 3912.5818 | X28: =W28*(1-0.1*K28)+0.7*U28-AD28*AE28 -> 3655.1386 | Y28: =X28*(1-0.1*K28)+0.7*U28-AD28*AE28 -> 3398.8037 | Z28: =Y28*(1-0.1*K28)+0.7*U28-AD28*AE28 -> 3143.5722 | AA28: =Z28*(1-0.1*K28)+0.7*U28-AD28*AE28 -> 2889.4395 | AB28: =AA28*(1-0.1*K28)+0.7*U28-AD28*AE28 -> 2636.4008 | AC28: =AB28*(1-0.1*K28)+0.7*U28-AD28*AE28 -> 2384.4515 | AD28: =VLOOKUP(B28,Migration!A$2:B$193,2,FALSE) -> 5694 | AE28: =1/20 -> 0.05 | AF28: =IF(AC28<V28,"Decreased","Increased") -> Decreased | AG28: =AD28/F28 -> 1.2871301
A29: Madagascar | B29: MDG | C29: Low-Income Economies | D29: 3438 | E29: 4560 | F29: 4560 | G29: 0.16765299 | H29: 0.35339731 | I29: 0.29951984 | J29: 0.13365552 | K29: 0.043048784 | L29: 0.0027255474 | M29: =$F$4*G29 -> 11185.364 | N29: =$F$4*H29 -> 23577.734 | O29: =$F$4*I29 -> 19983.171 | P29: =$F$4*J29 -> 8917.1429 | Q29: =$F$4*K29 -> 2872.1009 | R29: =$F$4*L29 -> 181.84131 | S29: =VLOOKUP(B29,'Edu updated'!B$2:J$48,9,FALSE) -> 2540 | T29: =S29/F29 -> 0.55701754 | U29: =T29*F29 -> 2540 | V29: =F29*(1-L29)+0.7*U29-AD29*AE29 -> 6325.4215 | W29: =V29*(1-0.1*K29)+0.7*U29-AD29*AE29 -> 8076.0413 | X29: =W29*(1-0.1*K29)+0.7*U29-AD29*AE29 -> 9819.125 | Y29: =X29*(1-0.1*K29)+0.7*U29-AD29*AE29 -> 11554.705 | Z29: =Y29*(1-0.1*K29)+0.7*U29-AD29*AE29 -> 13282.813 | AA29: =Z29*(1-0.1*K29)+0.7*U29-AD29*AE29 -> 15003.482 | AB29: =AA29*(1-0.1*K29)+0.7*U29-AD29*AE29 -> 16716.744 | AC29: =AB29*(1-0.1*K29)+0.7*U29-AD29*AE29 -> 18422.631 | AD29: =VLOOKUP(B29,Migration!A$2:B$193,2,FALSE) -> 3 | AE29: =1/20 -> 0.05 | AF29: =IF(AC29<V29,"Decreased","Increased") -> Increased | AG29: =AD29/F29 -> 0.00065789474
A30: Malawi | B30: MWI | C30: Low-Income Economies | D30: 3545 | E30: 7957 | F30: 9592 | G30: 0.032318599 | H30: 0.49374479 | I30: 0.28377815 | J30: 0.16816097 | K30: 0.021997498 | L30: 0 | M30: =$F$4*G30 -> 2156.2114 | N30: =$F$4*H30 -> 32941.346 | O30: =$F$4*I30 -> 18932.927 | P30: =$F$4*J30 -> 11219.255 | Q30: =$F$4*K30 -> 1467.6149 | R30: =$F$4*L30 -> 0 | S30: =VLOOKUP(B30,'Edu updated'!B$2:J$48,9,FALSE) -> 386 | T30: =S30/F30 -> 0.040241868 | U30: =T30*F30 -> 386 | V30: =F30*(1-L30)+0.7*U30-AD30*AE30 -> 9852.2 | W30: =V30*(1-0.1*K30)+0.7*U30-AD30*AE30 -> 10090.728 | X30: =W30*(1-0.1*K30)+0.7*U30-AD30*AE30 -> 10328.731 | Y30: =X30*(1-0.1*K30)+0.7*U30-AD30*AE30 -> 10566.21 | Z30: =Y30*(1-0.1*K30)+0.7*U30-AD30*AE30 -> 10803.167 | AA30: =Z30*(1-0.1*K30)+0.7*U30-AD30*AE30 -> 11039.603 | AB30: =AA30*(1-0.1*K30)+0.7*U30-AD30*AE30 -> 11275.518 | AC30: =AB30*(1-0.1*K30)+0.7*U30-AD30*AE30 -> 11510.915 | AD30: =VLOOKUP(B30,Migration!A$2:B$193,2,FALSE) -> 200 | AE30: =1/20 -> 0.05 | AF30: =IF(AC30<V30,"Decreased","Increased") -> Increased | AG30: =AD30/F30 -> 0.020850709
A31: Mali | B31: MLI | C31: Low-Income Economies | D31: 4257 | E31: 5225 | F31: 6327 | G31: 0.16765299 | H31: 0.35339731 | I31: 0.29951984 | J31: 0.13365552 | K31: 0.043048784 | L31: 0.0027255474 | M31: =$F$4*G31 -> 11185.364 | N31: =$F$4*H31 -> 23577.734 | O31: =$F$4*I31 -> 19983.171 | P31: =$F$4*J31 -> 8917.1429 | Q31: =$F$4*K31 -> 2872.1009 | R31: =$F$4*L31 -> 181.84131 | S31: =VLOOKUP(B31,'Edu updated'!B$2:J$48,9,FALSE) -> 0 | T31: 0.162 | U31: =T31*F31 -> 1024.974 | V31: =F31*(1-L31)+0.7*U31-AD31*AE31 -> 7024.6373 | W31: =V31*(1-0.1*K31)+0.7*U31-AD31*AE31 -> 7709.2789 | X31: =W31*(1-0.1*K31)+0.7*U31-AD31*AE31 -> 8390.9731 | Y31: =X31*(1-0.1*K31)+0.7*U31-AD31*AE31 -> 9069.7328 | Z31: =Y31*(1-0.1*K31)+0.7*U31-AD31*AE31 -> 9745.5705 | AA31: =Z31*(1-0.1*K31)+0.7*U31-AD31*AE31 -> 10418.499 | AB31: =AA31*(1-0.1*K31)+0.7*U31-AD31*AE31 -> 11088.53 | AC31: =AB31*(1-0.1*K31)+0.7*U31-AD31*AE31 -> 11755.677 | AD31: =VLOOKUP(B31,Migration!A$2:B$193,2,FALSE) -> 52 | AE31: =1/20 -> 0.05 | AF31: =IF(AC31<V31,"Decreased","Increased") -> Increased | AG31: =AD31/F31 -> 0.0082187451
A32: Mauritania | B32: MRT | C32: Lower-Middle-Income Economies | D32: 3846 | E32: 4066 | F32: 6503 | G32: 0.031079804 | H32: 0.33653963 | I32: 0.34941396 | J32: 0.20169963 | K32: 0.073507085 | L32: 0.0077599026 | M32: =$F$4*G32 -> 2073.5623 | N32: =$F$4*H32 -> 22453.033 | O32: =$F$4*I32 -> 23311.975 | P32: =$F$4*J32 -> 13456.865 | Q32: =$F$4*K32 -> 4904.1982 | R32: =$F$4*L32 -> 517.72017 | S32: =VLOOKUP(B32,'Edu updated'!B$2:J$48,9,FALSE) -> 113 | T32: =S32/F32 -> 0.017376595 | U32: =T32*F32 -> 113 | V32: =F32*(1-L32)+0.7*U32-AD32*AE32 -> 6531.0374 | W32: =V32*(1-0.1*K32)+0.7*U32-AD32*AE32 -> 6561.5296 | X32: =W32*(1-0.1*K32)+0.7*U32-AD32*AE32 -> 6591.7977 | Y32: =X32*(1-0.1*K32)+0.7*U32-AD32*AE32 -> 6621.8433 | Z32: =Y32*(1-0.1*K32)+0.7*U32-AD32*AE32 -> 6651.6681 | AA32: =Z32*(1-0.1*K32)+0.7*U32-AD32*AE32 -> 6681.2736 | AB32: =AA32*(1-0.1*K32)+0.7*U32-AD32*AE32 -> 6710.6615 | AC32: =AB32*(1-0.1*K32)+0.7*U32-AD32*AE32 -> 6739.8334 | AD32: =VLOOKUP(B32,Migration!A$2:B$193,2,FALSE) -> 12 | AE32: =1/20 -> 0.05 | AF32: =IF(AC32<V32,"Decreased","Increased") -> Increased | AG32: =AD32/F32 -> 0.0018453022
A33: Mauritius | B33: MUS | C33: High/Upper-Middle-Income Economies | D33: 3963 | E33: 4986 | F33: 4598.8787 | G33: 0.018679111 | H33: 0.24613492 | I33: 0.31712616 | J33: 0.24329285 | K33: 0.13924057 | L33: 0.035526392 | M33: =$F$4*G33 -> 1246.2209 | N33: =$F$4*H33 -> 16421.47 | O33: =$F$4*I33 -> 21157.818 | P33: =$F$4*J33 -> 16231.855 | Q33: =$F$4*K33 -> 9289.7624 | R33: =$F$4*L33 -> 2370.2269 | S33: =VLOOKUP(B33,'Edu updated'!B$2:J$48,9,FALSE) -> 175 | T33: =S33/F33 -> 0.038052754 | U33: =T33*F33 -> 175 | V33: =F33*(1-L33)+0.7*U33-AD33*AE33 -> 4534.2472 | W33: =V33*(1-0.1*K33)+0.7*U33-AD33*AE33 -> 4569.8621 | X33: =W33*(1-0.1*K33)+0.7*U33-AD33*AE33 -> 4604.981 | Y33: =X33*(1-0.1*K33)+0.7*U33-AD33*AE33 -> 4639.611 | Z33: =Y33*(1-0.1*K33)+0.7*U33-AD33*AE33 -> 4673.7588 | AA33: =Z33*(1-0.1*K33)+0.7*U33-AD33*AE33 -> 4707.4311 | AB33: =AA33*(1-0.1*K33)+0.7*U33-AD33*AE33 -> 4740.6346 | AC33: =AB33*(1-0.1*K33)+0.7*U33-AD33*AE33 -> 4773.3757 | AD33: =VLOOKUP(B33,Migration!A$2:B$193,2,FALSE) -> 475 | AE33: =1/20 -> 0.05 | AF33: =IF(AC33<V33,"Decreased","Increased") -> Increased | AG33: =AD33/F33 -> 0.10328605
A34: Mozambique | B34: MOZ | C34: Low-Income Economies | D34: 6432 | E34: 8153 | F34: 17168 | G34: 0.16765299 | H34: 0.35339731 | I34: 0.29951984 | J34: 0.13365552 | K34: 0.043048784 | L34: 0.0027255474 | M34: =$F$4*G34 -> 11185.364 | N34: =$F$4*H34 -> 23577.734 | O34: =$F$4*I34 -> 19983.171 | P34: =$F$4*J34 -> 8917.1429 | Q34: =$F$4*K34 -> 2872.1009 | R34: =$F$4*L34 -> 181.84131 | S34: =VLOOKUP(B34,'Edu updated'!B$2:J$48,9,FALSE) -> 580 | T34: =S34/F34 -> 0.033783784 | U34: =T34*F34 -> 580 | V34: =F34*(1-L34)+0.7*U34-AD34*AE34 -> 17525.708 | W34: =V34*(1-0.1*K34)+0.7*U34-AD34*AE34 -> 17854.762 | X34: =W34*(1-0.1*K34)+0.7*U34-AD34*AE34 -> 18182.399 | Y34: =X34*(1-0.1*K34)+0.7*U34-AD34*AE34 -> 18508.626 | Z34: =Y34*(1-0.1*K34)+0.7*U34-AD34*AE34 -> 18833.449 | AA34: =Z34*(1-0.1*K34)+0.7*U34-AD34*AE34 -> 19156.873 | AB34: =AA34*(1-0.1*K34)+0.7*U34-AD34*AE34 -> 19478.905 | AC34: =AB34*(1-0.1*K34)+0.7*U34-AD34*AE34 -> 19799.551 | AD34: =VLOOKUP(B34,Migration!A$2:B$193,2,FALSE) -> 30 | AE34: =1/20 -> 0.05 | AF34: =IF(AC34<V34,"Decreased","Increased") -> Increased | AG34: =AD34/F34 -> 0.0017474371
A35: Namibia | B35: NAM | C35: High/Upper-Middle-Income Economies | D35: 4110 | E35: 12956 | F35: 15558.322 | G35: 0.018679111 | H35: 0.24613492 | I35: 0.31712616 | J35: 0.24329285 | K35: 0.13924057 | L35: 0.035526392 | M35: =$F$4*G35 -> 1246.2209 | N35: =$F$4*H35 -> 16421.47 | O35: =$F$4*I35 -> 21157.818 | P35: =$F$4*J35 -> 16231.855 | Q35: =$F$4*K35 -> 9289.7624 | R35: =$F$4*L35 -> 2370.2269 | S35: =VLOOKUP(B35,'Edu updated'!B$2:J$48,9,FALSE) -> 200 | T35: =S35/F35 -> 0.012854857 | U35: =T35*F35 -> 200 | V35: =F35*(1-L35)+0.7*U35-AD35*AE35 -> 15142.091 | W35: =V35*(1-0.1*K35)+0.7*U35-AD35*AE35 -> 15067.751 | X35: =W35*(1-0.1*K35)+0.7*U35-AD35*AE35 -> 14994.447 | Y35: =X35*(1-0.1*K35)+0.7*U35-AD35*AE35 -> 14922.164 | Z35: =Y35*(1-0.1*K35)+0.7*U35-AD35*AE35 -> 14850.887 | AA35: =Z35*(1-0.1*K35)+0.7*U35-AD35*AE35 -> 14780.602 | AB35: =AA35*(1-0.1*K35)+0.7*U35-AD35*AE35 -> 14711.296 | AC35: =AB35*(1-0.1*K35)+0.7*U35-AD35*AE35 -> 14642.955 | AD35: =VLOOKUP(B35,Migration!A$2:B$193,2,FALSE) -> 70 | AE35: =1/20 -> 0.05 | AF35: =IF(AC35<V35,"Decreased","Increased") -> Decreased | AG35: =AD35/F35 -> 0.0044991999
A36: Niger | B36: NER | C36: Low-Income Economies | D36: 3533 | E36: 4107 | F36: 4565 | G36: 0.16765299 | H36: 0.35339731 | I36: 0.29951984 | J36: 0.13365552 | K36: 0.043048784 | L36: 0.0027255474 | M36: =$F$4*G36 -> 11185.364 | N36: =$F$4*H36 -> 23577.734 | O36: =$F$4*I36 -> 19983.171 | P36: =$F$4*J36 -> 8917.1429 | Q36: =$F$4*K36 -> 2872.1009 | R36: =$F$4*L36 -> 181.84131 | S36: =VLOOKUP(B36,'Edu updated'!B$2:J$48,9,FALSE) -> 305 | T36: =S36/F36 -> 0.066812705 | U36: =T36*F36 -> 305 | V36: =F36*(1-L36)+0.7*U36-AD36*AE36 -> 4762.4579 | W36: =V36*(1-0.1*K36)+0.7*U36-AD36*AE36 -> 4951.8561 | X36: =W36*(1-0.1*K36)+0.7*U36-AD36*AE36 -> 5140.4389 | Y36: =X36*(1-0.1*K36)+0.7*U36-AD36*AE36 -> 5328.21 | Z36: =Y36*(1-0.1*K36)+0.7*U36-AD36*AE36 -> 5515.1727 | AA36: =Z36*(1-0.1*K36)+0.7*U36-AD36*AE36 -> 5701.3305 | AB36: =AA36*(1-0.1*K36)+0.7*U36-AD36*AE36 -> 5886.687 | AC36: =AB36*(1-0.1*K36)+0.7*U36-AD36*AE36 -> 6071.2455 | AD36: =VLOOKUP(B36,Migration!A$2:B$193,2,FALSE) -> 72 | AE36: =1/20 -> 0.05 | AF36: =IF(AC36<V36,"Decreased","Increased") -> Increased | AG36: =AD36/F36 -> 0.01577218
A37: Nigeria | B37: NGA | C37: Lower-Middle-Income Economies | D37: 74920 | E37: 180709 | F37: 220681 | G37: 0.030857698 | H37: 0.36394374 | I37: 0.30764366 | J37: 0.18093086 | K37: 0.10857971 | L37: 0.0080443344 | M37: =$F$4*G37 -> 2058.7439 | N37: =$F$4*H37 -> 24281.363 | O37: =$F$4*I37 -> 20525.171 | P37: =$F$4*J37 -> 12071.228 | Q37: =$F$4*K37 -> 7244.151 | R37: =$F$4*L37 -> 536.69671 | S37: =VLOOKUP(B37,'Edu updated'!B$2:J$48,9,FALSE) -> 12835 | T37: =S37/F37 -> 0.058160875 | U37: =T37*F37 -> 12835 | V37: =F37*(1-L37)+0.7*U37-AD37*AE37 -> 225845.27 | W37: =V37*(1-0.1*K37)+0.7*U37-AD37*AE37 -> 230332.55 | X37: =W37*(1-0.1*K37)+0.7*U37-AD37*AE37 -> 234771.1 | Y37: =X37*(1-0.1*K37)+0.7*U37-AD37*AE37 -> 239161.46 | Z37: =Y37*(1-0.1*K37)+0.7*U37-AD37*AE37 -> 243504.16 | AA37: =Z37*(1-0.1*K37)+0.7*U37-AD37*AE37 -> 247799.7 | AB37: =AA37*(1-0.1*K37)+0.7*U37-AD37*AE37 -> 252048.59 | AC37: =AB37*(1-0.1*K37)+0.7*U37-AD37*AE37 -> 256251.36 | AD37: =VLOOKUP(B37,Migration!A$2:B$193,2,FALSE) -> 40900 | AE37: =1/20 -> 0.05 | AF37: =IF(AC37<V37,"Decreased","Increased") -> Increased | AG37: =AD37/F37 -> 0.18533539
A38: Rwanda | B38: RWA | C38: Low-Income Economies | D38: 9625 | E38: 13345 | F38: 13501.24 | G38: 0.16765299 | H38: 0.35339731 | I38: 0.29951984 | J38: 0.13365552 | K38: 0.043048784 | L38: 0.0027255474 | M38: =$F$4*G38 -> 11185.364 | N38: =$F$4*H38 -> 23577.734 | O38: =$F$4*I38 -> 19983.171 | P38: =$F$4*J38 -> 8917.1429 | Q38: =$F$4*K38 -> 2872.1009 | R38: =$F$4*L38 -> 181.84131 | S38: =VLOOKUP(B38,'Edu updated'!B$2:J$48,9,FALSE) -> 355 | T38: =S38/F38 -> 0.026293882 | U38: =T38*F38 -> 355 | V38: =F38*(1-L38)+0.7*U38-AD38*AE38 -> 13708.741 | W38: =V38*(1-0.1*K38)+0.7*U38-AD38*AE38 -> 13894.027 | X38: =W38*(1-0.1*K38)+0.7*U38-AD38*AE38 -> 14078.515 | Y38: =X38*(1-0.1*K38)+0.7*U38-AD38*AE38 -> 14262.209 | Z38: =Y38*(1-0.1*K38)+0.7*U38-AD38*AE38 -> 14445.112 | AA38: =Z38*(1-0.1*K38)+0.7*U38-AD38*AE38 -> 14627.227 | AB38: =AA38*(1-0.1*K38)+0.7*U38-AD38*AE38 -> 14808.559 | AC38: =AB38*(1-0.1*K38)+0.7*U38-AD38*AE38 -> 14989.11 | AD38: =VLOOKUP(B38,Migration!A$2:B$193,2,FALSE) -> 84 | AE38: =1/20 -> 0.05 | AF38: =IF(AC38<V38,"Decreased","Increased") -> Increased | AG38: =AD38/F38 -> 0.0062216509
A39: Sao Tome and Principe | B39: STP | C39: Lower-Middle-Income Economies | D39: 442 | E39: 406 | F39: 440 | G39: 0.031079804 | H39: 0.33653963 | I39: 0.34941396 | J39: 0.20169963 | K39: 0.073507085 | L39: 0.0077599026 | M39: =$F$4*G39 -> 2073.5623 | N39: =$F$4*H39 -> 22453.033 | O39: =$F$4*I39 -> 23311.975 | P39: =$F$4*J39 -> 13456.865 | Q39: =$F$4*K39 -> 4904.1982 | R39: =$F$4*L39 -> 517.72017 | S39: =VLOOKUP(B39,'Edu updated'!B$2:J$48,9,FALSE) -> 0 | T39: 0.0811 | U39: =T39*F39 -> 35.684 | V39: =F39*(1-L39)+0.7*U39-AD39*AE39 -> 461.51444 | W39: =V39*(1-0.1*K39)+0.7*U39-AD39*AE39 -> 483.05078 | X39: =W39*(1-0.1*K39)+0.7*U39-AD39*AE39 -> 504.42882 | Y39: =X39*(1-0.1*K39)+0.7*U39-AD39*AE39 -> 525.64971 | Z39: =Y39*(1-0.1*K39)+0.7*U39-AD39*AE39 -> 546.71461 | AA39: =Z39*(1-0.1*K39)+0.7*U39-AD39*AE39 -> 567.62467 | AB39: =AA39*(1-0.1*K39)+0.7*U39-AD39*AE39 -> 588.38103 | AC39: =AB39*(1-0.1*K39)+0.7*U39-AD39*AE39 -> 608.98481 | AD39: =VLOOKUP(B39,Migration!A$2:B$193,2,FALSE) -> 1 | AE39: =1/20 -> 0.05 | AF39: =IF(AC39<V39,"Decreased","Increased") -> Increased | AG39: =AD39/F39 -> 0.0022727273
A40: Senegal | B40: SEN | C40: Lower-Middle-Income Economies | D40: 1682 | E40: 4577 | F40: 4737 | G40: 0.0031665611 | H40: 0.23495883 | I40: 0.56322567 | J40: 0.14967279 | K40: 0.042854127 | L40: 0.0061220182 | M40: =$F$4*G40 -> 211.26458 | N40: =$F$4*H40 -> 15675.832 | O40: =$F$4*I40 -> 37576.926 | P40: =$F$4*J40 -> 9985.7724 | Q40: =$F$4*K40 -> 2859.114 | R40: =$F$4*L40 -> 408.44485 | S40: =VLOOKUP(B40,'Edu updated'!B$2:J$48,9,FALSE) -> 582 | T40: =S40/F40 -> 0.12286257 | U40: =T40*F40 -> 582 | V40: =F40*(1-L40)+0.7*U40-AD40*AE40 -> 5090.45 | W40: =V40*(1-0.1*K40)+0.7*U40-AD40*AE40 -> 5451.0853 | X40: =W40*(1-0.1*K40)+0.7*U40-AD40*AE40 -> 5810.1752 | Y40: =X40*(1-0.1*K40)+0.7*U40-AD40*AE40 -> 6167.7262 | Z40: =Y40*(1-0.1*K40)+0.7*U40-AD40*AE40 -> 6523.7449 | AA40: =Z40*(1-0.1*K40)+0.7*U40-AD40*AE40 -> 6878.238 | AB40: =AA40*(1-0.1*K40)+0.7*U40-AD40*AE40 -> 7231.2119 | AC40: =AB40*(1-0.1*K40)+0.7*U40-AD40*AE40 -> 7582.6732 | AD40: =VLOOKUP(B40,Migration!A$2:B$193,2,FALSE) -> 499 | AE40: =1/20 -> 0.05 | AF40: =IF(AC40<V40,"Decreased","Increased") -> Increased | AG40: =AD40/F40 -> 0.10534093
A41: Seychelles | B41: SYC | C41: High/Upper-Middle-Income Economies | D41: 419 | E41: 1272 | F41: 1277 | G41: 0.044350581 | H41: 0.27032735 | I41: 0.25237592 | J41: 0.17106653 | K41: 0.17740232 | L41: 0.084477297 | M41: =$F$4*G41 -> 2958.9534 | N41: =$F$4*H41 -> 18035.525 | O41: =$F$4*I41 -> 16837.854 | P41: =$F$4*J41 -> 11413.106 | Q41: =$F$4*K41 -> 11835.814 | R41: =$F$4*L41 -> 5636.1017 | S41: =VLOOKUP(B41,'Edu updated'!B$2:J$48,9,FALSE) -> 40 | T41: =S41/F41 -> 0.031323414 | U41: =T41*F41 -> 40 | V41: =F41*(1-L41)+0.7*U41-AD41*AE41 -> 1193.9225 | W41: =V41*(1-0.1*K41)+0.7*U41-AD41*AE41 -> 1197.542 | X41: =W41*(1-0.1*K41)+0.7*U41-AD41*AE41 -> 1201.0974 | Y41: =X41*(1-0.1*K41)+0.7*U41-AD41*AE41 -> 1204.5896 | Z41: =Y41*(1-0.1*K41)+0.7*U41-AD41*AE41 -> 1208.0199 | AA41: =Z41*(1-0.1*K41)+0.7*U41-AD41*AE41 -> 1211.3894 | AB41: =AA41*(1-0.1*K41)+0.7*U41-AD41*AE41 -> 1214.699 | AC41: =AB41*(1-0.1*K41)+0.7*U41-AD41*AE41 -> 1217.95 | AD41: =VLOOKUP(B41,Migration!A$2:B$193,2,FALSE) -> 64 | AE41: =1/20 -> 0.05 | AF41: =IF(AC41<V41,"Decreased","Increased") -> Increased | AG41: =AD41/F41 -> 0.050117463
...

Sheet Education
A1: Row Labels | B1: Nursing Associate Professionals | C1: Nursing Professionals | D1: Nurses
A2: Angola | D2: =B2+C2 -> 0
A3: Benin | B3: 140 | D3: =B3+C3 -> 140
A4: Botswana | D4: =B4+C4 -> 0
A5: Burkina Faso | D5: =B5+C5 -> 0
A6: Burundi | D6: =B6+C6 -> 0
A7: Cameroon | D7: =B7+C7 -> 0
A8: Cape-Verde | C8: 6 | D8: =B8+C8 -> 6
A9: CAR | D9: =B9+C9 -> 0
A10: Chad | B10: 208 | C10: 423 | D10: =B10+C10 -> 631
A11: Congo | C11: 5 | D11: =B11+C11 -> 5
A12: Cote d'Ivoire | D12: =B12+C12 -> 0
A13: DRC | D13: =B13+C13 -> 0
A14: Eritrea | C14: 43 | D14: =B14+C14 -> 43
A15: Eswatini | D15: =B15+C15 -> 0
A16: Ethiopia | B16: 4174 | D16: =B16+C16 -> 4174
A17: Gabon | D17: =B17+C17 -> 0
A18: Gambia | D18: =B18+C18 -> 0
A19: Ghana | D19: =B19+C19 -> 0
A20: Guinea | D20: =B20+C20 -> 0
A21: Guinea-Bissau | D21: =B21+C21 -> 0
A22: Kenya | B22: 1070 | D22: =B22+C22 -> 1070
A23: Lesotho | B23: 112 | D23: =B23+C23 -> 112
A24: Liberia | C24: 17 | D24: =B24+C24 -> 17
A25: Madagascar | D25: =B25+C25 -> 0
A26: Malawi | D26: =B26+C26 -> 0
A27: Mali | D27: =B27+C27 -> 0
A28: Mauritania | D28: =B28+C28 -> 0
A29: Mauritius | D29: =B29+C29 -> 0
A30: Mozambique | B30: 580 | D30: =B30+C30 -> 580
A31: Namibia | B31: 1414 | D31: =B31+C31 -> 1414
A32: Niger | B32: 282 | D32: =B32+C32 -> 282
A33: Nigeria | D33: =B33+C33 -> 0
A34: Rwanda | B34: 355 | D34: =B34+C34 -> 355
A35: Senegal | D35: =B35+C35 -> 0
A36: Sierra Leone | B36: =275+961+1 -> 1237 | D36: =B36+C36 -> 1237
A37: South Africa | B37: 4445 | D37: =B37+C37 -> 4445
A38: South Sudan | D38: =B38+C38 -> 0
A39: Tanzania | D39: =B39+C39 -> 0
A40: Togo | B40: 160 | D40: =B40+C40 -> 160
...

Sheet Edu updated
A1: Country | B1: iso codes | C1: Generalist Medical Practitioners | D1: Specialist Medical Practitioners | E1: Dentists | F1: Other Dental practitioners | G1: Pharmacists | H1: Other Pharmacy practitioners | I1: Midwifery personnel | J1: Nursing Personnel | K1: Medical and Pathology Laboratory scientists | L1: Paramedical Practitioners | M1: Other Health Workers | N1: Total | O1: Data Sorce(s)
A2: Algeria | B2: DZA | C2: 0 | N2: 0 | O2: NHWA dataset, 2023
A3: Angola | B3: AGO | C3: 611 | E3: 145 | G3: 529 | J3: 2950 | N3: 4235 | O3: Dent-2018;
A4: Benin | B4: BEN | C4: 780 | D4: 385 | G4: 143 | I4: 247 | J4: 257 | K4: 1113 | M4: 1194 | N4: 4119 | O4: Med-2021; Pharm-2021;Mid-2021; Nur-2021;Biom-2021; others-2021
A5: Botswana | B5: BWA | C5: 60 | D5: 48 | E5: 7 | F5: 10 | G5: 95 | H5: 60 | I5: 40 | J5: 490 | K5: 189 | L5: 30 | M5: 597 | N5: 1626 | O5: 2022 for all
A6: Burkina Faso | B6: BFA | C6: 1492 | D6: 385 | E6: 62 | G6: 594 | I6: 1170 | J6: 1170 | N6: 4873 | O6: NHWA dataset, 2023
A7: Burundi | B7: BDI | C7: 325 | D7: 240 | G7: 39 | I7: 196 | J7: 1467 | K7: 322 | M7: 194 | N7: 2783 | O7: 2018 dataset
A8: Cameroon | B8: CMR | C8: 800 | J8: 2660 | K8: 800 | N8: 4260 | O8: NHWA dataset, 2023
A9: Cabo Verde | B9: CPV | F9: 7 | M9: 83 | N9: 90 | O9: NHWA dataset, 2023
A10: Central African Republic | B10: CAF | C10: 18 | N10: 18 | O10: NHWA dataset, 2023
A11: Chad | B11: TCD | C11: 330 | D11: 30 | G11: 80 | H11: 180 | I11: 2084 | J11: 2920 | K11: 220 | N11: 5844 | O11: NHWA dataset, 2023
