Workbook

Sheet Sheet3
A3: Row Labels | B3: Average of Pharmacists Stock By Age Group < 25 yrs2 | C3: Average of Pharmacists Stock By Age Group 25-34 yrs2 | D3: Average of Pharmacists Stock By Age Group 35-44 yrs2 | E3: Average of Pharmacists Stock By Age Group 45-54 yrs2 | F3: Average of Pharmacists Stock By Age Group 55-64 yrs2 | G3: Average of Pharmacists Stock By Age Group ≥ 65 yrs2
A4: AFRO | B4: 0.093811881 | C4: 0.39455446 | D4: 0.31943069 | E4: 0.15074257 | F4: 0.038118812 | G4: 0.0033415842
A5: High/Upper-Middle-Income Economies | B5: 0.0035971223 | C5: 0.15030216 | D5: 0.28869065 | E5: 0.28509353 | F5: 0.21433094 | G5: 0.057985612
A6: Lower-Middle-Income Economies | B6: 0.046700487 | C6: 0.38491371 | D6: 0.33633804 | E6: 0.14508994 | F6: 0.081948012 | G6: 0.0050098082
A7: Low-Income Economies | B7: 0.1012751 | C7: 0.48002118 | D7: 0.28827007 | E7: 0.091590837 | F7: 0.033097084 | G7: 0.0057457277
A8: Grand Total | B8: 0.059688138 | C8: 0.3858001 | D8: 0.31675237 | E8: 0.14609907 | F8: 0.080652568 | G8: 0.011007752

Sheet proportions
A1: Row Labels | B1: Pharmacists Stock By Age Group < 25 yrs | C1: Pharmacists Stock By Age Group 25-34 yrs | D1: Pharmacists Stock By Age Group 35-44 yrs | E1: Pharmacists Stock By Age Group 45-54 yrs | F1: Pharmacists Stock By Age Group 55-64 yrs | G1: Pharmacists Stock By Age Group ≥ 65 yrs | H1: Total | I1: Pharmacists Stock By Age Group < 25 yrs | J1: Pharmacists Stock By Age Group 25-34 yrs | K1: Pharmacists Stock By Age Group 35-44 yrs | L1: Pharmacists Stock By Age Group 45-54 yrs | M1: Pharmacists Stock By Age Group 55-64 yrs | N1: Pharmacists Stock By Age Group ≥ 65 yrs | O1: income
A2: AFRO | B2: 758 | C2: 3188 | D2: 2581 | E2: 1218 | F2: 308 | G2: 27 | H2: =SUM(B2:G2) -> 8080 | I2: =B2/$H2 -> 0.093811881 | J2: =C2/$H2 -> 0.39455446 | K2: =D2/$H2 -> 0.31943069 | L2: =E2/$H2 -> 0.15074257 | M2: =F2/$H2 -> 0.038118812 | N2: =G2/$H2 -> 0.0033415842 | O2: AFRO
A3: BFA | B3: 0 | C3: 127 | D3: 329 | E3: 108 | F3: 11 | G3: 0 | H3: =SUM(B3:G3) -> 575 | I3: =B3/$H3 -> 0 | J3: =C3/$H3 -> 0.22086957 | K3: =D3/$H3 -> 0.57217391 | L3: =E3/$H3 -> 0.18782609 | M3: =F3/$H3 -> 0.019130435 | N3: =G3/$H3 -> 0 | O3: =VLOOKUP(A3,Sheet2!A$2:D$49,4,FALSE) -> Low-Income Economies
A4: BWA | C4: 7 | D4: 38 | E4: 38 | F4: 32 | G4: 10 | H4: =SUM(B4:G4) -> 125 | I4: =B4/$H4 -> 0 | J4: =C4/$H4 -> 0.056 | K4: =D4/$H4 -> 0.304 | L4: =E4/$H4 -> 0.304 | M4: =F4/$H4 -> 0.256 | N4: =G4/$H4 -> 0.08 | O4: =VLOOKUP(A4,Sheet2!A$2:D$49,4,FALSE) -> High/Upper-Middle-Income Economies
A5: CIV | B5: 0 | C5: 256 | D5: 539 | E5: 354 | F5: 13 | G5: 0 | H5: =SUM(B5:G5) -> 1162 | I5: =B5/$H5 -> 0 | J5: =C5/$H5 -> 0.22030981 | K5: =D5/$H5 -> 0.46385542 | L5: =E5/$H5 -> 0.30464716 | M5: =F5/$H5 -> 0.011187608 | N5: =G5/$H5 -> 0 | O5: =VLOOKUP(A5,Sheet2!A$2:D$49,4,FALSE) -> Lower-Middle-Income Economies
A6: CMR | B6: 3 | C6: 389 | D6: 201 | E6: 8 | F6: 1 | G6: 0 | H6: =SUM(B6:G6) -> 602 | I6: =B6/$H6 -> 0.0049833887 | J6: =C6/$H6 -> 0.6461794 | K6: =D6/$H6 -> 0.33388704 | L6: =E6/$H6 -> 0.013289037 | M6: =F6/$H6 -> 0.0016611296 | N6: =G6/$H6 -> 0 | O6: =VLOOKUP(A6,Sheet2!A$2:D$49,4,FALSE) -> Lower-Middle-Income Economies
A7: COG | B7: 1 | C7: 6 | D7: 9 | E7: 4 | F7: 8 | H7: =SUM(B7:G7) -> 28 | I7: =B7/$H7 -> 0.035714286 | J7: =C7/$H7 -> 0.21428571 | K7: =D7/$H7 -> 0.32142857 | L7: =E7/$H7 -> 0.14285714 | M7: =F7/$H7 -> 0.28571429 | N7: =G7/$H7 -> 0 | O7: =VLOOKUP(A7,Sheet2!A$2:D$49,4,FALSE) -> Lower-Middle-Income Economies
A8: ERI | B8: 8 | C8: 161 | D8: 20 | E8: 9 | F8: 1 | H8: =SUM(B8:G8) -> 199 | I8: =B8/$H8 -> 0.040201005 | J8: =C8/$H8 -> 0.80904523 | K8: =D8/$H8 -> 0.10050251 | L8: =E8/$H8 -> 0.045226131 | M8: =F8/$H8 -> 0.0050251256 | N8: =G8/$H8 -> 0 | O8: =VLOOKUP(A8,Sheet2!A$2:D$49,4,FALSE) -> Low-Income Economies
A9: GAB | B9: 1 | C9: 34 | D9: 38 | E9: 37 | F9: 24 | G9: 5 | H9: =SUM(B9:G9) -> 139 | I9: =B9/$H9 -> 0.0071942446 | J9: =C9/$H9 -> 0.24460432 | K9: =D9/$H9 -> 0.27338129 | L9: =E9/$H9 -> 0.26618705 | M9: =F9/$H9 -> 0.17266187 | N9: =G9/$H9 -> 0.035971223 | O9: =VLOOKUP(A9,Sheet2!A$2:D$49,4,FALSE) -> High/Upper-Middle-Income Economies
A10: GHA | B10: 0 | C10: 431 | D10: 394 | E10: 213 | F10: 99 | G10: 0 | H10: =SUM(B10:G10) -> 1137 | I10: =B10/$H10 -> 0 | J10: =C10/$H10 -> 0.37906772 | K10: =D10/$H10 -> 0.34652595 | L10: =E10/$H10 -> 0.18733509 | M10: =F10/$H10 -> 0.08707124 | N10: =G10/$H10 -> 0 | O10: =VLOOKUP(A10,Sheet2!A$2:D$49,4,FALSE) -> Lower-Middle-Income Economies
A11: KEN | B11: 21 | C11: 272 | D11: 473 | E11: 129 | F11: 11 | G11: 0 | H11: =SUM(B11:G11) -> 906 | I11: =B11/$H11 -> 0.023178808 | J11: =C11/$H11 -> 0.30022075 | K11: =D11/$H11 -> 0.52207506 | L11: =E11/$H11 -> 0.14238411 | M11: =F11/$H11 -> 0.01214128 | N11: =G11/$H11 -> 0 | O11: =VLOOKUP(A11,Sheet2!A$2:D$49,4,FALSE) -> Lower-Middle-Income Economies
A12: MOZ | B12: 5 | C12: 213 | D12: 181 | E12: 49 | F12: 11 | G12: 2 | H12: =SUM(B12:G12) -> 461 | I12: =B12/$H12 -> 0.010845987 | J12: =C12/$H12 -> 0.46203905 | K12: =D12/$H12 -> 0.39262473 | L12: =E12/$H12 -> 0.10629067 | M12: =F12/$H12 -> 0.023861171 | N12: =G12/$H12 -> 0.0043383948 | O12: =VLOOKUP(A12,Sheet2!A$2:D$49,4,FALSE) -> Low-Income Economies
A13: MWI | B13: 50 | C13: 25 | D13: 19 | E13: 11 | F13: 6 | H13: =SUM(B13:G13) -> 111 | I13: =B13/$H13 -> 0.45045045 | J13: =C13/$H13 -> 0.22522523 | K13: =D13/$H13 -> 0.17117117 | L13: =E13/$H13 -> 0.099099099 | M13: =F13/$H13 -> 0.054054054 | N13: =G13/$H13 -> 0 | O13: =VLOOKUP(A13,Sheet2!A$2:D$49,4,FALSE) -> Low-Income Economies
A14: SEN | B14: 1 | C14: 78 | D14: 151 | E14: 69 | F14: 39 | H14: =SUM(B14:G14) -> 338 | I14: =B14/$H14 -> 0.0029585799 | J14: =C14/$H14 -> 0.23076923 | K14: =D14/$H14 -> 0.44674556 | L14: =E14/$H14 -> 0.20414201 | M14: =F14/$H14 -> 0.11538462 | N14: =G14/$H14 -> 0 | O14: =VLOOKUP(A14,Sheet2!A$2:D$49,4,FALSE) -> Lower-Middle-Income Economies
A15: TCD | B15: 1 | C15: 140 | D15: 42 | E15: 4 | F15: 13 | G15: 5 | H15: =SUM(B15:G15) -> 205 | I15: =B15/$H15 -> 0.0048780488 | J15: =C15/$H15 -> 0.68292683 | K15: =D15/$H15 -> 0.20487805 | L15: =E15/$H15 -> 0.019512195 | M15: =F15/$H15 -> 0.063414634 | N15: =G15/$H15 -> 0.024390244 | O15: =VLOOKUP(A15,Sheet2!A$2:D$49,4,FALSE) -> Low-Income Economies
A16: ZMB | B16: 7 | C16: 328 | D16: 214 | E16: 58 | F16: 27 | G16: 5 | H16: =SUM(B16:G16) -> 639 | I16: =B16/$H16 -> 0.010954617 | J16: =C16/$H16 -> 0.51330203 | K16: =D16/$H16 -> 0.33489828 | L16: =E16/$H16 -> 0.090766823 | M16: =F16/$H16 -> 0.042253521 | N16: =G16/$H16 -> 0.0078247261 | O16: =VLOOKUP(A16,Sheet2!A$2:D$49,4,FALSE) -> Lower-Middle-Income Economies
A17: ZWE | B17: 666 | C17: 951 | D17: 114 | E17: 152 | F17: 0 | G17: 0 | H17: =SUM(B17:G17) -> 1883 | I17: =B17/$H17 -> 0.35369092 | J17: =C17/$H17 -> 0.50504514 | K17: =D17/$H17 -> 0.060541689 | L17: =E17/$H17 -> 0.080722252 | M17: =F17/$H17 -> 0 | N17: =G17/$H17 -> 0 | O17: =VLOOKUP(A17,Sheet2!A$2:D$49,4,FALSE) -> Lower-Middle-Income Economies
A18: BEN | B18: 6 | C18: 233 | D18: 119 | E18: 23 | F18: 17 | G18: 2 | H18: =SUM(B18:G18) -> 400 | I18: =B18/$H18 -> 0.015 | J18: =C18/$H18 -> 0.5825 | K18: =D18/$H18 -> 0.2975 | L18: =E18/$H18 -> 0.0575 | M18: =F18/$H18 -> 0.0425 | N18: =G18/$H18 -> 0.005 | O18: =VLOOKUP(A18,Sheet2!A$2:D$49,4,FALSE) -> Lower-Middle-Income Economies
A19: DZA | B19: 386 | C19: 4842 | D19: 4437 | E19: 4274 | F19: 4167 | G19: 701 | H19: =SUM(B19:G19) -> 18807 | I19: =B19/$H19 -> 0.020524273 | J19: =C19/$H19 -> 0.25745733 | K19: =D19/$H19 -> 0.23592279 | L19: =E19/$H19 -> 0.22725581 | M19: =F19/$H19 -> 0.22156644 | N19: =G19/$H19 -> 0.037273356 | O19: =VLOOKUP(A19,Sheet2!A$2:D$49,4,FALSE) -> Lower-Middle-Income Economies
A43: Income level | B43: Pharmacists Stock By Age Group < 25 yrs | C43: Pharmacists Stock By Age Group 25-34 yrs | D43: Pharmacists Stock By Age Group 35-44 yrs | E43: Pharmacists Stock By Age Group 45-54 yrs | F43: Pharmacists Stock By Age Group 55-64 yrs | G43: Pharmacists Stock By Age Group ≥ 65 yrs
A44: High/Upper-Middle-Income Economies | B44: 0.0035971223 | C44: 0.15030216 | D44: 0.28869065 | E44: 0.28509353 | F44: 0.21433094 | G44: 0.057985612
A45: Lower-Middle-Income Economies | B45: 0.046700487 | C45: 0.38491371 | D45: 0.33633804 | E45: 0.14508994 | F45: 0.081948012 | G45: 0.0050098082
A46: Low-Income Economies | B46: 0.1012751 | C46: 0.48002118 | D46: 0.28827007 | E46: 0.091590837 | F46: 0.033097084 | G46: 0.0057457277
A47: AFRO | B47: 0.093811881 | C47: 0.39455446 | D47: 0.31943069 | E47: 0.15074257 | F47: 0.038118812 | G47: 0.0033415842

Sheet Sheet2
A1: country code | B1: Country | C1: country code | D1: Income
A2: DZA | B2: Algeria | C2: DZA | D2: Lower-Middle-Income Economies
A3: AGO | B3: Angola | C3: AGO | D3: Lower-Middle-Income Economies
A4: BEN | B4: Benin | C4: BEN | D4: Lower-Middle-Income Economies
A5: BWA | B5: Botswana | C5: BWA | D5: High/Upper-Middle-Income Economies
A6: BFA | B6: Burkina Faso | C6: BFA | D6: Low-Income Economies
A7: BDI | B7: Burundi | C7: BDI | D7: Low-Income Economies
A8: CMR | B8: Cameroon | C8: CMR | D8: Lower-Middle-Income Economies
A9: CPV | B9: Cape-Verde | C9: CPV | D9: Lower-Middle-Income Economies
A10: CAF | B10: Central African Republic | C10: CAF | D10: Low-Income Economies
A11: TCD | B11: Chad | C11: TCD | D11: Low-Income Economies
A12: COM | B12: Comoros | C12: COM | D12: Lower-Middle-Income Economies
... A48: ZWE | B48: Zimbabwe | C48: ZWE | D48: Lower-Middle-Income Economies
A49: AFRO | B49: AFRO | C49: AFRO

Sheet Sheet7
A3: Row Labels | B3: Average of Graduates to stock ratio
A4: AFRO
A5: High/Upper-Middle-Income Economies | B5: 0.28050332
A6: Lower-Middle-Income Economies | B6: 0.2192751
A7: Low-Income Economies | B7: 0.28182149
A8: Grand Total | B8: 0.260753

Sheet projections
A2: Country | B2: Country code | C2: income level | D2: 2013 | E2: 2018 | F2: Adjusted 2022 | G2: Pharmacists Stock By Age Group < 25 yrs (prop) | H2: Pharmacists Stock By Age Group 25-34 yrs (prop) | I2: Pharmacists Stock By Age Group 35-44 yrs (prop) | J2: Pharmacists Stock By Age Group 45-54 yrs (prop) | K2: Pharmacists Stock By Age Group 55-64 yrs (prop) | L2: Pharmacists Stock By Age Group ≥ 65 yrs (prop) | M2: Pharmacists Stock By Age Group < 25 yrs | N2: Pharmacists Stock By Age Group 25-34 yrs | O2: Pharmacists Stock By Age Group 35-44 yrs | P2: Pharmacists Stock By Age Group 45-54 yrs | Q2: Pharmacists Stock By Age Group 55-64 yrs | R2: Pharmacists Stock By Age Group ≥ 65 yrs | S2: cond | T2: Annual graduations | U2: Graduates to stock ratio | V2: Estimated graduates | W2: Projected 2023 | X2: Projected 2024 | Y2: Projected 2025 | Z2: Projected 2026 | AA2: Projected 2027 | AB2: Projected 2028 | AC2: Projected 2029 | AD2: Projected 2030
A3: Algeria | B3: DZA | C3: Lower-Middle-Income Economies | D3: 0 | E3: 18807 | F3: 13642 | G3: 0.020524273 | H3: 0.25745733 | I3: 0.23592279 | J3: 0.22725581 | K3: 0.22156644 | L3: 0.037273356 | M3: =$E3*G3 -> 386 | N3: =$E3*H3 -> 4842 | O3: =$E3*I3 -> 4437 | P3: =$E3*J3 -> 4274 | Q3: =$E3*K3 -> 4167 | R3: =$E3*L3 -> 701 | S3: =F3<E3*0.7 -> FALSE | T3: =VLOOKUP(B3,Education!B$2:G$48,6,FALSE) -> 0 | U3: 0.2192751 | V3: =U3*E3 -> 4123.9067 | W3: =F3*(1-L3)+0.7*V3 -> 16020.252 | X3: =W3*(1-0.1*K3)+0.7*V3 -> 18552.031 | Y3: =X3*(1-0.1*K3)+0.7*V3 -> 21027.715 | Z3: =Y3*(1-0.1*K3)+0.7*V3 -> 23448.546 | AA3: =Z3*(1-0.1*K3)+0.7*V3 -> 25815.74 | AB3: =AA3*(1-0.1*K3)+0.7*V3 -> 28130.485 | AC3: =AB3*(1-0.1*K3)+0.7*V3 -> 30393.942 | AD3: =AC3*(1-0.1*K3)+0.7*V3 -> 32607.249
A4: Angola | B4: AGO | C4: Lower-Middle-Income Economies | D4: 0 | E4: 2302 | F4: 1434.0323 | G4: 0.046700487 | H4: 0.38491371 | I4: 0.33633804 | J4: 0.14508994 | K4: 0.081948012 | L4: 0.0050098082 | M4: =$E4*G4 -> 107.50452 | N4: =$E4*H4 -> 886.07137 | O4: =$E4*I4 -> 774.25016 | P4: =$E4*J4 -> 333.99705 | Q4: =$E4*K4 -> 188.64432 | R4: =$E4*L4 -> 11.532578 | S4: =F4<E4*0.7 -> TRUE | T4: =VLOOKUP(B4,Education!B$2:G$48,6,FALSE) -> 529 | U4: =T4/E4 -> 0.22980017 | V4: =U4*F4 -> 329.54088 | W4: =F4*(1-L4)+0.7*V4 -> 1657.5267 | X4: =W4*(1-0.1*K4)+0.7*V4 -> 1874.6222 | Y4: =X4*(1-0.1*K4)+0.7*V4 -> 2089.9387 | Z4: =Y4*(1-0.1*K4)+0.7*V4 -> 2303.4907 | AA4: =Z4*(1-0.1*K4)+0.7*V4 -> 2515.2927 | AB4: =AA4*(1-0.1*K4)+0.7*V4 -> 2725.359 | AC4: =AB4*(1-0.1*K4)+0.7*V4 -> 2933.7038 | AD4: =AC4*(1-0.1*K4)+0.7*V4 -> 3140.3413
A5: Benin | B5: BEN | C5: Lower-Middle-Income Economies | D5: 1330 | E5: 306 | F5: 382 | G5: 0.015 | H5: 0.5825 | I5: 0.2975 | J5: 0.0575 | K5: 0.0425 | L5: 0.005 | M5: =$F5*G5 -> 5.73 | N5: =$F5*H5 -> 222.515 | O5: =$F5*I5 -> 113.645 | P5: =$F5*J5 -> 21.965 | Q5: =$F5*K5 -> 16.235 | R5: =$F5*L5 -> 1.91 | S5: =F5<E5*0.7 -> FALSE | T5: =VLOOKUP(B5,Education!B$2:G$48,6,FALSE) -> 143 | U5: =T5/F5 -> 0.37434555 | V5: =U5*F5 -> 143 | W5: =F5*(1-L5)+0.7*V5 -> 480.19 | X5: =W5*(1-0.1*K5)+0.7*V5 -> 578.24919 | Y5: =X5*(1-0.1*K5)+0.7*V5 -> 675.89163 | Z5: =Y5*(1-0.1*K5)+0.7*V5 -> 773.11909 | AA5: =Z5*(1-0.1*K5)+0.7*V5 -> 869.93334 | AB5: =AA5*(1-0.1*K5)+0.7*V5 -> 966.33612 | AC5: =AB5*(1-0.1*K5)+0.7*V5 -> 1062.3292 | AD5: =AC5*(1-0.1*K5)+0.7*V5 -> 1157.9143
A6: Botswana | B6: BWA | C6: High/Upper-Middle-Income Economies | D6: 0 | E6: 156 | F6: 143.66233 | G6: 0 | H6: 0.056 | I6: 0.304 | J6: 0.304 | K6: 0.256 | L6: 0.08 | M6: =$F6*G6 -> 0 | N6: =$F6*H6 -> 8.0450905 | O6: =$F6*I6 -> 43.673348 | P6: =$F6*J6 -> 43.673348 | Q6: =$F6*K6 -> 36.777557 | R6: =$F6*L6 -> 11.492986 | S6: =F6<E6*0.7 -> FALSE | T6: =VLOOKUP(B6,Education!B$2:G$48,6,FALSE) -> 95 | U6: =T6/F6 -> 0.66127286 | V6: =U6*F6 -> 95 | W6: =F6*(1-L6)+0.7*V6 -> 198.66934 | X6: =W6*(1-0.1*K6)+0.7*V6 -> 260.08341 | Y6: =X6*(1-0.1*K6)+0.7*V6 -> 319.92527 | Z6: =Y6*(1-0.1*K6)+0.7*V6 -> 378.23519 | AA6: =Z6*(1-0.1*K6)+0.7*V6 -> 435.05237 | AB6: =AA6*(1-0.1*K6)+0.7*V6 -> 490.41503 | AC6: =AB6*(1-0.1*K6)+0.7*V6 -> 544.3604 | AD6: =AC6*(1-0.1*K6)+0.7*V6 -> 596.92477
A7: Burkina Faso | B7: BFA | C7: Low-Income Economies | D7: 207 | E7: 636 | F7: 590.71659 | G7: 0 | H7: 0.22086957 | I7: 0.57217391 | J7: 0.18782609 | K7: 0.019130435 | L7: 0 | M7: =$F7*G7 -> 0 | N7: =$F7*H7 -> 130.47132 | O7: =$F7*I7 -> 337.99262 | P7: =$F7*J7 -> 110.95199 | Q7: =$F7*K7 -> 11.300665 | R7: =$F7*L7 -> 0 | S7: =F7<E7*0.7 -> FALSE | T7: =VLOOKUP(B7,Education!B$2:G$48,6,FALSE) -> 594 | U7: =T7/F7 -> 1.0055583 | V7: =U7*F7 -> 594 | W7: =F7*(1-L7)+0.7*V7 -> 1006.5166 | X7: =W7*(1-0.1*K7)+0.7*V7 -> 1420.3911 | Y7: =X7*(1-0.1*K7)+0.7*V7 -> 1833.4738 | Z7: =Y7*(1-0.1*K7)+0.7*V7 -> 2245.7663 | AA7: =Z7*(1-0.1*K7)+0.7*V7 -> 2657.2701 | AB7: =AA7*(1-0.1*K7)+0.7*V7 -> 3067.9866 | AC7: =AB7*(1-0.1*K7)+0.7*V7 -> 3477.9174 | AD7: =AC7*(1-0.1*K7)+0.7*V7 -> 3887.064
A8: Burundi | B8: BDI | C8: Low-Income Economies | D8: 4 | E8: 119 | F8: 123.73306 | G8: 0.1012751 | H8: 0.48002118 | I8: 0.28827007 | J8: 0.091590837 | K8: 0.033097084 | L8: 0.0057457277 | M8: =$F8*G8 -> 12.531078 | N8: =$F8*H8 -> 59.394488 | O8: =$F8*I8 -> 35.668538 | P8: =$F8*J8 -> 11.332814 | Q8: =$F8*K8 -> 4.0952034 | R8: =$F8*L8 -> 0.71093646 | S8: =F8<E8*0.7 -> FALSE | T8: =VLOOKUP(B8,Education!B$2:G$48,6,FALSE) -> 39 | U8: =T8/F8 -> 0.31519467 | V8: =U8*F8 -> 39 | W8: =F8*(1-L8)+0.7*V8 -> 150.32212 | X8: =W8*(1-0.1*K8)+0.7*V8 -> 177.1246 | Y8: =X8*(1-0.1*K8)+0.7*V8 -> 203.83837 | Z8: =Y8*(1-0.1*K8)+0.7*V8 -> 230.46372 | AA8: =Z8*(1-0.1*K8)+0.7*V8 -> 257.00095 | AB8: =AA8*(1-0.1*K8)+0.7*V8 -> 283.45036 | AC8: =AB8*(1-0.1*K8)+0.7*V8 -> 309.81222 | AD8: =AC8*(1-0.1*K8)+0.7*V8 -> 336.08683
A9: Cameroon | B9: CMR | C9: Lower-Middle-Income Economies | D9: 162 | E9: 350 | F9: 602 | G9: 0.0049833887 | H9: 0.6461794 | I9: 0.33388704 | J9: 0.013289037 | K9: 0.0016611296 | L9: 0 | M9: =$F9*G9 -> 3 | N9: =$F9*H9 -> 389 | O9: =$F9*I9 -> 201 | P9: =$F9*J9 -> 8 | Q9: =$F9*K9 -> 1 | R9: =$F9*L9 -> 0 | S9: =F9<E9*0.7 -> FALSE | T9: =VLOOKUP(B9,Education!B$2:G$48,6,FALSE) -> 0 | U9: 0.2192751 | V9: =U9*F9 -> 132.00361 | W9: =F9*(1-L9)+0.7*V9 -> 694.40253 | X9: =W9*(1-0.1*K9)+0.7*V9 -> 786.6897 | Y9: =X9*(1-0.1*K9)+0.7*V9 -> 878.96155 | Z9: =Y9*(1-0.1*K9)+0.7*V9 -> 971.21807 | AA9: =Z9*(1-0.1*K9)+0.7*V9 -> 1063.4593 | AB9: =AA9*(1-0.1*K9)+0.7*V9 -> 1155.6851 | AC9: =AB9*(1-0.1*K9)+0.7*V9 -> 1247.8957 | AD9: =AC9*(1-0.1*K9)+0.7*V9 -> 1340.0909
A10: Cape-Verde | B10: CPV | C10: Lower-Middle-Income Economies | D10: 0 | E10: 172 | F10: 28.598813 | G10: 0.046700487 | H10: 0.38491371 | I10: 0.33633804 | J10: 0.14508994 | K10: 0.081948012 | L10: 0.0050098082 | M10: =$E10*G10 -> 8.0324838 | N10: =$E10*H10 -> 66.205159 | O10: =$E10*I10 -> 57.850142 | P10: =$E10*J10 -> 24.95547 | Q10: =$E10*K10 -> 14.095058 | R10: =$E10*L10 -> 0.86168701 | S10: =F10<E10*0.7 -> TRUE | T10: =VLOOKUP(B10,Education!B$2:G$48,6,FALSE) -> 0 | U10: 0.2192751 | V10: =U10*E10 -> 37.715317 | W10: =E10*(1-L10)+0.7*V10 -> 197.53903 | X10: =W10*(1-0.1*K10)+0.7*V10 -> 222.32096 | Y10: =X10*(1-0.1*K10)+0.7*V10 -> 246.89981 | Z10: =Y10*(1-0.1*K10)+0.7*V10 -> 271.27724 | AA10: =Z10*(1-0.1*K10)+0.7*V10 -> 295.45489 | AB10: =AA10*(1-0.1*K10)+0.7*V10 -> 319.43442 | AC10: =AB10*(1-0.1*K10)+0.7*V10 -> 343.21744 | AD10: =AC10*(1-0.1*K10)+0.7*V10 -> 366.80556
A11: Central African Republic | B11: CAF | C11: Low-Income Economies | D11: 20 | E11: 36 | F11: 2.5682382 | G11: 0.1012751 | H11: 0.48002118 | I11: 0.28827007 | J11: 0.091590837 | K11: 0.033097084 | L11: 0.0057457277 | M11: =$E11*G11 -> 3.6459035 | N11: =$E11*H11 -> 17.280762 | O11: =$E11*I11 -> 10.377723 | P11: =$E11*J11 -> 3.2972701 | Q11: =$E11*K11 -> 1.191495 | R11: =$E11*L11 -> 0.2068462 | S11: =F11<E11*0.7 -> TRUE | T11: =VLOOKUP(B11,Education!B$2:G$48,6,FALSE) -> 0 | U11: 0.28182149 | V11: =U11*E11 -> 10.145574 | W11: =E11*(1-L11)+0.7*V11 -> 42.895055 | X11: =W11*(1-0.1*K11)+0.7*V11 -> 49.854987 | Y11: =X11*(1-0.1*K11)+0.7*V11 -> 56.791883 | Z11: =Y11*(1-0.1*K11)+0.7*V11 -> 63.70582 | AA11: =Z11*(1-0.1*K11)+0.7*V11 -> 70.596873 | AB11: =AA11*(1-0.1*K11)+0.7*V11 -> 77.46512 | AC11: =AB11*(1-0.1*K11)+0.7*V11 -> 84.310634 | AD11: =AC11*(1-0.1*K11)+0.7*V11 -> 91.133492
A12: Chad | B12: TCD | C12: Low-Income Economies | D12: 72 | E12: 269 | F12: 188.23925 | G12: 0.0048780488 | H12: 0.68292683 | I12: 0.20487805 | J12: 0.019512195 | K12: 0.063414634 | L12: 0.024390244 | M12: =$F12*G12 -> 0.91824026 | N12: =$F12*H12 -> 128.55364 | O12: =$F12*I12 -> 38.566091 | P12: =$F12*J12 -> 3.6729611 | Q12: =$F12*K12 -> 11.937123 | R12: =$F12*L12 -> 4.5912013 | S12: =F12<E12*0.7 -> TRUE | T12: =VLOOKUP(B12,Education!B$2:G$48,6,FALSE) -> 80 | U12: =T12/E12 -> 0.29739777 | V12: =U12*E12 -> 80 | W12: =E12*(1-L12)+0.7*V12 -> 318.43902 | X12: =W12*(1-0.1*K12)+0.7*V12 -> 372.41965 | Y12: =X12*(1-0.1*K12)+0.7*V12 -> 426.05797 | Z12: =Y12*(1-0.1*K12)+0.7*V12 -> 479.35614 | AA12: =Z12*(1-0.1*K12)+0.7*V12 -> 532.31632 | AB12: =AA12*(1-0.1*K12)+0.7*V12 -> 584.94065 | AC12: =AB12*(1-0.1*K12)+0.7*V12 -> 637.23127 | AD12: =AC12*(1-0.1*K12)+0.7*V12 -> 689.1903
A13: Comoros | B13: COM | C13: Lower-Middle-Income Economies | D13: 16 | E13: 36 | F13: 40.225453 | G13: 0.046700487 | H13: 0.38491371 | I13: 0.33633804 | J13: 0.14508994 | K13: 0.081948012 | L13: 0.0050098082 | M13: =$F13*G13 -> 1.8785482 | N13: =$F13*H13 -> 15.483328 | O13: =$F13*I13 -> 13.52935 | P13: =$F13*J13 -> 5.8363086 | Q13: =$F13*K13 -> 3.2963959 | R13: =$F13*L13 -> 0.2015218 | S13: =F13<E13*0.7 -> FALSE | T13: =VLOOKUP(B13,Education!B$2:G$48,6,FALSE) -> 0 | U13: 0.2192751 | V13: =U13*F13 -> 8.82044 | W13: =F13*(1-L13)+0.7*V13 -> 46.198239 | X13: =W13*(1-0.1*K13)+0.7*V13 -> 51.993961 | Y13: =X13*(1-0.1*K13)+0.7*V13 -> 57.742189 | Z13: =Y13*(1-0.1*K13)+0.7*V13 -> 63.443311 | AA13: =Z13*(1-0.1*K13)+0.7*V13 -> 69.097714 | AB13: =AA13*(1-0.1*K13)+0.7*V13 -> 74.70578 | AC13: =AB13*(1-0.1*K13)+0.7*V13 -> 80.267889 | AD13: =AC13*(1-0.1*K13)+0.7*V13 -> 85.784418
A14: Congo | B14: COG | C14: Lower-Middle-Income Economies | D14: 0 | E14: 157 | F14: 32.180362 | G14: 0.035714286 | H14: 0.21428571 | I14: 0.32142857 | J14: 0.14285714 | K14: 0.28571429 | L14: 0 | M14: =$E14*G14 -> 5.6071429 | N14: =$E14*H14 -> 33.642857 | O14: =$E14*I14 -> 50.464286 | P14: =$E14*J14 -> 22.428571 | Q14: =$E14*K14 -> 44.857143 | R14: =$E14*L14 -> 0 | S14: =F14<E14*0.7 -> TRUE | T14: =VLOOKUP(B14,Education!B$2:G$48,6,FALSE) -> 0 | U14: 0.2192751 | V14: =U14*E14 -> 34.42619 | W14: =E14*(1-L14)+0.7*V14 -> 181.09833 | X14: =W14*(1-0.1*K14)+0.7*V14 -> 200.02243 | Y14: =X14*(1-0.1*K14)+0.7*V14 -> 218.40583 | Z14: =Y14*(1-0.1*K14)+0.7*V14 -> 236.264 | AA14: =Z14*(1-0.1*K14)+0.7*V14 -> 253.61193 | AB14: =AA14*(1-0.1*K14)+0.7*V14 -> 270.46421 | AC14: =AB14*(1-0.1*K14)+0.7*V14 -> 286.835 | AD14: =AC14*(1-0.1*K14)+0.7*V14 -> 302.73804
A15: Cote d'Ivoire | B15: CIV | C15: Lower-Middle-Income Economies | D15: 2430 | E15: 2495 | F15: 1491.4027 | G15: 0 | H15: 0.22030981 | I15: 0.46385542 | J15: 0.30464716 | K15: 0.011187608 | L15: 0 | M15: =$F15*G15 -> 0 | N15: =$F15*H15 -> 328.57065 | O15: =$F15*I15 -> 691.79524 | P15: =$F15*J15 -> 454.3516 | Q15: =$F15*K15 -> 16.685228 | R15: =$F15*L15 -> 0 | S15: =F15<E15*0.7 -> TRUE | T15: =VLOOKUP(B15,Education!B$2:G$48,6,FALSE) -> 0 | U15: 0.2192751 | V15: =U15*F15 -> 327.02747 | W15: =F15*(1-L15)+0.7*V15 -> 1720.322 | X15: =W15*(1-0.1*K15)+0.7*V15 -> 1947.3166 | Y15: =X15*(1-0.1*K15)+0.7*V15 -> 2174.0572 | Z15: =Y15*(1-0.1*K15)+0.7*V15 -> 2400.5442 | AA15: =Z15*(1-0.1*K15)+0.7*V15 -> 2626.7778 | AB15: =AA15*(1-0.1*K15)+0.7*V15 -> 2852.7583 | AC15: =AB15*(1-0.1*K15)+0.7*V15 -> 3078.486 | AD15: =AC15*(1-0.1*K15)+0.7*V15 -> 3303.9611
A16: DRC | B16: COD | C16: Low-Income Economies | D16: 283 | E16: 1687 | F16: 927.90281 | G16: 0.1012751 | H16: 0.48002118 | I16: 0.28827007 | J16: 0.091590837 | K16: 0.033097084 | L16: 0.0057457277 | M16: =$F16*G16 -> 93.973449 | N16: =$F16*H16 -> 445.413 | O16: =$F16*I16 -> 267.48661 | P16: =$F16*J16 -> 84.987395 | Q16: =$F16*K16 -> 30.710877 | R16: =$F16*L16 -> 5.3314769 | S16: =F16<E16*0.7 -> TRUE | T16: =VLOOKUP(B16,Education!B$2:G$48,6,FALSE) -> 178 | U16: =T16/E16 -> 0.10551274 | V16: =U16*E16 -> 178 | W16: =E16*(1-L16)+0.7*V16 -> 1801.907 | X16: =W16*(1-0.1*K16)+0.7*V16 -> 1920.5432 | Y16: =X16*(1-0.1*K16)+0.7*V16 -> 2038.7867 | Z16: =Y16*(1-0.1*K16)+0.7*V16 -> 2156.6389 | AA16: =Z16*(1-0.1*K16)+0.7*V16 -> 2274.1011 | AB16: =AA16*(1-0.1*K16)+0.7*V16 -> 2391.1745 | AC16: =AB16*(1-0.1*K16)+0.7*V16 -> 2507.8604 | AD16: =AC16*(1-0.1*K16)+0.7*V16 -> 2624.1601
A17: Equatorial Guinea | B17: GNQ | C17: High/Upper-Middle-Income Economies | D17: 0 | E17: 10 | F17: 14 | G17: 0.0035971223 | H17: 0.15030216 | I17: 0.28869065 | J17: 0.28509353 | K17: 0.21433094 | L17: 0.057985612 | M17: =$F17*G17 -> 0.050359712 | N17: =$F17*H17 -> 2.1042302 | O17: =$F17*I17 -> 4.0416691 | P17: =$F17*J17 -> 3.9913094 | Q17: =$F17*K17 -> 3.0006331 | R17: =$F17*L17 -> 0.81179856 | S17: =F17<E17*0.7 -> FALSE | T17: =VLOOKUP(B17,Education!B$2:G$48,6,FALSE) -> 0 | U17: 0.28050332 | V17: =U17*F17 -> 3.9270465 | W17: =F17*(1-L17)+0.7*V17 -> 15.937134 | X17: =W17*(1-0.1*K17)+0.7*V17 -> 18.344484 | Y17: =X17*(1-0.1*K17)+0.7*V17 -> 20.700238 | Z17: =Y17*(1-0.1*K17)+0.7*V17 -> 23.0055 | AA17: =Z17*(1-0.1*K17)+0.7*V17 -> 25.261354 | AB17: =AA17*(1-0.1*K17)+0.7*V17 -> 27.468857 | AC17: =AB17*(1-0.1*K17)+0.7*V17 -> 29.629047 | AD17: =AC17*(1-0.1*K17)+0.7*V17 -> 31.742938
A18: Eritrea | B18: ERI | C18: Low-Income Economies | D18: 0 | E18: 451 | F18: 228.71043 | G18: 0.040201005 | H18: 0.80904523 | I18: 0.10050251 | J18: 0.045226131 | K18: 0.0050251256 | L18: 0 | M18: =$F18*G18 -> 9.1943892 | N18: =$F18*H18 -> 185.03708 | O18: =$F18*I18 -> 22.985973 | P18: =$F18*J18 -> 10.343688 | Q18: =$F18*K18 -> 1.1492986 | R18: =$F18*L18 -> 0 | S18: =F18<E18*0.7 -> TRUE | T18: =VLOOKUP(B18,Education!B$2:G$48,6,FALSE) -> 0 | U18: 0.28182149 | V18: =U18*E18 -> 127.10149 | W18: =E18*(1-L18)+0.7*V18 -> 539.97104 | X18: =W18*(1-0.1*K18)+0.7*V18 -> 628.67074 | Y18: =X18*(1-0.1*K18)+0.7*V18 -> 717.32587 | Z18: =Y18*(1-0.1*K18)+0.7*V18 -> 805.93645 | AA18: =Z18*(1-0.1*K18)+0.7*V18 -> 894.5025 | AB18: =AA18*(1-0.1*K18)+0.7*V18 -> 983.02405 | AC18: =AB18*(1-0.1*K18)+0.7*V18 -> 1071.5011 | AD18: =AC18*(1-0.1*K18)+0.7*V18 -> 1159.9337
A19: Eswatini | B19: SWZ | C19: Lower-Middle-Income Economies | D19: 0 | E19: 281 | F19: 60.196905 | G19: 0.046700487 | H19: 0.38491371 | I19: 0.33633804 | J19: 0.14508994 | K19: 0.081948012 | L19: 0.0050098082 | M19: =$E19*G19 -> 13.122837 | N19: =$E19*H19 -> 108.16075 | O19: =$E19*I19 -> 94.510988 | P19: =$E19*J19 -> 40.770274 | Q19: =$E19*K19 -> 23.027391 | R19: =$E19*L19 -> 1.4077561 | S19: =F19<E19*0.7 -> TRUE | T19: =VLOOKUP(B19,Education!B$2:G$48,6,FALSE) -> 44 | U19: =T19/E19 -> 0.15658363 | V19: =U19*E19 -> 44 | W19: =E19*(1-L19)+0.7*V19 -> 310.39224 | X19: =W19*(1-0.1*K19)+0.7*V19 -> 338.64864 | Y19: =X19*(1-0.1*K19)+0.7*V19 -> 366.67348 | Z19: =Y19*(1-0.1*K19)+0.7*V19 -> 394.46867 | AA19: =Z19*(1-0.1*K19)+0.7*V19 -> 422.03607 | AB19: =AA19*(1-0.1*K19)+0.7*V19 -> 449.37757 | AC19: =AB19*(1-0.1*K19)+0.7*V19 -> 476.49501 | AD19: =AC19*(1-0.1*K19)+0.7*V19 -> 503.39023
A20: Ethiopia | B20: ETH | C20: Low-Income Economies | D20: 0 | E20: 10752 | F20: 22344 | G20: 0.1012751 | H20: 0.48002118 | I20: 0.28827007 | J20: 0.091590837 | K20: 0.033097084 | L20: 0.0057457277 | M20: =$F20*G20 -> 2262.8908 | N20: =$F20*H20 -> 10725.593 | O20: =$F20*I20 -> 6441.1066 | P20: =$F20*J20 -> 2046.5057 | Q20: =$F20*K20 -> 739.52124 | R20: =$F20*L20 -> 128.38254 | S20: =F20<E20*0.7 -> FALSE | T20: =VLOOKUP(B20,Education!B$2:G$48,6,FALSE) -> 699 | U20: =T20/F20 -> 0.031283566 | V20: =U20*F20 -> 699 | W20: =F20*(1-L20)+0.7*V20 -> 22704.917 | X20: =W20*(1-0.1*K20)+0.7*V20 -> 23119.071 | Y20: =X20*(1-0.1*K20)+0.7*V20 -> 23531.853 | Z20: =Y20*(1-0.1*K20)+0.7*V20 -> 23943.27 | AA20: =Z20*(1-0.1*K20)+0.7*V20 -> 24353.325 | AB20: =AA20*(1-0.1*K20)+0.7*V20 -> 24762.022 | AC20: =AB20*(1-0.1*K20)+0.7*V20 -> 25169.367 | AD20: =AC20*(1-0.1*K20)+0.7*V20 -> 25575.364
A21: Gabon | B21: GAB | C21: High/Upper-Middle-Income Economies | D21: 0 | E21: 227 | F21: 186.64222 | G21: 0.0071942446 | H21: 0.24460432 | I21: 0.27338129 | J21: 0.26618705 | K21: 0.17266187 | L21: 0.035971223 | M21: =$F21*G21 -> 1.3427498 | N21: =$F21*H21 -> 45.653493 | O21: =$F21*I21 -> 51.024492 | P21: =$F21*J21 -> 49.681742 | Q21: =$F21*K21 -> 32.225995 | R21: =$F21*L21 -> 6.713749 | S21: =F21<E21*0.7 -> FALSE | T21: =VLOOKUP(B21,Education!B$2:G$48,6,FALSE) -> 2 | U21: =T21/F21 -> 0.010715689 | V21: =U21*F21 -> 2 | W21: =F21*(1-L21)+0.7*V21 -> 181.32847 | X21: =W21*(1-0.1*K21)+0.7*V21 -> 179.59762 | Y21: =X21*(1-0.1*K21)+0.7*V21 -> 177.89665 | Z21: =Y21*(1-0.1*K21)+0.7*V21 -> 176.22506 | AA21: =Z21*(1-0.1*K21)+0.7*V21 -> 174.58232 | AB21: =AA21*(1-0.1*K21)+0.7*V21 -> 172.96795 | AC21: =AB21*(1-0.1*K21)+0.7*V21 -> 171.38145 | AD21: =AC21*(1-0.1*K21)+0.7*V21 -> 169.82235
A22: Gambia | B22: GMB | C22: Low-Income Economies | D22: 5 | E22: 78 | F22: 4.0723751 | G22: 0.1012751 | H22: 0.48002118 | I22: 0.28827007 | J22: 0.091590837 | K22: 0.033097084 | L22: 0.0057457277 | M22: =$E22*G22 -> 7.8994577 | N22: =$E22*H22 -> 37.441652 | O22: =$E22*I22 -> 22.485066 | P22: =$E22*J22 -> 7.1440853 | Q22: =$E22*K22 -> 2.5815726 | R22: =$E22*L22 -> 0.44816676 | S22: =F22<E22*0.7 -> TRUE | T22: =VLOOKUP(B22,Education!B$2:G$48,6,FALSE) -> 0 | U22: 0.28182149 | V22: =U22*E22 -> 21.982076 | W22: =E22*(1-L22)+0.7*V22 -> 92.939286 | X22: =W22*(1-0.1*K22)+0.7*V22 -> 108.01914 | Y22: =X22*(1-0.1*K22)+0.7*V22 -> 123.04908 | Z22: =Y22*(1-0.1*K22)+0.7*V22 -> 138.02928 | AA22: =Z22*(1-0.1*K22)+0.7*V22 -> 152.95989 | AB22: =AA22*(1-0.1*K22)+0.7*V22 -> 167.84109 | AC22: =AB22*(1-0.1*K22)+0.7*V22 -> 182.67304 | AD22: =AC22*(1-0.1*K22)+0.7*V22 -> 197.4559
A23: Ghana | B23: GHA | C23: Lower-Middle-Income Economies | D23: 0 | E23: 918 | F23: 5736 | G23: 0 | H23: 0.37906772 | I23: 0.34652595 | J23: 0.18733509 | K23: 0.08707124 | L23: 0 | M23: =$F23*G23 -> 0 | N23: =$F23*H23 -> 2174.3325 | O23: =$F23*I23 -> 1987.6728 | P23: =$F23*J23 -> 1074.5541 | Q23: =$F23*K23 -> 499.44063 | R23: =$F23*L23 -> 0 | S23: =F23<E23*0.7 -> FALSE | T23: =VLOOKUP(B23,Education!B$2:G$48,6,FALSE) -> 343 | U23: =T23/F23 -> 0.059797768 | V23: =U23*F23 -> 343 | W23: =F23*(1-L23)+0.7*V23 -> 5976.1 | X23: =W23*(1-0.1*K23)+0.7*V23 -> 6164.1654 | Y23: =X23*(1-0.1*K23)+0.7*V23 -> 6350.5932 | Z23: =Y23*(1-0.1*K23)+0.7*V23 -> 6535.3978 | AA23: =Z23*(1-0.1*K23)+0.7*V23 -> 6718.5933 | AB23: =AA23*(1-0.1*K23)+0.7*V23 -> 6900.1937 | AC23: =AB23*(1-0.1*K23)+0.7*V23 -> 7080.2128 | AD23: =AC23*(1-0.1*K23)+0.7*V23 -> 7258.6645
A24: Guinea | B24: GIN | C24: Low-Income Economies | D24: 142 | E24: 255 | F24: 255 | G24: 0.1012751 | H24: 0.48002118 | I24: 0.28827007 | J24: 0.091590837 | K24: 0.033097084 | L24: 0.0057457277 | M24: =$F24*G24 -> 25.82515 | N24: =$F24*H24 -> 122.4054 | O24: =$F24*I24 -> 73.508869 | P24: =$F24*J24 -> 23.355663 | Q24: =$F24*K24 -> 8.4397564 | R24: =$F24*L24 -> 1.4651606 | S24: =F24<E24*0.7 -> FALSE | T24: =VLOOKUP(B24,Education!B$2:G$48,6,FALSE) -> 113 | U24: =T24/F24 -> 0.44313725 | V24: =U24*F24 -> 113 | W24: =F24*(1-L24)+0.7*V24 -> 332.63484 | X24: =W24*(1-0.1*K24)+0.7*V24 -> 410.63392 | Y24: =X24*(1-0.1*K24)+0.7*V24 -> 488.37484 | Z24: =Y24*(1-0.1*K24)+0.7*V24 -> 565.85846 | AA24: =Z24*(1-0.1*K24)+0.7*V24 -> 643.08563 | AB24: =AA24*(1-0.1*K24)+0.7*V24 -> 720.05721 | AC24: =AB24*(1-0.1*K24)+0.7*V24 -> 796.77403 | AD24: =AC24*(1-0.1*K24)+0.7*V24 -> 873.23694
A25: Guinea-Bissau | B25: GNB | C25: Low-Income Economies | D25: 0 | E25: 13 | F25: 2.4240811 | G25: 0.1012751 | H25: 0.48002118 | I25: 0.28827007 | J25: 0.091590837 | K25: 0.033097084 | L25: 0.0057457277 | M25: =$F25*G25 -> 0.24549905 | N25: =$F25*H25 -> 1.1636103 | O25: =$F25*I25 -> 0.69879004 | P25: =$F25*J25 -> 0.22202362 | Q25: =$F25*K25 -> 0.080230016 | R25: =$F25*L25 -> 0.01392811 | S25: =F25<E25*0.7 -> TRUE | T25: =VLOOKUP(B25,Education!B$2:G$48,6,FALSE) -> 0 | U25: 0.28182149 | V25: =U25*E25 -> 3.6636793 | W25: =E25*(1-L25)+0.7*V25 -> 15.489881 | X25: =W25*(1-0.1*K25)+0.7*V25 -> 18.00319 | Y25: =X25*(1-0.1*K25)+0.7*V25 -> 20.50818 | Z25: =Y25*(1-0.1*K25)+0.7*V25 -> 23.004879 | AA25: =Z25*(1-0.1*K25)+0.7*V25 -> 25.493315 | AB25: =AA25*(1-0.1*K25)+0.7*V25 -> 27.973515 | AC25: =AB25*(1-0.1*K25)+0.7*V25 -> 30.445507 | AD25: =AC25*(1-0.1*K25)+0.7*V25 -> 32.909317
A26: Kenya | B26: KEN | C26: Lower-Middle-Income Economies | D26: 2202 | E26: 964 | F26: 1337 | G26: 0.023178808 | H26: 0.30022075 | I26: 0.52207506 | J26: 0.14238411 | K26: 0.01214128 | L26: 0 | M26: =$F26*G26 -> 30.990066 | N26: =$F26*H26 -> 401.39514 | O26: =$F26*I26 -> 698.01435 | P26: =$F26*J26 -> 190.36755 | Q26: =$F26*K26 -> 16.232892 | R26: =$F26*L26 -> 0 | S26: =F26<E26*0.7 -> FALSE | T26: =VLOOKUP(B26,Education!B$2:G$48,6,FALSE) -> 379 | U26: =T26/F26 -> 0.28347046 | V26: =U26*F26 -> 379 | W26: =F26*(1-L26)+0.7*V26 -> 1602.3 | X26: =W26*(1-0.1*K26)+0.7*V26 -> 1865.6546 | Y26: =X26*(1-0.1*K26)+0.7*V26 -> 2128.6895 | Z26: =Y26*(1-0.1*K26)+0.7*V26 -> 2391.405 | AA26: =Z26*(1-0.1*K26)+0.7*V26 -> 2653.8015 | AB26: =AA26*(1-0.1*K26)+0.7*V26 -> 2915.8794 | AC26: =AB26*(1-0.1*K26)+0.7*V26 -> 3177.6392 | AD26: =AC26*(1-0.1*K26)+0.7*V26 -> 3439.0811
A27: Lesotho | B27: LSO | C27: Lower-Middle-Income Economies | D27: 0 | E27: 398 | F27: 256.80611 | G27: 0.046700487 | H27: 0.38491371 | I27: 0.33633804 | J27: 0.14508994 | K27: 0.081948012 | L27: 0.0050098082 | M27: =$F27*G27 -> 11.99297 | N27: =$F27*H27 -> 98.848193 | O27: =$F27*I27 -> 86.373662 | P27: =$F27*J27 -> 37.259984 | Q27: =$F27*K27 -> 21.04475 | R27: =$F27*L27 -> 1.2865493 | S27: =F27<E27*0.7 -> TRUE | T27: =VLOOKUP(B27,Education!B$2:G$48,6,FALSE) -> 33 | U27: =T27/E27 -> 0.082914573 | V27: =U27*F27 -> 21.292969 | W27: =F27*(1-L27)+0.7*V27 -> 270.42464 | X27: =W27*(1-0.1*K27)+0.7*V27 -> 283.11364 | Y27: =X27*(1-0.1*K27)+0.7*V27 -> 295.69866 | Z27: =Y27*(1-0.1*K27)+0.7*V27 -> 308.18054 | AA27: =Z27*(1-0.1*K27)+0.7*V27 -> 320.56014 | AB27: =AA27*(1-0.1*K27)+0.7*V27 -> 332.8383 | AC27: =AB27*(1-0.1*K27)+0.7*V27 -> 345.01583 | AD27: =AC27*(1-0.1*K27)+0.7*V27 -> 357.09357
A28: Liberia | B28: LBR | C28: Low-Income Economies | D28: 0 | E28: 109 | F28: 170 | G28: 0.1012751 | H28: 0.48002118 | I28: 0.28827007 | J28: 0.091590837 | K28: 0.033097084 | L28: 0.0057457277 | M28: =$F28*G28 -> 17.216767 | N28: =$F28*H28 -> 81.6036 | O28: =$F28*I28 -> 49.005913 | P28: =$F28*J28 -> 15.570442 | Q28: =$F28*K28 -> 5.6265043 | R28: =$F28*L28 -> 0.97677372 | S28: =F28<E28*0.7 -> FALSE | T28: =VLOOKUP(B28,Education!B$2:G$48,6,FALSE) -> 22 | U28: =T28/F28 -> 0.12941176 | V28: =U28*F28 -> 22 | W28: =F28*(1-L28)+0.7*V28 -> 184.42323 | X28: =W28*(1-0.1*K28)+0.7*V28 -> 199.21284 | Y28: =X28*(1-0.1*K28)+0.7*V28 -> 213.9535 | Z28: =Y28*(1-0.1*K28)+0.7*V28 -> 228.64538 | AA28: =Z28*(1-0.1*K28)+0.7*V28 -> 243.28863 | AB28: =AA28*(1-0.1*K28)+0.7*V28 -> 257.88342 | AC28: =AB28*(1-0.1*K28)+0.7*V28 -> 272.4299 | AD28: =AC28*(1-0.1*K28)+0.7*V28 -> 286.92823
A29: Madagascar | B29: MDG | C29: Low-Income Economies | D29: 17 | E29: 319 | F29: 30.09434 | G29: 0.1012751 | H29: 0.48002118 | I29: 0.28827007 | J29: 0.091590837 | K29: 0.033097084 | L29: 0.0057457277 | M29: =$E29*G29 -> 32.306756 | N29: =$E29*H29 -> 153.12676 | O29: =$E29*I29 -> 91.958154 | P29: =$E29*J29 -> 29.217477 | Q29: =$E29*K29 -> 10.55797 | R29: =$E29*L29 -> 1.8328871 | S29: =F29<E29*0.7 -> TRUE | T29: =VLOOKUP(B29,Education!B$2:G$48,6,FALSE) -> 0 | U29: 0.28182149 | V29: =U29*E29 -> 89.901054 | W29: =E29*(1-L29)+0.7*V29 -> 380.09785 | X29: =W29*(1-0.1*K29)+0.7*V29 -> 441.77058 | Y29: =X29*(1-0.1*K29)+0.7*V29 -> 503.23918 | Z29: =Y29*(1-0.1*K29)+0.7*V29 -> 564.50435 | AA29: =Z29*(1-0.1*K29)+0.7*V29 -> 625.56674 | AB29: =AA29*(1-0.1*K29)+0.7*V29 -> 686.42703 | AC29: =AB29*(1-0.1*K29)+0.7*V29 -> 747.0859 | AD29: =AC29*(1-0.1*K29)+0.7*V29 -> 807.544
A30: Malawi | B30: MWI | C30: Low-Income Economies | D30: 170 | E30: 387 | F30: 122.98753 | G30: 0.45045045 | H30: 0.22522523 | I30: 0.17117117 | J30: 0.099099099 | K30: 0.054054054 | L30: 0 | M30: =$F30*G30 -> 55.399788 | N30: =$F30*H30 -> 27.699894 | O30: =$F30*I30 -> 21.051919 | P30: =$F30*J30 -> 12.187953 | Q30: =$F30*K30 -> 6.6479745 | R30: =$F30*L30 -> 0 | S30: =F30<E30*0.7 -> TRUE | T30: =VLOOKUP(B30,Education!B$2:G$48,6,FALSE) -> 110 | U30: =T30/E30 -> 0.28423773 | V30: =U30*E30 -> 110 | W30: =E30*(1-L30)+0.7*V30 -> 464 | X30: =W30*(1-0.1*K30)+0.7*V30 -> 538.49189 | Y30: =X30*(1-0.1*K30)+0.7*V30 -> 612.58112 | Z30: =Y30*(1-0.1*K30)+0.7*V30 -> 686.26988 | AA30: =Z30*(1-0.1*K30)+0.7*V30 -> 759.56031 | AB30: =AA30*(1-0.1*K30)+0.7*V30 -> 832.45458 | AC30: =AB30*(1-0.1*K30)+0.7*V30 -> 904.95482 | AD30: =AC30*(1-0.1*K30)+0.7*V30 -> 977.06318
A31: Mali | B31: MLI | C31: Low-Income Economies | D31: 0 | E31: 1340 | F31: 1721 | G31: 0.1012751 | H31: 0.48002118 | I31: 0.28827007 | J31: 0.091590837 | K31: 0.033097084 | L31: 0.0057457277 | M31: =$F31*G31 -> 174.29444 | N31: =$F31*H31 -> 826.11645 | O31: =$F31*I31 -> 496.1128 | P31: =$F31*J31 -> 157.62783 | Q31: =$F31*K31 -> 56.960082 | R31: =$F31*L31 -> 9.8883974 | S31: =F31<E31*0.7 -> FALSE | T31: =VLOOKUP(B31,Education!B$2:G$48,6,FALSE) -> 0 | U31: 0.28182149 | V31: =U31*F31 -> 485.01478 | W31: =F31*(1-L31)+0.7*V31 -> 2050.6219 | X31: =W31*(1-0.1*K31)+0.7*V31 -> 2383.3453 | Y31: =X31*(1-0.1*K31)+0.7*V31 -> 2714.9675 | Z31: =Y31*(1-0.1*K31)+0.7*V31 -> 3045.4921 | AA31: =Z31*(1-0.1*K31)+0.7*V31 -> 3374.9227 | AB31: =AA31*(1-0.1*K31)+0.7*V31 -> 3703.2631 | AC31: =AB31*(1-0.1*K31)+0.7*V31 -> 4030.5167 | AD31: =AC31*(1-0.1*K31)+0.7*V31 -> 4356.6872
A32: Mauritania | B32: MRT | C32: Lower-Middle-Income Economies | D32: 0 | E32: 87 | F32: 96.787074 | G32: 0.046700487 | H32: 0.38491371 | I32: 0.33633804 | J32: 0.14508994 | K32: 0.081948012 | L32: 0.0050098082 | M32: =$F32*G32 -> 4.5200035 | N32: =$F32*H32 -> 37.254672 | O32: =$F32*I32 -> 32.553174 | P32: =$F32*J32 -> 14.042831 | Q32: =$F32*K32 -> 7.9315083 | R32: =$F32*L32 -> 0.48488468 | S32: =F32<E32*0.7 -> FALSE | T32: =VLOOKUP(B32,Education!B$2:G$48,6,FALSE) -> 0 | U32: 0.2192751 | V32: =U32*F32 -> 21.222995 | W32: =F32*(1-L32)+0.7*V32 -> 111.15829 | X32: =W32*(1-0.1*K32)+0.7*V32 -> 125.10346 | Y32: =X32*(1-0.1*K32)+0.7*V32 -> 138.93436 | Z32: =Y32*(1-0.1*K32)+0.7*V32 -> 152.65192 | AA32: =Z32*(1-0.1*K32)+0.7*V32 -> 166.25706 | AB32: =AA32*(1-0.1*K32)+0.7*V32 -> 179.75072 | AC32: =AB32*(1-0.1*K32)+0.7*V32 -> 193.13379 | AD32: =AC32*(1-0.1*K32)+0.7*V32 -> 206.40719
A33: Mauritius | B33: MUS | C33: High/Upper-Middle-Income Economies | D33: 460 | E33: 748 | F33: 41.271989 | G33: 0.0035971223 | H33: 0.15030216 | I33: 0.28869065 | J33: 0.28509353 | K33: 0.21433094 | L33: 0.057985612 | M33: =$E33*G33 -> 2.6906475 | N33: =$E33*H33 -> 112.42601 | O33: =$E33*I33 -> 215.9406 | P33: =$E33*J33 -> 213.24996 | Q33: =$E33*K33 -> 160.31954 | R33: =$E33*L33 -> 43.373237 | S33: =F33<E33*0.7 -> TRUE | T33: =VLOOKUP(B33,Education!B$2:G$48,6,FALSE) -> 0 | U33: 0.28050332 | V33: =U33*E33 -> 209.81648 | W33: =E33*(1-L33)+0.7*V33 -> 851.4983 | X33: =W33*(1-0.1*K33)+0.7*V33 -> 980.1196 | Y33: =X33*(1-0.1*K33)+0.7*V33 -> 1105.9841 | Z33: =Y33*(1-0.1*K33)+0.7*V33 -> 1229.151 | AA33: =Z33*(1-0.1*K33)+0.7*V33 -> 1349.678 | AB33: =AA33*(1-0.1*K33)+0.7*V33 -> 1467.6218 | AC33: =AB33*(1-0.1*K33)+0.7*V33 -> 1583.0377 | AD33: =AC33*(1-0.1*K33)+0.7*V33 -> 1695.9798
A34: Mozambique | B34: MOZ | C34: Low-Income Economies | D34: 103 | E34: 305 | F34: 498 | G34: 0.010845987 | H34: 0.46203905 | I34: 0.39262473 | J34: 0.10629067 | K34: 0.023861171 | L34: 0.0043383948 | M34: =$F34*G34 -> 5.4013015 | N34: =$F34*H34 -> 230.09544 | O34: =$F34*I34 -> 195.52711 | P34: =$F34*J34 -> 52.932755 | Q34: =$F34*K34 -> 11.882863 | R34: =$F34*L34 -> 2.1605206 | S34: =F34<E34*0.7 -> FALSE | T34: =VLOOKUP(B34,Education!B$2:G$48,6,FALSE) -> 0 | U34: 0.28182149 | V34: =U34*F34 -> 140.3471 | W34: =F34*(1-L34)+0.7*V34 -> 594.08245 | X34: =W34*(1-0.1*K34)+0.7*V34 -> 690.90787 | Y34: =X34*(1-0.1*K34)+0.7*V34 -> 787.50225 | Z34: =Y34*(1-0.1*K34)+0.7*V34 -> 883.86615 | AA34: =Z34*(1-0.1*K34)+0.7*V34 -> 980.00011 | AB34: =AA34*(1-0.1*K34)+0.7*V34 -> 1075.9047 | AC34: =AB34*(1-0.1*K34)+0.7*V34 -> 1171.5804 | AD34: =AC34*(1-0.1*K34)+0.7*V34 -> 1267.0279
A35: Namibia | B35: NAM | C35: High/Upper-Middle-Income Economies | D35: 0 | E35: 598 | F35: 655 | G35: 0.0035971223 | H35: 0.15030216 | I35: 0.28869065 | J35: 0.28509353 | K35: 0.21433094 | L35: 0.057985612 | M35: =$F35*G35 -> 2.3561151 | N35: =$F35*H35 -> 98.447914 | O35: =$F35*I35 -> 189.09237 | P35: =$F35*J35 -> 186.73626 | Q35: =$F35*K35 -> 140.38676 | R35: =$F35*L35 -> 37.980576 | S35: =F35<E35*0.7 -> FALSE | T35: =VLOOKUP(B35,Education!B$2:G$48,6,FALSE) -> 247 | U35: =T35/F35 -> 0.37709924 | V35: =U35*F35 -> 247 | W35: =F35*(1-L35)+0.7*V35 -> 789.91942 | X35: =W35*(1-0.1*K35)+0.7*V35 -> 945.88901 | Y35: =X35*(1-0.1*K35)+0.7*V35 -> 1098.5157 | Z35: =Y35*(1-0.1*K35)+0.7*V35 -> 1247.8711 | AA35: =Z35*(1-0.1*K35)+0.7*V35 -> 1394.0254 | AB35: =AA35*(1-0.1*K35)+0.7*V35 -> 1537.0471 | AC35: =AB35*(1-0.1*K35)+0.7*V35 -> 1677.0034 | AD35: =AC35*(1-0.1*K35)+0.7*V35 -> 1813.96
A36: Niger | B36: NER | C36: Low-Income Economies | D36: 51 | E36: 60 | F36: 49.419842 | G36: 0.1012751 | H36: 0.48002118 | I36: 0.28827007 | J36: 0.091590837 | K36: 0.033097084 | L36: 0.0057457277 | M36: =$F36*G36 -> 5.0049993 | N36: =$F36*H36 -> 23.722571 | O36: =$F36*I36 -> 14.246261 | P36: =$F36*J36 -> 4.5264047 | Q36: =$F36*K36 -> 1.6356527 | R36: =$F36*L36 -> 0.28395296 | S36: =F36<E36*0.7 -> FALSE | T36: =VLOOKUP(B36,Education!B$2:G$48,6,FALSE) -> 0 | U36: 0.28182149 | V36: =U36*F36 -> 13.927573 | W36: =F36*(1-L36)+0.7*V36 -> 58.88519 | X36: =W36*(1-0.1*K36)+0.7*V36 -> 68.439599 | Y36: =X36*(1-0.1*K36)+0.7*V36 -> 77.962385 | Z36: =Y36*(1-0.1*K36)+0.7*V36 -> 87.453653 | AA36: =Z36*(1-0.1*K36)+0.7*V36 -> 96.913508 | AB36: =AA36*(1-0.1*K36)+0.7*V36 -> 106.34205 | AC36: =AB36*(1-0.1*K36)+0.7*V36 -> 115.73939 | AD36: =AC36*(1-0.1*K36)+0.7*V36 -> 125.10563
A37: Nigeria | B37: NGA | C37: Lower-Middle-Income Economies | D37: 20035 | E37: 24668 | F37: 21005.731 | G37: 0.046700487 | H37: 0.38491371 | I37: 0.33633804 | J37: 0.14508994 | K37: 0.081948012 | L37: 0.0050098082 | M37: =$F37*G37 -> 980.97788 | N37: =$F37*H37 -> 8085.394 | O37: =$F37*I37 -> 7065.0264 | P37: =$F37*J37 -> 3047.7204 | Q37: =$F37*K37 -> 1721.3779 | R37: =$F37*L37 -> 105.23468 | S37: =F37<E37*0.7 -> FALSE | T37: =VLOOKUP(B37,Education!B$2:G$48,6,FALSE) -> 0 | U37: 0.2192751 | V37: =U37*F37 -> 4606.0338 | W37: =F37*(1-L37)+0.7*V37 -> 24124.72 | X37: =W37*(1-0.1*K37)+0.7*V37 -> 27151.247 | Y37: =X37*(1-0.1*K37)+0.7*V37 -> 30152.971 | Z37: =Y37*(1-0.1*K37)+0.7*V37 -> 33130.097 | AA37: =Z37*(1-0.1*K37)+0.7*V37 -> 36082.826 | AB37: =AA37*(1-0.1*K37)+0.7*V37 -> 39011.358 | AC37: =AB37*(1-0.1*K37)+0.7*V37 -> 41915.892 | AD37: =AC37*(1-0.1*K37)+0.7*V37 -> 44796.623
A38: Rwanda | B38: RWA | C38: Low-Income Economies | D38: 114 | E38: 886 | F38: 886 | G38: 0.1012751 | H38: 0.48002118 | I38: 0.28827007 | J38: 0.091590837 | K38: 0.033097084 | L38: 0.0057457277 | M38: =$F38*G38 -> 89.729737 | N38: =$F38*H38 -> 425.29876 | O38: =$F38*I38 -> 255.40729 | P38: =$F38*J38 -> 81.149481 | Q38: =$F38*K38 -> 29.324016 | R38: =$F38*L38 -> 5.0907148 | S38: =F38<E38*0.7 -> FALSE | T38: =VLOOKUP(B38,Education!B$2:G$48,6,FALSE) -> 95 | U38: =T38/F38 -> 0.10722348 | V38: =U38*F38 -> 95 | W38: =F38*(1-L38)+0.7*V38 -> 947.40929 | X38: =W38*(1-0.1*K38)+0.7*V38 -> 1010.7736 | Y38: =X38*(1-0.1*K38)+0.7*V38 -> 1073.9283 | Z38: =Y38*(1-0.1*K38)+0.7*V38 -> 1136.8739 | AA38: =Z38*(1-0.1*K38)+0.7*V38 -> 1199.6112 | AB38: =AA38*(1-0.1*K38)+0.7*V38 -> 1262.1408 | AC38: =AB38*(1-0.1*K38)+0.7*V38 -> 1324.4635 | AD38: =AC38*(1-0.1*K38)+0.7*V38 -> 1386.5799
A39: Sao Tome and Principe | B39: STP | C39: Lower-Middle-Income Economies | D39: 0 | E39: 37 | F39: 37 | G39: 0.046700487 | H39: 0.38491371 | I39: 0.33633804 | J39: 0.14508994 | K39: 0.081948012 | L39: 0.0050098082 | M39: =$F39*G39 -> 1.727918 | N39: =$F39*H39 -> 14.241807 | O39: =$F39*I39 -> 12.444507 | P39: =$F39*J39 -> 5.3683279 | Q39: =$F39*K39 -> 3.0320764 | R39: =$F39*L39 -> 0.1853629 | S39: =F39<E39*0.7 -> FALSE | T39: =VLOOKUP(B39,Education!B$2:G$48,6,FALSE) -> 0 | U39: 0.2192751 | V39: =U39*F39 -> 8.1131786 | W39: =F39*(1-L39)+0.7*V39 -> 42.493862 | X39: =W39*(1-0.1*K39)+0.7*V39 -> 47.824858 | Y39: =X39*(1-0.1*K39)+0.7*V39 -> 53.112168 | Z39: =Y39*(1-0.1*K39)+0.7*V39 -> 58.356149 | AA39: =Z39*(1-0.1*K39)+0.7*V39 -> 63.557157 | AB39: =AA39*(1-0.1*K39)+0.7*V39 -> 68.715544 | AC39: =AB39*(1-0.1*K39)+0.7*V39 -> 73.831659 | AD39: =AC39*(1-0.1*K39)+0.7*V39 -> 78.905848
A40: Senegal | B40: SEN | C40: Lower-Middle-Income Economies | D40: 143 | E40: 162 | F40: 352 | G40: 0.0029585799 | H40: 0.23076923 | I40: 0.44674556 | J40: 0.20414201 | K40: 0.11538462 | L40: 0 | M40: =$F40*G40 -> 1.0414201 | N40: =$F40*H40 -> 81.230769 | O40: =$F40*I40 -> 157.25444 | P40: =$F40*J40 -> 71.857988 | Q40: =$F40*K40 -> 40.615385 | R40: =$F40*L40 -> 0 | S40: =F40<E40*0.7 -> FALSE | T40: =VLOOKUP(B40,Education!B$2:G$48,6,FALSE) -> 171 | U40: =T40/F40 -> 0.48579545 | V40: =U40*F40 -> 171 | W40: =F40*(1-L40)+0.7*V40 -> 471.7 | X40: =W40*(1-0.1*K40)+0.7*V40 -> 585.95731 | Y40: =X40*(1-0.1*K40)+0.7*V40 -> 698.89626 | Z40: =Y40*(1-0.1*K40)+0.7*V40 -> 810.53207 | AA40: =Z40*(1-0.1*K40)+0.7*V40 -> 920.87978 | AB40: =AA40*(1-0.1*K40)+0.7*V40 -> 1029.9542 | AC40: =AB40*(1-0.1*K40)+0.7*V40 -> 1137.7702 | AD40: =AC40*(1-0.1*K40)+0.7*V40 -> 1244.342
A41: Seychelles | B41: SYC | C41: High/Upper-Middle-Income Economies | D41: 4 | E41: 124 | F41: 70.107217 | G41: 0.0035971223 | H41: 0.15030216 | I41: 0.28869065 | J41: 0.28509353 | K41: 0.21433094 | L41: 0.057985612 | M41: =$F41*G41 -> 0.25218423 | N41: =$F41*H41 -> 10.537266 | O41: =$F41*I41 -> 20.239298 | P41: =$F41*J41 -> 19.987114 | Q41: =$F41*K41 -> 15.026145 | R41: =$F41*L41 -> 4.0652099 | S41: =F41<E41*0.7 -> TRUE | T41: =VLOOKUP(B41,Education!B$2:G$48,6,FALSE) -> 0 | U41: 0.28050332 | V41: =U41*F41 -> 19.665307 | W41: =F41*(1-L41)+0.7*V41 -> 79.807722 | X41: =W41*(1-0.1*K41)+0.7*V41 -> 91.862911 | Y41: =X41*(1-0.1*K41)+0.7*V41 -> 103.65972 | Z41: =Y41*(1-0.1*K41)+0.7*V41 -> 115.20369 | AA41: =Z41*(1-0.1*K41)+0.7*V41 -> 126.50023 | AB41: =AA41*(1-0.1*K41)+0.7*V41 -> 137.55465 | AC41: =AB41*(1-0.1*K41)+0.7*V41 -> 148.37215 | AD41: =AC41*(1-0.1*K41)+0.7*V41 -> 158.95779
...

Sheet Education
A1: Country | B1: iso codes | C1: Generalist Medical Practitioners | D1: Specialist Medical Practitioners | E1: Dentists | F1: Other Dental practitioners | G1: Pharmacists | H1: Other Pharmacy practitioners | I1: Midwifery personnel | J1: Nursing Personnel | K1: Medical and Pathology Laboratory scientists | L1: Paramedical Practitioners | M1: Other Health Workers | N1: Total | O1: Data Sorce(s)
A2: Algeria | B2: DZA | C2: 0 | N2: 0 | O2: NHWA dataset, 2023
A3: Angola | B3: AGO | C3: 611 | E3: 145 | G3: 529 | J3: 2950 | N3: 4235 | O3: Dent-2018;
A4: Benin | B4: BEN | C4: 780 | D4: 385 | G4: 143 | I4: 247 | J4: 257 | K4: 1113 | M4: 1194 | N4: 4119 | O4: Med-2021; Pharm-2021;Mid-2021; Nur-2021;Biom-2021; others-2021
A5: Botswana | B5: BWA | C5: 60 | D5: 48 | E5: 7 | F5: 10 | G5: 95 | H5: 60 | I5: 40 | J5: 490 | K5: 189 | L5: 30 | M5: 597 | N5: 1626 | O5: 2022 for all
A6: Burkina Faso | B6: BFA | C6: 1492 | D6: 385 | E6: 62 | G6: 594 | I6: 1170 | J6: 1170 | N6: 4873 | O6: NHWA dataset, 2023
A7: Burundi | B7: BDI | C7: 325 | D7: 240 | G7: 39 | I7: 196 | J7: 1467 | K7: 322 | M7: 194 | N7: 2783 | O7: 2018 dataset
A8: Cameroon | B8: CMR | C8: 800 | J8: 2660 | K8: 800 | N8: 4260 | O8: NHWA dataset, 2023
A9: Cabo Verde | B9: CPV | F9: 7 | M9: 83 | N9: 90 | O9: NHWA dataset, 2023
A10: Central African Republic | B10: CAF | C10: 18 | N10: 18 | O10: NHWA dataset, 2023
A11: Chad | B11: TCD | C11: 330 | D11: 30 | G11: 80 | H11: 180 | I11: 2084 | J11: 2920 | K11: 220 | N11: 5844 | O11: NHWA dataset, 2023
A12: Comoros | B12: COM | I12: 29 | J12: 40 | N12: 69 | O12: 2021 for all
A13: Congo | B13: COG | C13: 60 | D13: 315 | F13: 10 | H13: 5 | I13: 120 | J13: 60 | L13: 50 | M13: 408 | N13: 1028 | O13: 2022 for all
A14: Cote d'Ivoire | B14: CIV | C14: 254 | D14: 48 | H14: 151 | J14: 1007 | K14: 1106 | M14: 450 | N14: 3016 | O14: NHWA dataset, 2023
A15: Democratic Republic of the Congo | B15: COD | C15: 6020 | E15: 66 | G15: 178 | H15: 328 | I15: 3453 | J15: 24061 | K15: 2571 | M15: 3151 | N15: 39828 | O15: NHWA dataset, 2023
A16: Equatorial Guinea | B16: GNQ | C16: 767 | I16: 492 | J16: 962 | K16: 27 | M16: 1304 | N16: 3552 | O16: NHWA dataset, 2023
A17: Eritrea | B17: ERI | J17: 400 | M17: 1023 | N17: 1423 | O17: Nurs-2022
A18: Eswatini | B18: SWZ | G18: 44 | H18: 30 | I18: 80 | J18: 160 | K18: 78 | M18: 58 | N18: 450 | O18: NHWA dataset, 2023
A19: Ethiopia | B19: ETH | C19: 3114 | D19: 880 | E19: 189 | F19: 64 | G19: 699 | H19: 2878 | I19: 2440 | J19: 6298 | K19: 1220 | L19: 1613 | M19: 3672 | N19: 23067 | O19: pharmacist from 2018
A20: Gabon | B20: GAB | C20: 46 | D20: 16 | G20: 2 | I20: 34 | J20: 95 | K20: 6 | N20: 199 | O20: NHWA dataset, 2023
A21: Gambia | B21: GMB | C21: 23 | J21: 137 | K21: 6 | N21: 166 | O21: NHWA dataset, 2023
A22: Ghana | B22: GHA | C22: 1566 | G22: 343 | I22: 4827 | J22: 21271 | K22: 396 | N22: 28403 | O22: HLMA 2023; Ismaila (2023)
A23: Guinea | B23: GIN | C23: 767 | D23: 74 | G23: 113 | H23: 34 | I23: 492 | J23: 964 | K23: 27 | M23: 1304 | N23: 3775 | O23: NHWA dataset, 2023
A24: Guinea-Bissau | B24: GNB | K24: 23 | M24: 489 | N24: 512 | O24: NHWA dataset, 2023
A25: Kenya | B25: KEN | C25: 558 | E25: 36 | G25: 379 | H25: 20 | J25: 1070 | K25: 519 | M25: 366 | N25: 2948 | O25: HLMA data, Dentist-2018; CMHW-2022; Biom -2018;
A26: Lesotho | B26: LSO | C26: 8 | D26: 22 | E26: 8 | G26: 33 | H26: 20 | I26: 69 | J26: 376 | K26: 20 | N26: 556 | O26: NHWA dataset, 2023
A27: Liberia | B27: LBR | C27: 29 | D27: 50 | G27: 22 | J27: 63 | K27: 56 | M27: 50 | N27: 270 | O27: NHWA dataset, 2023
A28: Madagascar | B28: MDG | C28: 316 | D28: 156 | I28: 2473 | J28: 2540 | K28: 116 | M28: 297 | N28: 5898 | O28: NHWA dataset, 2023
A29: Malawi | B29: MWI | C29: 115 | D29: 167 | G29: 110 | H29: 189 | I29: 1171 | J29: 386 | K29: 175 | M29: 616 | N29: 2929 | O29: NHWA dataset, 2023
A30: Mali | B30: MLI | N30: 0 | O30: NHWA dataset, 2023
A31: Mauritania | B31: MRT | D31: 76 | J31: 113 | M31: 366 | N31: 555 | O31: NHWA dataset, 2023
A32: Mauritius | B32: MUS | C32: 432 | I32: 40 | J32: 175 | M32: 39 | N32: 686 | O32: SADC dataset, 2022
A33: Mozambique | B33: MOZ | C33: 819 | D33: 146 | E33: 161 | H33: 112 | I33: 140 | J33: 580 | K33: 248 | L33: 20 | N33: 2226 | O33: capacity-HLMA data extracted
A34: Namibia | B34: NAM | C34: 475 | D34: 3 | G34: 247 | H34: 31 | I34: 1414 | J34: 200 | K34: 121 | M34: 175 | N34: 2666 | O34: NHWA dataset, 2023; HLMA dataset, 2019; 2018 survey dataset
A35: Niger | B35: NER | C35: 370 | D35: 14 | I35: 124 | J35: 305 | K35: 45 | M35: 1891 | N35: 2749 | O35: Med-2021,2022; Nurs-2022; Midw-2022; Other-2021,2022, CHW-2021
A36: Nigeria | B36: NGA | C36: 4340 | E36: 459 | I36: 375 | J36: 12835 | K36: 1774 | N36: 19783 | O36: NHWA dataset, 2023
A37: Rwanda | B37: RWA | C37: 11 | G37: 95 | I37: 176 | J37: 355 | M37: 81 | N37: 718 | O37: NHWA dataset, 2023
A38: Sao Tome and Principe | B38: STP | N38: 0 | O38: NHWA dataset, 2023
A39: Senegal | B39: SEN | C39: 434 | D39: 137 | E39: 67 | G39: 171 | I39: 104 | J39: 582 | K39: 36 | M39: 710 | N39: 2241 | O39: NHWA dataset, 2023
A40: Seychelles | B40: SYC | C40: 10 | H40: 20 | I40: 10 | J40: 40 | M40: 80 | N40: 160 | O40: NHWA dataset, 2023
...

Sheet Sheet5
A1: Row Labels | B1: Pharmaceutical Technicians and Assistants | C1: Pharmacists | D1: Pharmacists
A2: Angola | D2: =B2+C2 -> 0
A3: Benin | C3: 22 | D3: =B3+C3 -> 22
A4: Botswana | C4: 0 | D4: =B4+C4 -> 0
A5: Burkina Faso | C5: 86 | D5: =B5+C5 -> 86
A6: Burundi | C6: 39 | D6: =B6+C6 -> 39
A7: Cameroon | D7: =B7+C7 -> 0
A8: Cape-Verde | C8: 7 | D8: =B8+C8 -> 7
A9: CAR | D9: =B9+C9 -> 0
A10: Chad | D10: =B10+C10 -> 0
A11: Congo | D11: =B11+C11 -> 0
A12: Cote d'Ivoire | C12: 67 | D12: =B12+C12 -> 67
A13: DRC | D13: =B13+C13 -> 0
A14: Eritrea | B14: 39 | C14: 43 | D14: =B14+C14 -> 82
A15: Eswatini | D15: =B15+C15 -> 0
A16: Ethiopia | C16: 350 | D16: =B16+C16 -> 350
A17: Gabon | C17: 2 | D17: =B17+C17 -> 2
A18: Gambia | D18: =B18+C18 -> 0
A19: Ghana | D19: =B19+C19 -> 0
A20: Guinea | C20: 113 | D20: =B20+C20 -> 113
A21: Guinea-Bissau | D21: =B21+C21 -> 0
A22: Kenya | C22: 379 | D22: =B22+C22 -> 379
A23: Lesotho | C23: 33 | D23: =B23+C23 -> 33
A24: Liberia | D24: =B24+C24 -> 0
A25: Madagascar | D25: =B25+C25 -> 0
A26: Malawi | B26: 75 | C26: 35 | D26: =B26+C26 -> 110
A27: Mali | D27: =B27+C27 -> 0
A28: Mauritania | D28: =B28+C28 -> 0
A29: Mauritius | D29: =B29+C29 -> 0
A30: Mozambique | D30: =B30+C30 -> 0
A31: Namibia | C31: 76 | D31: =B31+C31 -> 76
A32: Niger | C32: 0 | D32: =B32+C32 -> 0
A33: Nigeria | D33: =B33+C33 -> 0
A34: Rwanda | C34: 95 | D34: =B34+C34 -> 95
A35: Senegal | D35: =B35+C35 -> 0
A36: Sierra Leone | C36: 29 | D36: =B36+C36 -> 29
A37: South Africa | D37: =B37+C37 -> 0
A38: South Sudan | D38: =B38+C38 -> 0
A39: Tanzania | C39: 114 | D39: =B39+C39 -> 114
A40: Togo | C40: 2 | D40: =B40+C40 -> 2
...
