Workbook

Sheet Sheet2
A1: Country | B1: Generalist Medical Practitioners | C1: Specialist Medical Practitioners | D1: Dentists | E1: Other Dental practitioners | F1: Pharmacists | G1: Other Pharmacy practitioners | H1: Midwifery personnel | I1: Nursing Professionals | J1: Medical and Pathology Laboratory scientists | K1: Paramedical Practitioners | L1: Other Health Workers | M1: Total | N1: Year | O1: Source
A2: Cameroon | B2: 800 | I2: 2660 | J2: 800 | M2: 4260

Sheet Sheet1
A3: Row Labels | B3: Sum of Generalist Medical Practitioners | C3: Sum of Specialist Medical Practitioners | D3: Sum of Dentists | E3: Sum of Other Dental practitioners | F3: Sum of Pharmacists | G3: Sum of Other Pharmacy practitioners | H3: Sum of Midwifery personnel | I3: Count of Nursing Professionals | J3: Sum of Medical and Pathology Laboratory scientists | K3: Sum of Paramedical Practitioners | L3: Sum of Other Health Workers | M3: Sum of Total
A4: Algeria | B4: 3000 | M4: 3000
A5: Angola | B5: 611 | D5: 145 | F5: 529 | I5: 1 | M5: 4235
A6: Benin | B6: 780 | C6: 385 | F6: 143 | H6: 247 | I6: 1 | J6: 1113 | L6: 1194 | M6: 4119
A7: Botswana | B7: 60 | C7: 48 | D7: 7 | E7: 10 | F7: 95 | G7: 60 | H7: 40 | I7: 1 | J7: 189 | K7: 30 | L7: 597 | M7: 1136
A8: Burkina Faso | B8: 1492 | C8: 385 | D8: 62 | F8: 594 | H8: 1170 | I8: 1 | M8: 4873
A9: Burundi | B9: 325 | C9: 240 | F9: 39 | H9: 196 | I9: 1 | J9: 322 | L9: 194 | M9: 2783
A10: Cabo Verde | E10: 7 | L10: 83 | M10: 90
A11: Cameroon | B11: 800 | I11: 1 | J11: 800 | M11: 4260
A12: Central African Republic | B12: 18 | M12: 18
A13: Chad | B13: 330 | C13: 30 | F13: 80 | G13: 180 | H13: 2084 | I13: 1 | J13: 220 | M13: 31944
A14: Comoros | H14: 29 | I14: 1 | M14: 69
A15: Congo | B15: 60 | C15: 315 | E15: 10 | G15: 5 | H15: 120 | I15: 1 | K15: 50 | L15: 408 | M15: 1028
A16: Cote d'Ivoire | B16: 254 | C16: 48 | G16: 151 | I16: 1 | J16: 1106 | L16: 450 | M16: 3016
A17: Democratic Republic of the Congo | L17: 84 | M17: 84
A18: Equatorial Guinea | B18: 767 | H18: 492 | I18: 1 | J18: 27 | L18: 1304 | M18: 3552
A19: Eritrea | I19: 1 | L19: 1023 | M19: 1423
A20: Eswatini | F20: 44 | G20: 30 | H20: 80 | I20: 1 | J20: 78 | L20: 58 | M20: 450
A21: Ethiopia | B21: 3114 | C21: 880 | D21: 189 | E21: 64 | F21: 699 | G21: 2878 | H21: 2440 | I21: 1 | J21: 1220 | K21: 1613 | L21: 3672 | M21: 23067
A22: Gabon | B22: 46 | C22: 16 | F22: 2 | H22: 34 | I22: 1 | J22: 6 | M22: 199
A23: Gambia | B23: 23 | I23: 1 | J23: 6 | M23: 166
A24: Ghana | B24: 1566 | F24: 343 | H24: 4827 | I24: 1 | J24: 396 | M24: 28403
A25: Guinea | B25: 767 | C25: 74 | F25: 113 | G25: 34 | H25: 492 | I25: 1 | J25: 27 | L25: 1304 | M25: 3775
A26: Guinea-Bissau | J26: 23 | L26: 489 | M26: 512
A27: Kenya | B27: 558 | D27: 36 | F27: 379 | G27: 20 | I27: 1 | J27: 519 | L27: 366 | M27: 2948
A28: Lesotho | B28: 8 | C28: 22 | D28: 8 | F28: 33 | G28: 20 | H28: 69 | I28: 1 | J28: 20 | M28: 556
A29: Liberia | B29: 29 | C29: 50 | F29: 22 | I29: 1 | J29: 56 | L29: 50 | M29: 270
A30: Madagascar | B30: 316 | C30: 156 | H30: 2473 | I30: 1 | J30: 116 | L30: 297 | M30: 5898
A31: Malawi | B31: 115 | C31: 167 | F31: 110 | G31: 189 | H31: 1171 | I31: 1 | J31: 175 | L31: 616 | M31: 2929
A32: Mali | M32: 0
A33: Mauritania | C33: 76 | I33: 1 | L33: 366 | M33: 555
A34: Mauritius | B34: 432 | H34: 40 | I34: 1 | L34: 39 | M34: 686
A35: Mozambique | B35: 819 | C35: 146 | D35: 161 | G35: 112 | H35: 140 | I35: 1 | J35: 248 | K35: 20 | M35: 2226
A36: Namibia | B36: 475 | C36: 3 | F36: 247 | G36: 31 | H36: 1414 | I36: 1 | J36: 121 | L36: 175 | M36: 2666
A37: Niger | B37: 370 | C37: 14 | H37: 124 | I37: 1 | J37: 45 | L37: 1891 | M37: 2749
A38: Nigeria | B38: 4340 | D38: 459 | H38: 375 | I38: 1 | J38: 1774 | M38: 19783
A39: Rwanda | B39: 11 | F39: 95 | H39: 176 | I39: 1 | L39: 81 | M39: 718
A40: Sao Tome and Principe | M40: 0
A41: Senegal | B41: 529 | D41: 70 | F41: 289 | H41: 3600 | I41: 1 | J41: 36 | L41: 710 | M41: 8734
A42: Seychelles | B42: 10 | G42: 20 | H42: 10 | I42: 1 | L42: 80 | M42: 160
...

Sheet Education capacity
A1: Country | B1: Generalist Medical Practitioners | C1: Specialist Medical Practitioners | D1: Dentists | E1: Other Dental practitioners | F1: Pharmacists | G1: Other Pharmacy practitioners | H1: Midwifery personnel | I1: Nursing Personnel | J1: Medical and Pathology Laboratory scientists | K1: Paramedical Practitioners | L1: Other Health Workers | M1: Total | N1: Data Sorce(s)
A2: Algeria | B2: =+'[1]G_Alignment of education'!$H$25 -> 0 | M2: =SUM(B2:L2) -> 0 | N2: NHWA dataset, 2023
A3: Angola | B3: 611 | D3: 145 | F3: 529 | I3: 2950 | M3: =SUM(B3:L3) -> 4235 | N3: Dent-2018;
A4: Benin | B4: 780 | C4: 385 | F4: 143 | H4: 247 | I4: 257 | J4: 1113 | L4: 1194 | M4: =SUM(B4:L4) -> 4119 | N4: Med-2021; Pharm-2021;Mid-2021; Nur-2021;Biom-2021; others-2021
A5: Botswana | B5: 60 | C5: 48 | D5: 7 | E5: 10 | F5: 95 | G5: 60 | H5: 40 | I5: 490 | J5: 189 | K5: 30 | L5: 597 | M5: =SUM(B5:L5) -> 1626 | N5: 2022 for all
A6: Burkina Faso | B6: 1492 | C6: 385 | D6: 62 | F6: 594 | H6: 1170 | I6: 1170 | M6: =SUM(B6:L6) -> 4873 | N6: NHWA dataset, 2023
A7: Burundi | B7: 325 | C7: 240 | F7: 39 | H7: 196 | I7: 1467 | J7: 322 | L7: 194 | M7: =SUM(B7:L7) -> 2783 | N7: 2018 dataset
A8: Cameroon | B8: 800 | I8: 2660 | J8: 800 | M8: =SUM(B8:L8) -> 4260 | N8: NHWA dataset, 2023
A9: Cabo Verde | E9: 7 | L9: 83 | M9: =SUM(B9:L9) -> 90 | N9: NHWA dataset, 2023
A10: Central African Republic | B10: 18 | M10: =SUM(B10:L10) -> 18 | N10: NHWA dataset, 2023
A11: Chad | B11: 330 | C11: 30 | F11: 80 | G11: 180 | H11: 2084 | I11: 2920 | J11: 220 | M11: =SUM(B11:L11) -> 5844 | N11: NHWA dataset, 2023
A12: Comoros | H12: 29 | I12: 40 | M12: =SUM(B12:L12) -> 69 | N12: 2021 for all
A13: Congo | B13: 60 | C13: 315 | E13: 10 | G13: 5 | H13: 120 | I13: 60 | K13: 50 | L13: 408 | M13: =SUM(B13:L13) -> 1028 | N13: 2022 for all
A14: Cote d'Ivoire | B14: 254 | C14: 48 | G14: 151 | I14: 1007 | J14: 1106 | L14: 450 | M14: =SUM(B14:L14) -> 3016 | N14: NHWA dataset, 2023
A15: Democratic Republic of the Congo | B15: 6020 | D15: 66 | F15: 178 | G15: 328 | H15: 3453 | I15: 24061 | J15: 2571 | L15: 3151 | M15: 39828 | N15: NHWA dataset, 2023
A16: Equatorial Guinea | B16: 767 | H16: 492 | I16: 962 | J16: 27 | L16: 1304 | M16: =SUM(B16:L16) -> 3552 | N16: NHWA dataset, 2023
A17: Eritrea | I17: 400 | L17: 1023 | M17: =SUM(B17:L17) -> 1423 | N17: Nurs-2022
A18: Eswatini | F18: 44 | G18: 30 | H18: 80 | I18: 160 | J18: 78 | L18: 58 | M18: =SUM(B18:L18) -> 450 | N18: NHWA dataset, 2023
A19: Ethiopia | B19: 3114 | C19: 880 | D19: 189 | E19: 64 | F19: 699 | G19: 2878 | H19: 2440 | I19: 6298 | J19: 1220 | K19: 1613 | L19: 3672 | M19: =SUM(B19:L19) -> 23067 | N19: pharmacist from 2018
A20: Gabon | B20: 46 | C20: 16 | F20: 2 | H20: 34 | I20: 95 | J20: 6 | M20: =SUM(B20:L20) -> 199 | N20: NHWA dataset, 2023
A21: Gambia | B21: 23 | I21: 137 | J21: 6 | M21: =SUM(B21:L21) -> 166 | N21: NHWA dataset, 2023
A22: Ghana | B22: 1566 | F22: 343 | H22: 4827 | I22: 21271 | J22: 396 | M22: =SUM(B22:L22) -> 28403 | N22: HLMA 2023; Ismaila (2023)
A23: Guinea | B23: 767 | C23: 74 | F23: 113 | G23: 34 | H23: 492 | I23: 964 | J23: 27 | L23: 1304 | M23: =SUM(B23:L23) -> 3775 | N23: NHWA dataset, 2023
A24: Guinea-Bissau | J24: 23 | L24: 489 | M24: =SUM(B24:L24) -> 512 | N24: NHWA dataset, 2023
A25: Kenya | B25: 558 | D25: 36 | F25: 379 | G25: 20 | I25: 1070 | J25: 519 | L25: 366 | M25: =SUM(B25:L25) -> 2948 | N25: HLMA data, Dentist-2018; CMHW-2022; Biom -2018;
A26: Lesotho | B26: 8 | C26: 22 | D26: 8 | F26: 33 | G26: 20 | H26: 69 | I26: 376 | J26: 20 | M26: =SUM(B26:L26) -> 556 | N26: NHWA dataset, 2023
A27: Liberia | B27: 29 | C27: 50 | F27: 22 | I27: 63 | J27: 56 | L27: 50 | M27: =SUM(B27:L27) -> 270 | N27: NHWA dataset, 2023
A28: Madagascar | B28: 316 | C28: 156 | H28: 2473 | I28: 2540 | J28: 116 | L28: 297 | M28: =SUM(B28:L28) -> 5898 | N28: NHWA dataset, 2023
A29: Malawi | B29: 115 | C29: 167 | F29: 110 | G29: 189 | H29: 1171 | I29: 386 | J29: 175 | L29: 616 | M29: =SUM(B29:L29) -> 2929 | N29: NHWA dataset, 2023
A30: Mali | M30: =SUM(B30:L30) -> 0 | N30: NHWA dataset, 2023
A31: Mauritania | C31: 76 | I31: 113 | L31: 366 | M31: =SUM(B31:L31) -> 555 | N31: NHWA dataset, 2023
A32: Mauritius | B32: 432 | H32: 40 | I32: 175 | L32: 39 | M32: =SUM(B32:L32) -> 686 | N32: SADC dataset, 2022
A33: Mozambique | B33: 819 | C33: 146 | D33: 161 | G33: 112 | H33: 140 | I33: 580 | J33: 248 | K33: 20 | M33: =SUM(B33:L33) -> 2226 | N33: capacity-HLMA data extracted
A34: Namibia | B34: 475 | C34: 3 | F34: 247 | G34: 31 | H34: 1414 | I34: 200 | J34: 121 | L34: 175 | M34: =SUM(B34:L34) -> 2666 | N34: NHWA dataset, 2023; HLMA dataset, 2019; 2018 survey dataset
A35: Niger | B35: 370 | C35: 14 | H35: 124 | I35: 305 | J35: 45 | L35: 1891 | M35: =SUM(B35:L35) -> 2749 | N35: Med-2021,2022; Nurs-2022; Midw-2022; Other-2021,2022, CHW-2021
A36: Nigeria | B36: 4340 | D36: 459 | H36: 375 | I36: 12835 | J36: 1774 | M36: =SUM(B36:L36) -> 19783 | N36: NHWA dataset, 2023
A37: Rwanda | B37: 11 | F37: 95 | H37: 176 | I37: 355 | L37: 81 | M37: =SUM(B37:L37) -> 718 | N37: NHWA dataset, 2023
A38: Sao Tome and Principe | M38: =SUM(B38:L38) -> 0 | N38: NHWA dataset, 2023
A39: Senegal | B39: 434 | C39: 137 | D39: 67 | F39: 171 | H39: 104 | I39: 582 | J39: 36 | L39: 710 | M39: =SUM(B39:L39) -> 2241 | N39: NHWA dataset, 2023
A40: Seychelles | B40: 10 | G40: 20 | H40: 10 | I40: 40 | L40: 80 | M40: =SUM(B40:L40) -> 160 | N40: NHWA dataset, 2023
...

Sheet Education updated
A1: iso | B1: Country | C1: Generalist Medical Practitioners | D1: Specialist Medical Practitioners | E1: Dentists | F1: Other Dental practitioners | G1: Pharmacists | H1: Other Pharmacy practitioners | I1: Midwifery personnel | J1: Nursing Personnel | K1: Medical and Pathology Laboratory scientists | L1: Paramedical Practitioners | M1: Other Health Workers | N1: Total | O1: Data Sorce(s) | P1: iso
A2: DZA | B2: Algeria | C2: =+'[1]G_Alignment of education'!$H$25 -> 0 | N2: =SUM(C2:M2) -> 0 | O2: NHWA dataset, 2023 | P2: =VLOOKUP(Table14[[#This Row],[Country]],Graph!A$2:B$48,2,FALSE) -> DZA
A3: AGO | B3: Angola | C3: 611 | E3: 145 | G3: 529 | J3: 2950 | N3: =SUM(C3:M3) -> 4235 | O3: Dent-2018; | P3: =VLOOKUP(Table14[[#This Row],[Country]],Graph!A$2:B$48,2,FALSE) -> AGO
A4: BEN | B4: Benin | C4: 780 | D4: 385 | G4: 143 | I4: 247 | J4: 257 | K4: 1113 | M4: 1194 | N4: =SUM(C4:M4) -> 4119 | O4: Med-2021; Pharm-2021;Mid-2021; Nur-2021;Biom-2021; others-2021 | P4: =VLOOKUP(Table14[[#This Row],[Country]],Graph!A$2:B$48,2,FALSE) -> BEN
A5: BWA | B5: Botswana | C5: 60 | D5: 48 | E5: 7 | F5: 10 | G5: 95 | H5: 60 | I5: 40 | J5: 490 | K5: 189 | L5: 30 | M5: 597 | N5: =SUM(C5:M5) -> 1626 | O5: 2022 for all | P5: =VLOOKUP(Table14[[#This Row],[Country]],Graph!A$2:B$48,2,FALSE) -> BWA
A6: BFA | B6: Burkina Faso | C6: 1492 | D6: 385 | E6: 62 | G6: 594 | I6: 1170 | J6: 1170 | N6: =SUM(C6:M6) -> 4873 | O6: NHWA dataset, 2023 | P6: =VLOOKUP(Table14[[#This Row],[Country]],Graph!A$2:B$48,2,FALSE) -> BFA
A7: BDI | B7: Burundi | C7: 325 | D7: 240 | G7: 39 | I7: 196 | J7: 1467 | K7: 322 | M7: 194 | N7: =SUM(C7:M7) -> 2783 | O7: 2018 dataset | P7: =VLOOKUP(Table14[[#This Row],[Country]],Graph!A$2:B$48,2,FALSE) -> BDI
A8: CMR | B8: Cameroon | C8: 800 | J8: 2660 | K8: 800 | N8: =SUM(C8:M8) -> 4260 | O8: NHWA dataset, 2023 | P8: =VLOOKUP(Table14[[#This Row],[Country]],Graph!A$2:B$48,2,FALSE) -> CMR
A9: CPV | B9: Cabo Verde | F9: 7 | M9: 83 | N9: =SUM(C9:M9) -> 90 | O9: NHWA dataset, 2023 | P9: =VLOOKUP(Table14[[#This Row],[Country]],Graph!A$2:B$48,2,FALSE) -> CPV
A10: CAF | B10: Central African Republic | C10: 18 | N10: =SUM(C10:M10) -> 18 | O10: NHWA dataset, 2023 | P10: =VLOOKUP(Table14[[#This Row],[Country]],Graph!A$2:B$48,2,FALSE) -> CAF
A11: TCD | B11: Chad | C11: 330 | D11: 30 | G11: 80 | H11: 180 | I11: 2084 | J11: 2920 | K11: 220 | N11: =SUM(C11:M11) -> 5844 | O11: NHWA dataset, 2023 | P11: =VLOOKUP(Table14[[#This Row],[Country]],Graph!A$2:B$48,2,FALSE) -> TCD
A12: COM | B12: Comoros | I12: 29 | J12: 40 | N12: =SUM(C12:M12) -> 69 | O12: 2021 for all | P12: =VLOOKUP(Table14[[#This Row],[Country]],Graph!A$2:B$48,2,FALSE) -> COM
A13: COG | B13: Congo | C13: 60 | D13: 315 | F13: 10 | H13: 5 | I13: 120 | J13: 60 | L13: 50 | M13: 408 | N13: =SUM(C13:M13) -> 1028 | O13: 2022 for all | P13: =VLOOKUP(Table14[[#This Row],[Country]],Graph!A$2:B$48,2,FALSE) -> COG
A14: CIV | B14: Cote d'Ivoire | C14: 254 | D14: 48 | H14: 151 | J14: 1007 | K14: 1106 | M14: 450 | N14: =SUM(C14:M14) -> 3016 | O14: NHWA dataset, 2023 | P14: =VLOOKUP(Table14[[#This Row],[Country]],Graph!A$2:B$48,2,FALSE) -> CIV
A15: COD | B15: Democratic Republic of the Congo | C15: 6020 | E15: 66 | G15: 178 | H15: 328 | I15: 3453 | J15: 24061 | K15: 2571 | M15: 3151 | N15: 39828 | O15: NHWA dataset, 2023 | P15: =VLOOKUP(Table14[[#This Row],[Country]],Graph!A$2:B$48,2,FALSE) -> COD
A16: GNQ | B16: Equatorial Guinea | C16: 767 | I16: 492 | J16: 962 | K16: 27 | M16: 1304 | N16: =SUM(C16:M16) -> 3552 | O16: NHWA dataset, 2023 | P16: =VLOOKUP(Table14[[#This Row],[Country]],Graph!A$2:B$48,2,FALSE) -> GNQ
A17: ERI | B17: Eritrea | J17: 400 | M17: 1023 | N17: =SUM(C17:M17) -> 1423 | O17: Nurs-2022 | P17: =VLOOKUP(Table14[[#This Row],[Country]],Graph!A$2:B$48,2,FALSE) -> ERI
A18: SWZ | B18: Eswatini | G18: 44 | H18: 30 | I18: 80 | J18: 160 | K18: 78 | M18: 58 | N18: =SUM(C18:M18) -> 450 | O18: NHWA dataset, 2023 | P18: =VLOOKUP(Table14[[#This Row],[Country]],Graph!A$2:B$48,2,FALSE) -> SWZ
A19: ETH | B19: Ethiopia | C19: 3114 | D19: 880 | E19: 189 | F19: 64 | G19: 699 | H19: 2878 | I19: 2440 | J19: 6298 | K19: 1220 | L19: 1613 | M19: 3672 | N19: =SUM(C19:M19) -> 23067 | O19: pharmacist from 2018 | P19: =VLOOKUP(Table14[[#This Row],[Country]],Graph!A$2:B$48,2,FALSE) -> ETH
A20: GAB | B20: Gabon | C20: 46 | D20: 16 | G20: 2 | I20: 34 | J20: 95 | K20: 6 | N20: =SUM(C20:M20) -> 199 | O20: NHWA dataset, 2023 | P20: =VLOOKUP(Table14[[#This Row],[Country]],Graph!A$2:B$48,2,FALSE) -> GAB
A21: GMB | B21: Gambia | C21: 23 | J21: 137 | K21: 6 | N21: =SUM(C21:M21) -> 166 | O21: NHWA dataset, 2023 | P21: =VLOOKUP(Table14[[#This Row],[Country]],Graph!A$2:B$48,2,FALSE) -> GMB
A22: GHA | B22: Ghana | C22: 1566 | G22: 343 | I22: 4827 | J22: 21271 | K22: 396 | N22: =SUM(C22:M22) -> 28403 | O22: HLMA 2023; Ismaila (2023) | P22: =VLOOKUP(Table14[[#This Row],[Country]],Graph!A$2:B$48,2,FALSE) -> GHA
A23: GIN | B23: Guinea | C23: 767 | D23: 74 | G23: 113 | H23: 34 | I23: 492 | J23: 964 | K23: 27 | M23: 1304 | N23: =SUM(C23:M23) -> 3775 | O23: NHWA dataset, 2023 | P23: =VLOOKUP(Table14[[#This Row],[Country]],Graph!A$2:B$48,2,FALSE) -> GIN
A24: GNB | B24: Guinea-Bissau | K24: 23 | M24: 489 | N24: =SUM(C24:M24) -> 512 | O24: NHWA dataset, 2023 | P24: =VLOOKUP(Table14[[#This Row],[Country]],Graph!A$2:B$48,2,FALSE) -> GNB
A25: KEN | B25: Kenya | C25: 558 | E25: 36 | G25: 379 | H25: 20 | J25: 1070 | K25: 519 | M25: 366 | N25: =SUM(C25:M25) -> 2948 | O25: HLMA data, Dentist-2018; CMHW-2022; Biom -2018; | P25: =VLOOKUP(Table14[[#This Row],[Country]],Graph!A$2:B$48,2,FALSE) -> KEN
A26: LSO | B26: Lesotho | C26: 8 | D26: 22 | E26: 8 | G26: 33 | H26: 20 | I26: 69 | J26: 376 | K26: 20 | N26: =SUM(C26:M26) -> 556 | O26: NHWA dataset, 2023 | P26: =VLOOKUP(Table14[[#This Row],[Country]],Graph!A$2:B$48,2,FALSE) -> LSO
A27: LBR | B27: Liberia | C27: 29 | D27: 50 | G27: 22 | J27: 63 | K27: 56 | M27: 50 | N27: =SUM(C27:M27) -> 270 | O27: NHWA dataset, 2023 | P27: =VLOOKUP(Table14[[#This Row],[Country]],Graph!A$2:B$48,2,FALSE) -> LBR
A28: MDG | B28: Madagascar | C28: 316 | D28: 156 | I28: 2473 | J28: 2540 | K28: 116 | M28: 297 | N28: =SUM(C28:M28) -> 5898 | O28: NHWA dataset, 2023 | P28: =VLOOKUP(Table14[[#This Row],[Country]],Graph!A$2:B$48,2,FALSE) -> MDG
A29: MWI | B29: Malawi | C29: 115 | D29: 167 | G29: 110 | H29: 189 | I29: 1171 | J29: 386 | K29: 175 | M29: 616 | N29: =SUM(C29:M29) -> 2929 | O29: NHWA dataset, 2023 | P29: =VLOOKUP(Table14[[#This Row],[Country]],Graph!A$2:B$48,2,FALSE) -> MWI
A30: MLI | B30: Mali | N30: =SUM(C30:M30) -> 0 | O30: NHWA dataset, 2023 | P30: =VLOOKUP(Table14[[#This Row],[Country]],Graph!A$2:B$48,2,FALSE) -> MLI
A31: MRT | B31: Mauritania | D31: 76 | J31: 113 | M31: 366 | N31: =SUM(C31:M31) -> 555 | O31: NHWA dataset, 2023 | P31: =VLOOKUP(Table14[[#This Row],[Country]],Graph!A$2:B$48,2,FALSE) -> MRT
A32: MUS | B32: Mauritius | C32: 432 | I32: 40 | J32: 175 | M32: 39 | N32: =SUM(C32:M32) -> 686 | O32: SADC dataset, 2022 | P32: =VLOOKUP(Table14[[#This Row],[Country]],Graph!A$2:B$48,2,FALSE) -> MUS
A33: MOZ | B33: Mozambique | C33: 819 | D33: 146 | E33: 161 | H33: 112 | I33: 140 | J33: 580 | K33: 248 | L33: 20 | N33: =SUM(C33:M33) -> 2226 | O33: capacity-HLMA data extracted | P33: =VLOOKUP(Table14[[#This Row],[Country]],Graph!A$2:B$48,2,FALSE) -> MOZ
A34: NAM | B34: Namibia | C34: 475 | D34: 3 | G34: 247 | H34: 31 | I34: 1414 | J34: 200 | K34: 121 | M34: 175 | N34: =SUM(C34:M34) -> 2666 | O34: NHWA dataset, 2023; HLMA dataset, 2019; 2018 survey dataset | P34: =VLOOKUP(Table14[[#This Row],[Country]],Graph!A$2:B$48,2,FALSE) -> NAM
A35: NER | B35: Niger | C35: 370 | D35: 14 | I35: 124 | J35: 305 | K35: 45 | M35: 1891 | N35: =SUM(C35:M35) -> 2749 | O35: Med-2021,2022; Nurs-2022; Midw-2022; Other-2021,2022, CHW-2021 | P35: =VLOOKUP(Table14[[#This Row],[Country]],Graph!A$2:B$48,2,FALSE) -> NER
A36: NGA | B36: Nigeria | C36: 4340 | E36: 459 | I36: 375 | J36: 12835 | K36: 1774 | N36: =SUM(C36:M36) -> 19783 | O36: NHWA dataset, 2023 | P36: =VLOOKUP(Table14[[#This Row],[Country]],Graph!A$2:B$48,2,FALSE) -> NGA
A37: RWA | B37: Rwanda | C37: 11 | G37: 95 | I37: 176 | J37: 355 | M37: 81 | N37: =SUM(C37:M37) -> 718 | O37: NHWA dataset, 2023 | P37: =VLOOKUP(Table14[[#This Row],[Country]],Graph!A$2:B$48,2,FALSE) -> RWA
A38: STP | B38: Sao Tome and Principe | N38: =SUM(C38:M38) -> 0 | O38: NHWA dataset, 2023 | P38: =VLOOKUP(Table14[[#This Row],[Country]],Graph!A$2:B$48,2,FALSE) -> STP
A39: SEN | B39: Senegal | C39: 434 | D39: 137 | E39: 67 | G39: 171 | I39: 104 | J39: =288+294 -> 582 | K39: 36 | M39: 710 | N39: =SUM(C39:M39) -> 2241 | O39: NHWA dataset, 2023 | P39: =VLOOKUP(Table14[[#This Row],[Country]],Graph!A$2:B$48,2,FALSE) -> SEN
A40: SYC | B40: Seychelles | C40: 10 | H40: 20 | I40: 10 | J40: 40 | M40: 80 | N40: =SUM(C40:M40) -> 160 | O40: NHWA dataset, 2023 | P40: =VLOOKUP(Table14[[#This Row],[Country]],Graph!A$2:B$48,2,FALSE) -> SYC
...

Sheet Graph
A1: Country | B1: ISO3 | C1: Generalist Medical Practitioners | D1: Nursing Personnel | E1: Midwifery personnel | F1: Dentists | G1: Other Dental practitioners | H1: Pharmacists | I1: Other Pharmacy practitioners | J1: Medical and Pathology Laboratory scientists | K1: Paramedical Practitioners | L1: Other Health Workers | M1: Total | O1: Health workers graduation capacity among 29 countries in African region producing more than 1000 health workers annually, by occupation
A2: Algeria | B2: =VLOOKUP(A2,CountryCodes!A$2:C$195,3,FALSE) -> DZA | C2: =VLOOKUP(B2,'Education updated'!A$2:C$48,3,FALSE) -> 0 | D2: =VLOOKUP(B2,'Education updated'!A$2:J$48,10,FALSE) -> 0 | E2: =VLOOKUP(B2,'Education updated'!A$2:I$48,9,FALSE) -> 0 | F2: =VLOOKUP(B2,'Education updated'!A$2:E$48,5,FALSE) -> 0 | G2: =VLOOKUP(B2,'Education updated'!A$2:F$48,6,FALSE) -> 0 | H2: =VLOOKUP(B2,'Education updated'!A$2:G$48,7,FALSE) -> 0 | I2: =VLOOKUP(B2,'Education updated'!A$2:H$48,8,FALSE) -> 0 | J2: =VLOOKUP(B2,'Education updated'!A$2:K$48,11,FALSE) -> 0 | K2: =VLOOKUP(B2,'Education updated'!A$2:L$48,12,FALSE) -> 0
A3: Mali | B3: =VLOOKUP(A3,CountryCodes!A$2:C$195,3,FALSE) -> MLI | C3: =VLOOKUP(B3,'Education updated'!A$2:C$48,3,FALSE) -> 0 | D3: =VLOOKUP(B3,'Education updated'!A$2:J$48,10,FALSE) -> 0 | E3: =VLOOKUP(B3,'Education updated'!A$2:I$48,9,FALSE) -> 0 | F3: =VLOOKUP(B3,'Education updated'!A$2:E$48,5,FALSE) -> 0 | G3: =VLOOKUP(B3,'Education updated'!A$2:F$48,6,FALSE) -> 0 | H3: =VLOOKUP(B3,'Education updated'!A$2:G$48,7,FALSE) -> 0 | I3: =VLOOKUP(B3,'Education updated'!A$2:H$48,8,FALSE) -> 0 | J3: =VLOOKUP(B3,'Education updated'!A$2:K$48,11,FALSE) -> 0 | K3: =VLOOKUP(B3,'Education updated'!A$2:L$48,12,FALSE) -> 0
A4: Sao Tome and Principe | B4: =VLOOKUP(A4,CountryCodes!A$2:C$195,3,FALSE) -> STP | C4: =VLOOKUP(B4,'Education updated'!A$2:C$48,3,FALSE) -> 0 | D4: =VLOOKUP(B4,'Education updated'!A$2:J$48,10,FALSE) -> 0 | E4: =VLOOKUP(B4,'Education updated'!A$2:I$48,9,FALSE) -> 0 | F4: =VLOOKUP(B4,'Education updated'!A$2:E$48,5,FALSE) -> 0 | G4: =VLOOKUP(B4,'Education updated'!A$2:F$48,6,FALSE) -> 0 | H4: =VLOOKUP(B4,'Education updated'!A$2:G$48,7,FALSE) -> 0 | I4: =VLOOKUP(B4,'Education updated'!A$2:H$48,8,FALSE) -> 0 | J4: =VLOOKUP(B4,'Education updated'!A$2:K$48,11,FALSE) -> 0 | K4: =VLOOKUP(B4,'Education updated'!A$2:L$48,12,FALSE) -> 0
A5: Central African Republic | B5: =VLOOKUP(A5,CountryCodes!A$2:C$195,3,FALSE) -> CAF | C5: =VLOOKUP(B5,'Education updated'!A$2:C$48,3,FALSE) -> 18 | D5: =VLOOKUP(B5,'Education updated'!A$2:J$48,10,FALSE) -> 0 | E5: =VLOOKUP(B5,'Education updated'!A$2:I$48,9,FALSE) -> 0 | F5: =VLOOKUP(B5,'Education updated'!A$2:E$48,5,FALSE) -> 0 | G5: =VLOOKUP(B5,'Education updated'!A$2:F$48,6,FALSE) -> 0 | H5: =VLOOKUP(B5,'Education updated'!A$2:G$48,7,FALSE) -> 0 | I5: =VLOOKUP(B5,'Education updated'!A$2:H$48,8,FALSE) -> 0 | J5: =VLOOKUP(B5,'Education updated'!A$2:K$48,11,FALSE) -> 0 | K5: =VLOOKUP(B5,'Education updated'!A$2:L$48,12,FALSE) -> 0 | M5: =SUM(C5:L5) -> 18
A6: Comoros | B6: =VLOOKUP(A6,CountryCodes!A$2:C$195,3,FALSE) -> COM | C6: =VLOOKUP(B6,'Education updated'!A$2:C$48,3,FALSE) -> 0 | D6: =VLOOKUP(B6,'Education updated'!A$2:J$48,10,FALSE) -> 40 | E6: =VLOOKUP(B6,'Education updated'!A$2:I$48,9,FALSE) -> 29 | F6: =VLOOKUP(B6,'Education updated'!A$2:E$48,5,FALSE) -> 0 | G6: =VLOOKUP(B6,'Education updated'!A$2:F$48,6,FALSE) -> 0 | H6: =VLOOKUP(B6,'Education updated'!A$2:G$48,7,FALSE) -> 0 | I6: =VLOOKUP(B6,'Education updated'!A$2:H$48,8,FALSE) -> 0 | J6: =VLOOKUP(B6,'Education updated'!A$2:K$48,11,FALSE) -> 0 | K6: =VLOOKUP(B6,'Education updated'!A$2:L$48,12,FALSE) -> 0 | M6: =SUM(C6:L6) -> 69
A7: Cabo Verde | B7: CPV | C7: =VLOOKUP(B7,'Education updated'!A$2:C$48,3,FALSE) -> 0 | D7: =VLOOKUP(B7,'Education updated'!A$2:J$48,10,FALSE) -> 0 | E7: =VLOOKUP(B7,'Education updated'!A$2:I$48,9,FALSE) -> 0 | F7: =VLOOKUP(B7,'Education updated'!A$2:E$48,5,FALSE) -> 0 | G7: =VLOOKUP(B7,'Education updated'!A$2:F$48,6,FALSE) -> 7 | H7: =VLOOKUP(B7,'Education updated'!A$2:G$48,7,FALSE) -> 0 | I7: =VLOOKUP(B7,'Education updated'!A$2:H$48,8,FALSE) -> 0 | J7: =VLOOKUP(B7,'Education updated'!A$2:K$48,11,FALSE) -> 0 | K7: =VLOOKUP(B7,'Education updated'!A$2:L$48,12,FALSE) -> 0 | L7: 83 | M7: =SUM(C7:L7) -> 90
A8: Seychelles | B8: =VLOOKUP(A8,CountryCodes!A$2:C$195,3,FALSE) -> SYC | C8: =VLOOKUP(B8,'Education updated'!A$2:C$48,3,FALSE) -> 10 | D8: =VLOOKUP(B8,'Education updated'!A$2:J$48,10,FALSE) -> 40 | E8: =VLOOKUP(B8,'Education updated'!A$2:I$48,9,FALSE) -> 10 | F8: =VLOOKUP(B8,'Education updated'!A$2:E$48,5,FALSE) -> 0 | G8: =VLOOKUP(B8,'Education updated'!A$2:F$48,6,FALSE) -> 0 | H8: =VLOOKUP(B8,'Education updated'!A$2:G$48,7,FALSE) -> 0 | I8: =VLOOKUP(B8,'Education updated'!A$2:H$48,8,FALSE) -> 20 | J8: =VLOOKUP(B8,'Education updated'!A$2:K$48,11,FALSE) -> 0 | K8: =VLOOKUP(B8,'Education updated'!A$2:L$48,12,FALSE) -> 0 | L8: 80 | M8: =SUM(C8:L8) -> 160
A9: Gambia | B9: =VLOOKUP(A9,CountryCodes!A$2:C$195,3,FALSE) -> GMB | C9: =VLOOKUP(B9,'Education updated'!A$2:C$48,3,FALSE) -> 23 | D9: =VLOOKUP(B9,'Education updated'!A$2:J$48,10,FALSE) -> 137 | E9: =VLOOKUP(B9,'Education updated'!A$2:I$48,9,FALSE) -> 0 | F9: =VLOOKUP(B9,'Education updated'!A$2:E$48,5,FALSE) -> 0 | G9: =VLOOKUP(B9,'Education updated'!A$2:F$48,6,FALSE) -> 0 | H9: =VLOOKUP(B9,'Education updated'!A$2:G$48,7,FALSE) -> 0 | I9: =VLOOKUP(B9,'Education updated'!A$2:H$48,8,FALSE) -> 0 | J9: =VLOOKUP(B9,'Education updated'!A$2:K$48,11,FALSE) -> 6 | K9: =VLOOKUP(B9,'Education updated'!A$2:L$48,12,FALSE) -> 0 | M9: =SUM(C9:L9) -> 166
A10: Gabon | B10: =VLOOKUP(A10,CountryCodes!A$2:C$195,3,FALSE) -> GAB | C10: =VLOOKUP(B10,'Education updated'!A$2:C$48,3,FALSE) -> 46 | D10: =VLOOKUP(B10,'Education updated'!A$2:J$48,10,FALSE) -> 95 | E10: =VLOOKUP(B10,'Education updated'!A$2:I$48,9,FALSE) -> 34 | F10: =VLOOKUP(B10,'Education updated'!A$2:E$48,5,FALSE) -> 0 | G10: =VLOOKUP(B10,'Education updated'!A$2:F$48,6,FALSE) -> 0 | H10: =VLOOKUP(B10,'Education updated'!A$2:G$48,7,FALSE) -> 2 | I10: =VLOOKUP(B10,'Education updated'!A$2:H$48,8,FALSE) -> 0 | J10: =VLOOKUP(B10,'Education updated'!A$2:K$48,11,FALSE) -> 6 | K10: =VLOOKUP(B10,'Education updated'!A$2:L$48,12,FALSE) -> 0 | M10: =SUM(C10:L10) -> 183
A11: Liberia | B11: =VLOOKUP(A11,CountryCodes!A$2:C$195,3,FALSE) -> LBR | C11: =VLOOKUP(B11,'Education updated'!A$2:C$48,3,FALSE) -> 29 | D11: =VLOOKUP(B11,'Education updated'!A$2:J$48,10,FALSE) -> 63 | E11: =VLOOKUP(B11,'Education updated'!A$2:I$48,9,FALSE) -> 0 | F11: =VLOOKUP(B11,'Education updated'!A$2:E$48,5,FALSE) -> 0 | G11: =VLOOKUP(B11,'Education updated'!A$2:F$48,6,FALSE) -> 0 | H11: =VLOOKUP(B11,'Education updated'!A$2:G$48,7,FALSE) -> 22 | I11: =VLOOKUP(B11,'Education updated'!A$2:H$48,8,FALSE) -> 0 | J11: =VLOOKUP(B11,'Education updated'!A$2:K$48,11,FALSE) -> 56 | K11: =VLOOKUP(B11,'Education updated'!A$2:L$48,12,FALSE) -> 0 | L11: 50 | M11: =SUM(C11:L11) -> 220
A12: Eswatini | B12: =VLOOKUP(A12,CountryCodes!A$2:C$195,3,FALSE) -> SWZ | C12: =VLOOKUP(B12,'Education updated'!A$2:C$48,3,FALSE) -> 0 | D12: =VLOOKUP(B12,'Education updated'!A$2:J$48,10,FALSE) -> 160 | E12: =VLOOKUP(B12,'Education updated'!A$2:I$48,9,FALSE) -> 80 | F12: =VLOOKUP(B12,'Education updated'!A$2:E$48,5,FALSE) -> 0 | G12: =VLOOKUP(B12,'Education updated'!A$2:F$48,6,FALSE) -> 0 | H12: =VLOOKUP(B12,'Education updated'!A$2:G$48,7,FALSE) -> 44 | I12: =VLOOKUP(B12,'Education updated'!A$2:H$48,8,FALSE) -> 30 | J12: =VLOOKUP(B12,'Education updated'!A$2:K$48,11,FALSE) -> 78 | K12: =VLOOKUP(B12,'Education updated'!A$2:L$48,12,FALSE) -> 0 | L12: 58 | M12: =SUM(C12:L12) -> 450
A13: Mauritania | B13: =VLOOKUP(A13,CountryCodes!A$2:C$195,3,FALSE) -> MRT | C13: =VLOOKUP(B13,'Education updated'!A$2:C$48,3,FALSE) -> 0 | D13: =VLOOKUP(B13,'Education updated'!A$2:J$48,10,FALSE) -> 113 | E13: =VLOOKUP(B13,'Education updated'!A$2:I$48,9,FALSE) -> 0 | F13: =VLOOKUP(B13,'Education updated'!A$2:E$48,5,FALSE) -> 0 | G13: =VLOOKUP(B13,'Education updated'!A$2:F$48,6,FALSE) -> 0 | H13: =VLOOKUP(B13,'Education updated'!A$2:G$48,7,FALSE) -> 0 | I13: =VLOOKUP(B13,'Education updated'!A$2:H$48,8,FALSE) -> 0 | J13: =VLOOKUP(B13,'Education updated'!A$2:K$48,11,FALSE) -> 0 | K13: =VLOOKUP(B13,'Education updated'!A$2:L$48,12,FALSE) -> 0 | L13: 366 | M13: =SUM(C13:L13) -> 479
A14: Guinea-Bissau | B14: =VLOOKUP(A14,CountryCodes!A$2:C$195,3,FALSE) -> GNB | C14: =VLOOKUP(B14,'Education updated'!A$2:C$48,3,FALSE) -> 0 | D14: =VLOOKUP(B14,'Education updated'!A$2:J$48,10,FALSE) -> 0 | E14: =VLOOKUP(B14,'Education updated'!A$2:I$48,9,FALSE) -> 0 | F14: =VLOOKUP(B14,'Education updated'!A$2:E$48,5,FALSE) -> 0 | G14: =VLOOKUP(B14,'Education updated'!A$2:F$48,6,FALSE) -> 0 | H14: =VLOOKUP(B14,'Education updated'!A$2:G$48,7,FALSE) -> 0 | I14: =VLOOKUP(B14,'Education updated'!A$2:H$48,8,FALSE) -> 0 | J14: =VLOOKUP(B14,'Education updated'!A$2:K$48,11,FALSE) -> 23 | K14: =VLOOKUP(B14,'Education updated'!A$2:L$48,12,FALSE) -> 0 | L14: 489 | M14: =SUM(C14:L14) -> 512
A15: Lesotho | B15: =VLOOKUP(A15,CountryCodes!A$2:C$195,3,FALSE) -> LSO | C15: =VLOOKUP(B15,'Education updated'!A$2:C$48,3,FALSE) -> 8 | D15: =VLOOKUP(B15,'Education updated'!A$2:J$48,10,FALSE) -> 376 | E15: =VLOOKUP(B15,'Education updated'!A$2:I$48,9,FALSE) -> 69 | F15: =VLOOKUP(B15,'Education updated'!A$2:E$48,5,FALSE) -> 8 | G15: =VLOOKUP(B15,'Education updated'!A$2:F$48,6,FALSE) -> 0 | H15: =VLOOKUP(B15,'Education updated'!A$2:G$48,7,FALSE) -> 33 | I15: =VLOOKUP(B15,'Education updated'!A$2:H$48,8,FALSE) -> 20 | J15: =VLOOKUP(B15,'Education updated'!A$2:K$48,11,FALSE) -> 20 | K15: =VLOOKUP(B15,'Education updated'!A$2:L$48,12,FALSE) -> 0 | M15: =SUM(C15:L15) -> 534
A16: Mauritius | B16: =VLOOKUP(A16,CountryCodes!A$2:C$195,3,FALSE) -> MUS | C16: =VLOOKUP(B16,'Education updated'!A$2:C$48,3,FALSE) -> 432 | D16: =VLOOKUP(B16,'Education updated'!A$2:J$48,10,FALSE) -> 175 | E16: =VLOOKUP(B16,'Education updated'!A$2:I$48,9,FALSE) -> 40 | F16: =VLOOKUP(B16,'Education updated'!A$2:E$48,5,FALSE) -> 0 | G16: =VLOOKUP(B16,'Education updated'!A$2:F$48,6,FALSE) -> 0 | H16: =VLOOKUP(B16,'Education updated'!A$2:G$48,7,FALSE) -> 0 | I16: =VLOOKUP(B16,'Education updated'!A$2:H$48,8,FALSE) -> 0 | J16: =VLOOKUP(B16,'Education updated'!A$2:K$48,11,FALSE) -> 0 | K16: =VLOOKUP(B16,'Education updated'!A$2:L$48,12,FALSE) -> 0 | L16: 39 | M16: =SUM(C16:L16) -> 686
A17: Congo | B17: =VLOOKUP(A17,CountryCodes!A$2:C$195,3,FALSE) -> COG | C17: =VLOOKUP(B17,'Education updated'!A$2:C$48,3,FALSE) -> 60 | D17: =VLOOKUP(B17,'Education updated'!A$2:J$48,10,FALSE) -> 60 | E17: =VLOOKUP(B17,'Education updated'!A$2:I$48,9,FALSE) -> 120 | F17: =VLOOKUP(B17,'Education updated'!A$2:E$48,5,FALSE) -> 0 | G17: =VLOOKUP(B17,'Education updated'!A$2:F$48,6,FALSE) -> 10 | H17: =VLOOKUP(B17,'Education updated'!A$2:G$48,7,FALSE) -> 0 | I17: =VLOOKUP(B17,'Education updated'!A$2:H$48,8,FALSE) -> 5 | J17: =VLOOKUP(B17,'Education updated'!A$2:K$48,11,FALSE) -> 0 | K17: =VLOOKUP(B17,'Education updated'!A$2:L$48,12,FALSE) -> 50 | L17: 408 | M17: =SUM(C17:L17) -> 713
A18: Rwanda | B18: =VLOOKUP(A18,CountryCodes!A$2:C$195,3,FALSE) -> RWA | C18: =VLOOKUP(B18,'Education updated'!A$2:C$48,3,FALSE) -> 11 | D18: =VLOOKUP(B18,'Education updated'!A$2:J$48,10,FALSE) -> 355 | E18: =VLOOKUP(B18,'Education updated'!A$2:I$48,9,FALSE) -> 176 | F18: =VLOOKUP(B18,'Education updated'!A$2:E$48,5,FALSE) -> 0 | G18: =VLOOKUP(B18,'Education updated'!A$2:F$48,6,FALSE) -> 0 | H18: =VLOOKUP(B18,'Education updated'!A$2:G$48,7,FALSE) -> 95 | I18: =VLOOKUP(B18,'Education updated'!A$2:H$48,8,FALSE) -> 0 | J18: =VLOOKUP(B18,'Education updated'!A$2:K$48,11,FALSE) -> 0 | K18: =VLOOKUP(B18,'Education updated'!A$2:L$48,12,FALSE) -> 0 | L18: 81 | M18: =SUM(C18:L18) -> 718
A19: Togo | B19: =VLOOKUP(A19,CountryCodes!A$2:C$195,3,FALSE) -> TGO | C19: =VLOOKUP(B19,'Education updated'!A$2:C$48,3,FALSE) -> 77 | D19: =VLOOKUP(B19,'Education updated'!A$2:J$48,10,FALSE) -> 240 | E19: =VLOOKUP(B19,'Education updated'!A$2:I$48,9,FALSE) -> 130 | F19: =VLOOKUP(B19,'Education updated'!A$2:E$48,5,FALSE) -> 0 | G19: =VLOOKUP(B19,'Education updated'!A$2:F$48,6,FALSE) -> 0 | H19: =VLOOKUP(B19,'Education updated'!A$2:G$48,7,FALSE) -> 60 | I19: =VLOOKUP(B19,'Education updated'!A$2:H$48,8,FALSE) -> 0 | J19: =VLOOKUP(B19,'Education updated'!A$2:K$48,11,FALSE) -> 215 | K19: =VLOOKUP(B19,'Education updated'!A$2:L$48,12,FALSE) -> 0 | L19: 250 | M19: =SUM(C19:L19) -> 972
A20: Eritrea | B20: =VLOOKUP(A20,CountryCodes!A$2:C$195,3,FALSE) -> ERI | C20: =VLOOKUP(B20,'Education updated'!A$2:C$48,3,FALSE) -> 0 | D20: =VLOOKUP(B20,'Education updated'!A$2:J$48,10,FALSE) -> 400 | E20: =VLOOKUP(B20,'Education updated'!A$2:I$48,9,FALSE) -> 0 | F20: =VLOOKUP(B20,'Education updated'!A$2:E$48,5,FALSE) -> 0 | G20: =VLOOKUP(B20,'Education updated'!A$2:F$48,6,FALSE) -> 0 | H20: =VLOOKUP(B20,'Education updated'!A$2:G$48,7,FALSE) -> 0 | I20: =VLOOKUP(B20,'Education updated'!A$2:H$48,8,FALSE) -> 0 | J20: =VLOOKUP(B20,'Education updated'!A$2:K$48,11,FALSE) -> 0 | K20: =VLOOKUP(B20,'Education updated'!A$2:L$48,12,FALSE) -> 0 | L20: 1023 | M20: =SUM(C20:L20) -> 1423
A21: Botswana | B21: =VLOOKUP(A21,CountryCodes!A$2:C$195,3,FALSE) -> BWA | C21: =VLOOKUP(B21,'Education updated'!A$2:C$48,3,FALSE) -> 60 | D21: =VLOOKUP(B21,'Education updated'!A$2:J$48,10,FALSE) -> 490 | E21: =VLOOKUP(B21,'Education updated'!A$2:I$48,9,FALSE) -> 40 | F21: =VLOOKUP(B21,'Education updated'!A$2:E$48,5,FALSE) -> 7 | G21: =VLOOKUP(B21,'Education updated'!A$2:F$48,6,FALSE) -> 10 | H21: =VLOOKUP(B21,'Education updated'!A$2:G$48,7,FALSE) -> 95 | I21: =VLOOKUP(B21,'Education updated'!A$2:H$48,8,FALSE) -> 60 | J21: =VLOOKUP(B21,'Education updated'!A$2:K$48,11,FALSE) -> 189 | K21: =VLOOKUP(B21,'Education updated'!A$2:L$48,12,FALSE) -> 30 | L21: 597 | M21: =SUM(C21:L21) -> 1578
A22: South Sudan | B22: =VLOOKUP(A22,CountryCodes!A$2:C$195,3,FALSE) -> SSD | C22: =VLOOKUP(B22,'Education updated'!A$2:C$48,3,FALSE) -> 0 | D22: =VLOOKUP(B22,'Education updated'!A$2:J$48,10,FALSE) -> 241 | E22: =VLOOKUP(B22,'Education updated'!A$2:I$48,9,FALSE) -> 307 | F22: =VLOOKUP(B22,'Education updated'!A$2:E$48,5,FALSE) -> 0 | G22: =VLOOKUP(B22,'Education updated'!A$2:F$48,6,FALSE) -> 0 | H22: =VLOOKUP(B22,'Education updated'!A$2:G$48,7,FALSE) -> 0 | I22: =VLOOKUP(B22,'Education updated'!A$2:H$48,8,FALSE) -> 0 | J22: =VLOOKUP(B22,'Education updated'!A$2:K$48,11,FALSE) -> 681 | K22: =VLOOKUP(B22,'Education updated'!A$2:L$48,12,FALSE) -> 0 | L22: 484 | M22: =SUM(C22:L22) -> 1713
A23: Mozambique | B23: =VLOOKUP(A23,CountryCodes!A$2:C$195,3,FALSE) -> MOZ | C23: =VLOOKUP(B23,'Education updated'!A$2:C$48,3,FALSE) -> 819 | D23: =VLOOKUP(B23,'Education updated'!A$2:J$48,10,FALSE) -> 580 | E23: =VLOOKUP(B23,'Education updated'!A$2:I$48,9,FALSE) -> 140 | F23: =VLOOKUP(B23,'Education updated'!A$2:E$48,5,FALSE) -> 161 | G23: =VLOOKUP(B23,'Education updated'!A$2:F$48,6,FALSE) -> 0 | H23: =VLOOKUP(B23,'Education updated'!A$2:G$48,7,FALSE) -> 0 | I23: =VLOOKUP(B23,'Education updated'!A$2:H$48,8,FALSE) -> 112 | J23: =VLOOKUP(B23,'Education updated'!A$2:K$48,11,FALSE) -> 248 | K23: =VLOOKUP(B23,'Education updated'!A$2:L$48,12,FALSE) -> 20 | M23: =SUM(C23:L23) -> 2080
A24: Senegal | B24: =VLOOKUP(A24,CountryCodes!A$2:C$195,3,FALSE) -> SEN | C24: =VLOOKUP(B24,'Education updated'!A$2:C$48,3,FALSE) -> 434 | D24: =VLOOKUP(B24,'Education updated'!A$2:J$48,10,FALSE) -> 582 | E24: =VLOOKUP(B24,'Education updated'!A$2:I$48,9,FALSE) -> 104 | F24: =VLOOKUP(B24,'Education updated'!A$2:E$48,5,FALSE) -> 67 | G24: =VLOOKUP(B24,'Education updated'!A$2:F$48,6,FALSE) -> 0 | H24: =VLOOKUP(B24,'Education updated'!A$2:G$48,7,FALSE) -> 171 | I24: =VLOOKUP(B24,'Education updated'!A$2:H$48,8,FALSE) -> 0 | J24: =VLOOKUP(B24,'Education updated'!A$2:K$48,11,FALSE) -> 36 | K24: =VLOOKUP(B24,'Education updated'!A$2:L$48,12,FALSE) -> 0 | L24: 710 | M24: =SUM(C24:L24) -> 2104
A25: Sierra Leone | B25: =VLOOKUP(A25,CountryCodes!A$2:C$195,3,FALSE) -> SLE | C25: =VLOOKUP(B25,'Education updated'!A$2:C$48,3,FALSE) -> 217 | D25: =VLOOKUP(B25,'Education updated'!A$2:J$48,10,FALSE) -> 1755 | E25: =VLOOKUP(B25,'Education updated'!A$2:I$48,9,FALSE) -> 120 | F25: =VLOOKUP(B25,'Education updated'!A$2:E$48,5,FALSE) -> 0 | G25: =VLOOKUP(B25,'Education updated'!A$2:F$48,6,FALSE) -> 0 | H25: =VLOOKUP(B25,'Education updated'!A$2:G$48,7,FALSE) -> 69 | I25: =VLOOKUP(B25,'Education updated'!A$2:H$48,8,FALSE) -> 51 | J25: =VLOOKUP(B25,'Education updated'!A$2:K$48,11,FALSE) -> 90 | K25: =VLOOKUP(B25,'Education updated'!A$2:L$48,12,FALSE) -> 0 | L25: 186 | M25: =SUM(C25:L25) -> 2488
A26: Burundi | B26: =VLOOKUP(A26,CountryCodes!A$2:C$195,3,FALSE) -> BDI | C26: =VLOOKUP(B26,'Education updated'!A$2:C$48,3,FALSE) -> 325 | D26: =VLOOKUP(B26,'Education updated'!A$2:J$48,10,FALSE) -> 1467 | E26: =VLOOKUP(B26,'Education updated'!A$2:I$48,9,FALSE) -> 196 | F26: =VLOOKUP(B26,'Education updated'!A$2:E$48,5,FALSE) -> 0 | G26: =VLOOKUP(B26,'Education updated'!A$2:F$48,6,FALSE) -> 0 | H26: =VLOOKUP(B26,'Education updated'!A$2:G$48,7,FALSE) -> 39 | I26: =VLOOKUP(B26,'Education updated'!A$2:H$48,8,FALSE) -> 0 | J26: =VLOOKUP(B26,'Education updated'!A$2:K$48,11,FALSE) -> 322 | K26: =VLOOKUP(B26,'Education updated'!A$2:L$48,12,FALSE) -> 0 | L26: 194 | M26: =SUM(C26:L26) -> 2543
A27: Namibia | B27: =VLOOKUP(A27,CountryCodes!A$2:C$195,3,FALSE) -> NAM | C27: =VLOOKUP(B27,'Education updated'!A$2:C$48,3,FALSE) -> 475 | D27: =VLOOKUP(B27,'Education updated'!A$2:J$48,10,FALSE) -> 200 | E27: =VLOOKUP(B27,'Education updated'!A$2:I$48,9,FALSE) -> 1414 | F27: =VLOOKUP(B27,'Education updated'!A$2:E$48,5,FALSE) -> 0 | G27: =VLOOKUP(B27,'Education updated'!A$2:F$48,6,FALSE) -> 0 | H27: =VLOOKUP(B27,'Education updated'!A$2:G$48,7,FALSE) -> 247 | I27: =VLOOKUP(B27,'Education updated'!A$2:H$48,8,FALSE) -> 31 | J27: =VLOOKUP(B27,'Education updated'!A$2:K$48,11,FALSE) -> 121 | K27: =VLOOKUP(B27,'Education updated'!A$2:L$48,12,FALSE) -> 0 | L27: 175 | M27: =SUM(C27:L27) -> 2663
A28: Zimbabwe | B28: =VLOOKUP(A28,CountryCodes!A$2:C$195,3,FALSE) -> ZWE | C28: =VLOOKUP(B28,'Education updated'!A$2:C$48,3,FALSE) -> 265 | D28: =VLOOKUP(B28,'Education updated'!A$2:J$48,10,FALSE) -> 1100 | E28: =VLOOKUP(B28,'Education updated'!A$2:I$48,9,FALSE) -> 270 | F28: =VLOOKUP(B28,'Education updated'!A$2:E$48,5,FALSE) -> 80 | G28: =VLOOKUP(B28,'Education updated'!A$2:F$48,6,FALSE) -> 30 | H28: =VLOOKUP(B28,'Education updated'!A$2:G$48,7,FALSE) -> 155 | I28: =VLOOKUP(B28,'Education updated'!A$2:H$48,8,FALSE) -> 30 | J28: =VLOOKUP(B28,'Education updated'!A$2:K$48,11,FALSE) -> 358 | K28: =VLOOKUP(B28,'Education updated'!A$2:L$48,12,FALSE) -> 0 | L28: 421 | M28: =SUM(C28:L28) -> 2709
A29: Niger | B29: =VLOOKUP(A29,CountryCodes!A$2:C$195,3,FALSE) -> NER | C29: =VLOOKUP(B29,'Education updated'!A$2:C$48,3,FALSE) -> 370 | D29: =VLOOKUP(B29,'Education updated'!A$2:J$48,10,FALSE) -> 305 | E29: =VLOOKUP(B29,'Education updated'!A$2:I$48,9,FALSE) -> 124 | F29: =VLOOKUP(B29,'Education updated'!A$2:E$48,5,FALSE) -> 0 | G29: =VLOOKUP(B29,'Education updated'!A$2:F$48,6,FALSE) -> 0 | H29: =VLOOKUP(B29,'Education updated'!A$2:G$48,7,FALSE) -> 0 | I29: =VLOOKUP(B29,'Education updated'!A$2:H$48,8,FALSE) -> 0 | J29: =VLOOKUP(B29,'Education updated'!A$2:K$48,11,FALSE) -> 45 | K29: =VLOOKUP(B29,'Education updated'!A$2:L$48,12,FALSE) -> 0 | L29: 1891 | M29: =SUM(C29:L29) -> 2735
A30: Malawi | B30: =VLOOKUP(A30,CountryCodes!A$2:C$195,3,FALSE) -> MWI | C30: =VLOOKUP(B30,'Education updated'!A$2:C$48,3,FALSE) -> 115 | D30: =VLOOKUP(B30,'Education updated'!A$2:J$48,10,FALSE) -> 386 | E30: =VLOOKUP(B30,'Education updated'!A$2:I$48,9,FALSE) -> 1171 | F30: =VLOOKUP(B30,'Education updated'!A$2:E$48,5,FALSE) -> 0 | G30: =VLOOKUP(B30,'Education updated'!A$2:F$48,6,FALSE) -> 0 | H30: =VLOOKUP(B30,'Education updated'!A$2:G$48,7,FALSE) -> 110 | I30: =VLOOKUP(B30,'Education updated'!A$2:H$48,8,FALSE) -> 189 | J30: =VLOOKUP(B30,'Education updated'!A$2:K$48,11,FALSE) -> 175 | K30: =VLOOKUP(B30,'Education updated'!A$2:L$48,12,FALSE) -> 0 | L30: 616 | M30: =SUM(C30:L30) -> 2762
A31: Kenya | B31: =VLOOKUP(A31,CountryCodes!A$2:C$195,3,FALSE) -> KEN | C31: =VLOOKUP(B31,'Education updated'!A$2:C$48,3,FALSE) -> 558 | D31: =VLOOKUP(B31,'Education updated'!A$2:J$48,10,FALSE) -> 1070 | E31: =VLOOKUP(B31,'Education updated'!A$2:I$48,9,FALSE) -> 0 | F31: =VLOOKUP(B31,'Education updated'!A$2:E$48,5,FALSE) -> 36 | G31: =VLOOKUP(B31,'Education updated'!A$2:F$48,6,FALSE) -> 0 | H31: =VLOOKUP(B31,'Education updated'!A$2:G$48,7,FALSE) -> 379 | I31: =VLOOKUP(B31,'Education updated'!A$2:H$48,8,FALSE) -> 20 | J31: =VLOOKUP(B31,'Education updated'!A$2:K$48,11,FALSE) -> 519 | K31: =VLOOKUP(B31,'Education updated'!A$2:L$48,12,FALSE) -> 0 | L31: 366 | M31: =SUM(C31:L31) -> 2948
A32: Cote d'Ivoire | B32: =VLOOKUP(A32,CountryCodes!A$2:C$195,3,FALSE) -> CIV | C32: =VLOOKUP(B32,'Education updated'!A$2:C$48,3,FALSE) -> 254 | D32: =VLOOKUP(B32,'Education updated'!A$2:J$48,10,FALSE) -> 1007 | E32: =VLOOKUP(B32,'Education updated'!A$2:I$48,9,FALSE) -> 0 | F32: =VLOOKUP(B32,'Education updated'!A$2:E$48,5,FALSE) -> 0 | G32: =VLOOKUP(B32,'Education updated'!A$2:F$48,6,FALSE) -> 0 | H32: =VLOOKUP(B32,'Education updated'!A$2:G$48,7,FALSE) -> 0 | I32: =VLOOKUP(B32,'Education updated'!A$2:H$48,8,FALSE) -> 151 | J32: =VLOOKUP(B32,'Education updated'!A$2:K$48,11,FALSE) -> 1106 | K32: =VLOOKUP(B32,'Education updated'!A$2:L$48,12,FALSE) -> 0 | L32: 450 | M32: =SUM(C32:L32) -> 2968
A33: Equatorial Guinea | B33: =VLOOKUP(A33,CountryCodes!A$2:C$195,3,FALSE) -> GNQ | C33: =VLOOKUP(B33,'Education updated'!A$2:C$48,3,FALSE) -> 767 | D33: =VLOOKUP(B33,'Education updated'!A$2:J$48,10,FALSE) -> 962 | E33: =VLOOKUP(B33,'Education updated'!A$2:I$48,9,FALSE) -> 492 | F33: =VLOOKUP(B33,'Education updated'!A$2:E$48,5,FALSE) -> 0 | G33: =VLOOKUP(B33,'Education updated'!A$2:F$48,6,FALSE) -> 0 | H33: =VLOOKUP(B33,'Education updated'!A$2:G$48,7,FALSE) -> 0 | I33: =VLOOKUP(B33,'Education updated'!A$2:H$48,8,FALSE) -> 0 | J33: =VLOOKUP(B33,'Education updated'!A$2:K$48,11,FALSE) -> 27 | K33: =VLOOKUP(B33,'Education updated'!A$2:L$48,12,FALSE) -> 0 | L33: 1304 | M33: =SUM(C33:L33) -> 3552
A34: Guinea | B34: =VLOOKUP(A34,CountryCodes!A$2:C$195,3,FALSE) -> GIN | C34: =VLOOKUP(B34,'Education updated'!A$2:C$48,3,FALSE) -> 767 | D34: =VLOOKUP(B34,'Education updated'!A$2:J$48,10,FALSE) -> 964 | E34: =VLOOKUP(B34,'Education updated'!A$2:I$48,9,FALSE) -> 492 | F34: =VLOOKUP(B34,'Education updated'!A$2:E$48,5,FALSE) -> 0 | G34: =VLOOKUP(B34,'Education updated'!A$2:F$48,6,FALSE) -> 0 | H34: =VLOOKUP(B34,'Education updated'!A$2:G$48,7,FALSE) -> 113 | I34: =VLOOKUP(B34,'Education updated'!A$2:H$48,8,FALSE) -> 34 | J34: =VLOOKUP(B34,'Education updated'!A$2:K$48,11,FALSE) -> 27 | K34: =VLOOKUP(B34,'Education updated'!A$2:L$48,12,FALSE) -> 0 | L34: 1304 | M34: =SUM(C34:L34) -> 3701
A35: Benin | B35: =VLOOKUP(A35,CountryCodes!A$2:C$195,3,FALSE) -> BEN | C35: =VLOOKUP(B35,'Education updated'!A$2:C$48,3,FALSE) -> 780 | D35: =VLOOKUP(B35,'Education updated'!A$2:J$48,10,FALSE) -> 257 | E35: =VLOOKUP(B35,'Education updated'!A$2:I$48,9,FALSE) -> 247 | F35: =VLOOKUP(B35,'Education updated'!A$2:E$48,5,FALSE) -> 0 | G35: =VLOOKUP(B35,'Education updated'!A$2:F$48,6,FALSE) -> 0 | H35: =VLOOKUP(B35,'Education updated'!A$2:G$48,7,FALSE) -> 143 | I35: =VLOOKUP(B35,'Education updated'!A$2:H$48,8,FALSE) -> 0 | J35: =VLOOKUP(B35,'Education updated'!A$2:K$48,11,FALSE) -> 1113 | K35: =VLOOKUP(B35,'Education updated'!A$2:L$48,12,FALSE) -> 0 | L35: 1194 | M35: =SUM(C35:L35) -> 3734
A36: Angola | B36: =VLOOKUP(A36,CountryCodes!A$2:C$195,3,FALSE) -> AGO | C36: =VLOOKUP(B36,'Education updated'!A$2:C$48,3,FALSE) -> 611 | D36: =VLOOKUP(B36,'Education updated'!A$2:J$48,10,FALSE) -> 2950 | E36: =VLOOKUP(B36,'Education updated'!A$2:I$48,9,FALSE) -> 0 | F36: =VLOOKUP(B36,'Education updated'!A$2:E$48,5,FALSE) -> 145 | G36: =VLOOKUP(B36,'Education updated'!A$2:F$48,6,FALSE) -> 0 | H36: =VLOOKUP(B36,'Education updated'!A$2:G$48,7,FALSE) -> 529 | I36: =VLOOKUP(B36,'Education updated'!A$2:H$48,8,FALSE) -> 0 | J36: =VLOOKUP(B36,'Education updated'!A$2:K$48,11,FALSE) -> 0 | K36: =VLOOKUP(B36,'Education updated'!A$2:L$48,12,FALSE) -> 0 | M36: =SUM(C36:L36) -> 4235
A37: Cameroon | B37: =VLOOKUP(A37,CountryCodes!A$2:C$195,3,FALSE) -> CMR | C37: =VLOOKUP(B37,'Education updated'!A$2:C$48,3,FALSE) -> 800 | D37: =VLOOKUP(B37,'Education updated'!A$2:J$48,10,FALSE) -> 2660 | E37: =VLOOKUP(B37,'Education updated'!A$2:I$48,9,FALSE) -> 0 | F37: =VLOOKUP(B37,'Education updated'!A$2:E$48,5,FALSE) -> 0 | G37: =VLOOKUP(B37,'Education updated'!A$2:F$48,6,FALSE) -> 0 | H37: =VLOOKUP(B37,'Education updated'!A$2:G$48,7,FALSE) -> 0 | I37: =VLOOKUP(B37,'Education updated'!A$2:H$48,8,FALSE) -> 0 | J37: =VLOOKUP(B37,'Education updated'!A$2:K$48,11,FALSE) -> 800 | K37: =VLOOKUP(B37,'Education updated'!A$2:L$48,12,FALSE) -> 0 | M37: =SUM(C37:L37) -> 4260
A38: Burkina Faso | B38: =VLOOKUP(A38,CountryCodes!A$2:C$195,3,FALSE) -> BFA | C38: =VLOOKUP(B38,'Education updated'!A$2:C$48,3,FALSE) -> 1492 | D38: =VLOOKUP(B38,'Education updated'!A$2:J$48,10,FALSE) -> 1170 | E38: =VLOOKUP(B38,'Education updated'!A$2:I$48,9,FALSE) -> 1170 | F38: =VLOOKUP(B38,'Education updated'!A$2:E$48,5,FALSE) -> 62 | G38: =VLOOKUP(B38,'Education updated'!A$2:F$48,6,FALSE) -> 0 | H38: =VLOOKUP(B38,'Education updated'!A$2:G$48,7,FALSE) -> 594 | I38: =VLOOKUP(B38,'Education updated'!A$2:H$48,8,FALSE) -> 0 | J38: =VLOOKUP(B38,'Education updated'!A$2:K$48,11,FALSE) -> 0 | K38: =VLOOKUP(B38,'Education updated'!A$2:L$48,12,FALSE) -> 0 | M38: =SUM(C38:L38) -> 4488
A39: Madagascar | B39: =VLOOKUP(A39,CountryCodes!A$2:C$195,3,FALSE) -> MDG | C39: =VLOOKUP(B39,'Education updated'!A$2:C$48,3,FALSE) -> 316 | D39: =VLOOKUP(B39,'Education updated'!A$2:J$48,10,FALSE) -> 2540 | E39: =VLOOKUP(B39,'Education updated'!A$2:I$48,9,FALSE) -> 2473 | F39: =VLOOKUP(B39,'Education updated'!A$2:E$48,5,FALSE) -> 0 | G39: =VLOOKUP(B39,'Education updated'!A$2:F$48,6,FALSE) -> 0 | H39: =VLOOKUP(B39,'Education updated'!A$2:G$48,7,FALSE) -> 0 | I39: =VLOOKUP(B39,'Education updated'!A$2:H$48,8,FALSE) -> 0 | J39: =VLOOKUP(B39,'Education updated'!A$2:K$48,11,FALSE) -> 116 | K39: =VLOOKUP(B39,'Education updated'!A$2:L$48,12,FALSE) -> 0 | L39: 297 | M39: =SUM(C39:L39) -> 5742
A40: Chad | B40: =VLOOKUP(A40,CountryCodes!A$2:C$195,3,FALSE) -> TCD | C40: =VLOOKUP(B40,'Education updated'!A$2:C$48,3,FALSE) -> 330 | D40: =VLOOKUP(B40,'Education updated'!A$2:J$48,10,FALSE) -> 2920 | E40: =VLOOKUP(B40,'Education updated'!A$2:I$48,9,FALSE) -> 2084 | F40: =VLOOKUP(B40,'Education updated'!A$2:E$48,5,FALSE) -> 0 | G40: =VLOOKUP(B40,'Education updated'!A$2:F$48,6,FALSE) -> 0 | H40: =VLOOKUP(B40,'Education updated'!A$2:G$48,7,FALSE) -> 80 | I40: =VLOOKUP(B40,'Education updated'!A$2:H$48,8,FALSE) -> 180 | J40: =VLOOKUP(B40,'Education updated'!A$2:K$48,11,FALSE) -> 220 | K40: =VLOOKUP(B40,'Education updated'!A$2:L$48,12,FALSE) -> 0 | M40: =SUM(C40:L40) -> 5814
...

Sheet summary
B1: iso | C1: Generalist Medical Practitioners | D1: Nursing Personnel | E1: Midwifery personnel | F1: Dentists | G1: Other Dental practitioners | H1: Pharmacists | I1: Other Pharmacy practitioners | J1: Medical and Pathology Laboratory scientists | K1: Paramedical Practitioners | L1: Other Health Workers | M1: Total
B2: DZA
B3: AGO
B4: BEN
B5: BWA
B6: BFA
B7: BDI
B8: CMR
B9: CPV
B10: CAF
B11: TCD
B12: COM
B13: COG
... B48: ZWE
B49: #N/A

Sheet CountryCodes
A1: Country | B1: ISO2 | C1: ISO3 | D1: Reg | E1: WBI | F1: Notes | G1: unsd
A2: Algeria | B2: DZ | C2: DZA | D2: AFR | E2: LMI | F2: NULL | G2: 12
A3: Angola | B3: AO | C3: AGO | D3: AFR | E3: LMI | F3: NULL | G3: 24
A4: Benin | B4: BJ | C4: BEN | D4: AFR | E4: LIN | F4: NULL | G4: 204
A5: Botswana | B5: BW | C5: BWA | D5: AFR | E5: UMI | F5: NULL | G5: 72
A6: Burkina Faso | B6: BF | C6: BFA | D6: AFR | E6: LIN | F6: NULL | G6: 854
A7: Burundi | B7: BI | C7: BDI | D7: AFR | E7: LIN | F7: NULL | G7: 108
A8: Cameroon | B8: CM | C8: CMR | D8: AFR | E8: LIN | F8: NULL | G8: 120
A9: Cape Verde | B9: CV | C9: CPV | D9: AFR | E9: LMI | F9: NULL | G9: 132
A10: Central African Republic | B10: CF | C10: CAF | D10: AFR | E10: LIN | F10: NULL | G10: 140
A11: Chad | B11: TD | C11: TCD | D11: AFR | E11: LIN | F11: NULL | G11: 148
A12: Comoros | B12: KM | C12: COM | D12: AFR | E12: LIN | F12: NULL | G12: 174
A13: Congo | B13: CG | C13: COG | D13: AFR | E13: LIN | F13: NULL | G13: 178
... A195: Viet Nam | B195: VN | C195: VNM | D195: WPR | E195: LIN | F195: NULL | G195: 704
