Workbook
Name Country: #REF!

Sheet Female in leadership
A1: Country | C1: ISCO | D1: Occupation | E1: Percentage share
A2: Algeria | C2: 2211 | D2: Generalist medical practitioners
A3: Algeria | C3: 2212 | D3: Total of all Specialist medical practitioners
A4: Algeria | D4: Surgeon
A5: Algeria | D5: Pediatrician
A6: Algeria | D6: Family medicine
A7: Algeria | D7: Obstetrician & Gynecologist
A8: Algeria | D8: Internal medicine
A9: Algeria | C9: 2221 | D9: Nursing professionals
A10: Algeria | D10: Nurse, professional: paediatric
A11: Algeria | D11: Nurse, anaesthetics
A12: Algeria | D12: Nurse, operating theatre
A13: Algeria | C13: 3221 | D13: Nursing associate professionals
A14: Algeria | C14: 2222 | D14: Midwifery professionals
A15: Algeria | C15: 3222 | D15: Midwifery associate professionals
A16: Algeria | C16: 2240 | D16: Paramedical practitioners (specify)
A17: Algeria | C17: 2261 | D17: Dentists
A18: Algeria | C18: 3251 | D18: Dental assistants and therapists
A19: Algeria | C19: 2262 | D19: Pharmacists
A20: Algeria | C20: 3213 | D20: Pharmaceutical technicians and assistants
A21: Algeria | C21: 2263, 3257 | D21: Environmental and occupational health & hygiene workers
A22: Algeria | C22: 2264 | D22: Physiotherapists
A23: Algeria | C23: 3255 | D23: Physiotherapy assistants
A24: Algeria | C24: 2267 | D24: Optometrists
A25: Algeria | C25: 3254 | D25: Opticians
A26: Algeria | D26: Field Epidemiologist
A27: Algeria | C27: 3211 | D27: Medical imaging and therapeutic equipment operators
A28: Algeria | C28: 3212 | D28: Medical and pathology laboratory technicians
A29: Algeria | C29: 3214 | D29: Medical and dental prosthetic technicians
A30: Algeria | C30: 3253 | D30: Community health workers
A31: Algeria | C31: 3256 | D31: Medical assistants, clinical officers and physician Assistants
A32: Algeria | C32: 2230, 3230 | D32: Traditional and complementary medicine practitioners
A33: Algeria | C33: 2265 | D33: Dieticians and nutritionists
A34: Algeria | C34: 1342 | D34: Health service managers
A35: Algeria | C35: 3252 | D35: Medical records and health information technicians (including biostatisticians)
A36: Angola | C36: 2211 | D36: Generalist medical practitioners
A37: Angola | C37: 2212 | D37: Total of all Specialist medical practitioners
A38: Angola | D38: Surgeon
A39: Angola | D39: Pediatrician
A40: Angola | D40: Family medicine
...

Sheet Sheet3
B3: Column Labels
A4: Row Labels | B4: NO | C4: PARTLY | D4: YES | E4: (blank) | F4: Grand Total
A5: Algeria
A6: Angola
A7: Benin
A8: Botswana
A9: Burkina Faso
A10: Burundi
A11: Cabo Verde
A12: Cameroon
A13: Central African Republic
A14: Chad
A15: Comoros
A16: Congo
... A52: Grand Total

Sheet Sheet6
A1: Algeria | C1: Sub-indicator 1 | D1: Existence of national/subnational policies/laws regulating minimum wage (Yes/No)
A2: Algeria | C2: Sub-indicator 2 | D2: Existence of national/subnational policies/laws regulating social protection (Yes/No)
A3: Algeria | C3: Sub-indicator 3 | D3: Existence of national/subnational policies/laws regulating dual practice (Yes/No)
A4: Algeria | C4: Sub-indicator 4 | D4: Existence of national/subnational policies/laws regulating compulsory service (Yes/No)
A5: Angola | C5: Sub-indicator 1 | D5: Existence of national/subnational policies/laws regulating minimum wage (Yes/No) | E5: YES
A6: Angola | C6: Sub-indicator 2 | D6: Existence of national/subnational policies/laws regulating social protection (Yes/No) | E6: YES
A7: Angola | C7: Sub-indicator 3 | D7: Existence of national/subnational policies/laws regulating dual practice (Yes/No) | E7: NO
A8: Angola | C8: Sub-indicator 4 | D8: Existence of national/subnational policies/laws regulating compulsory service (Yes/No) | E8: YES
A9: Benin | C9: Sub-indicator 1 | D9: Existence of national/subnational policies/laws regulating minimum wage (Yes/No) | E9: YES
A10: Benin | C10: Sub-indicator 2 | D10: Existence of national/subnational policies/laws regulating social protection (Yes/No) | E10: YES
A11: Benin | C11: Sub-indicator 3 | D11: Existence of national/subnational policies/laws regulating dual practice (Yes/No) | E11: YES
A12: Benin | C12: Sub-indicator 4 | D12: Existence of national/subnational policies/laws regulating compulsory service (Yes/No) | E12: YES
A13: Botswana | C13: Sub-indicator 1 | D13: Existence of national/subnational policies/laws regulating minimum wage (Yes/No) | E13: YES
A14: Botswana | C14: Sub-indicator 2 | D14: Existence of national/subnational policies/laws regulating social protection (Yes/No) | E14: YES
A15: Botswana | C15: Sub-indicator 3 | D15: Existence of national/subnational policies/laws regulating dual practice (Yes/No) | E15: YES
A16: Botswana | C16: Sub-indicator 4 | D16: Existence of national/subnational policies/laws regulating compulsory service (Yes/No) | E16: YES
... A24: Burundi | C24: Sub-indicator 4 | D24: Existence of national/subnational policies/laws regulating compulsory service (Yes/No) | E24: NO
A25: Cabo verde | C25: Sub-indicator 1 | D25: Existence of national/subnational policies/laws regulating minimum wage (Yes/No)
A26: Cabo verde | C26: Sub-indicator 2 | D26: Existence of national/subnational policies/laws regulating social protection (Yes/No)
A27: Cabo verde | C27: Sub-indicator 3 | D27: Existence of national/subnational policies/laws regulating dual practice (Yes/No)
A28: Cabo verde | C28: Sub-indicator 4 | D28: Existence of national/subnational policies/laws regulating compulsory service (Yes/No)
A29: Cameroon | C29: Sub-indicator 1 | D29: Existence of national/subnational policies/laws regulating minimum wage (Yes/No) | E29: YES
A30: Cameroon | C30: Sub-indicator 2 | D30: Existence of national/subnational policies/laws regulating social protection (Yes/No) | E30: YES
A31: Cameroon | C31: Sub-indicator 3 | D31: Existence of national/subnational policies/laws regulating dual practice (Yes/No) | E31: YES
A32: Cameroon | C32: Sub-indicator 4 | D32: Existence of national/subnational policies/laws regulating compulsory service (Yes/No) | E32: YES
A33: Central African republic | C33: Sub-indicator 1 | D33: Existence of national/subnational policies/laws regulating minimum wage (Yes/No)
A34: Central African republic | C34: Sub-indicator 2 | D34: Existence of national/subnational policies/laws regulating social protection (Yes/No)
A35: Central African republic | C35: Sub-indicator 3 | D35: Existence of national/subnational policies/laws regulating dual practice (Yes/No)
A36: Central African republic | C36: Sub-indicator 4 | D36: Existence of national/subnational policies/laws regulating compulsory service (Yes/No)
A37: Chad | C37: Sub-indicator 1 | D37: Existence of national/subnational policies/laws regulating minimum wage (Yes/No) | E37: YES
A38: Chad | C38: Sub-indicator 2 | D38: Existence of national/subnational policies/laws regulating social protection (Yes/No) | E38: NO
A39: Chad | C39: Sub-indicator 3 | D39: Existence of national/subnational policies/laws regulating dual practice (Yes/No) | E39: YES
A40: Chad | C40: Sub-indicator 4 | D40: Existence of national/subnational policies/laws regulating compulsory service (Yes/No) | E40: YES
A41: Comoros | C41: Sub-indicator 1 | D41: Existence of national/subnational policies/laws regulating minimum wage (Yes/No) | E41: YES
A42: Comoros | C42: Sub-indicator 2 | D42: Existence of national/subnational policies/laws regulating social protection (Yes/No) | E42: YES
A43: Comoros | C43: Sub-indicator 3 | D43: Existence of national/subnational policies/laws regulating dual practice (Yes/No) | E43: YES
A44: Comoros | C44: Sub-indicator 4 | D44: Existence of national/subnational policies/laws regulating compulsory service (Yes/No) | E44: YES
A45: Congo | C45: Sub-indicator 1 | D45: Existence of national/subnational policies/laws regulating minimum wage (Yes/No) | E45: YES
A46: Congo | C46: Sub-indicator 2 | D46: Existence of national/subnational policies/laws regulating social protection (Yes/No) | E46: YES
A47: Congo | C47: Sub-indicator 3 | D47: Existence of national/subnational policies/laws regulating dual practice (Yes/No) | E47: YES
...

Sheet Sheet11
A1: Average tution fee
A2: Country | C2: ISCO | D2: Occupation | E2: Public | F2: Private | G2: Average
A3: Benin | C3: 2211 | D3: Generalist medical practitioners | E3: 415000
A4: Benin | C4: 2212 | D4: Total of all Specialist medical practitioners | E4: 750000
A5: Benin | D5: Surgeon
A6: Benin | D6: Pediatrician
A7: Benin | D7: Family medicine
A8: Benin | D8: Obstetrician & Gynecologist
A9: Benin | D9: Internal medicine
A10: Benin | C10: 2221 | D10: Nursing professionals | E10: 430000
A11: Benin | D11: Nurse, professional: paediatric | E11: 415000
A12: Benin | D12: Nurse, anaesthetics | E12: 415000
A13: Benin | D13: Nurse, operating theatre | E13: 415000
A14: Benin | C14: 3221 | D14: Nursing associate professionals | E14: 430000
A15: Benin | C15: 2222 | D15: Midwifery professionals | E15: 430000
A16: Benin | C16: 3222 | D16: Midwifery associate professionals | E16: 430000
A17: Benin | C17: 2240 | D17: Paramedical practitioners (specify) | E17: 415000
A18: Benin | C18: 2261 | D18: Dentists | E18: 400000
A19: Benin | C19: 3251 | D19: Dental assistants and therapists | E19: 415000
A20: Benin | C20: 2262 | D20: Pharmacists | E20: 415000
A21: Benin | C21: 3213 | D21: Pharmaceutical technicians and assistants | E21: 415000
A22: Benin | C22: 2263, 3257 | D22: Environmental and occupational health & hygiene workers | E22: 415000
A23: Benin | C23: 2264 | D23: Physiotherapists | E23: 415000
A24: Benin | C24: 3255 | D24: Physiotherapy assistants | E24: 415000
A25: Benin | C25: 2267 | D25: Optometrists
A26: Benin | C26: 3254 | D26: Opticians
A27: Benin | D27: Field Epidemiologist | E27: 480000
A28: Benin | C28: 3211 | D28: Medical imaging and therapeutic equipment operators | E28: 415000
A29: Benin | C29: 3212 | D29: Medical and pathology laboratory technicians | E29: 415000
A30: Benin | C30: 3214 | D30: Medical and dental prosthetic technicians | E30: 415000
A31: Benin | C31: 3253 | D31: Community health workers
A32: Benin | C32: 3256 | D32: Medical assistants, clinical officers and physician Assistants
A33: Benin | C33: 2230, 3230 | D33: Traditional and complementary medicine practitioners
A34: Benin | C34: 2265 | D34: Dieticians and nutritionists | E34: 415000
A35: Benin | C35: 1342 | D35: Health service managers | E35: 415000
A36: Benin | C36: 3252 | D36: Medical records and health information technicians (including biostatisticians)
A37: Botswana | C37: 2211 | D37: Generalist medical practitioners | E37: 78,735.00
A38: Botswana | C38: 2212 | D38: Total of all Specialist medical practitioners
A39: Botswana | D39: Surgeon | E39: 36,480.00
A40: Botswana | D40: Pediatrician | E40: 36,480.00
...

Sheet Accreditation
A1: Name of Country | B1: Code ISO 08 | C1: Occupation | D1: Existence of national and/or subnational mechanisms for accreditation of health workforce education and training institutions and their programmes (Yes/No/Partly)
A2: Algeria | B2: 1342 | C2: Health service managers
A3: Algeria | B3: 1342 | C3: Health service managers
A4: Algeria | B4: 1342 | C4: Health service managers | D4: YES
A5: Algeria | B5: 1342 | C5: Health service managers | D5: YES
A6: Algeria | B6: 1342 | C6: Health service managers | D6: YES
A7: Algeria | B7: 1342 | C7: Health service managers
A8: Algeria | B8: 1342 | C8: Health service managers
A9: Algeria | B9: 1342 | C9: Health service managers | D9: YES
A10: Algeria | B10: 1342 | C10: Health service managers
A11: Algeria | B11: 1342 | C11: Health service managers | D11: YES
A12: Algeria | B12: 1342 | C12: Health service managers
A13: Algeria | B13: 1342 | C13: Cadres de direction, services de santé | D13: YES
A14: Algeria | B14: 1342 | C14: Health service managers
A15: Algeria | B15: 1342 | C15: Health service managers
A16: Algeria | B16: 1342 | C16: Health service managers
A17: Algeria | B17: 1342 | C17: Health service managers | D17: PARTLY
A18: Algeria | B18: 1342 | C18: Health service managers | D18: YES
A19: Algeria | B19: 1342 | C19: Health service managers
A20: Algeria | B20: 1342 | C20: Health service managers
A21: Algeria | B21: 1342 | C21: Health service managers | D21: YES
A22: Algeria | B22: 1342 | C22: Health service managers | D22: YES
A23: Algeria | B23: 1342 | C23: Health service managers | D23: YES
A24: Algeria | B24: 1342 | C24: Gestores dos serviços de saúde | D24: NO
A25: Algeria | B25: 1342 | C25: Health service managers
A26: Algeria | B26: 1342 | C26: Health service managers
A27: Algeria | B27: 1342 | C27: Health service managers
A28: Algeria | B28: 1342 | C28: Health service managers
A29: Algeria | B29: 1342 | C29: Health service managers
A30: Algeria | B30: 1342 | C30: Health service managers
A31: Algeria | B31: 1342 | C31: Health service managers
A32: Algeria | B32: 1342 | C32: Health service managers
A33: Algeria | B33: 1342 | C33: Health service managers
A34: Algeria | B34: 1342 | C34: Health service managers
A35: Algeria | B35: 1342 | C35: Health service managers
A36: Angola | B36: 1342 | C36: Health service managers
... A42: Angola | B42: 1342 | C42: Health service managers
A43: Angola | B43: 1342 | C43: Health service managers | D43: NO
A44: Angola | B44: 1342 | C44: Health service managers
A45: Angola | B45: 1342 | C45: Health service managers | D45: NO
...

Sheet Accreditation-Pivot
B2: country | C2: (All)
B4: Count of Existence of national and/or subnational mechanisms for accreditation of health workforce education and training institutions and their programmes (Yes/No/Partly) | C4: Existence of national and/or subnational mechanisms for accreditation of health workforce education and training institutions and their programmes (Yes/No/Partly)
B5: Code ISCO 08 | C5: NO | D5: PARTLY | E5: YES | F5: Grand Total | H5: % of Countries with full Accredition | I5: % of Countries with Partial Accredition | J5: % of Countries with Partial Accredition
A6: =_xlfn.XLOOKUP(B:B,Accreditation!B:B,Accreditation!C:C,0) -> Health service managers | B6: 1342 | C6: 4 | D6: 1 | E6: 10 | F6: 15 | H6: =E6/F6 -> 0.66666667 | I6: =D6/F6 -> 0.066666667 | J6: =C6/F6 -> 0.26666667
A7: =_xlfn.XLOOKUP(B:B,Accreditation!B:B,Accreditation!C:C,0) -> Epidemiologist | B7: 2131 | C7: 3 | E7: 3 | F7: 6 | H7: =E7/F7 -> 0.5 | I7: =D7/F7 -> 0 | J7: =C7/F7 -> 0.5
A8: =_xlfn.XLOOKUP(B:B,Accreditation!B:B,Accreditation!C:C,0) -> Generalist medical practitioners | B8: 2211 | C8: 2 | D8: 2 | E8: 16 | F8: 20 | H8: =E8/F8 -> 0.8 | I8: =D8/F8 -> 0.1 | J8: =C8/F8 -> 0.1
A9: =_xlfn.XLOOKUP(B:B,Accreditation!B:B,Accreditation!C:C,0) -> Total of all Specialist medical practitioners | B9: 2212 | C9: 1 | D9: 1 | E9: 9 | F9: 11 | H9: =E9/F9 -> 0.81818182 | I9: =D9/F9 -> 0.090909091 | J9: =C9/F9 -> 0.090909091
A10: =_xlfn.XLOOKUP(B:B,Accreditation!B:B,Accreditation!C:C,0) -> Nursing professionals | B10: 2221 | C10: 2 | E10: 9 | F10: 11 | H10: =E10/F10 -> 0.81818182 | I10: =D10/F10 -> 0 | J10: =C10/F10 -> 0.18181818
A11: =_xlfn.XLOOKUP(B:B,Accreditation!B:B,Accreditation!C:C,0) -> Midwifery professionals | B11: 2222 | C11: 2 | E11: 12 | F11: 14 | H11: =E11/F11 -> 0.85714286 | I11: =D11/F11 -> 0 | J11: =C11/F11 -> 0.14285714
A12: =_xlfn.XLOOKUP(B:B,Accreditation!B:B,Accreditation!C:C,0) -> Paramedical practitioners (specify) | B12: 2240 | C12: 6 | E12: 11 | F12: 17 | H12: =E12/F12 -> 0.64705882 | I12: =D12/F12 -> 0 | J12: =C12/F12 -> 0.35294118
A13: =_xlfn.XLOOKUP(B:B,Accreditation!B:B,Accreditation!C:C,0) -> Dentists | B13: 2261 | C13: 5 | D13: 1 | E13: 14 | F13: 20 | H13: =E13/F13 -> 0.7 | I13: =D13/F13 -> 0.05 | J13: =C13/F13 -> 0.25
A14: =_xlfn.XLOOKUP(B:B,Accreditation!B:B,Accreditation!C:C,0) -> Pharmacists | B14: 2262 | C14: 2 | D14: 1 | E14: 16 | F14: 19 | H14: =E14/F14 -> 0.84210526 | I14: =D14/F14 -> 0.052631579 | J14: =C14/F14 -> 0.10526316
A15: =_xlfn.XLOOKUP(B:B,Accreditation!B:B,Accreditation!C:C,0) -> Physiotherapists | B15: 2264 | C15: 4 | D15: 1 | E15: 7 | F15: 12 | H15: =E15/F15 -> 0.58333333 | I15: =D15/F15 -> 0.083333333 | J15: =C15/F15 -> 0.33333333
A16: =_xlfn.XLOOKUP(B:B,Accreditation!B:B,Accreditation!C:C,0) -> Dieticians and nutritionists | B16: 2265 | C16: 6 | E16: 13 | F16: 19 | H16: =E16/F16 -> 0.68421053 | I16: =D16/F16 -> 0 | J16: =C16/F16 -> 0.31578947
A17: =_xlfn.XLOOKUP(B:B,Accreditation!B:B,Accreditation!C:C,0) -> Optometrists | B17: 2267 | C17: 5 | D17: 1 | E17: 5 | F17: 11 | H17: =E17/F17 -> 0.45454545 | I17: =D17/F17 -> 0.090909091 | J17: =C17/F17 -> 0.45454545
A18: =_xlfn.XLOOKUP(B:B,Accreditation!B:B,Accreditation!C:C,0) -> Medical imaging and therapeutic equipment operators | B18: 3211 | C18: 5 | D18: 1 | E18: 12 | F18: 18 | H18: =E18/F18 -> 0.66666667 | I18: =D18/F18 -> 0.055555556 | J18: =C18/F18 -> 0.27777778
A19: =_xlfn.XLOOKUP(B:B,Accreditation!B:B,Accreditation!C:C,0) -> Medical and pathology laboratory technicians | B19: 3212 | C19: 2 | D19: 1 | E19: 18 | F19: 21 | H19: =E19/F19 -> 0.85714286 | I19: =D19/F19 -> 0.047619048 | J19: =C19/F19 -> 0.095238095
A20: =_xlfn.XLOOKUP(B:B,Accreditation!B:B,Accreditation!C:C,0) -> Pharmaceutical technicians and assistants | B20: 3213 | C20: 4 | D20: 1 | E20: 15 | F20: 20 | H20: =E20/F20 -> 0.75 | I20: =D20/F20 -> 0.05 | J20: =C20/F20 -> 0.2
A21: =_xlfn.XLOOKUP(B:B,Accreditation!B:B,Accreditation!C:C,0) -> Medical and dental prosthetic technicians | B21: 3214 | C21: 5 | E21: 12 | F21: 17 | H21: =E21/F21 -> 0.70588235 | I21: =D21/F21 -> 0 | J21: =C21/F21 -> 0.29411765
A22: =_xlfn.XLOOKUP(B:B,Accreditation!B:B,Accreditation!C:C,0) -> Nursing associate professionals | B22: 3221 | C22: 5 | D22: 1 | E22: 8 | F22: 14 | H22: =E22/F22 -> 0.57142857 | I22: =D22/F22 -> 0.071428571 | J22: =C22/F22 -> 0.35714286
A23: =_xlfn.XLOOKUP(B:B,Accreditation!B:B,Accreditation!C:C,0) -> Midwifery associate professionals | B23: 3222 | C23: 5 | E23: 11 | F23: 16 | H23: =E23/F23 -> 0.6875 | I23: =D23/F23 -> 0 | J23: =C23/F23 -> 0.3125
A24: =_xlfn.XLOOKUP(B:B,Accreditation!B:B,Accreditation!C:C,0) -> Dental assistants and therapists | B24: 3251 | C24: 5 | D24: 2 | E24: 11 | F24: 18 | H24: =E24/F24 -> 0.61111111 | I24: =D24/F24 -> 0.11111111 | J24: =C24/F24 -> 0.27777778
A25: =_xlfn.XLOOKUP(B:B,Accreditation!B:B,Accreditation!C:C,0) -> Medical records and health information technicians (including biostatisticians) | B25: 3252 | C25: 8 | D25: 1 | E25: 5 | F25: 14 | H25: =E25/F25 -> 0.35714286 | I25: =D25/F25 -> 0.071428571 | J25: =C25/F25 -> 0.57142857
A26: =_xlfn.XLOOKUP(B:B,Accreditation!B:B,Accreditation!C:C,0) -> Community health workers | B26: 3253 | C26: 6 | D26: 1 | E26: 9 | F26: 16 | H26: =E26/F26 -> 0.5625 | I26: =D26/F26 -> 0.0625 | J26: =C26/F26 -> 0.375
A27: =_xlfn.XLOOKUP(B:B,Accreditation!B:B,Accreditation!C:C,0) -> Opticians | B27: 3254 | C27: 3 | E27: 6 | F27: 9 | H27: =E27/F27 -> 0.66666667 | I27: =D27/F27 -> 0 | J27: =C27/F27 -> 0.33333333
A28: =_xlfn.XLOOKUP(B:B,Accreditation!B:B,Accreditation!C:C,0) -> Physiotherapy assistants | B28: 3255 | C28: 4 | D28: 1 | E28: 6 | F28: 11 | H28: =E28/F28 -> 0.54545455 | I28: =D28/F28 -> 0.090909091 | J28: =C28/F28 -> 0.36363636
A29: =_xlfn.XLOOKUP(B:B,Accreditation!B:B,Accreditation!C:C,0) -> Medical assistants, clinical officers and physician Assistants | B29: 3256 | C29: 6 | D29: 1 | E29: 7 | F29: 14 | H29: =E29/F29 -> 0.5 | I29: =D29/F29 -> 0.071428571 | J29: =C29/F29 -> 0.42857143
A30: Traditional and complementary medicine practitioners | B30: 2230, 3230 | C30: 5 | D30: 1 | E30: 10 | F30: 16 | H30: =E30/F30 -> 0.625 | I30: =D30/F30 -> 0.0625 | J30: =C30/F30 -> 0.3125
A31: Environmental and occupational health & hygiene workers | B31: 2263, 3257 | C31: 4 | D31: 1 | E31: 13 | F31: 18 | H31: =E31/F31 -> 0.72222222 | I31: =D31/F31 -> 0.055555556 | J31: =C31/F31 -> 0.22222222
A32: Physiotherapists and physiotherapy assistants | B32: 2264, 3255 | C32: 2 | E32: 4 | F32: 6 | H32: =E32/F32 -> 0.66666667 | I32: =D32/F32 -> 0 | J32: =C32/F32 -> 0.33333333
A33: Optometrist and opticians | B33: 2267, 3254 | C33: 2 | E33: 4 | F33: 6 | H33: =E33/F33 -> 0.66666667 | I33: =D33/F33 -> 0 | J33: =C33/F33 -> 0.33333333
A34: Health care assistants and other personal care workers in health services | B34: 5321, 5322, 5329 | C34: 2 | E34: 4 | F34: 6 | H34: =E34/F34 -> 0.66666667 | I34: =D34/F34 -> 0 | J34: =C34/F34 -> 0.33333333
B35: Grand Total | C35: 115 | D35: 20 | E35: 280 | F35: 415 | H35: =E35/F35 -> 0.6746988 | I35: =D35/F35 -> 0.048192771 | J35: =C35/F35 -> 0.27710843
G446: =GETPIVOTDATA("Existence of national and/or subnational mechanisms for accreditation of health workforce education and training institutions and their programmes (Yes/No/Partly)",$B$3,"Existence of national and/or subnational mechanisms for accreditation of health workforce education and training institutions and their programmes (Yes/No/Partly)","YES")/GETPIVOTDATA("Existence of national and/or subnational mechanisms for accreditation of health workforce education and training institutions and their programmes (Yes/No/Partly)",$B$3) -> 0.6746988

Sheet E_Applications
D1: Family medicine | E1: 0 | F1: 1 | G1: 1 | K1: 1 | L1: 6 | M1: 7 | N1: 2 | O1: 8 | P1: 10 | Q1: 0 | R1: 0 | S1: 0 | T1: 3 | U1: 2 | V1: 5
D2: Internal medicine | E2: 0 | F2: 3 | G2: 3 | K2: 2 | L2: 3 | M2: 5 | N2: 1 | O2: 3 | P2: 4 | Q2: 3 | R2: 3 | S2: 6 | T2: 1 | U2: 3 | V2: 4
A3: Algeria | D3: Pediatrician | E3: 1 | F3: 3 | G3: 4 | K3: 0 | L3: 3 | M3: 3 | N3: 3 | O3: 15 | P3: 18 | Q3: 3 | R3: 11 | S3: 14 | T3: 1 | U3: 4 | V3: 5
A4: Algeria | D4: Obstetrician & Gynecologist | E4: 1 | F4: 6 | G4: 7 | K4: 3 | L4: 3 | M4: 6 | N4: 7 | O4: 6 | P4: 13 | Q4: 7 | R4: 7 | S4: 14 | T4: 7 | U4: 7 | V4: 14
A5: Algeria | D5: Surgeon | E5: 2 | F5: 2 | G5: 4 | K5: 0 | L5: 3 | M5: 3 | N5: 4 | O5: 4 | P5: 8 | Q5: 7 | R5: 0 | S5: 7 | T5: 3 | U5: 4 | V5: 7
A6: Algeria | D6: Nurse, anaesthetics | E6: 23 | F6: 65 | G6: 88 | K6: 34 | L6: 136 | M6: 170 | Q6: 15 | R6: 5 | S6: 20
A7: Algeria | C7: 3221 | D7: Nursing associate professionals | E7: 57 | F7: 45 | G7: 102 | K7: 42 | L7: 24 | M7: 66 | Q7: 16 | R7: 20 | S7: 36 | T7: 182 | U7: 124 | V7: 306
A8: Algeria | D8: Nurse, operating theatre | E8: 58 | F8: 337 | G8: 395 | K8: 58 | L8: 250 | M8: 308 | Q8: 34 | R8: 34 | S8: 68
A9: Algeria | C9: 2261 | D9: Dentists | E9: 106 | F9: 117 | G9: 223 | K9: 41 | L9: 178 | M9: 219 | T9: 102 | U9: 87 | V9: 189
A10: Algeria | C10: 2262 | D10: Pharmacists | E10: 115 | F10: 186 | G10: 301 | K10: 365 | L10: 844 | M10: 1209 | Q10: 1043 | R10: 1011 | S10: 2054 | T10: 474 | U10: 672 | V10: 1146
A11: Algeria | C11: 2265 | D11: Dieticians and nutritionists | E11: 160 | F11: 15 | G11: 175 | K11: 409 | L11: 922 | M11: 1331 | Q11: 146 | R11: 461 | S11: 607 | T11: 375 | U11: 845 | V11: 1220
A12: Algeria | C12: 3212 | D12: Medical and pathology laboratory technicians | E12: 228 | F12: 201 | G12: 429 | K12: 512 | L12: 732 | M12: 1244 | Q12: 1055 | R12: 1898 | S12: 2953 | T12: 489 | U12: 668 | V12: 1157
A13: Algeria | C13: Code ISO 08 | D13: Occupation | E13: 2022 | H13: 2022 | K13: 2021 | N13: 2020 | Q13: 2019 | T13: 2018
A14: Algeria | D14: Nurse, operating theatre | W14: Partial data of 2022 and 2018
A15: Algeria | E15: MALE | F15: FEMALE | G15: Total | H15: MALE | I15: FEMALE | J15: Total | K15: MALE | L15: FEMALE | M15: Total | N15: MALE | O15: FEMALE | P15: Total | Q15: MALE | R15: FEMALE | S15: Total | T15: MALE | U15: FEMALE | V15: Total
A16: Algeria | C16: 2211 | D16: Generalist medical practitioners | W16: No data
A17: Algeria | C17: 2212 | D17: Total of all Specialist medical practitioners | W17: No data
A18: Algeria | D18: Surgeon | W18: No data
A19: Algeria | D19: Pediatrician | W19: No data
A20: Algeria | D20: Family medicine | W20: No data
A21: Algeria | D21: Obstetrician & Gynecologist | W21: No data
A22: Algeria | D22: Internal medicine | W22: No data
A23: Algeria | C23: 2221 | D23: Nursing professionals | W23: No data
A24: Algeria | D24: Nurse, professional: paediatric | W24: No data
A25: Algeria | D25: Nurse, anaesthetics | W25: No data
A26: Algeria | D26: Nurse, operating theatre | W26: No data
A27: Algeria | C27: 3221 | D27: Nursing associate professionals | W27: No data
A28: Algeria | C28: 2222 | D28: Midwifery professionals | W28: No data
A29: Algeria | C29: 3222 | D29: Midwifery associate professionals | W29: No data
A30: Algeria | C30: 2240 | D30: Paramedical practitioners (specify) | W30: No data
A31: Algeria | C31: 2261 | D31: Dentists | W31: No data
A32: Algeria | C32: 3251 | D32: Dental assistants and therapists | W32: No data
A33: Algeria | C33: 2262 | D33: Pharmacists | W33: No data
A34: Algeria | C34: 3213 | D34: Pharmaceutical technicians and assistants | W34: No data
A35: Algeria | C35: 2263, 3257 | D35: Environmental and occupational health & hygiene workers | W35: No data
A36: Algeria | C36: 2264 | D36: Physiotherapists | W36: No data
A37: Angola | C37: 3255 | D37: Physiotherapy assistants | W37: No data
A38: Angola | C38: 2267 | D38: Optometrists | W38: No data
A39: Angola | C39: 3254 | D39: Opticians | W39: No data
A40: Angola | D40: Field Epidemiologist | W40: No data
...

Sheet Sheet4
A1: country | B1: Code ISCO 08 | C1: Occupation | D1: Existence of national and/or subnational mechanisms for accreditation of health workforce education and training institutions and their programmes (Yes/No/Partly)
A2: Benin | B2: 2211 | C2: Generalist medical practitioners | D2: YES | G2: {=_xlfn.UNIQUE(A:A)} -> country
A3: Benin | B3: 2212 | C3: Total of all Specialist medical practitioners | D3: YES | G3: Benin
A4: Benin | B4: 2221 | C4: Nursing professionals | D4: YES | G4: Botswana
A5: Benin | B5: 2222 | C5: Midwifery professionals | D5: YES | G5: Burkina Faso
A6: Benin | B6: 2240 | C6: Paramedical practitioners (specify) | D6: YES | G6: Cameroon
A7: Benin | B7: 2261 | C7: Dentists | D7: YES | G7: Chad
A8: Benin | B8: 3251 | C8: Dental assistants and therapists | D8: YES | G8: Congo
A9: Benin | B9: 2262 | C9: Pharmacists | D9: YES | G9: Democratic Republic of Congo
A10: Benin | B10: 2263, 3257 | C10: Environmental and occupational health & hygiene workers | D10: YES | G10: Eritrea
A11: Benin | B11: 2264 | C11: Physiotherapists | D11: YES | G11: Eswatini
A12: Benin | B12: 3255 | C12: Physiotherapy assistants | D12: YES | G12: Ethiopia
A13: Benin | B13: 3212 | C13: Medical and pathology laboratory technicians | D13: YES | G13: Gabon
A14: Benin | B14: 3253 | C14: Community health workers | D14: YES | G14: Gambia
A15: Benin | B15: 2265 | C15: Dieticians and nutritionists | D15: YES | G15: Ghana
A16: Benin | B16: 1342 | C16: Health service managers | D16: YES | G16: Guinea
A17: Botswana | B17: 2211 | C17: Generalist medical practitioners | D17: YES | G17: Guinea-Bissau
A18: Botswana | B18: 2212 | C18: Total of all Specialist medical practitioners | D18: YES | G18: Kenya
A19: Botswana | B19: 2221 | C19: Nursing professionals | D19: YES | G19: Madagascar
A20: Botswana | B20: 3221 | C20: Nursing associate professionals | D20: YES | G20: Mozambique
A21: Botswana | B21: 2222 | C21: Midwifery professionals | D21: YES | G21: Senegal
A22: Botswana | B22: 3222 | C22: Midwifery associate professionals | D22: YES | G22: Seychelles
... A26: Botswana | B26: 2262 | C26: Pharmacists | D26: YES | G26: Zimbabwe
A27: Botswana | B27: 3213 | C27: Pharmaceutical technicians and assistants | D27: YES | G27: 0
A28: Botswana | B28: 2263, 3257 | C28: Environmental and occupational health & hygiene workers | D28: YES
A29: Botswana | B29: 2264 | C29: Physiotherapists | D29: YES
A30: Botswana | B30: 3255 | C30: Physiotherapy assistants | D30: YES
A31: Botswana | B31: 2267 | C31: Optometrists | D31: YES
A32: Botswana | B32: 3254 | C32: Opticians | D32: YES
A33: Botswana | B33: 3211 | C33: Medical imaging and therapeutic equipment operators | D33: YES
A34: Botswana | B34: 3212 | C34: Medical and pathology laboratory technicians | D34: YES
A35: Botswana | B35: 3214 | C35: Medical and dental prosthetic technicians | D35: YES
A36: Botswana | B36: 3253 | C36: Community health workers | D36: YES
A37: Botswana | B37: 3256 | C37: Medical assistants, clinical officers and physician Assistants | D37: YES
A38: Botswana | B38: 2230, 3230 | C38: Traditional and complementary medicine practitioners | D38: YES
A39: Botswana | B39: 2265 | C39: Dieticians and nutritionists | D39: YES
A40: Botswana | B40: 1342 | C40: Health service managers | D40: YES
A41: Botswana | B41: 3252 | C41: Medical records and health information technicians (including biostatisticians) | D41: YES
A42: Burkina Faso | B42: 2211 | C42: Generalist medical practitioners | D42: YES
A43: Burkina Faso | B43: 2212 | C43: Total of all Specialist medical practitioners | D43: YES
...

Sheet G_Existence of HWF Unit
A1: Existence of a health workforce unit in the Ministry of Health responsible for developing and monitoring policies and plans on health workforce (Yes/No)
A2: Country | C2: Indicator | D2: Indicator (Descriptor) | E2: Response
A3: Algeria | C3: Sub-indicator 1 | D3: Existence of institutional mechanisms or bodies to coordinate an intersectoral health workforce agenda (Yes/No)
A4: Algeria | C4: Sub-indicator 2 | D4: Existence of mechanisms and models for health workforce planning (Yes/No)
A5: Algeria | C5: Sub-indicator 3 | D5: Existence of national education plans for the health workforce, aligned with the national health plan and the national health workforce strategy/plan (Yes/No)
A6: Algeria | C6: Sub-indicator 4 | D6: Existence of institutional models for assessing and monitoring staffing needs for health service delivery (Yes/No)
A7: Angola | C7: Sub-indicator 1 | D7: Existence of institutional mechanisms or bodies to coordinate an intersectoral health workforce agenda (Yes/No) | E7: NO
A8: Angola | C8: Sub-indicator 2 | D8: Existence of mechanisms and models for health workforce planning (Yes/No) | E8: YES
A9: Angola | C9: Sub-indicator 3 | D9: Existence of national education plans for the health workforce, aligned with the national health plan and the national health workforce strategy/plan (Yes/No) | E9: YES
A10: Angola | C10: Sub-indicator 4 | D10: Existence of institutional models for assessing and monitoring staffing needs for health service delivery (Yes/No) | E10: YES
A11: Benin | C11: Sub-indicator 1 | D11: Existence of institutional mechanisms or bodies to coordinate an intersectoral health workforce agenda (Yes/No) | E11: YES
A12: Benin | C12: Sub-indicator 2 | D12: Existence of mechanisms and models for health workforce planning (Yes/No) | E12: YES
A13: Benin | C13: Sub-indicator 3 | D13: Existence of national education plans for the health workforce, aligned with the national health plan and the national health workforce strategy/plan (Yes/No) | E13: YES
A14: Benin | C14: Sub-indicator 4 | D14: Existence of institutional models for assessing and monitoring staffing needs for health service delivery (Yes/No) | E14: YES
A15: Botswana | C15: Sub-indicator 1 | D15: Existence of institutional mechanisms or bodies to coordinate an intersectoral health workforce agenda (Yes/No) | E15: YES
A16: Botswana | C16: Sub-indicator 2 | D16: Existence of mechanisms and models for health workforce planning (Yes/No) | E16: YES
A17: Botswana | C17: Sub-indicator 3 | D17: Existence of national education plans for the health workforce, aligned with the national health plan and the national health workforce strategy/plan (Yes/No) | E17: YES
A18: Botswana | C18: Sub-indicator 4 | D18: Existence of institutional models for assessing and monitoring staffing needs for health service delivery (Yes/No) | E18: YES
... A26: Burundi | C26: Sub-indicator 4 | D26: Existence of institutional models for assessing and monitoring staffing needs for health service delivery (Yes/No) | E26: YES
A27: Cabo verde | C27: Sub-indicator 1 | D27: Existence of institutional mechanisms or bodies to coordinate an intersectoral health workforce agenda (Yes/No)
A28: Cabo verde | C28: Sub-indicator 2 | D28: Existence of mechanisms and models for health workforce planning (Yes/No)
A29: Cabo verde | C29: Sub-indicator 3 | D29: Existence of national education plans for the health workforce, aligned with the national health plan and the national health workforce strategy/plan (Yes/No)
A30: Cabo verde | C30: Sub-indicator 4 | D30: Existence of institutional models for assessing and monitoring staffing needs for health service delivery (Yes/No)
A31: Cameroon | C31: Sub-indicator 1 | D31: Existence of institutional mechanisms or bodies to coordinate an intersectoral health workforce agenda (Yes/No) | E31: NO
A32: Cameroon | C32: Sub-indicator 2 | D32: Existence of mechanisms and models for health workforce planning (Yes/No) | E32: NO
A33: Cameroon | C33: Sub-indicator 3 | D33: Existence of national education plans for the health workforce, aligned with the national health plan and the national health workforce strategy/plan (Yes/No) | E33: NO
A34: Cameroon | C34: Sub-indicator 4 | D34: Existence of institutional models for assessing and monitoring staffing needs for health service delivery (Yes/No) | E34: NO
A35: Central African republic | C35: Sub-indicator 1 | D35: Existence of institutional mechanisms or bodies to coordinate an intersectoral health workforce agenda (Yes/No)
A36: Central African republic | C36: Sub-indicator 2 | D36: Existence of mechanisms and models for health workforce planning (Yes/No)
A37: Central African republic | C37: Sub-indicator 3 | D37: Existence of national education plans for the health workforce, aligned with the national health plan and the national health workforce strategy/plan (Yes/No)
A38: Central African republic | C38: Sub-indicator 4 | D38: Existence of institutional models for assessing and monitoring staffing needs for health service delivery (Yes/No)
A39: Chad | C39: Sub-indicator 1 | D39: Existence of institutional mechanisms or bodies to coordinate an intersectoral health workforce agenda (Yes/No) | E39: YES
A40: Chad | C40: Sub-indicator 2 | D40: Existence of mechanisms and models for health workforce planning (Yes/No) | E40: YES
A41: Chad | C41: Sub-indicator 3 | D41: Existence of national education plans for the health workforce, aligned with the national health plan and the national health workforce strategy/plan (Yes/No) | E41: YES
A42: Chad | C42: Sub-indicator 4 | D42: Existence of institutional models for assessing and monitoring staffing needs for health service delivery (Yes/No) | E42: YES
A43: Comoros | C43: Sub-indicator 1 | D43: Existence of institutional mechanisms or bodies to coordinate an intersectoral health workforce agenda (Yes/No) | E43: YES
A44: Comoros | C44: Sub-indicator 2 | D44: Existence of mechanisms and models for health workforce planning (Yes/No) | E44: YES
A45: Comoros | C45: Sub-indicator 3 | D45: Existence of national education plans for the health workforce, aligned with the national health plan and the national health workforce strategy/plan (Yes/No) | E45: NO
A46: Comoros | C46: Sub-indicator 4 | D46: Existence of institutional models for assessing and monitoring staffing needs for health service delivery (Yes/No) | E46: NO
A47: Congo | C47: Sub-indicator 1 | D47: Existence of institutional mechanisms or bodies to coordinate an intersectoral health workforce agenda (Yes/No) | E47: YES
...

Sheet G_Alignment of education
D1: Indicators | E1: 2-05 National education alignment to population health service needs
A2: Algeria | D2: Sub-indicator 1 | E2: Existence of national and/or subnational standards for social accountability in accreditation mechanisms (Yes/No/Partly)
A3: Algeria | D3: Sub-indicator 2 | E3: Existence of national and/or subnational standards for the social determinants of health in accreditation mechanisms (Yes/No/Partly)
A4: Algeria | D4: Sub-indicator 3 | E4: Existence of national and/or subnational standards for interprofessional education in accreditation mechanisms (Yes/No/Partly)
A5: Algeria | D5: Sub-indicator 4 | E5: Existence of cooperation between health workforce education and training institutions and regulatory bodies to agree on accreditation standards (Yes/No/Partly)
A6: Algeria | D6: Sub-indicator 5 | E6: Existence of national systems for continuing professional development (Yes/No/Partly)
A7: Algeria | D7: Sub-indicator 6 | E7: Existence of in-service training as an element of national education plans for the health workforce (Yes/No/Partly)
A8: Angola | D8: Sub-indicator 1 | E8: Existence of national and/or subnational standards for social accountability in accreditation mechanisms (Yes/No/Partly)
A9: Angola | D9: Sub-indicator 2 | E9: Existence of national and/or subnational standards for the social determinants of health in accreditation mechanisms (Yes/No/Partly)
A10: Angola | D10: Sub-indicator 3 | E10: Existence of national and/or subnational standards for interprofessional education in accreditation mechanisms (Yes/No/Partly)
A11: Angola | D11: Sub-indicator 4 | E11: Existence of cooperation between health workforce education and training institutions and regulatory bodies to agree on accreditation standards (Yes/No/Partly)
A12: Angola | D12: Sub-indicator 5 | E12: Existence of national systems for continuing professional development (Yes/No/Partly)
A13: Angola | D13: Sub-indicator 6 | E13: Existence of in-service training as an element of national education plans for the health workforce (Yes/No/Partly)
A14: Benin | D14: Sub-indicator 1 | E14: Existence of national and/or subnational standards for social accountability in accreditation mechanisms (Yes/No/Partly) | F14: YES
A15: Benin | D15: Sub-indicator 2 | E15: Existence of national and/or subnational standards for the social determinants of health in accreditation mechanisms (Yes/No/Partly) | F15: YES
A16: Benin | D16: Sub-indicator 3 | E16: Existence of national and/or subnational standards for interprofessional education in accreditation mechanisms (Yes/No/Partly)
A17: Benin | D17: Sub-indicator 4 | E17: Existence of cooperation between health workforce education and training institutions and regulatory bodies to agree on accreditation standards (Yes/No/Partly) | F17: YES
A18: Benin | D18: Sub-indicator 5 | E18: Existence of national systems for continuing professional development (Yes/No/Partly) | F18: YES
A19: Benin | D19: Sub-indicator 6 | E19: Existence of in-service training as an element of national education plans for the health workforce (Yes/No/Partly) | F19: YES
A20: Botswana | D20: Sub-indicator 1 | E20: Existence of national and/or subnational standards for social accountability in accreditation mechanisms (Yes/No/Partly) | F20: YES
A21: Botswana | D21: Sub-indicator 2 | E21: Existence of national and/or subnational standards for the social determinants of health in accreditation mechanisms (Yes/No/Partly) | F21: YES
A22: Botswana | D22: Sub-indicator 3 | E22: Existence of national and/or subnational standards for interprofessional education in accreditation mechanisms (Yes/No/Partly) | F22: YES
A23: Botswana | D23: Sub-indicator 4 | E23: Existence of cooperation between health workforce education and training institutions and regulatory bodies to agree on accreditation standards (Yes/No/Partly) | F23: YES
A24: Botswana | D24: Sub-indicator 5 | E24: Existence of national systems for continuing professional development (Yes/No/Partly) | F24: YES
A25: Botswana | D25: Sub-indicator 6 | E25: Existence of in-service training as an element of national education plans for the health workforce (Yes/No/Partly) | F25: YES
A26: Burkina Faso | D26: Sub-indicator 1 | E26: Existence of national and/or subnational standards for social accountability in accreditation mechanisms (Yes/No/Partly) | F26: YES
A27: Burkina Faso | D27: Sub-indicator 2 | E27: Existence of national and/or subnational standards for the social determinants of health in accreditation mechanisms (Yes/No/Partly) | F27: YES
A28: Burkina Faso | D28: Sub-indicator 3 | E28: Existence of national and/or subnational standards for interprofessional education in accreditation mechanisms (Yes/No/Partly) | F28: YES
... A31: Burkina Faso | D31: Sub-indicator 6 | E31: Existence of in-service training as an element of national education plans for the health workforce (Yes/No/Partly) | F31: YES
A32: Burundi | D32: Sub-indicator 1 | E32: Existence of national and/or subnational standards for social accountability in accreditation mechanisms (Yes/No/Partly)
A33: Burundi | D33: Sub-indicator 2 | E33: Existence of national and/or subnational standards for the social determinants of health in accreditation mechanisms (Yes/No/Partly)
A34: Burundi | D34: Sub-indicator 3 | E34: Existence of national and/or subnational standards for interprofessional education in accreditation mechanisms (Yes/No/Partly)
A35: Burundi | D35: Sub-indicator 4 | E35: Existence of cooperation between health workforce education and training institutions and regulatory bodies to agree on accreditation standards (Yes/No/Partly)
A36: Burundi | D36: Sub-indicator 5 | E36: Existence of national systems for continuing professional development (Yes/No/Partly)
A37: Burundi | D37: Sub-indicator 6 | E37: Existence of in-service training as an element of national education plans for the health workforce (Yes/No/Partly)
A38: Cabo verde | D38: Sub-indicator 1 | E38: Existence of national and/or subnational standards for social accountability in accreditation mechanisms (Yes/No/Partly)
A39: Cabo verde | D39: Sub-indicator 2 | E39: Existence of national and/or subnational standards for the social determinants of health in accreditation mechanisms (Yes/No/Partly)
A40: Cabo verde | D40: Sub-indicator 3 | E40: Existence of national and/or subnational standards for interprofessional education in accreditation mechanisms (Yes/No/Partly)
A41: Cabo verde | D41: Sub-indicator 4 | E41: Existence of cooperation between health workforce education and training institutions and regulatory bodies to agree on accreditation standards (Yes/No/Partly)
A42: Cabo verde | D42: Sub-indicator 5 | E42: Existence of national systems for continuing professional development (Yes/No/Partly)
...
