Workbook
Name Country: #REF!

Sheet HRH Policy and Planning
A1: Country | B1: QUESTIONS | C1: RESPONSE (Yes/No/In progress)
A2: Angola | B2: Is there a national policy for HRH? | C2: YES | G2: Dimension | H2: Yes | I2: No | J2: % Yes | K2: % No | L2: No Countries
A3: Angola | B3: Is there a national strategic/investment plan for HRH? | C3: YES | G3: Is there a national policy for HRH? | H3: =COUNTIFS($B:$B,$G3,$C:$C,H$2) -> 24 | I3: =COUNTIFS($B:$B,$G3,$C:$C,I$2) -> 6 | J3: =H3/L3 -> 0.8 | K3: =I3/L3 -> 0.2 | L3: =H3+I3 -> 30
A4: Angola | B4: a. What is the period covered by current the HRH plan? | C4: 10 | G4: Is there a national strategic/investment plan for HRH? | H4: =COUNTIFS($B:$B,$G4,$C:$C,H$2) -> 22 | I4: =COUNTIFS($B:$B,$G4,$C:$C,I$2) -> 13 | J4: =H4/L4 -> 0.62857143 | K4: =I4/L4 -> 0.37142857 | L4: =H4+I4 -> 35
A5: Angola | B5: b. Has the strategy plan been costed? | C5: YES | G5: a. What is the period covered by current the HRH plan? | H5: =AVERAGEIFS(C:C,B:B,G5) -> 6.4166667 | M5: =_xlfn.MINIFS(C:C,B:B,G5) -> 1 | N5: =_xlfn.MAXIFS(C:C,B:B,G5) -> 10
A6: Angola | B6: c. Does it include projections of the HRH needs/demand | C6: YES | G6: b. Has the strategy plan been costed? | H6: =COUNTIFS($B:$B,$G6,$C:$C,H$2) -> 20 | I6: =COUNTIFS($B:$B,$G6,$C:$C,I$2) -> 5 | J6: =H6/L6 -> 0.8 | K6: =I6/L6 -> 0.2 | L6: =H6+I6 -> 25
A7: Angola | B7: d. Do the projections cover the public and private sectors? | C7: NO | G7: c. Does it include projections of the HRH needs/demand | H7: =COUNTIFS($B:$B,$G7,$C:$C,H$2) -> 23 | I7: =COUNTIFS($B:$B,$G7,$C:$C,I$2) -> 2 | J7: =H7/L7 -> 0.92 | K7: =I7/L7 -> 0.08 | L7: =H7+I7 -> 25
A8: Angola | B8: a. Educational targets (supply of health workforce) | C8: YES | G8: d. Do the projections cover the public and private sectors? | H8: =COUNTIFS($B:$B,$G8,$C:$C,H$2) -> 4 | I8: =COUNTIFS($B:$B,$G8,$C:$C,I$2) -> 20 | J8: =H8/L8 -> 0.16666667 | K8: =I8/L8 -> 0.83333333 | L8: =H8+I8 -> 24
A9: Angola | B9: b. Recruitment targets (planned new recruitments) | C9: YES | G9: If there is a strategic plan, what elements are covered? | H9: Yes | I9: No | J9: % Yes | K9: % No | L9: No Countries
A10: Angola | B10: c. Deployment and distribution | C10: YES | G10: a. Educational targets (supply of health workforce) | H10: =COUNTIFS($B:$B,$G10,$C:$C,H$2) -> 21 | I10: =COUNTIFS($B:$B,$G10,$C:$C,I$2) -> 3 | J10: =H10/L10 -> 0.875 | K10: =I10/L10 -> 0.125 | L10: =H10+I10 -> 24
A11: Angola | B11: d. Incentives/retention strategies | C11: YES | G11: b. Recruitment targets (planned new recruitments) | H11: =COUNTIFS($B:$B,$G11,$C:$C,H$2) -> 21 | I11: =COUNTIFS($B:$B,$G11,$C:$C,I$2) -> 3 | J11: =H11/L11 -> 0.875 | K11: =I11/L11 -> 0.125 | L11: =H11+I11 -> 24
A12: Angola | B12: e. International migration of staff | C12: NO | G12: c. Deployment and distribution | H12: =COUNTIFS($B:$B,$G12,$C:$C,H$2) -> 19 | I12: =COUNTIFS($B:$B,$G12,$C:$C,I$2) -> 5 | J12: =H12/L12 -> 0.79166667 | K12: =I12/L12 -> 0.20833333 | L12: =H12+I12 -> 24
A13: Angola | B13: Is there a commitment for increased allocation from national resources for plan implementation? | C13: YES | G13: d. Incentives/retention strategies | H13: =COUNTIFS($B:$B,$G13,$C:$C,H$2) -> 19 | I13: =COUNTIFS($B:$B,$G13,$C:$C,I$2) -> 5 | J13: =H13/L13 -> 0.79166667 | K13: =I13/L13 -> 0.20833333 | L13: =H13+I13 -> 24
A14: Benin | B14: Is there a national policy for HRH? | C14: YES | G14: e. International migration of staff | H14: =COUNTIFS($B:$B,$G14,$C:$C,H$2) -> 7 | I14: =COUNTIFS($B:$B,$G14,$C:$C,I$2) -> 16 | J14: =H14/L14 -> 0.30434783 | K14: =I14/L14 -> 0.69565217 | L14: =H14+I14 -> 23
A15: Benin | B15: Is there a national strategic/investment plan for HRH? | C15: YES | G15: Is there a commitment for increased allocation from national resources for plan implementation? | H15: =COUNTIFS($B:$B,$G15,$C:$C,H$2) -> 13 | I15: =COUNTIFS($B:$B,$G15,$C:$C,I$2) -> 13 | J15: =H15/L15 -> 0.5 | K15: =I15/L15 -> 0.5 | L15: =H15+I15 -> 26
A16: Benin | B16: a. What is the period covered by current the HRH plan? | C16: 10
A17: Benin | B17: b. Has the strategy plan been costed? | C17: YES
A18: Benin | B18: c. Does it include projections of the HRH needs/demand | C18: YES
A19: Benin | B19: d. Do the projections cover the public and private sectors? | C19: NO
A20: Benin | B20: a. Educational targets (supply of health workforce) | C20: YES
A21: Benin | B21: b. Recruitment targets (planned new recruitments) | C21: YES
A22: Benin | B22: c. Deployment and distribution | C22: YES
A23: Benin | B23: d. Incentives/retention strategies | C23: YES
A24: Benin | B24: e. International migration of staff | C24: NO
A25: Benin | B25: Is there a commitment for increased allocation from national resources for plan implementation? | C25: YES
A26: Botswana | B26: Is there a national policy for HRH? | C26: NO
A27: Botswana | B27: Is there a national strategic/investment plan for HRH? | C27: YES
A28: Botswana | B28: a. What is the period covered by current the HRH plan? | C28: 8
A29: Botswana | B29: b. Has the strategy plan been costed? | C29: NO
A30: Botswana | B30: c. Does it include projections of the HRH needs/demand | C30: YES
A31: Botswana | B31: d. Do the projections cover the public and private sectors? | C31: YES
A32: Botswana | B32: a. Educational targets (supply of health workforce) | C32: YES
A33: Botswana | B33: b. Recruitment targets (planned new recruitments) | C33: YES
A34: Botswana | B34: c. Deployment and distribution | C34: YES
A35: Botswana | B35: d. Incentives/retention strategies | C35: YES
A36: Botswana | B36: e. International migration of staff | C36: YES
A37: Botswana | B37: Is there a commitment for increased allocation from national resources for plan implementation? | C37: NO
A38: Burkina Faso | B38: Is there a national policy for HRH? | C38: IN PROGRESS
A39: Burkina Faso | B39: Is there a national strategic/investment plan for HRH? | C39: NO
A40: Burundi | B40: Is there a national policy for HRH? | C40: YES
...

Sheet Working Conditions
B3: Country | C3: Sub-Indicator | D3: 4-01 Regulation on working conditions | E3: Response | I3: Sub-Indicator | J3: 4-01 Regulation on working conditions | K3: Yes | L3: No | M3: % Yes | N3: % No | O3: No Countries
B4: Angola | C4: Sub-indicator 1 | D4: Existence of national/subnational policies/laws regulating minimum wage (Yes/No) | E4: YES | I4: Sub-indicator 1 | J4: Existence of national/subnational policies/laws regulating minimum wage (Yes/No) | K4: =COUNTIFS($D:$D,$J4,$E:$E,K$3) -> 28 | L4: =COUNTIFS($D:$D,$J4,$E:$E,L$3) -> 1 | M4: =K4/O4 -> 0.96551724 | N4: =L4/O4 -> 0.034482759 | O4: =K4+L4 -> 29
B5: Angola | C5: Sub-indicator 2 | D5: Existence of national/subnational policies/laws regulating social protection (Yes/No) | E5: YES | I5: Sub-indicator 2 | J5: Existence of national/subnational policies/laws regulating social protection (Yes/No) | K5: =COUNTIFS($D:$D,$J5,$E:$E,K$3) -> 25 | L5: =COUNTIFS($D:$D,$J5,$E:$E,L$3) -> 4 | M5: =K5/O5 -> 0.86206897 | N5: =L5/O5 -> 0.13793103 | O5: =K5+L5 -> 29
B6: Angola | C6: Sub-indicator 3 | D6: Existence of national/subnational policies/laws regulating dual practice (Yes/No) | E6: NO | I6: Sub-indicator 3 | J6: Existence of national/subnational policies/laws regulating dual practice (Yes/No) | K6: =COUNTIFS($D:$D,$J6,$E:$E,K$3) -> 15 | L6: =COUNTIFS($D:$D,$J6,$E:$E,L$3) -> 13 | M6: =K6/O6 -> 0.53571429 | N6: =L6/O6 -> 0.46428571 | O6: =K6+L6 -> 28
B7: Angola | C7: Sub-indicator 4 | D7: Existence of national/subnational policies/laws regulating compulsory service (Yes/No) | E7: YES | I7: Sub-indicator 4 | J7: Existence of national/subnational policies/laws regulating compulsory service (Yes/No) | K7: =COUNTIFS($D:$D,$J7,$E:$E,K$3) -> 18 | L7: =COUNTIFS($D:$D,$J7,$E:$E,L$3) -> 10 | M7: =K7/O7 -> 0.64285714 | N7: =L7/O7 -> 0.35714286 | O7: =K7+L7 -> 28
B8: Benin | C8: Sub-indicator 1 | D8: Existence of national/subnational policies/laws regulating minimum wage (Yes/No) | E8: YES
B9: Benin | C9: Sub-indicator 2 | D9: Existence of national/subnational policies/laws regulating social protection (Yes/No) | E9: YES
B10: Benin | C10: Sub-indicator 3 | D10: Existence of national/subnational policies/laws regulating dual practice (Yes/No) | E10: YES
B11: Benin | C11: Sub-indicator 4 | D11: Existence of national/subnational policies/laws regulating compulsory service (Yes/No) | E11: YES
B12: Botswana | C12: Sub-indicator 1 | D12: Existence of national/subnational policies/laws regulating minimum wage (Yes/No) | E12: YES
B13: Botswana | C13: Sub-indicator 2 | D13: Existence of national/subnational policies/laws regulating social protection (Yes/No) | E13: YES
B14: Botswana | C14: Sub-indicator 3 | D14: Existence of national/subnational policies/laws regulating dual practice (Yes/No) | E14: YES
B15: Botswana | C15: Sub-indicator 4 | D15: Existence of national/subnational policies/laws regulating compulsory service (Yes/No) | E15: YES
B16: Burkina Faso | C16: Sub-indicator 1 | D16: Existence of national/subnational policies/laws regulating minimum wage (Yes/No) | E16: YES
B17: Burkina Faso | C17: Sub-indicator 2 | D17: Existence of national/subnational policies/laws regulating social protection (Yes/No) | E17: YES
B18: Burkina Faso | C18: Sub-indicator 3 | D18: Existence of national/subnational policies/laws regulating dual practice (Yes/No) | E18: YES
B19: Burkina Faso | C19: Sub-indicator 4 | D19: Existence of national/subnational policies/laws regulating compulsory service (Yes/No) | E19: YES
... B117: Zimbabwe | C117: Sub-indicator 4 | D117: Existence of national/subnational policies/laws regulating compulsory service (Yes/No) | E117: YES

Sheet Existence of HRH Unit
A1: Country | B1: Sub_indicator | C1: 4-02 Existence of central health workforce unit and its subfunctions | D1: Respoonse
A2: Angola | B2: Sub-indicator 1 | C2: Existence of institutional mechanisms or bodies to coordinate an intersectoral health workforce agenda (Yes/No) | D2: NO | F2: Sub-indicator | G2: 4-02 Existence of central health workforce unit and its subfunctions | H2: Yes | I2: No | J2: % Yes | K2: % No | L2: No Countries
A3: Angola | B3: Sub-indicator 2 | C3: Existence of mechanisms and models for health workforce planning (Yes/No) | D3: YES | F3: Sub-indicator 1 | G3: Existence of institutional mechanisms or bodies to coordinate an intersectoral health workforce agenda (Yes/No) | H3: =COUNTIFS($C:$C,$G3,$D:$D,H$2) -> 22 | I3: =COUNTIFS($C:$C,$G3,$D:$D,I$2) -> 7 | J3: =H3/L3 -> 0.75862069 | K3: =I3/L3 -> 0.24137931 | L3: =H3+I3 -> 29
A4: Angola | B4: Sub-indicator 3 | C4: Existence of national education plans for the health workforce, aligned with the national health plan and the national health workforce strategy/plan (Yes/No) | D4: YES | F4: Sub-indicator 2 | G4: Existence of mechanisms and models for health workforce planning (Yes/No) | H4: =COUNTIFS($C:$C,$G4,$D:$D,H$2) -> 24 | I4: =COUNTIFS($C:$C,$G4,$D:$D,I$2) -> 5 | J4: =H4/L4 -> 0.82758621 | K4: =I4/L4 -> 0.17241379 | L4: =H4+I4 -> 29
A5: Angola | B5: Sub-indicator 4 | C5: Existence of institutional models for assessing and monitoring staffing needs for health service delivery (Yes/No) | D5: YES | F5: Sub-indicator 3 | G5: Existence of national education plans for the health workforce, aligned with the national health plan and the national health workforce strategy/plan (Yes/No) | H5: =COUNTIFS($C:$C,$G5,$D:$D,H$2) -> 22 | I5: =COUNTIFS($C:$C,$G5,$D:$D,I$2) -> 7 | J5: =H5/L5 -> 0.75862069 | K5: =I5/L5 -> 0.24137931 | L5: =H5+I5 -> 29
A6: Benin | B6: Sub-indicator 1 | C6: Existence of institutional mechanisms or bodies to coordinate an intersectoral health workforce agenda (Yes/No) | D6: YES | F6: Sub-indicator 4 | G6: Existence of institutional models for assessing and monitoring staffing needs for health service delivery (Yes/No) | H6: =COUNTIFS($C:$C,$G6,$D:$D,H$2) -> 18 | I6: =COUNTIFS($C:$C,$G6,$D:$D,I$2) -> 11 | J6: =H6/L6 -> 0.62068966 | K6: =I6/L6 -> 0.37931034 | L6: =H6+I6 -> 29
A7: Benin | B7: Sub-indicator 2 | C7: Existence of mechanisms and models for health workforce planning (Yes/No) | D7: YES
A8: Benin | B8: Sub-indicator 3 | C8: Existence of national education plans for the health workforce, aligned with the national health plan and the national health workforce strategy/plan (Yes/No) | D8: YES
A9: Benin | B9: Sub-indicator 4 | C9: Existence of institutional models for assessing and monitoring staffing needs for health service delivery (Yes/No) | D9: YES
A10: Botswana | B10: Sub-indicator 1 | C10: Existence of institutional mechanisms or bodies to coordinate an intersectoral health workforce agenda (Yes/No) | D10: YES
A11: Botswana | B11: Sub-indicator 2 | C11: Existence of mechanisms and models for health workforce planning (Yes/No) | D11: YES
A12: Botswana | B12: Sub-indicator 3 | C12: Existence of national education plans for the health workforce, aligned with the national health plan and the national health workforce strategy/plan (Yes/No) | D12: YES
A13: Botswana | B13: Sub-indicator 4 | C13: Existence of institutional models for assessing and monitoring staffing needs for health service delivery (Yes/No) | D13: YES
A14: Burkina Faso | B14: Sub-indicator 1 | C14: Existence of institutional mechanisms or bodies to coordinate an intersectoral health workforce agenda (Yes/No) | D14: YES
A15: Burkina Faso | B15: Sub-indicator 2 | C15: Existence of mechanisms and models for health workforce planning (Yes/No) | D15: YES
A16: Burkina Faso | B16: Sub-indicator 3 | C16: Existence of national education plans for the health workforce, aligned with the national health plan and the national health workforce strategy/plan (Yes/No) | D16: YES
A17: Burkina Faso | B17: Sub-indicator 4 | C17: Existence of institutional models for assessing and monitoring staffing needs for health service delivery (Yes/No) | D17: YES
A18: Burundi | B18: Sub-indicator 1 | C18: Existence of institutional mechanisms or bodies to coordinate an intersectoral health workforce agenda (Yes/No) | D18: YES
... A117: Zimbabwe | B117: Sub-indicator 4 | C117: Existence of institutional models for assessing and monitoring staffing needs for health service delivery (Yes/No) | D117: YES

Sheet Governace capacity
A1: Country | B1: 4-AFR-05 HRH Governance capacity in MoH and HRH regulation | C1: RESPONSES
A2: Angola | B2: Is there an HRH department/Directorate in the MoH responsible for developing, implementing and monitoring HRH strategies? | C2: YES | F2: 4-AFR-05 HRH Governance capacity in MoH and HRH regulation | G2: Yes | H2: No | I2: % Yes | J2: % No | K2: No Countries
A3: Angola | B3: i. HRH policy development | C3: YES | F3: Is there an HRH department/Directorate in the MoH responsible for developing, implementing and monitoring HRH strategies? | G3: =COUNTIFS($B:$B,$F3,$C:$C,G$2) -> 26 | H3: =COUNTIFS($B:$B,$F3,$C:$C,H$2) -> 0 | I3: =G3/K3 -> 1 | J3: =H3/K3 -> 0 | K3: =G3+H3 -> 26
A4: Angola | B4: ii. HRH planning | C4: YES | F4: i. HRH policy development | G4: =COUNTIFS($B:$B,$F4,$C:$C,G$2) -> 31 | H4: =COUNTIFS($B:$B,$F4,$C:$C,H$2) -> 1 | I4: =G4/K4 -> 0.96875 | J4: =H4/K4 -> 0.03125 | K4: =G4+H4 -> 32
A5: Angola | B5: iii. Personnel administration | C5: YES | F5: ii. HRH planning | G5: =COUNTIFS($B:$B,$F5,$C:$C,G$2) -> 32 | H5: =COUNTIFS($B:$B,$F5,$C:$C,H$2) -> 0 | I5: =G5/K5 -> 1 | J5: =H5/K5 -> 0 | K5: =G5+H5 -> 32
A6: Angola | B6: iv. Training and development | C6: YES | F6: iii. Personnel administration | G6: =COUNTIFS($B:$B,$F6,$C:$C,G$2) -> 29 | H6: =COUNTIFS($B:$B,$F6,$C:$C,H$2) -> 4 | I6: =G6/K6 -> 0.87878788 | J6: =H6/K6 -> 0.12121212 | K6: =G6+H6 -> 33
A7: Angola | B7: v. HRH information system | C7: YES | F7: iv. Training and development | G7: =COUNTIFS($B:$B,$F7,$C:$C,G$2) -> 31 | H7: =COUNTIFS($B:$B,$F7,$C:$C,H$2) -> 1 | I7: =G7/K7 -> 0.96875 | J7: =H7/K7 -> 0.03125 | K7: =G7+H7 -> 32
A8: Angola | B8: vi. Research, studies, documentation | C8: NO | F8: v. HRH information system | G8: =COUNTIFS($B:$B,$F8,$C:$C,G$2) -> 28 | H8: =COUNTIFS($B:$B,$F8,$C:$C,H$2) -> 4 | I8: =G8/K8 -> 0.875 | J8: =H8/K8 -> 0.125 | K8: =G8+H8 -> 32
A9: Angola | B9: vii. Monitoring and evaluation | C9: YES | F9: vi. Research, studies, documentation | G9: =COUNTIFS($B:$B,$F9,$C:$C,G$2) -> 21 | H9: =COUNTIFS($B:$B,$F9,$C:$C,H$2) -> 10 | I9: =G9/K9 -> 0.67741935 | J9: =H9/K9 -> 0.32258065 | K9: =G9+H9 -> 31
A10: Angola | B10: Is the head of the unit part of senior management team of the Ministry | C10: YES | F10: vii. Monitoring and evaluation | G10: =COUNTIFS($B:$B,$F10,$C:$C,G$2) -> 22 | H10: =COUNTIFS($B:$B,$F10,$C:$C,H$2) -> 7 | I10: =G10/K10 -> 0.75862069 | J10: =H10/K10 -> 0.24137931 | K10: =G10+H10 -> 29
A11: Angola | B11: Do you have HRH units at the regional/State/Provincial level? | C11: YES | F11: Is the head of the unit part of senior management team of the Ministry | G11: =COUNTIFS($B:$B,$F11,$C:$C,G$2) -> 31 | H11: =COUNTIFS($B:$B,$F11,$C:$C,H$2) -> 1 | I11: =G11/K11 -> 0.96875 | J11: =H11/K11 -> 0.03125 | K11: =G11+H11 -> 32
A12: Angola | B12: Do you have a multisectoral HRH national working group or taskforce in place | C12: PLANNED | F12: Do you have HRH units at the regional/State/Provincial level? | G12: =COUNTIFS($B:$B,$F12,$C:$C,G$2) -> 24 | H12: =COUNTIFS($B:$B,$F12,$C:$C,H$2) -> 7 | I12: =G12/K12 -> 0.77419355 | J12: =H12/K12 -> 0.22580645 | K12: =G12+H12 -> 31
A13: Angola | B13: Have you ever conducted a health workforce labour market study? | C13: YES | F13: Do you have a multisectoral HRH national working group or taskforce in place | G13: =COUNTIFS($B:$B,$F13,$C:$C,G$2) -> 20 | H13: =COUNTIFS($B:$B,$F13,$C:$C,H$2) -> 12 | I13: =G13/K13 -> 0.625 | J13: =H13/K13 -> 0.375 | K13: =G13+H13 -> 32
A14: Angola | B14: Does your country allow dual employment (i.e. for staff working full time in public sector to practice in the private sector) ? | C14: YES | F14: Have you ever conducted a health workforce labour market study? | G14: =COUNTIFS($B:$B,$F14,$C:$C,G$2) -> 14 | H14: =COUNTIFS($B:$B,$F14,$C:$C,H$2) -> 13 | I14: =G14/K14 -> 0.51851852 | J14: =H14/K14 -> 0.48148148 | K14: =G14+H14 -> 27
A15: Angola | B15: How many health worker strikes have taken place in the last 12 months in the country (for some or all categories combined)? | C15: 2
A16: Angola | B16: What is the average duration of a health worker strike in the last 12 months (in days) | C16: 7-14 days
A17: Angola | B17: Are strikes happening often (more than once a year) locally or across the country? | C17: Often locally
A18: Angola | B18: Is there a conflict resolution mechanism? If yes, specify in the remarks column | C18: IN PROGRESS
A19: Angola | B19: Do strikes normally have an impact on the functioning of health centers (or it’s mainly hospitals only?) | C19: Limited impact
A20: Benin | B20: Is there an HRH department/Directorate in the MoH responsible for developing, implementing and monitoring HRH strategies? | C20: YES
A21: Benin | B21: i. HRH policy development | C21: YES
A22: Benin | B22: ii. HRH planning | C22: YES
A23: Benin | B23: iii. Personnel administration | C23: YES
A24: Benin | B24: iv. Training and development | C24: YES
A25: Benin | B25: v. HRH information system | C25: YES
A26: Benin | B26: vi. Research, studies, documentation | C26: YES
A27: Benin | B27: vii. Monitoring and evaluation | C27: YES
... A46: Botswana | B46: Does your country allow dual employment (i.e. for staff working full time in public sector to practice in the private sector) ? | C46: NO
A47: Botswana | B47: How many health worker strikes have taken place in the last 12 months in the country (for some or all categories combined)? | C47: 0
A48: Botswana | B48: Is there a conflict resolution mechanism? If yes, specify in the remarks column | C48: YES
A49: Botswana | B49: Do strikes normally have an impact on the functioning of health centers (or it’s mainly hospitals only?) | C49: Significant impact
A50: Burkina Faso | B50: Is there an HRH department/Directorate in the MoH responsible for developing, implementing and monitoring HRH strategies? | C50: YES
A51: Burkina Faso | B51: i. HRH policy development | C51: YES
A52: Burkina Faso | B52: ii. HRH planning | C52: YES
A53: Burkina Faso | B53: iii. Personnel administration | C53: YES
A54: Burkina Faso | B54: iv. Training and development | C54: YES
A55: Burkina Faso | B55: v. HRH information system | C55: YES
A56: Burkina Faso | B56: vi. Research, studies, documentation | C56: NO
A57: Burkina Faso | B57: vii. Monitoring and evaluation | C57: YES
A58: Burkina Faso | B58: viii. Other (specify) | C58: Conflict management, advising structures on HR matters, channelling relations with the Civil Service Department
...

Sheet Strikes
A1: Country | B1: 4-AFR-05 HRH Governance capacity in MoH and HRH regulation | C1: RESPONSES
A2: Angola | B2: Do you have a multisectoral HRH national working group or taskforce in place | C2: PLANNED
A3: Angola | B3: How many health worker strikes have taken place in the last 12 months in the country (for some or all categories combined)? | C3: 2 | G3: What is the average duration of a health worker strike in the last 12 months (in days) | I3: Number of Countries
A4: Angola | B4: What is the average duration of a health worker strike in the last 12 months (in days) | C4: 7-14 days | G4: 1-3 days | H4: =COUNTIFS(C:C,G4,B:B,$G$3) -> 4
A5: Angola | B5: Are strikes happening often (more than once a year) locally or across the country? | C5: Often locally | G5: 4-6 days | H5: =COUNTIFS(C:C,G5,B:B,$G$3) -> 4
A6: Angola | B6: Is there a conflict resolution mechanism? If yes, specify in the remarks column | C6: IN PROGRESS | G6: 7-14 days | H6: =COUNTIFS(C:C,G6,B:B,$G$3) -> 6
A7: Angola | B7: Do strikes normally have an impact on the functioning of health centers (or it’s mainly hospitals only?) | C7: Limited impact | G7: 15 days & + | H7: =COUNTIFS(C:C,G7,B:B,$G$3) -> 2
A8: Benin | B8: Do you have a multisectoral HRH national working group or taskforce in place | C8: YES
A9: Benin | B9: Is there a conflict resolution mechanism? If yes, specify in the remarks column | C9: YES | G9: How many health worker strikes have taken place in the last 12 months in the country (for some or all categories combined)? | H9: =AVERAGEIFS($C:$C,$B:$B,$G$9) -> 2.1153846 | I9: =COUNTIF(B:B,G9) -> 26
A10: Botswana | B10: Do you have a multisectoral HRH national working group or taskforce in place | C10: NO | H10: =_xlfn.MINIFS($C:$C,$B:$B,$G$9) -> 0
A11: Botswana | B11: How many health worker strikes have taken place in the last 12 months in the country (for some or all categories combined)? | C11: 0 | H11: =_xlfn.MAXIFS($C:$C,$B:$B,$G$9) -> 17
A12: Botswana | B12: Is there a conflict resolution mechanism? If yes, specify in the remarks column | C12: YES
A13: Botswana | B13: Do strikes normally have an impact on the functioning of health centers (or it’s mainly hospitals only?) | C13: Significant impact
A14: Burkina Faso | B14: Do you have a multisectoral HRH national working group or taskforce in place | C14: YES
A15: Burkina Faso | B15: How many health worker strikes have taken place in the last 12 months in the country (for some or all categories combined)? | C15: 4
A16: Burkina Faso | B16: What is the average duration of a health worker strike in the last 12 months (in days) | C16: 1-3 days
A17: Burkina Faso | B17: Are strikes happening often (more than once a year) locally or across the country? | C17: Often locally
A18: Burkina Faso | B18: Is there a conflict resolution mechanism? If yes, specify in the remarks column | C18: YES
A19: Burkina Faso | B19: Do strikes normally have an impact on the functioning of health centers (or it’s mainly hospitals only?) | C19: Limited impact
A20: Burundi | B20: Do you have a multisectoral HRH national working group or taskforce in place | C20: YES
A21: Burundi | B21: Is there a conflict resolution mechanism? If yes, specify in the remarks column | C21: YES
A22: Burundi | B22: Do strikes normally have an impact on the functioning of health centers (or it’s mainly hospitals only?) | C22: No impact
A23: Cameroon | B23: Do you have a multisectoral HRH national working group or taskforce in place | C23: NO
A24: Cameroon | B24: How many health worker strikes have taken place in the last 12 months in the country (for some or all categories combined)? | C24: 2
A25: Cameroon | B25: What is the average duration of a health worker strike in the last 12 months (in days) | C25: 4-6 days
A26: Cameroon | B26: Are strikes happening often (more than once a year) locally or across the country? | C26: Often locally
A27: Cameroon | B27: Is there a conflict resolution mechanism? If yes, specify in the remarks column | C27: YES
A28: Cameroon | B28: Do strikes normally have an impact on the functioning of health centers (or it’s mainly hospitals only?) | C28: Limited impact
A29: Chad | B29: Do you have a multisectoral HRH national working group or taskforce in place | C29: YES
A30: Chad | B30: How many health worker strikes have taken place in the last 12 months in the country (for some or all categories combined)? | C30: 1
A31: Chad | B31: What is the average duration of a health worker strike in the last 12 months (in days) | C31: 1-3 days
A32: Chad | B32: Is there a conflict resolution mechanism? If yes, specify in the remarks column | C32: YES
A33: Chad | B33: Do strikes normally have an impact on the functioning of health centers (or it’s mainly hospitals only?) | C33: Significant impact
A34: Congo | B34: Do you have a multisectoral HRH national working group or taskforce in place | C34: NO
A35: Congo | B35: How many health worker strikes have taken place in the last 12 months in the country (for some or all categories combined)? | C35: 1
A36: Congo | B36: What is the average duration of a health worker strike in the last 12 months (in days) | C36: 7-14 days
A37: Congo | B37: Are strikes happening often (more than once a year) locally or across the country? | C37: Often locally
A38: Congo | B38: Is there a conflict resolution mechanism? If yes, specify in the remarks column | C38: NO
A39: Congo | B39: Do strikes normally have an impact on the functioning of health centers (or it’s mainly hospitals only?) | C39: Limited impact
A40: Cote d'Ivoire | B40: Do you have a multisectoral HRH national working group or taskforce in place | C40: YES
...

Sheet Summary Table_Pulled Together
B3: Main Indicator and Sub-Indicators | C3: Yes | D3: No | E3: % Yes | F3: % No | G3: No Countries that responded out of 47
B4: AFR-05 HRH Governance capacity in MoH and HRH regulation
B5: 1. Is there an HRH department/Directorate in the MoH responsible for developing, implementing and monitoring HRH strategies? | C5: =MAX(C6:C13) -> 32 | D5: =MAX(D6:D13) -> 10 | E5: =MAX(E6:E13) -> 1 | F5: =1-E5 -> 0 | G5: =MAX(G6:G13) -> 33
B6: 2. If there is Central HRH Unit, what are the main functions of the department/unit/team?
B7: i. HRH policy development | C7: ='Governace capacity'!G4 -> 31 | D7: ='Governace capacity'!H4 -> 1 | E7: ='Governace capacity'!I4 -> 0.96875 | F7: ='Governace capacity'!J4 -> 0.03125 | G7: ='Governace capacity'!K4 -> 32
B8: ii. HRH planning | C8: ='Governace capacity'!G5 -> 32 | D8: ='Governace capacity'!H5 -> 0 | E8: ='Governace capacity'!I5 -> 1 | F8: ='Governace capacity'!J5 -> 0 | G8: ='Governace capacity'!K5 -> 32
B9: iii. Personnel administration | C9: ='Governace capacity'!G6 -> 29 | D9: ='Governace capacity'!H6 -> 4 | E9: ='Governace capacity'!I6 -> 0.87878788 | F9: ='Governace capacity'!J6 -> 0.12121212 | G9: ='Governace capacity'!K6 -> 33
B10: iv. Training and development | C10: ='Governace capacity'!G7 -> 31 | D10: ='Governace capacity'!H7 -> 1 | E10: ='Governace capacity'!I7 -> 0.96875 | F10: ='Governace capacity'!J7 -> 0.03125 | G10: ='Governace capacity'!K7 -> 32
B11: v. HRH information system | C11: ='Governace capacity'!G8 -> 28 | D11: ='Governace capacity'!H8 -> 4 | E11: ='Governace capacity'!I8 -> 0.875 | F11: ='Governace capacity'!J8 -> 0.125 | G11: ='Governace capacity'!K8 -> 32
B12: vi. Research, studies, documentation | C12: ='Governace capacity'!G9 -> 21 | D12: ='Governace capacity'!H9 -> 10 | E12: ='Governace capacity'!I9 -> 0.67741935 | F12: ='Governace capacity'!J9 -> 0.32258065 | G12: ='Governace capacity'!K9 -> 31
B13: vii. Monitoring and evaluation | C13: ='Governace capacity'!G10 -> 22 | D13: ='Governace capacity'!H10 -> 7 | E13: ='Governace capacity'!I10 -> 0.75862069 | F13: ='Governace capacity'!J10 -> 0.24137931 | G13: ='Governace capacity'!K10 -> 29
B14: 3. Is the head of the unit part of senior management team of the Ministry | C14: ='Governace capacity'!G11 -> 31 | D14: ='Governace capacity'!H11 -> 1 | E14: ='Governace capacity'!I11 -> 0.96875 | F14: ='Governace capacity'!J11 -> 0.03125 | G14: ='Governace capacity'!K11 -> 32
B15: 4. Do you have HRH units at the regional/State/Provincial level? | C15: ='Governace capacity'!G12 -> 24 | D15: ='Governace capacity'!H12 -> 7 | E15: ='Governace capacity'!I12 -> 0.77419355 | F15: ='Governace capacity'!J12 -> 0.22580645 | G15: ='Governace capacity'!K12 -> 31
B16: 5. Do you have a multisectoral HRH national working group or taskforce in place | C16: ='Governace capacity'!G13 -> 20 | D16: ='Governace capacity'!H13 -> 12 | E16: ='Governace capacity'!I13 -> 0.625 | F16: ='Governace capacity'!J13 -> 0.375 | G16: ='Governace capacity'!K13 -> 32
B17: 6. Have you ever conducted a health workforce labour market study? | C17: ='Governace capacity'!G14 -> 14 | D17: ='Governace capacity'!H14 -> 13 | E17: ='Governace capacity'!I14 -> 0.51851852 | F17: ='Governace capacity'!J14 -> 0.48148148 | G17: ='Governace capacity'!K14 -> 27
B18: NHWA 4-02 Existence of central health workforce unit and its subfunctions
B19: 1. Existence of institutional mechanisms or bodies to coordinate an intersectoral health workforce agenda | C19: ='Existence of HRH Unit'!H3 -> 22 | D19: ='Existence of HRH Unit'!I3 -> 7 | E19: ='Existence of HRH Unit'!J3 -> 0.75862069 | F19: ='Existence of HRH Unit'!K3 -> 0.24137931 | G19: ='Existence of HRH Unit'!L3 -> 29
B20: 2. Existence of mechanisms and models for health workforce planning | C20: ='Existence of HRH Unit'!H4 -> 24 | D20: ='Existence of HRH Unit'!I4 -> 5 | E20: ='Existence of HRH Unit'!J4 -> 0.82758621 | F20: ='Existence of HRH Unit'!K4 -> 0.17241379 | G20: ='Existence of HRH Unit'!L4 -> 29
B21: 3. Existence of national education plans for the health workforce, aligned with the national health plan and the national health workforce strategy/plan | C21: ='Existence of HRH Unit'!H5 -> 22 | D21: ='Existence of HRH Unit'!I5 -> 7 | E21: ='Existence of HRH Unit'!J5 -> 0.75862069 | F21: ='Existence of HRH Unit'!K5 -> 0.24137931 | G21: ='Existence of HRH Unit'!L5 -> 29
B22: 4. Existence of institutional models for assessing and monitoring staffing needs for health service delivery | C22: ='Existence of HRH Unit'!H6 -> 18 | D22: ='Existence of HRH Unit'!I6 -> 11 | E22: ='Existence of HRH Unit'!J6 -> 0.62068966 | F22: ='Existence of HRH Unit'!K6 -> 0.37931034 | G22: ='Existence of HRH Unit'!L6 -> 29
B23: NHWA 4-01 Regulation on working conditions
B24: 1. Existence of national/subnational policies/laws regulating minimum wage | C24: ='Working Conditions'!K4 -> 28 | D24: ='Working Conditions'!L4 -> 1 | E24: ='Working Conditions'!M4 -> 0.96551724 | F24: ='Working Conditions'!N4 -> 0.034482759 | G24: ='Working Conditions'!O4 -> 29
B25: 2. Existence of national/subnational policies/laws regulating social protection | C25: ='Working Conditions'!K5 -> 25 | D25: ='Working Conditions'!L5 -> 4 | E25: ='Working Conditions'!M5 -> 0.86206897 | F25: ='Working Conditions'!N5 -> 0.13793103 | G25: ='Working Conditions'!O5 -> 29
B26: 3. Existence of national/subnational policies/laws regulating dual practice | C26: ='Working Conditions'!K6 -> 15 | D26: ='Working Conditions'!L6 -> 13 | E26: ='Working Conditions'!M6 -> 0.53571429 | F26: ='Working Conditions'!N6 -> 0.46428571 | G26: ='Working Conditions'!O6 -> 28
B27: 4. Existence of national/subnational policies/laws regulating compulsory service | C27: ='Working Conditions'!K7 -> 18 | D27: ='Working Conditions'!L7 -> 10 | E27: ='Working Conditions'!M7 -> 0.64285714 | F27: ='Working Conditions'!N7 -> 0.35714286 | G27: ='Working Conditions'!O7 -> 28
B28: AFR-04 HRH policy, Strategy and plan
B29: 1. Is there a national policy for HRH? | C29: ='HRH Policy and Planning'!H3 -> 24 | D29: ='HRH Policy and Planning'!I3 -> 6 | E29: ='HRH Policy and Planning'!J3 -> 0.8 | F29: ='HRH Policy and Planning'!K3 -> 0.2 | G29: ='HRH Policy and Planning'!L3 -> 30
B30: 2. Is there a national strategic/investment plan for HRH? | C30: ='HRH Policy and Planning'!H4 -> 22 | D30: ='HRH Policy and Planning'!I4 -> 13 | E30: ='HRH Policy and Planning'!J4 -> 0.62857143 | F30: ='HRH Policy and Planning'!K4 -> 0.37142857 | G30: ='HRH Policy and Planning'!L4 -> 35
B31: a. What is the period covered by current the HRH plan? | C31: ='HRH Policy and Planning'!H5 -> 6.4166667 | D31: ='HRH Policy and Planning'!I5 -> 0 | E31: ='HRH Policy and Planning'!J5 -> 0 | F31: ='HRH Policy and Planning'!K5 -> 0 | G31: ='HRH Policy and Planning'!L5 -> 0
B32: i. Has the strategy plan been costed? | C32: ='HRH Policy and Planning'!H6 -> 20 | D32: ='HRH Policy and Planning'!I6 -> 5 | E32: ='HRH Policy and Planning'!J6 -> 0.8 | F32: ='HRH Policy and Planning'!K6 -> 0.2 | G32: ='HRH Policy and Planning'!L6 -> 25
B33: ii. Does it include projections of the HRH needs/demand | C33: ='HRH Policy and Planning'!H7 -> 23 | D33: ='HRH Policy and Planning'!I7 -> 2 | E33: ='HRH Policy and Planning'!J7 -> 0.92 | F33: ='HRH Policy and Planning'!K7 -> 0.08 | G33: ='HRH Policy and Planning'!L7 -> 25
B34: iii. Do the projections cover the public and private sectors? | C34: ='HRH Policy and Planning'!H8 -> 4 | D34: ='HRH Policy and Planning'!I8 -> 20 | E34: ='HRH Policy and Planning'!J8 -> 0.16666667 | F34: ='HRH Policy and Planning'!K8 -> 0.83333333 | G34: ='HRH Policy and Planning'!L8 -> 24
B35: 3. If there is a strategic plan, what elements are covered?
B36: i. Educational targets (supply of health workforce) | C36: ='HRH Policy and Planning'!H10 -> 21 | D36: ='HRH Policy and Planning'!I10 -> 3 | E36: ='HRH Policy and Planning'!J10 -> 0.875 | F36: ='HRH Policy and Planning'!K10 -> 0.125 | G36: ='HRH Policy and Planning'!L10 -> 24
B37: ii. Recruitment targets (planned new recruitments) | C37: ='HRH Policy and Planning'!H11 -> 21 | D37: ='HRH Policy and Planning'!I11 -> 3 | E37: ='HRH Policy and Planning'!J11 -> 0.875 | F37: ='HRH Policy and Planning'!K11 -> 0.125 | G37: ='HRH Policy and Planning'!L11 -> 24
B38: iii. Deployment and distribution | C38: ='HRH Policy and Planning'!H12 -> 19 | D38: ='HRH Policy and Planning'!I12 -> 5 | E38: ='HRH Policy and Planning'!J12 -> 0.79166667 | F38: ='HRH Policy and Planning'!K12 -> 0.20833333 | G38: ='HRH Policy and Planning'!L12 -> 24
B39: iv. Incentives/retention strategies | C39: ='HRH Policy and Planning'!H13 -> 19 | D39: ='HRH Policy and Planning'!I13 -> 5 | E39: ='HRH Policy and Planning'!J13 -> 0.79166667 | F39: ='HRH Policy and Planning'!K13 -> 0.20833333 | G39: ='HRH Policy and Planning'!L13 -> 24
B40: v. International migration of staff | C40: ='HRH Policy and Planning'!H14 -> 7 | D40: ='HRH Policy and Planning'!I14 -> 16 | E40: ='HRH Policy and Planning'!J14 -> 0.30434783 | F40: ='HRH Policy and Planning'!K14 -> 0.69565217 | G40: ='HRH Policy and Planning'!L14 -> 23
B41: 4. Is there a commitment for increased allocation from national resources for plan implementation? | C41: ='HRH Policy and Planning'!H15 -> 13 | D41: ='HRH Policy and Planning'!I15 -> 13 | E41: ='HRH Policy and Planning'!J15 -> 0.5 | F41: ='HRH Policy and Planning'!K15 -> 0.5 | G41: ='HRH Policy and Planning'!L15 -> 26

Sheet Graphs
B3: Main Indicator and Sub-Indicators | C3: Yes | D3: No | E3: % Yes | F3: % No | G3: No Countries that responded out of 47
B4: AFR-05 HRH Governance capacity in MoH and HRH regulation | C4: Yes | D4: No | E4: % Yes | F4: % No | G4: No Countries that responded out of 47
B5: Availability of HRH department/Directorate in the MoH responsible for developing, implementing and monitoring HRH strategies | C5: =MAX(C6:C13) -> 32 | D5: =MAX(D6:D13) -> 10 | E5: =MAX(E6:E13) -> 1 | F5: =1-E5 -> 0 | G5: =MAX(G6:G13) -> 33
B6: 2. If there is Central HRH Unit, what are the main functions of the department/unit/team?
B7: i. HRH policy development | C7: ='Governace capacity'!G4 -> 31 | D7: ='Governace capacity'!H4 -> 1 | E7: ='Governace capacity'!I4 -> 0.96875 | F7: ='Governace capacity'!J4 -> 0.03125 | G7: ='Governace capacity'!K4 -> 32
B8: ii. HRH planning | C8: ='Governace capacity'!G5 -> 32 | D8: ='Governace capacity'!H5 -> 0 | E8: ='Governace capacity'!I5 -> 1 | F8: ='Governace capacity'!J5 -> 0 | G8: ='Governace capacity'!K5 -> 32
B9: iii. Personnel administration | C9: ='Governace capacity'!G6 -> 29 | D9: ='Governace capacity'!H6 -> 4 | E9: ='Governace capacity'!I6 -> 0.87878788 | F9: ='Governace capacity'!J6 -> 0.12121212 | G9: ='Governace capacity'!K6 -> 33
B10: iv. Training and development | C10: ='Governace capacity'!G7 -> 31 | D10: ='Governace capacity'!H7 -> 1 | E10: ='Governace capacity'!I7 -> 0.96875 | F10: ='Governace capacity'!J7 -> 0.03125 | G10: ='Governace capacity'!K7 -> 32
B11: v. HRH information system | C11: ='Governace capacity'!G8 -> 28 | D11: ='Governace capacity'!H8 -> 4 | E11: ='Governace capacity'!I8 -> 0.875 | F11: ='Governace capacity'!J8 -> 0.125 | G11: ='Governace capacity'!K8 -> 32
B12: vi. Research, studies, documentation | C12: ='Governace capacity'!G9 -> 21 | D12: ='Governace capacity'!H9 -> 10 | E12: ='Governace capacity'!I9 -> 0.67741935 | F12: ='Governace capacity'!J9 -> 0.32258065 | G12: ='Governace capacity'!K9 -> 31
B13: vii. Monitoring and evaluation | C13: ='Governace capacity'!G10 -> 22 | D13: ='Governace capacity'!H10 -> 7 | E13: ='Governace capacity'!I10 -> 0.75862069 | F13: ='Governace capacity'!J10 -> 0.24137931 | G13: ='Governace capacity'!K10 -> 29
B14: The head of the HRH unit being part of Senior Management team of the Ministry of Health | C14: ='Governace capacity'!G11 -> 31 | D14: ='Governace capacity'!H11 -> 1 | E14: ='Governace capacity'!I11 -> 0.96875 | F14: ='Governace capacity'!J11 -> 0.03125 | G14: ='Governace capacity'!K11 -> 32
B15: Availability of HRH units at the sub-national level (regional/state/provincial) | C15: ='Governace capacity'!G12 -> 24 | D15: ='Governace capacity'!H12 -> 7 | E15: ='Governace capacity'!I12 -> 0.77419355 | F15: ='Governace capacity'!J12 -> 0.22580645 | G15: ='Governace capacity'!K12 -> 31
B16: 4. Do you have a multisectoral HRH national working group or taskforce in place | C16: ='Governace capacity'!G13 -> 20 | D16: ='Governace capacity'!H13 -> 12 | E16: ='Governace capacity'!I13 -> 0.625 | F16: ='Governace capacity'!J13 -> 0.375 | G16: ='Governace capacity'!K13 -> 32
B17: 5. Have you ever conducted a health workforce labour market study? | C17: ='Governace capacity'!G14 -> 14 | D17: ='Governace capacity'!H14 -> 13 | E17: ='Governace capacity'!I14 -> 0.51851852 | F17: ='Governace capacity'!J14 -> 0.48148148 | G17: ='Governace capacity'!K14 -> 27
B18: NHWA 4-02 Existence of central health workforce unit and its subfunctions | C18: Yes | D18: No | E18: % Yes | F18: % No | G18: No Countries that responded out of 47
B19: Existence of institutional mechanisms or bodies to coordinate an intersectoral health workforce agenda (N = 29) | C19: ='Existence of HRH Unit'!H3 -> 22 | D19: ='Existence of HRH Unit'!I3 -> 7 | E19: ='Existence of HRH Unit'!J3 -> 0.75862069 | F19: ='Existence of HRH Unit'!K3 -> 0.24137931 | G19: ='Existence of HRH Unit'!L3 -> 29
B20: Existence of mechanisms and models for health workforce planning (N = 29) | C20: ='Existence of HRH Unit'!H4 -> 24 | D20: ='Existence of HRH Unit'!I4 -> 5 | E20: ='Existence of HRH Unit'!J4 -> 0.82758621 | F20: ='Existence of HRH Unit'!K4 -> 0.17241379 | G20: ='Existence of HRH Unit'!L4 -> 29
B21: Existence of national education plans for the health workforce, aligned with the national health plan and the national health workforce strategy/plan (N = 29) | C21: ='Existence of HRH Unit'!H5 -> 22 | D21: ='Existence of HRH Unit'!I5 -> 7 | E21: ='Existence of HRH Unit'!J5 -> 0.75862069 | F21: ='Existence of HRH Unit'!K5 -> 0.24137931 | G21: ='Existence of HRH Unit'!L5 -> 29
B22: Existence of institutional models for assessing and monitoring staffing needs for health service delivery (N = 29) | C22: ='Existence of HRH Unit'!H6 -> 18 | D22: ='Existence of HRH Unit'!I6 -> 11 | E22: ='Existence of HRH Unit'!J6 -> 0.62068966 | F22: ='Existence of HRH Unit'!K6 -> 0.37931034 | G22: ='Existence of HRH Unit'!L6 -> 29
B23: NHWA 4-01 Regulation on working conditions | C23: Yes | D23: No | E23: % Yes | F23: % No | G23: No Countries that responded out of 47
B24: Existence of national/subnational policies/laws regulating minimum wage (N = 29) | C24: ='Working Conditions'!K4 -> 28 | D24: ='Working Conditions'!L4 -> 1 | E24: ='Working Conditions'!M4 -> 0.96551724 | F24: ='Working Conditions'!N4 -> 0.034482759 | G24: ='Working Conditions'!O4 -> 29
B25: Existence of national/subnational policies/laws regulating social protection (N = 29) | C25: ='Working Conditions'!K5 -> 25 | D25: ='Working Conditions'!L5 -> 4 | E25: ='Working Conditions'!M5 -> 0.86206897 | F25: ='Working Conditions'!N5 -> 0.13793103 | G25: ='Working Conditions'!O5 -> 29
B26: Existence of national/subnational policies/laws regulating dual practice (N = 28) | C26: ='Working Conditions'!K6 -> 15 | D26: ='Working Conditions'!L6 -> 13 | E26: ='Working Conditions'!M6 -> 0.53571429 | F26: ='Working Conditions'!N6 -> 0.46428571 | G26: ='Working Conditions'!O6 -> 28
B27: Existence of national/subnational policies/laws regulating compulsory service (N = 28) | C27: ='Working Conditions'!K7 -> 18 | D27: ='Working Conditions'!L7 -> 10 | E27: ='Working Conditions'!M7 -> 0.64285714 | F27: ='Working Conditions'!N7 -> 0.35714286 | G27: ='Working Conditions'!O7 -> 28
B28: AFR-04 HRH policy, Strategy and plan | C28: Yes | D28: No | E28: % Yes | F28: % No | G28: No Countries that responded out of 47
B29: Availability of a national policy for HRH (N=30) | C29: ='HRH Policy and Planning'!H3 -> 24 | D29: ='HRH Policy and Planning'!I3 -> 6 | E29: ='HRH Policy and Planning'!J3 -> 0.8 | F29: ='HRH Policy and Planning'!K3 -> 0.2 | G29: ='HRH Policy and Planning'!L3 -> 30
B30: Availability of a national strategic/investment plan for HRH (N = 35) | C30: ='HRH Policy and Planning'!H4 -> 22 | D30: ='HRH Policy and Planning'!I4 -> 13 | E30: ='HRH Policy and Planning'!J4 -> 0.62857143 | F30: ='HRH Policy and Planning'!K4 -> 0.37142857 | G30: ='HRH Policy and Planning'!L4 -> 35
B31: a. What is the period covered by current the HRH plan? | C31: ='HRH Policy and Planning'!H5 -> 6.4166667 | D31: ='HRH Policy and Planning'!I5 -> 0 | E31: ='HRH Policy and Planning'!J5 -> 0 | F31: ='HRH Policy and Planning'!K5 -> 0 | G31: ='HRH Policy and Planning'!L5 -> 0
B32: i. Has the strategy plan been costed? | C32: ='HRH Policy and Planning'!H6 -> 20 | D32: ='HRH Policy and Planning'!I6 -> 5 | E32: ='HRH Policy and Planning'!J6 -> 0.8 | F32: ='HRH Policy and Planning'!K6 -> 0.2 | G32: ='HRH Policy and Planning'!L6 -> 25
B33: ii. Does it include projections of the HRH needs/demand | C33: ='HRH Policy and Planning'!H7 -> 23 | D33: ='HRH Policy and Planning'!I7 -> 2 | E33: ='HRH Policy and Planning'!J7 -> 0.92 | F33: ='HRH Policy and Planning'!K7 -> 0.08 | G33: ='HRH Policy and Planning'!L7 -> 25
B34: iii. Do the projections cover the public and private sectors? | C34: ='HRH Policy and Planning'!H8 -> 4 | D34: ='HRH Policy and Planning'!I8 -> 20 | E34: ='HRH Policy and Planning'!J8 -> 0.16666667 | F34: ='HRH Policy and Planning'!K8 -> 0.83333333 | G34: ='HRH Policy and Planning'!L8 -> 24
B35: 3. If there is a strategic plan, what elements are covered? | C35: Yes | D35: No | E35: % Yes | F35: % No | G35: No Countries that responded out of 47
B36: i. Educational targets (supply of health workforce) | C36: ='HRH Policy and Planning'!H10 -> 21 | D36: ='HRH Policy and Planning'!I10 -> 3 | E36: ='HRH Policy and Planning'!J10 -> 0.875 | F36: ='HRH Policy and Planning'!K10 -> 0.125 | G36: ='HRH Policy and Planning'!L10 -> 24
B37: ii. Recruitment targets (planned new recruitments) | C37: ='HRH Policy and Planning'!H11 -> 21 | D37: ='HRH Policy and Planning'!I11 -> 3 | E37: ='HRH Policy and Planning'!J11 -> 0.875 | F37: ='HRH Policy and Planning'!K11 -> 0.125 | G37: ='HRH Policy and Planning'!L11 -> 24
B38: iii. Deployment and distribution | C38: ='HRH Policy and Planning'!H12 -> 19 | D38: ='HRH Policy and Planning'!I12 -> 5 | E38: ='HRH Policy and Planning'!J12 -> 0.79166667 | F38: ='HRH Policy and Planning'!K12 -> 0.20833333 | G38: ='HRH Policy and Planning'!L12 -> 24
B39: iv. Incentives/retention strategies | C39: ='HRH Policy and Planning'!H13 -> 19 | D39: ='HRH Policy and Planning'!I13 -> 5 | E39: ='HRH Policy and Planning'!J13 -> 0.79166667 | F39: ='HRH Policy and Planning'!K13 -> 0.20833333 | G39: ='HRH Policy and Planning'!L13 -> 24
B40: v. International migration of staff | C40: ='HRH Policy and Planning'!H14 -> 7 | D40: ='HRH Policy and Planning'!I14 -> 16 | E40: ='HRH Policy and Planning'!J14 -> 0.30434783 | F40: ='HRH Policy and Planning'!K14 -> 0.69565217 | G40: ='HRH Policy and Planning'!L14 -> 23
B41: A commitment to increase allocation from national resources to to implement HRH strategy/Investment Plan (N = 26) | C41: ='HRH Policy and Planning'!H15 -> 13 | D41: ='HRH Policy and Planning'!I15 -> 13 | E41: ='HRH Policy and Planning'!J15 -> 0.5 | F41: ='HRH Policy and Planning'!K15 -> 0.5 | G41: ='HRH Policy and Planning'!L15 -> 26
B53: AFR-04 HRH policy, Strategy and plan | C53: Yes | D53: No | E53: % Yes | F53: % No | G53: No Countries that responded out of 47
...
