Workbook
Name Stock_grad_ratio: 'Density vs graduate Stock G (2)'!$AB$49
Name Stock_grad_ratio: 'Density vs graduate Stock Graph'!$AA$49
Name Weighted_average: 'Density vs graduate Stock G (2)'!$AA$49
Name Weighted_average: 'Density vs graduate Stock Graph'!$Z$49

Sheet Stock grad Doctors
A1: Country | B1: 2013 | C1: 2018 | D1: Doctors stock 2022 | E1: Doctors graduates
A2: Algeria | B2: 0 | C2: 73168 | D2: 48033.824 | E2: 0
A3: Angola | B3: 0 | C3: 6593 | D3: 8693 | E3: 611
A4: Benin | B4: 0 | C4: 908 | D4: 2608 | E4: 780
A5: Botswana | B5: 819 | C5: 925 | D5: 992 | E5: 60
A6: Burkina Faso | B6: 803 | C6: 1684 | D6: 3323 | E6: 1492
A7: Burundi | B7: 554 | C7: 1084 | D7: 1014.861 | E7: 325
A8: Cameroon | B8: 1842 | C8: 3259 | D8: 3759 | E8: 800
A9: Cabo Verde | B9: 308 | C9: 452 | D9: 2644 | E9: 0
A10: Central African Republic | B10: 324 | C10: 335 | D10: 146.38958 | E10: 18
A11: Chad | B11: 573 | C11: 803 | D11: 1507 | E11: 330
A12: Comoros | B12: 123 | C12: 220 | D12: 354 | E12: 0
A13: Congo | B13: 0 | C13: 544 | D13: 1042 | E13: 60
... A48: Zimbabwe | B48: 1114 | C48: 3026 | D48: 3131.5984 | E48: 265

Sheet Sheet2
A1: Country | B1: Generalist Medical Practitioners | C1: Specialist Medical Practitioners | D1: Dentists | E1: Other Dental practitioners | F1: Pharmacists | G1: Other Pharmacy practitioners | H1: Midwifery personnel | I1: Nursing Personnel | J1: Medical and Pathology Laboratory scientists | K1: Paramedical Practitioners | L1: Other Health Workers | M1: Total
A2: Algeria | B2: 0 | M2: 0
A3: Angola | B3: 611 | D3: 145 | F3: 529 | I3: 2950 | M3: 4235
A4: Benin | B4: 780 | C4: 385 | F4: 143 | H4: 247 | I4: 257 | J4: 1113 | L4: 1194 | M4: 4119
A5: Botswana | B5: 60 | C5: 48 | D5: 7 | E5: 10 | F5: 95 | G5: 60 | H5: 40 | I5: 490 | J5: 189 | K5: 30 | L5: 597 | M5: 1626
A6: Burkina Faso | B6: 1492 | C6: 385 | D6: 62 | F6: 594 | H6: 1170 | I6: 1170 | M6: 4873
A7: Burundi | B7: 325 | C7: 240 | F7: 39 | H7: 196 | I7: 1467 | J7: 322 | L7: 194 | M7: 2783
A8: Cameroon | B8: 800 | I8: 2660 | J8: 800 | M8: 4260
A9: Cabo Verde | E9: 7 | L9: 83 | M9: 90
A10: Central African Republic | B10: 18 | M10: 18
A11: Chad | B11: 330 | C11: 30 | F11: 80 | G11: 180 | H11: 2084 | I11: 2920 | J11: 220 | M11: 5844
A12: Comoros | H12: 29 | I12: 40 | M12: 69
A13: Congo | B13: 60 | C13: 315 | E13: 10 | G13: 5 | H13: 120 | I13: 60 | K13: 50 | L13: 408 | M13: 1028
A14: Cote d'Ivoire | B14: 254 | C14: 48 | G14: 151 | I14: 1007 | J14: 1106 | L14: 450 | M14: 3016
A15: DRC | B15: 6020 | D15: 66 | F15: 178 | G15: 328 | H15: 3453 | I15: 24061 | J15: 2571 | L15: 3151 | M15: 39828
A16: Equatorial Guinea | B16: 767 | H16: 492 | I16: 962 | J16: 27 | L16: 1304 | M16: 3552
A17: Eritrea | I17: 400 | L17: 1023 | M17: 1423
A18: Eswatini | F18: 44 | G18: 30 | H18: 80 | I18: 160 | J18: 78 | L18: 58 | M18: 450
A19: Ethiopia | B19: 3114 | C19: 880 | D19: 189 | E19: 64 | F19: 699 | G19: 2878 | H19: 2440 | I19: 6298 | J19: 1220 | K19: 1613 | L19: 3672 | M19: 23067
A20: Gabon | B20: 46 | C20: 16 | F20: 2 | H20: 34 | I20: 95 | J20: 6 | M20: 199
A21: Gambia | B21: 23 | I21: 137 | J21: 6 | M21: 166
A22: Ghana | B22: 1566 | F22: 343 | H22: 4827 | I22: 21271 | J22: 396 | M22: 28403
A23: Guinea | B23: 767 | C23: 74 | F23: 113 | G23: 34 | H23: 492 | I23: 964 | J23: 27 | L23: 1304 | M23: 3775
A24: Guinea-Bissau | J24: 23 | L24: 489 | M24: 512
A25: Kenya | B25: 558 | D25: 36 | F25: 379 | G25: 20 | I25: 1070 | J25: 519 | L25: 366 | M25: 2948
A26: Lesotho | B26: 8 | C26: 22 | D26: 8 | F26: 33 | G26: 20 | H26: 69 | I26: 376 | J26: 20 | M26: 556
A27: Liberia | B27: 29 | C27: 50 | F27: 22 | I27: 63 | J27: 56 | L27: 50 | M27: 270
A28: Madagascar | B28: 316 | C28: 156 | H28: 2473 | I28: 2540 | J28: 116 | L28: 297 | M28: 5898
A29: Malawi | B29: 115 | C29: 167 | F29: 110 | G29: 189 | H29: 1171 | I29: 386 | J29: 175 | L29: 616 | M29: 2929
A30: Mali | M30: 0
A31: Mauritania | C31: 76 | I31: 113 | L31: 366 | M31: 555
A32: Mauritius | B32: 432 | H32: 40 | I32: 175 | L32: 39 | M32: 686
A33: Mozambique | B33: 819 | C33: 146 | D33: 161 | G33: 112 | H33: 140 | I33: 580 | J33: 248 | K33: 20 | M33: 2226
A34: Namibia | B34: 475 | C34: 3 | F34: 247 | G34: 31 | H34: 1414 | I34: 200 | J34: 121 | L34: 175 | M34: 2666
A35: Niger | B35: 370 | C35: 14 | H35: 124 | I35: 305 | J35: 45 | L35: 1891 | M35: 2749
A36: Nigeria | B36: 4340 | D36: 459 | H36: 375 | I36: 12835 | J36: 1774 | M36: 19783
A37: Rwanda | B37: 11 | F37: 95 | H37: 176 | I37: 355 | L37: 81 | M37: 718
A38: Sao Tome and Principe | M38: 0
A39: Senegal | B39: 434 | C39: 137 | D39: 67 | F39: 171 | H39: 104 | I39: 582 | J39: 36 | L39: 710 | M39: 2241
A40: Seychelles | B40: 10 | G40: 20 | H40: 10 | I40: 40 | L40: 80 | M40: 160
...

Sheet Nurses
A1: Country | B1: 2013 | C1: 2018 | D1: Nurses Stock 2022 | E1: Nurses Graduates
A2: Algeria | B2: 0 | C2: 57705 | D2: 5043.8935 | E2: 0
A3: Angola | B3: 0 | C3: 46082 | D3: 66717.354 | E3: 2950
A4: Benin | B4: 4880 | C4: 3410 | D4: 5893 | E4: 257
A5: Botswana | B5: 5816 | C5: 7645 | D5: 8028 | E5: 490
A6: Burkina Faso | B6: 6196 | C6: 10325 | D6: 13961 | E6: 1170
A7: Burundi | B7: 6573 | C7: 9156 | D7: 9372 | E7: 1467
A8: Cameroon | B8: 18954 | C8: 9925 | D8: 16473 | E8: 2660
A9: Cabo Verde | B9: 403 | C9: 768 | D9: 941 | E9: 0
A10: Central African Republic | B10: 322 | C10: 1195 | D10: 648.48015 | E10: 0
A11: Chad | B11: 3606 | C11: 4799 | D11: 3387.1517 | E11: 2920
A12: Comoros | B12: 0 | C12: 747 | D12: 784.97097 | E12: 40
A13: Congo | B13: 3289 | C13: 5081 | D13: 5573 | E13: 60
... A48: Zimbabwe | B48: 18722 | C48: 27874 | D48: 46537 | E48: 1100

Sheet DoctNurses
A1: Country | B1: Doctors stock 2022 | C1: Doctors graduates | D1: Nurses Stock 2022 | E1: Nurses Graduates | F1: Doctors and Nurses Stock 2022 | G1: Doctors and Nurses graduates
A2: Algeria | B2: 48033.824 | C2: 0 | D2: 5043.8935 | E2: 0 | F2: =B2+D2 -> 53077.718
A3: Angola | B3: 8693 | C3: 611 | D3: 66717.354 | E3: 2950 | F3: =B3+D3 -> 75410.354 | G3: =C3+E3 -> 3561 | H3: =E3/C3 -> 4.8281506
A4: Benin | B4: 2608 | C4: 780 | D4: 5893 | E4: 257 | F4: =B4+D4 -> 8501 | G4: =C4+E4 -> 1037 | H4: =E4/C4 -> 0.32948718
A5: Botswana | B5: 992 | C5: 60 | D5: 8028 | E5: 490 | F5: =B5+D5 -> 9020 | G5: =C5+E5 -> 550 | H5: =E5/C5 -> 8.1666667
A6: Burkina Faso | B6: 3323 | C6: 1492 | D6: 13961 | E6: 1170 | F6: =B6+D6 -> 17284 | G6: =C6+E6 -> 2662 | H6: =E6/C6 -> 0.78418231
A7: Burundi | B7: 1014.861 | C7: 325 | D7: 9372 | E7: 1467 | F7: =B7+D7 -> 10386.861 | G7: =C7+E7 -> 1792 | H7: =E7/C7 -> 4.5138462
A8: Cameroon | B8: 3759 | C8: 800 | D8: 16473 | E8: 2660 | F8: =B8+D8 -> 20232 | G8: =C8+E8 -> 3460 | H8: =E8/C8 -> 3.325
A9: Cabo Verde | B9: 2644 | C9: 0 | D9: 941 | E9: 0 | F9: =B9+D9 -> 3585
A10: Central African Republic | B10: 146.38958 | C10: 18 | D10: 648.48015 | E10: 0 | F10: =B10+D10 -> 794.86973 | G10: =C10+E10 -> 18
A11: Chad | B11: 1507 | C11: 330 | D11: 3387.1517 | E11: 2920 | F11: =B11+D11 -> 4894.1517 | G11: =C11+E11 -> 3250 | H11: =E11/C11 -> 8.8484848
A12: Comoros | B12: 354 | C12: 0 | D12: 784.97097 | E12: 40 | F12: =B12+D12 -> 1138.971 | G12: =C12+E12 -> 40
A13: Congo | B13: 1042 | C13: 60 | D13: 5573 | E13: 60 | F13: =B13+D13 -> 6615 | G13: =C13+E13 -> 120 | H13: =E13/C13 -> 1
A14: Cote d'Ivoire | B14: 6327.552 | C14: 254 | D14: 19225.233 | E14: 1007 | F14: =B14+D14 -> 25552.785 | G14: =C14+E14 -> 1261 | H14: =E14/C14 -> 3.9645669
A15: DRC | B15: 21289.959 | C15: 6020 | D15: 115316 | E15: 24061 | F15: =B15+D15 -> 136605.96 | G15: =C15+E15 -> 30081 | H15: =E15/C15 -> 3.9968439
A16: Equatorial Guinea | B16: 274.68238 | C16: 767 | D16: 1375 | E16: 962 | F16: =B16+D16 -> 1649.6824 | G16: =C16+E16 -> 1729 | H16: =E16/C16 -> 1.2542373
A17: Eritrea | B17: 298.81765 | C17: 0 | D17: 5007 | E17: 400 | F17: =B17+D17 -> 5305.8176 | G17: =C17+E17 -> 400
A18: Eswatini | B18: 687 | C18: 0 | D18: 5242 | E18: 160 | F18: =B18+D18 -> 5929 | G18: =C18+E18 -> 160
A19: Ethiopia | B19: 23741 | C19: 3114 | D19: 131262 | E19: 6298 | F19: =B19+D19 -> 155003 | G19: =C19+E19 -> 9412 | H19: =E19/C19 -> 2.0224791
A20: Gabon | B20: 1265.3898 | C20: 46 | D20: 4751.5999 | E20: 95 | F20: =B20+D20 -> 6016.9897 | G20: =C20+E20 -> 141 | H20: =E20/C20 -> 2.0652174
A21: Gambia | B21: 273.86723 | C21: 23 | D21: 1429.4037 | E21: 137 | F21: =B21+D21 -> 1703.2709 | G21: =C21+E21 -> 160 | H21: =E21/C21 -> 5.9565217
A22: Ghana | B22: 4726 | C22: 1566 | D22: 124204.28 | E22: 21271 | F22: =B22+D22 -> 128930.28 | G22: =C22+E22 -> 22837 | H22: =E22/C22 -> 13.583014
A23: Guinea | B23: 341.3417 | C23: 767 | D23: 5018.9872 | E23: 964 | F23: =B23+D23 -> 5360.3289 | G23: =C23+E23 -> 1731 | H23: =E23/C23 -> 1.2568449
A24: Guinea-Bissau | B24: 530.87376 | C24: 0 | D24: 1879 | E24: 0 | F24: =B24+D24 -> 2409.8738
A25: Kenya | B25: 12792 | C25: 558 | D25: 109659 | E25: 1070 | F25: =B25+D25 -> 122451 | G25: =C25+E25 -> 1628 | H25: =E25/C25 -> 1.9175627
A26: Lesotho | B26: 536.60978 | C26: 8 | D26: 1235.4801 | E26: 376 | F26: =B26+D26 -> 1772.0899 | G26: =C26+E26 -> 384 | H26: =E26/C26 -> 47
A27: Liberia | B27: 954 | C27: 29 | D27: 4423.7953 | E27: 63 | F27: =B27+D27 -> 5377.7953 | G27: =C27+E27 -> 92 | H27: =E27/C27 -> 2.1724138
A28: Madagascar | B28: 5230 | C28: 316 | D28: 4560 | E28: 2540 | F28: =B28+D28 -> 9790 | G28: =C28+E28 -> 2856 | H28: =E28/C28 -> 8.0379747
A29: Malawi | B29: 1103.5638 | C29: 115 | D29: 9592 | E29: 386 | F29: =B29+D29 -> 10695.564 | G29: =C29+E29 -> 501 | H29: =E29/C29 -> 3.3565217
A30: Mali | B30: 4402 | C30: 0 | D30: 6327 | E30: 0 | F30: =B30+D30 -> 10729
A31: Mauritania | B31: 1273.0347 | C31: 0 | D31: 6503 | E31: 113 | F31: =B31+D31 -> 7776.0347 | G31: =C31+E31 -> 113
A32: Mauritius | B32: 1833.6555 | C32: 432 | D32: 4598.8787 | E32: 175 | F32: =B32+D32 -> 6432.5342 | G32: =C32+E32 -> 607 | H32: =E32/C32 -> 0.40509259
A33: Mozambique | B33: 5719 | C33: 819 | D33: 17168 | E33: 580 | F33: =B33+D33 -> 22887 | G33: =C33+E33 -> 1399 | H33: =E33/C33 -> 0.70818071
A34: Namibia | B34: 1597 | C34: 475 | D34: 15558.322 | E34: 200 | F34: =B34+D34 -> 17155.322 | G34: =C34+E34 -> 675 | H34: =E34/C34 -> 0.42105263
A35: Niger | B35: 705.66937 | C35: 370 | D35: 4565 | E35: 305 | F35: =B35+D35 -> 5270.6694 | G35: =C35+E35 -> 675 | H35: =E35/C35 -> 0.82432432
A36: Nigeria | B36: 86181 | C36: 4340 | D36: 220681 | E36: 12835 | F36: =B36+D36 -> 306862 | G36: =C36+E36 -> 17175 | H36: =E36/C36 -> 2.9573733
A37: Rwanda | B37: 1648 | C37: 11 | D37: 13501.24 | E37: 355 | F37: =B37+D37 -> 15149.24 | G37: =C37+E37 -> 366 | H37: =E37/C37 -> 32.272727
A38: Sao Tome and Principe | B38: 105 | C38: 0 | D38: 440 | E38: 0 | F38: =B38+D38 -> 545
A39: Senegal | B39: 2560.8623 | C39: 434 | D39: 4737 | E39: 582 | F39: =B39+D39 -> 7297.8623 | G39: =C39+E39 -> 1016 | H39: =E39/C39 -> 1.3410138
A40: Seychelles | B40: 828 | C40: 10 | D40: 1277 | E40: 40 | F40: =B40+D40 -> 2105 | G40: =C40+E40 -> 50 | H40: =E40/C40 -> 4
...

Sheet All workforce stock
C1: Core health workforce* | F1: Other workers | I1: Total
A2: S No | B2: Country | C2: 2013 | D2: 2018 | E2: Adjusted 2022 | F2: 2013 | G2: 2018 | H2: Adjusted 2022 | I2: 2013 | J2: 2018 | K2: Adjusted 2022
A3: 1 | B3: Algeria | C3: 11139 | D3: 175647 | E3: 74186.82 | F3: 200 | G3: 240105 | H3: 366963.78 | I3: 11339 | J3: 415752 | K3: 441150.6
A4: 2 | B4: Angola | C4: 30 | D4: 60468 | E4: 78869.769 | F4: 602 | G4: 50395 | H4: 58067.47 | I4: 632 | J4: 110863 | K4: 136937.24
A5: 3 | B5: Benin | C5: 7923 | D5: 5769 | E5: 11051.475 | F5: 15066 | G5: 11707 | H5: 13972.937 | I5: 22989 | J5: 17476 | K5: 25024.412
A6: 4 | B6: Botswana | C6: 8191 | D6: 9284 | E6: 9739.0852 | F6: 1000 | G6: 7514 | H6: 8210.398 | I6: 9191 | J6: 16798 | K6: 17949.483
A7: 5 | B7: Burkina Faso | C7: 8983 | D7: 19646 | E7: 27591.375 | F7: 4585 | G7: 7601 | H7: 10576.497 | I7: 13568 | J7: 27247 | K7: 38167.872
A8: 6 | B8: Burundi | C8: 7170 | D8: 10533 | E8: 10709.32 | F8: 44 | G8: 37621 | H8: 42120.333 | I8: 7214 | J8: 48154 | K8: 52829.653
A9: 7 | B9: Cameroon | C9: 22321 | D9: 14532 | E9: 23282 | F9: 0 | G9: 16843 | H9: 8354.2378 | I9: 22321 | J9: 31375 | K9: 31636.238
A10: 8 | B10: Cape-Verde | C10: 711 | D10: 1666 | E10: 3734.4936 | F10: 7662 | G10: 5297 | H10: 2475.7981 | I10: 8373 | J10: 6963 | K10: 6210.2918
A11: 9 | B11: Central African Republic | C11: 1180 | D11: 2027 | E11: 1344.0062 | F11: 384 | G11: 1029 | H11: 4353.7072 | I11: 1564 | J11: 3056 | K11: 5697.7134
A12: 10 | B12: Chad | C12: 4702 | D12: 6992 | E12: 6338.6323 | F12: 1664 | G12: 3800 | H12: 33923.737 | I12: 6366 | J12: 10792 | K12: 40262.37
A13: 11 | B13: Comoros | C13: 452 | D13: 1541 | E13: 1868.1964 | F13: 841 | G13: 1215 | H13: 753.73247 | I13: 1293 | J13: 2756 | K13: 2621.9289
A14: 12 | B14: Congo | C14: 4571 | D14: 6962 | E14: 7791.8818 | F14: 4923 | G14: 3307 | H14: 4346 | I14: 9494 | J14: 10269 | K14: 12137.882
... A50: 48 | B50: AFRO | C50: 841834 | D50: 1994699 | E50: 2460099.1 | F50: 724195 | G50: 2312731 | H50: 2488957.6 | I50: 1566029 | J50: 4307430 | K50: 4949056.7

Sheet All workforce density 
B1: Core health workforce* | E1: Other workers | H1: Total
A2: Country | B2: Density per 10,000 (2013) | C2: Density per 10,000 (2018) | D2: Density per 10,000 (2022) | E2: Density per 10,000 (2013) | F2: Density per 10,000 (2018) | G2: Density per 10,000 (2022) | H2: Density per 10,000 (2013) | I2: Density per 10,000 (2018) | J2: Density per 10,000 (2022)
A3: Algeria | B3: 2.9312675 | C3: 41.893522 | D3: 16.52149 | E3: 0.052630711 | F3: 57.06799 | G3: 81.537078 | H3: 2.9838982 | I3: 98.961512 | J3: 98.058569
A4: Angola | B4: 0.011473591 | C4: 19.3352 | D4: 22.161285 | E4: 0.23023672 | F4: 16.090283 | G4: 16.295061 | H4: 0.24171031 | I4: 35.425483 | J4: 38.456346
A5: Benin | B5: 7.6857184 | C5: 4.8313817 | D5: 8.2764832 | E5: 14.614797 | F5: 9.7917343 | G5: 10.453141 | H5: 22.300515 | I5: 14.623116 | J5: 18.729624
A6: Botswana | B6: 36.941692 | C6: 37.872105 | D6: 37.026575 | E6: 4.5100344 | F6: 30.541625 | G6: 31.089269 | H6: 41.451726 | I6: 68.41373 | J6: 68.115844
A7: Burkina Faso | B7: 5.0934409 | C7: 9.6338287 | D7: 12.168856 | E7: 2.5997358 | F7: 3.7258389 | G7: 4.658467 | H7: 7.6931767 | I7: 13.359668 | J7: 16.827323
A8: Burundi | B8: 7.0643335 | C8: 9.1643322 | D8: 8.3085116 | E8: 0.043351558 | F8: 32.732492 | G8: 32.677826 | H8: 7.107685 | I8: 41.896824 | J8: 40.986337
A9: Cameroon | B9: 10.318104 | C9: 5.7950101 | D9: 8.3404573 | E9: 0 | F9: 6.716581 | G9: 2.9859847 | H9: 10.318104 | I9: 12.511591 | J9: 11.326442
A10: Cape-Verde | B10: 13.16813 | C10: 29.16659 | D10: 62.960411 | E10: 141.90466 | F10: 92.384211 | G10: 41.402684 | H10: 155.07279 | I10: 121.5508 | J10: 104.3631
A11: Central African Republic | B11: 2.4570902 | C11: 3.978582 | D11: 2.408983 | E11: 0.79959545 | F11: 2.0177515 | G11: 7.8017481 | H11: 3.2566857 | I11: 5.9963335 | J11: 10.210731
A12: Chad | B12: 3.5576024 | C12: 4.480842 | D12: 3.5764373 | E12: 1.2590069 | F12: 2.4352402 | G12: 19.134535 | H12: 4.8166093 | I12: 6.9160823 | J12: 22.710972
A13: Comoros | B13: 6.4627516 | C13: 19.850228 | D13: 22.32619 | E13: 12.024721 | F13: 15.650894 | G13: 9.0076044 | H13: 18.487473 | I13: 35.501122 | J13: 31.333795
A14: Congo | B14: 9.4675581 | C14: 12.795296 | D14: 13.050801 | E14: 10.196628 | F14: 6.0778576 | G14: 7.279215 | H14: 19.664186 | I14: 18.873154 | J14: 20.330016
... A50: AFRO | B50: 11.136507 | C50: 23.57697 | D50: 26.089625 | E50: 8.3497581 | F50: 26.690657 | G50: 27.338421 | H50: 19.486265 | I50: 50.267627 | J50: 53.428046

Sheet Education capacity
A1: Country | B1: Generalist Medical Practitioners | C1: Specialist Medical Practitioners | D1: Dentists | E1: Other Dental practitioners | F1: Pharmacists | G1: Other Pharmacy practitioners | H1: Midwifery personnel | I1: Nursing Personnel | J1: Medical and Pathology Laboratory scientists | K1: Paramedical Practitioners | L1: Other Health Workers | M1: Total | N1: Data Sorce(s)
A2: Algeria | B2: 0 | M2: =SUM(B2:L2) -> 0 | N2: NHWA dataset, 2023
A3: Angola | B3: 611 | D3: 145 | F3: 529 | I3: 2950 | M3: =SUM(B3:L3) -> 4235 | N3: Dent-2018;
A4: Benin | B4: 780 | C4: 385 | F4: 143 | H4: 247 | I4: 257 | J4: 1113 | L4: 1194 | M4: =SUM(B4:L4) -> 4119 | N4: Med-2021; Pharm-2021;Mid-2021; Nur-2021;Biom-2021; others-2021
A5: Botswana | B5: 60 | C5: 48 | D5: 7 | E5: 10 | F5: 95 | G5: 60 | H5: 40 | I5: 490 | J5: 189 | K5: 30 | L5: 597 | M5: =SUM(B5:L5) -> 1626 | N5: 2022 for all
A6: Burkina Faso | B6: 1492 | C6: 385 | D6: 62 | F6: 594 | H6: 1170 | I6: 1170 | M6: =SUM(B6:L6) -> 4873 | N6: NHWA dataset, 2023
A7: Burundi | B7: 325 | C7: 240 | F7: 39 | H7: 196 | I7: 1467 | J7: 322 | L7: 194 | M7: =SUM(B7:L7) -> 2783 | N7: 2018 dataset
A8: Cameroon | B8: 800 | I8: 2660 | J8: 800 | M8: =SUM(B8:L8) -> 4260 | N8: NHWA dataset, 2023
A9: Cabo Verde | E9: 7 | L9: 83 | M9: =SUM(B9:L9) -> 90 | N9: NHWA dataset, 2023
A10: Central African Republic | B10: 18 | M10: =SUM(B10:L10) -> 18 | N10: NHWA dataset, 2023
A11: Chad | B11: 330 | C11: 30 | F11: 80 | G11: 180 | H11: 2084 | I11: 2920 | J11: 220 | M11: =SUM(B11:L11) -> 5844 | N11: NHWA dataset, 2023
A12: Comoros | H12: 29 | I12: 40 | M12: =SUM(B12:L12) -> 69 | N12: 2021 for all
A13: Congo | B13: 60 | C13: 315 | E13: 10 | G13: 5 | H13: 120 | I13: 60 | K13: 50 | L13: 408 | M13: =SUM(B13:L13) -> 1028 | N13: 2022 for all
A14: Cote d'Ivoire | B14: 254 | C14: 48 | G14: 151 | I14: 1007 | J14: 1106 | L14: 450 | M14: =SUM(B14:L14) -> 3016 | N14: NHWA dataset, 2023
A15: Democratic Republic of the Congo | B15: 6020 | D15: 66 | F15: 178 | G15: 328 | H15: 3453 | I15: 24061 | J15: 2571 | L15: 3151 | M15: 39828 | N15: NHWA dataset, 2023
A16: Equatorial Guinea | B16: 767 | H16: 492 | I16: 962 | J16: 27 | L16: 1304 | M16: =SUM(B16:L16) -> 3552 | N16: NHWA dataset, 2023
A17: Eritrea | I17: 400 | L17: 1023 | M17: =SUM(B17:L17) -> 1423 | N17: Nurs-2022
A18: Eswatini | F18: 44 | G18: 30 | H18: 80 | I18: 160 | J18: 78 | L18: 58 | M18: =SUM(B18:L18) -> 450 | N18: NHWA dataset, 2023
A19: Ethiopia | B19: 3114 | C19: 880 | D19: 189 | E19: 64 | F19: 699 | G19: 2878 | H19: 2440 | I19: 6298 | J19: 1220 | K19: 1613 | L19: 3672 | M19: =SUM(B19:L19) -> 23067 | N19: pharmacist from 2018
A20: Gabon | B20: 46 | C20: 16 | F20: 2 | H20: 34 | I20: 95 | J20: 6 | M20: =SUM(B20:L20) -> 199 | N20: NHWA dataset, 2023
A21: Gambia | B21: 23 | I21: 137 | J21: 6 | M21: =SUM(B21:L21) -> 166 | N21: NHWA dataset, 2023
A22: Ghana | B22: 1566 | F22: 343 | H22: 4827 | I22: 21271 | J22: 396 | M22: =SUM(B22:L22) -> 28403 | N22: HLMA 2023; Ismaila (2023)
A23: Guinea | B23: 767 | C23: 74 | F23: 113 | G23: 34 | H23: 492 | I23: 964 | J23: 27 | L23: 1304 | M23: =SUM(B23:L23) -> 3775 | N23: NHWA dataset, 2023
A24: Guinea-Bissau | J24: 23 | L24: 489 | M24: =SUM(B24:L24) -> 512 | N24: NHWA dataset, 2023
A25: Kenya | B25: 558 | D25: 36 | F25: 379 | G25: 20 | I25: 1070 | J25: 519 | L25: 366 | M25: =SUM(B25:L25) -> 2948 | N25: HLMA data, Dentist-2018; CMHW-2022; Biom -2018;
A26: Lesotho | B26: 8 | C26: 22 | D26: 8 | F26: 33 | G26: 20 | H26: 69 | I26: 376 | J26: 20 | M26: =SUM(B26:L26) -> 556 | N26: NHWA dataset, 2023
A27: Liberia | B27: 29 | C27: 50 | F27: 22 | I27: 63 | J27: 56 | L27: 50 | M27: =SUM(B27:L27) -> 270 | N27: NHWA dataset, 2023
A28: Madagascar | B28: 316 | C28: 156 | H28: 2473 | I28: 2540 | J28: 116 | L28: 297 | M28: =SUM(B28:L28) -> 5898 | N28: NHWA dataset, 2023
A29: Malawi | B29: 115 | C29: 167 | F29: 110 | G29: 189 | H29: 1171 | I29: 386 | J29: 175 | L29: 616 | M29: =SUM(B29:L29) -> 2929 | N29: NHWA dataset, 2023
A30: Mali | M30: =SUM(B30:L30) -> 0 | N30: NHWA dataset, 2023
A31: Mauritania | C31: 76 | I31: 113 | L31: 366 | M31: =SUM(B31:L31) -> 555 | N31: NHWA dataset, 2023
A32: Mauritius | B32: 432 | H32: 40 | I32: 175 | L32: 39 | M32: =SUM(B32:L32) -> 686 | N32: SADC dataset, 2022
A33: Mozambique | B33: 819 | C33: 146 | D33: 161 | G33: 112 | H33: 140 | I33: 580 | J33: 248 | K33: 20 | M33: =SUM(B33:L33) -> 2226 | N33: capacity-HLMA data extracted
A34: Namibia | B34: 475 | C34: 3 | F34: 247 | G34: 31 | H34: 1414 | I34: 200 | J34: 121 | L34: 175 | M34: =SUM(B34:L34) -> 2666 | N34: NHWA dataset, 2023; HLMA dataset, 2019; 2018 survey dataset
A35: Niger | B35: 370 | C35: 14 | H35: 124 | I35: 305 | J35: 45 | L35: 1891 | M35: =SUM(B35:L35) -> 2749 | N35: Med-2021,2022; Nurs-2022; Midw-2022; Other-2021,2022, CHW-2021
A36: Nigeria | B36: 4340 | D36: 459 | H36: 375 | I36: 12835 | J36: 1774 | M36: =SUM(B36:L36) -> 19783 | N36: NHWA dataset, 2023
A37: Rwanda | B37: 11 | F37: 95 | H37: 176 | I37: 355 | L37: 81 | M37: =SUM(B37:L37) -> 718 | N37: NHWA dataset, 2023
A38: Sao Tome and Principe | M38: =SUM(B38:L38) -> 0 | N38: NHWA dataset, 2023
A39: Senegal | B39: 434 | C39: 137 | D39: 67 | F39: 171 | H39: 104 | I39: =288+294 -> 582 | J39: 36 | L39: 710 | M39: =SUM(B39:L39) -> 2241 | N39: NHWA dataset, 2023
A40: Seychelles | B40: 10 | G40: 20 | H40: 10 | I40: 40 | L40: 80 | M40: =SUM(B40:L40) -> 160 | N40: NHWA dataset, 2023
...

Sheet Combined density-grad-stock
A1: FORBIDDEN CELL FOR JAMES | E1: Country | F1: Density per 10,000 (2022) | G1: Doctors and Nurses Stock 2022 | H1: Doctors and Nurses graduates | I1: Ratio stock to graduates | J1: categories | K1: Density quartile | AF1: Country | AG1: categories | AH1: Density quartile | AI1: Fiscal space
C2: Density quartiles | E2: Algeria | F2: 98.058569 | G2: 53077.718 | I2: =IF(H2=0,I$52,G2/H2) -> 22.857936 | J2: =IF(I2<10,"4. Very rapid education production - Less than 10 stock to grad",IF(AND(I2>=10,I2<20),"3. Rapid education production - 10 to 20 stock to grad",IF(AND(I2>=20,I2<30),"2. Slow education production - 20 to 30 stock to grad","1. Very slow education production - 30 stock to grad and more"))) -> 2. Slow education production - 20 to 30 stock to grad | K2: =IF(F2<D$3,"1. <Q1 density",IF(AND(F2>=D$3,F2<D$4),"2. Q1-Median density",IF(AND(F2>=D$4,F2<D$5),"3. Median-Q3 density","4. >Q3 density"))) -> 4. >Q3 density | AF2: Central African Republic | AG2: 1. Very slow education production - 30 stock to grad and more | AH2: 1. <Q1 density
C3: Q1 | D3: =PERCENTILE(F2:F48,0.25) -> 22.33987 | E3: Angola | F3: 38.456346 | G3: 75410.354 | H3: 3561 | I3: =IF(H3=0,I$52,G3/H3) -> 21.176735 | J3: =IF(I3<10,"4. Very rapid education production - Less than 10 stock to grad",IF(AND(I3>=10,I3<20),"3. Rapid education production - 10 to 20 stock to grad",IF(AND(I3>=20,I3<30),"2. Slow education production - 20 to 30 stock to grad","1. Very slow education production - 30 stock to grad and more"))) -> 2. Slow education production - 20 to 30 stock to grad | K3: =IF(F3<D$3,"1. <Q1 density",IF(AND(F3>=D$3,F3<D$4),"2. Q1-Median density",IF(AND(F3>=D$4,F3<D$5),"3. Median-Q3 density","4. >Q3 density"))) -> 3. Median-Q3 density | AF3: Congo | AG3: 1. Very slow education production - 30 stock to grad and more | AH3: 1. <Q1 density
C4: Median | D4: =MEDIAN(F2:F48) -> 38.456346 | E4: Benin | F4: 18.729624 | G4: 8501 | H4: 1037 | I4: =IF(H4=0,I$52,G4/H4) -> 8.1976856 | J4: =IF(I4<10,"4. Very rapid education production - Less than 10 stock to grad",IF(AND(I4>=10,I4<20),"3. Rapid education production - 10 to 20 stock to grad",IF(AND(I4>=20,I4<30),"2. Slow education production - 20 to 30 stock to grad","1. Very slow education production - 30 stock to grad and more"))) -> 4. Very rapid education production - Less than 10 stock to grad | K4: =IF(F4<D$3,"1. <Q1 density",IF(AND(F4>=D$3,F4<D$4),"2. Q1-Median density",IF(AND(F4>=D$4,F4<D$5),"3. Median-Q3 density","4. >Q3 density"))) -> 1. <Q1 density | AF4: Malawi | AG4: 2. Slow education production - 20 to 30 stock to grad | AH4: 1. <Q1 density
C5: Q3 | D5: =PERCENTILE(F2:F48,0.75) -> 63.718104 | E5: Botswana | F5: 68.115844 | G5: 9020 | H5: 550 | I5: =IF(H5=0,I$52,G5/H5) -> 16.4 | J5: =IF(I5<10,"4. Very rapid education production - Less than 10 stock to grad",IF(AND(I5>=10,I5<20),"3. Rapid education production - 10 to 20 stock to grad",IF(AND(I5>=20,I5<30),"2. Slow education production - 20 to 30 stock to grad","1. Very slow education production - 30 stock to grad and more"))) -> 3. Rapid education production - 10 to 20 stock to grad | K5: =IF(F5<D$3,"1. <Q1 density",IF(AND(F5>=D$3,F5<D$4),"2. Q1-Median density",IF(AND(F5>=D$4,F5<D$5),"3. Median-Q3 density","4. >Q3 density"))) -> 4. >Q3 density | AF5: Mali | AG5: 2. Slow education production - 20 to 30 stock to grad | AH5: 1. <Q1 density
E6: Burkina Faso | F6: 16.827323 | G6: 17284 | H6: 2662 | I6: =IF(H6=0,I$52,G6/H6) -> 6.4928625 | J6: =IF(I6<10,"4. Very rapid education production - Less than 10 stock to grad",IF(AND(I6>=10,I6<20),"3. Rapid education production - 10 to 20 stock to grad",IF(AND(I6>=20,I6<30),"2. Slow education production - 20 to 30 stock to grad","1. Very slow education production - 30 stock to grad and more"))) -> 4. Very rapid education production - Less than 10 stock to grad | K6: =IF(F6<D$3,"1. <Q1 density",IF(AND(F6>=D$3,F6<D$4),"2. Q1-Median density",IF(AND(F6>=D$4,F6<D$5),"3. Median-Q3 density","4. >Q3 density"))) -> 1. <Q1 density | AF6: South Sudan | AG6: 2. Slow education production - 20 to 30 stock to grad | AH6: 1. <Q1 density
E7: Burundi | F7: 40.986337 | G7: 10386.861 | H7: 1792 | I7: =IF(H7=0,I$52,G7/H7) -> 5.7962394 | J7: =IF(I7<10,"4. Very rapid education production - Less than 10 stock to grad",IF(AND(I7>=10,I7<20),"3. Rapid education production - 10 to 20 stock to grad",IF(AND(I7>=20,I7<30),"2. Slow education production - 20 to 30 stock to grad","1. Very slow education production - 30 stock to grad and more"))) -> 4. Very rapid education production - Less than 10 stock to grad | K7: =IF(F7<D$3,"1. <Q1 density",IF(AND(F7>=D$3,F7<D$4),"2. Q1-Median density",IF(AND(F7>=D$4,F7<D$5),"3. Median-Q3 density","4. >Q3 density"))) -> 3. Median-Q3 density | AF7: Benin | AG7: 4. Very rapid education production - Less than 10 stock to grad | AH7: 1. <Q1 density
E8: Cameroon | F8: 11.326442 | G8: 20232 | H8: 3460 | I8: =IF(H8=0,I$52,G8/H8) -> 5.8473988 | J8: =IF(I8<10,"4. Very rapid education production - Less than 10 stock to grad",IF(AND(I8>=10,I8<20),"3. Rapid education production - 10 to 20 stock to grad",IF(AND(I8>=20,I8<30),"2. Slow education production - 20 to 30 stock to grad","1. Very slow education production - 30 stock to grad and more"))) -> 4. Very rapid education production - Less than 10 stock to grad | K8: =IF(F8<D$3,"1. <Q1 density",IF(AND(F8>=D$3,F8<D$4),"2. Q1-Median density",IF(AND(F8>=D$4,F8<D$5),"3. Median-Q3 density","4. >Q3 density"))) -> 1. <Q1 density | AF8: Burkina Faso | AG8: 4. Very rapid education production - Less than 10 stock to grad | AH8: 1. <Q1 density
E9: Cape-Verde | F9: 104.3631 | G9: 3585 | I9: =IF(H9=0,I$52,G9/H9) -> 22.857936 | J9: =IF(I9<10,"4. Very rapid education production - Less than 10 stock to grad",IF(AND(I9>=10,I9<20),"3. Rapid education production - 10 to 20 stock to grad",IF(AND(I9>=20,I9<30),"2. Slow education production - 20 to 30 stock to grad","1. Very slow education production - 30 stock to grad and more"))) -> 2. Slow education production - 20 to 30 stock to grad | K9: =IF(F9<D$3,"1. <Q1 density",IF(AND(F9>=D$3,F9<D$4),"2. Q1-Median density",IF(AND(F9>=D$4,F9<D$5),"3. Median-Q3 density","4. >Q3 density"))) -> 4. >Q3 density | AF9: Cameroon | AG9: 4. Very rapid education production - Less than 10 stock to grad | AH9: 1. <Q1 density
E10: Central African Republic | F10: 10.210731 | G10: 794.86973 | H10: 18 | I10: =IF(H10=0,I$52,G10/H10) -> 44.159429 | J10: =IF(I10<10,"4. Very rapid education production - Less than 10 stock to grad",IF(AND(I10>=10,I10<20),"3. Rapid education production - 10 to 20 stock to grad",IF(AND(I10>=20,I10<30),"2. Slow education production - 20 to 30 stock to grad","1. Very slow education production - 30 stock to grad and more"))) -> 1. Very slow education production - 30 stock to grad and more | K10: =IF(F10<D$3,"1. <Q1 density",IF(AND(F10>=D$3,F10<D$4),"2. Q1-Median density",IF(AND(F10>=D$4,F10<D$5),"3. Median-Q3 density","4. >Q3 density"))) -> 1. <Q1 density | AF10: DRC | AG10: 4. Very rapid education production - Less than 10 stock to grad | AH10: 1. <Q1 density
E11: Chad | F11: 22.710972 | G11: 4894.1517 | H11: 3250 | I11: =IF(H11=0,I$52,G11/H11) -> 1.5058928 | J11: =IF(I11<10,"4. Very rapid education production - Less than 10 stock to grad",IF(AND(I11>=10,I11<20),"3. Rapid education production - 10 to 20 stock to grad",IF(AND(I11>=20,I11<30),"2. Slow education production - 20 to 30 stock to grad","1. Very slow education production - 30 stock to grad and more"))) -> 4. Very rapid education production - Less than 10 stock to grad | K11: =IF(F11<D$3,"1. <Q1 density",IF(AND(F11>=D$3,F11<D$4),"2. Q1-Median density",IF(AND(F11>=D$4,F11<D$5),"3. Median-Q3 density","4. >Q3 density"))) -> 2. Q1-Median density | AF11: Guinea | AG11: 4. Very rapid education production - Less than 10 stock to grad | AH11: 1. <Q1 density
E12: Comoros | F12: 31.333795 | G12: 1138.971 | H12: 40 | I12: =IF(H12=0,I$52,G12/H12) -> 28.474274 | J12: =IF(I12<10,"4. Very rapid education production - Less than 10 stock to grad",IF(AND(I12>=10,I12<20),"3. Rapid education production - 10 to 20 stock to grad",IF(AND(I12>=20,I12<30),"2. Slow education production - 20 to 30 stock to grad","1. Very slow education production - 30 stock to grad and more"))) -> 2. Slow education production - 20 to 30 stock to grad | K12: =IF(F12<D$3,"1. <Q1 density",IF(AND(F12>=D$3,F12<D$4),"2. Q1-Median density",IF(AND(F12>=D$4,F12<D$5),"3. Median-Q3 density","4. >Q3 density"))) -> 2. Q1-Median density | AF12: Madagascar | AG12: 4. Very rapid education production - Less than 10 stock to grad | AH12: 1. <Q1 density
E13: Congo | F13: 20.330016 | G13: 6615 | H13: 120 | I13: =IF(H13=0,I$52,G13/H13) -> 55.125 | J13: =IF(I13<10,"4. Very rapid education production - Less than 10 stock to grad",IF(AND(I13>=10,I13<20),"3. Rapid education production - 10 to 20 stock to grad",IF(AND(I13>=20,I13<30),"2. Slow education production - 20 to 30 stock to grad","1. Very slow education production - 30 stock to grad and more"))) -> 1. Very slow education production - 30 stock to grad and more | K13: =IF(F13<D$3,"1. <Q1 density",IF(AND(F13>=D$3,F13<D$4),"2. Q1-Median density",IF(AND(F13>=D$4,F13<D$5),"3. Median-Q3 density","4. >Q3 density"))) -> 1. <Q1 density | AF13: Niger | AG13: 4. Very rapid education production - Less than 10 stock to grad | AH13: 1. <Q1 density
E14: Cote d'Ivoire | F14: 25.919754 | G14: 25552.785 | H14: 1261 | I14: =IF(H14=0,I$52,G14/H14) -> 20.263906 | J14: =IF(I14<10,"4. Very rapid education production - Less than 10 stock to grad",IF(AND(I14>=10,I14<20),"3. Rapid education production - 10 to 20 stock to grad",IF(AND(I14>=20,I14<30),"2. Slow education production - 20 to 30 stock to grad","1. Very slow education production - 30 stock to grad and more"))) -> 2. Slow education production - 20 to 30 stock to grad | K14: =IF(F14<D$3,"1. <Q1 density",IF(AND(F14>=D$3,F14<D$4),"2. Q1-Median density",IF(AND(F14>=D$4,F14<D$5),"3. Median-Q3 density","4. >Q3 density"))) -> 2. Q1-Median density | AF14: Comoros | AG14: 2. Slow education production - 20 to 30 stock to grad | AH14: 2. Q1-Median density
E15: DRC | F15: 15.888047 | G15: 136605.96 | H15: 30081 | I15: =IF(H15=0,I$52,G15/H15) -> 4.5412705 | J15: =IF(I15<10,"4. Very rapid education production - Less than 10 stock to grad",IF(AND(I15>=10,I15<20),"3. Rapid education production - 10 to 20 stock to grad",IF(AND(I15>=20,I15<30),"2. Slow education production - 20 to 30 stock to grad","1. Very slow education production - 30 stock to grad and more"))) -> 4. Very rapid education production - Less than 10 stock to grad | K15: =IF(F15<D$3,"1. <Q1 density",IF(AND(F15>=D$3,F15<D$4),"2. Q1-Median density",IF(AND(F15>=D$4,F15<D$5),"3. Median-Q3 density","4. >Q3 density"))) -> 1. <Q1 density | AF15: Cote d'Ivoire | AG15: 2. Slow education production - 20 to 30 stock to grad | AH15: 2. Q1-Median density
E16: Equatorial Guinea | F16: 27.930586 | G16: 1649.6824 | H16: 1729 | I16: =IF(H16=0,I$52,G16/H16) -> 0.95412515 | J16: =IF(I16<10,"4. Very rapid education production - Less than 10 stock to grad",IF(AND(I16>=10,I16<20),"3. Rapid education production - 10 to 20 stock to grad",IF(AND(I16>=20,I16<30),"2. Slow education production - 20 to 30 stock to grad","1. Very slow education production - 30 stock to grad and more"))) -> 4. Very rapid education production - Less than 10 stock to grad | K16: =IF(F16<D$3,"1. <Q1 density",IF(AND(F16>=D$3,F16<D$4),"2. Q1-Median density",IF(AND(F16>=D$4,F16<D$5),"3. Median-Q3 density","4. >Q3 density"))) -> 2. Q1-Median density | AF16: Eritrea | AG16: 3. Rapid education production - 10 to 20 stock to grad | AH16: 2. Q1-Median density
E17: Eritrea | F17: 38.107951 | G17: 5305.8176 | H17: 400 | I17: =IF(H17=0,I$52,G17/H17) -> 13.264544 | J17: =IF(I17<10,"4. Very rapid education production - Less than 10 stock to grad",IF(AND(I17>=10,I17<20),"3. Rapid education production - 10 to 20 stock to grad",IF(AND(I17>=20,I17<30),"2. Slow education production - 20 to 30 stock to grad","1. Very slow education production - 30 stock to grad and more"))) -> 3. Rapid education production - 10 to 20 stock to grad | K17: =IF(F17<D$3,"1. <Q1 density",IF(AND(F17>=D$3,F17<D$4),"2. Q1-Median density",IF(AND(F17>=D$4,F17<D$5),"3. Median-Q3 density","4. >Q3 density"))) -> 2. Q1-Median density | AF17: Ethiopia | AG17: 3. Rapid education production - 10 to 20 stock to grad | AH17: 2. Q1-Median density
E18: Eswatini | F18: 140.19826 | G18: 5929 | H18: 160 | I18: =IF(H18=0,I$52,G18/H18) -> 37.05625 | J18: =IF(I18<10,"4. Very rapid education production - Less than 10 stock to grad",IF(AND(I18>=10,I18<20),"3. Rapid education production - 10 to 20 stock to grad",IF(AND(I18>=20,I18<30),"2. Slow education production - 20 to 30 stock to grad","1. Very slow education production - 30 stock to grad and more"))) -> 1. Very slow education production - 30 stock to grad and more | K18: =IF(F18<D$3,"1. <Q1 density",IF(AND(F18>=D$3,F18<D$4),"2. Q1-Median density",IF(AND(F18>=D$4,F18<D$5),"3. Median-Q3 density","4. >Q3 density"))) -> 4. >Q3 density | AF18: Gambia | AG18: 3. Rapid education production - 10 to 20 stock to grad | AH18: 2. Q1-Median density
E19: Ethiopia | F19: 33.829584 | G19: 155003 | H19: 9412 | I19: =IF(H19=0,I$52,G19/H19) -> 16.468657 | J19: =IF(I19<10,"4. Very rapid education production - Less than 10 stock to grad",IF(AND(I19>=10,I19<20),"3. Rapid education production - 10 to 20 stock to grad",IF(AND(I19>=20,I19<30),"2. Slow education production - 20 to 30 stock to grad","1. Very slow education production - 30 stock to grad and more"))) -> 3. Rapid education production - 10 to 20 stock to grad | K19: =IF(F19<D$3,"1. <Q1 density",IF(AND(F19>=D$3,F19<D$4),"2. Q1-Median density",IF(AND(F19>=D$4,F19<D$5),"3. Median-Q3 density","4. >Q3 density"))) -> 2. Q1-Median density | AF19: Nigeria | AG19: 3. Rapid education production - 10 to 20 stock to grad | AH19: 2. Q1-Median density
E20: Gabon | F20: 57.112152 | G20: 6016.9897 | H20: 141 | I20: =IF(H20=0,I$52,G20/H20) -> 42.673686 | J20: =IF(I20<10,"4. Very rapid education production - Less than 10 stock to grad",IF(AND(I20>=10,I20<20),"3. Rapid education production - 10 to 20 stock to grad",IF(AND(I20>=20,I20<30),"2. Slow education production - 20 to 30 stock to grad","1. Very slow education production - 30 stock to grad and more"))) -> 1. Very slow education production - 30 stock to grad and more | K20: =IF(F20<D$3,"1. <Q1 density",IF(AND(F20>=D$3,F20<D$4),"2. Q1-Median density",IF(AND(F20>=D$4,F20<D$5),"3. Median-Q3 density","4. >Q3 density"))) -> 3. Median-Q3 density | AF20: Tanzania | AG20: 3. Rapid education production - 10 to 20 stock to grad | AH20: 2. Q1-Median density
E21: Gambia | F21: 34.171088 | G21: 1703.2709 | H21: 160 | I21: =IF(H21=0,I$52,G21/H21) -> 10.645443 | J21: =IF(I21<10,"4. Very rapid education production - Less than 10 stock to grad",IF(AND(I21>=10,I21<20),"3. Rapid education production - 10 to 20 stock to grad",IF(AND(I21>=20,I21<30),"2. Slow education production - 20 to 30 stock to grad","1. Very slow education production - 30 stock to grad and more"))) -> 3. Rapid education production - 10 to 20 stock to grad | K21: =IF(F21<D$3,"1. <Q1 density",IF(AND(F21>=D$3,F21<D$4),"2. Q1-Median density",IF(AND(F21>=D$4,F21<D$5),"3. Median-Q3 density","4. >Q3 density"))) -> 2. Q1-Median density | AF21: Togo | AG21: 3. Rapid education production - 10 to 20 stock to grad | AH21: 2. Q1-Median density
... E23: Guinea | F23: 17.813553 | G23: 5360.3289 | H23: 1731 | I23: =IF(H23=0,I$52,G23/H23) -> 3.096666 | J23: =IF(I23<10,"4. Very rapid education production - Less than 10 stock to grad",IF(AND(I23>=10,I23<20),"3. Rapid education production - 10 to 20 stock to grad",IF(AND(I23>=20,I23<30),"2. Slow education production - 20 to 30 stock to grad","1. Very slow education production - 30 stock to grad and more"))) -> 4. Very rapid education production - Less than 10 stock to grad | K23: =IF(F23<D$3,"1. <Q1 density",IF(AND(F23>=D$3,F23<D$4),"2. Q1-Median density",IF(AND(F23>=D$4,F23<D$5),"3. Median-Q3 density","4. >Q3 density"))) -> 1. <Q1 density | AF23: Equatorial Guinea | AG23: 4. Very rapid education production - Less than 10 stock to grad | AH23: 2. Q1-Median density
E24: Guinea-Bissau | F24: 43.637165 | G24: 2409.8738 | I24: =IF(H24=0,I$52,G24/H24) -> 22.857936 | J24: =IF(I24<10,"4. Very rapid education production - Less than 10 stock to grad",IF(AND(I24>=10,I24<20),"3. Rapid education production - 10 to 20 stock to grad",IF(AND(I24>=20,I24<30),"2. Slow education production - 20 to 30 stock to grad","1. Very slow education production - 30 stock to grad and more"))) -> 2. Slow education production - 20 to 30 stock to grad | K24: =IF(F24<D$3,"1. <Q1 density",IF(AND(F24>=D$3,F24<D$4),"2. Q1-Median density",IF(AND(F24>=D$4,F24<D$5),"3. Median-Q3 density","4. >Q3 density"))) -> 3. Median-Q3 density | AF24: Senegal | AG24: 4. Very rapid education production - Less than 10 stock to grad | AH24: 2. Q1-Median density
E25: Kenya | F25: 52.761766 | G25: 122451 | H25: 1628 | I25: =IF(H25=0,I$52,G25/H25) -> 75.215602 | J25: =IF(I25<10,"4. Very rapid education production - Less than 10 stock to grad",IF(AND(I25>=10,I25<20),"3. Rapid education production - 10 to 20 stock to grad",IF(AND(I25>=20,I25<30),"2. Slow education production - 20 to 30 stock to grad","1. Very slow education production - 30 stock to grad and more"))) -> 1. Very slow education production - 30 stock to grad and more | K25: =IF(F25<D$3,"1. <Q1 density",IF(AND(F25>=D$3,F25<D$4),"2. Q1-Median density",IF(AND(F25>=D$4,F25<D$5),"3. Median-Q3 density","4. >Q3 density"))) -> 3. Median-Q3 density | AF25: Gabon | AG25: 1. Very slow education production - 30 stock to grad and more | AH25: 3. Median-Q3 density
E26: Lesotho | F26: 125.68172 | G26: 1772.0899 | H26: 384 | I26: =IF(H26=0,I$52,G26/H26) -> 4.6148175 | J26: =IF(I26<10,"4. Very rapid education production - Less than 10 stock to grad",IF(AND(I26>=10,I26<20),"3. Rapid education production - 10 to 20 stock to grad",IF(AND(I26>=20,I26<30),"2. Slow education production - 20 to 30 stock to grad","1. Very slow education production - 30 stock to grad and more"))) -> 4. Very rapid education production - Less than 10 stock to grad | K26: =IF(F26<D$3,"1. <Q1 density",IF(AND(F26>=D$3,F26<D$4),"2. Q1-Median density",IF(AND(F26>=D$4,F26<D$5),"3. Median-Q3 density","4. >Q3 density"))) -> 4. >Q3 density | AF26: Kenya | AG26: 1. Very slow education production - 30 stock to grad and more | AH26: 3. Median-Q3 density
E27: Liberia | F27: 57.003752 | G27: 5377.7953 | H27: 92 | I27: =IF(H27=0,I$52,G27/H27) -> 58.454297 | J27: =IF(I27<10,"4. Very rapid education production - Less than 10 stock to grad",IF(AND(I27>=10,I27<20),"3. Rapid education production - 10 to 20 stock to grad",IF(AND(I27>=20,I27<30),"2. Slow education production - 20 to 30 stock to grad","1. Very slow education production - 30 stock to grad and more"))) -> 1. Very slow education production - 30 stock to grad and more | K27: =IF(F27<D$3,"1. <Q1 density",IF(AND(F27>=D$3,F27<D$4),"2. Q1-Median density",IF(AND(F27>=D$4,F27<D$5),"3. Median-Q3 density","4. >Q3 density"))) -> 3. Median-Q3 density | AF27: Liberia | AG27: 1. Very slow education production - 30 stock to grad and more | AH27: 3. Median-Q3 density
E28: Madagascar | F28: 21.968768 | G28: 9790 | H28: 2856 | I28: =IF(H28=0,I$52,G28/H28) -> 3.4278711 | J28: =IF(I28<10,"4. Very rapid education production - Less than 10 stock to grad",IF(AND(I28>=10,I28<20),"3. Rapid education production - 10 to 20 stock to grad",IF(AND(I28>=20,I28<30),"2. Slow education production - 20 to 30 stock to grad","1. Very slow education production - 30 stock to grad and more"))) -> 4. Very rapid education production - Less than 10 stock to grad | K28: =IF(F28<D$3,"1. <Q1 density",IF(AND(F28>=D$3,F28<D$4),"2. Q1-Median density",IF(AND(F28>=D$4,F28<D$5),"3. Median-Q3 density","4. >Q3 density"))) -> 1. <Q1 density | AF28: Mauritania | AG28: 1. Very slow education production - 30 stock to grad and more | AH28: 3. Median-Q3 density
E29: Malawi | F29: 18.931285 | G29: 10695.564 | H29: 501 | I29: =IF(H29=0,I$52,G29/H29) -> 21.348431 | J29: =IF(I29<10,"4. Very rapid education production - Less than 10 stock to grad",IF(AND(I29>=10,I29<20),"3. Rapid education production - 10 to 20 stock to grad",IF(AND(I29>=20,I29<30),"2. Slow education production - 20 to 30 stock to grad","1. Very slow education production - 30 stock to grad and more"))) -> 2. Slow education production - 20 to 30 stock to grad | K29: =IF(F29<D$3,"1. <Q1 density",IF(AND(F29>=D$3,F29<D$4),"2. Q1-Median density",IF(AND(F29>=D$4,F29<D$5),"3. Median-Q3 density","4. >Q3 density"))) -> 1. <Q1 density | AF29: Rwanda | AG29: 1. Very slow education production - 30 stock to grad and more | AH29: 3. Median-Q3 density
E30: Mali | F30: 16.946844 | G30: 10729 | I30: =IF(H30=0,I$52,G30/H30) -> 22.857936 | J30: =IF(I30<10,"4. Very rapid education production - Less than 10 stock to grad",IF(AND(I30>=10,I30<20),"3. Rapid education production - 10 to 20 stock to grad",IF(AND(I30>=20,I30<30),"2. Slow education production - 20 to 30 stock to grad","1. Very slow education production - 30 stock to grad and more"))) -> 2. Slow education production - 20 to 30 stock to grad | K30: =IF(F30<D$3,"1. <Q1 density",IF(AND(F30>=D$3,F30<D$4),"2. Q1-Median density",IF(AND(F30>=D$4,F30<D$5),"3. Median-Q3 density","4. >Q3 density"))) -> 1. <Q1 density | AF30: Angola | AG30: 2. Slow education production - 20 to 30 stock to grad | AH30: 3. Median-Q3 density
E31: Mauritania | F31: 43.978835 | G31: 7776.0347 | H31: 113 | I31: =IF(H31=0,I$52,G31/H31) -> 68.814466 | J31: =IF(I31<10,"4. Very rapid education production - Less than 10 stock to grad",IF(AND(I31>=10,I31<20),"3. Rapid education production - 10 to 20 stock to grad",IF(AND(I31>=20,I31<30),"2. Slow education production - 20 to 30 stock to grad","1. Very slow education production - 30 stock to grad and more"))) -> 1. Very slow education production - 30 stock to grad and more | K31: =IF(F31<D$3,"1. <Q1 density",IF(AND(F31>=D$3,F31<D$4),"2. Q1-Median density",IF(AND(F31>=D$4,F31<D$5),"3. Median-Q3 density","4. >Q3 density"))) -> 3. Median-Q3 density | AF31: Guinea-Bissau | AG31: 2. Slow education production - 20 to 30 stock to grad | AH31: 3. Median-Q3 density
E32: Mauritius | F32: 117.20285 | G32: 6432.5342 | H32: 607 | I32: =IF(H32=0,I$52,G32/H32) -> 10.597256 | J32: =IF(I32<10,"4. Very rapid education production - Less than 10 stock to grad",IF(AND(I32>=10,I32<20),"3. Rapid education production - 10 to 20 stock to grad",IF(AND(I32>=20,I32<30),"2. Slow education production - 20 to 30 stock to grad","1. Very slow education production - 30 stock to grad and more"))) -> 3. Rapid education production - 10 to 20 stock to grad | K32: =IF(F32<D$3,"1. <Q1 density",IF(AND(F32>=D$3,F32<D$4),"2. Q1-Median density",IF(AND(F32>=D$4,F32<D$5),"3. Median-Q3 density","4. >Q3 density"))) -> 4. >Q3 density | AF32: Sao Tome and Principe | AG32: 2. Slow education production - 20 to 30 stock to grad | AH32: 3. Median-Q3 density
E33: Mozambique | F33: 54.608508 | G33: 22887 | H33: 1399 | I33: =IF(H33=0,I$52,G33/H33) -> 16.359543 | J33: =IF(I33<10,"4. Very rapid education production - Less than 10 stock to grad",IF(AND(I33>=10,I33<20),"3. Rapid education production - 10 to 20 stock to grad",IF(AND(I33>=20,I33<30),"2. Slow education production - 20 to 30 stock to grad","1. Very slow education production - 30 stock to grad and more"))) -> 3. Rapid education production - 10 to 20 stock to grad | K33: =IF(F33<D$3,"1. <Q1 density",IF(AND(F33>=D$3,F33<D$4),"2. Q1-Median density",IF(AND(F33>=D$4,F33<D$5),"3. Median-Q3 density","4. >Q3 density"))) -> 3. Median-Q3 density | AF33: Mozambique | AG33: 3. Rapid education production - 10 to 20 stock to grad | AH33: 3. Median-Q3 density
E34: Namibia | F34: 105.35216 | G34: 17155.322 | H34: 675 | I34: =IF(H34=0,I$52,G34/H34) -> 25.415291 | J34: =IF(I34<10,"4. Very rapid education production - Less than 10 stock to grad",IF(AND(I34>=10,I34<20),"3. Rapid education production - 10 to 20 stock to grad",IF(AND(I34>=20,I34<30),"2. Slow education production - 20 to 30 stock to grad","1. Very slow education production - 30 stock to grad and more"))) -> 2. Slow education production - 20 to 30 stock to grad | K34: =IF(F34<D$3,"1. <Q1 density",IF(AND(F34>=D$3,F34<D$4),"2. Q1-Median density",IF(AND(F34>=D$4,F34<D$5),"3. Median-Q3 density","4. >Q3 density"))) -> 4. >Q3 density | AF34: Zambia | AG34: 3. Rapid education production - 10 to 20 stock to grad | AH34: 3. Median-Q3 density
E35: Niger | F35: 4.9558483 | G35: 5270.6694 | H35: 675 | I35: =IF(H35=0,I$52,G35/H35) -> 7.8083991 | J35: =IF(I35<10,"4. Very rapid education production - Less than 10 stock to grad",IF(AND(I35>=10,I35<20),"3. Rapid education production - 10 to 20 stock to grad",IF(AND(I35>=20,I35<30),"2. Slow education production - 20 to 30 stock to grad","1. Very slow education production - 30 stock to grad and more"))) -> 4. Very rapid education production - Less than 10 stock to grad | K35: =IF(F35<D$3,"1. <Q1 density",IF(AND(F35>=D$3,F35<D$4),"2. Q1-Median density",IF(AND(F35>=D$4,F35<D$5),"3. Median-Q3 density","4. >Q3 density"))) -> 1. <Q1 density | AF35: Burundi | AG35: 4. Very rapid education production - Less than 10 stock to grad | AH35: 3. Median-Q3 density
E36: Nigeria | F36: 36.583982 | G36: 306862 | H36: 17175 | I36: =IF(H36=0,I$52,G36/H36) -> 17.866783 | J36: =IF(I36<10,"4. Very rapid education production - Less than 10 stock to grad",IF(AND(I36>=10,I36<20),"3. Rapid education production - 10 to 20 stock to grad",IF(AND(I36>=20,I36<30),"2. Slow education production - 20 to 30 stock to grad","1. Very slow education production - 30 stock to grad and more"))) -> 3. Rapid education production - 10 to 20 stock to grad | K36: =IF(F36<D$3,"1. <Q1 density",IF(AND(F36>=D$3,F36<D$4),"2. Q1-Median density",IF(AND(F36>=D$4,F36<D$5),"3. Median-Q3 density","4. >Q3 density"))) -> 2. Q1-Median density | AF36: Sierra Leone | AG36: 4. Very rapid education production - Less than 10 stock to grad | AH36: 3. Median-Q3 density
E37: Rwanda | F37: 59.624043 | G37: 15149.24 | H37: 366 | I37: =IF(H37=0,I$52,G37/H37) -> 41.391365 | J37: =IF(I37<10,"4. Very rapid education production - Less than 10 stock to grad",IF(AND(I37>=10,I37<20),"3. Rapid education production - 10 to 20 stock to grad",IF(AND(I37>=20,I37<30),"2. Slow education production - 20 to 30 stock to grad","1. Very slow education production - 30 stock to grad and more"))) -> 1. Very slow education production - 30 stock to grad and more | K37: =IF(F37<D$3,"1. <Q1 density",IF(AND(F37>=D$3,F37<D$4),"2. Q1-Median density",IF(AND(F37>=D$4,F37<D$5),"3. Median-Q3 density","4. >Q3 density"))) -> 3. Median-Q3 density | AF37: Eswatini | AG37: 1. Very slow education production - 30 stock to grad and more | AH37: 4. >Q3 density
E38: Sao Tome and Principe | F38: 63.393221 | G38: 545 | I38: =IF(H38=0,I$52,G38/H38) -> 22.857936 | J38: =IF(I38<10,"4. Very rapid education production - Less than 10 stock to grad",IF(AND(I38>=10,I38<20),"3. Rapid education production - 10 to 20 stock to grad",IF(AND(I38>=20,I38<30),"2. Slow education production - 20 to 30 stock to grad","1. Very slow education production - 30 stock to grad and more"))) -> 2. Slow education production - 20 to 30 stock to grad | K38: =IF(F38<D$3,"1. <Q1 density",IF(AND(F38>=D$3,F38<D$4),"2. Q1-Median density",IF(AND(F38>=D$4,F38<D$5),"3. Median-Q3 density","4. >Q3 density"))) -> 3. Median-Q3 density | AF38: Seychelles | AG38: 1. Very slow education production - 30 stock to grad and more | AH38: 4. >Q3 density
E39: Senegal | F39: 23.796886 | G39: 7297.8623 | H39: 1016 | I39: =IF(H39=0,I$52,G39/H39) -> 7.1829353 | J39: =IF(I39<10,"4. Very rapid education production - Less than 10 stock to grad",IF(AND(I39>=10,I39<20),"3. Rapid education production - 10 to 20 stock to grad",IF(AND(I39>=20,I39<30),"2. Slow education production - 20 to 30 stock to grad","1. Very slow education production - 30 stock to grad and more"))) -> 4. Very rapid education production - Less than 10 stock to grad | K39: =IF(F39<D$3,"1. <Q1 density",IF(AND(F39>=D$3,F39<D$4),"2. Q1-Median density",IF(AND(F39>=D$4,F39<D$5),"3. Median-Q3 density","4. >Q3 density"))) -> 2. Q1-Median density | AF39: South Africa | AG39: 1. Very slow education production - 30 stock to grad and more | AH39: 4. >Q3 density
E40: Seychelles | F40: 296.46629 | G40: 2105 | H40: 50 | I40: =IF(H40=0,I$52,G40/H40) -> 42.1 | J40: =IF(I40<10,"4. Very rapid education production - Less than 10 stock to grad",IF(AND(I40>=10,I40<20),"3. Rapid education production - 10 to 20 stock to grad",IF(AND(I40>=20,I40<30),"2. Slow education production - 20 to 30 stock to grad","1. Very slow education production - 30 stock to grad and more"))) -> 1. Very slow education production - 30 stock to grad and more | K40: =IF(F40<D$3,"1. <Q1 density",IF(AND(F40>=D$3,F40<D$4),"2. Q1-Median density",IF(AND(F40>=D$4,F40<D$5),"3. Median-Q3 density","4. >Q3 density"))) -> 4. >Q3 density | AF40: Zimbabwe | AG40: 1. Very slow education production - 30 stock to grad and more | AH40: 4. >Q3 density
E41: Sierra Leone | F41: 45.477301 | G41: 16772 | H41: 1972 | I41: =IF(H41=0,I$52,G41/H41) -> 8.505071 | J41: =IF(I41<10,"4. Very rapid education production - Less than 10 stock to grad",IF(AND(I41>=10,I41<20),"3. Rapid education production - 10 to 20 stock to grad",IF(AND(I41>=20,I41<30),"2. Slow education production - 20 to 30 stock to grad","1. Very slow education production - 30 stock to grad and more"))) -> 4. Very rapid education production - Less than 10 stock to grad | K41: =IF(F41<D$3,"1. <Q1 density",IF(AND(F41>=D$3,F41<D$4),"2. Q1-Median density",IF(AND(F41>=D$4,F41<D$5),"3. Median-Q3 density","4. >Q3 density"))) -> 3. Median-Q3 density | AF41: Algeria | AG41: 2. Slow education production - 20 to 30 stock to grad | AH41: 4. >Q3 density
...

Sheet Sheet4
A3: Count of Country | B3: Column Labels
A4: Row Labels | B4: <Q1 density | C4: >Q3 density | D4: Median-Q3 density | E4: Q1-Median density | F4: Grand Total
A5: Rapid education production - 10 to 20 stock to grad | C5: 2 | D5: 2 | E5: 6 | F5: 10
A6: Slow education production - 20 to 30 stock to grad | B6: 3 | C6: 3 | D6: 3 | E6: 2 | F6: 11
A7: Very rapid education production - Less than 10 stock to grad | B7: 7 | C7: 3 | D7: 2 | E7: 3 | F7: 15
A8: Very slow education production - 30 stock to grad and more | B8: 2 | C8: 4 | D8: 5 | F8: 11
A9: Grand Total | B9: 12 | C9: 12 | D9: 12 | E9: 11 | F9: 47

Sheet Combined density-grad-stock (2)
A1: FORBIDDEN CELL FOR JAMES | E1: Country | F1: Density per 10,000 (2022) | G1: Doctors and Nurses Stock 2022 | H1: Doctors and Nurses graduates | I1: Ratio stock to graduates | J1: categories | K1: Density quartile | AF1: Country | AG1: categories | AH1: Density quartile | AI1: Fiscal space
C2: Density quartiles | E2: Algeria | F2: 98.058569 | G2: 53077.718 | I2: =IF(H2=0,I$52,G2/H2) -> 22.857936 | J2: =IF(I2<10,"4. Very rapid education production - Less than 10 stock to grad",IF(AND(I2>=10,I2<20),"3. Rapid education production - 10 to 20 stock to grad",IF(AND(I2>=20,I2<30),"2. Slow education production - 20 to 30 stock to grad","1. Very slow education production - 30 stock to grad and more"))) -> 2. Slow education production - 20 to 30 stock to grad | K2: =IF(F2<D$3,"1. <Q1 density",IF(AND(F2>=D$3,F2<D$4),"2. Q1-Median density",IF(AND(F2>=D$4,F2<D$5),"3. Median-Q3 density","4. >Q3 density"))) -> 4. >Q3 density | AF2: Central African Republic | AG2: 1. Very slow education production - 30 stock to grad and more | AH2: 1. <Q1 density
C3: Q1 | D3: =PERCENTILE(F2:F48,0.25) -> 22.33987 | E3: Angola | F3: 38.456346 | G3: 75410.354 | H3: 3561 | I3: =IF(H3=0,I$52,G3/H3) -> 21.176735 | J3: =IF(I3<10,"4. Very rapid education production - Less than 10 stock to grad",IF(AND(I3>=10,I3<20),"3. Rapid education production - 10 to 20 stock to grad",IF(AND(I3>=20,I3<30),"2. Slow education production - 20 to 30 stock to grad","1. Very slow education production - 30 stock to grad and more"))) -> 2. Slow education production - 20 to 30 stock to grad | K3: =IF(F3<D$3,"1. <Q1 density",IF(AND(F3>=D$3,F3<D$4),"2. Q1-Median density",IF(AND(F3>=D$4,F3<D$5),"3. Median-Q3 density","4. >Q3 density"))) -> 3. Median-Q3 density | AF3: Congo | AG3: 1. Very slow education production - 30 stock to grad and more | AH3: 1. <Q1 density
C4: Median | D4: =MEDIAN(F2:F48) -> 38.456346 | E4: Benin | F4: 18.729624 | G4: 8501 | H4: 1037 | I4: =IF(H4=0,I$52,G4/H4) -> 8.1976856 | J4: =IF(I4<10,"4. Very rapid education production - Less than 10 stock to grad",IF(AND(I4>=10,I4<20),"3. Rapid education production - 10 to 20 stock to grad",IF(AND(I4>=20,I4<30),"2. Slow education production - 20 to 30 stock to grad","1. Very slow education production - 30 stock to grad and more"))) -> 4. Very rapid education production - Less than 10 stock to grad | K4: =IF(F4<D$3,"1. <Q1 density",IF(AND(F4>=D$3,F4<D$4),"2. Q1-Median density",IF(AND(F4>=D$4,F4<D$5),"3. Median-Q3 density","4. >Q3 density"))) -> 1. <Q1 density | AF4: Malawi | AG4: 2. Slow education production - 20 to 30 stock to grad | AH4: 1. <Q1 density
C5: Q3 | D5: =PERCENTILE(F2:F48,0.75) -> 63.718104 | E5: Botswana | F5: 68.115844 | G5: 9020 | H5: 550 | I5: =IF(H5=0,I$52,G5/H5) -> 16.4 | J5: =IF(I5<10,"4. Very rapid education production - Less than 10 stock to grad",IF(AND(I5>=10,I5<20),"3. Rapid education production - 10 to 20 stock to grad",IF(AND(I5>=20,I5<30),"2. Slow education production - 20 to 30 stock to grad","1. Very slow education production - 30 stock to grad and more"))) -> 3. Rapid education production - 10 to 20 stock to grad | K5: =IF(F5<D$3,"1. <Q1 density",IF(AND(F5>=D$3,F5<D$4),"2. Q1-Median density",IF(AND(F5>=D$4,F5<D$5),"3. Median-Q3 density","4. >Q3 density"))) -> 4. >Q3 density | AF5: Mali | AG5: 2. Slow education production - 20 to 30 stock to grad | AH5: 1. <Q1 density
E6: Burkina Faso | F6: 16.827323 | G6: 17284 | H6: 2662 | I6: =IF(H6=0,I$52,G6/H6) -> 6.4928625 | J6: =IF(I6<10,"4. Very rapid education production - Less than 10 stock to grad",IF(AND(I6>=10,I6<20),"3. Rapid education production - 10 to 20 stock to grad",IF(AND(I6>=20,I6<30),"2. Slow education production - 20 to 30 stock to grad","1. Very slow education production - 30 stock to grad and more"))) -> 4. Very rapid education production - Less than 10 stock to grad | K6: =IF(F6<D$3,"1. <Q1 density",IF(AND(F6>=D$3,F6<D$4),"2. Q1-Median density",IF(AND(F6>=D$4,F6<D$5),"3. Median-Q3 density","4. >Q3 density"))) -> 1. <Q1 density | AF6: South Sudan | AG6: 2. Slow education production - 20 to 30 stock to grad | AH6: 1. <Q1 density
E7: Burundi | F7: 40.986337 | G7: 10386.861 | H7: 1792 | I7: =IF(H7=0,I$52,G7/H7) -> 5.7962394 | J7: =IF(I7<10,"4. Very rapid education production - Less than 10 stock to grad",IF(AND(I7>=10,I7<20),"3. Rapid education production - 10 to 20 stock to grad",IF(AND(I7>=20,I7<30),"2. Slow education production - 20 to 30 stock to grad","1. Very slow education production - 30 stock to grad and more"))) -> 4. Very rapid education production - Less than 10 stock to grad | K7: =IF(F7<D$3,"1. <Q1 density",IF(AND(F7>=D$3,F7<D$4),"2. Q1-Median density",IF(AND(F7>=D$4,F7<D$5),"3. Median-Q3 density","4. >Q3 density"))) -> 3. Median-Q3 density | AF7: Benin | AG7: 4. Very rapid education production - Less than 10 stock to grad | AH7: 1. <Q1 density
E8: Cameroon | F8: 11.326442 | G8: 20232 | H8: 3460 | I8: =IF(H8=0,I$52,G8/H8) -> 5.8473988 | J8: =IF(I8<10,"4. Very rapid education production - Less than 10 stock to grad",IF(AND(I8>=10,I8<20),"3. Rapid education production - 10 to 20 stock to grad",IF(AND(I8>=20,I8<30),"2. Slow education production - 20 to 30 stock to grad","1. Very slow education production - 30 stock to grad and more"))) -> 4. Very rapid education production - Less than 10 stock to grad | K8: =IF(F8<D$3,"1. <Q1 density",IF(AND(F8>=D$3,F8<D$4),"2. Q1-Median density",IF(AND(F8>=D$4,F8<D$5),"3. Median-Q3 density","4. >Q3 density"))) -> 1. <Q1 density | AF8: Burkina Faso | AG8: 4. Very rapid education production - Less than 10 stock to grad | AH8: 1. <Q1 density
E9: Cabo Verde | F9: 104.3631 | G9: 3585 | I9: =IF(H9=0,I$52,G9/H9) -> 22.857936 | J9: =IF(I9<10,"4. Very rapid education production - Less than 10 stock to grad",IF(AND(I9>=10,I9<20),"3. Rapid education production - 10 to 20 stock to grad",IF(AND(I9>=20,I9<30),"2. Slow education production - 20 to 30 stock to grad","1. Very slow education production - 30 stock to grad and more"))) -> 2. Slow education production - 20 to 30 stock to grad | K9: =IF(F9<D$3,"1. <Q1 density",IF(AND(F9>=D$3,F9<D$4),"2. Q1-Median density",IF(AND(F9>=D$4,F9<D$5),"3. Median-Q3 density","4. >Q3 density"))) -> 4. >Q3 density | AF9: Cameroon | AG9: 4. Very rapid education production - Less than 10 stock to grad | AH9: 1. <Q1 density
E10: Central African Republic | F10: 10.210731 | G10: 794.86973 | H10: 18 | I10: =IF(H10=0,I$52,G10/H10) -> 44.159429 | J10: =IF(I10<10,"4. Very rapid education production - Less than 10 stock to grad",IF(AND(I10>=10,I10<20),"3. Rapid education production - 10 to 20 stock to grad",IF(AND(I10>=20,I10<30),"2. Slow education production - 20 to 30 stock to grad","1. Very slow education production - 30 stock to grad and more"))) -> 1. Very slow education production - 30 stock to grad and more | K10: =IF(F10<D$3,"1. <Q1 density",IF(AND(F10>=D$3,F10<D$4),"2. Q1-Median density",IF(AND(F10>=D$4,F10<D$5),"3. Median-Q3 density","4. >Q3 density"))) -> 1. <Q1 density | AF10: DRC | AG10: 4. Very rapid education production - Less than 10 stock to grad | AH10: 1. <Q1 density
E11: Chad | F11: 22.710972 | G11: 4894.1517 | H11: 3250 | I11: =IF(H11=0,I$52,G11/H11) -> 1.5058928 | J11: =IF(I11<10,"4. Very rapid education production - Less than 10 stock to grad",IF(AND(I11>=10,I11<20),"3. Rapid education production - 10 to 20 stock to grad",IF(AND(I11>=20,I11<30),"2. Slow education production - 20 to 30 stock to grad","1. Very slow education production - 30 stock to grad and more"))) -> 4. Very rapid education production - Less than 10 stock to grad | K11: =IF(F11<D$3,"1. <Q1 density",IF(AND(F11>=D$3,F11<D$4),"2. Q1-Median density",IF(AND(F11>=D$4,F11<D$5),"3. Median-Q3 density","4. >Q3 density"))) -> 2. Q1-Median density | AF11: Guinea | AG11: 4. Very rapid education production - Less than 10 stock to grad | AH11: 1. <Q1 density
E12: Comoros | F12: 31.333795 | G12: 1138.971 | H12: 40 | I12: =IF(H12=0,I$52,G12/H12) -> 28.474274 | J12: =IF(I12<10,"4. Very rapid education production - Less than 10 stock to grad",IF(AND(I12>=10,I12<20),"3. Rapid education production - 10 to 20 stock to grad",IF(AND(I12>=20,I12<30),"2. Slow education production - 20 to 30 stock to grad","1. Very slow education production - 30 stock to grad and more"))) -> 2. Slow education production - 20 to 30 stock to grad | K12: =IF(F12<D$3,"1. <Q1 density",IF(AND(F12>=D$3,F12<D$4),"2. Q1-Median density",IF(AND(F12>=D$4,F12<D$5),"3. Median-Q3 density","4. >Q3 density"))) -> 2. Q1-Median density | AF12: Madagascar | AG12: 4. Very rapid education production - Less than 10 stock to grad | AH12: 1. <Q1 density
