Workbook
Name _R²_Impact: Model_2!$AB$3
Name _R²_Impact: Model_3!$AB$3
Name _R²_Impact: Model_1!$AA$3
Name _R²_Outcome: Model_2!$U$3
Name _R²_Outcome: Model_3!$U$3
Name _R²_Outcome: Model_1!$T$3
Name _R²_Output: Model_2!$O$3
Name _R²_Output: Model_3!$O$3
Name _R²_Output: Model_1!$N$3
Name coef1_Dentists: 'Coef.'!$G$4
Name coef1_Medical_and_Pathology_Laboratory_Scientists: 'Coef.'!$I$4
Name coef1_Medical_and_Pathology_Laboratory_Technicians: 'Coef.'!$J$4
Name coef1_Medical_Doctors: 'Coef.'!$D$4
Name coef1_Midwifery_Personnel: 'Coef.'!$F$4
Name coef1_Nursing_Personnel: 'Coef.'!$E$4
Name coef1_Pharmacists: 'Coef.'!$H$4
Name GDP_per_capita_growth__annual: 'Coef.'!$D$10
Name HWF_In_service_training_coef.: Model_2!$K$3
Name HWF_In_service_training_coef.: Model_3!$K$3
Name HWF_In_service_training_coef.: Model_1!$J$3
Name Impact_1_Coef.: Model_2!$AC$3
Name Impact_1_Coef.: Model_3!$AC$3
Name Impact_1_Coef.: Model_1!$AB$3
Name Impact_2_Coef.: Model_2!$AD$3
Name Impact_2_Coef.: Model_3!$AD$3
Name Impact_2_Coef.: Model_1!$AC$3
Name Incentive: Model_2!$L$3
Name Incentive: Model_3!$L$3
Name Incentive: Model_1!$K$3
Name Input_1_coef.: Model_2!$D$3
Name Input_1_coef.: Model_3!$D$3
Name Input_1_coef.: Model_1!$D$3
Name Input_2_coef.: Model_2!$E$3
Name Input_2_coef.: Model_3!$E$3
Name Input_2_coef.: Model_1!$E$3
Name Input_3_coef.: Model_3!$F$3
Name Input_3_coef.: Model_2!$F$3
Name Outcome_1_Coef.: Model_2!$V$3
Name Outcome_1_Coef.: Model_3!$V$3
Name Outcome_1_Coef.: Model_1!$U$3
Name Outcome_2_Coef.: Model_2!$W$3
Name Outcome_2_Coef.: Model_3!$W$3
Name Outcome_2_Coef.: Model_1!$V$3
Name Outcome_3_Coef.: Model_2!$X$3
Name Outcome_3_Coef.: Model_3!$X$3
Name Outcome_3_Coef.: Model_1!$W$3
Name OUTcome1_DALYS_2021_Communicable__maternal__perinatal_and_nutritional_conditions_per_capita_2021: 'Coef.'!$D$8
Name OUTcome1_DALYS_2021_Injuries_per_capita_2021: 'Coef.'!$F$8
Name OUTcome1_DALYS_2021_Noncommunicable_diseases_per_capita__2021: 'Coef.'!$E$8
Name Output_1_Coef.: Model_2!$P$3
Name Output_1_Coef.: Model_3!$P$3
Name Output_1_Coef.: Model_1!$O$3
Name Output_2_Coef.: Model_2!$Q$3
Name Output_2_Coef.: Model_3!$Q$3
Name Output_2_Coef.: Model_1!$P$3
Name Output_3_Coef.: Model_2!$R$3
Name Output_3_Coef.: Model_3!$R$3
Name Output_3_Coef.: Model_1!$Q$3
Name OUTput1_SCI_Infectiousdiseases: 'Coef.'!$D$6
Name OUTput1_SCI_NCD: 'Coef.'!$E$6

Sheet SEM_HWF
A1: Country | B1: ISO | C1: Population_2023 | D1: Invest_1 | E1: Invest_2 | F1: Output_1 | G1: Output_2 | H1: Output_3 | I1: Output_4 | J1: SCI_Average | K1: DALYS_2021_All Causes per capita 2021 | L1: Outcome_1 | M1: Outcome_2 | N1: Outcome_3 | O1: Outcome_4 | P1: Outcome_5 | Q1: Impact_1 | R1: Impact_2 | S1: Impact_3 | T1: GDP_Growth_per_capita | U1: HR_1 | V1: HR_2 | W1: HR_3 | X1: HR_4 | Y1: HR_5 | Z1: HR_6 | AA1: HR_7 | AB1: HR_8 | AC1: DADLYs All | AD1: Outcome_1a | AE1: Outcome_2a | AF1: Outcome_3a | AG1: HR_1d | AH1: HR_2d | AI1: HR_3d | AJ1: HR_4d | AK1: HR_5d | AL1: HR_6d | AM1: HR_7d
A2: Algeria | B2: DZA | C2: 46053477 | D2: 61.01303 | E2: 0.13419182 | F2: 88.72 | G2: 82.21 | H2: 60.71 | I2: 68.12 | J2: 74.94 | K2: 0.25858507 | L2: 0.054826069 | M2: 0.17657851 | N2: 0.02400285 | O2: 0.262 | P2: 0.5866345 | Q2: 15545.11 | R2: 28.18 | S2: 37.36 | T2: 3.3 | U2: 16.39659 | V2: 22.750942 | W2: 2.0148316 | X2: 3.5224268 | Y2: 2.9622085 | Z2: 0.029530886 | AA2: 3.3087621 | AB2: 50.985293 | AC2: =K2*$C2 -> 11908741 | AD2: =L2*$C2 -> 2524931.1 | AE2: =M2*$C2 -> 8132054.4 | AF2: =N2*$C2 -> 1105414.7 | AG2: 75512 | AH2: 104776 | AI2: 9279 | AJ2: 16222 | AK2: 13642 | AL2: 136 | AM2: 15238
A3: Angola | B3: AGO | C3: 36148636 | D3: 18.553569 | E3: 2.4607173 | F3: 21.08 | G3: 36.07 | H3: 53.76 | I3: 44.51 | J3: 38.855 | K3: 0.55586603 | L3: 0.34291113 | M3: 0.16924787 | N3: 0.040767474 | O3: 0.291 | P3: 0.2930257 | Q3: 8866.691 | R3: 9.49 | S3: 45 | T3: 4.4239045 | U3: 2.4047934 | V3: 18.456575 | W3: 0.0091289752 | X3: 0.070265445 | Y3: 0.39669547 | Z3: 0.0035962629 | AA3: 0.004979441 | AB3: 21.346034 | AC3: =K3*$C3 -> 20093799 | AD3: =L3*$C3 -> 12395770 | AE3: =M3*$C3 -> 6118079.5 | AF3: =N3*$C3 -> 1473688.6 | AG3: 8693 | AH3: 66718 | AI3: 33 | AJ3: 254 | AK3: 1434 | AL3: 13 | AM3: 18
A4: Benin | B4: BEN | C4: 13124347 | D4: 10.88486 | E4: 2.8272298 | F4: 16.86 | G4: 47 | H4: 60.77 | I4: 42.82 | J4: 41.8625 | K4: 0.5415334 | L4: 0.32523931 | M4: 0.16627788 | N4: 0.047324915 | O4: 0.254 | P4: 0.3140346 | Q4: 3966.803 | R4: 4.16 | S4: 37.6 | T4: 7.4531157 | U4: 2.3178296 | V4: 4.7164251 | W4: 1.8484729 | X4: 0.050288216 | Y4: 0.32992118 | Z4: 0.5089777 | AA4: 1.2434904 | AB4: 11.015405 | AC4: =K4*$C4 -> 7107272.3 | AD4: =L4*$C4 -> 4268553.5 | AE4: =M4*$C4 -> 2182288.6 | AF4: =N4*$C4 -> 621108.6 | AG4: 3042 | AH4: 6190 | AI4: 2426 | AJ4: 66 | AK4: 433 | AL4: 668 | AM4: 1632
A5: Botswana | B5: BWA | C5: 2483754 | D5: 32.040541 | E5: 6.3942892 | F5: 43.33 | G5: 66.05 | H5: 60.17 | I5: 53.85 | J5: 55.85 | K5: 0.51046947 | L5: 0.29056739 | M5: 0.16281769 | N5: 0.03681854 | O5: 0.336 | P5: 0.3750613 | Q5: 16749.389 | R5: 23.79 | S5: 57.4 | T5: -2.9898688 | U5: 3.78862 | V5: 30.135835 | W5: 0 | X5: 0.35832856 | Y5: 0.5314536 | Z5: 0.60392454 | AA5: 1.2521369 | AB5: 36.670298 | AC5: =K5*$C5 -> 1267880.6 | AD5: =L5*$C5 -> 721697.91 | AE5: =M5*$C5 -> 404399.1 | AF5: =N5*$C5 -> 91448.197 | AG5: 941 | AH5: 7485 | AI5: 0 | AJ5: 89 | AK5: 132 | AL5: 150 | AM5: 311
A6: Burkina Faso | B6: BFA | C6: 22720842 | D6: 10.935549 | E6: 3.0043273 | F6: 14.92 | G6: 50.01 | H6: 54.76 | I6: 60.22 | J6: 44.9775 | K6: 0.53931546 | L6: 0.30772701 | M6: 0.16837414 | N6: 0.059056873 | O6: 0.298 | P6: 0.2846235 | Q6: 2508.528 | R6: 4.3 | S6: 0 | T6: 4.985103 | U6: 1.4625338 | V6: 5.994056 | W6: 3.6217848 | X6: 0.058536563 | Y6: 0.39655221 | Z6: 0.0026407472 | AA6: 0.48589749 | AB6: 12.022002 | AC6: =K6*$C6 -> 12253701 | AD6: =L6*$C6 -> 6991816.7 | AE6: =M6*$C6 -> 3825602.3 | AF6: =N6*$C6 -> 1341821.9 | AG6: 3323 | AH6: 13619 | AI6: 8229 | AJ6: 133 | AK6: 901 | AL6: 6 | AM6: 1104
A7: Burundi | B7: BDI | C7: 12999141 | D7: 9.4270121 | E7: 3.2873539 | F7: 13.85 | G7: 60.47 | H7: 59.39 | I7: 59.42 | J7: 48.2825 | K7: 0.46057153 | L7: 0.25291885 | M7: 0.15453908 | N7: 0.051080321 | O7: 0.221 | P7: 0.2583942 | Q7: 879.67 | R7: 0.9 | S7: 33.33 | T7: 3.4892317 | U7: 0.7985143 | V7: 8.3643988 | W7: 0.37156301 | X7: 0.010769942 | Y7: 0.095390919 | Z7: 0.98006476 | AA7: 0.70081554 | AB7: 11.321517 | AC7: =K7*$C7 -> 5987034.2 | AD7: =L7*$C7 -> 3287727.8 | AE7: =M7*$C7 -> 2008875.3 | AF7: =N7*$C7 -> 664000.29 | AG7: 1038 | AH7: 10873 | AI7: 483 | AJ7: 14 | AK7: 124 | AL7: 1274 | AM7: 911
A8: Cabo Verde | B8: CPV | C8: 573322 | D8: 24.528465 | F8: 66.2 | G8: 90.4 | H8: 56.77 | I8: 75.55 | J8: 72.23 | K8: 0.28416804 | L8: 0.064726853 | M8: 0.18145936 | N8: 0.034756189 | O8: 0.341 | P8: 0.5024222 | Q8: 10052.799 | R8: 11.35 | S8: 52.5 | T8: 7.2718815 | U8: 6.6454802 | V8: 16.378231 | W8: 0.45349734 | X8: 0.13953764 | Y8: 0.17442205 | Z8: 0.069768821 | AA8: 0.13953764 | AB8: 24.000474 | AC8: =K8*$C8 -> 162919.79 | AD8: =L8*$C8 -> 37109.329 | AE8: =M8*$C8 -> 104034.64 | AF8: =N8*$C8 -> 19926.488 | AG8: 381 | AH8: 939 | AI8: 26 | AJ8: 8 | AK8: 10 | AL8: 4 | AM8: 8
A9: Cameroon | B9: CMR | C9: 28608129 | D9: 7.6903691 | E9: 2.9013855 | F9: 28.28 | G9: 56.12 | H9: 49.14 | I9: 47.52 | J9: 45.265 | K9: 0.54981019 | L9: 0.32608299 | M9: 0.1751217 | N9: 0.042805912 | O9: 0.286 | P9: 0.3372569 | Q9: 4880.519 | R9: 6.23 | S9: 49 | T9: 3.6707428 | U9: 1.3150108 | V9: 5.7798257 | W9: 0.58479882 | X9: 0.11080767 | Y9: 0.2104297 | Z9: 0.10241844 | AA9: 0.083542688 | AB9: 8.1868339 | AC9: =K9*$C9 -> 15729041 | AD9: =L9*$C9 -> 9328624.2 | AE9: =M9*$C9 -> 5009904.3 | AF9: =N9*$C9 -> 1224597 | AG9: 3762 | AH9: 16535 | AI9: 1673 | AJ9: 317 | AK9: 602 | AL9: 293 | AM9: 239
A10: Central African Republic | B10: CAF | C10: 5119136 | D10: 10.510261 | E10: 0.072434098 | F10: 16.76 | G10: 38.69 | H10: 43.77 | I10: 38.17 | J10: 34.3475 | K10: 0.83557862 | L10: 0.58633456 | M10: 0.16570339 | N10: 0.07557031 | O10: 0.186 | P10: 0.1516031 | Q10: 1145.161 | R10: 1.57 | S10: 59.27 | T10: 1.5396325 | U10: 0.74817313 | V10: 7.3371756 | W10: 3.7057035 | X10: 0.0058603639 | Y10: 0.02539491 | Z10: 0.21878692 | AA10: 0.56064148 | AB10: 12.601736 | AC10: =K10*$C10 -> 4277440.6 | AD10: =L10*$C10 -> 3001526.3 | AE10: =M10*$C10 -> 848258.18 | AF10: =N10*$C10 -> 386854.7 | AG10: 383 | AH10: 3756 | AI10: 1897 | AJ10: 3 | AK10: 13 | AL10: 112 | AM10: 287
A11: Chad | B11: TCD | C11: 17921183 | D11: 3.9757716 | E11: 4.1133942 | F11: 10.76 | G11: 41.09 | H11: 58.54 | I11: 28.87 | J11: 34.815 | K11: 0.72291648 | L11: 0.50936099 | M11: 0.15067299 | N11: 0.056395953 | O11: 0.239 | P11: 0.2375145 | Q11: 2588.82 | R11: 3.29 | S11: 36.9 | T11: 3.6544511 | U11: 0.91567616 | V11: 1.3263633 | W11: 0.47150905 | X11: 0.0072539854 | Y11: 0.090953817 | Z11: 0.57362285 | AA11: 0.58478282 | AB11: 3.970162 | AC11: =K11*$C11 -> 12955518 | AD11: =L11*$C11 -> 9128351.6 | AE11: =M11*$C11 -> 2700238.2 | AF11: =N11*$C11 -> 1010682.2 | AG11: 1641 | AH11: 2377 | AI11: 845 | AJ11: 13 | AK11: 163 | AL11: 1028 | AM11: 1048
A12: Comoros | B12: COM | C12: 926492 | D12: 20.789889 | E12: 0.9298947 | F12: 37.44 | G12: 51.48 | H12: 56.05 | I12: 49.64 | J12: 48.6525 | K12: 0.3998434 | L12: 0.18043054 | M12: 0.17489083 | N12: 0.039609689 | O12: 0.249 | P12: 0.3180644 | Q12: 3392.316 | R12: 6.02 | S12: 55.92 | T12: 3.3887835 | U12: 3.8208641 | V12: 8.4728201 | W12: 6.3249332 | X12: 0.34538884 | Y12: 0.43173605 | Z12: 1.7377376 | AA12: 0.17269442 | AB12: 21.306174 | AC12: =K12*$C12 -> 370451.72 | AD12: =L12*$C12 -> 167167.45 | AE12: =M12*$C12 -> 162034.96 | AF12: =N12*$C12 -> 36698.06 | AG12: 354 | AH12: 785 | AI12: 586 | AJ12: 32 | AK12: 40 | AL12: 161 | AM12: 16
A13: Congo | B13: COG | C13: 5940746 | D13: 13.271803 | E13: 0.42558796 | F13: 28.57 | G13: 36.21 | H13: 52.47 | I13: 52.06 | J13: 42.3275 | K13: 0.45539965 | L13: 0.27170787 | M13: 0.15151453 | N13: 0.027856401 | O13: 0.263 | P13: 0.3395313 | Q13: 5622.161 | R13: 7.57 | S13: 41.9 | T13: 2.5796664 | U13: 1.7539885 | V13: 9.3809767 | W13: 2.0031154 | X13: 0.016832903 | Y13: 0.053865289 | Z13: 0.53865289 | AA13: 1.3079165 | AB13: 15.055348 | AC13: =K13*$C13 -> 2705413.6 | AD13: =L13*$C13 -> 1614147.4 | AE13: =M13*$C13 -> 900109.35 | AF13: =N13*$C13 -> 165487.8 | AG13: 1042 | AH13: 5573 | AI13: 1190 | AJ13: 10 | AK13: 32 | AL13: 320 | AM13: 777
A14: Côte d'Ivoire | B14: CIV | C14: 28444206 | D14: 10.770365 | E14: 1.395126 | F14: 19.16 | G14: 58.23 | H14: 58.65 | I14: 51.18 | J14: 46.805 | K14: 0.50783164 | L14: 0.2963126 | M14: 0.162066 | N14: 0.045583166 | O14: 0.312 | P14: 0.3432034 | Q14: 6726.072 | R14: 8.59 | S14: 45.6 | T14: 5.95 | U14: 1.8172418 | V14: 5.6475473 | W14: 3.040338 | X14: 0.14941532 | Y14: 0.42820671 | Z14: 0.17472803 | AA14: 0 | AB14: 11.257477 | AC14: =K14*$C14 -> 14444868 | AD14: =L14*$C14 -> 8428376.7 | AE14: =M14*$C14 -> 4609838.8 | AF14: =N14*$C14 -> 1296577 | AG14: 5169 | AH14: 16064 | AI14: 8648 | AJ14: 425 | AK14: 1218 | AL14: 497 | AM14: 0
A15: Democratic Republic of the Congo | B15: COD | C15: 98151951 | D15: 13.539167 | E15: 6.8932479 | F15: 24.44 | G15: 48.21 | H15: 59.59 | I15: 43.22 | J15: 43.865 | K15: 0.61083886 | L15: 0.39012943 | M15: 0.16891108 | N15: 0.047809794 | O15: 0.261 | P15: 0.290413 | Q15: 1592.477 | R15: 2.41 | S15: 41.64 | T15: 6.6759303 | U15: 2.1690858 | V15: 11.748722 | W15: 0.43728117 | X15: 0.045949163 | Y15: 0.09454728 | Z15: 0.29892427 | AA15: 0.29892427 | AB15: 15.093434 | AC15: =K15*$C15 -> 59955026 | AD15: =L15*$C15 -> 38291964 | AE15: =M15*$C15 -> 16578952 | AF15: =N15*$C15 -> 4692624.6 | AG15: 21290 | AH15: 115316 | AI15: 4292 | AJ15: 451 | AK15: 928 | AL15: 2934 | AM15: 2934
A16: Equatorial Guinea | B16: GNQ | C16: 1543389 | D16: 17.115684 | E16: 23.864221 | F16: 41.09 | G16: 43.59 | H16: 50.27 | I16: 48.65 | J16: 45.9 | K16: 0.58306554 | L16: 0.37725803 | M16: 0.17062504 | N16: 0.031497727 | O16: 0.174 | P16: 0.4242096 | Q16: 18565.41 | R16: 18.85 | S16: 50.2 | T16: 0.90724825 | U16: 1.7817932 | V16: 15.893595 | W16: 0.16846045 | X16: 0 | Y16: 0.090709471 | Z16: 0.86821922 | AA16: 1.4772685 | AB16: 20.280046 | AC16: =K16*$C16 -> 899896.94 | AD16: =L16*$C16 -> 582255.9 | AE16: =M16*$C16 -> 263340.81 | AF16: =N16*$C16 -> 48613.246 | AG16: 275 | AH16: 2453 | AI16: 26 | AJ16: 0 | AK16: 14 | AL16: 134 | AM16: 228
A17: Eritrea | B17: ERI | C17: 3727656 | D17: 14.517287 | E17: 2.6869969 | F17: 35.7 | G17: 36.43 | H17: 60.09 | I17: 51.96 | J17: 46.045 | K17: 0.43861377 | L17: 0.18328273 | M17: 0.20161049 | N17: 0.049832601 | O17: 0.214 | P17: 0.2559651 | Q17: 650 | R17: 2.78 | S17: 0 | U17: 0.80211264 | V17: 13.933689 | W17: 0.17973762 | X17: 0.17973762 | Y17: 0.61432707 | Z17: 0.91210133 | AA17: 0.82357385 | AB17: 17.445279 | AC17: =K17*$C17 -> 1635001.2 | AD17: =L17*$C17 -> 683214.95 | AE17: =M17*$C17 -> 751534.57 | AF17: =N17*$C17 -> 185758.79 | AG17: 299 | AH17: 5194 | AI17: 67 | AJ17: 67 | AK17: 229 | AL17: 340 | AM17: 307
A18: Eswatini | B18: SWZ | C18: 1197512 | D18: 43.650798 | E18: 4.3127443 | F18: 32.98 | G18: 65.08 | H18: 62 | I18: 73.19 | J18: 58.3125 | K18: 0.71206086 | L18: 0.38181597 | M18: 0.23565534 | N18: 0.07556241 | O18: 0.293 | P18: 0.3252324 | Q18: 11315.553 | R18: 24.95 | S18: 63.7 | T18: 2.6407046 | U18: 5.7201932 | V18: 43.774092 | W18: 0 | X18: 0.29227265 | Y18: 0.35072717 | Z18: 0 | AA18: 0 | AB18: 50.137285 | AC18: =K18*$C18 -> 852701.43 | AD18: =L18*$C18 -> 457229.21 | AE18: =M18*$C18 -> 282200.1 | AF18: =N18*$C18 -> 90486.892 | AG18: 685 | AH18: 5242 | AI18: 0 | AJ18: 35 | AK18: 42 | AL18: 0 | AM18: 0
A19: Ethiopia | B19: ETH | C19: 123771387 | D19: 17.313519 | E19: 1.864483 | F19: 20.87 | G19: 29.04 | H19: 52.49 | I19: 47.93 | J19: 37.5825 | K19: 0.38864963 | L19: 0.20396758 | M19: 0.13963053 | N19: 0.041155729 | O19: 0.378 | P19: 0.3120527 | Q19: 3591.681 | R19: 4.7 | S19: 30.98 | T19: 7.3166911 | U19: 1.4876621 | V19: 10.605197 | W19: 1.7770666 | X19: 0.28455688 | Y19: 1.5290287 | Z19: 1.9194259 | AA19: 1.7550098 | AB19: 19.357947 | AC19: =K19*$C19 -> 48103704 | AD19: =L19*$C19 -> 25245350 | AE19: =M19*$C19 -> 17282264 | AF19: =N19*$C19 -> 5093901.6 | AG19: 18413 | AH19: 131262 | AI19: 21995 | AJ19: 3522 | AK19: 18925 | AL19: 23757 | AM19: 21722
A20: Gabon | B20: GAB | C20: 2383905 | D20: 30.40605 | E20: 1.3004665 | F20: 48.48 | G20: 34.37 | H20: 53.8 | I20: 64.17 | J20: 50.205 | K20: 0.44235278 | L20: 0.24190195 | M20: 0.1657311 | N20: 0.03146404 | O20: 0.218 | P20: 0.3962385 | Q20: 21218.077 | R20: 34.92 | S20: 69 | T20: 3.3839076 | U20: 5.3106143 | V20: 20.281848 | W20: 3.8801882 | X20: 0.18457111 | Y20: 0.78442723 | Z20: 1.0780631 | AA20: 1.0612839 | AB20: 32.580996 | AC20: =K20*$C20 -> 1054527 | AD20: =L20*$C20 -> 576671.27 | AE20: =M20*$C20 -> 395087.19 | AF20: =N20*$C20 -> 75007.281 | AG20: 1266 | AH20: 4835 | AI20: 925 | AJ20: 44 | AK20: 187 | AL20: 257 | AM20: 253
A21: Gambia | B21: GMB | C21: 2631251 | D21: 7.5746518 | E21: 1.3278116 | F21: 28.12 | G21: 43.85 | H21: 57.74 | I21: 63.72 | J21: 48.3575 | K21: 0.43458985 | L21: 0.23410545 | M21: 0.15868965 | N21: 0.036390079 | O21: 0.287 | P21: 0.3467981 | Q21: 3073.541 | R21: 5.97 | S21: 67.2 | T21: 5.7467177 | U21: 0.91971461 | V21: 5.111637 | W21: 1.6304032 | X21: 0.034204263 | Y21: 0.038004736 | Z21: 0.19382415 | AA21: 0.67268383 | AB21: 8.6004718 | AC21: =K21*$C21 -> 1143515 | AD21: =L21*$C21 -> 615990.19 | AE21: =M21*$C21 -> 417552.31 | AF21: =N21*$C21 -> 95751.431 | AG21: 242 | AH21: 1345 | AI21: 429 | AJ21: 9 | AK21: 10 | AL21: 51 | AM21: 177
A22: Ghana | B22: GHA | C22: 33062741 | D22: 40.416607 | E22: 15.163718 | F22: 25.98 | G22: 41.42 | H22: 70.51 | I22: 68.74 | J22: 51.6625 | K22: 0.40610834 | L22: 0.19130623 | M22: 0.17586458 | N22: 0.035717695 | O22: 0.343 | P22: 0.3605526 | Q22: 7061.935 | R22: 10.84 | S22: 47.5 | T22: 5.6848726 | U22: 2.7151409 | V22: 34.116954 | W22: 7.8807743 | X22: 0.073799084 | Y22: 1.7348834 | Z22: 0.8105801 | AA22: 1.13209 | AB22: 48.464221 | AC22: =K22*$C22 -> 13427055 | AD22: =L22*$C22 -> 6325108.3 | AE22: =M22*$C22 -> 5814565.1 | AF22: =N22*$C22 -> 1180924.9 | AG22: 8977 | AH22: 112800 | AI22: 26056 | AJ22: 244 | AK22: 5736 | AL22: 2680 | AM22: 3743
A23: Guinea | B23: GIN | C23: 14238716 | D23: 7.1826172 | E23: 2.7373714 | F23: 18.03 | G23: 47.87 | H23: 58.4 | I23: 50.42 | J23: 43.68 | K23: 0.62038058 | L23: 0.39821246 | M23: 0.16588447 | N23: 0.053108951 | O23: 0.268 | P23: 0.2568856 | Q23: 3895.767 | R23: 6.82 | S23: 68.5 | T23: 5.6685239 | U23: 2.0690068 | V23: 3.5248965 | W23: 0.62716329 | X23: 0.02739011 | Y23: 0.17908918 | Z23: 0.1271182 | AA23: 0.22263243 | AB23: 6.7772965 | AC23: =K23*$C23 -> 8833422.9 | AD23: =L23*$C23 -> 5670034.2 | AE23: =M23*$C23 -> 2361981.9 | AF23: =N23*$C23 -> 756203.27 | AG23: 2946 | AH23: 5019 | AI23: 893 | AJ23: 39 | AK23: 255 | AL23: 181 | AM23: 317
A24: Guinea-Bissau | B24: GNB | C24: 2111612 | D24: 12.653132 | E24: 0.1256791 | F24: 17.33 | G24: 29.95 | H24: 61.51 | I24: 60.3 | J24: 42.2725 | K24: 0.59333548 | L24: 0.36455418 | M24: 0.17227405 | N24: 0.049926094 | O24: 0.214 | P24: 0.2426292 | Q24: 2729.159 | R24: 3.06 | S24: 55.76 | T24: 4.813486 | U24: 2.5146665 | V24: 8.9126222 | W24: 0.96135085 | X24: 0.099450088 | Y24: 0.009471437 | Z24: 0.0047357185 | AA24: 0.80980786 | AB24: 13.312105 | AC24: =K24*$C24 -> 1252894.3 | AD24: =L24*$C24 -> 769796.98 | AE24: =M24*$C24 -> 363775.96 | AF24: =N24*$C24 -> 105424.54 | AG24: 531 | AH24: 1882 | AI24: 203 | AJ24: 21 | AK24: 2 | AL24: 1 | AM24: 171
A25: Kenya | B25: KEN | C25: 57458890 | D25: 23.42452 | E25: 0.84095736 | F25: 40.62 | G25: 53.15 | H25: 50.91 | I25: 73.63 | J25: 54.5775 | K25: 0.35501401 | L25: 0.18481356 | M25: 0.1352383 | N25: 0.031453024 | O25: 0.388 | P25: 0.3336342 | Q25: 6267.148 | R25: 7.39 | S25: 50 | T25: 4.4964983 | U25: 2.7835553 | V25: 21.841529 | W25: 0.04820838 | X25: 0.23390636 | Y25: 0.20640844 | Z25: 1.7403747 | AA25: 0.14549533 | AB25: 26.999477 | AC25: =K25*$C25 -> 20398711 | AD25: =L25*$C25 -> 10619182 | AE25: =M25*$C25 -> 7770642.9 | AF25: =N25*$C25 -> 1807255.9 | AG25: 15994 | AH25: 125499 | AI25: 277 | AJ25: 1344 | AK25: 1186 | AL25: 10000 | AM25: 836
A26: Lesotho | B26: LSO | C26: 2192400 | D26: 23.526334 | E26: 4.2294499 | F26: 32.27 | G26: 50.71 | H26: 65.78 | I26: 74.68 | J26: 55.86 | K26: 0.8061546 | L26: 0.46635144 | M26: 0.24303601 | N26: 0.084683657 | O26: 0.309 | P26: 0.2633865 | Q26: 2891.054 | R26: 3.19 | S26: 56.01 | T26: 2.7622382 | U26: 2.4493706 | V26: 5.6330962 | W26: 12.675607 | X26: 0.38314176 | Y26: 1.1722313 | Z26: 1.897464 | AA26: 1.2452107 | AB26: 25.456121 | AC26: =K26*$C26 -> 1767413.3 | AD26: =L26*$C26 -> 1022428.9 | AE26: =M26*$C26 -> 532832.14 | AF26: =N26*$C26 -> 185660.45 | AG26: 537 | AH26: 1235 | AI26: 2779 | AJ26: 84 | AK26: 257 | AL26: 416 | AM26: 273
A27: Liberia | B27: LBR | C27: 5432272 | D27: 11.11493 | E27: 0.55403733 | F27: 29.07 | G27: 42.02 | H27: 53.05 | I27: 61.65 | J27: 46.4475 | K27: 0.53500919 | L27: 0.33742173 | M27: 0.15837177 | N27: 0.037012274 | O27: 0.357 | P27: 0.3573526 | Q27: 1670.302 | R27: 1.53 | S27: 43 | T27: 4.7929148 | U27: 1.7561713 | V27: 8.1439221 | W27: 1.820601 | X27: 0.014726803 | Y27: 0.31294457 | Z27: 0.21169779 | AA27: 0 | AB27: 12.260064 | AC27: =K27*$C27 -> 2906315.5 | AD27: =L27*$C27 -> 1832966.6 | AE27: =M27*$C27 -> 860318.51 | AF27: =N27*$C27 -> 201060.74 | AG27: 954 | AH27: 4424 | AI27: 989 | AJ27: 8 | AK27: 170 | AL27: 115 | AM27: 0
A28: Madagascar | B28: MDG | C28: 29942591 | D28: 5.5460292 | E28: 2.0891931 | F28: 18.98 | G28: 29.47 | H28: 45.77 | I28: 58.24 | J28: 38.115 | K28: 0.50996008 | L28: 0.28997474 | M28: 0.17565736 | N28: 0.039462753 | O28: 0.304 | P28: 0.2901793 | Q28: 1731.305 | R28: 1.89 | S28: 56.2 | T28: 4.2 | U28: 1.7466758 | V28: 1.5229143 | W28: 1.3338859 | X28: 0.083827081 | Y28: 0.010019173 | Z28: 0.10219556 | AA28: 0.10219556 | AB28: 4.9017134 | AC28: =K28*$C28 -> 15269526 | AD28: =L28*$C28 -> 8682595 | AE28: =M28*$C28 -> 5259636.4 | AF28: =N28*$C28 -> 1181617.1 | AG28: 5230 | AH28: 4560 | AI28: 3994 | AJ28: 251 | AK28: 30 | AL28: 306 | AM28: 306
A29: Malawi | B29: MWI | C29: 20728157 | D29: 5.0174021 | E29: 0.71150071 | F29: 22.25 | G29: 57.77 | H29: 58.77 | I29: 71.89 | J29: 52.67 | K29: 0.44481134 | L29: 0.24303618 | M29: 0.16367847 | N29: 0.033520622 | O29: 0.285 | P29: 0.2989006 | Q29: 1514.554 | R29: 2.77 | S29: 47 | T29: 1.82685 | U29: 0.53791565 | V29: 4.7370347 | W29: 0.2971803 | X29: 0.048725991 | Y29: 0.059339574 | Z29: 0.0434192 | AA29: 0.10082903 | AB29: 5.8244445 | AC29: =K29*$C29 -> 9220119.3 | AD29: =L29*$C29 -> 5037692 | AE29: =M29*$C29 -> 3392753 | AF29: =N29*$C29 -> 694820.71 | AG29: 1115 | AH29: 9819 | AI29: 616 | AJ29: 101 | AK29: 123 | AL29: 90 | AM29: 209
A30: Mali | B30: MLI | C30: 22105727 | D30: 8.1755817 | F30: 15.25 | G30: 59.37 | H30: 67.76 | I30: 47.33 | J30: 47.4275 | K30: 0.63970272 | L30: 0.42599321 | M30: 0.15654856 | N30: 0.053925055 | O30: 0.29 | P30: 0.2959361 | Q30: 2472.828 | R30: 2.99 | S30: 36.5 | T30: 5.0045459 | U30: 2.0157672 | V30: 2.8811538 | W30: 1.4756357 | X30: 0.013571144 | Y30: 0.77853128 | Z30: 0.6767477 | AA30: 0 | AB30: 7.8414069 | AC30: =K30*$C30 -> 14141094 | AD30: =L30*$C30 -> 9416889.6 | AE30: =M30*$C30 -> 3460619.7 | AF30: =N30*$C30 -> 1192052.5 | AG30: 4456 | AH30: 6369 | AI30: 3262 | AJ30: 30 | AK30: 1721 | AL30: 1496 | AM30: 0
A31: Mauritania | B31: MRT | C31: 5030233 | D31: 17.621923 | E31: 0.48384449 | F31: 22.04 | G31: 47.04 | H31: 60.5 | I31: 41.31 | J31: 42.7225 | K31: 0.35641087 | L31: 0.18769682 | M31: 0.13676512 | N31: 0.026374756 | O31: 0.262 | P31: 0.4214104 | Q31: 7258.253 | R31: 15.14 | S31: 76 | T31: 5.2 | U31: 2.5306979 | V31: 12.927831 | W31: 2.6658805 | X31: 0.29620894 | Y31: 0.19283401 | Z31: 0.64808131 | AA31: 0.017891815 | AB31: 19.279425 | AC31: =K31*$C31 -> 1792829.7 | AD31: =L31*$C31 -> 944158.72 | AE31: =M31*$C31 -> 687960.41 | AF31: =N31*$C31 -> 132671.17 | AG31: 1273 | AH31: 6503 | AI31: 1341 | AJ31: 149 | AK31: 97 | AL31: 326 | AM31: 9
A32: Mauritius | B32: MUS | C32: 1275657 | D32: 66.876465 | E32: 9.9309121 | F32: 77.61 | G32: 52.41 | H32: 61.3 | I32: 74.5 | J32: 66.455 | K32: 0.3804525 | L32: 0.056210978 | M32: 0.30203463 | N32: 0.022206883 | O32: 0.397 | P32: 0.5665122 | Q32: 27341.634 | R32: 32.83 | S32: 41.9 | T32: 4.6939032 | U32: 14.369066 | V32: 36.052011 | W32: 4.4447685 | X32: 3.2453865 | Y32: 0.32140301 | Z32: 2.4928331 | AA32: 2.0695218 | AB32: 62.99499 | AC32: =K32*$C32 -> 485326.89 | AD32: =L32*$C32 -> 71705.927 | AE32: =M32*$C32 -> 385292.6 | AF32: =N32*$C32 -> 28328.365 | AG32: 1833 | AH32: 4599 | AI32: 567 | AJ32: 414 | AK32: 41 | AL32: 318 | AM32: 264
A33: Mozambique | B33: MOZ | C33: 34034812 | D33: 10.86393 | E33: 1.0442801 | F33: 23.4 | G33: 57.76 | H33: 49.78 | I33: 55.67 | J33: 46.6525 | K33: 0.63336597 | L33: 0.40815361 | M33: 0.17392551 | N33: 0.043108831 | O33: 0.304 | P33: 0.2511178 | Q33: 1485.598 | R33: 2.43 | S33: 40 | T33: 1.851775 | U33: 1.6803384 | V33: 5.044247 | W33: 3.915109 | X33: 0.10753695 | Y33: 0.14749604 | Z33: 0.094902831 | AA33: 0.63199997 | AB33: 11.62163 | AC33: =K33*$C33 -> 21556492 | AD33: =L33*$C33 -> 13891431 | AE33: =M33*$C33 -> 5919522.2 | AF33: =N33*$C33 -> 1467201 | AG33: 5719 | AH33: 17168 | AI33: 13325 | AJ33: 366 | AK33: 502 | AL33: 323 | AM33: 2151
A34: Namibia | B34: NAM | C34: 2680497 | D34: 62.136352 | E34: 7.4922891 | F34: 55.5 | G34: 57.25 | H34: 64.71 | I34: 74.87 | J34: 63.0825 | K34: 0.53297666 | L34: 0.29762114 | M34: 0.16825145 | N34: 0.046707971 | O34: 0.303 | P34: 0.3993723 | Q34: 10419.859 | R34: 15.64 | S34: 70.1 | T34: 3.711545 | U34: 5.9578504 | V34: 58.041475 | W34: 0.02611456 | X34: 0.83566592 | Y34: 2.4435767 | Z34: 0.36187319 | AA34: 3.9731438 | AB34: 71.6397 | AC34: =K34*$C34 -> 1428642.3 | AD34: =L34*$C34 -> 797772.57 | AE34: =M34*$C34 -> 450997.51 | AF34: =N34*$C34 -> 125200.58 | AG34: 1597 | AH34: 15558 | AI34: 7 | AJ34: 224 | AK34: 655 | AL34: 97 | AM34: 1065
A35: Niger | B35: NER | C35: 27066230 | D35: 4.0944273 | E35: 0.54349922 | F35: 11.68 | G35: 49.68 | H35: 49.3 | I35: 52.36 | J35: 40.755 | K35: 0.74303883 | L35: 0.52283858 | M35: 0.15281919 | N35: 0.062854541 | O35: 0.287 | P35: 0.2645919 | Q35: 1747.635 | R35: 2.34 | S35: 29.2 | T35: 8.4215979 | U35: 0.3672473 | V35: 3.4278878 | W35: 0.63621716 | X35: 0.010344994 | Y35: 0.020689989 | Z35: 0.15960849 | AA35: 0.23978219 | AB35: 4.8617779 | AC35: =K35*$C35 -> 20111260 | AD35: =L35*$C35 -> 14151269 | AE35: =M35*$C35 -> 4136239.3 | AF35: =N35*$C35 -> 1701235.5 | AG35: 994 | AH35: 9278 | AI35: 1722 | AJ35: 28 | AK35: 56 | AL35: 432 | AM35: 649
A36: Nigeria | B36: NGA | C36: 222182400 | D36: 23.664466 | E36: 1.7813083 | F36: 14.08 | G36: 53.21 | H36: 62.66 | I36: 46.44 | J36: 44.0975 | K36: 0.60520175 | L36: 0.41661934 | M36: 0.14433402 | N36: 0.042283575 | O36: 0.38 | P36: 0.3161699 | Q36: 5789.016 | R36: 5.8 | S36: 46.8 | T36: 3.4264395 | U36: 3.8995888 | V36: 9.9324249 | W36: 6.6065989 | X36: 0.22720071 | Y36: 0.82261241 | Z36: 1.6577821 | AA36: 1.7423522 | AB36: 24.88856 | AC36: =K36*$C36 -> 1.3446518e+08 | AD36: =L36*$C36 -> 92565485 | AE36: =M36*$C36 -> 32068479 | AF36: =N36*$C36 -> 9394666.1 | AG36: 86642 | AH36: 220681 | AI36: 146787 | AJ36: 5048 | AK36: 18277 | AL36: 36833 | AM36: 38712
A37: Rwanda | B37: RWA | C37: 13924498 | D37: 11.403764 | E37: 0.69228833 | F37: 26.82 | G37: 70.06 | H37: 44.01 | I37: 67.2 | J37: 52.0225 | K37: 0.3827553 | L37: 0.16597404 | M37: 0.1730401 | N37: 0.040846173 | O37: 0.331 | P37: 0.3176267 | Q37: 3355.683 | R37: 6 | S37: 28.9 | T37: 8.8906553 | U37: 0.87830814 | V37: 9.6958612 | W37: 1.1433087 | X37: 0.1967755 | Y37: 0.058170858 | Z37: 0 | AA37: 1.3465476 | AB37: 13.318972 | AC37: =K37*$C37 -> 5329675.4 | AD37: =L37*$C37 -> 2311105.1 | AE37: =M37*$C37 -> 2409496.5 | AF37: =N37*$C37 -> 568762.46 | AG37: 1223 | AH37: 13501 | AI37: 1592 | AJ37: 274 | AK37: 81 | AL37: 0 | AM37: 1875
A38: Sao Tome and Principe | B38: STP | C38: 232132 | D38: 30.890154 | F38: 44.77 | G38: 53.47 | H38: 62.61 | I38: 79.7 | J38: 60.1375 | K38: 0.26640418 | L38: 0.085742941 | M38: 0.15520469 | N38: 0.021865647 | O38: 0.266 | P38: 0.4141126 | Q38: 5449.789 | R38: 16.63 | S38: 32.13 | T38: 0.9000006 | U38: 4.5232885 | V38: 18.954733 | W38: 2.1539469 | X38: 0.25847363 | Y38: 1.5939207 | Z38: 6.2895249 | AA38: 0 | AB38: 33.773887 | AC38: =K38*$C38 -> 61840.934 | AD38: =L38*$C38 -> 19903.68 | AE38: =M38*$C38 -> 36027.974 | AF38: =N38*$C38 -> 5075.7163 | AG38: 105 | AH38: 440 | AI38: 50 | AJ38: 6 | AK38: 37 | AL38: 146 | AM38: 0
A39: Senegal | B39: SEN | C39: 18116526 | D39: 5.7327207 | E39: 1.4601029 | F39: 30.05 | G39: 63.69 | H39: 55.65 | I39: 59.11 | J39: 52.125 | K39: 0.36508063 | L39: 0.16490721 | M39: 0.15800663 | N39: 0.036505767 | O39: 0.328 | P39: 0.3396112 | Q39: 4464.78 | R39: 6.73 | S39: 58.7 | T39: 6.8920074 | U39: 1.0890609 | V39: 2.6384749 | W39: 1.5952286 | X39: 0.10874049 | Y39: 0.20147351 | Z39: 0 | AA39: 0.14351537 | AB39: 5.7764938 | AC39: =K39*$C39 -> 6613992.8 | AD39: =L39*$C39 -> 2987545.8 | AE39: =M39*$C39 -> 2862531.2 | AF39: =N39*$C39 -> 661357.68 | AG39: 1973 | AH39: 4780 | AI39: 2890 | AJ39: 197 | AK39: 365 | AL39: 0 | AM39: 260
A40: Seychelles | B40: SYC | C40: 99912 | D40: 230.71805 | E40: 10.684803 | F40: 78.3 | G40: 87.12 | H40: 57.3 | I40: 79.13 | J40: 75.4625 | K40: 0.31209413 | L40: 0.067825983 | M40: 0.22109038 | N40: 0.023145292 | O40: 0.318 | P40: 0.52842651 | Q40: 35085.182 | S40: 46 | T40: 3.4656807 | U40: 82.872928 | V40: 62.555048 | W40: 31.22748 | X40: 4.4038754 | Y40: 5.4047562 | Z40: 1.0008808 | AA40: 2.1018496 | AB40: 189.56682 | AC40: =K40*$C40 -> 31181.949 | AD40: =L40*$C40 -> 6776.6296 | AE40: =M40*$C40 -> 22089.582 | AF40: =N40*$C40 -> 2312.4924 | AG40: 828 | AH40: 625 | AI40: 312 | AJ40: 44 | AK40: 54 | AL40: 10 | AM40: 21
...

Sheet Sheet5

Sheet Sheet1
D4: AGO | E4: Unit increase | I4: SCI | J4: Increased SCI | K4: DALYS Coef | L4: DALYS per capita
D5: 36148636 | E5: =D5/10000 -> 3614.8636 | F5: 21.08 | G5: 36.07 | H5: 53.76 | I5: =AVERAGE(F5:H5) -> 36.97 | J5: =I5*1.073 -> 39.66881 | K5: =-0.56 -> -0.56 | L5: 0.55586603 | M5: =L5*K5 -> -0.31128498 | N5: =M5*D5 -> -11252527

Sheet SEM_Vars_HWF
B2: varname | C2: variable definition
B3: Invest_1 | C3: Salary per capita
B4: Invest_2 | C4: Total core cadre training per capita
B5: Output_1 | C5: SCI_Infectious diseases
B6: Output_2 | C6: SCI_NCD
B7: Output_3 | C7: SCI_RMNCH
B8: Outcome_1 | C8: DALYS_2021_Communicable, maternal, perinatal and nutritional conditions per capita 2021
B9: Outcome_2 | C9: DALYS_2021_Noncommunicable diseases per capita (2021)
B10: Outcome_3 | C10: DALYS_2021_Injuries per capita 2021
B11: Outcome_4 | C11: Health_Security_Index_2021
B12: Outcome_5 | C12: HAQ
B13: Impact_1 | C13: GDP per capita growth (annual %) | D13: Gross domestic product is the total income earned through the production of goods and services in an economic territory during an accounting period. It can be measured in three different ways: using either the expenditure approach, the income approach, or the production approach. The core indicator has been divided by the general population to achieve a per capita estimate.This indicator denotes the percentage change over each previous year of the constant price (base year 2015) series in United States dollars.
B14: Impact_2 | C14: GDP growth (annual %) | D14: Gross domestic product is the total income earned through the production of goods and services in an economic territory during an accounting period. It can be measured in three different ways: using either the expenditure approach, the income approach, or the production approach. This indicator denotes the percentage change over each previous year of the constant price (base year 2015) series in United States dollars.
B15: Impact_3 | C15: GDP per capita, PPP (constant 2017 international $) | D15: This indicator provides values for gross domestic product (GDP) expressed in constant international dollars, converted by purchasing power parities (PPPs). PPPs account for the different price levels across countries and thus PPP-based comparisons of economic output are more appropriate for comparing the output of economies and the average material well-being of their inhabitants than exchange-rate based comparisons. Gross domestic product is the total income earned through the production of goods and services in an economic territory during an accounting period. It can be measured in three different ways: using either the expenditure approach, the income approach, or the production approach. The core indicator has been divided by the general population to achieve a per capita estimate. This indicator is expressed in constant prices, meaning the series has been adjusted to account for price changes over time. The reference year for this adjustment is 2021. The PPP conversion factor is a currency conversion factor and a spatial price deflator. PPPs convert different currencies to a common currency and, in the process of conversion, equalize their purchasing power by eliminating the differences in price levels between countries, thereby allowing volume or output comparisons of GDP and its expenditure components.
B16: HR_1 | C16: Density_2023_Medical Doctors
B17: HR_2 | C17: Density_2023_Nursing Personnel
B18: HR_3 | C18: Density_2023_Midwifery Personnel
B19: HR_4 | C19: Density_2023_Dentists
B20: HR_5 | C20: Density_2023_Pharmacists
B21: HR_6 | C21: Density_2023_Medical and Pathology Laboratory Scientists
B22: HR_7 | C22: Density_2023_Medical and Pathology Laboratory Technicians
B23: HR_8 | C23: Density_7_cadres_2023
A27: Construct | B27: Var_code | C27: Var_name
A28: HRH AVAILABILITY | B28: HR_1 | C28: Density_2023_Medical Doctors
B29: HR_2 | C29: Density_2023_Nursing Personnel
B30: HR_3 | C30: Density_2023_Midwifery Personnel
B31: HR_4 | C31: Density_2023_Dentists
B32: HR_5 | C32: Density_2023_Pharmacists
B33: HR_6 | C33: Density_2023_Medical and Pathology Laboratory Scientists
B34: HR_7 | C34: Density_2023_Medical and Pathology Laboratory Technicians
A35: OUTPUT | B35: Output_1 | C35: SCI_Infectious diseases
B36: Output_2 | C36: SCI_NCD
B37: Output_3 | C37: SCI_RMNCH
A38: OUTCOME | B38: Outcome_1 | C38: DALYS_2021_Communicable, maternal, perinatal and nutritional conditions per capita 2021
B39: Outcome_2 | C39: DALYS_2021_Noncommunicable diseases per capita (2021)
B40: Outcome_3 | C40: DALYS_2021_Injuries per capita 2021
A41: IMPACT | B41: Impact_1 | C41: GDP per capita growth (annual %)

Sheet SEM
A1: Country | B1: ISO | C1: Population_2023 | D1: Invest_1 | E1: Invest_2 | F1: Output_1 | G1: Output_2 | H1: Output_3 | I1: Output_4 | J1: SCI_Average | K1: DALYS_2021_All Causes per capita 2021 | L1: Outcome_1 | M1: Outcome_2 | N1: Outcome_3 | O1: Outcome_4 | P1: Outcome_5 | Q1: Impact_1 | R1: Impact_2 | S1: Impact_3 | T1: GDP_Growth_per_capita
A2: Algeria | B2: DZA | C2: 46053477 | D2: 61.01303 | E2: 0.13419182 | F2: 88.72 | G2: 82.21 | H2: 60.71 | I2: 68.12 | J2: 74.94 | K2: 0.25858507 | L2: 0.054826069 | M2: 0.17657851 | N2: 0.02400285 | O2: 0.262 | P2: 0.5866345 | Q2: 15545.11 | R2: 28.18 | S2: 37.36 | T2: 3.3
A3: Angola | B3: AGO | C3: 36148636 | D3: 18.553569 | E3: 2.4607173 | F3: 21.08 | G3: 36.07 | H3: 53.76 | I3: 44.51 | J3: 38.855 | K3: 0.55586603 | L3: 0.34291113 | M3: 0.16924787 | N3: 0.040767474 | O3: 0.291 | P3: 0.2930257 | Q3: 8866.691 | R3: 9.49 | S3: 45 | T3: 4.4239045
A4: Benin | B4: BEN | C4: 13124347 | D4: 10.88486 | E4: 2.8272298 | F4: 16.86 | G4: 47 | H4: 60.77 | I4: 42.82 | J4: 41.8625 | K4: 0.5415334 | L4: 0.32523931 | M4: 0.16627788 | N4: 0.047324915 | O4: 0.254 | P4: 0.3140346 | Q4: 3966.803 | R4: 4.16 | S4: 37.6 | T4: 7.4531157
A5: Botswana | B5: BWA | C5: 2483754 | D5: 32.040541 | E5: 6.3942892 | F5: 43.33 | G5: 66.05 | H5: 60.17 | I5: 53.85 | J5: 55.85 | K5: 0.51046947 | L5: 0.29056739 | M5: 0.16281769 | N5: 0.03681854 | O5: 0.336 | P5: 0.3750613 | Q5: 16749.389 | R5: 23.79 | S5: 57.4 | T5: -2.9898688
A6: Burkina Faso | B6: BFA | C6: 22720842 | D6: 10.935549 | E6: 3.0043273 | F6: 14.92 | G6: 50.01 | H6: 54.76 | I6: 60.22 | J6: 44.9775 | K6: 0.53931546 | L6: 0.30772701 | M6: 0.16837414 | N6: 0.059056873 | O6: 0.298 | P6: 0.2846235 | Q6: 2508.528 | R6: 4.3 | S6: 0 | T6: 4.985103
A7: Burundi | B7: BDI | C7: 12999141 | D7: 9.4270121 | E7: 3.2873539 | F7: 13.85 | G7: 60.47 | H7: 59.39 | I7: 59.42 | J7: 48.2825 | K7: 0.46057153 | L7: 0.25291885 | M7: 0.15453908 | N7: 0.051080321 | O7: 0.221 | P7: 0.2583942 | Q7: 879.67 | R7: 0.9 | S7: 33.33 | T7: 3.4892317
A8: Cabo Verde | B8: CPV | C8: 573322 | D8: 24.528465 | F8: 66.2 | G8: 90.4 | H8: 56.77 | I8: 75.55 | J8: 72.23 | K8: 0.28416804 | L8: 0.064726853 | M8: 0.18145936 | N8: 0.034756189 | O8: 0.341 | P8: 0.5024222 | Q8: 10052.799 | R8: 11.35 | S8: 52.5 | T8: 7.2718815
A9: Cameroon | B9: CMR | C9: 28608129 | D9: 7.6903691 | E9: 2.9013855 | F9: 28.28 | G9: 56.12 | H9: 49.14 | I9: 47.52 | J9: 45.265 | K9: 0.54981019 | L9: 0.32608299 | M9: 0.1751217 | N9: 0.042805912 | O9: 0.286 | P9: 0.3372569 | Q9: 4880.519 | R9: 6.23 | S9: 49 | T9: 3.6707428
A10: Central African Republic | B10: CAF | C10: 5119136 | D10: 10.510261 | E10: 0.072434098 | F10: 16.76 | G10: 38.69 | H10: 43.77 | I10: 38.17 | J10: 34.3475 | K10: 0.83557862 | L10: 0.58633456 | M10: 0.16570339 | N10: 0.07557031 | O10: 0.186 | P10: 0.1516031 | Q10: 1145.161 | R10: 1.57 | S10: 59.27 | T10: 1.5396325
A11: Chad | B11: TCD | C11: 17921183 | D11: 3.9757716 | E11: 4.1133942 | F11: 10.76 | G11: 41.09 | H11: 58.54 | I11: 28.87 | J11: 34.815 | K11: 0.72291648 | L11: 0.50936099 | M11: 0.15067299 | N11: 0.056395953 | O11: 0.239 | P11: 0.2375145 | Q11: 2588.82 | R11: 3.29 | S11: 36.9 | T11: 3.6544511
A12: Comoros | B12: COM | C12: 926492 | D12: 20.789889 | E12: 0.9298947 | F12: 37.44 | G12: 51.48 | H12: 56.05 | I12: 49.64 | J12: 48.6525 | K12: 0.3998434 | L12: 0.18043054 | M12: 0.17489083 | N12: 0.039609689 | O12: 0.249 | P12: 0.3180644 | Q12: 3392.316 | R12: 6.02 | S12: 55.92 | T12: 3.3887835
A13: Congo | B13: COG | C13: 5940746 | D13: 13.271803 | E13: 0.42558796 | F13: 28.57 | G13: 36.21 | H13: 52.47 | I13: 52.06 | J13: 42.3275 | K13: 0.45539965 | L13: 0.27170787 | M13: 0.15151453 | N13: 0.027856401 | O13: 0.263 | P13: 0.3395313 | Q13: 5622.161 | R13: 7.57 | S13: 41.9 | T13: 2.5796664
A14: Côte d'Ivoire | B14: CIV | C14: 28444206 | D14: 10.770365 | E14: 1.395126 | F14: 19.16 | G14: 58.23 | H14: 58.65 | I14: 51.18 | J14: 46.805 | K14: 0.50783164 | L14: 0.2963126 | M14: 0.162066 | N14: 0.045583166 | O14: 0.312 | P14: 0.3432034 | Q14: 6726.072 | R14: 8.59 | S14: 45.6 | T14: 5.95
A15: Democratic Republic of the Congo | B15: COD | C15: 98151951 | D15: 13.539167 | E15: 6.8932479 | F15: 24.44 | G15: 48.21 | H15: 59.59 | I15: 43.22 | J15: 43.865 | K15: 0.61083886 | L15: 0.39012943 | M15: 0.16891108 | N15: 0.047809794 | O15: 0.261 | P15: 0.290413 | Q15: 1592.477 | R15: 2.41 | S15: 41.64 | T15: 6.6759303
A16: Equatorial Guinea | B16: GNQ | C16: 1543389 | D16: 17.115684 | E16: 23.864221 | F16: 41.09 | G16: 43.59 | H16: 50.27 | I16: 48.65 | J16: 45.9 | K16: 0.58306554 | L16: 0.37725803 | M16: 0.17062504 | N16: 0.031497727 | O16: 0.174 | P16: 0.4242096 | Q16: 18565.41 | R16: 18.85 | S16: 50.2 | T16: 0.90724825
A17: Eritrea | B17: ERI | C17: 3727656 | D17: 14.517287 | E17: 2.6869969 | F17: 35.7 | G17: 36.43 | H17: 60.09 | I17: 51.96 | J17: 46.045 | K17: 0.43861377 | L17: 0.18328273 | M17: 0.20161049 | N17: 0.049832601 | O17: 0.214 | P17: 0.2559651 | Q17: 650 | R17: 2.78 | S17: 0
A18: Eswatini | B18: SWZ | C18: 1197512 | D18: 43.650798 | E18: 4.3127443 | F18: 32.98 | G18: 65.08 | H18: 62 | I18: 73.19 | J18: 58.3125 | K18: 0.71206086 | L18: 0.38181597 | M18: 0.23565534 | N18: 0.07556241 | O18: 0.293 | P18: 0.3252324 | Q18: 11315.553 | R18: 24.95 | S18: 63.7 | T18: 2.6407046
A19: Ethiopia | B19: ETH | C19: 123771387 | D19: 17.313519 | E19: 1.864483 | F19: 20.87 | G19: 29.04 | H19: 52.49 | I19: 47.93 | J19: 37.5825 | K19: 0.38864963 | L19: 0.20396758 | M19: 0.13963053 | N19: 0.041155729 | O19: 0.378 | P19: 0.3120527 | Q19: 3591.681 | R19: 4.7 | S19: 30.98 | T19: 7.3166911
A20: Gabon | B20: GAB | C20: 2383905 | D20: 30.40605 | E20: 1.3004665 | F20: 48.48 | G20: 34.37 | H20: 53.8 | I20: 64.17 | J20: 50.205 | K20: 0.44235278 | L20: 0.24190195 | M20: 0.1657311 | N20: 0.03146404 | O20: 0.218 | P20: 0.3962385 | Q20: 21218.077 | R20: 34.92 | S20: 69 | T20: 3.3839076
A21: Gambia | B21: GMB | C21: 2631251 | D21: 7.5746518 | E21: 1.3278116 | F21: 28.12 | G21: 43.85 | H21: 57.74 | I21: 63.72 | J21: 48.3575 | K21: 0.43458985 | L21: 0.23410545 | M21: 0.15868965 | N21: 0.036390079 | O21: 0.287 | P21: 0.3467981 | Q21: 3073.541 | R21: 5.97 | S21: 67.2 | T21: 5.7467177
A22: Ghana | B22: GHA | C22: 33062741 | D22: 40.416607 | E22: 15.163718 | F22: 25.98 | G22: 41.42 | H22: 70.51 | I22: 68.74 | J22: 51.6625 | K22: 0.40610834 | L22: 0.19130623 | M22: 0.17586458 | N22: 0.035717695 | O22: 0.343 | P22: 0.3605526 | Q22: 7061.935 | R22: 10.84 | S22: 47.5 | T22: 5.6848726
A23: Guinea | B23: GIN | C23: 14238716 | D23: 7.1826172 | E23: 2.7373714 | F23: 18.03 | G23: 47.87 | H23: 58.4 | I23: 50.42 | J23: 43.68 | K23: 0.62038058 | L23: 0.39821246 | M23: 0.16588447 | N23: 0.053108951 | O23: 0.268 | P23: 0.2568856 | Q23: 3895.767 | R23: 6.82 | S23: 68.5 | T23: 5.6685239
A24: Guinea-Bissau | B24: GNB | C24: 2111612 | D24: 12.653132 | E24: 0.1256791 | F24: 17.33 | G24: 29.95 | H24: 61.51 | I24: 60.3 | J24: 42.2725 | K24: 0.59333548 | L24: 0.36455418 | M24: 0.17227405 | N24: 0.049926094 | O24: 0.214 | P24: 0.2426292 | Q24: 2729.159 | R24: 3.06 | S24: 55.76 | T24: 4.813486
A25: Kenya | B25: KEN | C25: 57458890 | D25: 23.42452 | E25: 0.84095736 | F25: 40.62 | G25: 53.15 | H25: 50.91 | I25: 73.63 | J25: 54.5775 | K25: 0.35501401 | L25: 0.18481356 | M25: 0.1352383 | N25: 0.031453024 | O25: 0.388 | P25: 0.3336342 | Q25: 6267.148 | R25: 7.39 | S25: 50 | T25: 4.4964983
A26: Lesotho | B26: LSO | C26: 2192400 | D26: 23.526334 | E26: 4.2294499 | F26: 32.27 | G26: 50.71 | H26: 65.78 | I26: 74.68 | J26: 55.86 | K26: 0.8061546 | L26: 0.46635144 | M26: 0.24303601 | N26: 0.084683657 | O26: 0.309 | P26: 0.2633865 | Q26: 2891.054 | R26: 3.19 | S26: 56.01 | T26: 2.7622382
A27: Liberia | B27: LBR | C27: 5432272 | D27: 11.11493 | E27: 0.55403733 | F27: 29.07 | G27: 42.02 | H27: 53.05 | I27: 61.65 | J27: 46.4475 | K27: 0.53500919 | L27: 0.33742173 | M27: 0.15837177 | N27: 0.037012274 | O27: 0.357 | P27: 0.3573526 | Q27: 1670.302 | R27: 1.53 | S27: 43 | T27: 4.7929148
A28: Madagascar | B28: MDG | C28: 29942591 | D28: 5.5460292 | E28: 2.0891931 | F28: 18.98 | G28: 29.47 | H28: 45.77 | I28: 58.24 | J28: 38.115 | K28: 0.50996008 | L28: 0.28997474 | M28: 0.17565736 | N28: 0.039462753 | O28: 0.304 | P28: 0.2901793 | Q28: 1731.305 | R28: 1.89 | S28: 56.2 | T28: 4.2
A29: Malawi | B29: MWI | C29: 20728157 | D29: 5.0174021 | E29: 0.71150071 | F29: 22.25 | G29: 57.77 | H29: 58.77 | I29: 71.89 | J29: 52.67 | K29: 0.44481134 | L29: 0.24303618 | M29: 0.16367847 | N29: 0.033520622 | O29: 0.285 | P29: 0.2989006 | Q29: 1514.554 | R29: 2.77 | S29: 47 | T29: 1.82685
A30: Mali | B30: MLI | C30: 22105727 | D30: 8.1755817 | F30: 15.25 | G30: 59.37 | H30: 67.76 | I30: 47.33 | J30: 47.4275 | K30: 0.63970272 | L30: 0.42599321 | M30: 0.15654856 | N30: 0.053925055 | O30: 0.29 | P30: 0.2959361 | Q30: 2472.828 | R30: 2.99 | S30: 36.5 | T30: 5.0045459
A31: Mauritania | B31: MRT | C31: 5030233 | D31: 17.621923 | E31: 0.48384449 | F31: 22.04 | G31: 47.04 | H31: 60.5 | I31: 41.31 | J31: 42.7225 | K31: 0.35641087 | L31: 0.18769682 | M31: 0.13676512 | N31: 0.026374756 | O31: 0.262 | P31: 0.4214104 | Q31: 7258.253 | R31: 15.14 | S31: 76 | T31: 5.2
A32: Mauritius | B32: MUS | C32: 1275657 | D32: 66.876465 | E32: 9.9309121 | F32: 77.61 | G32: 52.41 | H32: 61.3 | I32: 74.5 | J32: 66.455 | K32: 0.3804525 | L32: 0.056210978 | M32: 0.30203463 | N32: 0.022206883 | O32: 0.397 | P32: 0.5665122 | Q32: 27341.634 | R32: 32.83 | S32: 41.9 | T32: 4.6939032
A33: Mozambique | B33: MOZ | C33: 34034812 | D33: 10.86393 | E33: 1.0442801 | F33: 23.4 | G33: 57.76 | H33: 49.78 | I33: 55.67 | J33: 46.6525 | K33: 0.63336597 | L33: 0.40815361 | M33: 0.17392551 | N33: 0.043108831 | O33: 0.304 | P33: 0.2511178 | Q33: 1485.598 | R33: 2.43 | S33: 40 | T33: 1.851775
A34: Namibia | B34: NAM | C34: 2680497 | D34: 62.136352 | E34: 7.4922891 | F34: 55.5 | G34: 57.25 | H34: 64.71 | I34: 74.87 | J34: 63.0825 | K34: 0.53297666 | L34: 0.29762114 | M34: 0.16825145 | N34: 0.046707971 | O34: 0.303 | P34: 0.3993723 | Q34: 10419.859 | R34: 15.64 | S34: 70.1 | T34: 3.711545
A35: Niger | B35: NER | C35: 27066230 | D35: 4.0944273 | E35: 0.54349922 | F35: 11.68 | G35: 49.68 | H35: 49.3 | I35: 52.36 | J35: 40.755 | K35: 0.74303883 | L35: 0.52283858 | M35: 0.15281919 | N35: 0.062854541 | O35: 0.287 | P35: 0.2645919 | Q35: 1747.635 | R35: 2.34 | S35: 29.2 | T35: 8.4215979
A36: Nigeria | B36: NGA | C36: 222182400 | D36: 23.664466 | E36: 1.7813083 | F36: 14.08 | G36: 53.21 | H36: 62.66 | I36: 46.44 | J36: 44.0975 | K36: 0.60520175 | L36: 0.41661934 | M36: 0.14433402 | N36: 0.042283575 | O36: 0.38 | P36: 0.3161699 | Q36: 5789.016 | R36: 5.8 | S36: 46.8 | T36: 3.4264395
A37: Rwanda | B37: RWA | C37: 13924498 | D37: 11.403764 | E37: 0.69228833 | F37: 26.82 | G37: 70.06 | H37: 44.01 | I37: 67.2 | J37: 52.0225 | K37: 0.3827553 | L37: 0.16597404 | M37: 0.1730401 | N37: 0.040846173 | O37: 0.331 | P37: 0.3176267 | Q37: 3355.683 | R37: 6 | S37: 28.9 | T37: 8.8906553
A38: Sao Tome and Principe | B38: STP | C38: 232132 | D38: 30.890154 | F38: 44.77 | G38: 53.47 | H38: 62.61 | I38: 79.7 | J38: 60.1375 | K38: 0.26640418 | L38: 0.085742941 | M38: 0.15520469 | N38: 0.021865647 | O38: 0.266 | P38: 0.4141126 | Q38: 5449.789 | R38: 16.63 | S38: 32.13 | T38: 0.9000006
A39: Senegal | B39: SEN | C39: 18116526 | D39: 5.7327207 | E39: 1.4601029 | F39: 30.05 | G39: 63.69 | H39: 55.65 | I39: 59.11 | J39: 52.125 | K39: 0.36508063 | L39: 0.16490721 | M39: 0.15800663 | N39: 0.036505767 | O39: 0.328 | P39: 0.3396112 | Q39: 4464.78 | R39: 6.73 | S39: 58.7 | T39: 6.8920074
A40: Seychelles | B40: SYC | C40: 99912 | D40: 230.71805 | E40: 10.684803 | F40: 78.3 | G40: 87.12 | H40: 57.3 | I40: 79.13 | J40: 75.4625 | K40: 0.31209413 | L40: 0.067825983 | M40: 0.22109038 | N40: 0.023145292 | O40: 0.318 | P40: 0.52842651 | Q40: 35085.182 | S40: 46 | T40: 3.4656807
...

Sheet Model_1
J1: HWF Performance | Z1: Borrowed from Model 1
D2: Input 1 coef. | E2: Input 2 coef. | F2: Input 3 coef. | H2: Percentage of people trained | I2: Percentage of people incentivised | J2: HWF In-service training coef. | K2: Incentive | M2: Total Output coef. | N2: R²_Output | O2: Output 1 Coef. | P2: Output 2 Coef. | Q2: Output 3 Coef. | S2: Total Outcome coef. | T2: R²_Outcome | U2: Outcome 1 Coef. | V2: Outcome 2 Coef. | W2: Outcome 3 Coef. | Y2: Direct effect from HWF availability to Outcome | Z2: Total Impact coef. | AA2: R²_Impact | AB2: Impact 1 Coef. | AC2: Impact 2 Coef.
D3: 0.95 | E3: 0.595 | H3: 0.1 | I3: 0.1 | J3: 0.115 | K3: 0.012 | M3: 0.525 | N3: 0.276 | O3: 0.805 | P3: 0.41 | Q3: 0.874 | S3: -0.416 | T3: 0.444 | U3: 0.869 | V3: -0.604 | W3: 0.574 | Y3: -0.346 | Z3: -0.649 | AA3: 0.421 | AB3: 0.948 | AC3: 0.926
D4: Investments | H4: HWF Availability | O4: SCI_Infectious diseases | P4: SCI_NCD | Q4: SCI_RMNCH | U4: DALYS_2021_Communicable, maternal, perinatal and nutritional conditions per capita 2021 | V4: DALYS_2021_Noncommunicable diseases per capita (2021) | W4: DALYS_2021_Injuries per capita 2021 | AB4: GDP_PPP_2024 | AC4: Productivity
B5: Country | C5: ISO | D5: Education | E5: Employment | F5: Retention | H5: HWF Availability Estimation | I5: Real value | M5: Total Output | S5: Total Outcome from output | Y5: Direct Outcome from HWF availability | Z5: Total Impact | AD5: Initial investment per HWF | AE5: Intial investment per population | AF5: Population | AG5: GDP_PP | AH5: ROI on GDP
B6: Algeria | C6: DZA | D6: =_xlfn.XLOOKUP($C6,SEM!$B:$B,SEM!$D:$D)*Model_1!$D$3 -> 57.962378 | E6: =_xlfn.XLOOKUP($C6,SEM!$B:$B,SEM!$E:$E)*Model_1!$E$3 -> 0.079844134 | H6: =Input_1_coef.*_xlfn.XLOOKUP($C6,COMBINED!$B:$B,COMBINED!$AB:$AB)+Input_2_coef.*_xlfn.XLOOKUP($C6,COMBINED!$B:$B,COMBINED!$AC:$AC) -> 58.042222 | I6: =_xlfn.XLOOKUP($C6,COMBINED!$B:$B,COMBINED!$N:$N) -> 50.985293 | M6: =Total_Output_coef.*$H6*_R²_Output+(HWF_In_service_training_coef.*Percentage_of_people_trained*$H6)+($H6*Incentive*Percentage_of_people_incentivised) -> 9.1474542 | O6: =Output_1_Coef.*$M6*_R²_Output -> 2.0323814 | P6: =Output_2_Coef.*$M6*_R²_Output -> 1.0351259 | Q6: =Output_3_Coef.*$M6*_R²_Output -> 2.2065855 | S6: =Total_Outcome_coef.*M6*_R²_Outcome -> -1.6895714 | U6: =Outcome_1_Coef.*$S6*_R²_Outcome -> -0.65189747 | V6: =Outcome_2_Coef.*$S6*_R²_Outcome -> 0.4531025 | W6: =Outcome_3_Coef.*$S6*_R²_Outcome -> -0.4305974 | Y6: =H6*$Y$3*_R²_Outcome -> -8.9166784 | Z6: =Y6+S6 -> -10.60625 | AB6: =_R²_Impact*$Z6*Impact_1_Coef.*Total_Impact_coef. -> 2.7472424 | AC6: =_R²_Impact*$Z6*Impact_2_Coef.*Total_Impact_coef. -> 2.6834878 | AD6: =_xlfn.XLOOKUP($C6,SEM!$B:$B,SEM!$D:$D)+_xlfn.XLOOKUP($C6,SEM!$B:$B,SEM!$E:$E) -> 61.147221 | AE6: =_xlfn.XLOOKUP($C6,SEM!$B:$B,COMBINED!$AE:$AE)*AD6 -> 14357673 | AF6: =_xlfn.XLOOKUP($C6,SEM!$B:$B,SEM!C:C) -> 46053477 | AG6: =AF6*AB6 -> 1.2652006e+08 | AH6: =AG6/AE6 -> 8.8120172 | AI6: =AE6/AF6 -> 0.3117609 | AJ6: =AB6/AI6 -> 8.8120172
B7: Angola | C7: AGO | D7: =_xlfn.XLOOKUP($C7,SEM!$B:$B,SEM!$D:$D)*Model_1!$D$3 -> 17.625891 | E7: =_xlfn.XLOOKUP($C7,SEM!$B:$B,SEM!$E:$E)*Model_1!$E$3 -> 1.4641268 | H7: =Input_1_coef.*_xlfn.XLOOKUP($C7,COMBINED!$B:$B,COMBINED!$AB:$AB)+Input_2_coef.*_xlfn.XLOOKUP($C7,COMBINED!$B:$B,COMBINED!$AC:$AC) -> 19.090018 | I7: =_xlfn.XLOOKUP($C7,COMBINED!$B:$B,COMBINED!$N:$N) -> 21.346034 | M7: =Total_Output_coef.*$H7*_R²_Output+(HWF_In_service_training_coef.*Percentage_of_people_trained*$H7)+($H7*Incentive*Percentage_of_people_incentivised) -> 3.0085868 | O7: =Output_1_Coef.*$M7*_R²_Output -> 0.66844782 | P7: =Output_2_Coef.*$M7*_R²_Output -> 0.34045168 | Q7: =Output_3_Coef.*$M7*_R²_Output -> 0.72574334 | S7: =Total_Outcome_coef.*M7*_R²_Outcome -> -0.55569802 | U7: =Outcome_1_Coef.*$S7*_R²_Outcome -> -0.2144083 | V7: =Outcome_2_Coef.*$S7*_R²_Outcome -> 0.14902487 | W7: =Outcome_3_Coef.*$S7*_R²_Outcome -> -0.14162297 | Y7: =H7*$Y$3*_R²_Outcome -> -2.9326849 | Z7: =Y7+S7 -> -3.4883829 | AB7: =_R²_Impact*$Z7*Impact_1_Coef.*Total_Impact_coef. -> 0.90356475 | AC7: =_R²_Impact*$Z7*Impact_2_Coef.*Total_Impact_coef. -> 0.88259595 | AD7: =_xlfn.XLOOKUP($C7,SEM!$B:$B,SEM!$D:$D)+_xlfn.XLOOKUP($C7,SEM!$B:$B,SEM!$E:$E) -> 21.014287 | AE7: =_xlfn.XLOOKUP($C7,SEM!$B:$B,COMBINED!$AE:$AE)*AD7 -> 1621525.4 | AF7: =_xlfn.XLOOKUP($C7,SEM!$B:$B,SEM!C:C) -> 36148636 | AG7: =AF7*AB7 -> 32662633 | AH7: =AG7/AE7 -> 20.143152 | AI7: =AE7/AF7 -> 0.044857167 | AJ7: =AB7/AI7 -> 20.143152
B8: Benin | C8: BEN | D8: =_xlfn.XLOOKUP($C8,SEM!$B:$B,SEM!$D:$D)*Model_1!$D$3 -> 10.340617 | E8: =_xlfn.XLOOKUP($C8,SEM!$B:$B,SEM!$E:$E)*Model_1!$E$3 -> 1.6822017 | H8: =Input_1_coef.*_xlfn.XLOOKUP($C8,COMBINED!$B:$B,COMBINED!$AB:$AB)+Input_2_coef.*_xlfn.XLOOKUP($C8,COMBINED!$B:$B,COMBINED!$AC:$AC) -> 12.022819 | I8: =_xlfn.XLOOKUP($C8,COMBINED!$B:$B,COMBINED!$N:$N) -> 11.015405 | M8: =Total_Output_coef.*$H8*_R²_Output+(HWF_In_service_training_coef.*Percentage_of_people_trained*$H8)+($H8*Incentive*Percentage_of_people_incentivised) -> 1.8947963 | O8: =Output_1_Coef.*$M8*_R²_Output -> 0.42098584 | P8: =Output_2_Coef.*$M8*_R²_Output -> 0.21441515 | Q8: =Output_3_Coef.*$M8*_R²_Output -> 0.45707034 | S8: =Total_Outcome_coef.*M8*_R²_Outcome -> -0.34997645 | U8: =Outcome_1_Coef.*$S8*_R²_Outcome -> -0.13503351 | V8: =Outcome_2_Coef.*$S8*_R²_Outcome -> 0.093855285 | W8: =Outcome_3_Coef.*$S8*_R²_Outcome -> -0.089193598 | Y8: =H8*$Y$3*_R²_Outcome -> -1.8469935 | Z8: =Y8+S8 -> -2.19697 | AB8: =_R²_Impact*$Z8*Impact_1_Coef.*Total_Impact_coef. -> 0.56906157 | AC8: =_R²_Impact*$Z8*Impact_2_Coef.*Total_Impact_coef. -> 0.5558555 | AD8: =_xlfn.XLOOKUP($C8,SEM!$B:$B,SEM!$D:$D)+_xlfn.XLOOKUP($C8,SEM!$B:$B,SEM!$E:$E) -> 13.71209 | AE8: =_xlfn.XLOOKUP($C8,SEM!$B:$B,COMBINED!$AE:$AE)*AD8 -> 198235.69 | AF8: =_xlfn.XLOOKUP($C8,SEM!$B:$B,SEM!C:C) -> 13124347 | AG8: =AF8*AB8 -> 7468561.5 | AH8: =AG8/AE8 -> 37.675161
B9: Botswana | C9: BWA | D9: =_xlfn.XLOOKUP($C9,SEM!$B:$B,SEM!$D:$D)*Model_1!$D$3 -> 30.438514 | E9: =_xlfn.XLOOKUP($C9,SEM!$B:$B,SEM!$E:$E)*Model_1!$E$3 -> 3.8046021 | H9: =Input_1_coef.*_xlfn.XLOOKUP($C9,COMBINED!$B:$B,COMBINED!$AB:$AB)+Input_2_coef.*_xlfn.XLOOKUP($C9,COMBINED!$B:$B,COMBINED!$AC:$AC) -> 34.243116 | I9: =_xlfn.XLOOKUP($C9,COMBINED!$B:$B,COMBINED!$N:$N) -> 36.670298 | M9: =Total_Output_coef.*$H9*_R²_Output+(HWF_In_service_training_coef.*Percentage_of_people_trained*$H9)+($H9*Incentive*Percentage_of_people_incentivised) -> 5.396715 | O9: =Output_1_Coef.*$M9*_R²_Output -> 1.1990421 | P9: =Output_2_Coef.*$M9*_R²_Output -> 0.61069227 | Q9: =Output_3_Coef.*$M9*_R²_Output -> 1.3018172 | S9: =Total_Outcome_coef.*M9*_R²_Outcome -> -0.99679486 | U9: =Outcome_1_Coef.*$S9*_R²_Outcome -> -0.38459934 | V9: =Outcome_2_Coef.*$S9*_R²_Outcome -> 0.26731646 | W9: =Outcome_3_Coef.*$S9*_R²_Outcome -> -0.25403915 | Y9: =H9*$Y$3*_R²_Outcome -> -5.2605644 | Z9: =Y9+S9 -> -6.2573593 | AB9: =_R²_Impact*$Z9*Impact_1_Coef.*Total_Impact_coef. -> 1.620788 | AC9: =_R²_Impact*$Z9*Impact_2_Coef.*Total_Impact_coef. -> 1.5831748 | AD9: =_xlfn.XLOOKUP($C9,SEM!$B:$B,SEM!$D:$D)+_xlfn.XLOOKUP($C9,SEM!$B:$B,SEM!$E:$E) -> 38.43483 | AE9: =_xlfn.XLOOKUP($C9,SEM!$B:$B,COMBINED!$AE:$AE)*AD9 -> 350064.43 | AF9: =_xlfn.XLOOKUP($C9,SEM!$B:$B,SEM!C:C) -> 2483754 | AG9: =AF9*AB9 -> 4025638.8 | AH9: =AG9/AE9 -> 11.499708
B10: Burkina Faso | C10: BFA | D10: =_xlfn.XLOOKUP($C10,SEM!$B:$B,SEM!$D:$D)*Model_1!$D$3 -> 10.388772 | E10: =_xlfn.XLOOKUP($C10,SEM!$B:$B,SEM!$E:$E)*Model_1!$E$3 -> 1.7875747 | H10: =Input_1_coef.*_xlfn.XLOOKUP($C10,COMBINED!$B:$B,COMBINED!$AB:$AB)+Input_2_coef.*_xlfn.XLOOKUP($C10,COMBINED!$B:$B,COMBINED!$AC:$AC) -> 12.176347 | I10: =_xlfn.XLOOKUP($C10,COMBINED!$B:$B,COMBINED!$N:$N) -> 12.022002 | M10: =Total_Output_coef.*$H10*_R²_Output+(HWF_In_service_training_coef.*Percentage_of_people_trained*$H10)+($H10*Incentive*Percentage_of_people_incentivised) -> 1.9189922 | O10: =Output_1_Coef.*$M10*_R²_Output -> 0.42636169 | P10: =Output_2_Coef.*$M10*_R²_Output -> 0.21715316 | Q10: =Output_3_Coef.*$M10*_R²_Output -> 0.46290698 | S10: =Total_Outcome_coef.*M10*_R²_Outcome -> -0.35444554 | U10: =Outcome_1_Coef.*$S10*_R²_Outcome -> -0.13675785 | V10: =Outcome_2_Coef.*$S10*_R²_Outcome -> 0.095053787 | W10: =Outcome_3_Coef.*$S10*_R²_Outcome -> -0.090332572 | Y10: =H10*$Y$3*_R²_Outcome -> -1.8705791 | Z10: =Y10+S10 -> -2.2250246 | AB10: =_R²_Impact*$Z10*Impact_1_Coef.*Total_Impact_coef. -> 0.5763283 | AC10: =_R²_Impact*$Z10*Impact_2_Coef.*Total_Impact_coef. -> 0.56295359 | AD10: =_xlfn.XLOOKUP($C10,SEM!$B:$B,SEM!$D:$D)+_xlfn.XLOOKUP($C10,SEM!$B:$B,SEM!$E:$E) -> 13.939877 | AE10: =_xlfn.XLOOKUP($C10,SEM!$B:$B,COMBINED!$AE:$AE)*AD10 -> 380767.73 | AF10: =_xlfn.XLOOKUP($C10,SEM!$B:$B,SEM!C:C) -> 22720842 | AG10: =AF10*AB10 -> 13094664 | AH10: =AG10/AE10 -> 34.390163
B11: Burundi | C11: BDI | D11: =_xlfn.XLOOKUP($C11,SEM!$B:$B,SEM!$D:$D)*Model_1!$D$3 -> 8.9556615 | E11: =_xlfn.XLOOKUP($C11,SEM!$B:$B,SEM!$E:$E)*Model_1!$E$3 -> 1.9559756 | H11: =Input_1_coef.*_xlfn.XLOOKUP($C11,COMBINED!$B:$B,COMBINED!$AB:$AB)+Input_2_coef.*_xlfn.XLOOKUP($C11,COMBINED!$B:$B,COMBINED!$AC:$AC) -> 10.911637 | I11: =_xlfn.XLOOKUP($C11,COMBINED!$B:$B,COMBINED!$N:$N) -> 11.321517 | M11: =Total_Output_coef.*$H11*_R²_Output+(HWF_In_service_training_coef.*Percentage_of_people_trained*$H11)+($H11*Incentive*Percentage_of_people_incentivised) -> 1.719674 | O11: =Output_1_Coef.*$M11*_R²_Output -> 0.38207717 | P11: =Output_2_Coef.*$M11*_R²_Output -> 0.19459831 | Q11: =Output_3_Coef.*$M11*_R²_Output -> 0.41482664 | S11: =Total_Outcome_coef.*M11*_R²_Outcome -> -0.31763067 | U11: =Outcome_1_Coef.*$S11*_R²_Outcome -> -0.12255335 | V11: =Outcome_2_Coef.*$S11*_R²_Outcome -> 0.085180921 | W11: =Outcome_3_Coef.*$S11*_R²_Outcome -> -0.080950081 | Y11: =H11*$Y$3*_R²_Outcome -> -1.6762893 | Z11: =Y11+S11 -> -1.99392 | AB11: =_R²_Impact*$Z11*Impact_1_Coef.*Total_Impact_coef. -> 0.51646733 | AC11: =_R²_Impact*$Z11*Impact_2_Coef.*Total_Impact_coef. -> 0.5044818 | AD11: =_xlfn.XLOOKUP($C11,SEM!$B:$B,SEM!$D:$D)+_xlfn.XLOOKUP($C11,SEM!$B:$B,SEM!$E:$E) -> 12.714366 | AE11: =_xlfn.XLOOKUP($C11,SEM!$B:$B,COMBINED!$AE:$AE)*AD11 -> 187117.32 | AF11: =_xlfn.XLOOKUP($C11,SEM!$B:$B,SEM!C:C) -> 12999141 | AG11: =AF11*AB11 -> 6713631.7 | AH11: =AG11/AE11 -> 35.879263
B12: Cabo Verde | C12: CPV | D12: =_xlfn.XLOOKUP($C12,SEM!$B:$B,SEM!$D:$D)*Model_1!$D$3 -> 23.302042 | E12: =_xlfn.XLOOKUP($C12,SEM!$B:$B,SEM!$E:$E)*Model_1!$E$3 -> 0 | H12: =Input_1_coef.*_xlfn.XLOOKUP($C12,COMBINED!$B:$B,COMBINED!$AB:$AB)+Input_2_coef.*_xlfn.XLOOKUP($C12,COMBINED!$B:$B,COMBINED!$AC:$AC) -> 23.302042 | I12: =_xlfn.XLOOKUP($C12,COMBINED!$B:$B,COMBINED!$N:$N) -> 24.000474 | M12: =Total_Output_coef.*$H12*_R²_Output+(HWF_In_service_training_coef.*Percentage_of_people_trained*$H12)+($H12*Incentive*Percentage_of_people_incentivised) -> 3.6724018 | O12: =Output_1_Coef.*$M12*_R²_Output -> 0.81593424 | P12: =Output_2_Coef.*$M12*_R²_Output -> 0.41556899 | Q12: =Output_3_Coef.*$M12*_R²_Output -> 0.88587146 | S12: =Total_Outcome_coef.*M12*_R²_Outcome -> -0.67830731 | U12: =Outcome_1_Coef.*$S12*_R²_Outcome -> -0.26171538 | V12: =Outcome_2_Coef.*$S12*_R²_Outcome -> 0.18190574 | W12: =Outcome_3_Coef.*$S12*_R²_Outcome -> -0.17287069 | Y12: =H12*$Y$3*_R²_Outcome -> -3.5797529 | Z12: =Y12+S12 -> -4.2580602 | AB12: =_R²_Impact*$Z12*Impact_1_Coef.*Total_Impact_coef. -> 1.1029274 | AC12: =_R²_Impact*$Z12*Impact_2_Coef.*Total_Impact_coef. -> 1.077332 | AD12: =_xlfn.XLOOKUP($C12,SEM!$B:$B,SEM!$D:$D)+_xlfn.XLOOKUP($C12,SEM!$B:$B,SEM!$E:$E) -> 24.528465 | AE12: =_xlfn.XLOOKUP($C12,SEM!$B:$B,COMBINED!$AE:$AE)*AD12 -> 33751.168 | AF12: =_xlfn.XLOOKUP($C12,SEM!$B:$B,SEM!C:C) -> 573322 | AG12: =AF12*AB12 -> 632332.54 | AH12: =AG12/AE12 -> 18.735131
B13: Cameroon | C13: CMR | D13: =_xlfn.XLOOKUP($C13,SEM!$B:$B,SEM!$D:$D)*Model_1!$D$3 -> 7.3058506 | E13: =_xlfn.XLOOKUP($C13,SEM!$B:$B,SEM!$E:$E)*Model_1!$E$3 -> 1.7263244 | H13: =Input_1_coef.*_xlfn.XLOOKUP($C13,COMBINED!$B:$B,COMBINED!$AB:$AB)+Input_2_coef.*_xlfn.XLOOKUP($C13,COMBINED!$B:$B,COMBINED!$AC:$AC) -> 9.032175 | I13: =_xlfn.XLOOKUP($C13,COMBINED!$B:$B,COMBINED!$N:$N) -> 8.1868339 | M13: =Total_Output_coef.*$H13*_R²_Output+(HWF_In_service_training_coef.*Percentage_of_people_trained*$H13)+($H13*Incentive*Percentage_of_people_incentivised) -> 1.4234708 | O13: =Output_1_Coef.*$M13*_R²_Output -> 0.31626674 | P13: =Output_2_Coef.*$M13*_R²_Output -> 0.16107995 | Q13: =Output_3_Coef.*$M13*_R²_Output -> 0.34337531 | S13: =Total_Outcome_coef.*M13*_R²_Outcome -> -0.26292075 | U13: =Outcome_1_Coef.*$S13*_R²_Outcome -> -0.10144429 | V13: =Outcome_2_Coef.*$S13*_R²_Outcome -> 0.070509034 | W13: =Outcome_3_Coef.*$S13*_R²_Outcome -> -0.06700693 | Y13: =H13*$Y$3*_R²_Outcome -> -1.3875588 | Z13: =Y13+S13 -> -1.6504796 | AB13: =_R²_Impact*$Z13*Impact_1_Coef.*Total_Impact_coef. -> 0.42750903 | AC13: =_R²_Impact*$Z13*Impact_2_Coef.*Total_Impact_coef. -> 0.41758793 | AD13: =_xlfn.XLOOKUP($C13,SEM!$B:$B,SEM!$D:$D)+_xlfn.XLOOKUP($C13,SEM!$B:$B,SEM!$E:$E) -> 10.591755 | AE13: =_xlfn.XLOOKUP($C13,SEM!$B:$B,COMBINED!$AE:$AE)*AD13 -> 248069.48 | AF13: =_xlfn.XLOOKUP($C13,SEM!$B:$B,SEM!C:C) -> 28608129 | AG13: =AF13*AB13 -> 12230233 | AH13: =AG13/AE13 -> 49.301644
B14: Central African Republic | C14: CAF | D14: =_xlfn.XLOOKUP($C14,SEM!$B:$B,SEM!$D:$D)*Model_1!$D$3 -> 9.9847476 | E14: =_xlfn.XLOOKUP($C14,SEM!$B:$B,SEM!$E:$E)*Model_1!$E$3 -> 0.043098288 | H14: =Input_1_coef.*_xlfn.XLOOKUP($C14,COMBINED!$B:$B,COMBINED!$AB:$AB)+Input_2_coef.*_xlfn.XLOOKUP($C14,COMBINED!$B:$B,COMBINED!$AC:$AC) -> 10.027846 | I14: =_xlfn.XLOOKUP($C14,COMBINED!$B:$B,COMBINED!$N:$N) -> 12.601736 | M14: =Total_Output_coef.*$H14*_R²_Output+(HWF_In_service_training_coef.*Percentage_of_people_trained*$H14)+($H14*Incentive*Percentage_of_people_incentivised) -> 1.5803885 | O14: =Output_1_Coef.*$M14*_R²_Output -> 0.35113072 | P14: =Output_2_Coef.*$M14*_R²_Output -> 0.17883676 | Q14: =Output_3_Coef.*$M14*_R²_Output -> 0.38122764 | S14: =Total_Outcome_coef.*M14*_R²_Outcome -> -0.29190408 | U14: =Outcome_1_Coef.*$S14*_R²_Outcome -> -0.1126271 | V14: =Outcome_2_Coef.*$S14*_R²_Outcome -> 0.078281669 | W14: =Outcome_3_Coef.*$S14*_R²_Outcome -> -0.074393506 | Y14: =H14*$Y$3*_R²_Outcome -> -1.5405178 | Z14: =Y14+S14 -> -1.8324219 | AB14: =_R²_Impact*$Z14*Impact_1_Coef.*Total_Impact_coef. -> 0.47463592 | AC14: =_R²_Impact*$Z14*Impact_2_Coef.*Total_Impact_coef. -> 0.46362116 | AD14: =_xlfn.XLOOKUP($C14,SEM!$B:$B,SEM!$D:$D)+_xlfn.XLOOKUP($C14,SEM!$B:$B,SEM!$E:$E) -> 10.582695 | AE14: =_xlfn.XLOOKUP($C14,SEM!$B:$B,COMBINED!$AE:$AE)*AD14 -> 68268.964 | AF14: =_xlfn.XLOOKUP($C14,SEM!$B:$B,SEM!C:C) -> 5119136 | AG14: =AF14*AB14 -> 2429725.8 | AH14: =AG14/AE14 -> 35.590489
