Workbook

Sheet COMBINED
A1: Country | B1: ISO | C1: Population_2023 | D1: HAQ | E1: Productivity | F1: GINI INDEX | G1: Density_2023_Medical Doctors | H1: Density_2023_Nursing Personnel | I1: Density_2023_Midwifery Personnel | J1: Density_2023_Dentists | K1: Density_2023_Pharmacists | L1: Density_2023_Medical and Pathology Laboratory Scientists | M1: Density_2023_Medical and Pathology Laboratory Technicians | N1: Density_7_cadres_2023 | O1: GDP_PPP_2023 | P1: GDP_PPP_2024 | Q1: HALE_2021 | R1: SCI_Capacity and Access | S1: SCI_Infectious diseases | T1: SCI_NCD | U1: SCI_RMNCH | V1: SCI_Average | W1: DALYS_2021_All Causes per capita 2021 | X1: DALYS_2021_Communicable, maternal, perinatal and nutritional conditions per capita 2021 | Y1: DALYS_2021_Noncommunicable diseases per capita (2021) | Z1: DALYS_2021_Injuries per capita 2021 | AA1: Health_Security_Index_2021
A2: Algeria | B2: DZA | C2: 46053477 | D2: 58.66345 | E2: 28.18 | F2: 37.36 | G2: 16.39659 | H2: 22.750942 | I2: 2.0148316 | J2: 3.5224268 | K2: 2.9622085 | L2: 0.029530886 | M2: 3.3087621 | N2: 50.985293 | O2: 15227.463 | P2: 15545.11 | Q2: 65.548195 | R2: 88.72 | S2: 82.21 | T2: 60.71 | U2: 68.12 | V2: 74.94 | W2: 0.25858507 | X2: 0.054826069 | Y2: 0.17657851 | Z2: 0.02400285 | AA2: 26.2
A3: Angola | B3: AGO | C3: 36148636 | D3: 29.30257 | E3: 9.49 | F3: 45 | G3: 2.4047934 | H3: 18.456575 | I3: 0.0091289752 | J3: 0.070265445 | K3: 0.39669547 | L3: 0.0035962629 | M3: 0.004979441 | N3: 21.346034 | O3: 8781.558 | P3: 8866.691 | Q3: 53.761871 | R3: 21.08 | S3: 36.07 | T3: 53.76 | U3: 44.51 | V3: 38.855 | W3: 0.55586603 | X3: 0.34291113 | Y3: 0.16924787 | Z3: 0.040767474 | AA3: 29.1
A4: Benin | B4: BEN | C4: 13124347 | D4: 31.40346 | E4: 4.16 | F4: 37.6 | G4: 2.3178296 | H4: 4.7164251 | I4: 1.8484729 | J4: 0.050288216 | K4: 0.32992118 | L4: 0.5089777 | M4: 1.2434904 | N4: 11.015405 | O4: 3829.285 | P4: 3966.803 | Q4: 55.715813 | R4: 16.86 | S4: 47 | T4: 60.77 | U4: 42.82 | V4: 41.8625 | W4: 0.5415334 | X4: 0.32523931 | Y4: 0.16627788 | Z4: 0.047324915 | AA4: 25.4
A5: Botswana | B5: BWA | C5: 2483754 | D5: 37.50613 | E5: 23.79 | F5: 57.4 | G5: 3.78862 | H5: 30.135835 | I5: 0 | J5: 0.35832856 | K5: 0.5314536 | L5: 0.60392454 | M5: 1.2521369 | N5: 36.670298 | O5: 17551.773 | P5: 16749.389 | Q5: 53.103672 | R5: 43.33 | S5: 66.05 | T5: 60.17 | U5: 53.85 | V5: 55.85 | W5: 0.51046947 | X5: 0.29056739 | Y5: 0.16281769 | Z5: 0.03681854 | AA5: 33.6
A6: Burkina Faso | B6: BFA | C6: 22720842 | D6: 28.46235 | E6: 4.3 | F6: 0 | G6: 1.4625338 | H6: 5.994056 | I6: 3.6217848 | J6: 0.058536563 | K6: 0.39655221 | L6: 0.0026407472 | M6: 0.48589749 | N6: 12.022002 | O6: 2462.852 | P6: 2508.528 | Q6: 54.562424 | R6: 14.92 | S6: 50.01 | T6: 54.76 | U6: 60.22 | V6: 44.9775 | W6: 0.53931546 | X6: 0.30772701 | Y6: 0.16837414 | Z6: 0.059056873 | AA6: 29.8
A7: Burundi | B7: BDI | C7: 12999141 | D7: 25.83942 | E7: 0.9 | F7: 33.33 | G7: 0.7985143 | H7: 8.3643988 | I7: 0.37156301 | J7: 0.010769942 | K7: 0.095390919 | L7: 0.98006476 | M7: 0.70081554 | N7: 11.321517 | O7: 875.157 | P7: 879.67 | Q7: 55.844139 | R7: 13.85 | S7: 60.47 | T7: 59.39 | U7: 59.42 | V7: 48.2825 | W7: 0.46057153 | X7: 0.25291885 | Y7: 0.15453908 | Z7: 0.051080321 | AA7: 22.1
A8: Cabo Verde | B8: CPV | C8: 573322 | D8: 50.24222 | E8: 11.35 | F8: 52.5 | G8: 6.6454802 | H8: 16.378231 | I8: 0.45349734 | J8: 0.13953764 | K8: 0.17442205 | L8: 0.069768821 | M8: 0.13953764 | N8: 24.000474 | O8: 9530.21 | P8: 10052.799 | Q8: 63.765907 | R8: 66.2 | S8: 90.4 | T8: 56.77 | U8: 75.55 | V8: 72.23 | W8: 0.28416804 | X8: 0.064726853 | Y8: 0.18145936 | Z8: 0.034756189 | AA8: 34.1
A9: Cameroon | B9: CMR | C9: 28608129 | D9: 33.72569 | E9: 6.23 | F9: 49 | G9: 1.3150108 | H9: 5.7798257 | I9: 0.58479882 | J9: 0.11080767 | K9: 0.2104297 | L9: 0.10241844 | M9: 0.083542688 | N9: 8.1868339 | O9: 4829.024 | P9: 4880.519 | Q9: 54.007027 | R9: 28.28 | S9: 56.12 | T9: 49.14 | U9: 47.52 | V9: 45.265 | W9: 0.54981019 | X9: 0.32608299 | Y9: 0.1751217 | Z9: 0.042805912 | AA9: 28.6
A10: Central African Republic | B10: CAF | C10: 5119136 | D10: 15.16031 | E10: 1.57 | F10: 59.27 | G10: 0.74817313 | H10: 7.3371756 | I10: 3.7057035 | J10: 0.0058603639 | K10: 0.02539491 | L10: 0.21878692 | M10: 0.56064148 | N10: 12.601736 | O10: 1163.458 | P10: 1145.161 | Q10: 45.432892 | R10: 16.76 | S10: 38.69 | T10: 43.77 | U10: 38.17 | V10: 34.3475 | W10: 0.83557862 | X10: 0.58633456 | Y10: 0.16570339 | Z10: 0.07557031 | AA10: 18.6
A11: Chad | B11: TCD | C11: 17921183 | D11: 23.75145 | E11: 3.29 | F11: 36.9 | G11: 0.91567616 | H11: 1.3263633 | I11: 0.47150905 | J11: 0.0072539854 | K11: 0.090953817 | L11: 0.57362285 | M11: 0.58478282 | N11: 3.970162 | O11: 2623.622 | P11: 2588.82 | Q11: 51.51506 | R11: 10.76 | S11: 41.09 | T11: 58.54 | U11: 28.87 | V11: 34.815 | W11: 0.72291648 | X11: 0.50936099 | Y11: 0.15067299 | Z11: 0.056395953 | AA11: 23.9
A12: Comoros | B12: COM | C12: 926492 | D12: 31.80644 | E12: 6.02 | F12: 55.92 | G12: 3.8208641 | H12: 8.4728201 | I12: 6.3249332 | J12: 0.34538884 | K12: 0.43173605 | L12: 1.7377376 | M12: 0.17269442 | N12: 21.306174 | O12: 3356.835 | P12: 3392.316 | Q12: 59.019386 | R12: 37.44 | S12: 51.48 | T12: 56.05 | U12: 49.64 | V12: 48.6525 | W12: 0.3998434 | X12: 0.18043054 | Y12: 0.17489083 | Z12: 0.039609689 | AA12: 24.9
A13: Congo | B13: COG | C13: 5940746 | D13: 33.95313 | E13: 7.57 | F13: 41.9 | G13: 1.7539885 | H13: 9.3809767 | I13: 2.0031154 | J13: 0.016832903 | K13: 0.053865289 | L13: 0.53865289 | M13: 1.3079165 | N13: 15.055348 | O13: 5633.357 | P13: 5622.161 | Q13: 54.835735 | R13: 28.57 | S13: 36.21 | T13: 52.47 | U13: 52.06 | V13: 42.3275 | W13: 0.45539965 | X13: 0.27170787 | Y13: 0.15151453 | Z13: 0.027856401 | AA13: 26.3
... A39: Senegal | B39: SEN | C39: 18116526 | D39: 33.96112 | E39: 6.73 | F39: 58.7 | G39: 1.0890609 | H39: 2.6384749 | I39: 1.5952286 | J39: 0.10874049 | K39: 0.20147351 | L39: 0 | M39: 0.14351537 | N39: 5.7764938 | O39: 4300.203 | P39: 4464.78 | Q39: 58.903 | R39: 30.05 | S39: 63.69 | T39: 55.65 | U39: 59.11 | V39: 52.125 | W39: 0.36508063 | X39: 0.16490721 | Y39: 0.15800663 | Z39: 0.036505767 | AA39: 32.8
A40: Seychelles | B40: SYC | C40: 99912 | D40: 52.842651 | F40: 46 | G40: 82.872928 | H40: 62.555048 | I40: 31.22748 | J40: 4.4038754 | K40: 5.4047562 | L40: 1.0008808 | M40: 2.1018496 | N40: 189.56682 | O40: 34366.619 | P40: 35085.182 | Q40: 64.721451 | R40: 78.3 | S40: 87.12 | T40: 57.3 | U40: 79.13 | V40: 75.4625 | W40: 0.31209413 | X40: 0.067825983 | Y40: 0.22109038 | Z40: 0.023145292 | AA40: 31.8
A41: Sierra Leone | B41: SLE | C41: 8472212 | D41: 30.91938 | E41: 2.63 | F41: 59 | G41: 1.3054442 | H41: 8.6825023 | I41: 2.6805278 | J41: 0.017704939 | K41: 0.10504931 | L41: 0 | M41: 0.35173813 | N41: 13.142967 | O41: 2920.12 | P41: 2966.491 | Q41: 53.127224 | R41: 14.19 | S41: 50.54 | T41: 54.72 | U41: 72.06 | V41: 47.8775 | W41: 0.62214616 | X41: 0.39564769 | Y41: 0.17921993 | Z41: 0.04572357 | AA41: 32.7
A42: South Africa | B42: ZAF | C42: 61452696 | D42: 44.56413 | E42: 21.64 | F42: 54 | G42: 8.0603461 | H42: 64.645008 | I42: 0.25108744 | J42: 0.19039035 | K42: 2.7385292 | L42: 0.0021154483 | M42: 0.18062674 | N42: 76.068103 | O42: 13897.062 | P42: 13771.97 | Q42: 52.757084 | R42: 79.53 | S42: 68.77 | T42: 60.66 | U42: 76.38 | V42: 71.335 | W42: 0.59898341 | X42: 0.27289034 | Y42: 0.23352654 | Z42: 0.066110009 | AA42: 45.8
A43: South Sudan | B43: SSD | C43: 11891023 | D43: 29.1139 | E43: 3.35 | F43: 46.32 | G43: 0.38348256 | H43: 3.8095965 | I43: 2.596917 | J43: 0.026911057 | K43: 0.13455529 | L43: 0.53401629 | M43: 0.22874399 | N43: 7.7142227 | O43: 938.257 | P43: 660.094 | Q43: 50.530018 | R43: 21.91 | S43: 35.58 | T43: 59.48 | U43: 29.42 | V43: 36.5975 | W43: 0.63690566 | X43: 0.41618333 | Y43: 0.15884745 | Z43: 0.057924879 | AA43: 21.3
A44: Togo | B44: UGA | C44: 49700758 | D44: 32.35637 | E44: 4.33 | F44: 40.1 | G44: 1.8213002 | H44: 14.928746 | I44: 6.631086 | J44: 0.1014069 | K44: 0.34446155 | L44: 0.75894215 | M44: 2.6921119 | N44: 27.278055 | O44: 3143.583 | P44: 3240.979 | Q44: 55.849014 | R44: 22.84 | S44: 55.37 | T44: 56.9 | U44: 52.14 | V44: 46.8125 | W44: 0.39850537 | X44: 0.21625225 | Y44: 0.13944238 | Z44: 0.040092692 | AA44: 27.8
A45: Uganda | B45: TZA | C45: 65136238 | D45: 32.46088 | E45: 3.2 | F45: 41.2 | G45: 1.3345874 | H45: 7.0860709 | I45: 0 | J45: 0.1159109 | K45: 0.34727213 | L45: 0.23826982 | M45: 0.72816609 | N45: 9.8502772 | O45: 3553.409 | P45: 3638.147 | Q45: 57.224392 | R45: 27.27 | S45: 54.91 | T45: 54.5 | U45: 68.17 | V45: 51.2125 | W45: 0.40710628 | X45: 0.22733353 | Y45: 0.14378753 | Z45: 0.03339787 | AA45: 36.5
A46: United Republic of Tanzania | B46: TGO | C46: 8886635 | D46: 33.47842 | E46: 3.7 | F46: 33.8 | G46: 0.82145829 | H46: 2.9595004 | I46: 2.0975319 | J46: 0.024756277 | K46: 0.28694776 | L46: 0.14178595 | M46: 0.46586813 | N46: 6.7978487 | O46: 2815.904 | P46: 2895.085 | Q46: 58.072868 | R46: 19.6 | S46: 52.66 | T46: 50.72 | U46: 63.1 | V46: 46.52 | W46: 0.48252291 | X46: 0.25168432 | Y46: 0.18194219 | Z46: 0.045928544 | AA46: 31.3
A47: Zambia | B47: ZMB | C47: 20032801 | D47: 31.61706 | E47: 5.23 | F47: 52.3 | G47: 3.2601532 | H47: 24.946586 | I47: 4.5934665 | J47: 0.14126831 | K47: 0.71133338 | L47: 0.20915697 | M47: 0.76524496 | N47: 34.62721 | O47: 3701.027 | P47: 3747.732 | Q47: 52.970093 | R47: 37.54 | S47: 60.64 | T47: 57.47 | U47: 74.31 | V47: 57.49 | W47: 0.50513805 | X47: 0.30859836 | Y47: 0.15379622 | Z47: 0.036071447 | AA47: 26.5
A48: Zimbabwe | B48: ZWE | C48: 15581023 | D48: 28.5771 | E48: 4.5 | F48: 46 | G48: 1.4260938 | H48: 29.867744 | I48: 1.8002669 | J48: 0.31576874 | K48: 1.2207157 | L48: 0.92997745 | M48: 0.67710573 | N48: 36.237672 | O48: 4473.673 | P48: 4465.361 | Q48: 51.248913 | R48: 40.41 | S48: 47.83 | T48: 66.74 | U48: 71.16 | V48: 56.535 | W48: 0.55124774 | X48: 0.29968262 | Y48: 0.1852836 | Z48: 0.057561611 | AA48: 32.4

Sheet Variables
B2: Country
B3: ISO
B4: Population_2023
B5: HAQ | C5: Healthcare Access and Quality (HAQ) Index is a metric developed by the Institute for Health Metrics and Evaluation (IHME) to assess health system performance.
B6: Productivity | C6: The Productivity Index developed by the International Labour Organization (ILO) measures the efficiency of labour in generating economic output.
B7: GINI INDEX | C7: The Gini coefficient is a key economic metric for measuring income or wealth inequality within a population
B8: Density_2023_Medical Doctors | C8: per 10000 population
B9: Density_2023_Nursing Personnel | C9: per 10000 population
B10: Density_2023_Midwifery Personnel | C10: per 10000 population
B11: Density_2023_Dentists | C11: per 10000 population
B12: Density_2023_Pharmacists | C12: per 10000 population
B13: Density_2023_Medical and Pathology Laboratory Scientists | C13: per 10000 population
B14: Density_2023_Medical and Pathology Laboratory Technicians | C14: per 10000 population
B15: Density_7_cadres_2023 | C15: per 10000 population
B16: GDP_PPP_2023 | C16: Measures a country’s economic output adjusted for price differences across countries (PPP) and inflation (constant currency).
B17: GDP_PPP_2024
B18: HALE_2021 | C18: HALE estimates the average number of years a person can expect to live in full health (discounting years lived with illness/disability). It combines mortality and morbidity data into a single metric.
B19: SCI_Capacity and Access | C19: The UHC Service Coverage Index (SCI) is a WHO-developed metric to track progress toward Universal Health Coverage (UHC) by measuring health service capacity and access.
B20: SCI_Infectious diseases | C20: measures a country's capacity to prevent, detect, and treat communicable diseases
B21: SCI_NCD | C21: evaluates a health system's capacity to prevent, diagnose, and manage chronic diseases
B22: SCI_RMNCH | C22: measures coverage of essential health services for women and children, including prenatal care, skilled birth attendance, immunization, and postnatal care.
B23: SCI_Average
B24: DALYS_2021_All Causes per capita 2021 | C24: measures the average number of healthy life years lost per person in 2021 due to all diseases and injuries, combining premature death and disability.
B25: DALYS_2021_Communicable, maternal, perinatal and nutritional conditions per capita 2021 | C25: measures the average number of healthy life years lost per person in 2021 due to infectious diseases, pregnancy-related complications, birth conditions, and nutritional deficiencies.
B26: DALYS_2021_Noncommunicable diseases per capita (2021) | C26: measures the average number of healthy life years lost per person in 2021 due to Noncommunicable diseases deficiencies.
B27: DALYS_2021_Injuries per capita 2021 | C27: measures the average number of healthy life years lost per person in 2021 due to Injuries
B28: Health_Security_Index_2021 | C28: global benchmark that assesses how well 195 countries are prepared to prevent, detect, and respond to infectious disease threats, revealing widespread gaps in pandemic readiness

Sheet Tuition and salaries
C3: Tuition fees
D4: Generalist Medical Practitioners | E4: Nursing Professionals | F4: Midwifery personnel | G4: Pharmacists | H4: Dentists | I4: Paramedical Practitioners
C5: Variable | D5: Medical Doctors | E5: Nursing Personnel | F5: Midwifery personnel | G5: Pharmacists | H5: Dentist | I5: Clinical Officer/Physician Assistant
C6: Median | D6: 3510.5 | E6: 1881 | F6: 1434 | G6: 1165 | H6: 5292 | I6: 20000
C7: Average | D7: 5843.1667 | E7: 5020.1 | F7: 4508.6 | G7: 5297.6 | H7: 7995.75 | I7: 20000
C8: Minimum | D8: 851 | E8: 400 | F8: 404 | G8: 637 | H8: 799 | I8: 20000
C9: Maximum | D9: 20600 | E9: 11538.5 | F9: 10000 | G9: 18600 | H9: 20600 | I9: 20000
C10: Number of countries | D10: 6 | E10: 5 | F10: 5 | G10: 5 | H10: 4 | I10: 1
C15: Estimated Salaries of Health Workers
F16: 11856.737
C17: Occupation | D17: Median | E17: Minimum | F17: Maximum | G17: Number of Countries
C18: Audiologists and Speech Therapists | D18: 8475.8805 | E18: 3176.4688 | F18: 11856.737 | G18: Inputed with average | H18: =IF(F18<D18,"Check","") | W18: Average | X18: Median | Y18: Min | Z18: Max
C19: Community Health Workers | D19: 2100.5642 | E19: 18.910956 | F19: 6691.2 | G19: 10 | H19: =IF(F19<D19,"Check","") | W19: 11856.737 | X19: 8475.8805 | Y19: 3176.4688 | Z19: 42931.282
B20: Dentist | C20: Dentists | D20: 24675.147 | E20: 4350 | F20: 65003.378 | G20: 13 | H20: =IF(F20<D20,"Check","")
C21: Dental Assistants and Therapists | D21: 8475.8805 | E21: 3176.4688 | F21: 11856.737 | G21: Inputed with average | H21: =IF(F21<F16,"Check","")
C22: Dieticians and nutritionists | D22: 8475.8805 | E22: 3176.4688 | F22: 11856.737 | G22: Inputed with average | H22: =IF(F22<D22,"Check","")
C23: Environmental and occupational health & hygiene workers | D23: 8373.3581 | E23: 2274.6189 | F23: 23780.741 | G23: 14 | H23: =IF(F23<D23,"Check","")
B24: Medical Doctors | C24: Generalist Medical Practitioners | D24: 16711.451 | E24: 4350 | F24: 70131.643 | G24: 17 | H24: =IF(F24<D24,"Check","")
C25: Medical and dental Prosthetic Technicians | D25: 8475.8805 | E25: 3176.4688 | F25: 11856.737 | G25: Inputed with average | H25: =IF(F25<D25,"Check","")
B26: Other Health Workers | C26: Medical and Pathology Laboratory scientists | D26: 7741.2876 | E26: 3030.4286 | F26: 96426.69 | G26: 15 | H26: =IF(F26<D26,"Check","")
C27: Medical and Pathology Laboratory Technicians | D27: 8475.8805 | E27: 3176.4688 | F27: 11856.737 | G27: Inputed with average | H27: =IF(F27<D27,"Check","")
C28: Medical Imaging and Therapeutic Equipment Technicians | D28: 7741.2876 | E28: 3525.7655 | F28: 43430.123 | G28: 15 | H28: =IF(F28<D28,"Check","")
B29: Midwifery personnel | C29: Midwifery personnel | D29: 8216.3677 | E29: 4119.0419 | F29: 22257.168 | G29: 6.6666667 | H29: =IF(F29<D29,"Check","")
B30: Nursing Personnel | C30: Nursing Personnel | D30: 7534.1459 | E30: 4119.0419 | F30: 64855.987 | G30: 8 | H30: =IF(F30<D30,"Check","")
C31: Nursing Personnel | D31: 7534.1459 | E31: 4119.0419 | F31: 64855.987 | G31: 8 | H31: =IF(F31<D31,"Check","")
C32: Optometrists and Ophthalmic Opticians | D32: 8475.8805 | E32: 3176.4688 | F32: 11856.737 | G32: Inputed with average | H32: =IF(F32<D32,"Check","")
C33: Paramedical Practitioners | D33: 6335.0389 | E33: 3525.7655 | F33: 12006 | G33: 10 | H33: =IF(F33<D33,"Check","")
C34: Pharmaceutical Technicians and Assistants | D34: 8475.8805 | E34: 3176.4688 | F34: 11856.737 | G34: Inputed with average | H34: =IF(F34<D34,"Check","")
B35: Pharmacist | C35: Pharmacists | D35: 11129.029 | E35: 4812.3086 | F35: 51236.733 | G35: 9 | H35: =IF(F35<D35,"Check","")
C36: Physiotherapists and physiotherapy assistants | D36: 12188.43 | E36: 3525.7655 | F36: 39012.857 | G36: 13 | H36: =IF(F36<D36,"Check","")
C37: Psychologists | D37: 8475.8805 | E37: 3176.4688 | F37: 11856.737 | G37: Inputed with average | H37: =IF(F37<D37,"Check","")
C38: Social workers | D38: 8475.8805 | E38: 3176.4688 | F38: 11856.737 | G38: Inputed with average | H38: =IF(F38<D38,"Check","")
C39: Specialist Medical Practitioners | D39: 33928.98 | E39: 5391 | F39: 184378.44 | G39: 15 | H39: =IF(F39<D39,"Check","")
C40: Mean | D40: 11859.994 | E40: 5611.1188 | F40: 35120.689 | H40: =IF(F40<D40,"Check","")
C41: Median | D41: 11856.737 | E41: 4581.1543 | F41: 17131.584 | H41: =IF(F41<D41,"Check","")
C48: Training Cost
C50: Occupation | D50: Median | E50: Average | F50: Minimum | G50: Maximum | H50: Number of countries
A51: Generalist Medical Practitioners | B51: Medical Doctors | C51: Generalist Medical Practitioners | D51: 10572 | E51: 17350.8 | F51: 5106 | G51: 31950 | H51: 6 | I51: 6 | J51: 2891.8
A52: Generalist Medical Practitioners | C52: Specialist Medical Practitioners | D52: 5286 | E52: 8675.4 | F52: 2553 | G52: 15975 | I52: 3
A53: Nursing Professionals | B53: Nursing Personnel | C53: Nursing Personnel | D53: 4972.5 | E53: 10171.5 | F53: 1200 | G53: 29541 | H53: 5 | I53: 3
...

Sheet Graduates
A1: Country | B1: ISO3 | C1: Generalist Medical Practitioners | D1: Nursing Personnel | E1: Midwifery personnel | F1: Dentists | G1: Other Dental practitioners | H1: Pharmacists | I1: Other Pharmacy practitioners | J1: Medical and Pathology Laboratory scientists | K1: Paramedical Practitioners | L1: Other Health Workers | M1: Total | N1: Medical Doctors | O1: Nursing Personnel | P1: Midwifery Personnel | Q1: Dentists | R1: Pharmacists | S1: Medical and Pathology Laboratory Scientists | T1: Medical Doctors | U1: Nursing Personnel | V1: Midwifery Personnel | W1: Dentists | X1: Pharmacists | Y1: Medical and Pathology Laboratory Scientists | Z1: Total core cadre training | AA1: Population | AB1: Total core cadre training per capita
A2: Mali | B2: MLI | C2: 0 | D2: 0 | E2: 0 | F2: 0 | G2: 0 | H2: 0 | I2: 0 | J2: 0 | K2: 0 | L2: 0 | M2: 0 | N2: 0 | O2: 0 | P2: 0 | Q2: 0 | R2: 0 | S2: 0 | T2: 0 | U2: 0 | V2: 0 | W2: 0 | X2: 0 | Y2: 0 | Z2: =SUM(T2:Y2) -> 0 | AA2: =VLOOKUP(B2,Salaries_total!$B$3:$C$49,2,FALSE) -> 22105727 | AB2: =Z2/AA2 -> 0
A3: Sao Tome and Principe | B3: STP | C3: 0 | D3: 0 | E3: 0 | F3: 0 | G3: 0 | H3: 0 | I3: 0 | J3: 0 | K3: 0 | L3: 0 | M3: 0 | N3: 0 | O3: 0 | P3: 0 | Q3: 0 | R3: 0 | S3: 0 | T3: 0 | U3: 0 | V3: 0 | W3: 0 | X3: 0 | Y3: 0 | Z3: =SUM(T3:Y3) -> 0 | AA3: =VLOOKUP(B3,Salaries_total!$B$3:$C$49,2,FALSE) -> 232132 | AB3: =Z3/AA3 -> 0
A4: Central African Republic | B4: CAF | C4: 18 | D4: 0 | E4: 0 | F4: 0 | G4: 0 | H4: 0 | I4: 0 | J4: 0 | K4: 0 | L4: 0 | M4: 18 | N4: 18 | O4: 0 | P4: 0 | Q4: 0 | R4: 0 | S4: 0 | T4: 370800 | U4: 0 | V4: 0 | W4: 0 | X4: 0 | Y4: 0 | Z4: =SUM(T4:Y4) -> 370800 | AA4: =VLOOKUP(B4,Salaries_total!$B$3:$C$49,2,FALSE) -> 5119136 | AB4: =Z4/AA4 -> 0.072434098
A5: Comoros | B5: COM | C5: 0 | D5: 40 | E5: 29 | F5: 0 | G5: 0 | H5: 0 | I5: 0 | J5: 0 | K5: 0 | L5: 0 | M5: 69 | N5: 0 | O5: 40 | P5: 29 | Q5: 0 | R5: 0 | S5: 0 | T5: 0 | U5: 461540 | V5: 400000 | W5: 0 | X5: 0 | Y5: 0 | Z5: =SUM(T5:Y5) -> 861540 | AA5: =VLOOKUP(B5,Salaries_total!$B$3:$C$49,2,FALSE) -> 926492 | AB5: =Z5/AA5 -> 0.9298947
A6: Cabo Verde | B6: CPV | C6: 0 | D6: 0 | E6: 0 | F6: 0 | G6: 7 | H6: 0 | I6: 0 | J6: 0 | K6: 0 | L6: 83 | M6: 90 | N6: 0 | O6: 0 | P6: 0 | Q6: 0 | R6: 0 | S6: 0 | T6: 0 | U6: 0 | V6: 0 | W6: 0 | X6: 0 | Y6: 0 | Z6: =SUM(T6:Y6) -> 0 | AA6: =VLOOKUP(B6,Salaries_total!$B$3:$C$49,2,FALSE) -> 573322 | AB6: =Z6/AA6 -> 0
A7: Seychelles | B7: SYC | C7: 10 | D7: 40 | E7: 10 | F7: 0 | G7: 0 | H7: 0 | I7: 20 | J7: 0 | K7: 0 | L7: 80 | M7: 160 | N7: 10 | O7: 40 | P7: 10 | Q7: 0 | R7: 0 | S7: 0 | T7: 206000 | U7: 461540 | V7: 400000 | W7: 0 | X7: 0 | Y7: 0 | Z7: =SUM(T7:Y7) -> 1067540 | AA7: =VLOOKUP(B7,Salaries_total!$B$3:$C$49,2,FALSE) -> 99912 | AB7: =Z7/AA7 -> 10.684803
A8: Gambia | B8: GMB | C8: 23 | D8: 137 | E8: 0 | F8: 0 | G8: 0 | H8: 0 | I8: 0 | J8: 6 | K8: 0 | L8: 0 | M8: 166 | N8: 23 | O8: 137 | P8: 0 | Q8: 0 | R8: 0 | S8: 6 | T8: 473800 | U8: 1580774.5 | V8: 1370000 | W8: 0 | X8: 0 | Y8: 69231 | Z8: =SUM(T8:Y8) -> 3493805.5 | AA8: =VLOOKUP(B8,Salaries_total!$B$3:$C$49,2,FALSE) -> 2631251 | AB8: =Z8/AA8 -> 1.3278116
A9: Gabon | B9: GAB | C9: 46 | D9: 95 | E9: 34 | F9: 0 | G9: 0 | H9: 2 | I9: 0 | J9: 6 | K9: 0 | L9: 0 | M9: 183 | N9: 46 | O9: 95 | P9: 34 | Q9: 0 | R9: 2 | S9: 6 | T9: 947600 | U9: 1096157.5 | V9: 950000 | W9: 0 | X9: 37200 | Y9: 69231 | Z9: =SUM(T9:Y9) -> 3100188.5 | AA9: =VLOOKUP(B9,Salaries_total!$B$3:$C$49,2,FALSE) -> 2383905 | AB9: =Z9/AA9 -> 1.3004665
A10: Liberia | B10: LBR | C10: 29 | D10: 63 | E10: 0 | F10: 0 | G10: 0 | H10: 22 | I10: 0 | J10: 56 | K10: 0 | L10: 50 | M10: 220 | N10: 29 | O10: 63 | P10: 0 | Q10: 0 | R10: 22 | S10: 56 | T10: 597400 | U10: 726925.5 | V10: 630000 | W10: 0 | X10: 409200 | Y10: 646156 | Z10: =SUM(T10:Y10) -> 3009681.5 | AA10: =VLOOKUP(B10,Salaries_total!$B$3:$C$49,2,FALSE) -> 5432272 | AB10: =Z10/AA10 -> 0.55403733
A11: Algeria | B11: DZA | C11: 300 | D11: 0 | E11: 0 | F11: 0 | G11: 0 | H11: 0 | I11: 0 | J11: 0 | K11: 0 | L11: 0 | M11: 300 | N11: 300 | O11: 0 | P11: 0 | Q11: 0 | R11: 0 | S11: 0 | T11: 6180000 | U11: 0 | V11: 0 | W11: 0 | X11: 0 | Y11: 0 | Z11: =SUM(T11:Y11) -> 6180000 | AA11: =VLOOKUP(B11,Salaries_total!$B$3:$C$49,2,FALSE) -> 46053477 | AB11: =Z11/AA11 -> 0.13419182
A12: Eswatini | B12: SWZ | C12: 0 | D12: 160 | E12: 80 | F12: 0 | G12: 0 | H12: 44 | I12: 30 | J12: 78 | K12: 0 | L12: 58 | M12: 450 | N12: 0 | O12: 160 | P12: 80 | Q12: 0 | R12: 44 | S12: 78 | T12: 0 | U12: 1846160 | V12: 1600000 | W12: 0 | X12: 818400 | Y12: 900003 | Z12: =SUM(T12:Y12) -> 5164563 | AA12: =VLOOKUP(B12,Salaries_total!$B$3:$C$49,2,FALSE) -> 1197512 | AB12: =Z12/AA12 -> 4.3127443
A13: Mauritania | B13: MRT | C13: 0 | D13: 113 | E13: 0 | F13: 0 | G13: 0 | H13: 0 | I13: 0 | J13: 0 | K13: 0 | L13: 366 | M13: 479 | N13: 0 | O13: 113 | P13: 0 | Q13: 0 | R13: 0 | S13: 0 | T13: 0 | U13: 1303850.5 | V13: 1130000 | W13: 0 | X13: 0 | Y13: 0 | Z13: =SUM(T13:Y13) -> 2433850.5 | AA13: =VLOOKUP(B13,Salaries_total!$B$3:$C$49,2,FALSE) -> 5030233 | AB13: =Z13/AA13 -> 0.48384449
... A48: Democratic Republic of the Congo | B48: COD | C48: 6020 | D48: 24061 | E48: 3453 | F48: 66 | G48: 0 | H48: 178 | I48: 328 | J48: 2571 | K48: 0 | L48: 3151 | M48: 39828 | N48: 6020 | O48: 24061 | P48: 3453 | Q48: 66 | R48: 178 | S48: 2571 | T48: 124012000 | U48: 2.7762785e+08 | V48: 240610000 | W48: 1359600 | X48: 3310800 | Y48: 29665484 | Z48: =SUM(T48:Y48) -> 676585732 | AA48: =VLOOKUP(B48,Salaries_total!$B$3:$C$49,2,FALSE) -> 98151951 | AB48: =Z48/AA48 -> 6.8932479
U52: Generalist Medical Practitioners | V52: Nursing Professionals | W52: Midwifery personnel | X52: Pharmacists | Y52: Dentists | Z52: Paramedical Practitioners
T53: Variable | U53: Medical Doctors | V53: Nursing Personnel | W53: Midwifery personnel | X53: Pharmacists | Y53: Dentist | Z53: Clinical Officer/Physician Assistant
T54: Median | U54: 3510.5 | V54: 1881 | W54: 1434 | X54: 1165 | Y54: 5292 | Z54: 20000
T55: Average | U55: 5843.1667 | V55: 5020.1 | W55: 4508.6 | X55: 5297.6 | Y55: 7995.75 | Z55: 20000
T56: Minimum | U56: 851 | V56: 400 | W56: 404 | X56: 637 | Y56: 799 | Z56: 20000
T57: Maximum | U57: 20600 | V57: 11538.5 | W57: 10000 | X57: 18600 | Y57: 20600 | Z57: 20000

Sheet Salaries_total
A2: Country | B2: ISO | C2: Population_2023 | D2: Density_2023_Medical Doctors | E2: Density_2023_Nursing Personnel | F2: Density_2023_Midwifery Personnel | G2: Density_2023_Dentists | H2: Density_2023_Pharmacists | I2: Density_2023_Medical and Pathology Laboratory Scientists | J2: Density_2023_Medical and Pathology Laboratory Technicians | K2: Density_7_cadres_2023 | L2: Total_2023_Medical Doctors | M2: Total_2023_Nursing Personnel | N2: Total__2023_Midwifery Personnel | O2: Total_2023_Dentists | P2: Total_2023_Pharmacists | Q2: Total_2023_Medical and Pathology Laboratory Scientists | R2: Total_2023_Medical and Pathology Laboratory Technicians | S2: Density_7_cadres_2023 | T2: Salary_Exp_2023_Medical Doctors | U2: Salary_Exp_2023_Nursing Personnel | V2: Salary_Exp_2023_Midwifery Personnel | W2: Salary_Exp_2023_Dentists | X2: Salary_Exp_2023_Pharmacists | Y2: Salary_Exp_2023_Medical and Pathology Laboratory Scientists | Z2: Salary_Exp_2023_Medical and Pathology Laboratory Technicians | AA2: Salary_Exp_7_cadres_2023 | AB2: salary per population for the 7 core cadres
A3: Algeria | B3: DZA | C3: 46053477 | D3: 16.39659 | E3: 22.750942 | F3: 2.0148316 | G3: 3.5224268 | H3: 2.9622085 | I3: 0.029530886 | J3: 3.3087621 | K3: 50.985293 | L3: =C3*D3/10000 -> 75512 | M3: =C3*E3/10000 -> 104776 | N3: =C3*F3/10000 -> 9279 | O3: =C3*G3/10000 -> 16222 | P3: =C3*H3/10000 -> 13642 | Q3: =C3*I3/10000 -> 136 | R3: =C3*J3/10000 -> 15238 | S3: =C3*K3/10000 -> 234805 | T3: =L3*16711.45 -> 1261915012 | U3: =M3*7534.14 -> 7.8939705e+08 | V3: =N3*8216.36 -> 76239604 | W3: =O3*24675.14 -> 4.0028012e+08 | X3: =P3*11129.02 -> 1.5182209e+08 | Y3: =Q3*7741.28 -> 1052814.1 | Z3: =R3*8475.88 -> 1.2915546e+08 | AA3: =SUM(T3:Z3) -> 2809862155 | AB3: =AA3/C3 -> 61.01303
A4: Angola | B4: AGO | C4: 36148636 | D4: 2.4047934 | E4: 18.456575 | F4: 0.0091289752 | G4: 0.070265445 | H4: 0.39669547 | I4: 0.0035962629 | J4: 0.004979441 | K4: 21.346034 | L4: =C4*D4/10000 -> 8693 | M4: =C4*E4/10000 -> 66718 | N4: =C4*F4/10000 -> 33 | O4: =C4*G4/10000 -> 254 | P4: =C4*H4/10000 -> 1434 | Q4: =C4*I4/10000 -> 13 | R4: =C4*J4/10000 -> 18 | S4: =C4*K4/10000 -> 77163 | T4: =L4*16711.45 -> 1.4527263e+08 | U4: =M4*7534.14 -> 5.0266275e+08 | V4: =N4*8216.36 -> 271139.88 | W4: =O4*24675.14 -> 6267485.6 | X4: =P4*11129.02 -> 15959015 | Y4: =Q4*7741.28 -> 100636.64 | Z4: =R4*8475.88 -> 152565.84 | AA4: =SUM(T4:Z4) -> 670686230 | AB4: =AA4/C4 -> 18.553569
A5: Benin | B5: BEN | C5: 13124347 | D5: 2.3178296 | E5: 4.7164251 | F5: 1.8484729 | G5: 0.050288216 | H5: 0.32992118 | I5: 0.5089777 | J5: 1.2434904 | K5: 11.015405 | L5: =C5*D5/10000 -> 3042 | M5: =C5*E5/10000 -> 6190 | N5: =C5*F5/10000 -> 2426 | O5: =C5*G5/10000 -> 66 | P5: =C5*H5/10000 -> 433 | Q5: =C5*I5/10000 -> 668 | R5: =C5*J5/10000 -> 1632 | S5: =C5*K5/10000 -> 14457 | T5: =L5*16711.45 -> 50836231 | U5: =M5*7534.14 -> 46636327 | V5: =N5*8216.36 -> 19932889 | W5: =O5*24675.14 -> 1628559.2 | X5: =P5*11129.02 -> 4818865.7 | Y5: =Q5*7741.28 -> 5171175 | Z5: =R5*8475.88 -> 13832636 | AA5: =SUM(T5:Z5) -> 142856683 | AB5: =AA5/C5 -> 10.88486
A6: Botswana | B6: BWA | C6: 2483754 | D6: 3.78862 | E6: 30.135835 | F6: 0 | G6: 0.35832856 | H6: 0.5314536 | I6: 0.60392454 | J6: 1.2521369 | K6: 36.670298 | L6: =C6*D6/10000 -> 941 | M6: =C6*E6/10000 -> 7485 | N6: =C6*F6/10000 -> 0 | O6: =C6*G6/10000 -> 89 | P6: =C6*H6/10000 -> 132 | Q6: =C6*I6/10000 -> 150 | R6: =C6*J6/10000 -> 311 | S6: =C6*K6/10000 -> 9108 | T6: =L6*16711.45 -> 15725474 | U6: =M6*7534.14 -> 56393038 | V6: =N6*8216.36 -> 0 | W6: =O6*24675.14 -> 2196087.5 | X6: =P6*11129.02 -> 1469030.6 | Y6: =Q6*7741.28 -> 1161192 | Z6: =R6*8475.88 -> 2635998.7 | AA6: =SUM(T6:Z6) -> 79580821 | AB6: =AA6/C6 -> 32.040541
A7: Burkina Faso | B7: BFA | C7: 22720842 | D7: 1.4625338 | E7: 5.994056 | F7: 3.6217848 | G7: 0.058536563 | H7: 0.39655221 | I7: 0.0026407472 | J7: 0.48589749 | K7: 12.022002 | L7: =C7*D7/10000 -> 3323 | M7: =C7*E7/10000 -> 13619 | N7: =C7*F7/10000 -> 8229 | O7: =C7*G7/10000 -> 133 | P7: =C7*H7/10000 -> 901 | Q7: =C7*I7/10000 -> 6 | R7: =C7*J7/10000 -> 1104 | S7: =C7*K7/10000 -> 27315 | T7: =L7*16711.45 -> 55532148 | U7: =M7*7534.14 -> 1.0260745e+08 | V7: =N7*8216.36 -> 67612426 | W7: =O7*24675.14 -> 3281793.6 | X7: =P7*11129.02 -> 10027247 | Y7: =Q7*7741.28 -> 46447.68 | Z7: =R7*8475.88 -> 9357371.5 | AA7: =SUM(T7:Z7) -> 2.4846489e+08 | AB7: =AA7/C7 -> 10.935549
A8: Burundi | B8: BDI | C8: 12999141 | D8: 0.7985143 | E8: 8.3643988 | F8: 0.37156301 | G8: 0.010769942 | H8: 0.095390919 | I8: 0.98006476 | J8: 0.70081554 | K8: 11.321517 | L8: =C8*D8/10000 -> 1038 | M8: =C8*E8/10000 -> 10873 | N8: =C8*F8/10000 -> 483 | O8: =C8*G8/10000 -> 14 | P8: =C8*H8/10000 -> 124 | Q8: =C8*I8/10000 -> 1274 | R8: =C8*J8/10000 -> 911 | S8: =C8*K8/10000 -> 14717 | T8: =L8*16711.45 -> 17346485 | U8: =M8*7534.14 -> 81918704 | V8: =N8*8216.36 -> 3968501.9 | W8: =O8*24675.14 -> 345451.96 | X8: =P8*11129.02 -> 1379998.5 | Y8: =Q8*7741.28 -> 9862390.7 | Z8: =R8*8475.88 -> 7721526.7 | AA8: =SUM(T8:Z8) -> 122543059 | AB8: =AA8/C8 -> 9.4270121
A9: Cabo Verde | B9: CPV | C9: 573322 | D9: 6.6454802 | E9: 16.378231 | F9: 0.45349734 | G9: 0.13953764 | H9: 0.17442205 | I9: 0.069768821 | J9: 0.13953764 | K9: 24.000474 | L9: =C9*D9/10000 -> 381 | M9: =C9*E9/10000 -> 939 | N9: =C9*F9/10000 -> 26 | O9: =C9*G9/10000 -> 8 | P9: =C9*H9/10000 -> 10 | Q9: =C9*I9/10000 -> 4 | R9: =C9*J9/10000 -> 8 | S9: =C9*K9/10000 -> 1376 | T9: =L9*16711.45 -> 6367062.5 | U9: =M9*7534.14 -> 7074557.5 | V9: =N9*8216.36 -> 213625.36 | W9: =O9*24675.14 -> 197401.12 | X9: =P9*11129.02 -> 111290.2 | Y9: =Q9*7741.28 -> 30965.12 | Z9: =R9*8475.88 -> 67807.04 | AA9: =SUM(T9:Z9) -> 14062709 | AB9: =AA9/C9 -> 24.528465
A10: Cameroon | B10: CMR | C10: 28608129 | D10: 1.3150108 | E10: 5.7798257 | F10: 0.58479882 | G10: 0.11080767 | H10: 0.2104297 | I10: 0.10241844 | J10: 0.083542688 | K10: 8.1868339 | L10: =C10*D10/10000 -> 3762 | M10: =C10*E10/10000 -> 16535 | N10: =C10*F10/10000 -> 1673 | O10: =C10*G10/10000 -> 317 | P10: =C10*H10/10000 -> 602 | Q10: =C10*I10/10000 -> 293 | R10: =C10*J10/10000 -> 239 | S10: =C10*K10/10000 -> 23421 | T10: =L10*16711.45 -> 62868475 | U10: =M10*7534.14 -> 1.24577e+08 | V10: =N10*8216.36 -> 13745970 | W10: =O10*24675.14 -> 7822019.4 | X10: =P10*11129.02 -> 6699670 | Y10: =Q10*7741.28 -> 2268195 | Z10: =R10*8475.88 -> 2025735.3 | AA10: =SUM(T10:Z10) -> 2.2000707e+08 | AB10: =AA10/C10 -> 7.6903691
A11: Central African Republic | B11: CAF | C11: 5119136 | D11: 0.74817313 | E11: 7.3371756 | F11: 3.7057035 | G11: 0.0058603639 | H11: 0.02539491 | I11: 0.21878692 | J11: 0.56064148 | K11: 12.601736 | L11: =C11*D11/10000 -> 383 | M11: =C11*E11/10000 -> 3756 | N11: =C11*F11/10000 -> 1897 | O11: =C11*G11/10000 -> 3 | P11: =C11*H11/10000 -> 13 | Q11: =C11*I11/10000 -> 112 | R11: =C11*J11/10000 -> 287 | S11: =C11*K11/10000 -> 6451 | T11: =L11*16711.45 -> 6400485.3 | U11: =M11*7534.14 -> 28298230 | V11: =N11*8216.36 -> 15586435 | W11: =O11*24675.14 -> 74025.42 | X11: =P11*11129.02 -> 144677.26 | Y11: =Q11*7741.28 -> 867023.36 | Z11: =R11*8475.88 -> 2432577.6 | AA11: =SUM(T11:Z11) -> 53803454 | AB11: =AA11/C11 -> 10.510261
A12: Chad | B12: TCD | C12: 17921183 | D12: 0.91567616 | E12: 1.3263633 | F12: 0.47150905 | G12: 0.0072539854 | H12: 0.090953817 | I12: 0.57362285 | J12: 0.58478282 | K12: 3.970162 | L12: =C12*D12/10000 -> 1641 | M12: =C12*E12/10000 -> 2377 | N12: =C12*F12/10000 -> 845 | O12: =C12*G12/10000 -> 13 | P12: =C12*H12/10000 -> 163 | Q12: =C12*I12/10000 -> 1028 | R12: =C12*J12/10000 -> 1048 | S12: =C12*K12/10000 -> 7115 | T12: =L12*16711.45 -> 27423489 | U12: =M12*7534.14 -> 17908651 | V12: =N12*8216.36 -> 6942824.2 | W12: =O12*24675.14 -> 320776.82 | X12: =P12*11129.02 -> 1814030.3 | Y12: =Q12*7741.28 -> 7958035.8 | Z12: =R12*8475.88 -> 8882722.2 | AA12: =SUM(T12:Z12) -> 71250530 | AB12: =AA12/C12 -> 3.9757716
A13: Comoros | B13: COM | C13: 926492 | D13: 3.8208641 | E13: 8.4728201 | F13: 6.3249332 | G13: 0.34538884 | H13: 0.43173605 | I13: 1.7377376 | J13: 0.17269442 | K13: 21.306174 | L13: =C13*D13/10000 -> 354 | M13: =C13*E13/10000 -> 785 | N13: =C13*F13/10000 -> 586 | O13: =C13*G13/10000 -> 32 | P13: =C13*H13/10000 -> 40 | Q13: =C13*I13/10000 -> 161 | R13: =C13*J13/10000 -> 16 | S13: =C13*K13/10000 -> 1974 | T13: =L13*16711.45 -> 5915853.3 | U13: =M13*7534.14 -> 5914299.9 | V13: =N13*8216.36 -> 4814787 | W13: =O13*24675.14 -> 789604.48 | X13: =P13*11129.02 -> 445160.8 | Y13: =Q13*7741.28 -> 1246346.1 | Z13: =R13*8475.88 -> 135614.08 | AA13: =SUM(T13:Z13) -> 19261666 | AB13: =AA13/C13 -> 20.789889
A14: Congo | B14: COG | C14: 5940746 | D14: 1.7539885 | E14: 9.3809767 | F14: 2.0031154 | G14: 0.016832903 | H14: 0.053865289 | I14: 0.53865289 | J14: 1.3079165 | K14: 15.055348 | L14: =C14*D14/10000 -> 1042 | M14: =C14*E14/10000 -> 5573 | N14: =C14*F14/10000 -> 1190 | O14: =C14*G14/10000 -> 10 | P14: =C14*H14/10000 -> 32 | Q14: =C14*I14/10000 -> 320 | R14: =C14*J14/10000 -> 777 | S14: =C14*K14/10000 -> 8944 | T14: =L14*16711.45 -> 17413331 | U14: =M14*7534.14 -> 41987762 | V14: =N14*8216.36 -> 9777468.4 | W14: =O14*24675.14 -> 246751.4 | X14: =P14*11129.02 -> 356128.64 | Y14: =Q14*7741.28 -> 2477209.6 | Z14: =R14*8475.88 -> 6585758.8 | AA14: =SUM(T14:Z14) -> 78844410 | AB14: =AA14/C14 -> 13.271803
... A49: Zimbabwe | B49: ZWE | C49: 15581023 | D49: 1.4260938 | E49: 29.867744 | F49: 1.8002669 | G49: 0.31576874 | H49: 1.2207157 | I49: 0.92997745 | J49: 0.67710573 | K49: 36.237672 | L49: =C49*D49/10000 -> 2222 | M49: =C49*E49/10000 -> 46537 | N49: =C49*F49/10000 -> 2805 | O49: =C49*G49/10000 -> 492 | P49: =C49*H49/10000 -> 1902 | Q49: =C49*I49/10000 -> 1449 | R49: =C49*J49/10000 -> 1055 | S49: =C49*K49/10000 -> 56462 | T49: =L49*16711.45 -> 37132842 | U49: =M49*7534.14 -> 3.5061627e+08 | V49: =N49*8216.36 -> 23046890 | W49: =O49*24675.14 -> 12140169 | X49: =P49*11129.02 -> 21167396 | Y49: =Q49*7741.28 -> 11217115 | Z49: =R49*8475.88 -> 8942053.4 | AA49: =SUM(T49:Z49) -> 4.6426274e+08 | AB49: =AA49/C49 -> 29.796679
